Workbook
Name ___xlnm._FilterDatabase_2: #REF!
Name ___xlnm._FilterDatabase_2: #REF!
Name ___xlnm._FilterDatabase_2: #REF!
Name ___xlnm._FilterDatabase_2: #REF!
Name ___xlnm._FilterDatabase_2: #REF!
Name ___xlnm._FilterDatabase_2: #REF!
Name ___xlnm._FilterDatabase_2: #REF!
Name ___xlnm._FilterDatabase_2: #REF!
Name ___xlnm._FilterDatabase_2: #REF!
Name ___xlnm._FilterDatabase_2: #REF!
Name ___xlnm._FilterDatabase_2: #REF!
Name ___xlnm._FilterDatabase_2: #REF!
Name ___xlnm._FilterDatabase_2: #REF!
Name ___xlnm._FilterDatabase_2: #REF!
Name ___xlnm._FilterDatabase_2: #REF!
Name ___xlnm._FilterDatabase_2: #REF!
Name __xlnm._FilterDatabase_2: #REF!
Name __xlnm._FilterDatabase_2: #REF!
Name __xlnm._FilterDatabase_2: #REF!
Name __xlnm._FilterDatabase_2: #REF!
Name __xlnm._FilterDatabase_2: #REF!
Name __xlnm._FilterDatabase_2: #REF!
Name __xlnm._FilterDatabase_2: #REF!
Name __xlnm._FilterDatabase_2: #REF!
Name __xlnm._FilterDatabase_2: #REF!
Name __xlnm._FilterDatabase_2: #REF!
Name __xlnm._FilterDatabase_2: #REF!
Name __xlnm._FilterDatabase_2: #REF!
Name __xlnm._FilterDatabase_2: #REF!
Name __xlnm._FilterDatabase_2: #REF!
Name __xlnm._FilterDatabase_2: #REF!
Name __xlnm._FilterDatabase_2: #REF!
Name Excel_BuiltIn__FilterDatabase_1: #REF!
Name Excel_BuiltIn__FilterDatabase_1: #REF!
Name Excel_BuiltIn__FilterDatabase_1: #REF!
Name Excel_BuiltIn__FilterDatabase_1: #REF!
Name Excel_BuiltIn__FilterDatabase_1: #REF!
Name Excel_BuiltIn__FilterDatabase_1: #REF!
Name Excel_BuiltIn__FilterDatabase_1: #REF!
Name Excel_BuiltIn__FilterDatabase_1: #REF!
Name Excel_BuiltIn__FilterDatabase_1: #REF!
Name Excel_BuiltIn__FilterDatabase_1: #REF!
Name Excel_BuiltIn__FilterDatabase_1: #REF!
Name Excel_BuiltIn__FilterDatabase_1: #REF!
Name Excel_BuiltIn__FilterDatabase_1: #REF!
Name Excel_BuiltIn__FilterDatabase_1: #REF!
Name Excel_BuiltIn__FilterDatabase_1: #REF!
Name Excel_BuiltIn__FilterDatabase_1: #REF!
Name Export_3: #REF!
Name Export_3: #REF!
Name Export_3: #REF!
Name Export_3: #REF!
Name Export_3: #REF!
Name Export_3: #REF!
Name Export_3: #REF!
Name Export_3: #REF!
Name Export_3: #REF!
Name Export_3: #REF!
Name FOB: 'Summary FOB'!#REF!
Name FOB: 'Summary FOB'!#REF!

Sheet SO FOB Januari 2026
A2: SALES ORDER
A4: 46023
A6: Week | B6: DATE | D6: TOTAL | E6: FOB SETU-AAE | F6: FOB SETU- SIDO | G6: FOB SETU - GIG | H6: FOB SETU - SALMAH | I6: FOB SETU - NNE | J6: FOB SETU - GAS | K6: FOB SETU -SBE | L6: FOB SETU -DAMASINDO | M6: FOB SETU-LARAS | N6: FOB SETU-KIRANA | O6: FOB KHT-APE | P6: FOB KHT - JPEN | Q6: FOB KHT - Laras | R6: FOB KHT - ANAGATA
A7: =WEEKNUM(B7) -> 1 | B7: 46023 | C7: =TEXT(B7,"ddd") -> Kam | D7: =SUM(E7:R7) -> 0 | E7: 0 | F7: 0 | G7: 0 | H7: 0 | I7: 0 | J7: 0 | K7: 0 | L7: 0 | M7: 0 | N7: 0 | O7: 0 | P7: 0 | Q7: 0 | R7: 0
B8: =B7+1 -> 46024 | C8: =TEXT(B8,"ddd") -> Jum | D8: =SUM(E8:R8) -> 0 | E8: 0 | F8: 0 | G8: 0 | H8: 0 | I8: 0 | J8: 0 | K8: 0 | L8: 0 | M8: 0 | N8: 0 | O8: 0 | P8: 0 | Q8: 0 | R8: 0
B9: =B8+1 -> 46025 | C9: =TEXT(B9,"ddd") -> Sab | D9: =SUM(E9:R9) -> 0 | E9: 0 | F9: 0 | G9: 0 | H9: 0 | I9: 0 | J9: 0 | K9: 0 | L9: 0 | M9: 0 | N9: 0 | O9: 0 | P9: 0 | Q9: 0 | R9: 0
B10: =B9+1 -> 46026 | C10: =TEXT(B10,"ddd") -> Mgg | D10: =SUM(E10:R10) -> 0 | E10: 0 | F10: 0 | G10: 0 | H10: 0 | I10: 0 | J10: 0 | K10: 0 | L10: 0 | M10: 0 | N10: 0 | O10: 0 | P10: 0 | Q10: 0 | R10: 0
B11: Sub Total | D11: =SUM(D7:D10) -> 0 | E11: =SUM(E7:E10) -> 0 | F11: =SUM(F7:F10) -> 0 | G11: =SUM(G7:G10) -> 0 | H11: =SUM(H7:H10) -> 0 | I11: =SUM(I7:I10) -> 0 | J11: =SUM(J7:J10) -> 0 | K11: =SUM(K7:K10) -> 0 | ... R11: =SUM(R7:R10) -> 0
R12: 0
A13: =WEEKNUM(B15) -> 2 | B13: =B10+1 -> 46027 | C13: =TEXT(B13,"ddd") -> Sen | D13: =SUM(E13:R13) -> 0 | E13: 0 | F13: 0 | G13: 0 | H13: 0 | I13: 0 | J13: 0 | K13: 0 | L13: 0 | M13: 0 | N13: 0 | O13: 0 | P13: 0 | Q13: 0 | R13: 0
B14: =B13+1 -> 46028 | C14: =TEXT(B14,"ddd") -> Sel | D14: =SUM(E14:R14) -> 0 | E14: 0 | F14: 0 | G14: 0 | H14: 0 | I14: 0 | J14: 0 | K14: 0 | L14: 0 | M14: 0 | N14: 0 | O14: 0 | P14: 0 | Q14: 0 | R14: 0
B15: =B14+1 -> 46029 | C15: =TEXT(B15,"ddd") -> Rab | D15: =SUM(E15:R15) -> 0 | E15: 0 | F15: 0 | G15: 0 | H15: 0 | I15: 0 | J15: 0 | K15: 0 | L15: 0 | M15: 0 | N15: 0 | O15: 0 | P15: 0 | Q15: 0 | R15: 0
B16: =B15+1 -> 46030 | C16: =TEXT(B16,"ddd") -> Kam | D16: =SUM(E16:R16) -> 0 | E16: 0 | F16: 0 | G16: 0 | H16: 0 | I16: 0 | J16: 0 | K16: 0 | L16: 0 | M16: 0 | N16: 0 | O16: 0 | P16: 0 | Q16: 0 | R16: 0
B17: =B16+1 -> 46031 | C17: =TEXT(B17,"ddd") -> Jum | D17: =SUM(E17:R17) -> 0 | E17: 0 | F17: 0 | G17: 0 | H17: 0 | I17: 0 | J17: 0 | K17: 0 | L17: 0 | M17: 0 | N17: 0 | O17: 0 | P17: 0 | Q17: 0 | R17: 0
B18: =B17+1 -> 46032 | C18: =TEXT(B18,"ddd") -> Sab | D18: =SUM(E18:R18) -> 0 | E18: 0 | F18: 0 | G18: 0 | H18: 0 | I18: 0 | J18: 0 | K18: 0 | L18: 0 | M18: 0 | N18: 0 | O18: 0 | P18: 0 | Q18: 0 | R18: 0
B19: =B18+1 -> 46033 | C19: =TEXT(B19,"ddd") -> Mgg | D19: =SUM(E19:R19) -> 0 | E19: 0 | F19: 0 | G19: 0 | H19: 0 | I19: 0 | J19: 0 | K19: 0 | L19: 0 | M19: 0 | N19: 0 | O19: 0 | P19: 0 | Q19: 0 | R19: 0
B20: Sub Total | D20: =SUM(D13:D19) -> 0 | E20: =SUM(E13:E19) -> 0 | F20: =SUM(F13:F19) -> 0 | G20: =SUM(G13:G19) -> 0 | H20: =SUM(H13:H19) -> 0 | I20: =SUM(I13:I19) -> 0 | J20: =SUM(J13:J19) -> 0 | K20: =SUM(K13:K19) -> 0 | ... R20: =SUM(R13:R19) -> 0
R21: 0
A22: =WEEKNUM(B24) -> 3 | B22: =B19+1 -> 46034 | C22: =TEXT(B22,"ddd") -> Sen | D22: =SUM(E22:R22) -> 0 | E22: 0 | F22: 0 | G22: 0 | H22: 0 | I22: 0 | J22: 0 | K22: 0 | L22: 0 | M22: 0 | N22: 0 | O22: 0 | P22: 0 | Q22: 0 | R22: 0
B23: =B22+1 -> 46035 | C23: =TEXT(B23,"ddd") -> Sel | D23: =SUM(E23:R23) -> 0 | E23: 0 | F23: 0 | G23: 0 | H23: 0 | I23: 0 | J23: 0 | K23: 0 | L23: 0 | M23: 0 | N23: 0 | O23: 0 | P23: 0 | Q23: 0 | R23: 0
B24: =B23+1 -> 46036 | C24: =TEXT(B24,"ddd") -> Rab | D24: =SUM(E24:R24) -> 0 | E24: 0 | F24: 0 | G24: 0 | H24: 0 | I24: 0 | J24: 0 | K24: 0 | L24: 0 | M24: 0 | N24: 0 | O24: 0 | P24: 0 | Q24: 0 | R24: 0
B25: =B24+1 -> 46037 | C25: =TEXT(B25,"ddd") -> Kam | D25: =SUM(E25:R25) -> 0 | E25: 0 | F25: 0 | G25: 0 | H25: 0 | I25: 0 | J25: 0 | K25: 0 | L25: 0 | M25: 0 | N25: 0 | O25: 0 | P25: 0 | Q25: 0 | R25: 0
B26: =B25+1 -> 46038 | C26: =TEXT(B26,"ddd") -> Jum | D26: =SUM(E26:R26) -> 0 | E26: 0 | F26: 0 | G26: 0 | H26: 0 | I26: 0 | J26: 0 | K26: 0 | L26: 0 | M26: 0 | N26: 0 | O26: 0 | P26: 0 | Q26: 0 | R26: 0
B27: =B26+1 -> 46039 | C27: =TEXT(B27,"ddd") -> Sab | D27: =SUM(E27:R27) -> 0 | E27: 0 | F27: 0 | G27: 0 | H27: 0 | I27: 0 | J27: 0 | K27: 0 | L27: 0 | M27: 0 | N27: 0 | O27: 0 | P27: 0 | Q27: 0 | R27: 0
B28: =B27+1 -> 46040 | C28: =TEXT(B28,"ddd") -> Mgg | D28: =SUM(E28:R28) -> 0 | E28: 0 | F28: 0 | G28: 0 | H28: 0 | I28: 0 | J28: 0 | K28: 0 | L28: 0 | M28: 0 | N28: 0 | O28: 0 | P28: 0 | Q28: 0 | R28: 0
B29: Sub Total | D29: =SUM(D22:D28) -> 0 | E29: =SUM(E22:E28) -> 0 | F29: =SUM(F22:F28) -> 0 | G29: =SUM(G22:G28) -> 0 | H29: =SUM(H22:H28) -> 0 | I29: =SUM(I22:I28) -> 0 | J29: =SUM(J22:J28) -> 0 | K29: =SUM(K22:K28) -> 0 | ... R29: =SUM(R22:R28) -> 0
R30: 0
A31: =WEEKNUM(B33) -> 4 | B31: =B28+1 -> 46041 | C31: =TEXT(B31,"ddd") -> Sen | D31: =SUM(E31:R31) -> 0 | E31: 0 | F31: 0 | G31: 0 | H31: 0 | I31: 0 | J31: 0 | K31: 0 | L31: 0 | M31: 0 | N31: 0 | O31: 0 | P31: 0 | Q31: 0 | R31: 0
B32: =B31+1 -> 46042 | C32: =TEXT(B32,"ddd") -> Sel | D32: =SUM(E32:R32) -> 0 | E32: 0 | F32: 0 | G32: 0 | H32: 0 | I32: 0 | J32: 0 | K32: 0 | L32: 0 | M32: 0 | N32: 0 | O32: 0 | P32: 0 | Q32: 0 | R32: 0
B33: =B32+1 -> 46043 | C33: =TEXT(B33,"ddd") -> Rab | D33: =SUM(E33:R33) -> 0 | E33: 0 | F33: 0 | G33: 0 | H33: 0 | I33: 0 | J33: 0 | K33: 0 | L33: 0 | M33: 0 | N33: 0 | O33: 0 | P33: 0 | Q33: 0 | R33: 0
B34: =B33+1 -> 46044 | C34: =TEXT(B34,"ddd") -> Kam | D34: =SUM(E34:R34) -> 0 | E34: 0 | F34: 0 | G34: 0 | H34: 0 | I34: 0 | J34: 0 | K34: 0 | L34: 0 | M34: 0 | N34: 0 | O34: 0 | P34: 0 | Q34: 0 | R34: 0
B35: =B34+1 -> 46045 | C35: =TEXT(B35,"ddd") -> Jum | D35: =SUM(E35:R35) -> 0 | E35: 0 | F35: 0 | G35: 0 | H35: 0 | I35: 0 | J35: 0 | K35: 0 | L35: 0 | M35: 0 | N35: 0 | O35: 0 | P35: 0 | Q35: 0 | R35: 0
B36: =B35+1 -> 46046 | C36: =TEXT(B36,"ddd") -> Sab | D36: =SUM(E36:R36) -> 0 | E36: 0 | F36: 0 | G36: 0 | H36: 0 | I36: 0 | J36: 0 | K36: 0 | L36: 0 | M36: 0 | N36: 0 | O36: 0 | P36: 0 | Q36: 0 | R36: 0
B37: =B36+1 -> 46047 | C37: =TEXT(B37,"ddd") -> Mgg | D37: =SUM(E37:R37) -> 0 | E37: 0 | F37: 0 | G37: 0 | H37: 0 | I37: 0 | J37: 0 | K37: 0 | L37: 0 | M37: 0 | N37: 0 | O37: 0 | P37: 0 | Q37: 0 | R37: 0
B38: Sub Total | D38: =SUM(D31:D37) -> 0 | E38: =SUM(E31:E37) -> 0 | F38: =SUM(F31:F37) -> 0 | G38: =SUM(G31:G37) -> 0 | H38: =SUM(H31:H37) -> 0 | I38: =SUM(I31:I37) -> 0 | J38: =SUM(J31:J37) -> 0 | K38: =SUM(K31:K37) -> 0 | ... R38: =SUM(R31:R37) -> 0
R39: 0
A40: =WEEKNUM(B44) -> 5 | B40: =B37+1 -> 46048 | C40: =TEXT(B40,"ddd") -> Sen | D40: =SUM(E40:R40) -> 0 | E40: 0 | F40: 0 | G40: 0 | H40: 0 | I40: 0 | J40: 0 | K40: 0 | L40: 0 | M40: 0 | N40: 0 | O40: 0 | P40: 0 | Q40: 0 | R40: 0
B41: =B40+1 -> 46049 | C41: =TEXT(B41,"ddd") -> Sel | D41: =SUM(E41:R41) -> 0 | E41: 0 | F41: 0 | G41: 0 | H41: 0 | I41: 0 | J41: 0 | K41: 0 | L41: 0 | M41: 0 | N41: 0 | O41: 0 | P41: 0 | Q41: 0 | R41: 0
B42: =B41+1 -> 46050 | C42: =TEXT(B42,"ddd") -> Rab | D42: =SUM(E42:R42) -> 0 | E42: 0 | F42: 0 | G42: 0 | H42: 0 | I42: 0 | J42: 0 | K42: 0 | L42: 0 | M42: 0 | N42: 0 | O42: 0 | P42: 0 | Q42: 0 | R42: 0
B43: =B42+1 -> 46051 | C43: =TEXT(B43,"ddd") -> Kam | D43: =SUM(E43:R43) -> 0 | E43: 0 | F43: 0 | G43: 0 | H43: 0 | I43: 0 | J43: 0 | K43: 0 | L43: 0 | M43: 0 | N43: 0 | O43: 0 | P43: 0 | Q43: 0 | R43: 0
...

Sheet SO Januari 2026 rev.2
A2: SALES ORDER
A3: 46023 | O3: =O4/2 -> 0
Q4: =Q9/24 -> 485.81477 | S4: =S11/24 -> 0 | AL4: =AL11/24 -> 0 | AP4: =AP6/24 -> 1000
A5: Week | B5: DATE | D5: TOTAL | E5: CLIN | F5: BI | G5: MKG | H5: STM | I5: OAJ | J5: NNI | K5: SHB | L5: GTL | M5: TWK | N5: BYC | O5: GF RANCA | P5: SMA | Q5: UMI | R5: HLI | S5: CERES | T5: DIC | U5: KSN | V5: ADP | W5: ALT (KSO MASAMI) | X5: IDP (KSO AAE) | Y5: FJI (KSO SALMAH) | Z5: WINGLOK (KSO EBM) | AA5: CISF (KSO RRS) | AB5: KGM (KSO RRS) | AC5: PUJ - LUBRICANT | AD5: CALBEE (KSO BMI) | AE5: IP | AF5: BEM | AG5: AMI | AH5: KA | AI5: KTN | AJ5: TOMIMOTO | AK5: NIAGA GARAM | AL5: PCI 84 | AM5: PCI MENGGER | AN5: INDOFOOD | AO5: HCI | AP5: ASAHIMAS | AQ5: ABC KOGEN | AR5: TONGJI ( KSO GAS) | AS5: CITYMALL GARUT | AT5: PERHUTANI (KSO PTGN) | AU5: PA | AV5: RPI | AW5: RB | AX5: GF ATOM | AY5: GF KULIT | AZ5: HSK (KSO GAS) | BA5: SDM | BB5: JARGAS | BC5: SBI | BD5: SP KSO JES | BE5: SP GLOBAL
A6: =WEEKNUM(B6) -> 1 | B6: =A3 -> 46023 | C6: =TEXT(B6,"ddd") -> Kam | D6: =SUM(E6:BE6) -> 145591.94 | E6: 812.17 | F6: 3000 | G6: 1129.7313 | H6: 0 | I6: 644.02065 | J6: 5500 | K6: 166.97065 | L6: 603.76323 | M6: 673.27548 | N6: 4514.199 | O6: 6823.0623 | P6: 0 | Q6: 11659.555 | R6: 3600 | S6: 8706.0571 | T6: 0 | U6: 5000 | V6: 500 | W6: 926.09448 | X6: 0 | Y6: 70.054839 | Z6: 89.451613 | AA6: 3500 | AB6: 0 | AC6: 2901.4806 | AD6: 0 | AE6: 2020.8603 | AF6: 678.7 | AG6: 7121.8519 | AH6: 2443.8768 | AI6: 2043.2745 | AJ6: 1439.5303 | AK6: 260.97419 | AL6: 11007.047 | AM6: 1519.5448 | AN6: 3799.6742 | AO6: 0 | AP6: 24000 | AQ6: 8000 | AR6: 2105.6477 | AS6: 0 | AT6: 0 | AU6: 726.81516 | AV6: 3500 | AW6: 3018.0416 | AX6: 2044.9997 | AY6: 369.61071 | AZ6: 3500 | BA6: 1121.9003 | BB6: 1500 | BC6: 2549.7026 | BD6: 0 | BE6: 0
B7: =B6+1 -> 46024 | C7: =TEXT(B7,"ddd") -> Jum | D7: =SUM(E7:BE7) -> 148466.26 | E7: 812.17 | F7: 3000 | G7: 1129.7313 | H7: 0 | I7: 644.02065 | J7: 5500 | K7: 166.97065 | L7: 603.76323 | M7: 673.27548 | N7: 4514.199 | O7: 6823.0623 | P7: 2874.3265 | Q7: 11659.555 | R7: 3600 | S7: 8706.0571 | T7: 0 | U7: 5000 | V7: 500 | W7: 926.09448 | X7: 0 | Y7: 70.054839 | Z7: 89.451613 | AA7: 3500 | AB7: 0 | AC7: 2901.4806 | AD7: 0 | AE7: 2020.8603 | AF7: 678.7 | AG7: 7121.8519 | AH7: 2443.8768 | AI7: 2043.2745 | AJ7: 1439.5303 | AK7: 260.97419 | AL7: 11007.047 | AM7: 1519.5448 | AN7: 3799.6742 | AO7: 0 | AP7: 24000 | AQ7: 8000 | AR7: 2105.6477 | AS7: 0 | AT7: 0 | AU7: 726.81516 | AV7: 3500 | AW7: 3018.0416 | AX7: 2044.9997 | AY7: 369.61071 | AZ7: 3500 | BA7: 1121.9003 | BB7: 1500 | BC7: 2549.7026 | BD7: 0 | BE7: 0
B8: =B7+1 -> 46025 | C8: =TEXT(B8,"ddd") -> Sab | D8: =SUM(E8:BE8) -> 147862.5 | E8: 812.17 | F8: 3000 | G8: 1129.7313 | H8: 0 | I8: 644.02065 | J8: 5500 | K8: 166.97065 | L8: 0 | M8: 673.27548 | N8: 4514.199 | O8: 6823.0623 | P8: 2874.3265 | Q8: 11659.555 | R8: 3600 | S8: 8706.0571 | T8: 0 | U8: 5000 | V8: 500 | W8: 926.09448 | X8: 0 | Y8: 70.054839 | Z8: 89.451613 | AA8: 3500 | AB8: 0 | AC8: 2901.4806 | AD8: 0 | AE8: 2020.8603 | AF8: 678.7 | AG8: 7121.8519 | AH8: 2443.8768 | AI8: 2043.2745 | AJ8: 1439.5303 | AK8: 260.97419 | AL8: 11007.047 | AM8: 1519.5448 | AN8: 3799.6742 | AO8: 0 | AP8: 24000 | AQ8: 8000 | AR8: 2105.6477 | AS8: 0 | AT8: 0 | AU8: 726.81516 | AV8: 3500 | AW8: 3018.0416 | AX8: 2044.9997 | AY8: 369.61071 | AZ8: 3500 | BA8: 1121.9003 | BB8: 1500 | BC8: 2549.7026 | BD8: 0 | BE8: 0
B9: =B8+1 -> 46026 | C9: =TEXT(B9,"ddd") -> Mgg | D9: =SUM(E9:BE9) -> 150966.26 | E9: 812.17 | F9: 3000 | G9: 1129.7313 | H9: 0 | I9: 644.02065 | J9: 5500 | K9: 166.97065 | L9: 603.76323 | M9: 673.27548 | N9: 4514.199 | O9: 6823.0623 | P9: 2874.3265 | Q9: 11659.555 | R9: 3600 | S9: 8706.0571 | T9: 0 | U9: 5000 | V9: 500 | W9: 926.09448 | X9: 2500 | Y9: 70.054839 | Z9: 89.451613 | AA9: 3500 | AB9: 0 | AC9: 2901.4806 | AD9: 0 | AE9: 2020.8603 | AF9: 678.7 | AG9: 7121.8519 | AH9: 2443.8768 | AI9: 2043.2745 | AJ9: 1439.5303 | AK9: 260.97419 | AL9: 11007.047 | AM9: 1519.5448 | AN9: 3799.6742 | AO9: 0 | AP9: 24000 | AQ9: 8000 | AR9: 2105.6477 | AS9: 0 | AT9: 0 | AU9: 726.81516 | AV9: 3500 | AW9: 3018.0416 | AX9: 2044.9997 | AY9: 369.61071 | AZ9: 3500 | BA9: 1121.9003 | BB9: 1500 | BC9: 2549.7026 | BD9: 0 | BE9: 0
B10: Sub Total | D10: =SUM(D6:D9) -> 592886.97 | E10: =SUM(E6:E9) -> 3248.68 | F10: =SUM(F6:F9) -> 12000 | G10: =SUM(G6:G9) -> 4518.9252 | H10: =SUM(H6:H9) -> 0 | I10: =SUM(I6:I9) -> 2576.0826 | J10: =SUM(J6:J9) -> 22000 | K10: =SUM(K6:K9) -> 667.88258 | ... BE10: =SUM(BE6:BE9) -> 0
A12: =WEEKNUM(B14) -> 2 | B12: =B9+1 -> 46027 | C12: =TEXT(B12,"ddd") -> Sen | D12: =SUM(E12:BE12) -> 161505.47 | E12: 812.17 | F12: 3000 | G12: 1129.7313 | H12: 3282.5161 | I12: 644.02065 | J12: 5500 | K12: 166.97065 | L12: 603.76323 | M12: 673.27548 | N12: 4514.199 | O12: 6823.0623 | P12: 2874.3265 | Q12: 11659.555 | R12: 3600 | S12: 8706.0571 | T12: 5776.6897 | U12: 5000 | V12: 500 | W12: 926.09448 | X12: 5500 | Y12: 70.054839 | Z12: 89.451613 | AA12: 3500 | AB12: 0 | AC12: 2901.4806 | AD12: 0 | AE12: 2020.8603 | AF12: 678.7 | AG12: 7121.8519 | AH12: 2943.8768 | AI12: 2043.2745 | AJ12: 1439.5303 | AK12: 260.97419 | AL12: 11007.047 | AM12: 2999.5448 | AN12: 3799.6742 | AO12: 0 | AP12: 24000 | AQ12: 8000 | AR12: 2105.6477 | AS12: 0 | AT12: 0 | AU12: 726.81516 | AV12: 0 | AW12: 3018.0416 | AX12: 2044.9997 | AY12: 369.61071 | AZ12: 3500 | BA12: 1121.9003 | BB12: 1500 | BC12: 2549.7026 | BD12: 0 | BE12: 0
B13: =B12+1 -> 46028 | C13: =TEXT(B13,"ddd") -> Sel | D13: =SUM(E13:BE13) -> 165505.47 | E13: 812.17 | F13: 3000 | G13: 1129.7313 | H13: 3282.5161 | I13: 644.02065 | J13: 5500 | K13: 166.97065 | L13: 603.76323 | M13: 673.27548 | N13: 4514.199 | O13: 6823.0623 | P13: 2874.3265 | Q13: 11659.555 | R13: 3600 | S13: 8706.0571 | T13: 5776.6897 | U13: 3500 | V13: 500 | W13: 926.09448 | X13: 5500 | Y13: 70.054839 | Z13: 89.451613 | AA13: 3500 | AB13: 0 | AC13: 2901.4806 | AD13: 0 | AE13: 2020.8603 | AF13: 678.7 | AG13: 7121.8519 | AH13: 2943.8768 | AI13: 2043.2745 | AJ13: 1439.5303 | AK13: 260.97419 | AL13: 11007.047 | AM13: 2999.5448 | AN13: 3799.6742 | AO13: 5500 | AP13: 24000 | AQ13: 8000 | AR13: 2105.6477 | AS13: 0 | AT13: 0 | AU13: 726.81516 | AV13: 0 | AW13: 3018.0416 | AX13: 2044.9997 | AY13: 369.61071 | AZ13: 3500 | BA13: 1121.9003 | BB13: 1500 | BC13: 2549.7026 | BD13: 0 | BE13: 0
B14: =B13+1 -> 46029 | C14: =TEXT(B14,"ddd") -> Rab | D14: =SUM(E14:BE14) -> 165505.47 | E14: 812.17 | F14: 3000 | G14: 1129.7313 | H14: 3282.5161 | I14: 644.02065 | J14: 5500 | K14: 166.97065 | L14: 603.76323 | M14: 673.27548 | N14: 4514.199 | O14: 6823.0623 | P14: 2874.3265 | Q14: 11659.555 | R14: 3600 | S14: 8706.0571 | T14: 5776.6897 | U14: 3500 | V14: 500 | W14: 926.09448 | X14: 5500 | Y14: 70.054839 | Z14: 89.451613 | AA14: 3500 | AB14: 0 | AC14: 2901.4806 | AD14: 0 | AE14: 2020.8603 | AF14: 678.7 | AG14: 7121.8519 | AH14: 2943.8768 | AI14: 2043.2745 | AJ14: 1439.5303 | AK14: 260.97419 | AL14: 11007.047 | AM14: 2999.5448 | AN14: 3799.6742 | AO14: 5500 | AP14: 24000 | AQ14: 8000 | AR14: 2105.6477 | AS14: 0 | AT14: 0 | AU14: 726.81516 | AV14: 0 | AW14: 3018.0416 | AX14: 2044.9997 | AY14: 369.61071 | AZ14: 3500 | BA14: 1121.9003 | BB14: 1500 | BC14: 2549.7026 | BD14: 0 | BE14: 0
B15: =B14+1 -> 46030 | C15: =TEXT(B15,"ddd") -> Kam | D15: =SUM(E15:BE15) -> 165505.47 | E15: 812.17 | F15: 3000 | G15: 1129.7313 | H15: 3282.5161 | I15: 644.02065 | J15: 5500 | K15: 166.97065 | L15: 603.76323 | M15: 673.27548 | N15: 4514.199 | O15: 6823.0623 | P15: 2874.3265 | Q15: 11659.555 | R15: 3600 | S15: 8706.0571 | T15: 5776.6897 | U15: 3500 | V15: 500 | W15: 926.09448 | X15: 5500 | Y15: 70.054839 | Z15: 89.451613 | AA15: 3500 | AB15: 0 | AC15: 2901.4806 | AD15: 0 | AE15: 2020.8603 | AF15: 678.7 | AG15: 7121.8519 | AH15: 2943.8768 | AI15: 2043.2745 | AJ15: 1439.5303 | AK15: 260.97419 | AL15: 11007.047 | AM15: 2999.5448 | AN15: 3799.6742 | AO15: 5500 | AP15: 24000 | AQ15: 8000 | AR15: 2105.6477 | AS15: 0 | AT15: 0 | AU15: 726.81516 | AV15: 0 | AW15: 3018.0416 | AX15: 2044.9997 | AY15: 369.61071 | AZ15: 3500 | BA15: 1121.9003 | BB15: 1500 | BC15: 2549.7026 | BD15: 0 | BE15: 0
B16: =B15+1 -> 46031 | C16: =TEXT(B16,"ddd") -> Jum | D16: =SUM(E16:BE16) -> 165505.47 | E16: 812.17 | F16: 3000 | G16: 1129.7313 | H16: 3282.5161 | I16: 644.02065 | J16: 5500 | K16: 166.97065 | L16: 603.76323 | M16: 673.27548 | N16: 4514.199 | O16: 6823.0623 | P16: 2874.3265 | Q16: 11659.555 | R16: 3600 | S16: 8706.0571 | T16: 5776.6897 | U16: 3500 | V16: 500 | W16: 926.09448 | X16: 5500 | Y16: 70.054839 | Z16: 89.451613 | AA16: 3500 | AB16: 0 | AC16: 2901.4806 | AD16: 0 | AE16: 2020.8603 | AF16: 678.7 | AG16: 7121.8519 | AH16: 2943.8768 | AI16: 2043.2745 | AJ16: 1439.5303 | AK16: 260.97419 | AL16: 11007.047 | AM16: 2999.5448 | AN16: 3799.6742 | AO16: 5500 | AP16: 24000 | AQ16: 8000 | AR16: 2105.6477 | AS16: 0 | AT16: 0 | AU16: 726.81516 | AV16: 0 | AW16: 3018.0416 | AX16: 2044.9997 | AY16: 369.61071 | AZ16: 3500 | BA16: 1121.9003 | BB16: 1500 | BC16: 2549.7026 | BD16: 0 | BE16: 0
B17: =B16+1 -> 46032 | C17: =TEXT(B17,"ddd") -> Sab | D17: =SUM(E17:BE17) -> 165505.47 | E17: 812.17 | F17: 3000 | G17: 1129.7313 | H17: 3282.5161 | I17: 644.02065 | J17: 5500 | K17: 166.97065 | L17: 603.76323 | M17: 673.27548 | N17: 4514.199 | O17: 6823.0623 | P17: 2874.3265 | Q17: 11659.555 | R17: 3600 | S17: 8706.0571 | T17: 5776.6897 | U17: 3500 | V17: 500 | W17: 926.09448 | X17: 5500 | Y17: 70.054839 | Z17: 89.451613 | AA17: 3500 | AB17: 0 | AC17: 2901.4806 | AD17: 0 | AE17: 2020.8603 | AF17: 678.7 | AG17: 7121.8519 | AH17: 2943.8768 | AI17: 2043.2745 | AJ17: 1439.5303 | AK17: 260.97419 | AL17: 11007.047 | AM17: 2999.5448 | AN17: 3799.6742 | AO17: 5500 | AP17: 24000 | AQ17: 8000 | AR17: 2105.6477 | AS17: 0 | AT17: 0 | AU17: 726.81516 | AV17: 0 | AW17: 3018.0416 | AX17: 2044.9997 | AY17: 369.61071 | AZ17: 3500 | BA17: 1121.9003 | BB17: 1500 | BC17: 2549.7026 | BD17: 0 | BE17: 0
B18: =B17+1 -> 46033 | C18: =TEXT(B18,"ddd") -> Mgg | D18: =SUM(E18:BE18) -> 165505.47 | E18: 812.17 | F18: 3000 | G18: 1129.7313 | H18: 3282.5161 | I18: 644.02065 | J18: 5500 | K18: 166.97065 | L18: 603.76323 | M18: 673.27548 | N18: 4514.199 | O18: 6823.0623 | P18: 2874.3265 | Q18: 11659.555 | R18: 3600 | S18: 8706.0571 | T18: 5776.6897 | U18: 3500 | V18: 500 | W18: 926.09448 | X18: 5500 | Y18: 70.054839 | Z18: 89.451613 | AA18: 3500 | AB18: 0 | AC18: 2901.4806 | AD18: 0 | AE18: 2020.8603 | AF18: 678.7 | AG18: 7121.8519 | AH18: 2943.8768 | AI18: 2043.2745 | AJ18: 1439.5303 | AK18: 260.97419 | AL18: 11007.047 | AM18: 2999.5448 | AN18: 3799.6742 | AO18: 5500 | AP18: 24000 | AQ18: 8000 | AR18: 2105.6477 | AS18: 0 | AT18: 0 | AU18: 726.81516 | AV18: 0 | AW18: 3018.0416 | AX18: 2044.9997 | AY18: 369.61071 | AZ18: 3500 | BA18: 1121.9003 | BB18: 1500 | BC18: 2549.7026 | BD18: 0 | BE18: 0
B19: Sub Total | D19: =SUM(D12:D18) -> 1154538.3 | E19: =SUM(E12:E18) -> 5685.19 | F19: =SUM(F12:F18) -> 21000 | G19: =SUM(G12:G18) -> 7908.119 | H19: =SUM(H12:H18) -> 22977.613 | I19: =SUM(I12:I18) -> 4508.1445 | J19: =SUM(J12:J18) -> 38500 | K19: =SUM(K12:K18) -> 1168.7945 | ... BE19: =SUM(BE12:BE18) -> 0
A21: =WEEKNUM(B23) -> 3 | B21: =B18+1 -> 46034 | C21: =TEXT(B21,"ddd") -> Sen | D21: =SUM(E21:BE21) -> 165505.47 | E21: 812.17 | F21: 3000 | G21: 1129.7313 | H21: 3282.5161 | I21: 644.02065 | J21: 5500 | K21: 166.97065 | L21: 603.76323 | M21: 673.27548 | N21: 4514.199 | O21: 6823.0623 | P21: 2874.3265 | Q21: 11659.555 | R21: 3600 | S21: 8706.0571 | T21: 5776.6897 | U21: 3500 | V21: 500 | W21: 926.09448 | X21: 5500 | Y21: 70.054839 | Z21: 89.451613 | AA21: 3500 | AB21: 0 | AC21: 2901.4806 | AD21: 0 | AE21: 2020.8603 | AF21: 678.7 | AG21: 7121.8519 | AH21: 2943.8768 | AI21: 2043.2745 | AJ21: 1439.5303 | AK21: 260.97419 | AL21: 11007.047 | AM21: 2999.5448 | AN21: 3799.6742 | AO21: 5500 | AP21: 24000 | AQ21: 8000 | AR21: 2105.6477 | AS21: 0 | AT21: 0 | AU21: 726.81516 | AV21: 0 | AW21: 3018.0416 | AX21: 2044.9997 | AY21: 369.61071 | AZ21: 3500 | BA21: 1121.9003 | BB21: 1500 | BC21: 2549.7026 | BD21: 0 | BE21: 0
B22: =B21+1 -> 46035 | C22: =TEXT(B22,"ddd") -> Sel | D22: =SUM(E22:BE22) -> 165505.47 | E22: 812.17 | F22: 3000 | G22: 1129.7313 | H22: 3282.5161 | I22: 644.02065 | J22: 5500 | K22: 166.97065 | L22: 603.76323 | M22: 673.27548 | N22: 4514.199 | O22: 6823.0623 | P22: 2874.3265 | Q22: 11659.555 | R22: 3600 | S22: 8706.0571 | T22: 5776.6897 | U22: 3500 | V22: 500 | W22: 926.09448 | X22: 5500 | Y22: 70.054839 | Z22: 89.451613 | AA22: 3500 | AB22: 0 | AC22: 2901.4806 | AD22: 0 | AE22: 2020.8603 | AF22: 678.7 | AG22: 7121.8519 | AH22: 2943.8768 | AI22: 2043.2745 | AJ22: 1439.5303 | AK22: 260.97419 | AL22: 11007.047 | AM22: 2999.5448 | AN22: 3799.6742 | AO22: 5500 | AP22: 24000 | AQ22: 8000 | AR22: 2105.6477 | AS22: 0 | AT22: 0 | AU22: 726.81516 | AV22: 0 | AW22: 3018.0416 | AX22: 2044.9997 | AY22: 369.61071 | AZ22: 3500 | BA22: 1121.9003 | BB22: 1500 | BC22: 2549.7026 | BD22: 0 | BE22: 0
B23: =B22+1 -> 46036 | C23: =TEXT(B23,"ddd") -> Rab | D23: =SUM(E23:BE23) -> 165505.47 | E23: 812.17 | F23: 3000 | G23: 1129.7313 | H23: 3282.5161 | I23: 644.02065 | J23: 5500 | K23: 166.97065 | L23: 603.76323 | M23: 673.27548 | N23: 4514.199 | O23: 6823.0623 | P23: 2874.3265 | Q23: 11659.555 | R23: 3600 | S23: 8706.0571 | T23: 5776.6897 | U23: 3500 | V23: 500 | W23: 926.09448 | X23: 5500 | Y23: 70.054839 | Z23: 89.451613 | AA23: 3500 | AB23: 0 | AC23: 2901.4806 | AD23: 0 | AE23: 2020.8603 | AF23: 678.7 | AG23: 7121.8519 | AH23: 2943.8768 | AI23: 2043.2745 | AJ23: 1439.5303 | AK23: 260.97419 | AL23: 11007.047 | AM23: 2999.5448 | AN23: 3799.6742 | AO23: 5500 | AP23: 24000 | AQ23: 8000 | AR23: 2105.6477 | AS23: 0 | AT23: 0 | AU23: 726.81516 | AV23: 0 | AW23: 3018.0416 | AX23: 2044.9997 | AY23: 369.61071 | AZ23: 3500 | BA23: 1121.9003 | BB23: 1500 | BC23: 2549.7026 | BD23: 0 | BE23: 0
B24: =B23+1 -> 46037 | C24: =TEXT(B24,"ddd") -> Kam | D24: =SUM(E24:BE24) -> 165505.47 | E24: 812.17 | F24: 3000 | G24: 1129.7313 | H24: 3282.5161 | I24: 644.02065 | J24: 5500 | K24: 166.97065 | L24: 603.76323 | M24: 673.27548 | N24: 4514.199 | O24: 6823.0623 | P24: 2874.3265 | Q24: 11659.555 | R24: 3600 | S24: 8706.0571 | T24: 5776.6897 | U24: 3500 | V24: 500 | W24: 926.09448 | X24: 5500 | Y24: 70.054839 | Z24: 89.451613 | AA24: 3500 | AB24: 0 | AC24: 2901.4806 | AD24: 0 | AE24: 2020.8603 | AF24: 678.7 | AG24: 7121.8519 | AH24: 2943.8768 | AI24: 2043.2745 | AJ24: 1439.5303 | AK24: 260.97419 | AL24: 11007.047 | AM24: 2999.5448 | AN24: 3799.6742 | AO24: 5500 | AP24: 24000 | AQ24: 8000 | AR24: 2105.6477 | AS24: 0 | AT24: 0 | AU24: 726.81516 | AV24: 0 | AW24: 3018.0416 | AX24: 2044.9997 | AY24: 369.61071 | AZ24: 3500 | BA24: 1121.9003 | BB24: 1500 | BC24: 2549.7026 | BD24: 0 | BE24: 0
B25: =B24+1 -> 46038 | C25: =TEXT(B25,"ddd") -> Jum | D25: =SUM(E25:BE25) -> 165505.47 | E25: 812.17 | F25: 3000 | G25: 1129.7313 | H25: 3282.5161 | I25: 644.02065 | J25: 5500 | K25: 166.97065 | L25: 603.76323 | M25: 673.27548 | N25: 4514.199 | O25: 6823.0623 | P25: 2874.3265 | Q25: 11659.555 | R25: 3600 | S25: 8706.0571 | T25: 5776.6897 | U25: 3500 | V25: 500 | W25: 926.09448 | X25: 5500 | Y25: 70.054839 | Z25: 89.451613 | AA25: 3500 | AB25: 0 | AC25: 2901.4806 | AD25: 0 | AE25: 2020.8603 | AF25: 678.7 | AG25: 7121.8519 | AH25: 2943.8768 | AI25: 2043.2745 | AJ25: 1439.5303 | AK25: 260.97419 | AL25: 11007.047 | AM25: 2999.5448 | AN25: 3799.6742 | AO25: 5500 | AP25: 24000 | AQ25: 8000 | AR25: 2105.6477 | AS25: 0 | AT25: 0 | AU25: 726.81516 | AV25: 0 | AW25: 3018.0416 | AX25: 2044.9997 | AY25: 369.61071 | AZ25: 3500 | BA25: 1121.9003 | BB25: 1500 | BC25: 2549.7026 | BD25: 0 | BE25: 0
B26: =B25+1 -> 46039 | C26: =TEXT(B26,"ddd") -> Sab | D26: =SUM(E26:BE26) -> 165505.47 | E26: 812.17 | F26: 3000 | G26: 1129.7313 | H26: 3282.5161 | I26: 644.02065 | J26: 5500 | K26: 166.97065 | L26: 603.76323 | M26: 673.27548 | N26: 4514.199 | O26: 6823.0623 | P26: 2874.3265 | Q26: 11659.555 | R26: 3600 | S26: 8706.0571 | T26: 5776.6897 | U26: 3500 | V26: 500 | W26: 926.09448 | X26: 5500 | Y26: 70.054839 | Z26: 89.451613 | AA26: 3500 | AB26: 0 | AC26: 2901.4806 | AD26: 0 | AE26: 2020.8603 | AF26: 678.7 | AG26: 7121.8519 | AH26: 2943.8768 | AI26: 2043.2745 | AJ26: 1439.5303 | AK26: 260.97419 | AL26: 11007.047 | AM26: 2999.5448 | AN26: 3799.6742 | AO26: 5500 | AP26: 24000 | AQ26: 8000 | AR26: 2105.6477 | AS26: 0 | AT26: 0 | AU26: 726.81516 | AV26: 0 | AW26: 3018.0416 | AX26: 2044.9997 | AY26: 369.61071 | AZ26: 3500 | BA26: 1121.9003 | BB26: 1500 | BC26: 2549.7026 | BD26: 0 | BE26: 0
B27: =B26+1 -> 46040 | C27: =TEXT(B27,"ddd") -> Mgg | D27: =SUM(E27:BE27) -> 165505.47 | E27: 812.17 | F27: 3000 | G27: 1129.7313 | H27: 3282.5161 | I27: 644.02065 | J27: 5500 | K27: 166.97065 | L27: 603.76323 | M27: 673.27548 | N27: 4514.199 | O27: 6823.0623 | P27: 2874.3265 | Q27: 11659.555 | R27: 3600 | S27: 8706.0571 | T27: 5776.6897 | U27: 3500 | V27: 500 | W27: 926.09448 | X27: 5500 | Y27: 70.054839 | Z27: 89.451613 | AA27: 3500 | AB27: 0 | AC27: 2901.4806 | AD27: 0 | AE27: 2020.8603 | AF27: 678.7 | AG27: 7121.8519 | AH27: 2943.8768 | AI27: 2043.2745 | AJ27: 1439.5303 | AK27: 260.97419 | AL27: 11007.047 | AM27: 2999.5448 | AN27: 3799.6742 | AO27: 5500 | AP27: 24000 | AQ27: 8000 | AR27: 2105.6477 | AS27: 0 | AT27: 0 | AU27: 726.81516 | AV27: 0 | AW27: 3018.0416 | AX27: 2044.9997 | AY27: 369.61071 | AZ27: 3500 | BA27: 1121.9003 | BB27: 1500 | BC27: 2549.7026 | BD27: 0 | BE27: 0
B28: Sub Total | D28: =SUM(D21:D27) -> 1158538.3 | E28: =SUM(E21:E27) -> 5685.19 | F28: =SUM(F21:F27) -> 21000 | G28: =SUM(G21:G27) -> 7908.119 | H28: =SUM(H21:H27) -> 22977.613 | I28: =SUM(I21:I27) -> 4508.1445 | J28: =SUM(J21:J27) -> 38500 | K28: =SUM(K21:K27) -> 1168.7945 | ... BE28: =SUM(BE21:BE27) -> 0
A30: =WEEKNUM(B32) -> 4 | B30: =B27+1 -> 46041 | C30: =TEXT(B30,"ddd") -> Sen | D30: =SUM(E30:BE30) -> 165505.47 | E30: 812.17 | F30: 3000 | G30: 1129.7313 | H30: 3282.5161 | I30: 644.02065 | J30: 5500 | K30: 166.97065 | L30: 603.76323 | M30: 673.27548 | N30: 4514.199 | O30: 6823.0623 | P30: 2874.3265 | Q30: 11659.555 | R30: 3600 | S30: 8706.0571 | T30: 5776.6897 | U30: 3500 | V30: 500 | W30: 926.09448 | X30: 5500 | Y30: 70.054839 | Z30: 89.451613 | AA30: 3500 | AB30: 0 | AC30: 2901.4806 | AD30: 0 | AE30: 2020.8603 | AF30: 678.7 | AG30: 7121.8519 | AH30: 2943.8768 | AI30: 2043.2745 | AJ30: 1439.5303 | AK30: 260.97419 | AL30: 11007.047 | AM30: 2999.5448 | AN30: 3799.6742 | AO30: 5500 | AP30: 24000 | AQ30: 8000 | AR30: 2105.6477 | AS30: 0 | AT30: 0 | AU30: 726.81516 | AV30: 0 | AW30: 3018.0416 | AX30: 2044.9997 | AY30: 369.61071 | AZ30: 3500 | BA30: 1121.9003 | BB30: 1500 | BC30: 2549.7026 | BD30: 0 | BE30: 0
B31: =B30+1 -> 46042 | C31: =TEXT(B31,"ddd") -> Sel | D31: =SUM(E31:BE31) -> 165505.47 | E31: 812.17 | F31: 3000 | G31: 1129.7313 | H31: 3282.5161 | I31: 644.02065 | J31: 5500 | K31: 166.97065 | L31: 603.76323 | M31: 673.27548 | N31: 4514.199 | O31: 6823.0623 | P31: 2874.3265 | Q31: 11659.555 | R31: 3600 | S31: 8706.0571 | T31: 5776.6897 | U31: 3500 | V31: 500 | W31: 926.09448 | X31: 5500 | Y31: 70.054839 | Z31: 89.451613 | AA31: 3500 | AB31: 0 | AC31: 2901.4806 | AD31: 0 | AE31: 2020.8603 | AF31: 678.7 | AG31: 7121.8519 | AH31: 2943.8768 | AI31: 2043.2745 | AJ31: 1439.5303 | AK31: 260.97419 | AL31: 11007.047 | AM31: 2999.5448 | AN31: 3799.6742 | AO31: 5500 | AP31: 24000 | AQ31: 8000 | AR31: 2105.6477 | AS31: 0 | AT31: 0 | AU31: 726.81516 | AV31: 0 | AW31: 3018.0416 | AX31: 2044.9997 | AY31: 369.61071 | AZ31: 3500 | BA31: 1121.9003 | BB31: 1500 | BC31: 2549.7026 | BD31: 0 | BE31: 0
B32: =B31+1 -> 46043 | C32: =TEXT(B32,"ddd") -> Rab | D32: =SUM(E32:BE32) -> 165505.47 | E32: 812.17 | F32: 3000 | G32: 1129.7313 | H32: 3282.5161 | I32: 644.02065 | J32: 5500 | K32: 166.97065 | L32: 603.76323 | M32: 673.27548 | N32: 4514.199 | O32: 6823.0623 | P32: 2874.3265 | Q32: 11659.555 | R32: 3600 | S32: 8706.0571 | T32: 5776.6897 | U32: 3500 | V32: 500 | W32: 926.09448 | X32: 5500 | Y32: 70.054839 | Z32: 89.451613 | AA32: 3500 | AB32: 0 | AC32: 2901.4806 | AD32: 0 | AE32: 2020.8603 | AF32: 678.7 | AG32: 7121.8519 | AH32: 2943.8768 | AI32: 2043.2745 | AJ32: 1439.5303 | AK32: 260.97419 | AL32: 11007.047 | AM32: 2999.5448 | AN32: 3799.6742 | AO32: 5500 | AP32: 24000 | AQ32: 8000 | AR32: 2105.6477 | AS32: 0 | AT32: 0 | AU32: 726.81516 | AV32: 0 | AW32: 3018.0416 | AX32: 2044.9997 | AY32: 369.61071 | AZ32: 3500 | BA32: 1121.9003 | BB32: 1500 | BC32: 2549.7026 | BD32: 0 | BE32: 0
B33: =B32+1 -> 46044 | C33: =TEXT(B33,"ddd") -> Kam | D33: =SUM(E33:BE33) -> 165505.47 | E33: 812.17 | F33: 3000 | G33: 1129.7313 | H33: 3282.5161 | I33: 644.02065 | J33: 5500 | K33: 166.97065 | L33: 603.76323 | M33: 673.27548 | N33: 4514.199 | O33: 6823.0623 | P33: 2874.3265 | Q33: 11659.555 | R33: 3600 | S33: 8706.0571 | T33: 5776.6897 | U33: 3500 | V33: 500 | W33: 926.09448 | X33: 5500 | Y33: 70.054839 | Z33: 89.451613 | AA33: 3500 | AB33: 0 | AC33: 2901.4806 | AD33: 0 | AE33: 2020.8603 | AF33: 678.7 | AG33: 7121.8519 | AH33: 2943.8768 | AI33: 2043.2745 | AJ33: 1439.5303 | AK33: 260.97419 | AL33: 11007.047 | AM33: 2999.5448 | AN33: 3799.6742 | AO33: 5500 | AP33: 24000 | AQ33: 8000 | AR33: 2105.6477 | AS33: 0 | AT33: 0 | AU33: 726.81516 | AV33: 0 | AW33: 3018.0416 | AX33: 2044.9997 | AY33: 369.61071 | AZ33: 3500 | BA33: 1121.9003 | BB33: 1500 | BC33: 2549.7026 | BD33: 0 | BE33: 0
B34: =B33+1 -> 46045 | C34: =TEXT(B34,"ddd") -> Jum | D34: =SUM(E34:BE34) -> 165505.47 | E34: 812.17 | F34: 3000 | G34: 1129.7313 | H34: 3282.5161 | I34: 644.02065 | J34: 5500 | K34: 166.97065 | L34: 603.76323 | M34: 673.27548 | N34: 4514.199 | O34: 6823.0623 | P34: 2874.3265 | Q34: 11659.555 | R34: 3600 | S34: 8706.0571 | T34: 5776.6897 | U34: 3500 | V34: 500 | W34: 926.09448 | X34: 5500 | Y34: 70.054839 | Z34: 89.451613 | AA34: 3500 | AB34: 0 | AC34: 2901.4806 | AD34: 0 | AE34: 2020.8603 | AF34: 678.7 | AG34: 7121.8519 | AH34: 2943.8768 | AI34: 2043.2745 | AJ34: 1439.5303 | AK34: 260.97419 | AL34: 11007.047 | AM34: 2999.5448 | AN34: 3799.6742 | AO34: 5500 | AP34: 24000 | AQ34: 8000 | AR34: 2105.6477 | AS34: 0 | AT34: 0 | AU34: 726.81516 | AV34: 0 | AW34: 3018.0416 | AX34: 2044.9997 | AY34: 369.61071 | AZ34: 3500 | BA34: 1121.9003 | BB34: 1500 | BC34: 2549.7026 | BD34: 0 | BE34: 0
B35: =B34+1 -> 46046 | C35: =TEXT(B35,"ddd") -> Sab | D35: =SUM(E35:BE35) -> 165505.47 | E35: 812.17 | F35: 3000 | G35: 1129.7313 | H35: 3282.5161 | I35: 644.02065 | J35: 5500 | K35: 166.97065 | L35: 603.76323 | M35: 673.27548 | N35: 4514.199 | O35: 6823.0623 | P35: 2874.3265 | Q35: 11659.555 | R35: 3600 | S35: 8706.0571 | T35: 5776.6897 | U35: 3500 | V35: 500 | W35: 926.09448 | X35: 5500 | Y35: 70.054839 | Z35: 89.451613 | AA35: 3500 | AB35: 0 | AC35: 2901.4806 | AD35: 0 | AE35: 2020.8603 | AF35: 678.7 | AG35: 7121.8519 | AH35: 2943.8768 | AI35: 2043.2745 | AJ35: 1439.5303 | AK35: 260.97419 | AL35: 11007.047 | AM35: 2999.5448 | AN35: 3799.6742 | AO35: 5500 | AP35: 24000 | AQ35: 8000 | AR35: 2105.6477 | AS35: 0 | AT35: 0 | AU35: 726.81516 | AV35: 0 | AW35: 3018.0416 | AX35: 2044.9997 | AY35: 369.61071 | AZ35: 3500 | BA35: 1121.9003 | BB35: 1500 | BC35: 2549.7026 | BD35: 0 | BE35: 0
B36: =B35+1 -> 46047 | C36: =TEXT(B36,"ddd") -> Mgg | D36: =SUM(E36:BE36) -> 165505.47 | E36: 812.17 | F36: 3000 | G36: 1129.7313 | H36: 3282.5161 | I36: 644.02065 | J36: 5500 | K36: 166.97065 | L36: 603.76323 | M36: 673.27548 | N36: 4514.199 | O36: 6823.0623 | P36: 2874.3265 | Q36: 11659.555 | R36: 3600 | S36: 8706.0571 | T36: 5776.6897 | U36: 3500 | V36: 500 | W36: 926.09448 | X36: 5500 | Y36: 70.054839 | Z36: 89.451613 | AA36: 3500 | AB36: 0 | AC36: 2901.4806 | AD36: 0 | AE36: 2020.8603 | AF36: 678.7 | AG36: 7121.8519 | AH36: 2943.8768 | AI36: 2043.2745 | AJ36: 1439.5303 | AK36: 260.97419 | AL36: 11007.047 | AM36: 2999.5448 | AN36: 3799.6742 | AO36: 5500 | AP36: 24000 | AQ36: 8000 | AR36: 2105.6477 | AS36: 0 | AT36: 0 | AU36: 726.81516 | AV36: 0 | AW36: 3018.0416 | AX36: 2044.9997 | AY36: 369.61071 | AZ36: 3500 | BA36: 1121.9003 | BB36: 1500 | BC36: 2549.7026 | BD36: 0 | BE36: 0
B37: Sub Total | D37: =SUM(D30:D36) -> 1158538.3 | E37: =SUM(E30:E36) -> 5685.19 | F37: =SUM(F30:F36) -> 21000 | G37: =SUM(G30:G36) -> 7908.119 | H37: =SUM(H30:H36) -> 22977.613 | I37: =SUM(I30:I36) -> 4508.1445 | J37: =SUM(J30:J36) -> 38500 | K37: =SUM(K30:K36) -> 1168.7945 | ... BE37: =SUM(BE30:BE36) -> 0
A39: =WEEKNUM(B41) -> 5 | B39: =B36+1 -> 46048 | C39: =TEXT(B39,"ddd") -> Sen | D39: =SUM(E39:BE39) -> 165505.47 | E39: 812.17 | F39: 3000 | G39: 1129.7313 | H39: 3282.5161 | I39: 644.02065 | J39: 5500 | K39: 166.97065 | L39: 603.76323 | M39: 673.27548 | N39: 4514.199 | O39: 6823.0623 | P39: 2874.3265 | Q39: 11659.555 | R39: 3600 | S39: 8706.0571 | T39: 5776.6897 | U39: 3500 | V39: 500 | W39: 926.09448 | X39: 5500 | Y39: 70.054839 | Z39: 89.451613 | AA39: 3500 | AB39: 0 | AC39: 2901.4806 | AD39: 0 | AE39: 2020.8603 | AF39: 678.7 | AG39: 7121.8519 | AH39: 2943.8768 | AI39: 2043.2745 | AJ39: 1439.5303 | AK39: 260.97419 | AL39: 11007.047 | AM39: 2999.5448 | AN39: 3799.6742 | AO39: 5500 | AP39: 24000 | AQ39: 8000 | AR39: 2105.6477 | AS39: 0 | AT39: 0 | AU39: 726.81516 | AV39: 0 | AW39: 3018.0416 | AX39: 2044.9997 | AY39: 369.61071 | AZ39: 3500 | BA39: 1121.9003 | BB39: 1500 | BC39: 2549.7026 | BD39: 0 | BE39: 0
B40: =B39+1 -> 46049 | C40: =TEXT(B40,"ddd") -> Sel | D40: =SUM(E40:BE40) -> 165505.47 | E40: 812.17 | F40: 3000 | G40: 1129.7313 | H40: 3282.5161 | I40: 644.02065 | J40: 5500 | K40: 166.97065 | L40: 603.76323 | M40: 673.27548 | N40: 4514.199 | O40: 6823.0623 | P40: 2874.3265 | Q40: 11659.555 | R40: 3600 | S40: 8706.0571 | T40: 5776.6897 | U40: 3500 | V40: 500 | W40: 926.09448 | X40: 5500 | Y40: 70.054839 | Z40: 89.451613 | AA40: 3500 | AB40: 0 | AC40: 2901.4806 | AD40: 0 | AE40: 2020.8603 | AF40: 678.7 | AG40: 7121.8519 | AH40: 2943.8768 | AI40: 2043.2745 | AJ40: 1439.5303 | AK40: 260.97419 | AL40: 11007.047 | AM40: 2999.5448 | AN40: 3799.6742 | AO40: 5500 | AP40: 24000 | AQ40: 8000 | AR40: 2105.6477 | AS40: 0 | AT40: 0 | AU40: 726.81516 | AV40: 0 | AW40: 3018.0416 | AX40: 2044.9997 | AY40: 369.61071 | AZ40: 3500 | BA40: 1121.9003 | BB40: 1500 | BC40: 2549.7026 | BD40: 0 | BE40: 0
B41: =B40+1 -> 46050 | C41: =TEXT(B41,"ddd") -> Rab | D41: =SUM(E41:BE41) -> 165505.47 | E41: 812.17 | F41: 3000 | G41: 1129.7313 | H41: 3282.5161 | I41: 644.02065 | J41: 5500 | K41: 166.97065 | L41: 603.76323 | M41: 673.27548 | N41: 4514.199 | O41: 6823.0623 | P41: 2874.3265 | Q41: 11659.555 | R41: 3600 | S41: 8706.0571 | T41: 5776.6897 | U41: 3500 | V41: 500 | W41: 926.09448 | X41: 5500 | Y41: 70.054839 | Z41: 89.451613 | AA41: 3500 | AB41: 0 | AC41: 2901.4806 | AD41: 0 | AE41: 2020.8603 | AF41: 678.7 | AG41: 7121.8519 | AH41: 2943.8768 | AI41: 2043.2745 | AJ41: 1439.5303 | AK41: 260.97419 | AL41: 11007.047 | AM41: 2999.5448 | AN41: 3799.6742 | AO41: 5500 | AP41: 24000 | AQ41: 8000 | AR41: 2105.6477 | AS41: 0 | AT41: 0 | AU41: 726.81516 | AV41: 0 | AW41: 3018.0416 | AX41: 2044.9997 | AY41: 369.61071 | AZ41: 3500 | BA41: 1121.9003 | BB41: 1500 | BC41: 2549.7026 | BD41: 0 | BE41: 0
B42: =B41+1 -> 46051 | C42: =TEXT(B42,"ddd") -> Kam | D42: =SUM(E42:BE42) -> 165505.47 | E42: 812.17 | F42: 3000 | G42: 1129.7313 | H42: 3282.5161 | I42: 644.02065 | J42: 5500 | K42: 166.97065 | L42: 603.76323 | M42: 673.27548 | N42: 4514.199 | O42: 6823.0623 | P42: 2874.3265 | Q42: 11659.555 | R42: 3600 | S42: 8706.0571 | T42: 5776.6897 | U42: 3500 | V42: 500 | W42: 926.09448 | X42: 5500 | Y42: 70.054839 | Z42: 89.451613 | AA42: 3500 | AB42: 0 | AC42: 2901.4806 | AD42: 0 | AE42: 2020.8603 | AF42: 678.7 | AG42: 7121.8519 | AH42: 2943.8768 | AI42: 2043.2745 | AJ42: 1439.5303 | AK42: 260.97419 | AL42: 11007.047 | AM42: 2999.5448 | AN42: 3799.6742 | AO42: 5500 | AP42: 24000 | AQ42: 8000 | AR42: 2105.6477 | AS42: 0 | AT42: 0 | AU42: 726.81516 | AV42: 0 | AW42: 3018.0416 | AX42: 2044.9997 | AY42: 369.61071 | AZ42: 3500 | BA42: 1121.9003 | BB42: 1500 | BC42: 2549.7026 | BD42: 0 | BE42: 0
B43: =B42+1 -> 46052 | C43: =TEXT(B43,"ddd") -> Jum | D43: =SUM(E43:BE43) -> 165505.47 | E43: 812.17 | F43: 3000 | G43: 1129.7313 | H43: 3282.5161 | I43: 644.02065 | J43: 5500 | K43: 166.97065 | L43: 603.76323 | M43: 673.27548 | N43: 4514.199 | O43: 6823.0623 | P43: 2874.3265 | Q43: 11659.555 | R43: 3600 | S43: 8706.0571 | T43: 5776.6897 | U43: 3500 | V43: 500 | W43: 926.09448 | X43: 5500 | Y43: 70.054839 | Z43: 89.451613 | AA43: 3500 | AB43: 0 | AC43: 2901.4806 | AD43: 0 | AE43: 2020.8603 | AF43: 678.7 | AG43: 7121.8519 | AH43: 2943.8768 | AI43: 2043.2745 | AJ43: 1439.5303 | AK43: 260.97419 | AL43: 11007.047 | AM43: 2999.5448 | AN43: 3799.6742 | AO43: 5500 | AP43: 24000 | AQ43: 8000 | AR43: 2105.6477 | AS43: 0 | AT43: 0 | AU43: 726.81516 | AV43: 0 | AW43: 3018.0416 | AX43: 2044.9997 | AY43: 369.61071 | AZ43: 3500 | BA43: 1121.9003 | BB43: 1500 | BC43: 2549.7026 | BD43: 0 | BE43: 0
B44: =B43+1 -> 46053 | C44: =TEXT(B44,"ddd") -> Sab | D44: =SUM(E44:BE44) -> 165505.47 | E44: 812.17 | F44: 3000 | G44: 1129.7313 | H44: 3282.5161 | I44: 644.02065 | J44: 5500 | K44: 166.97065 | L44: 603.76323 | M44: 673.27548 | N44: 4514.199 | O44: 6823.0623 | P44: 2874.3265 | Q44: 11659.555 | R44: 3600 | S44: 8706.0571 | T44: 5776.6897 | U44: 3500 | V44: 500 | W44: 926.09448 | X44: 5500 | Y44: 70.054839 | Z44: 89.451613 | AA44: 3500 | AB44: 0 | AC44: 2901.4806 | AD44: 0 | AE44: 2020.8603 | AF44: 678.7 | AG44: 7121.8519 | AH44: 2943.8768 | AI44: 2043.2745 | AJ44: 1439.5303 | AK44: 260.97419 | AL44: 11007.047 | AM44: 2999.5448 | AN44: 3799.6742 | AO44: 5500 | AP44: 24000 | AQ44: 8000 | AR44: 2105.6477 | AS44: 0 | AT44: 0 | AU44: 726.81516 | AV44: 0 | AW44: 3018.0416 | AX44: 2044.9997 | AY44: 369.61071 | AZ44: 3500 | BA44: 1121.9003 | BB44: 1500 | BC44: 2549.7026 | BD44: 0 | BE44: 0
B45: Sub Total | D45: =SUM(D39:D44) -> 993032.82 | E45: =SUM(E39:E44) -> 4873.02 | F45: =SUM(F39:F44) -> 18000 | G45: =SUM(G39:G44) -> 6778.3877 | H45: =SUM(H39:H44) -> 19695.097 | I45: =SUM(I39:I44) -> 3864.1239 | J45: =SUM(J39:J44) -> 33000 | K45: =SUM(K39:K44) -> 1001.8239 | ... BE45: =SUM(BE39:BE44) -> 0
...

Sheet KEBUTUHAN GAS
A1: KEBUTUHAN GAS
A4: ='SO FOB Januari 2026'!A4 -> 46023 | E4: KEBUTUHAN GAS | I4: KUOTA GAS
A5: Week | B5: DATE | D5: SELISIH GAS | E5: JABAR | F5: JATENG | G5: JATIM | H5: TOTAL | I5: MS SETU | J5: MS KHT | K5: MS BLORA | L5: MS BITUNG | M5: MS ZEBRA | N5: MS TAMBAKLOROK | O5: MS SAG | P5: MS SADANG | Q5: TOTAL
A6: =WEEKNUM(B6) -> 1 | B6: 46023 | C6: =TEXT(B6,"ddd") -> Kam | D6: =Q6-H6 -> -31591.938 | E6: =SUM('SO Januari 2026 rev.2'!E6:AR6) -> 127260.87 | F6: =SUM('SO Januari 2026 rev.2'!AU6:BC6) -> 18331.07 | G6: =SUM('SO Januari 2026 rev.2'!BD6:BE6) -> 0 | H6: =SUM(E6:G6) -> 145591.94 | I6: ='SO MS'!E6 -> 60000 | J6: ='SO MS'!F6 -> 43200 | K6: ='SO MS'!G6 -> 10800 | L6: ='SO MS'!H6 -> 0 | M6: ='SO MS'!I6 -> 0 | N6: ='SO MS'!J6 -> 0 | O6: ='SO MS'!K6 -> 0 | P6: ='SO MS'!L6 -> 0 | Q6: =SUM(I6:P6) -> 114000
B7: =B6+1 -> 46024 | C7: =TEXT(B7,"ddd") -> Jum | D7: =Q7-H7 -> -39026.265 | E7: =SUM('SO Januari 2026 rev.2'!E7:AR7) -> 130135.19 | F7: =SUM('SO Januari 2026 rev.2'!AU7:BC7) -> 18331.07 | G7: =SUM('SO Januari 2026 rev.2'!BD7:BE7) -> 0 | H7: =SUM(E7:G7) -> 148466.26 | I7: ='SO MS'!E7 -> 60000 | J7: ='SO MS'!F7 -> 38640 | K7: ='SO MS'!G7 -> 10800 | L7: ='SO MS'!H7 -> 0 | M7: ='SO MS'!I7 -> 0 | N7: ='SO MS'!J7 -> 0 | O7: ='SO MS'!K7 -> 0 | P7: ='SO MS'!L7 -> 0 | Q7: =SUM(I7:P7) -> 109440
B8: =B7+1 -> 46025 | C8: =TEXT(B8,"ddd") -> Sab | D8: =Q8-H8 -> -38422.501 | E8: =SUM('SO Januari 2026 rev.2'!E8:AR8) -> 129531.43 | F8: =SUM('SO Januari 2026 rev.2'!AU8:BC8) -> 18331.07 | G8: =SUM('SO Januari 2026 rev.2'!BD8:BE8) -> 0 | H8: =SUM(E8:G8) -> 147862.5 | I8: ='SO MS'!E8 -> 60000 | J8: ='SO MS'!F8 -> 38640 | K8: ='SO MS'!G8 -> 10800 | L8: ='SO MS'!H8 -> 0 | M8: ='SO MS'!I8 -> 0 | N8: ='SO MS'!J8 -> 0 | O8: ='SO MS'!K8 -> 0 | P8: ='SO MS'!L8 -> 0 | Q8: =SUM(I8:P8) -> 109440
B9: =B8+1 -> 46026 | C9: =TEXT(B9,"ddd") -> Mgg | D9: =Q9-H9 -> -41526.265 | E9: =SUM('SO Januari 2026 rev.2'!E9:AR9) -> 132635.19 | F9: =SUM('SO Januari 2026 rev.2'!AU9:BC9) -> 18331.07 | G9: =SUM('SO Januari 2026 rev.2'!BD9:BE9) -> 0 | H9: =SUM(E9:G9) -> 150966.26 | I9: ='SO MS'!E9 -> 60000 | J9: ='SO MS'!F9 -> 38640 | K9: ='SO MS'!G9 -> 10800 | L9: ='SO MS'!H9 -> 0 | M9: ='SO MS'!I9 -> 0 | N9: ='SO MS'!J9 -> 0 | O9: ='SO MS'!K9 -> 0 | P9: ='SO MS'!L9 -> 0 | Q9: =SUM(I9:P9) -> 109440
B10: Sub Total | D10: =SUM(D6:D9) -> -150566.97 | E10: =SUM(E6:E9) -> 519562.69 | F10: =SUM(F6:F9) -> 73324.28 | G10: =SUM(G6:G9) -> 0 | H10: =SUM(H6:H9) -> 592886.97 | I10: =SUM(I6:I9) -> 240000 | J10: =SUM(J6:J9) -> 159120 | K10: =SUM(K6:K9) -> 43200 | ... Q10: =SUM(Q6:Q9) -> 442320
A12: =WEEKNUM(B13) -> 2 | B12: =B9+1 -> 46027 | C12: =TEXT(B12,"ddd") -> Sen | D12: =Q12-H12 -> -56145.47 | E12: =SUM('SO Januari 2026 rev.2'!E12:AR12) -> 146674.4 | F12: =SUM('SO Januari 2026 rev.2'!AU12:BC12) -> 14831.07 | G12: =SUM('SO Januari 2026 rev.2'!BD12:BE12) -> 0 | H12: =SUM(E12:G12) -> 161505.47 | I12: ='SO MS'!E12 -> 60000 | J12: ='SO MS'!F12 -> 34560 | K12: ='SO MS'!G12 -> 10800 | L12: ='SO MS'!H12 -> 0 | M12: ='SO MS'!I12 -> 0 | N12: ='SO MS'!J12 -> 0 | O12: ='SO MS'!K12 -> 0 | P12: ='SO MS'!L12 -> 0 | Q12: =SUM(I12:P12) -> 105360
B13: =B12+1 -> 46028 | C13: =TEXT(B13,"ddd") -> Sel | D13: =Q13-H13 -> -48039.823 | E13: =SUM('SO Januari 2026 rev.2'!E13:AR13)-'SO Januari 2026 rev.2'!U13 -> 147174.4 | F13: =SUM('SO Januari 2026 rev.2'!AU13:BC13)+'SO Januari 2026 rev.2'!U13 -> 18331.07 | G13: =SUM('SO Januari 2026 rev.2'!BD13:BE13) -> 0 | H13: =SUM(E13:G13) -> 165505.47 | I13: ='SO MS'!E13 -> 60000 | J13: ='SO MS'!F13 -> 34560 | K13: ='SO MS'!G13 -> 10800 | L13: ='SO MS'!H13 -> 10000 | M13: ='SO MS'!I13 -> 0 | N13: ='SO MS'!J13 -> 2105.6477 | O13: ='SO MS'!K13 -> 0 | P13: ='SO MS'!L13 -> 0 | Q13: =SUM(I13:P13) -> 117465.65
B14: =B13+1 -> 46029 | C14: =TEXT(B14,"ddd") -> Rab | D14: =Q14-H14 -> -43039.823 | E14: =SUM('SO Januari 2026 rev.2'!E14:AR14)-'SO Januari 2026 rev.2'!U14 -> 147174.4 | F14: =SUM('SO Januari 2026 rev.2'!AU14:BC14)+'SO Januari 2026 rev.2'!U14 -> 18331.07 | G14: =SUM('SO Januari 2026 rev.2'!BD14:BE14) -> 0 | H14: =SUM(E14:G14) -> 165505.47 | I14: ='SO MS'!E14 -> 60000 | J14: ='SO MS'!F14 -> 34560 | K14: ='SO MS'!G14 -> 10800 | L14: ='SO MS'!H14 -> 10000 | M14: ='SO MS'!I14 -> 0 | N14: ='SO MS'!J14 -> 2105.6477 | O14: ='SO MS'!K14 -> 5000 | P14: ='SO MS'!L14 -> 0 | Q14: =SUM(I14:P14) -> 122465.65
B15: =B14+1 -> 46030 | C15: =TEXT(B15,"ddd") -> Kam | D15: =Q15-H15 -> -43039.823 | E15: =SUM('SO Januari 2026 rev.2'!E15:AR15)-'SO Januari 2026 rev.2'!U15 -> 147174.4 | F15: =SUM('SO Januari 2026 rev.2'!AU15:BC15)+'SO Januari 2026 rev.2'!U15 -> 18331.07 | G15: =SUM('SO Januari 2026 rev.2'!BD15:BE15) -> 0 | H15: =SUM(E15:G15) -> 165505.47 | I15: ='SO MS'!E15 -> 60000 | J15: ='SO MS'!F15 -> 34560 | K15: ='SO MS'!G15 -> 10800 | L15: ='SO MS'!H15 -> 10000 | M15: ='SO MS'!I15 -> 0 | N15: ='SO MS'!J15 -> 2105.6477 | O15: ='SO MS'!K15 -> 5000 | P15: ='SO MS'!L15 -> 0 | Q15: =SUM(I15:P15) -> 122465.65
B16: =B15+1 -> 46031 | C16: =TEXT(B16,"ddd") -> Jum | D16: =Q16-H16 -> -43039.823 | E16: =SUM('SO Januari 2026 rev.2'!E16:AR16)-'SO Januari 2026 rev.2'!U16 -> 147174.4 | F16: =SUM('SO Januari 2026 rev.2'!AU16:BC16)+'SO Januari 2026 rev.2'!U16 -> 18331.07 | G16: =SUM('SO Januari 2026 rev.2'!BD16:BE16) -> 0 | H16: =SUM(E16:G16) -> 165505.47 | I16: ='SO MS'!E16 -> 60000 | J16: ='SO MS'!F16 -> 34560 | K16: ='SO MS'!G16 -> 10800 | L16: ='SO MS'!H16 -> 10000 | M16: ='SO MS'!I16 -> 0 | N16: ='SO MS'!J16 -> 2105.6477 | O16: ='SO MS'!K16 -> 5000 | P16: ='SO MS'!L16 -> 0 | Q16: =SUM(I16:P16) -> 122465.65
B17: =B16+1 -> 46032 | C17: =TEXT(B17,"ddd") -> Sab | D17: =Q17-H17 -> -43039.823 | E17: =SUM('SO Januari 2026 rev.2'!E17:AR17)-'SO Januari 2026 rev.2'!U17 -> 147174.4 | F17: =SUM('SO Januari 2026 rev.2'!AU17:BC17)+'SO Januari 2026 rev.2'!U17 -> 18331.07 | G17: =SUM('SO Januari 2026 rev.2'!BD17:BE17) -> 0 | H17: =SUM(E17:G17) -> 165505.47 | I17: ='SO MS'!E17 -> 60000 | J17: ='SO MS'!F17 -> 34560 | K17: ='SO MS'!G17 -> 10800 | L17: ='SO MS'!H17 -> 10000 | M17: ='SO MS'!I17 -> 0 | N17: ='SO MS'!J17 -> 2105.6477 | O17: ='SO MS'!K17 -> 5000 | P17: ='SO MS'!L17 -> 0 | Q17: =SUM(I17:P17) -> 122465.65
B18: =B17+1 -> 46033 | C18: =TEXT(B18,"ddd") -> Mgg | D18: =Q18-H18 -> -43039.823 | E18: =SUM('SO Januari 2026 rev.2'!E18:AR18)-'SO Januari 2026 rev.2'!U18 -> 147174.4 | F18: =SUM('SO Januari 2026 rev.2'!AU18:BC18)+'SO Januari 2026 rev.2'!U18 -> 18331.07 | G18: =SUM('SO Januari 2026 rev.2'!BD18:BE18) -> 0 | H18: =SUM(E18:G18) -> 165505.47 | I18: ='SO MS'!E18 -> 60000 | J18: ='SO MS'!F18 -> 34560 | K18: ='SO MS'!G18 -> 10800 | L18: ='SO MS'!H18 -> 10000 | M18: ='SO MS'!I18 -> 0 | N18: ='SO MS'!J18 -> 2105.6477 | O18: ='SO MS'!K18 -> 5000 | P18: ='SO MS'!L18 -> 0 | Q18: =SUM(I18:P18) -> 122465.65
B19: Sub Total | D19: =SUM(D12:D18) -> -319384.41 | E19: =SUM(E12:E18) -> 1029720.8 | F19: =SUM(F12:F18) -> 124817.49 | G19: =SUM(G12:G18) -> 0 | H19: =SUM(H12:H18) -> 1154538.3 | I19: =SUM(I12:I18) -> 420000 | J19: =SUM(J12:J18) -> 241920 | K19: =SUM(K12:K18) -> 75600 | ... Q19: =SUM(Q12:Q18) -> 835153.89
A21: =WEEKNUM(B22) -> 3 | B21: =B18+1 -> 46034 | C21: =TEXT(B21,"ddd") -> Sen | D21: =Q21-H21 -> -43039.823 | E21: =SUM('SO Januari 2026 rev.2'!E21:AR21)-'SO Januari 2026 rev.2'!U21 -> 147174.4 | F21: =SUM('SO Januari 2026 rev.2'!AU21:BC21)+'SO Januari 2026 rev.2'!U21 -> 18331.07 | G21: =SUM('SO Januari 2026 rev.2'!BD21:BE21) -> 0 | H21: =SUM(E21:G21) -> 165505.47 | I21: ='SO MS'!E21 -> 60000 | J21: ='SO MS'!F21 -> 34560 | K21: ='SO MS'!G21 -> 10800 | L21: ='SO MS'!H21 -> 10000 | M21: ='SO MS'!I21 -> 0 | N21: ='SO MS'!J21 -> 2105.6477 | O21: ='SO MS'!K21 -> 5000 | P21: ='SO MS'!L21 -> 0 | Q21: =SUM(I21:P21) -> 122465.65
B22: =B21+1 -> 46035 | C22: =TEXT(B22,"ddd") -> Sel | D22: =Q22-H22 -> -48039.823 | E22: =SUM('SO Januari 2026 rev.2'!E22:AR22)-'SO Januari 2026 rev.2'!U22 -> 147174.4 | F22: =SUM('SO Januari 2026 rev.2'!AU22:BC22)+'SO Januari 2026 rev.2'!U22 -> 18331.07 | G22: =SUM('SO Januari 2026 rev.2'!BD22:BE22) -> 0 | H22: =SUM(E22:G22) -> 165505.47 | I22: ='SO MS'!E22 -> 60000 | J22: ='SO MS'!F22 -> 34560 | K22: ='SO MS'!G22 -> 10800 | L22: ='SO MS'!H22 -> 10000 | M22: ='SO MS'!I22 -> 0 | N22: ='SO MS'!J22 -> 2105.6477 | O22: ='SO MS'!K22 -> 0 | P22: ='SO MS'!L22 -> 0 | Q22: =SUM(I22:P22) -> 117465.65
B23: =B22+1 -> 46036 | C23: =TEXT(B23,"ddd") -> Rab | D23: =Q23-H23 -> -48039.823 | E23: =SUM('SO Januari 2026 rev.2'!E23:AR23)-'SO Januari 2026 rev.2'!U23 -> 147174.4 | F23: =SUM('SO Januari 2026 rev.2'!AU23:BC23)+'SO Januari 2026 rev.2'!U23 -> 18331.07 | G23: =SUM('SO Januari 2026 rev.2'!BD23:BE23) -> 0 | H23: =SUM(E23:G23) -> 165505.47 | I23: ='SO MS'!E23 -> 60000 | J23: ='SO MS'!F23 -> 34560 | K23: ='SO MS'!G23 -> 10800 | L23: ='SO MS'!H23 -> 10000 | M23: ='SO MS'!I23 -> 0 | N23: ='SO MS'!J23 -> 2105.6477 | O23: ='SO MS'!K23 -> 0 | P23: ='SO MS'!L23 -> 0 | Q23: =SUM(I23:P23) -> 117465.65
B24: =B23+1 -> 46037 | C24: =TEXT(B24,"ddd") -> Kam | D24: =Q24-H24 -> -48039.823 | E24: =SUM('SO Januari 2026 rev.2'!E24:AR24)-'SO Januari 2026 rev.2'!U24 -> 147174.4 | F24: =SUM('SO Januari 2026 rev.2'!AU24:BC24)+'SO Januari 2026 rev.2'!U24 -> 18331.07 | G24: =SUM('SO Januari 2026 rev.2'!BD24:BE24) -> 0 | H24: =SUM(E24:G24) -> 165505.47 | I24: ='SO MS'!E24 -> 60000 | J24: ='SO MS'!F24 -> 34560 | K24: ='SO MS'!G24 -> 10800 | L24: ='SO MS'!H24 -> 10000 | M24: ='SO MS'!I24 -> 0 | N24: ='SO MS'!J24 -> 2105.6477 | O24: ='SO MS'!K24 -> 0 | P24: ='SO MS'!L24 -> 0 | Q24: =SUM(I24:P24) -> 117465.65
B25: =B24+1 -> 46038 | C25: =TEXT(B25,"ddd") -> Jum | D25: =Q25-H25 -> -48039.823 | E25: =SUM('SO Januari 2026 rev.2'!E25:AR25)-'SO Januari 2026 rev.2'!U25 -> 147174.4 | F25: =SUM('SO Januari 2026 rev.2'!AU25:BC25)+'SO Januari 2026 rev.2'!U25 -> 18331.07 | G25: =SUM('SO Januari 2026 rev.2'!BD25:BE25) -> 0 | H25: =SUM(E25:G25) -> 165505.47 | I25: ='SO MS'!E25 -> 60000 | J25: ='SO MS'!F25 -> 34560 | K25: ='SO MS'!G25 -> 10800 | L25: ='SO MS'!H25 -> 10000 | M25: ='SO MS'!I25 -> 0 | N25: ='SO MS'!J25 -> 2105.6477 | O25: ='SO MS'!K25 -> 0 | P25: ='SO MS'!L25 -> 0 | Q25: =SUM(I25:P25) -> 117465.65
B26: =B25+1 -> 46039 | C26: =TEXT(B26,"ddd") -> Sab | D26: =Q26-H26 -> -48039.823 | E26: =SUM('SO Januari 2026 rev.2'!E26:AR26)-'SO Januari 2026 rev.2'!U26 -> 147174.4 | F26: =SUM('SO Januari 2026 rev.2'!AU26:BC26)+'SO Januari 2026 rev.2'!U26 -> 18331.07 | G26: =SUM('SO Januari 2026 rev.2'!BD26:BE26) -> 0 | H26: =SUM(E26:G26) -> 165505.47 | I26: ='SO MS'!E26 -> 60000 | J26: ='SO MS'!F26 -> 34560 | K26: ='SO MS'!G26 -> 10800 | L26: ='SO MS'!H26 -> 10000 | M26: ='SO MS'!I26 -> 0 | N26: ='SO MS'!J26 -> 2105.6477 | O26: ='SO MS'!K26 -> 0 | P26: ='SO MS'!L26 -> 0 | Q26: =SUM(I26:P26) -> 117465.65
B27: =B26+1 -> 46040 | C27: =TEXT(B27,"ddd") -> Mgg | D27: =Q27-H27 -> -48039.823 | E27: =SUM('SO Januari 2026 rev.2'!E27:AR27)-'SO Januari 2026 rev.2'!U27 -> 147174.4 | F27: =SUM('SO Januari 2026 rev.2'!AU27:BC27)+'SO Januari 2026 rev.2'!U27 -> 18331.07 | G27: =SUM('SO Januari 2026 rev.2'!BD27:BE27) -> 0 | H27: =SUM(E27:G27) -> 165505.47 | I27: ='SO MS'!E27 -> 60000 | J27: ='SO MS'!F27 -> 34560 | K27: ='SO MS'!G27 -> 10800 | L27: ='SO MS'!H27 -> 10000 | M27: ='SO MS'!I27 -> 0 | N27: ='SO MS'!J27 -> 2105.6477 | O27: ='SO MS'!K27 -> 0 | P27: ='SO MS'!L27 -> 0 | Q27: =SUM(I27:P27) -> 117465.65
B28: Sub Total | D28: =SUM(D21:D27) -> -331278.76 | E28: =SUM(E21:E27) -> 1030220.8 | F28: =SUM(F21:F27) -> 128317.49 | G28: =SUM(G21:G27) -> 0 | H28: =SUM(H21:H27) -> 1158538.3 | I28: =SUM(I21:I27) -> 420000 | J28: =SUM(J21:J27) -> 241920 | K28: =SUM(K21:K27) -> 75600 | ... Q28: =SUM(Q21:Q27) -> 827259.53
A30: =WEEKNUM(B31) -> 4 | B30: =B27+1 -> 46041 | C30: =TEXT(B30,"ddd") -> Sen | D30: =Q30-H30 -> -48039.823 | E30: =SUM('SO Januari 2026 rev.2'!E30:AR30)-'SO Januari 2026 rev.2'!U30 -> 147174.4 | F30: =SUM('SO Januari 2026 rev.2'!AU30:BC30)+'SO Januari 2026 rev.2'!U30 -> 18331.07 | G30: =SUM('SO Januari 2026 rev.2'!BD30:BE30) -> 0 | H30: =SUM(E30:G30) -> 165505.47 | I30: ='SO MS'!E30 -> 60000 | J30: ='SO MS'!F30 -> 34560 | K30: ='SO MS'!G30 -> 10800 | L30: ='SO MS'!H30 -> 10000 | M30: ='SO MS'!I30 -> 0 | N30: ='SO MS'!J30 -> 2105.6477 | O30: ='SO MS'!K30 -> 0 | P30: ='SO MS'!L30 -> 0 | Q30: =SUM(I30:P30) -> 117465.65
B31: =B30+1 -> 46042 | C31: =TEXT(B31,"ddd") -> Sel | D31: =Q31-H31 -> -48039.823 | E31: =SUM('SO Januari 2026 rev.2'!E31:AR31)-'SO Januari 2026 rev.2'!U31 -> 147174.4 | F31: =SUM('SO Januari 2026 rev.2'!AU31:BC31)+'SO Januari 2026 rev.2'!U31 -> 18331.07 | G31: =SUM('SO Januari 2026 rev.2'!BD31:BE31) -> 0 | H31: =SUM(E31:G31) -> 165505.47 | I31: ='SO MS'!E31 -> 60000 | J31: ='SO MS'!F31 -> 34560 | K31: ='SO MS'!G31 -> 10800 | L31: ='SO MS'!H31 -> 10000 | M31: ='SO MS'!I31 -> 0 | N31: ='SO MS'!J31 -> 2105.6477 | O31: ='SO MS'!K31 -> 0 | P31: ='SO MS'!L31 -> 0 | Q31: =SUM(I31:P31) -> 117465.65
B32: =B31+1 -> 46043 | C32: =TEXT(B32,"ddd") -> Rab | D32: =Q32-H32 -> -48039.823 | E32: =SUM('SO Januari 2026 rev.2'!E32:AR32)-'SO Januari 2026 rev.2'!U32 -> 147174.4 | F32: =SUM('SO Januari 2026 rev.2'!AU32:BC32)+'SO Januari 2026 rev.2'!U32 -> 18331.07 | G32: =SUM('SO Januari 2026 rev.2'!BD32:BE32) -> 0 | H32: =SUM(E32:G32) -> 165505.47 | I32: ='SO MS'!E32 -> 60000 | J32: ='SO MS'!F32 -> 34560 | K32: ='SO MS'!G32 -> 10800 | L32: ='SO MS'!H32 -> 10000 | M32: ='SO MS'!I32 -> 0 | N32: ='SO MS'!J32 -> 2105.6477 | O32: ='SO MS'!K32 -> 0 | P32: ='SO MS'!L32 -> 0 | Q32: =SUM(I32:P32) -> 117465.65
B33: =B32+1 -> 46044 | C33: =TEXT(B33,"ddd") -> Kam | D33: =Q33-H33 -> -48039.823 | E33: =SUM('SO Januari 2026 rev.2'!E33:AR33)-'SO Januari 2026 rev.2'!U33 -> 147174.4 | F33: =SUM('SO Januari 2026 rev.2'!AU33:BC33)+'SO Januari 2026 rev.2'!U33 -> 18331.07 | G33: =SUM('SO Januari 2026 rev.2'!BD33:BE33) -> 0 | H33: =SUM(E33:G33) -> 165505.47 | I33: ='SO MS'!E33 -> 60000 | J33: ='SO MS'!F33 -> 34560 | K33: ='SO MS'!G33 -> 10800 | L33: ='SO MS'!H33 -> 10000 | M33: ='SO MS'!I33 -> 0 | N33: ='SO MS'!J33 -> 2105.6477 | O33: ='SO MS'!K33 -> 0 | P33: ='SO MS'!L33 -> 0 | Q33: =SUM(I33:P33) -> 117465.65
B34: =B33+1 -> 46045 | C34: =TEXT(B34,"ddd") -> Jum | D34: =Q34-H34 -> -48039.823 | E34: =SUM('SO Januari 2026 rev.2'!E34:AR34)-'SO Januari 2026 rev.2'!U34 -> 147174.4 | F34: =SUM('SO Januari 2026 rev.2'!AU34:BC34)+'SO Januari 2026 rev.2'!U34 -> 18331.07 | G34: =SUM('SO Januari 2026 rev.2'!BD34:BE34) -> 0 | H34: =SUM(E34:G34) -> 165505.47 | I34: ='SO MS'!E34 -> 60000 | J34: ='SO MS'!F34 -> 34560 | K34: ='SO MS'!G34 -> 10800 | L34: ='SO MS'!H34 -> 10000 | M34: ='SO MS'!I34 -> 0 | N34: ='SO MS'!J34 -> 2105.6477 | O34: ='SO MS'!K34 -> 0 | P34: ='SO MS'!L34 -> 0 | Q34: =SUM(I34:P34) -> 117465.65
B35: =B34+1 -> 46046 | C35: =TEXT(B35,"ddd") -> Sab | D35: =Q35-H35 -> -48039.823 | E35: =SUM('SO Januari 2026 rev.2'!E35:AR35)-'SO Januari 2026 rev.2'!U35 -> 147174.4 | F35: =SUM('SO Januari 2026 rev.2'!AU35:BC35)+'SO Januari 2026 rev.2'!U35 -> 18331.07 | G35: =SUM('SO Januari 2026 rev.2'!BD35:BE35) -> 0 | H35: =SUM(E35:G35) -> 165505.47 | I35: ='SO MS'!E35 -> 60000 | J35: ='SO MS'!F35 -> 34560 | K35: ='SO MS'!G35 -> 10800 | L35: ='SO MS'!H35 -> 10000 | M35: ='SO MS'!I35 -> 0 | N35: ='SO MS'!J35 -> 2105.6477 | O35: ='SO MS'!K35 -> 0 | P35: ='SO MS'!L35 -> 0 | Q35: =SUM(I35:P35) -> 117465.65
B36: =B35+1 -> 46047 | C36: =TEXT(B36,"ddd") -> Mgg | D36: =Q36-H36 -> -48039.823 | E36: =SUM('SO Januari 2026 rev.2'!E36:AR36)-'SO Januari 2026 rev.2'!U36 -> 147174.4 | F36: =SUM('SO Januari 2026 rev.2'!AU36:BC36)+'SO Januari 2026 rev.2'!U36 -> 18331.07 | G36: =SUM('SO Januari 2026 rev.2'!BD36:BE36) -> 0 | H36: =SUM(E36:G36) -> 165505.47 | I36: ='SO MS'!E36 -> 60000 | J36: ='SO MS'!F36 -> 34560 | K36: ='SO MS'!G36 -> 10800 | L36: ='SO MS'!H36 -> 10000 | M36: ='SO MS'!I36 -> 0 | N36: ='SO MS'!J36 -> 2105.6477 | O36: ='SO MS'!K36 -> 0 | P36: ='SO MS'!L36 -> 0 | Q36: =SUM(I36:P36) -> 117465.65
B37: Sub Total | D37: =SUM(D30:D36) -> -336278.76 | E37: =SUM(E30:E36) -> 1030220.8 | F37: =SUM(F30:F36) -> 128317.49 | G37: =SUM(G30:G36) -> 0 | H37: =SUM(H30:H36) -> 1158538.3 | I37: =SUM(I30:I36) -> 420000 | J37: =SUM(J30:J36) -> 241920 | K37: =SUM(K30:K36) -> 75600 | ... Q37: =SUM(Q30:Q36) -> 822259.53
A39: =WEEKNUM(B41) -> 5 | B39: =B36+1 -> 46048 | C39: =TEXT(B39,"ddd") -> Sen | D39: =Q39-H39 -> -48039.823 | E39: =SUM('SO Januari 2026 rev.2'!E39:AR39)-'SO Januari 2026 rev.2'!U39 -> 147174.4 | F39: =SUM('SO Januari 2026 rev.2'!AU39:BC39)+'SO Januari 2026 rev.2'!U39 -> 18331.07 | G39: =SUM('SO Januari 2026 rev.2'!BD39:BE39) -> 0 | H39: =SUM(E39:G39) -> 165505.47 | I39: ='SO MS'!E39 -> 60000 | J39: ='SO MS'!F39 -> 34560 | K39: ='SO MS'!G39 -> 10800 | L39: ='SO MS'!H39 -> 10000 | M39: ='SO MS'!I39 -> 0 | N39: ='SO MS'!J39 -> 2105.6477 | O39: ='SO MS'!K39 -> 0 | P39: ='SO MS'!L39 -> 0 | Q39: =SUM(I39:P39) -> 117465.65
B40: =B39+1 -> 46049 | C40: =TEXT(B40,"ddd") -> Sel | D40: =Q40-H40 -> -48039.823 | E40: =SUM('SO Januari 2026 rev.2'!E40:AR40)-'SO Januari 2026 rev.2'!U40 -> 147174.4 | F40: =SUM('SO Januari 2026 rev.2'!AU40:BC40)+'SO Januari 2026 rev.2'!U40 -> 18331.07 | G40: =SUM('SO Januari 2026 rev.2'!BD40:BE40) -> 0 | H40: =SUM(E40:G40) -> 165505.47 | I40: ='SO MS'!E40 -> 60000 | J40: ='SO MS'!F40 -> 34560 | K40: ='SO MS'!G40 -> 10800 | L40: ='SO MS'!H40 -> 10000 | M40: ='SO MS'!I40 -> 0 | N40: ='SO MS'!J40 -> 2105.6477 | O40: ='SO MS'!K40 -> 0 | P40: ='SO MS'!L40 -> 0 | Q40: =SUM(I40:P40) -> 117465.65
B41: =B40+1 -> 46050 | C41: =TEXT(B41,"ddd") -> Rab | D41: =Q41-H41 -> -48039.823 | E41: =SUM('SO Januari 2026 rev.2'!E41:AR41)-'SO Januari 2026 rev.2'!U41 -> 147174.4 | F41: =SUM('SO Januari 2026 rev.2'!AU41:BC41)+'SO Januari 2026 rev.2'!U41 -> 18331.07 | G41: =SUM('SO Januari 2026 rev.2'!BD41:BE41) -> 0 | H41: =SUM(E41:G41) -> 165505.47 | I41: ='SO MS'!E41 -> 60000 | J41: ='SO MS'!F41 -> 34560 | K41: ='SO MS'!G41 -> 10800 | L41: ='SO MS'!H41 -> 10000 | M41: ='SO MS'!I41 -> 0 | N41: ='SO MS'!J41 -> 2105.6477 | O41: ='SO MS'!K41 -> 0 | P41: ='SO MS'!L41 -> 0 | Q41: =SUM(I41:P41) -> 117465.65
B42: =B41+1 -> 46051 | C42: =TEXT(B42,"ddd") -> Kam | D42: =Q42-H42 -> -48039.823 | E42: =SUM('SO Januari 2026 rev.2'!E42:AR42)-'SO Januari 2026 rev.2'!U42 -> 147174.4 | F42: =SUM('SO Januari 2026 rev.2'!AU42:BC42)+'SO Januari 2026 rev.2'!U42 -> 18331.07 | G42: =SUM('SO Januari 2026 rev.2'!BD42:BE42) -> 0 | H42: =SUM(E42:G42) -> 165505.47 | I42: ='SO MS'!E42 -> 60000 | J42: ='SO MS'!F42 -> 34560 | K42: ='SO MS'!G42 -> 10800 | L42: ='SO MS'!H42 -> 10000 | M42: ='SO MS'!I42 -> 0 | N42: ='SO MS'!J42 -> 2105.6477 | O42: ='SO MS'!K42 -> 0 | P42: ='SO MS'!L42 -> 0 | Q42: =SUM(I42:P42) -> 117465.65
B43: =B42+1 -> 46052 | C43: =TEXT(B43,"ddd") -> Jum | D43: =Q43-H43 -> -48039.823 | E43: =SUM('SO Januari 2026 rev.2'!E43:AR43)-'SO Januari 2026 rev.2'!U43 -> 147174.4 | F43: =SUM('SO Januari 2026 rev.2'!AU43:BC43)+'SO Januari 2026 rev.2'!U43 -> 18331.07 | G43: =SUM('SO Januari 2026 rev.2'!BD43:BE43) -> 0 | H43: =SUM(E43:G43) -> 165505.47 | I43: ='SO MS'!E43 -> 60000 | J43: ='SO MS'!F43 -> 34560 | K43: ='SO MS'!G43 -> 10800 | L43: ='SO MS'!H43 -> 10000 | M43: ='SO MS'!I43 -> 0 | N43: ='SO MS'!J43 -> 2105.6477 | O43: ='SO MS'!K43 -> 0 | P43: ='SO MS'!L43 -> 0 | Q43: =SUM(I43:P43) -> 117465.65
B44: =B43+1 -> 46053 | C44: =TEXT(B44,"ddd") -> Sab | D44: =Q44-H44 -> -48039.823 | E44: =SUM('SO Januari 2026 rev.2'!E44:AR44)-'SO Januari 2026 rev.2'!U44 -> 147174.4 | F44: =SUM('SO Januari 2026 rev.2'!AU44:BC44)+'SO Januari 2026 rev.2'!U44 -> 18331.07 | G44: =SUM('SO Januari 2026 rev.2'!BD44:BE44) -> 0 | H44: =SUM(E44:G44) -> 165505.47 | I44: ='SO MS'!E44 -> 60000 | J44: ='SO MS'!F44 -> 34560 | K44: ='SO MS'!G44 -> 10800 | L44: ='SO MS'!H44 -> 10000 | M44: ='SO MS'!I44 -> 0 | N44: ='SO MS'!J44 -> 2105.6477 | O44: ='SO MS'!K44 -> 0 | P44: ='SO MS'!L44 -> 0 | Q44: =SUM(I44:P44) -> 117465.65
B45: Sub Total | D45: =SUM(D39:D44) -> -288238.94 | E45: =SUM(E39:E44) -> 883046.4 | F45: =SUM(F39:F44) -> 109986.42 | G45: =SUM(G39:G44) -> 0 | H45: =SUM(H39:H44) -> 993032.82 | I45: =SUM(I39:I44) -> 360000 | J45: =SUM(J39:J44) -> 207360 | K45: =SUM(K39:K44) -> 64800 | ... Q45: =SUM(Q39:Q44) -> 704793.89
