Workbook
Name ___xlnm._FilterDatabase_2: #REF!
Name ___xlnm._FilterDatabase_2: #REF!
Name ___xlnm._FilterDatabase_2: #REF!
Name ___xlnm._FilterDatabase_2: #REF!
Name ___xlnm._FilterDatabase_2: #REF!
Name ___xlnm._FilterDatabase_2: #REF!
Name ___xlnm._FilterDatabase_2: #REF!
Name ___xlnm._FilterDatabase_2: #REF!
Name ___xlnm._FilterDatabase_2: #REF!
Name ___xlnm._FilterDatabase_2: #REF!
Name ___xlnm._FilterDatabase_2: #REF!
Name ___xlnm._FilterDatabase_2: #REF!
Name ___xlnm._FilterDatabase_2: #REF!
Name ___xlnm._FilterDatabase_2: #REF!
Name ___xlnm._FilterDatabase_2: #REF!
Name ___xlnm._FilterDatabase_2: #REF!
Name __xlnm._FilterDatabase_2: #REF!
Name __xlnm._FilterDatabase_2: #REF!
Name __xlnm._FilterDatabase_2: #REF!
Name __xlnm._FilterDatabase_2: #REF!
Name __xlnm._FilterDatabase_2: #REF!
Name __xlnm._FilterDatabase_2: #REF!
Name __xlnm._FilterDatabase_2: #REF!
Name __xlnm._FilterDatabase_2: #REF!
Name __xlnm._FilterDatabase_2: #REF!
Name __xlnm._FilterDatabase_2: #REF!
Name __xlnm._FilterDatabase_2: #REF!
Name __xlnm._FilterDatabase_2: #REF!
Name __xlnm._FilterDatabase_2: #REF!
Name __xlnm._FilterDatabase_2: #REF!
Name __xlnm._FilterDatabase_2: #REF!
Name __xlnm._FilterDatabase_2: #REF!
Name Excel_BuiltIn__FilterDatabase_1: #REF!
Name Excel_BuiltIn__FilterDatabase_1: #REF!
Name Excel_BuiltIn__FilterDatabase_1: #REF!
Name Excel_BuiltIn__FilterDatabase_1: #REF!
Name Excel_BuiltIn__FilterDatabase_1: #REF!
Name Excel_BuiltIn__FilterDatabase_1: #REF!
Name Excel_BuiltIn__FilterDatabase_1: #REF!
Name Excel_BuiltIn__FilterDatabase_1: #REF!
Name Excel_BuiltIn__FilterDatabase_1: #REF!
Name Excel_BuiltIn__FilterDatabase_1: #REF!
Name Excel_BuiltIn__FilterDatabase_1: #REF!
Name Excel_BuiltIn__FilterDatabase_1: #REF!
Name Excel_BuiltIn__FilterDatabase_1: #REF!
Name Excel_BuiltIn__FilterDatabase_1: #REF!
Name Excel_BuiltIn__FilterDatabase_1: #REF!
Name Excel_BuiltIn__FilterDatabase_1: #REF!
Name Export_3: #REF!
Name Export_3: #REF!
Name Export_3: #REF!
Name Export_3: #REF!
Name Export_3: #REF!
Name Export_3: #REF!
Name Export_3: #REF!
Name Export_3: #REF!
Name Export_3: #REF!
Name Export_3: #REF!
Name FOB: 'Summary FOB'!#REF!
Name FOB: 'Summary FOB'!#REF!

Sheet SO Februari 2026 Rev.2
A2: SALES ORDER
A3: 46054 | O3: =O4/2 -> 0
A5: Week | B5: DATE | D5: TOTAL | E5: CLIN | F5: BI | G5: MKG | H5: STM | I5: OAJ | J5: NNI | K5: SHB | L5: GTL | M5: TWK | N5: BYC | O5: GF RANCA | P5: SMA | Q5: UMI | R5: HLI | S5: CERES | T5: DIC | U5: HCI | V5: KSN | W5: ADP | X5: ALT (KSO MASAMI) | Y5: IDP (KSO AAE) | Z5: FJI (KSO SALMAH) | AA5: WINGLOK (KSO EBM) | AB5: CISF (KSO RRS) | AC5: PUJ - LUBRICANT | AD5: CALBEE (KSO BMI) | AE5: IP | AF5: BEM | AG5: AMI | AH5: KA | AI5: KTN | AJ5: TOMIMOTO | AK5: NIAGA GARAM | AL5: PCI 84 | AM5: PCI MENGGER | AN5: INDOFOOD | AO5: ASAHIMAS | AP5: ABC KOGEN | AQ5: TONGJI ( KSO GAS) | AR5: PA | AS5: RB | AT5: GF ATOM | AU5: GF KULIT | AV5: HSK (KSO GAS) | AW5: SDM | AX5: JARGAS | AY5: SBI | AZ5: SP KSO JES | BA5: SP GLOBAL
A6: =WEEKNUM(B6) -> 6 | B6: =A3 -> 46054 | C6: =TEXT(B6,"ddd") -> Mgg | D6: =SUM(E6:BA6) -> 180951.47 | E6: 812.17 | F6: 3000 | G6: 1129.7313 | H6: 3282.5161 | I6: 644.02065 | J6: 5500 | K6: 166.97065 | L6: 603.76323 | M6: 673.27548 | N6: 4514.199 | O6: 8000.0623 | P6: 2874.3265 | Q6: 11659.555 | R6: 3600 | S6: 9000.0571 | T6: 4482.6897 | U6: 5500 | V6: 3500 | W6: 500 | X6: 926.09448 | Y6: 5500 | Z6: 70.054839 | AA6: 89.451613 | AB6: 3500 | AC6: 4000.4806 | AD6: 0 | AE6: 2020.8603 | AF6: 678.7 | AG6: 7121.8519 | AH6: 2443.8768 | AI6: 2043.2745 | AJ6: 1439.5303 | AK6: 260.97419 | AL6: 11007.047 | AM6: 1519.5448 | AN6: 3999.6742 | AO6: 26500 | AP6: 8000 | AQ6: 2105.6477 | AR6: 726.81516 | AS6: 3018.0416 | AT6: 2044.9997 | AU6: 369.61071 | AV6: 3500 | AW6: 1121.9003 | AX6: 1500 | AY6: 2499.7026 | AZ6: 9000 | BA6: 4500
B7: Sub Total | D7: =SUM(D6:D6) -> 180951.47 | E7: =SUM(E6:E6) -> 812.17 | F7: =SUM(F6:F6) -> 3000 | G7: =SUM(G6:G6) -> 1129.7313 | H7: =SUM(H6:H6) -> 3282.5161 | I7: =SUM(I6:I6) -> 644.02065 | J7: =SUM(J6:J6) -> 5500 | K7: =SUM(K6:K6) -> 166.97065 | ... BA7: =SUM(BA6:BA6) -> 4500
A9: =WEEKNUM(B9) -> 6 | B9: =B6+1 -> 46055 | C9: =TEXT(B9,"ddd") -> Sen | D9: =SUM(E9:BA9) -> 180951.47 | E9: 812.17 | F9: 3000 | G9: 1129.7313 | H9: 3282.5161 | I9: 644.02065 | J9: 5500 | K9: 166.97065 | L9: 603.76323 | M9: 673.27548 | N9: 4514.199 | O9: 8000.0623 | P9: 2874.3265 | Q9: 11659.555 | R9: 3600 | S9: 9000.0571 | T9: 4482.6897 | U9: 5500 | V9: 3500 | W9: 500 | X9: 926.09448 | Y9: 5500 | Z9: 70.054839 | AA9: 89.451613 | AB9: 3500 | AC9: 4000.4806 | AD9: 0 | AE9: 2020.8603 | AF9: 678.7 | AG9: 7121.8519 | AH9: 2443.8768 | AI9: 2043.2745 | AJ9: 1439.5303 | AK9: 260.97419 | AL9: 11007.047 | AM9: 1519.5448 | AN9: 3999.6742 | AO9: 26500 | AP9: 8000 | AQ9: 2105.6477 | AR9: 726.81516 | AS9: 3018.0416 | AT9: 2044.9997 | AU9: 369.61071 | AV9: 3500 | AW9: 1121.9003 | AX9: 1500 | AY9: 2499.7026 | AZ9: 9000 | BA9: 4500
B10: =B9+1 -> 46056 | C10: =TEXT(B10,"ddd") -> Sel | D10: =SUM(E10:BA10) -> 180951.47 | E10: 812.17 | F10: 3000 | G10: 1129.7313 | H10: 3282.5161 | I10: 644.02065 | J10: 5500 | K10: 166.97065 | L10: 603.76323 | M10: 673.27548 | N10: 4514.199 | O10: 8000.0623 | P10: 2874.3265 | Q10: 11659.555 | R10: 3600 | S10: 9000.0571 | T10: 4482.6897 | U10: 5500 | V10: 3500 | W10: 500 | X10: 926.09448 | Y10: 5500 | Z10: 70.054839 | AA10: 89.451613 | AB10: 3500 | AC10: 4000.4806 | AD10: 0 | AE10: 2020.8603 | AF10: 678.7 | AG10: 7121.8519 | AH10: 2443.8768 | AI10: 2043.2745 | AJ10: 1439.5303 | AK10: 260.97419 | AL10: 11007.047 | AM10: 1519.5448 | AN10: 3999.6742 | AO10: 26500 | AP10: 8000 | AQ10: 2105.6477 | AR10: 726.81516 | AS10: 3018.0416 | AT10: 2044.9997 | AU10: 369.61071 | AV10: 3500 | AW10: 1121.9003 | AX10: 1500 | AY10: 2499.7026 | AZ10: 9000 | BA10: 4500
B11: =B10+1 -> 46057 | C11: =TEXT(B11,"ddd") -> Rab | D11: =SUM(E11:BA11) -> 180951.47 | E11: 812.17 | F11: 3000 | G11: 1129.7313 | H11: 3282.5161 | I11: 644.02065 | J11: 5500 | K11: 166.97065 | L11: 603.76323 | M11: 673.27548 | N11: 4514.199 | O11: 8000.0623 | P11: 2874.3265 | Q11: 11659.555 | R11: 3600 | S11: 9000.0571 | T11: 4482.6897 | U11: 5500 | V11: 3500 | W11: 500 | X11: 926.09448 | Y11: 5500 | Z11: 70.054839 | AA11: 89.451613 | AB11: 3500 | AC11: 4000.4806 | AD11: 0 | AE11: 2020.8603 | AF11: 678.7 | AG11: 7121.8519 | AH11: 2443.8768 | AI11: 2043.2745 | AJ11: 1439.5303 | AK11: 260.97419 | AL11: 11007.047 | AM11: 1519.5448 | AN11: 3999.6742 | AO11: 26500 | AP11: 8000 | AQ11: 2105.6477 | AR11: 726.81516 | AS11: 3018.0416 | AT11: 2044.9997 | AU11: 369.61071 | AV11: 3500 | AW11: 1121.9003 | AX11: 1500 | AY11: 2499.7026 | AZ11: 9000 | BA11: 4500
B12: =B11+1 -> 46058 | C12: =TEXT(B12,"ddd") -> Kam | D12: =SUM(E12:BA12) -> 180951.47 | E12: 812.17 | F12: 3000 | G12: 1129.7313 | H12: 3282.5161 | I12: 644.02065 | J12: 5500 | K12: 166.97065 | L12: 603.76323 | M12: 673.27548 | N12: 4514.199 | O12: 8000.0623 | P12: 2874.3265 | Q12: 11659.555 | R12: 3600 | S12: 9000.0571 | T12: 4482.6897 | U12: 5500 | V12: 3500 | W12: 500 | X12: 926.09448 | Y12: 5500 | Z12: 70.054839 | AA12: 89.451613 | AB12: 3500 | AC12: 4000.4806 | AD12: 0 | AE12: 2020.8603 | AF12: 678.7 | AG12: 7121.8519 | AH12: 2443.8768 | AI12: 2043.2745 | AJ12: 1439.5303 | AK12: 260.97419 | AL12: 11007.047 | AM12: 1519.5448 | AN12: 3999.6742 | AO12: 26500 | AP12: 8000 | AQ12: 2105.6477 | AR12: 726.81516 | AS12: 3018.0416 | AT12: 2044.9997 | AU12: 369.61071 | AV12: 3500 | AW12: 1121.9003 | AX12: 1500 | AY12: 2499.7026 | AZ12: 9000 | BA12: 4500
B13: =B12+1 -> 46059 | C13: =TEXT(B13,"ddd") -> Jum | D13: =SUM(E13:BA13) -> 180951.47 | E13: 812.17 | F13: 3000 | G13: 1129.7313 | H13: 3282.5161 | I13: 644.02065 | J13: 5500 | K13: 166.97065 | L13: 603.76323 | M13: 673.27548 | N13: 4514.199 | O13: 8000.0623 | P13: 2874.3265 | Q13: 11659.555 | R13: 3600 | S13: 9000.0571 | T13: 4482.6897 | U13: 5500 | V13: 3500 | W13: 500 | X13: 926.09448 | Y13: 5500 | Z13: 70.054839 | AA13: 89.451613 | AB13: 3500 | AC13: 4000.4806 | AD13: 0 | AE13: 2020.8603 | AF13: 678.7 | AG13: 7121.8519 | AH13: 2443.8768 | AI13: 2043.2745 | AJ13: 1439.5303 | AK13: 260.97419 | AL13: 11007.047 | AM13: 1519.5448 | AN13: 3999.6742 | AO13: 26500 | AP13: 8000 | AQ13: 2105.6477 | AR13: 726.81516 | AS13: 3018.0416 | AT13: 2044.9997 | AU13: 369.61071 | AV13: 3500 | AW13: 1121.9003 | AX13: 1500 | AY13: 2499.7026 | AZ13: 9000 | BA13: 4500
B14: =B13+1 -> 46060 | C14: =TEXT(B14,"ddd") -> Sab | D14: =SUM(E14:BA14) -> 180951.47 | E14: 812.17 | F14: 3000 | G14: 1129.7313 | H14: 3282.5161 | I14: 644.02065 | J14: 5500 | K14: 166.97065 | L14: 603.76323 | M14: 673.27548 | N14: 4514.199 | O14: 8000.0623 | P14: 2874.3265 | Q14: 11659.555 | R14: 3600 | S14: 9000.0571 | T14: 4482.6897 | U14: 5500 | V14: 3500 | W14: 500 | X14: 926.09448 | Y14: 5500 | Z14: 70.054839 | AA14: 89.451613 | AB14: 3500 | AC14: 4000.4806 | AD14: 0 | AE14: 2020.8603 | AF14: 678.7 | AG14: 7121.8519 | AH14: 2443.8768 | AI14: 2043.2745 | AJ14: 1439.5303 | AK14: 260.97419 | AL14: 11007.047 | AM14: 1519.5448 | AN14: 3999.6742 | AO14: 26500 | AP14: 8000 | AQ14: 2105.6477 | AR14: 726.81516 | AS14: 3018.0416 | AT14: 2044.9997 | AU14: 369.61071 | AV14: 3500 | AW14: 1121.9003 | AX14: 1500 | AY14: 2499.7026 | AZ14: 9000 | BA14: 4500
B15: =B14+1 -> 46061 | C15: =TEXT(B15,"ddd") -> Mgg | D15: =SUM(E15:BA15) -> 180951.47 | E15: 812.17 | F15: 3000 | G15: 1129.7313 | H15: 3282.5161 | I15: 644.02065 | J15: 5500 | K15: 166.97065 | L15: 603.76323 | M15: 673.27548 | N15: 4514.199 | O15: 8000.0623 | P15: 2874.3265 | Q15: 11659.555 | R15: 3600 | S15: 9000.0571 | T15: 4482.6897 | U15: 5500 | V15: 3500 | W15: 500 | X15: 926.09448 | Y15: 5500 | Z15: 70.054839 | AA15: 89.451613 | AB15: 3500 | AC15: 4000.4806 | AD15: 0 | AE15: 2020.8603 | AF15: 678.7 | AG15: 7121.8519 | AH15: 2443.8768 | AI15: 2043.2745 | AJ15: 1439.5303 | AK15: 260.97419 | AL15: 11007.047 | AM15: 1519.5448 | AN15: 3999.6742 | AO15: 26500 | AP15: 8000 | AQ15: 2105.6477 | AR15: 726.81516 | AS15: 3018.0416 | AT15: 2044.9997 | AU15: 369.61071 | AV15: 3500 | AW15: 1121.9003 | AX15: 1500 | AY15: 2499.7026 | AZ15: 9000 | BA15: 4500
B16: Sub Total | D16: =SUM(D9:D15) -> 1266660.3 | E16: =SUM(E9:E15) -> 5685.19 | F16: =SUM(F9:F15) -> 21000 | G16: =SUM(G9:G15) -> 7908.119 | H16: =SUM(H9:H15) -> 22977.613 | I16: =SUM(I9:I15) -> 4508.1445 | J16: =SUM(J9:J15) -> 38500 | K16: =SUM(K9:K15) -> 1168.7945 | ... BA16: =SUM(BA9:BA15) -> 31500
A18: =WEEKNUM(B23) -> 7 | B18: =B15+1 -> 46062 | C18: =TEXT(B18,"ddd") -> Sen | D18: =SUM(E18:BA18) -> 175574.47 | E18: 812.17 | F18: 2500 | G18: 1129.7313 | H18: 3282.5161 | I18: 644.02065 | J18: 2000 | K18: 166.97065 | L18: 603.76323 | M18: 673.27548 | N18: 5514.199 | O18: 6000.0623 | P18: 2874.3265 | Q18: 15659.555 | R18: 1500 | S18: 11000.057 | T18: 3999.6897 | U18: 3500 | V18: 3500 | W18: 1500 | X18: 926.09448 | Y18: 4500 | Z18: 70.054839 | AA18: 89.451613 | AB18: 3500 | AC18: 4000.4806 | AD18: 0 | AE18: 2020.8603 | AF18: 678.7 | AG18: 7121.8519 | AH18: 3499.8768 | AI18: 1500.2745 | AJ18: 2139.5303 | AK18: 1260.9742 | AL18: 10000.047 | AM18: 1519.5448 | AN18: 3999.6742 | AO18: 26500 | AP18: 5000 | AQ18: 2105.6477 | AR18: 726.81516 | AS18: 3018.0416 | AT18: 2044.9997 | AU18: 369.61071 | AV18: 3500 | AW18: 1121.9003 | AX18: 1500 | AY18: 2499.7026 | AZ18: 9000 | BA18: 4500
B19: =B18+1 -> 46063 | C19: =TEXT(B19,"ddd") -> Sel | D19: =SUM(E19:BA19) -> 175574.47 | E19: 812.17 | F19: 2500 | G19: 1129.7313 | H19: 3282.5161 | I19: 644.02065 | J19: 2000 | K19: 166.97065 | L19: 603.76323 | M19: 673.27548 | N19: 5514.199 | O19: 6000.0623 | P19: 2874.3265 | Q19: 15659.555 | R19: 1500 | S19: 11000.057 | T19: 3999.6897 | U19: 3500 | V19: 3500 | W19: 1500 | X19: 926.09448 | Y19: 4500 | Z19: 70.054839 | AA19: 89.451613 | AB19: 3500 | AC19: 4000.4806 | AD19: 0 | AE19: 2020.8603 | AF19: 678.7 | AG19: 7121.8519 | AH19: 3499.8768 | AI19: 1500.2745 | AJ19: 2139.5303 | AK19: 1260.9742 | AL19: 10000.047 | AM19: 1519.5448 | AN19: 3999.6742 | AO19: 26500 | AP19: 5000 | AQ19: 2105.6477 | AR19: 726.81516 | AS19: 3018.0416 | AT19: 2044.9997 | AU19: 369.61071 | AV19: 3500 | AW19: 1121.9003 | AX19: 1500 | AY19: 2499.7026 | AZ19: 9000 | BA19: 4500
B20: =B19+1 -> 46064 | C20: =TEXT(B20,"ddd") -> Rab | D20: =SUM(E20:BA20) -> 175574.47 | E20: 812.17 | F20: 2500 | G20: 1129.7313 | H20: 3282.5161 | I20: 644.02065 | J20: 2000 | K20: 166.97065 | L20: 603.76323 | M20: 673.27548 | N20: 5514.199 | O20: 6000.0623 | P20: 2874.3265 | Q20: 15659.555 | R20: 1500 | S20: 11000.057 | T20: 3999.6897 | U20: 3500 | V20: 3500 | W20: 1500 | X20: 926.09448 | Y20: 4500 | Z20: 70.054839 | AA20: 89.451613 | AB20: 3500 | AC20: 4000.4806 | AD20: 0 | AE20: 2020.8603 | AF20: 678.7 | AG20: 7121.8519 | AH20: 3499.8768 | AI20: 1500.2745 | AJ20: 2139.5303 | AK20: 1260.9742 | AL20: 10000.047 | AM20: 1519.5448 | AN20: 3999.6742 | AO20: 26500 | AP20: 5000 | AQ20: 2105.6477 | AR20: 726.81516 | AS20: 3018.0416 | AT20: 2044.9997 | AU20: 369.61071 | AV20: 3500 | AW20: 1121.9003 | AX20: 1500 | AY20: 2499.7026 | AZ20: 9000 | BA20: 4500
B21: =B20+1 -> 46065 | C21: =TEXT(B21,"ddd") -> Kam | D21: =SUM(E21:BA21) -> 175574.47 | E21: 812.17 | F21: 2500 | G21: 1129.7313 | H21: 3282.5161 | I21: 644.02065 | J21: 2000 | K21: 166.97065 | L21: 603.76323 | M21: 673.27548 | N21: 5514.199 | O21: 6000.0623 | P21: 2874.3265 | Q21: 15659.555 | R21: 1500 | S21: 11000.057 | T21: 3999.6897 | U21: 3500 | V21: 3500 | W21: 1500 | X21: 926.09448 | Y21: 4500 | Z21: 70.054839 | AA21: 89.451613 | AB21: 3500 | AC21: 4000.4806 | AD21: 0 | AE21: 2020.8603 | AF21: 678.7 | AG21: 7121.8519 | AH21: 3499.8768 | AI21: 1500.2745 | AJ21: 2139.5303 | AK21: 1260.9742 | AL21: 10000.047 | AM21: 1519.5448 | AN21: 3999.6742 | AO21: 26500 | AP21: 5000 | AQ21: 2105.6477 | AR21: 726.81516 | AS21: 3018.0416 | AT21: 2044.9997 | AU21: 369.61071 | AV21: 3500 | AW21: 1121.9003 | AX21: 1500 | AY21: 2499.7026 | AZ21: 9000 | BA21: 4500
B22: =B21+1 -> 46066 | C22: =TEXT(B22,"ddd") -> Jum | D22: =SUM(E22:BA22) -> 175574.47 | E22: 812.17 | F22: 2500 | G22: 1129.7313 | H22: 3282.5161 | I22: 644.02065 | J22: 2000 | K22: 166.97065 | L22: 603.76323 | M22: 673.27548 | N22: 5514.199 | O22: 6000.0623 | P22: 2874.3265 | Q22: 15659.555 | R22: 1500 | S22: 11000.057 | T22: 3999.6897 | U22: 3500 | V22: 3500 | W22: 1500 | X22: 926.09448 | Y22: 4500 | Z22: 70.054839 | AA22: 89.451613 | AB22: 3500 | AC22: 4000.4806 | AD22: 0 | AE22: 2020.8603 | AF22: 678.7 | AG22: 7121.8519 | AH22: 3499.8768 | AI22: 1500.2745 | AJ22: 2139.5303 | AK22: 1260.9742 | AL22: 10000.047 | AM22: 1519.5448 | AN22: 3999.6742 | AO22: 26500 | AP22: 5000 | AQ22: 2105.6477 | AR22: 726.81516 | AS22: 3018.0416 | AT22: 2044.9997 | AU22: 369.61071 | AV22: 3500 | AW22: 1121.9003 | AX22: 1500 | AY22: 2499.7026 | AZ22: 9000 | BA22: 4500
B23: =B22+1 -> 46067 | C23: =TEXT(B23,"ddd") -> Sab | D23: =SUM(E23:BA23) -> 165174.59 | E23: 812.17 | F23: 2000 | G23: 729.73129 | H23: 3282.5161 | I23: 644.02065 | J23: 2000 | K23: 166.97065 | L23: 603.76323 | M23: 673.27548 | N23: 4514.199 | O23: 6000.0623 | P23: 2874.3265 | Q23: 15659.555 | R23: 1500 | S23: 9000.0571 | T23: 3999.6897 | U23: 3500 | V23: 3500 | W23: 1500 | X23: 926.09448 | Y23: 4500 | Z23: 70.054839 | AA23: 89.451613 | AB23: 3500 | AC23: 4000.4806 | AD23: 0 | AE23: 2020.8603 | AF23: 678.7 | AG23: 4121.8519 | AH23: 0 | AI23: 1500.2745 | AJ23: 2139.5303 | AK23: 1260.9742 | AL23: 10000.047 | AM23: 1519.5448 | AN23: 3999.6742 | AO23: 26500 | AP23: 5000 | AQ23: 2105.6477 | AR23: 726.81516 | AS23: 3018.0416 | AT23: 2044.9997 | AU23: 369.61071 | AV23: 3500 | AW23: 1121.9003 | AX23: 1500 | AY23: 2499.7026 | AZ23: 9000 | BA23: 4500
B24: =B23+1 -> 46068 | C24: =TEXT(B24,"ddd") -> Mgg | D24: =SUM(E24:BA24) -> 156619.42 | E24: 812.17 | F24: 500 | G24: 729.73129 | H24: 3282.5161 | I24: 644.02065 | J24: 2000 | K24: 0 | L24: 603.76323 | M24: 673.27548 | N24: 0 | O24: 6000.0623 | P24: 500.32645 | Q24: 6659.5545 | R24: 1500 | S24: 6000.0571 | T24: 3999.6897 | U24: 3500 | V24: 3500 | W24: 1500 | X24: 926.09448 | Y24: 2500 | Z24: 70.054839 | AA24: 89.451613 | AB24: 3500 | AC24: 1000.4806 | AD24: 0 | AE24: 2020.8603 | AF24: 678.7 | AG24: 2121.8519 | AH24: 0 | AI24: 1500.2745 | AJ24: 2139.5303 | AK24: 1260.9742 | AL24: 10000.047 | AM24: 1519.5448 | AN24: 3999.6742 | AO24: 45500 | AP24: 5000 | AQ24: 2105.6477 | AR24: 726.81516 | AS24: 3018.0416 | AT24: 2044.9997 | AU24: 369.61071 | AV24: 3500 | AW24: 1121.9003 | AX24: 1500 | AY24: 2499.7026 | AZ24: 9000 | BA24: 4500
B25: Sub Total | D25: =SUM(D18:D24) -> 1199666.4 | E25: =SUM(E18:E24) -> 5685.19 | F25: =SUM(F18:F24) -> 15000 | G25: =SUM(G18:G24) -> 7108.119 | H25: =SUM(H18:H24) -> 22977.613 | I25: =SUM(I18:I24) -> 4508.1445 | J25: =SUM(J18:J24) -> 14000 | K25: =SUM(K18:K24) -> 1001.8239 | ... BA25: =SUM(BA18:BA24) -> 31500
A27: =WEEKNUM(B32) -> 8 | B27: =B24+1 -> 46069 | C27: =TEXT(B27,"ddd") -> Sen | D27: =SUM(E27:BA27) -> 149971.02 | E27: 812.17 | F27: 500 | G27: 629.73129 | H27: 0 | I27: 644.02065 | J27: 0 | K27: 0 | L27: 603.76323 | M27: 673.27548 | N27: 0 | O27: 6000.0623 | P27: 874.32645 | Q27: 11659.555 | R27: 1500 | S27: 6000.0571 | T27: 3999.6897 | U27: 3500 | V27: 3500 | W27: 1500 | X27: 926.09448 | Y27: 4500 | Z27: 70.054839 | AA27: 89.451613 | AB27: 0 | AC27: 0 | AD27: 0 | AE27: 2020.8603 | AF27: 678.7 | AG27: 0 | AH27: 2443.8768 | AI27: 1500.2745 | AJ27: 0 | AK27: 260.97419 | AL27: 10000.047 | AM27: 1519.5448 | AN27: 3999.6742 | AO27: 36000 | AP27: 5000 | AQ27: 2105.6477 | AR27: 726.81516 | AS27: 3018.0416 | AT27: 2044.9997 | AU27: 369.61071 | AV27: 3500 | AW27: 0 | AX27: 1800 | AY27: 2499.7026 | AZ27: 13500 | BA27: 9000
B28: =B27+1 -> 46070 | C28: =TEXT(B28,"ddd") -> Sel | D28: =SUM(E28:BA28) -> 142271.46 | E28: 812.17 | F28: 500 | G28: 629.73129 | H28: 0 | I28: 644.02065 | J28: 0 | K28: 0 | L28: 603.76323 | M28: 673.27548 | N28: 0 | O28: 6000.0623 | P28: 874.32645 | Q28: 11659.555 | R28: 1500 | S28: 6000.0571 | T28: 3999.6897 | U28: 0 | V28: 3500 | W28: 0 | X28: 926.09448 | Y28: 4500 | Z28: 70.054839 | AA28: 89.451613 | AB28: 0 | AC28: 0 | AD28: 0 | AE28: 0 | AF28: 0 | AG28: 0 | AH28: 2443.8768 | AI28: 1500.2745 | AJ28: 0 | AK28: 260.97419 | AL28: 10000.047 | AM28: 1519.5448 | AN28: 3999.6742 | AO28: 36000 | AP28: 5000 | AQ28: 2105.6477 | AR28: 726.81516 | AS28: 3018.0416 | AT28: 2044.9997 | AU28: 369.61071 | AV28: 3500 | AW28: 0 | AX28: 1800 | AY28: 2499.7026 | AZ28: 13500 | BA28: 9000
B29: =B28+1 -> 46071 | C29: =TEXT(B29,"ddd") -> Rab | D29: =SUM(E29:BA29) -> 184874.47 | E29: 812.17 | F29: 2500 | G29: 1129.7313 | H29: 3282.5161 | I29: 644.02065 | J29: 2000 | K29: 166.97065 | L29: 603.76323 | M29: 673.27548 | N29: 5514.199 | O29: 6000.0623 | P29: 2874.3265 | Q29: 15659.555 | R29: 1500 | S29: 11000.057 | T29: 3999.6897 | U29: 3500 | V29: 3500 | W29: 1500 | X29: 926.09448 | Y29: 4500 | Z29: 70.054839 | AA29: 89.451613 | AB29: 3500 | AC29: 4000.4806 | AD29: 0 | AE29: 2020.8603 | AF29: 678.7 | AG29: 7121.8519 | AH29: 3499.8768 | AI29: 1500.2745 | AJ29: 2139.5303 | AK29: 1260.9742 | AL29: 10000.047 | AM29: 1519.5448 | AN29: 3999.6742 | AO29: 26500 | AP29: 5000 | AQ29: 2105.6477 | AR29: 726.81516 | AS29: 3018.0416 | AT29: 2044.9997 | AU29: 369.61071 | AV29: 3500 | AW29: 1121.9003 | AX29: 1800 | AY29: 2499.7026 | AZ29: 13500 | BA29: 9000
B30: =B29+1 -> 46072 | C30: =TEXT(B30,"ddd") -> Kam | D30: =SUM(E30:BA30) -> 184874.47 | E30: 812.17 | F30: 2500 | G30: 1129.7313 | H30: 3282.5161 | I30: 644.02065 | J30: 2000 | K30: 166.97065 | L30: 603.76323 | M30: 673.27548 | N30: 5514.199 | O30: 6000.0623 | P30: 2874.3265 | Q30: 15659.555 | R30: 1500 | S30: 11000.057 | T30: 3999.6897 | U30: 3500 | V30: 3500 | W30: 1500 | X30: 926.09448 | Y30: 4500 | Z30: 70.054839 | AA30: 89.451613 | AB30: 3500 | AC30: 4000.4806 | AD30: 0 | AE30: 2020.8603 | AF30: 678.7 | AG30: 7121.8519 | AH30: 3499.8768 | AI30: 1500.2745 | AJ30: 2139.5303 | AK30: 1260.9742 | AL30: 10000.047 | AM30: 1519.5448 | AN30: 3999.6742 | AO30: 26500 | AP30: 5000 | AQ30: 2105.6477 | AR30: 726.81516 | AS30: 3018.0416 | AT30: 2044.9997 | AU30: 369.61071 | AV30: 3500 | AW30: 1121.9003 | AX30: 1800 | AY30: 2499.7026 | AZ30: 13500 | BA30: 9000
B31: =B30+1 -> 46073 | C31: =TEXT(B31,"ddd") -> Jum | D31: =SUM(E31:BA31) -> 184874.47 | E31: 812.17 | F31: 2500 | G31: 1129.7313 | H31: 3282.5161 | I31: 644.02065 | J31: 2000 | K31: 166.97065 | L31: 603.76323 | M31: 673.27548 | N31: 5514.199 | O31: 6000.0623 | P31: 2874.3265 | Q31: 15659.555 | R31: 1500 | S31: 11000.057 | T31: 3999.6897 | U31: 3500 | V31: 3500 | W31: 1500 | X31: 926.09448 | Y31: 4500 | Z31: 70.054839 | AA31: 89.451613 | AB31: 3500 | AC31: 4000.4806 | AD31: 0 | AE31: 2020.8603 | AF31: 678.7 | AG31: 7121.8519 | AH31: 3499.8768 | AI31: 1500.2745 | AJ31: 2139.5303 | AK31: 1260.9742 | AL31: 10000.047 | AM31: 1519.5448 | AN31: 3999.6742 | AO31: 26500 | AP31: 5000 | AQ31: 2105.6477 | AR31: 726.81516 | AS31: 3018.0416 | AT31: 2044.9997 | AU31: 369.61071 | AV31: 3500 | AW31: 1121.9003 | AX31: 1800 | AY31: 2499.7026 | AZ31: 13500 | BA31: 9000
B32: =B31+1 -> 46074 | C32: =TEXT(B32,"ddd") -> Sab | D32: =SUM(E32:BA32) -> 173474.59 | E32: 812.17 | F32: 2000 | G32: 729.73129 | H32: 2282.5161 | I32: 644.02065 | J32: 2000 | K32: 166.97065 | L32: 603.76323 | M32: 673.27548 | N32: 4514.199 | O32: 6000.0623 | P32: 2874.3265 | Q32: 15659.555 | R32: 1500 | S32: 9000.0571 | T32: 3999.6897 | U32: 3500 | V32: 3500 | W32: 1500 | X32: 926.09448 | Y32: 4500 | Z32: 70.054839 | AA32: 89.451613 | AB32: 3500 | AC32: 4000.4806 | AD32: 0 | AE32: 2020.8603 | AF32: 678.7 | AG32: 4121.8519 | AH32: 0 | AI32: 1500.2745 | AJ32: 2139.5303 | AK32: 1260.9742 | AL32: 10000.047 | AM32: 1519.5448 | AN32: 3999.6742 | AO32: 26500 | AP32: 5000 | AQ32: 2105.6477 | AR32: 726.81516 | AS32: 3018.0416 | AT32: 2044.9997 | AU32: 369.61071 | AV32: 3500 | AW32: 1121.9003 | AX32: 1800 | AY32: 2499.7026 | AZ32: 13500 | BA32: 9000
B33: =B32+1 -> 46075 | C33: =TEXT(B33,"ddd") -> Mgg | D33: =SUM(E33:BA33) -> 163636.42 | E33: 812.17 | F33: 500 | G33: 729.73129 | H33: 999.51613 | I33: 644.02065 | J33: 2000 | K33: 0 | L33: 603.76323 | M33: 673.27548 | N33: 0 | O33: 6000.0623 | P33: 500.32645 | Q33: 6659.5545 | R33: 1500 | S33: 6000.0571 | T33: 3999.6897 | U33: 3500 | V33: 3500 | W33: 1500 | X33: 926.09448 | Y33: 2500 | Z33: 70.054839 | AA33: 89.451613 | AB33: 3500 | AC33: 1000.4806 | AD33: 0 | AE33: 2020.8603 | AF33: 678.7 | AG33: 2121.8519 | AH33: 0 | AI33: 1500.2745 | AJ33: 2139.5303 | AK33: 1260.9742 | AL33: 10000.047 | AM33: 1519.5448 | AN33: 3999.6742 | AO33: 45500 | AP33: 5000 | AQ33: 2105.6477 | AR33: 726.81516 | AS33: 3018.0416 | AT33: 2044.9997 | AU33: 369.61071 | AV33: 3500 | AW33: 1121.9003 | AX33: 1800 | AY33: 2499.7026 | AZ33: 13500 | BA33: 9000
B34: Sub Total | D34: =SUM(D27:D33) -> 1183976.9 | E34: =SUM(E27:E33) -> 5685.19 | F34: =SUM(F27:F33) -> 11000 | G34: =SUM(G27:G33) -> 6108.119 | H34: =SUM(H27:H33) -> 13129.581 | I34: =SUM(I27:I33) -> 4508.1445 | J34: =SUM(J27:J33) -> 10000 | K34: =SUM(K27:K33) -> 667.88258 | ... BA34: =SUM(BA27:BA33) -> 63000
A36: =WEEKNUM(B41) -> 9 | B36: =B33+1 -> 46076 | C36: =TEXT(B36,"ddd") -> Sen | D36: =SUM(E36:BA36) -> 188374.47 | E36: 812.17 | F36: 2500 | G36: 1129.7313 | H36: 3282.5161 | I36: 644.02065 | J36: 5500 | K36: 166.97065 | L36: 603.76323 | M36: 673.27548 | N36: 5514.199 | O36: 6000.0623 | P36: 2874.3265 | Q36: 15659.555 | R36: 1500 | S36: 11000.057 | T36: 3999.6897 | U36: 3500 | V36: 3500 | W36: 1500 | X36: 926.09448 | Y36: 4500 | Z36: 70.054839 | AA36: 89.451613 | AB36: 3500 | AC36: 4000.4806 | AD36: 0 | AE36: 2020.8603 | AF36: 678.7 | AG36: 7121.8519 | AH36: 3499.8768 | AI36: 1500.2745 | AJ36: 2139.5303 | AK36: 1260.9742 | AL36: 10000.047 | AM36: 1519.5448 | AN36: 3999.6742 | AO36: 26500 | AP36: 5000 | AQ36: 2105.6477 | AR36: 726.81516 | AS36: 3018.0416 | AT36: 2044.9997 | AU36: 369.61071 | AV36: 3500 | AW36: 1121.9003 | AX36: 1800 | AY36: 2499.7026 | AZ36: 13500 | BA36: 9000
B37: =B36+1 -> 46077 | C37: =TEXT(B37,"ddd") -> Sel | D37: =SUM(E37:BA37) -> 188374.47 | E37: 812.17 | F37: 2500 | G37: 1129.7313 | H37: 3282.5161 | I37: 644.02065 | J37: 5500 | K37: 166.97065 | L37: 603.76323 | M37: 673.27548 | N37: 5514.199 | O37: 6000.0623 | P37: 2874.3265 | Q37: 15659.555 | R37: 1500 | S37: 11000.057 | T37: 3999.6897 | U37: 3500 | V37: 3500 | W37: 1500 | X37: 926.09448 | Y37: 4500 | Z37: 70.054839 | AA37: 89.451613 | AB37: 3500 | AC37: 4000.4806 | AD37: 0 | AE37: 2020.8603 | AF37: 678.7 | AG37: 7121.8519 | AH37: 3499.8768 | AI37: 1500.2745 | AJ37: 2139.5303 | AK37: 1260.9742 | AL37: 10000.047 | AM37: 1519.5448 | AN37: 3999.6742 | AO37: 26500 | AP37: 5000 | AQ37: 2105.6477 | AR37: 726.81516 | AS37: 3018.0416 | AT37: 2044.9997 | AU37: 369.61071 | AV37: 3500 | AW37: 1121.9003 | AX37: 1800 | AY37: 2499.7026 | AZ37: 13500 | BA37: 9000
B38: =B37+1 -> 46078 | C38: =TEXT(B38,"ddd") -> Rab | D38: =SUM(E38:BA38) -> 188374.47 | E38: 812.17 | F38: 2500 | G38: 1129.7313 | H38: 3282.5161 | I38: 644.02065 | J38: 5500 | K38: 166.97065 | L38: 603.76323 | M38: 673.27548 | N38: 5514.199 | O38: 6000.0623 | P38: 2874.3265 | Q38: 15659.555 | R38: 1500 | S38: 11000.057 | T38: 3999.6897 | U38: 3500 | V38: 3500 | W38: 1500 | X38: 926.09448 | Y38: 4500 | Z38: 70.054839 | AA38: 89.451613 | AB38: 3500 | AC38: 4000.4806 | AD38: 0 | AE38: 2020.8603 | AF38: 678.7 | AG38: 7121.8519 | AH38: 3499.8768 | AI38: 1500.2745 | AJ38: 2139.5303 | AK38: 1260.9742 | AL38: 10000.047 | AM38: 1519.5448 | AN38: 3999.6742 | AO38: 26500 | AP38: 5000 | AQ38: 2105.6477 | AR38: 726.81516 | AS38: 3018.0416 | AT38: 2044.9997 | AU38: 369.61071 | AV38: 3500 | AW38: 1121.9003 | AX38: 1800 | AY38: 2499.7026 | AZ38: 13500 | BA38: 9000
B39: =B38+1 -> 46079 | C39: =TEXT(B39,"ddd") -> Kam | D39: =SUM(E39:BA39) -> 188374.47 | E39: 812.17 | F39: 2500 | G39: 1129.7313 | H39: 3282.5161 | I39: 644.02065 | J39: 5500 | K39: 166.97065 | L39: 603.76323 | M39: 673.27548 | N39: 5514.199 | O39: 6000.0623 | P39: 2874.3265 | Q39: 15659.555 | R39: 1500 | S39: 11000.057 | T39: 3999.6897 | U39: 3500 | V39: 3500 | W39: 1500 | X39: 926.09448 | Y39: 4500 | Z39: 70.054839 | AA39: 89.451613 | AB39: 3500 | AC39: 4000.4806 | AD39: 0 | AE39: 2020.8603 | AF39: 678.7 | AG39: 7121.8519 | AH39: 3499.8768 | AI39: 1500.2745 | AJ39: 2139.5303 | AK39: 1260.9742 | AL39: 10000.047 | AM39: 1519.5448 | AN39: 3999.6742 | AO39: 26500 | AP39: 5000 | AQ39: 2105.6477 | AR39: 726.81516 | AS39: 3018.0416 | AT39: 2044.9997 | AU39: 369.61071 | AV39: 3500 | AW39: 1121.9003 | AX39: 1800 | AY39: 2499.7026 | AZ39: 13500 | BA39: 9000
B40: =B39+1 -> 46080 | C40: =TEXT(B40,"ddd") -> Jum | D40: =SUM(E40:BA40) -> 188374.47 | E40: 812.17 | F40: 2500 | G40: 1129.7313 | H40: 3282.5161 | I40: 644.02065 | J40: 5500 | K40: 166.97065 | L40: 603.76323 | M40: 673.27548 | N40: 5514.199 | O40: 6000.0623 | P40: 2874.3265 | Q40: 15659.555 | R40: 1500 | S40: 11000.057 | T40: 3999.6897 | U40: 3500 | V40: 3500 | W40: 1500 | X40: 926.09448 | Y40: 4500 | Z40: 70.054839 | AA40: 89.451613 | AB40: 3500 | AC40: 4000.4806 | AD40: 0 | AE40: 2020.8603 | AF40: 678.7 | AG40: 7121.8519 | AH40: 3499.8768 | AI40: 1500.2745 | AJ40: 2139.5303 | AK40: 1260.9742 | AL40: 10000.047 | AM40: 1519.5448 | AN40: 3999.6742 | AO40: 26500 | AP40: 5000 | AQ40: 2105.6477 | AR40: 726.81516 | AS40: 3018.0416 | AT40: 2044.9997 | AU40: 369.61071 | AV40: 3500 | AW40: 1121.9003 | AX40: 1800 | AY40: 2499.7026 | AZ40: 13500 | BA40: 9000
B41: =B40+1 -> 46081 | C41: =TEXT(B41,"ddd") -> Sab | D41: =SUM(E41:BA41) -> 176974.59 | E41: 812.17 | F41: 2000 | G41: 729.73129 | H41: 2282.5161 | I41: 644.02065 | J41: 5500 | K41: 166.97065 | L41: 603.76323 | M41: 673.27548 | N41: 4514.199 | O41: 6000.0623 | P41: 2874.3265 | Q41: 15659.555 | R41: 1500 | S41: 9000.0571 | T41: 3999.6897 | U41: 3500 | V41: 3500 | W41: 1500 | X41: 926.09448 | Y41: 4500 | Z41: 70.054839 | AA41: 89.451613 | AB41: 3500 | AC41: 4000.4806 | AD41: 0 | AE41: 2020.8603 | AF41: 678.7 | AG41: 4121.8519 | AH41: 0 | AI41: 1500.2745 | AJ41: 2139.5303 | AK41: 1260.9742 | AL41: 10000.047 | AM41: 1519.5448 | AN41: 3999.6742 | AO41: 26500 | AP41: 5000 | AQ41: 2105.6477 | AR41: 726.81516 | AS41: 3018.0416 | AT41: 2044.9997 | AU41: 369.61071 | AV41: 3500 | AW41: 1121.9003 | AX41: 1800 | AY41: 2499.7026 | AZ41: 13500 | BA41: 9000
B42: Sub Total | D42: =SUM(D36:D41) -> 1118846.9 | E42: =SUM(E36:E41) -> 4873.02 | F42: =SUM(F36:F41) -> 14500 | G42: =SUM(G36:G41) -> 6378.3877 | H42: =SUM(H36:H41) -> 18695.097 | I42: =SUM(I36:I41) -> 3864.1239 | J42: =SUM(J36:J41) -> 33000 | K42: =SUM(K36:K41) -> 1001.8239 | ... BA42: =SUM(BA36:BA41) -> 54000
B46: Sub Total | D46: =SUM(D42,D34,D25,D16,D7) -> 4950102 | E46: =SUM(E42,E34,E25,E16,E7) -> 22740.76 | F46: =SUM(F42,F34,F25,F16,F7) -> 64500 | G46: =SUM(G42,G34,G25,G16,G7) -> 28632.476 | H46: =SUM(H42,H34,H25,H16,H7) -> 81062.419 | I46: =SUM(I42,I34,I25,I16,I7) -> 18032.578 | J46: =SUM(J42,J34,J25,J16,J7) -> 101000 | K46: =SUM(K42,K34,K25,K16,K7) -> 4007.2955 | ... BA46: =SUM(BA42,BA34,BA25,BA16,BA7) -> 184500
B47: Total | D47: =SUM(D27:D33,D18:D24,D9:D15,D6,D36:D41) -> 4950102 | E47: =SUM(E27:E33,E18:E24,E9:E15,E6,E36:E41) -> 22740.76 | F47: =SUM(F27:F33,F18:F24,F9:F15,F6,F36:F41) -> 64500 | G47: =SUM(G27:G33,G18:G24,G9:G15,G6,G36:G41) -> 28632.476 | H47: =SUM(H27:H33,H18:H24,H9:H15,H6,H36:H41) -> 81062.419 | I47: =SUM(I27:I33,I18:I24,I9:I15,I6,I36:I41) -> 18032.578 | J47: =SUM(J27:J33,J18:J24,J9:J15,J6,J36:J41) -> 101000 | K47: =SUM(K27:K33,K18:K24,K9:K15,K6,K36:K41) -> 4007.2955 | ... BA47: =SUM(BA27:BA33,BA18:BA24,BA9:BA15,BA6,BA36:BA41) -> 184500
B58: 5. Penyesuaian volume MS SETU, kuota Torabika IC di tambahkan ke Torabika Cikupa mulai April 2025
B59: 5. Penyesuaian volume MS SETU, kuota Torabika IC di tambahkan ke Torabika Cikupa mulai April 2025
...

Sheet SUMMARY GAS
A1: KEBUTUHAN GAS
A4: =B6 -> 46054 | E4: KEBUTUHAN GAS | I4: KUOTA GAS | R4: ACTUAL SERAPAN GAS
A5: Week | B5: DATE | D5: SELISIH GAS | E5: JABAR | F5: JATENG | G5: JATIM | H5: TOTAL | I5: MS SETU | J5: MS KHT | K5: MS BITUNG | L5: MS TAMBAKLOROK | M5: MS BLORA | N5: MS ZEBRA | O5: MS WUNUT | P5: MS JES | Q5: TOTAL | R5: MS SETU | S5: MS KHT | T5: MS BITUNG | U5: MS TAMBAKLOROK | V5: MS BLORA | W5: MS ZEBRA | X5: MS WUNUT | Y5: MS JES | Z5: TOTAL
A6: =WEEKNUM(B6) -> 6 | B6: 46054 | C6: =TEXT(B6,"ddd") -> Mgg | D6: =Q6-H6 -> -18751.47 | E6: =SUM('SO Februari 2026 Rev.2'!E6:AQ6) -> 152670.4 | F6: =SUM('SO Februari 2026 Rev.2'!AR6:AY6) -> 14781.07 | G6: =SUM('SO Februari 2026 Rev.2'!AZ6:BA6) -> 13500 | H6: =SUM(E6:G6) -> 180951.47 | I6: =3*28000 -> 84000 | J6: =1.8*24000 -> 43200 | K6: =13000 -> 13000 | M6: =0.5*24000 -> 12000 | O6: 10000 | Q6: =SUM(I6:P6) -> 162200 | R6: ='Summary sales'!D8 -> 65680.61 | S6: ='Summary sales'!E8 -> 27163.79 | T6: ='Summary sales'!G8 -> 11250.33 | U6: ='Summary sales'!I8 -> 0 | V6: ='Summary sales'!F8 -> 18204.9 | W6: ='Summary sales'!H8 -> 0 | X6: ='Summary sales'!K8 -> 4132.085 | Y6: ='Summary sales'!L8 -> 0 | Z6: =SUM(R6:Y6) -> 126431.71
B7: Sub Total | D7: =SUM(D6) -> -18751.47 | E7: =SUM(E6) -> 152670.4 | F7: =SUM(F6) -> 14781.07 | G7: =SUM(G6) -> 13500 | H7: =SUM(H6) -> 180951.47 | I7: =SUM(I6) -> 84000 | J7: =SUM(J6) -> 43200 | K7: =SUM(K6) -> 13000 | ... Z7: =SUM(Z6) -> 126431.71
A9: =WEEKNUM(B9) -> 6 | B9: =B6+1 -> 46055 | C9: =TEXT(B9,"ddd") -> Sen | D9: =Q9-H9 -> -23311.47 | E9: =SUM('SO Februari 2026 Rev.2'!E9:AQ9) -> 152670.4 | F9: =SUM('SO Februari 2026 Rev.2'!AR9:AY9) -> 14781.07 | G9: =SUM('SO Februari 2026 Rev.2'!AZ9:BA9) -> 13500 | H9: =SUM(E9:G9) -> 180951.47 | I9: 84000 | J9: =1.61*24000 -> 38640 | K9: 13000 | M9: =0.5*24000 -> 12000 | O9: 10000 | Q9: =SUM(I9:P9) -> 157640 | R9: ='Summary sales'!D9 -> 67220.24 | S9: ='Summary sales'!E9 -> 54414.53 | T9: ='Summary sales'!G9 -> 10284.26 | U9: ='Summary sales'!I9 -> 0 | V9: ='Summary sales'!F9 -> 22714.29 | W9: ='Summary sales'!H9 -> 0 | X9: ='Summary sales'!K9 -> 4145.078 | Y9: ='Summary sales'!L9 -> 0 | Z9: =SUM(R9:Y9) -> 158778.4
B10: =B9+1 -> 46056 | C10: =TEXT(B10,"ddd") -> Sel | D10: =Q10-H10 -> -18311.47 | E10: =SUM('SO Februari 2026 Rev.2'!E10:AQ10) -> 152670.4 | F10: =SUM('SO Februari 2026 Rev.2'!AR10:AY10) -> 14781.07 | G10: =SUM('SO Februari 2026 Rev.2'!AZ10:BA10) -> 13500 | H10: =SUM(E10:G10) -> 180951.47 | I10: 84000 | J10: =1.61*24000 -> 38640 | K10: 13000 | L10: 5000 | M10: =0.5*24000 -> 12000 | O10: 10000 | Q10: =SUM(I10:P10) -> 162640 | R10: ='Summary sales'!D10 -> 68333.24 | S10: ='Summary sales'!E10 -> 52211.86 | T10: ='Summary sales'!G10 -> 9298.95 | U10: ='Summary sales'!I10 -> 0 | V10: ='Summary sales'!F10 -> 22550.56 | W10: ='Summary sales'!H10 -> 0 | X10: ='Summary sales'!K10 -> 3903.109 | Y10: ='Summary sales'!L10 -> 0 | Z10: =SUM(R10:Y10) -> 156297.72
B11: =B10+1 -> 46057 | C11: =TEXT(B11,"ddd") -> Rab | D11: =Q11-H11 -> -18311.47 | E11: =SUM('SO Februari 2026 Rev.2'!E11:AQ11) -> 152670.4 | F11: =SUM('SO Februari 2026 Rev.2'!AR11:AY11) -> 14781.07 | G11: =SUM('SO Februari 2026 Rev.2'!AZ11:BA11) -> 13500 | H11: =SUM(E11:G11) -> 180951.47 | I11: 84000 | J11: =1.61*24000 -> 38640 | K11: 13000 | L11: 5000 | M11: =0.5*24000 -> 12000 | O11: 10000 | Q11: =SUM(I11:P11) -> 162640 | R11: ='Summary sales'!D11 -> 72469.97 | S11: ='Summary sales'!E11 -> 54698.88 | T11: ='Summary sales'!G11 -> 9866 | U11: ='Summary sales'!I11 -> 0 | V11: ='Summary sales'!F11 -> 13355.34 | W11: ='Summary sales'!H11 -> 0 | X11: ='Summary sales'!K11 -> 4367.708 | Y11: ='Summary sales'!L11 -> 0 | Z11: =SUM(R11:Y11) -> 154757.9
B12: =B11+1 -> 46058 | C12: =TEXT(B12,"ddd") -> Kam | D12: =Q12-H12 -> -22391.47 | E12: =SUM('SO Februari 2026 Rev.2'!E12:AQ12) -> 152670.4 | F12: =SUM('SO Februari 2026 Rev.2'!AR12:AY12) -> 14781.07 | G12: =SUM('SO Februari 2026 Rev.2'!AZ12:BA12) -> 13500 | H12: =SUM(E12:G12) -> 180951.47 | I12: 84000 | J12: =1.44*24000 -> 34560 | K12: 13000 | L12: 5000 | M12: =0.5*24000 -> 12000 | O12: 10000 | Q12: =SUM(I12:P12) -> 158560 | R12: ='Summary sales'!D12 -> 69578.64 | S12: ='Summary sales'!E12 -> 48891.03 | T12: ='Summary sales'!G12 -> 13940.41 | U12: ='Summary sales'!I12 -> 3400.26 | V12: ='Summary sales'!F12 -> 23008.11 | W12: ='Summary sales'!H12 -> 0 | X12: ='Summary sales'!K12 -> 4280.4 | Y12: ='Summary sales'!L12 -> 0 | Z12: =SUM(R12:Y12) -> 163098.85
B13: =B12+1 -> 46059 | C13: =TEXT(B13,"ddd") -> Jum | D13: =Q13-H13 -> -22391.47 | E13: =SUM('SO Februari 2026 Rev.2'!E13:AQ13) -> 152670.4 | F13: =SUM('SO Februari 2026 Rev.2'!AR13:AY13) -> 14781.07 | G13: =SUM('SO Februari 2026 Rev.2'!AZ13:BA13) -> 13500 | H13: =SUM(E13:G13) -> 180951.47 | I13: 84000 | J13: =1.44*24000 -> 34560 | K13: 13000 | L13: 5000 | M13: =0.5*24000 -> 12000 | O13: 10000 | Q13: =SUM(I13:P13) -> 158560 | R13: ='Summary sales'!D13 -> 77972.03 | S13: ='Summary sales'!E13 -> 55115.98 | T13: ='Summary sales'!G13 -> 10778.32 | U13: ='Summary sales'!I13 -> 4002.23 | V13: ='Summary sales'!F13 -> 18549.36 | W13: ='Summary sales'!H13 -> 0 | X13: ='Summary sales'!K13 -> 3227.514 | Y13: ='Summary sales'!L13 -> 0 | Z13: =SUM(R13:Y13) -> 169645.43
B14: =B13+1 -> 46060 | C14: =TEXT(B14,"ddd") -> Sab | D14: =Q14-H14 -> -22391.47 | E14: =SUM('SO Februari 2026 Rev.2'!E14:AQ14) -> 152670.4 | F14: =SUM('SO Februari 2026 Rev.2'!AR14:AY14) -> 14781.07 | G14: =SUM('SO Februari 2026 Rev.2'!AZ14:BA14) -> 13500 | H14: =SUM(E14:G14) -> 180951.47 | I14: 84000 | J14: =1.44*24000 -> 34560 | K14: 13000 | L14: 5000 | M14: =0.5*24000 -> 12000 | O14: 10000 | Q14: =SUM(I14:P14) -> 158560 | R14: ='Summary sales'!D14 -> 87147.29 | S14: ='Summary sales'!E14 -> 47499.03 | T14: ='Summary sales'!G14 -> 0 | U14: ='Summary sales'!I14 -> 4507.53 | V14: ='Summary sales'!F14 -> 19287.7 | W14: ='Summary sales'!H14 -> 0 | X14: ='Summary sales'!K14 -> 4205.486 | Y14: ='Summary sales'!L14 -> 0 | Z14: =SUM(R14:Y14) -> 162647.04
B15: =B14+1 -> 46061 | C15: =TEXT(B15,"ddd") -> Mgg | D15: =Q15-H15 -> -22391.47 | E15: =SUM('SO Februari 2026 Rev.2'!E15:AQ15) -> 152670.4 | F15: =SUM('SO Februari 2026 Rev.2'!AR15:AY15) -> 14781.07 | G15: =SUM('SO Februari 2026 Rev.2'!AZ15:BA15) -> 13500 | H15: =SUM(E15:G15) -> 180951.47 | I15: 84000 | J15: =1.44*24000 -> 34560 | K15: 13000 | L15: 5000 | M15: =0.5*24000 -> 12000 | O15: 10000 | Q15: =SUM(I15:P15) -> 158560 | R15: ='Summary sales'!D15 -> 83726.4 | S15: ='Summary sales'!E15 -> 47551.77 | T15: ='Summary sales'!G15 -> 8746.28 | U15: ='Summary sales'!I15 -> 3583.8 | V15: ='Summary sales'!F15 -> 25515.59 | W15: ='Summary sales'!H15 -> 0 | X15: ='Summary sales'!K15 -> 8439.715 | Y15: ='Summary sales'!L15 -> 0 | Z15: =SUM(R15:Y15) -> 177563.55
B16: Sub Total | D16: =Q16-H16 -> -149500.29 | E16: =SUM(E9:E15) -> 1068692.8 | F16: =SUM(F9:F15) -> 103467.49 | G16: =SUM(G9:G15) -> 94500 | H16: =SUM(H9:H15) -> 1266660.3 | I16: =SUM(I9:I15) -> 588000 | J16: =SUM(J9:J15) -> 254160 | K16: =SUM(K9:K15) -> 91000 | L16: =SUM(L9:L15) -> 30000 | ... Z16: =SUM(Z9:Z15) -> 1142788.9
E17: =SUM('SO Februari 2026 Rev.2'!E17:AQ17)-'SO Februari 2026 Rev.2'!U17 -> 0
A18: =WEEKNUM(B23) -> 7 | B18: =B15+1 -> 46062 | C18: =TEXT(B18,"ddd") -> Sen | D18: =Q18-H18 -> -7014.4704 | E18: =SUM('SO Februari 2026 Rev.2'!E18:AQ18) -> 147293.4 | F18: =SUM('SO Februari 2026 Rev.2'!AR18:AY18) -> 14781.07 | G18: =SUM('SO Februari 2026 Rev.2'!AZ18:BA18) -> 13500 | H18: =SUM(E18:G18) -> 175574.47 | I18: 84000 | J18: =1.44*24000 -> 34560 | K18: 13000 | L18: 5000 | M18: =0.5*24000 -> 12000 | N18: 10000 | O18: 10000 | Q18: =SUM(I18:P18) -> 168560 | R18: ='Summary sales'!D16 -> 83018.27 | S18: ='Summary sales'!E16 -> 50487.25 | T18: ='Summary sales'!G16 -> 4901.39 | U18: ='Summary sales'!I16 -> 3288.62 | V18: ='Summary sales'!F16 -> 28237.89 | W18: ='Summary sales'!H16 -> 0 | X18: ='Summary sales'!K16 -> 4285.751 | Y18: ='Summary sales'!L16 -> 0 | Z18: =SUM(R18:Y18) -> 174219.17
B19: =B18+1 -> 46063 | C19: =TEXT(B19,"ddd") -> Sel | D19: =Q19-H19 -> -7014.4704 | E19: =SUM('SO Februari 2026 Rev.2'!E19:AQ19) -> 147293.4 | F19: =SUM('SO Februari 2026 Rev.2'!AR19:AY19) -> 14781.07 | G19: =SUM('SO Februari 2026 Rev.2'!AZ19:BA19) -> 13500 | H19: =SUM(E19:G19) -> 175574.47 | I19: 84000 | J19: =1.44*24000 -> 34560 | K19: 13000 | L19: 5000 | M19: =0.5*24000 -> 12000 | N19: 10000 | O19: 10000 | Q19: =SUM(I19:P19) -> 168560 | R19: ='Summary sales'!D17 -> 83245.43 | S19: ='Summary sales'!E17 -> 47611.23 | T19: ='Summary sales'!G17 -> 9543.6 | U19: ='Summary sales'!I17 -> 0 | V19: ='Summary sales'!F17 -> 24041.73 | W19: ='Summary sales'!H17 -> 0 | X19: ='Summary sales'!K17 -> 13719.345 | Y19: ='Summary sales'!L17 -> 0 | Z19: =SUM(R19:Y19) -> 178161.34
B20: =B19+1 -> 46064 | C20: =TEXT(B20,"ddd") -> Rab | D20: =Q20-H20 -> -7014.4704 | E20: =SUM('SO Februari 2026 Rev.2'!E20:AQ20) -> 147293.4 | F20: =SUM('SO Februari 2026 Rev.2'!AR20:AY20) -> 14781.07 | G20: =SUM('SO Februari 2026 Rev.2'!AZ20:BA20) -> 13500 | H20: =SUM(E20:G20) -> 175574.47 | I20: 84000 | J20: =1.44*24000 -> 34560 | K20: 13000 | L20: 5000 | M20: =0.5*24000 -> 12000 | N20: 10000 | O20: 10000 | Q20: =SUM(I20:P20) -> 168560 | R20: ='Summary sales'!D18 -> 83389.85 | S20: ='Summary sales'!E18 -> 48102.97 | T20: ='Summary sales'!G18 -> 7419.46 | U20: ='Summary sales'!I18 -> 3637.13 | V20: ='Summary sales'!F18 -> 24581.93 | W20: ='Summary sales'!H18 -> 4156.133 | X20: ='Summary sales'!K18 -> 12998.123 | Y20: ='Summary sales'!L18 -> 0 | Z20: =SUM(R20:Y20) -> 184285.6
B21: =B20+1 -> 46065 | C21: =TEXT(B21,"ddd") -> Kam | D21: =Q21-H21 -> -7014.4704 | E21: =SUM('SO Februari 2026 Rev.2'!E21:AQ21) -> 147293.4 | F21: =SUM('SO Februari 2026 Rev.2'!AR21:AY21) -> 14781.07 | G21: =SUM('SO Februari 2026 Rev.2'!AZ21:BA21) -> 13500 | H21: =SUM(E21:G21) -> 175574.47 | I21: 84000 | J21: =1.44*24000 -> 34560 | K21: 13000 | L21: 5000 | M21: =0.5*24000 -> 12000 | N21: 10000 | O21: 10000 | Q21: =SUM(I21:P21) -> 168560 | R21: ='Summary sales'!D19 -> 77591.26 | S21: ='Summary sales'!E19 -> 49097.03 | T21: ='Summary sales'!G19 -> 10299.28 | U21: ='Summary sales'!I19 -> 6645.21 | V21: ='Summary sales'!F19 -> 23333.07 | W21: ='Summary sales'!H19 -> 0 | X21: ='Summary sales'!K19 -> 9061.876 | Y21: ='Summary sales'!L19 -> 0 | Z21: =SUM(R21:Y21) -> 176027.73
B22: =B21+1 -> 46066 | C22: =TEXT(B22,"ddd") -> Jum | D22: =Q22-H22 -> -7014.4704 | E22: =SUM('SO Februari 2026 Rev.2'!E22:AQ22) -> 147293.4 | F22: =SUM('SO Februari 2026 Rev.2'!AR22:AY22) -> 14781.07 | G22: =SUM('SO Februari 2026 Rev.2'!AZ22:BA22) -> 13500 | H22: =SUM(E22:G22) -> 175574.47 | I22: 84000 | J22: =1.44*24000 -> 34560 | K22: 13000 | L22: 5000 | M22: =0.5*24000 -> 12000 | N22: 10000 | O22: 10000 | Q22: =SUM(I22:P22) -> 168560 | R22: ='Summary sales'!D20 -> 80453.75 | S22: ='Summary sales'!E20 -> 45710.39 | T22: ='Summary sales'!G20 -> 11605.67 | U22: ='Summary sales'!I20 -> 3853.52 | V22: ='Summary sales'!F20 -> 20950.19 | W22: ='Summary sales'!H20 -> 4665.24 | X22: ='Summary sales'!K20 -> 8362.777 | Y22: ='Summary sales'!L20 -> 0 | Z22: =SUM(R22:Y22) -> 175601.54
B23: =B22+1 -> 46067 | C23: =TEXT(B23,"ddd") -> Sab | D23: =Q23-H23 -> 3385.4064 | E23: =SUM('SO Februari 2026 Rev.2'!E23:AQ23) -> 136893.52 | F23: =SUM('SO Februari 2026 Rev.2'!AR23:AY23) -> 14781.07 | G23: =SUM('SO Februari 2026 Rev.2'!AZ23:BA23) -> 13500 | H23: =SUM(E23:G23) -> 165174.59 | I23: 84000 | J23: =1.44*24000 -> 34560 | K23: 13000 | L23: 5000 | M23: =0.5*24000 -> 12000 | N23: 10000 | O23: 10000 | Q23: =SUM(I23:P23) -> 168560 | R23: ='Summary sales'!D21 -> 75311.32 | S23: ='Summary sales'!E21 -> 45351.01 | T23: ='Summary sales'!G21 -> 11283.88 | U23: ='Summary sales'!I21 -> 6326.6 | V23: ='Summary sales'!F21 -> 25244.9 | W23: ='Summary sales'!H21 -> 4505.721 | X23: ='Summary sales'!K21 -> 8556.172 | Y23: ='Summary sales'!L21 -> 0 | Z23: =SUM(R23:Y23) -> 176579.6
B24: =B23+1 -> 46068 | C24: =TEXT(B24,"ddd") -> Mgg | D24: =Q24-H24 -> 11940.576 | E24: =SUM('SO Februari 2026 Rev.2'!E24:AQ24) -> 128338.35 | F24: =SUM('SO Februari 2026 Rev.2'!AR24:AY24) -> 14781.07 | G24: =SUM('SO Februari 2026 Rev.2'!AZ24:BA24) -> 13500 | H24: =SUM(E24:G24) -> 156619.42 | I24: 84000 | J24: =1.44*24000 -> 34560 | K24: 13000 | L24: 5000 | M24: =0.5*24000 -> 12000 | N24: 10000 | O24: 10000 | Q24: =SUM(I24:P24) -> 168560 | R24: ='Summary sales'!D22 -> 88213.57 | S24: ='Summary sales'!E22 -> 49051.69 | T24: ='Summary sales'!G22 -> 11537.65 | U24: ='Summary sales'!I22 -> 3345.52 | V24: ='Summary sales'!F22 -> 24791.4 | W24: ='Summary sales'!H22 -> 4651.391 | X24: ='Summary sales'!K22 -> 7875.195 | Y24: ='Summary sales'!L22 -> 0 | Z24: =SUM(R24:Y24) -> 189466.42
B25: Sub Total | D25: =Q25-H25 -> -19746.369 | E25: =SUM(E18:E24) -> 1001698.9 | F25: =SUM(F18:F24) -> 103467.49 | G25: =SUM(G18:G24) -> 94500 | H25: =SUM(H18:H24) -> 1199666.4 | I25: =SUM(I18:I24) -> 588000 | J25: =SUM(J18:J24) -> 241920 | K25: =SUM(K18:K24) -> 91000 | L25: =SUM(L18:L24) -> 35000 | ... Z25: =SUM(Z18:Z24) -> 1254341.4
A27: =WEEKNUM(B32) -> 8 | B27: =B24+1 -> 46069 | C27: =TEXT(B27,"ddd") -> Sen | D27: =Q27-H27 -> 26988.979 | E27: =SUM('SO Februari 2026 Rev.2'!E27:AQ27) -> 113511.85 | F27: =SUM('SO Februari 2026 Rev.2'!AR27:AY27) -> 13959.17 | G27: =SUM('SO Februari 2026 Rev.2'!AZ27:BA27) -> 22500 | H27: =SUM(E27:G27) -> 149971.02 | I27: =3.3*28000 -> 92400 | J27: =1.44*24000 -> 34560 | K27: 13000 | L27: 5000 | M27: =0.5*24000 -> 12000 | N27: 10000 | O27: 10000 | Q27: =SUM(I27:P27) -> 176960 | R27: ='Summary sales'!D23 -> 85166.21 | S27: ='Summary sales'!E23 -> 45428.22 | T27: ='Summary sales'!G23 -> 10548.78 | U27: ='Summary sales'!I23 -> 3454.46 | V27: ='Summary sales'!F23 -> 13531.21 | W27: ='Summary sales'!H23 -> 0 | X27: ='Summary sales'!K23 -> 8563.532 | Y27: ='Summary sales'!L23 -> 0 | Z27: =SUM(R27:Y27) -> 166692.41
B28: =B27+1 -> 46070 | C28: =TEXT(B28,"ddd") -> Sel | D28: =Q28-H28 -> 34688.539 | E28: =SUM('SO Februari 2026 Rev.2'!E28:AQ28) -> 105812.29 | F28: =SUM('SO Februari 2026 Rev.2'!AR28:AY28) -> 13959.17 | G28: =SUM('SO Februari 2026 Rev.2'!AZ28:BA28) -> 22500 | H28: =SUM(E28:G28) -> 142271.46 | I28: 92400 | J28: =1.44*24000 -> 34560 | K28: 13000 | L28: 5000 | M28: =0.5*24000 -> 12000 | N28: 10000 | O28: 10000 | Q28: =SUM(I28:P28) -> 176960 | R28: ='Summary sales'!D24 -> 74677.92 | S28: ='Summary sales'!E24 -> 49266.33 | T28: ='Summary sales'!G24 -> 5529.94 | U28: ='Summary sales'!I24 -> 3444.89 | V28: ='Summary sales'!F24 -> 17092.17 | W28: ='Summary sales'!H24 -> 4700.939 | X28: ='Summary sales'!K24 -> 8234.772 | Y28: ='Summary sales'!L24 -> 0 | Z28: =SUM(R28:Y28) -> 162946.96
B29: =B28+1 -> 46071 | C29: =TEXT(B29,"ddd") -> Rab | D29: =Q29-H29 -> -7914.4704 | E29: =SUM('SO Februari 2026 Rev.2'!E29:AQ29) -> 147293.4 | F29: =SUM('SO Februari 2026 Rev.2'!AR29:AY29) -> 15081.07 | G29: =SUM('SO Februari 2026 Rev.2'!AZ29:BA29) -> 22500 | H29: =SUM(E29:G29) -> 184874.47 | I29: 92400 | J29: =1.44*24000 -> 34560 | K29: 13000 | L29: 5000 | M29: =0.5*24000 -> 12000 | N29: 10000 | O29: 10000 | Q29: =SUM(I29:P29) -> 176960 | R29: ='Summary sales'!D25 -> 75579.51 | S29: ='Summary sales'!E25 -> 45894.19 | T29: ='Summary sales'!G25 -> 10609.23 | U29: ='Summary sales'!I25 -> 3441.09 | V29: ='Summary sales'!F25 -> 22123.93 | W29: ='Summary sales'!H25 -> 4719.902 | X29: ='Summary sales'!K25 -> 8386.682 | Y29: ='Summary sales'!L25 -> 0 | Z29: =SUM(R29:Y29) -> 170754.53
B30: =B29+1 -> 46072 | C30: =TEXT(B30,"ddd") -> Kam | D30: =Q30-H30 -> -7914.4704 | E30: =SUM('SO Februari 2026 Rev.2'!E30:AQ30) -> 147293.4 | F30: =SUM('SO Februari 2026 Rev.2'!AR30:AY30) -> 15081.07 | G30: =SUM('SO Februari 2026 Rev.2'!AZ30:BA30) -> 22500 | H30: =SUM(E30:G30) -> 184874.47 | I30: 92400 | J30: =1.44*24000 -> 34560 | K30: 13000 | L30: 5000 | M30: =0.5*24000 -> 12000 | N30: 10000 | O30: 10000 | Q30: =SUM(I30:P30) -> 176960 | R30: ='Summary sales'!D26 -> 75016.9 | S30: ='Summary sales'!E26 -> 47503.56 | T30: ='Summary sales'!G26 -> 10007 | U30: ='Summary sales'!I26 -> 6868.23 | V30: ='Summary sales'!F26 -> 19100.23 | W30: ='Summary sales'!H26 -> 9059.231 | X30: ='Summary sales'!K26 -> 8162.548 | Y30: ='Summary sales'!L26 -> 0 | Z30: =SUM(R30:Y30) -> 175717.7
B31: =B30+1 -> 46073 | C31: =TEXT(B31,"ddd") -> Jum | D31: =Q31-H31 -> -7914.4704 | E31: =SUM('SO Februari 2026 Rev.2'!E31:AQ31) -> 147293.4 | F31: =SUM('SO Februari 2026 Rev.2'!AR31:AY31) -> 15081.07 | G31: =SUM('SO Februari 2026 Rev.2'!AZ31:BA31) -> 22500 | H31: =SUM(E31:G31) -> 184874.47 | I31: 92400 | J31: =1.44*24000 -> 34560 | K31: 13000 | L31: 5000 | M31: =0.5*24000 -> 12000 | N31: 10000 | O31: 10000 | Q31: =SUM(I31:P31) -> 176960 | R31: ='Summary sales'!D27 -> 71194.61 | S31: ='Summary sales'!E27 -> 48020.36 | T31: ='Summary sales'!G27 -> 10792.89 | U31: ='Summary sales'!I27 -> 3338.79 | V31: ='Summary sales'!F27 -> 22709.66 | W31: ='Summary sales'!H27 -> 4528.709 | X31: ='Summary sales'!K27 -> 0 | Y31: ='Summary sales'!L27 -> 0 | Z31: =SUM(R31:Y31) -> 160585.02
B32: =B31+1 -> 46074 | C32: =TEXT(B32,"ddd") -> Sab | D32: =Q32-H32 -> 3485.4064 | E32: =SUM('SO Februari 2026 Rev.2'!E32:AQ32) -> 135893.52 | F32: =SUM('SO Februari 2026 Rev.2'!AR32:AY32) -> 15081.07 | G32: =SUM('SO Februari 2026 Rev.2'!AZ32:BA32) -> 22500 | H32: =SUM(E32:G32) -> 173474.59 | I32: 92400 | J32: =1.44*24000 -> 34560 | K32: 13000 | L32: 5000 | M32: =0.5*24000 -> 12000 | N32: 10000 | O32: 10000 | Q32: =SUM(I32:P32) -> 176960 | R32: ='Summary sales'!D28 -> 64128.01 | S32: ='Summary sales'!E28 -> 42867.06 | T32: ='Summary sales'!G28 -> 9818.96 | U32: ='Summary sales'!I28 -> 3128.84 | V32: ='Summary sales'!F28 -> 16396.46 | W32: ='Summary sales'!H28 -> 4639.404 | X32: ='Summary sales'!K28 -> 13159.695 | Y32: ='Summary sales'!L28 -> 0 | Z32: =SUM(R32:Y32) -> 154138.43
B33: =B32+1 -> 46075 | C33: =TEXT(B33,"ddd") -> Mgg | D33: =Q33-H33 -> 13323.576 | E33: =SUM('SO Februari 2026 Rev.2'!E33:AQ33) -> 126055.35 | F33: =SUM('SO Februari 2026 Rev.2'!AR33:AY33) -> 15081.07 | G33: =SUM('SO Februari 2026 Rev.2'!AZ33:BA33) -> 22500 | H33: =SUM(E33:G33) -> 163636.42 | I33: 92400 | J33: =1.44*24000 -> 34560 | K33: 13000 | L33: 5000 | M33: =0.5*24000 -> 12000 | N33: 10000 | O33: 10000 | Q33: =SUM(I33:P33) -> 176960 | R33: ='Summary sales'!D29 -> 71292.35 | S33: ='Summary sales'!E29 -> 48817.85 | T33: ='Summary sales'!G29 -> 14293 | U33: ='Summary sales'!I29 -> 3187.86 | V33: ='Summary sales'!F29 -> 14537.32 | W33: ='Summary sales'!H29 -> 9401.245 | X33: ='Summary sales'!K29 -> 4178.169 | Y33: ='Summary sales'!L29 -> 0 | Z33: =SUM(R33:Y33) -> 165707.79
B34: Sub Total | D34: =Q34-H34 -> 54743.089 | E34: =SUM(E27:E33) -> 923153.22 | F34: =SUM(F27:F33) -> 103323.69 | G34: =SUM(G27:G33) -> 157500 | H34: =SUM(H27:H33) -> 1183976.9 | I34: =SUM(I27:I33) -> 646800 | J34: =SUM(J27:J33) -> 241920 | K34: =SUM(K27:K33) -> 91000 | L34: =SUM(L27:L33) -> 35000 | ... Z34: =SUM(Z27:Z33) -> 1156542.8
A36: =WEEKNUM(B41) -> 9 | B36: =B33+1 -> 46076 | C36: =TEXT(B36,"ddd") -> Sen | D36: =Q36-H36 -> -11414.47 | E36: =SUM('SO Februari 2026 Rev.2'!E36:AQ36) -> 150793.4 | F36: =SUM('SO Februari 2026 Rev.2'!AR36:AY36) -> 15081.07 | G36: =SUM('SO Februari 2026 Rev.2'!AZ36:BA36) -> 22500 | H36: =SUM(E36:G36) -> 188374.47 | I36: 92400 | J36: =1.44*24000 -> 34560 | K36: 13000 | L36: 5000 | M36: =0.5*24000 -> 12000 | N36: 10000 | O36: 10000 | Q36: =SUM(I36:P36) -> 176960 | R36: ='Summary sales'!D30 -> 64583.88 | S36: ='Summary sales'!E30 -> 46308.44 | T36: ='Summary sales'!G30 -> 10012.73 | U36: ='Summary sales'!I30 -> 3410.54 | V36: ='Summary sales'!F30 -> 17347.55 | W36: ='Summary sales'!H30 -> 4511.717 | X36: ='Summary sales'!K30 -> 8599.906 | Y36: ='Summary sales'!L30 -> 0 | Z36: =SUM(R36:Y36) -> 154774.76
B37: =B36+1 -> 46077 | C37: =TEXT(B37,"ddd") -> Sel | D37: =Q37-H37 -> -11414.47 | E37: =SUM('SO Februari 2026 Rev.2'!E37:AQ37) -> 150793.4 | F37: =SUM('SO Februari 2026 Rev.2'!AR37:AY37) -> 15081.07 | G37: =SUM('SO Februari 2026 Rev.2'!AZ37:BA37) -> 22500 | H37: =SUM(E37:G37) -> 188374.47 | I37: 92400 | J37: =1.44*24000 -> 34560 | K37: 13000 | L37: 5000 | M37: =0.5*24000 -> 12000 | N37: 10000 | O37: 10000 | Q37: =SUM(I37:P37) -> 176960 | R37: ='Summary sales'!D31 -> 68313.14 | S37: ='Summary sales'!E31 -> 49348.61 | T37: ='Summary sales'!G31 -> 9521.06 | U37: ='Summary sales'!I31 -> 3440.44 | V37: ='Summary sales'!F31 -> 9446.36 | W37: ='Summary sales'!H31 -> 4497.076 | X37: ='Summary sales'!K31 -> 8390.586 | Y37: ='Summary sales'!L31 -> 0 | Z37: =SUM(R37:Y37) -> 152957.27
B38: =B37+1 -> 46078 | C38: =TEXT(B38,"ddd") -> Rab | D38: =Q38-H38 -> -11414.47 | E38: =SUM('SO Februari 2026 Rev.2'!E38:AQ38) -> 150793.4 | F38: =SUM('SO Februari 2026 Rev.2'!AR38:AY38) -> 15081.07 | G38: =SUM('SO Februari 2026 Rev.2'!AZ38:BA38) -> 22500 | H38: =SUM(E38:G38) -> 188374.47 | I38: 92400 | J38: =1.44*24000 -> 34560 | K38: 13000 | L38: 5000 | M38: =0.5*24000 -> 12000 | N38: 10000 | O38: 10000 | Q38: =SUM(I38:P38) -> 176960 | R38: ='Summary sales'!D32 -> 70740.19 | S38: ='Summary sales'!E32 -> 45731.34 | T38: ='Summary sales'!G32 -> 4450.39 | U38: ='Summary sales'!I32 -> 6836.35 | V38: ='Summary sales'!F32 -> 18776.83 | W38: ='Summary sales'!H32 -> 9954.199 | X38: ='Summary sales'!K32 -> 12154.07 | Y38: ='Summary sales'!L32 -> 0 | Z38: =SUM(R38:Y38) -> 168643.37
B39: =B38+1 -> 46079 | C39: =TEXT(B39,"ddd") -> Kam | D39: =Q39-H39 -> -11414.47 | E39: =SUM('SO Februari 2026 Rev.2'!E39:AQ39) -> 150793.4 | F39: =SUM('SO Februari 2026 Rev.2'!AR39:AY39) -> 15081.07 | G39: =SUM('SO Februari 2026 Rev.2'!AZ39:BA39) -> 22500 | H39: =SUM(E39:G39) -> 188374.47 | I39: 92400 | J39: =1.44*24000 -> 34560 | K39: 13000 | L39: 5000 | M39: =0.5*24000 -> 12000 | N39: 10000 | O39: 10000 | Q39: =SUM(I39:P39) -> 176960 | R39: ='Summary sales'!D33 -> 68737.02 | S39: ='Summary sales'!E33 -> 44808.81 | T39: ='Summary sales'!G33 -> 9871.98 | U39: ='Summary sales'!I33 -> 3305.48 | V39: ='Summary sales'!F33 -> 27734.53 | W39: ='Summary sales'!H33 -> 4616.523 | X39: ='Summary sales'!K33 -> 8753.816 | Y39: ='Summary sales'!L33 -> 0 | Z39: =SUM(R39:Y39) -> 167828.16
B40: =B39+1 -> 46080 | C40: =TEXT(B40,"ddd") -> Jum | D40: =Q40-H40 -> -11414.47 | E40: =SUM('SO Februari 2026 Rev.2'!E40:AQ40) -> 150793.4 | F40: =SUM('SO Februari 2026 Rev.2'!AR40:AY40) -> 15081.07 | G40: =SUM('SO Februari 2026 Rev.2'!AZ40:BA40) -> 22500 | H40: =SUM(E40:G40) -> 188374.47 | I40: 92400 | J40: =1.44*24000 -> 34560 | K40: 13000 | L40: 5000 | M40: =0.5*24000 -> 12000 | N40: 10000 | O40: 10000 | Q40: =SUM(I40:P40) -> 176960 | R40: ='Summary sales'!D34 -> 69602.4 | S40: ='Summary sales'!E34 -> 47559.88 | T40: ='Summary sales'!G34 -> 8561.53 | U40: ='Summary sales'!I34 -> 3341.59 | V40: ='Summary sales'!F34 -> 18101.31 | W40: ='Summary sales'!H34 -> 0 | X40: ='Summary sales'!K34 -> 13856.04 | Y40: ='Summary sales'!L34 -> 0 | Z40: =SUM(R40:Y40) -> 161022.75
B41: =B40+1 -> 46081 | C41: =TEXT(B41,"ddd") -> Sab | D41: =Q41-H41 -> -14.593613 | E41: =SUM('SO Februari 2026 Rev.2'!E41:AQ41) -> 139393.52 | F41: =SUM('SO Februari 2026 Rev.2'!AR41:AY41) -> 15081.07 | G41: =SUM('SO Februari 2026 Rev.2'!AZ41:BA41) -> 22500 | H41: =SUM(E41:G41) -> 176974.59 | I41: 92400 | J41: =1.44*24000 -> 34560 | K41: 13000 | L41: 5000 | M41: =0.5*24000 -> 12000 | N41: 10000 | O41: 10000 | Q41: =SUM(I41:P41) -> 176960 | R41: ='Summary sales'!D35 -> 92415.8 | S41: ='Summary sales'!E35 -> 46672.53 | T41: ='Summary sales'!G35 -> 10104.5 | U41: ='Summary sales'!I35 -> 3259.4 | V41: ='Summary sales'!F35 -> 24719.15 | W41: ='Summary sales'!H35 -> 0 | X41: ='Summary sales'!K35 -> 13593.878 | Y41: ='Summary sales'!L35 -> 0 | Z41: =SUM(R41:Y41) -> 190765.26
B42: Sub Total | D42: =Q42-H42 -> -57086.946 | E42: =SUM(E35:E41) -> 893360.53 | F42: =SUM(F35:F41) -> 90486.42 | G42: =SUM(G35:G41) -> 135000 | H42: =SUM(H35:H41) -> 1118846.9 | I42: =SUM(I35:I41) -> 554400 | J42: =SUM(J35:J41) -> 207360 | K42: =SUM(K35:K41) -> 78000 | L42: =SUM(L35:L41) -> 30000 | ... Z42: =SUM(Z35:Z41) -> 995991.57
B44: Sub Total | D44: =SUM(D6,D9:D15,D18:D24,D27:D33,D36:D41) -> -190341.99 | E44: =SUM(E6,E9:E15,E18:E24,E27:E33,E36:E41) -> 4039575.8 | F44: =SUM(F6,F9:F15,F18:F24,F27:F33,F36:F41) -> 415526.16 | G44: =SUM(G6,G9:G15,G18:G24,G27:G33,G36:G41) -> 495000 | H44: =SUM(H6,H9:H15,H18:H24,H27:H33,H36:H41) -> 4950102 | I44: =SUM(I6,I9:I15,I18:I24,I27:I33,I36:I41) -> 2461200 | J44: =SUM(J6,J9:J15,J18:J24,J27:J33,J36:J41) -> 988560 | K44: =SUM(K6,K9:K15,K18:K24,K27:K33,K36:K41) -> 364000 | ... Z44: =SUM(Z6,Z9:Z15,Z18:Z24,Z27:Z33,Z36:Z41) -> 4676096.4
B45: Total | D45: =D7+D16+D25+D34+D42 -> -190341.99 | E45: =E7+E16+E25+E34+E42 -> 4039575.8 | F45: =F7+F16+F25+F34+F42 -> 415526.16 | G45: =G7+G16+G25+G34+G42 -> 495000 | H45: =H7+H16+H25+H34+H42 -> 4950102 | I45: =I7+I16+I25+I34+I42 -> 2461200 | J45: =J7+J16+J25+J34+J42 -> 988560 | K45: =K7+K16+K25+K34+K42 -> 364000 | ... Z45: =Z7+Z16+Z25+Z34+Z42 -> 4676096.4

Sheet Daily Sales
A1: Daily Sales
A2: 46054 | H2: =H17/24 -> 33.840417 | L2: =L17/24 -> 104.16667 | P2: =P17/24 -> 47.072137 | T2: =T17/24 -> 136.77151 | X2: =X17/24 -> 26.834194 | AB2: =AB17/24 -> 83.333333 | AF2: =AF17/24 -> 6.9571102 | AJ2: =AJ17/24 -> 25.156801 | AN2: =AN17/24 -> 28.053145 | AR2: =AR17/24 -> 229.75829 | AV2: =AV17/24 -> 250.00259 | AZ2: =AZ17/24 -> 119.7636 | BD2: =BD17/24 -> 62.5 | BH2: =BH17/24 -> 62.5 | BL2: =BL17/24 -> 458.33571 | BP2: =BP17/24 -> 38.58727 | BT2: =BT17/24 -> 187.5 | BX2: =BX17/24 -> 2.9189516 | CF2: =CF17/24 -> 145.83333 | CJ2: =CJ17/12 -> 333.37339 | CN2: =CN17/24 -> 145.83333 | CV2: =CV17/24 -> 652.48144 | CZ2: =CZ17/24 -> 84.202513 | DD2: =DD17/24 -> 28.279167 | DH2: =DH17/24 -> 296.74383 | DL2: =DL17/17 -> 205.8751 | DP2: =DP17/24 -> 62.511438 | DT2: =DT17/24 -> 89.147097 | DX2: =DX17/24 -> 52.540591 | EB2: =EB17/24 -> 416.66864 | EF2: =EF17/24 -> 63.314368 | EJ2: =EJ17/24 -> 166.65309 | EN2: =EN17/24 -> 145.83333 | ER2: =ER17/24 -> 166.65374 | EV2: =EV17/24 -> 1104.1667 | EZ2: =EZ17/16 -> 312.5 | FD2: =FD17/24 -> 87.735323 | FL2: =FL17/24 -> 125.75173 | FP2: =FP17/24 -> 85.20832 | FT2: =FT17/24 -> 15.400446 | FX2: =FX17/24 -> 375 | GB2: =GB17/24 -> 145.83333 | GF2: =GF17/24 -> 46.745847 | GN2: =GN17/24 -> 104.15427 | GR2: =GR17/24 -> 187.5
A3: Week | B3: DATE | C3: DAY | D3: Total | H3: CLIN | L3: BI | P3: MKG | T3: STM | X3: OAJ | AB3: NNI | AF3: SHB | AJ3: GTL | AN3: TWK | AR3: BYC | AV3: GF RANCA | AZ3: SMA | BD3: ADP | BH3: HLI | BL3: CERES | BP3: ALT (KSO MASAMI) | BT3: IDP (KSO AAE) | BX3: FJI (KSO SALMAH) | CB3: WINGLOK (KSO EBM) | CF3: CISF (KSO RRS) | CJ3: PUJ - LUBRICANT | CN3: KSN | CR3: CALBEE (KSO BMI) | CV3: UMI | CZ3: IP | DD3: BEM | DH3: AMI | DL3: KA | DP3: KTN | DT3: TOMIMOTO | DX3: NIAGA GARAM | EB3: PCI 84 | EF3: PCI MENGGER | EJ3: INDOFOOD | EN3: HCI | ER3: DIC | EV3: ASAHIMAS | EZ3: ABC KOGEN | FD3: TONGJI ( KSO GAS) | FH3: PA | FL3: RB | FP3: GF ATOM | FT3: GF KULIT | FX3: SP KSO JES | GB3: HSK (KSO GAS) | GF3: SDM | GJ3: JARGAS | GN3: SBI | GR3: SP GLOBAL
D4: TARGET | E4: ACTUAL | F4: SELISIH | G4: PERSENTASE | H4: TARGET | I4: ACTUAL | J4: SELISIH | K4: PERSENTASE | L4: TARGET | M4: ACTUAL | N4: SELISIH | O4: PERSENTASE | P4: TARGET | Q4: ACTUAL | R4: SELISIH | S4: PERSENTASE | T4: TARGET | U4: ACTUAL | V4: SELISIH | W4: PERSENTASE | X4: TARGET | Y4: ACTUAL | Z4: SELISIH | AA4: PERSENTASE | AB4: TARGET | AC4: ACTUAL | AD4: SELISIH | AE4: PERSENTASE | AF4: TARGET | AG4: ACTUAL | AH4: SELISIH | AI4: PERSENTASE | AJ4: TARGET | AK4: ACTUAL | AL4: SELISIH | AM4: PERSENTASE | AN4: TARGET | AO4: ACTUAL | AP4: SELISIH | AQ4: PERSENTASE | AR4: TARGET | AS4: ACTUAL | AT4: SELISIH | AU4: PERSENTASE | AV4: TARGET | AW4: ACTUAL | AX4: SELISIH | AY4: PERSENTASE | AZ4: TARGET | BA4: ACTUAL | BB4: SELISIH | BC4: PERSENTASE | BD4: TARGET | BE4: ACTUAL | BF4: SELISIH | BG4: PERSENTASE | BH4: TARGET | BI4: ACTUAL | BJ4: SELISIH | BK4: PERSENTASE | BL4: TARGET | BM4: ACTUAL | BN4: SELISIH | BO4: PERSENTASE | BP4: TARGET | BQ4: ACTUAL | BR4: SELISIH | BS4: PERSENTASE | BT4: TARGET | BU4: ACTUAL | BV4: SELISIH | BW4: PERSENTASE | BX4: TARGET | BY4: ACTUAL | BZ4: SELISIH | CA4: PERSENTASE | CB4: TARGET | CC4: ACTUAL | CD4: SELISIH | CE4: PERSENTASE | CF4: TARGET | CG4: ACTUAL | CH4: SELISIH | CI4: PERSENTASE | CJ4: TARGET | CK4: ACTUAL | CL4: SELISIH | CM4: PERSENTASE | CN4: TARGET | CO4: ACTUAL | CP4: SELISIH | CQ4: PERSENTASE | CR4: TARGET | CS4: ACTUAL | CT4: SELISIH | CU4: PERSENTASE | CV4: TARGET | CW4: ACTUAL | CX4: SELISIH | CY4: PERSENTASE | CZ4: TARGET | DA4: ACTUAL | DB4: SELISIH | DC4: PERSENTASE | DD4: TARGET | DE4: ACTUAL | DF4: SELISIH | DG4: PERSENTASE | DH4: TARGET | DI4: ACTUAL | DJ4: SELISIH | DK4: PERSENTASE | DL4: TARGET | DM4: ACTUAL | DN4: SELISIH | DO4: PERSENTASE | DP4: TARGET | DQ4: ACTUAL | DR4: SELISIH | DS4: PERSENTASE | DT4: TARGET | DU4: ACTUAL | DV4: SELISIH | DW4: PERSENTASE | DX4: TARGET | DY4: ACTUAL | DZ4: SELISIH | EA4: PERSENTASE | EB4: TARGET | EC4: ACTUAL | ED4: SELISIH | EE4: PERSENTASE | EF4: TARGET | EG4: ACTUAL | EH4: SELISIH | EI4: PERSENTASE | EJ4: TARGET | EK4: ACTUAL | EL4: SELISIH | EM4: PERSENTASE | EN4: TARGET | EO4: ACTUAL | EP4: SELISIH | EQ4: PERSENTASE | ER4: TARGET | ES4: ACTUAL | ET4: SELISIH | EU4: PERSENTASE | EV4: TARGET | EW4: ACTUAL | EX4: SELISIH | EY4: PERSENTASE | EZ4: TARGET | FA4: ACTUAL | FB4: SELISIH | FC4: PERSENTASE | FD4: TARGET | FE4: ACTUAL | FF4: SELISIH | FG4: PERSENTASE | FH4: TARGET | FI4: ACTUAL | FJ4: SELISIH | FK4: PERSENTASE | FL4: TARGET | FM4: ACTUAL | FN4: SELISIH | FO4: PERSENTASE | FP4: TARGET | FQ4: ACTUAL | FR4: SELISIH | FS4: PERSENTASE | FT4: TARGET | FU4: ACTUAL | FV4: SELISIH | FW4: PERSENTASE | FX4: TARGET | FY4: ACTUAL | FZ4: SELISIH | GA4: PERSENTASE | GB4: TARGET | GC4: ACTUAL | GD4: SELISIH | GE4: PERSENTASE | GF4: TARGET | GG4: ACTUAL | GH4: SELISIH | GI4: PERSENTASE | GJ4: TARGET | GK4: ACTUAL | GL4: SELISIH | GM4: PERSENTASE | GN4: TARGET | GO4: ACTUAL | GP4: SELISIH | GQ4: PERSENTASE | GR4: TARGET | GS4: ACTUAL | GT4: SELISIH | GU4: PERSENTASE
