Workbook
Name ___xlnm._FilterDatabase_2: #REF!
Name ___xlnm._FilterDatabase_2: #REF!
Name ___xlnm._FilterDatabase_2: #REF!
Name ___xlnm._FilterDatabase_2: #REF!
Name ___xlnm._FilterDatabase_2: #REF!
Name ___xlnm._FilterDatabase_2: #REF!
Name ___xlnm._FilterDatabase_2: #REF!
Name ___xlnm._FilterDatabase_2: #REF!
Name ___xlnm._FilterDatabase_2: #REF!
Name ___xlnm._FilterDatabase_2: #REF!
Name ___xlnm._FilterDatabase_2: #REF!
Name ___xlnm._FilterDatabase_2: #REF!
Name ___xlnm._FilterDatabase_2: #REF!
Name ___xlnm._FilterDatabase_2: #REF!
Name ___xlnm._FilterDatabase_2: #REF!
Name ___xlnm._FilterDatabase_2: #REF!
Name __xlnm._FilterDatabase_2: #REF!
Name __xlnm._FilterDatabase_2: #REF!
Name __xlnm._FilterDatabase_2: #REF!
Name __xlnm._FilterDatabase_2: #REF!
Name __xlnm._FilterDatabase_2: #REF!
Name __xlnm._FilterDatabase_2: #REF!
Name __xlnm._FilterDatabase_2: #REF!
Name __xlnm._FilterDatabase_2: #REF!
Name __xlnm._FilterDatabase_2: #REF!
Name __xlnm._FilterDatabase_2: #REF!
Name __xlnm._FilterDatabase_2: #REF!
Name __xlnm._FilterDatabase_2: #REF!
Name __xlnm._FilterDatabase_2: #REF!
Name __xlnm._FilterDatabase_2: #REF!
Name __xlnm._FilterDatabase_2: #REF!
Name __xlnm._FilterDatabase_2: #REF!
Name Excel_BuiltIn__FilterDatabase_1: #REF!
Name Excel_BuiltIn__FilterDatabase_1: #REF!
Name Excel_BuiltIn__FilterDatabase_1: #REF!
Name Excel_BuiltIn__FilterDatabase_1: #REF!
Name Excel_BuiltIn__FilterDatabase_1: #REF!
Name Excel_BuiltIn__FilterDatabase_1: #REF!
Name Excel_BuiltIn__FilterDatabase_1: #REF!
Name Excel_BuiltIn__FilterDatabase_1: #REF!
Name Excel_BuiltIn__FilterDatabase_1: #REF!
Name Excel_BuiltIn__FilterDatabase_1: #REF!
Name Excel_BuiltIn__FilterDatabase_1: #REF!
Name Excel_BuiltIn__FilterDatabase_1: #REF!
Name Excel_BuiltIn__FilterDatabase_1: #REF!
Name Excel_BuiltIn__FilterDatabase_1: #REF!
Name Excel_BuiltIn__FilterDatabase_1: #REF!
Name Excel_BuiltIn__FilterDatabase_1: #REF!
Name Export_3: #REF!
Name Export_3: #REF!
Name Export_3: #REF!
Name Export_3: #REF!
Name Export_3: #REF!
Name Export_3: #REF!
Name Export_3: #REF!
Name Export_3: #REF!
Name Export_3: #REF!
Name Export_3: #REF!
Name FOB: 'Summary FOB'!#REF!
Name FOB: 'Summary FOB'!#REF!

Sheet SO Maret 2026 Rev 2
A2: SALES ORDER
A3: 46082 | O3: =O4/2 -> 0
A5: Week | B5: DATE | D5: TOTAL | E5: CLIN | F5: BI | G5: MKG | H5: STM | I5: OAJ | J5: NNI | K5: SHB | L5: GTL | M5: TWK | N5: BYC | O5: GF RANCA | P5: SMA | Q5: UMI | R5: HLI | S5: CERES | T5: DIC | U5: HCI | V5: ADP | W5: ALT (KSO MASAMI) | X5: IDP (KSO AAE) | Y5: FJI (KSO SALMAH) | Z5: WINGLOK (KSO EBM) | AA5: CISF (KSO RRS) | AB5: PUJ - LUBRICANT | AC5: CALBEE (KSO BMI) | AD5: IP | AE5: BEM | AF5: AMI | AG5: KA | AH5: KTN | AI5: TOMIMOTO | AJ5: NIAGA GARAM | AK5: PCI 84 | AL5: PCI MENGGER | AM5: INDOFOOD | AN5: ASAHIMAS | AO5: ABC KOGEN | AP5: KSN | AQ5: TONGJI ( KSO GAS) | AR5: PA | AS5: RB | AT5: GF ATOM | AU5: GF KULIT | AV5: HSK (KSO GAS) | AW5: SDM | AX5: JARGAS | AY5: SBI | AZ5: SP KSO JES | BA5: SP GLOBAL
A6: =WEEKNUM(B6) -> 10 | B6: =A3 -> 46082 | C6: Sun | D6: =SUM(E6:BA6) -> 182536.18 | E6: 733.5729 | F6: 1000 | G6: 1129.7313 | H6: 999.51613 | I6: 644.02065 | J6: 5500 | K6: 0 | L6: 603.76323 | M6: 673.27548 | N6: 0 | O6: 6600.0623 | P6: 300 | Q6: 6659.5545 | R6: 3600 | S6: 6000.0571 | T6: 4482.6897 | U6: 5500 | V6: 500 | W6: 0 | X6: 2500 | Y6: 70.054839 | Z6: 89.451613 | AA6: 1000 | AB6: 2901.4806 | AC6: 8500 | AD6: 2020.8603 | AE6: 0 | AF6: 2999.8519 | AG6: 0 | AH6: 2043.2745 | AI6: 1999.5303 | AJ6: 0 | AK6: 11007.047 | AL6: 1519.5448 | AM6: 3999.6742 | AN6: 48000 | AO6: 8000 | AP6: 3500 | AQ6: 3500 | AR6: 726.81516 | AS6: 3018.0416 | AT6: 2044.9997 | AU6: 369.61071 | AV6: 1000 | AW6: 0 | AX6: 1800 | AY6: 2499.7026 | AZ6: 13500 | BA6: 9000
B7: Sub Total | D7: =SUM(D6:D6) -> 182536.18 | E7: =SUM(E6:E6) -> 733.5729 | F7: =SUM(F6:F6) -> 1000 | G7: =SUM(G6:G6) -> 1129.7313 | H7: =SUM(H6:H6) -> 999.51613 | I7: =SUM(I6:I6) -> 644.02065 | J7: =SUM(J6:J6) -> 5500 | K7: =SUM(K6:K6) -> 0 | ... AY7: =SUM(AY6:AY6) -> 2499.7026 | AZ7: 13500 | BA7: =SUM(BA6:BA6) -> 9000
A9: =WEEKNUM(B9) -> 10 | B9: =B6+1 -> 46083 | C9: Mon | D9: =SUM(E9:BA9) -> 202796.16 | E9: 1199.5729 | F9: 2500 | G9: 1129.7313 | H9: 3282.5161 | I9: 644.02065 | J9: 5500 | K9: 499.97065 | L9: 603.76323 | M9: 673.27548 | N9: 5514.199 | O9: 6600.0623 | P9: 2874.3265 | Q9: 11659.555 | R9: 3600 | S9: 9000.0571 | T9: 4482.6897 | U9: 5500 | V9: 500 | W9: 1000 | X9: 5500 | Y9: 70.054839 | Z9: 89.451613 | AA9: 3500 | AB9: 2901.4806 | AC9: 8500 | AD9: 2020.8603 | AE9: 678.7 | AF9: 7121.8519 | AG9: 3499.8768 | AH9: 2043.2745 | AI9: 1999.5303 | AJ9: 1000 | AK9: 11007.047 | AL9: 1519.5448 | AM9: 3999.6742 | AN9: 26500 | AO9: 8000 | AP9: 3500 | AQ9: 3500 | AR9: 726.81516 | AS9: 3018.0416 | AT9: 2044.9997 | AU9: 369.61071 | AV9: 5000 | AW9: 1121.9003 | AX9: 1800 | AY9: 2499.7026 | AZ9: 13500 | BA9: 9000
B10: =B9+1 -> 46084 | C10: Tue | D10: =SUM(E10:BA10) -> 202796.16 | E10: 1199.5729 | F10: 2500 | G10: 1129.7313 | H10: 3282.5161 | I10: 644.02065 | J10: 5500 | K10: 499.97065 | L10: 603.76323 | M10: 673.27548 | N10: 5514.199 | O10: 6600.0623 | P10: 2874.3265 | Q10: 11659.555 | R10: 3600 | S10: 9000.0571 | T10: 4482.6897 | U10: 5500 | V10: 500 | W10: 1000 | X10: 5500 | Y10: 70.054839 | Z10: 89.451613 | AA10: 3500 | AB10: 2901.4806 | AC10: 8500 | AD10: 2020.8603 | AE10: 678.7 | AF10: 7121.8519 | AG10: 3499.8768 | AH10: 2043.2745 | AI10: 1999.5303 | AJ10: 1000 | AK10: 11007.047 | AL10: 1519.5448 | AM10: 3999.6742 | AN10: 26500 | AO10: 8000 | AP10: 3500 | AQ10: 3500 | AR10: 726.81516 | AS10: 3018.0416 | AT10: 2044.9997 | AU10: 369.61071 | AV10: 5000 | AW10: 1121.9003 | AX10: 1800 | AY10: 2499.7026 | AZ10: 13500 | BA10: 9000
B11: =B10+1 -> 46085 | C11: Wed | D11: =SUM(E11:BA11) -> 202796.16 | E11: 1199.5729 | F11: 2500 | G11: 1129.7313 | H11: 3282.5161 | I11: 644.02065 | J11: 5500 | K11: 499.97065 | L11: 603.76323 | M11: 673.27548 | N11: 5514.199 | O11: 6600.0623 | P11: 2874.3265 | Q11: 11659.555 | R11: 3600 | S11: 9000.0571 | T11: 4482.6897 | U11: 5500 | V11: 500 | W11: 1000 | X11: 5500 | Y11: 70.054839 | Z11: 89.451613 | AA11: 3500 | AB11: 2901.4806 | AC11: 8500 | AD11: 2020.8603 | AE11: 678.7 | AF11: 7121.8519 | AG11: 3499.8768 | AH11: 2043.2745 | AI11: 1999.5303 | AJ11: 1000 | AK11: 11007.047 | AL11: 1519.5448 | AM11: 3999.6742 | AN11: 26500 | AO11: 8000 | AP11: 3500 | AQ11: 3500 | AR11: 726.81516 | AS11: 3018.0416 | AT11: 2044.9997 | AU11: 369.61071 | AV11: 5000 | AW11: 1121.9003 | AX11: 1800 | AY11: 2499.7026 | AZ11: 13500 | BA11: 9000
B12: =B11+1 -> 46086 | C12: Thu | D12: =SUM(E12:BA12) -> 202796.16 | E12: 1199.5729 | F12: 2500 | G12: 1129.7313 | H12: 3282.5161 | I12: 644.02065 | J12: 5500 | K12: 499.97065 | L12: 603.76323 | M12: 673.27548 | N12: 5514.199 | O12: 6600.0623 | P12: 2874.3265 | Q12: 11659.555 | R12: 3600 | S12: 9000.0571 | T12: 4482.6897 | U12: 5500 | V12: 500 | W12: 1000 | X12: 5500 | Y12: 70.054839 | Z12: 89.451613 | AA12: 3500 | AB12: 2901.4806 | AC12: 8500 | AD12: 2020.8603 | AE12: 678.7 | AF12: 7121.8519 | AG12: 3499.8768 | AH12: 2043.2745 | AI12: 1999.5303 | AJ12: 1000 | AK12: 11007.047 | AL12: 1519.5448 | AM12: 3999.6742 | AN12: 26500 | AO12: 8000 | AP12: 3500 | AQ12: 3500 | AR12: 726.81516 | AS12: 3018.0416 | AT12: 2044.9997 | AU12: 369.61071 | AV12: 5000 | AW12: 1121.9003 | AX12: 1800 | AY12: 2499.7026 | AZ12: 13500 | BA12: 9000
B13: =B12+1 -> 46087 | C13: Fri | D13: =SUM(E13:BA13) -> 202796.16 | E13: 1199.5729 | F13: 2500 | G13: 1129.7313 | H13: 3282.5161 | I13: 644.02065 | J13: 5500 | K13: 499.97065 | L13: 603.76323 | M13: 673.27548 | N13: 5514.199 | O13: 6600.0623 | P13: 2874.3265 | Q13: 11659.555 | R13: 3600 | S13: 9000.0571 | T13: 4482.6897 | U13: 5500 | V13: 500 | W13: 1000 | X13: 5500 | Y13: 70.054839 | Z13: 89.451613 | AA13: 3500 | AB13: 2901.4806 | AC13: 8500 | AD13: 2020.8603 | AE13: 678.7 | AF13: 7121.8519 | AG13: 3499.8768 | AH13: 2043.2745 | AI13: 1999.5303 | AJ13: 1000 | AK13: 11007.047 | AL13: 1519.5448 | AM13: 3999.6742 | AN13: 26500 | AO13: 8000 | AP13: 3500 | AQ13: 3500 | AR13: 726.81516 | AS13: 3018.0416 | AT13: 2044.9997 | AU13: 369.61071 | AV13: 5000 | AW13: 1121.9003 | AX13: 1800 | AY13: 2499.7026 | AZ13: 13500 | BA13: 9000
B14: =B13+1 -> 46088 | C14: Sat | D14: =SUM(E14:BA14) -> 197830.28 | E14: 733.5729 | F14: 2500 | G14: 1129.7313 | H14: 3282.5161 | I14: 644.02065 | J14: 5500 | K14: 499.97065 | L14: 603.76323 | M14: 673.27548 | N14: 4514.199 | O14: 6600.0623 | P14: 2874.3265 | Q14: 11659.555 | R14: 3600 | S14: 9000.0571 | T14: 4482.6897 | U14: 5500 | V14: 500 | W14: 1000 | X14: 5500 | Y14: 70.054839 | Z14: 89.451613 | AA14: 3500 | AB14: 2901.4806 | AC14: 8500 | AD14: 2020.8603 | AE14: 678.7 | AF14: 7121.8519 | AG14: 0 | AH14: 2043.2745 | AI14: 1999.5303 | AJ14: 1000 | AK14: 11007.047 | AL14: 1519.5448 | AM14: 3999.6742 | AN14: 26500 | AO14: 8000 | AP14: 3500 | AQ14: 3500 | AR14: 726.81516 | AS14: 3018.0416 | AT14: 2044.9997 | AU14: 369.61071 | AV14: 5000 | AW14: 1121.9003 | AX14: 1800 | AY14: 2499.7026 | AZ14: 13500 | BA14: 9000
B15: =B14+1 -> 46089 | C15: Sun | D15: =SUM(E15:BA15) -> 179004.97 | E15: 733.5729 | F15: 1000 | G15: 500 | H15: 999.51613 | I15: 644.02065 | J15: 5500 | K15: 0 | L15: 603.76323 | M15: 673.27548 | N15: 0 | O15: 6600.0623 | P15: 300 | Q15: 6659.5545 | R15: 3600 | S15: 6000.0571 | T15: 4482.6897 | U15: 5500 | V15: 500 | W15: 0 | X15: 2500 | Y15: 70.054839 | Z15: 89.451613 | AA15: 1000 | AB15: 0 | AC15: 8500 | AD15: 2020.8603 | AE15: 0 | AF15: 2999.8519 | AG15: 0 | AH15: 2043.2745 | AI15: 1999.5303 | AJ15: 0 | AK15: 11007.047 | AL15: 1519.5448 | AM15: 3999.6742 | AN15: 48000 | AO15: 8000 | AP15: 3500 | AQ15: 3500 | AR15: 726.81516 | AS15: 3018.0416 | AT15: 2044.9997 | AU15: 369.61071 | AV15: 1000 | AW15: 0 | AX15: 1800 | AY15: 2499.7026 | AZ15: 13500 | BA15: 9000
B16: Sub Total | D16: =SUM(D9:D15) -> 1390816 | E16: =SUM(E9:E15) -> 7465.0103 | F16: =SUM(F9:F15) -> 16000 | G16: =SUM(G9:G15) -> 7278.3877 | H16: =SUM(H9:H15) -> 20694.613 | I16: =SUM(I9:I15) -> 4508.1445 | J16: =SUM(J9:J15) -> 38500 | K16: =SUM(K9:K15) -> 2999.8239 | ... AY16: =SUM(AY9:AY15) -> 17497.918 | AZ16: 94500 | BA16: =SUM(BA9:BA15) -> 63000
A18: =WEEKNUM(B23) -> 11 | B18: =B15+1 -> 46090 | C18: Mon | D18: =SUM(E18:BA18) -> 208836.6 | E18: 1199.5729 | F18: 2500 | G18: 1129.7313 | H18: 3282.5161 | I18: 644.02065 | J18: 2000 | K18: 499.97065 | L18: 603.76323 | M18: 673.27548 | N18: 5514.199 | O18: 6600.0623 | P18: 2874.3265 | Q18: 16500 | R18: 4800 | S18: 9000.0571 | T18: 4482.6897 | U18: =4000 -> 4000 | V18: 500 | W18: 1000 | X18: 5500 | Y18: 70.054839 | Z18: 89.451613 | AA18: 3500 | AB18: 2901.4806 | AC18: 8500 | AD18: 2020.8603 | AE18: 678.7 | AF18: 7121.8519 | AG18: 3499.8768 | AH18: 2043.2745 | AI18: 1999.5303 | AJ18: 1000 | AK18: 11007.047 | AL18: 1519.5448 | AM18: 3999.6742 | AN18: =26500+5000 -> 31500 | AO18: 8000 | AP18: 3500 | AQ18: 3500 | AR18: 726.81516 | AS18: 3018.0416 | AT18: 2044.9997 | AU18: 369.61071 | AV18: 5000 | AW18: 1121.9003 | AX18: 1800 | AY18: 2499.7026 | AZ18: 13500 | BA18: 9000
B19: =B18+1 -> 46091 | C19: Tue | D19: =SUM(E19:BA19) -> 208836.6 | E19: 1199.5729 | F19: 2500 | G19: 1129.7313 | H19: 3282.5161 | I19: 644.02065 | J19: 2000 | K19: 499.97065 | L19: 603.76323 | M19: 673.27548 | N19: 5514.199 | O19: 6600.0623 | P19: 2874.3265 | Q19: 16500 | R19: 4800 | S19: 9000.0571 | T19: 4482.6897 | U19: 4000 | V19: 500 | W19: 1000 | X19: 5500 | Y19: 70.054839 | Z19: 89.451613 | AA19: 3500 | AB19: 2901.4806 | AC19: 8500 | AD19: 2020.8603 | AE19: 678.7 | AF19: 7121.8519 | AG19: 3499.8768 | AH19: 2043.2745 | AI19: 1999.5303 | AJ19: 1000 | AK19: 11007.047 | AL19: 1519.5448 | AM19: 3999.6742 | AN19: 31500 | AO19: 8000 | AP19: 3500 | AQ19: 3500 | AR19: 726.81516 | AS19: 3018.0416 | AT19: 2044.9997 | AU19: 369.61071 | AV19: 5000 | AW19: 1121.9003 | AX19: 1800 | AY19: 2499.7026 | AZ19: 13500 | BA19: 9000
B20: =B19+1 -> 46092 | C20: Wed | D20: =SUM(E20:BA20) -> 208836.6 | E20: 1199.5729 | F20: 2500 | G20: 1129.7313 | H20: 3282.5161 | I20: 644.02065 | J20: 2000 | K20: 499.97065 | L20: 603.76323 | M20: 673.27548 | N20: 5514.199 | O20: 6600.0623 | P20: 2874.3265 | Q20: 16500 | R20: 4800 | S20: 9000.0571 | T20: 4482.6897 | U20: 4000 | V20: 500 | W20: 1000 | X20: 5500 | Y20: 70.054839 | Z20: 89.451613 | AA20: 3500 | AB20: 2901.4806 | AC20: 8500 | AD20: 2020.8603 | AE20: 678.7 | AF20: 7121.8519 | AG20: 3499.8768 | AH20: 2043.2745 | AI20: 1999.5303 | AJ20: 1000 | AK20: 11007.047 | AL20: 1519.5448 | AM20: 3999.6742 | AN20: 31500 | AO20: 8000 | AP20: 3500 | AQ20: 3500 | AR20: 726.81516 | AS20: 3018.0416 | AT20: 2044.9997 | AU20: 369.61071 | AV20: 5000 | AW20: 1121.9003 | AX20: 1800 | AY20: 2499.7026 | AZ20: 13500 | BA20: 9000
B21: =B20+1 -> 46093 | C21: Thu | D21: =SUM(E21:BA21) -> 208836.6 | E21: 1199.5729 | F21: 2500 | G21: 1129.7313 | H21: 3282.5161 | I21: 644.02065 | J21: 2000 | K21: 499.97065 | L21: 603.76323 | M21: 673.27548 | N21: 5514.199 | O21: 6600.0623 | P21: 2874.3265 | Q21: 16500 | R21: 4800 | S21: 9000.0571 | T21: 4482.6897 | U21: 4000 | V21: 500 | W21: 1000 | X21: 5500 | Y21: 70.054839 | Z21: 89.451613 | AA21: 3500 | AB21: 2901.4806 | AC21: 8500 | AD21: 2020.8603 | AE21: 678.7 | AF21: 7121.8519 | AG21: 3499.8768 | AH21: 2043.2745 | AI21: 1999.5303 | AJ21: 1000 | AK21: 11007.047 | AL21: 1519.5448 | AM21: 3999.6742 | AN21: 31500 | AO21: 8000 | AP21: 3500 | AQ21: 3500 | AR21: 726.81516 | AS21: 3018.0416 | AT21: 2044.9997 | AU21: 369.61071 | AV21: 5000 | AW21: 1121.9003 | AX21: 1800 | AY21: 2499.7026 | AZ21: 13500 | BA21: 9000
B22: =B21+1 -> 46094 | C22: Fri | D22: =SUM(E22:BA22) -> 193157.93 | E22: 1199.5729 | F22: 2500 | G22: 1129.7313 | H22: 3282.5161 | I22: 644.02065 | J22: 2000 | K22: 0 | L22: 603.76323 | M22: 673.27548 | N22: 5514.199 | O22: 6600.0623 | P22: 2874.3265 | Q22: 16500 | R22: 4800 | S22: 9000.0571 | T22: 4482.6897 | U22: 4000 | V22: 500 | W22: 1000 | X22: 5500 | Y22: 70.054839 | Z22: 89.451613 | AA22: 3500 | AB22: 2901.4806 | AC22: 8500 | AD22: 2020.8603 | AE22: 0 | AF22: 7121.8519 | AG22: 3499.8768 | AH22: 2043.2745 | AI22: 1999.5303 | AJ22: 0 | AK22: 11007.047 | AL22: 1519.5448 | AM22: 3999.6742 | AN22: 31500 | AO22: 8000 | AP22: 3500 | AQ22: 3500 | AR22: 726.81516 | AS22: 3018.0416 | AT22: 2044.9997 | AU22: 369.61071 | AV22: 5000 | AW22: 1121.9003 | AX22: 1800 | AY22: 2499.7026 | AZ22: 0 | BA22: 9000
B23: =B22+1 -> 46095 | C23: Sat | D23: =SUM(E23:BA23) -> 175192.05 | E23: 733.5729 | F23: 2500 | G23: 1129.7313 | H23: 3282.5161 | I23: 644.02065 | J23: 2000 | K23: 0 | L23: 603.76323 | M23: 673.27548 | N23: 4514.199 | O23: 6600.0623 | P23: 2874.3265 | Q23: 16500 | R23: 4800 | S23: 9000.0571 | T23: 4482.6897 | U23: 0 | V23: 500 | W23: 1000 | X23: 5500 | Y23: 70.054839 | Z23: 89.451613 | AA23: 3500 | AB23: 2901.4806 | AC23: 8500 | AD23: 2020.8603 | AE23: 0 | AF23: 7121.8519 | AG23: 0 | AH23: 2043.2745 | AI23: 1999.5303 | AJ23: 0 | AK23: 11007.047 | AL23: 1519.5448 | AM23: 3999.6742 | AN23: 31500 | AO23: 8000 | AP23: 3500 | AQ23: 3500 | AR23: 726.81516 | AS23: 3018.0416 | AT23: 2044.9997 | AU23: 369.61071 | AV23: 5000 | AW23: 1121.9003 | AX23: 1800 | AY23: 2499.7026 | AZ23: 0 | BA23: 0
B24: =B23+1 -> 46096 | C24: Sun | D24: =SUM(E24:BA24) -> 152524.88 | E24: 733.5729 | F24: 1000 | G24: 500 | H24: 999.51613 | I24: 644.02065 | J24: 2000 | K24: 0 | L24: 603.76323 | M24: 673.27548 | N24: 0 | O24: 6600.0623 | P24: 300 | Q24: 16500 | R24: 4800 | S24: 6000.0571 | T24: 4482.6897 | U24: 0 | V24: 500 | W24: 0 | X24: 2500 | Y24: 70.054839 | Z24: 89.451613 | AA24: 1000 | AB24: 0 | AC24: 8500 | AD24: 0 | AE24: 0 | AF24: 2999.8519 | AG24: 0 | AH24: 2043.2745 | AI24: 1999.5303 | AJ24: 0 | AK24: 11007.047 | AL24: 1519.5448 | AM24: 0 | AN24: 48000 | AO24: 8000 | AP24: 3500 | AQ24: 3500 | AR24: 726.81516 | AS24: 3018.0416 | AT24: 2044.9997 | AU24: 369.61071 | AV24: 1000 | AW24: 0 | AX24: 1800 | AY24: 2499.7026 | AZ24: 0 | BA24: 0
B25: Sub Total | D25: =SUM(D18:D24) -> 1356221.3 | E25: =SUM(E18:E24) -> 7465.0103 | F25: =SUM(F18:F24) -> 16000 | G25: =SUM(G18:G24) -> 7278.3877 | H25: =SUM(H18:H24) -> 20694.613 | I25: =SUM(I18:I24) -> 4508.1445 | J25: =SUM(J18:J24) -> 14000 | K25: =SUM(K18:K24) -> 1999.8826 | ... AY25: =SUM(AY18:AY24) -> 17497.918 | AZ25: 54000 | BA25: =SUM(BA18:BA24) -> 45000
A27: =WEEKNUM(B32) -> 12 | B27: =B24+1 -> 46097 | C27: Mon | D27: =SUM(E27:BA27) -> 162636.38 | E27: 1199.5729 | F27: 2500 | G27: 1129.7313 | H27: 999.51613 | I27: 300 | J27: 2000 | K27: 0 | L27: 603.76323 | M27: 673.27548 | N27: 5514.199 | O27: 6600.0623 | P27: 1000.3265 | Q27: 16500 | R27: 4800 | S27: 9000.0571 | T27: 4482.6897 | U27: 4000 | V27: 500 | W27: 1000 | X27: 5500 | Y27: 70.054839 | Z27: 89.451613 | AA27: 3500 | AB27: 2901.4806 | AC27: 8500 | AD27: 0 | AE27: 0 | AF27: 7121.8519 | AG27: 3499.8768 | AH27: 2043.2745 | AI27: 1999.5303 | AJ27: 0 | AK27: 11007.047 | AL27: 1519.5448 | AM27: 0 | AN27: 22000 | AO27: 6500 | AP27: 3500 | AQ27: 3500 | AR27: 726.81516 | AS27: 3018.0416 | AT27: 2044.9997 | AU27: 369.61071 | AV27: 5000 | AW27: 1121.9003 | AX27: 1800 | AY27: 2499.7026 | AZ27: 0 | BA27: 0
B28: =B27+1 -> 46098 | C28: Tue | D28: =SUM(E28:BA28) -> 151514.52 | E28: 1199.5729 | F28: 1000 | G28: 1129.7313 | H28: 999.51613 | I28: 300 | J28: 2000 | K28: 0 | L28: 603.76323 | M28: 673.27548 | N28: 5514.199 | O28: 6600.0623 | P28: 1000.3265 | Q28: 16500 | R28: 4800 | S28: 9000.0571 | T28: 4482.6897 | U28: 4000 | V28: 500 | W28: 1000 | X28: 5500 | Y28: 70.054839 | Z28: 89.451613 | AA28: 3500 | AB28: 2901.4806 | AC28: 6000 | AD28: 0 | AE28: 0 | AF28: 0 | AG28: 3499.8768 | AH28: 2043.2745 | AI28: 1999.5303 | AJ28: 0 | AK28: 11007.047 | AL28: 1519.5448 | AM28: 0 | AN28: 22000 | AO28: 6500 | AP28: 3500 | AQ28: 3500 | AR28: 726.81516 | AS28: 3018.0416 | AT28: 2044.9997 | AU28: 369.61071 | AV28: 5000 | AW28: 1121.9003 | AX28: 1800 | AY28: 2499.7026 | AZ28: 0 | BA28: 0
B29: =B28+1 -> 46099 | C29: Wed (cuti bersama) | D29: =SUM(E29:BA29) -> 132069.23 | E29: 0 | F29: 0 | G29: 1129.7313 | H29: 0 | I29: 300 | J29: 0 | K29: 0 | L29: 300 | M29: 673.27548 | N29: 5514.199 | O29: 0 | P29: 0 | Q29: 16500 | R29: 4800 | S29: 4000.0571 | T29: 0 | U29: 0 | V29: 0 | W29: 1000 | X29: 2500 | Y29: 70.054839 | Z29: 89.451613 | AA29: 3500 | AB29: 0 | AC29: 0 | AD29: 0 | AE29: 0 | AF29: 0 | AG29: 3499.8768 | AH29: 0 | AI29: 1999.5303 | AJ29: 0 | AK29: 11007.047 | AL29: 1519.5448 | AM29: 0 | AN29: 48000 | AO29: 8000 | AP29: 0 | AQ29: 3500 | AR29: 726.81516 | AS29: 3018.0416 | AT29: 0 | AU29: 0 | AV29: 5000 | AW29: 1121.9003 | AX29: 1800 | AY29: 2499.7026 | AZ29: 0 | BA29: 0
B30: =B29+1 -> 46100 | C30: Thu (Nyepi) | D30: =SUM(E30:BA30) -> 105970.73 | E30: 0 | F30: 0 | G30: 1129.7313 | H30: 0 | I30: 300 | J30: 0 | K30: 0 | L30: 300 | M30: 0 | N30: 5514.199 | O30: 0 | P30: 0 | Q30: 16500 | R30: 4800 | S30: 4000.0571 | T30: 0 | U30: 0 | V30: 0 | W30: 0 | X30: 0 | Y30: 0 | Z30: 89.451613 | AA30: 0 | AB30: 0 | AC30: 0 | AD30: 0 | AE30: 0 | AF30: 0 | AG30: 0 | AH30: 0 | AI30: 0 | AJ30: 0 | AK30: 5000 | AL30: 1519.5448 | AM30: 0 | AN30: 48000 | AO30: 8000 | AP30: 0 | AQ30: 3500 | AR30: 0 | AS30: 3018.0416 | AT30: 0 | AU30: 0 | AV30: 0 | AW30: 0 | AX30: 1800 | AY30: 2499.7026 | AZ30: 0 | BA30: 0
B31: =B30+1 -> 46101 | C31: Fri (Ied 1) | D31: =SUM(E31:BA31) -> 83078.497 | E31: 0 | F31: 0 | G31: 1129.7313 | H31: 0 | I31: 300 | J31: 0 | K31: 0 | L31: 300 | M31: 0 | N31: 0 | O31: 0 | P31: 0 | Q31: 6659.5545 | R31: 4800 | S31: 4000.0571 | T31: 0 | U31: 0 | V31: 0 | W31: 0 | X31: 0 | Y31: 0 | Z31: 89.451613 | AA31: 0 | AB31: 0 | AC31: 0 | AD31: 0 | AE31: 0 | AF31: 0 | AG31: 0 | AH31: 0 | AI31: 0 | AJ31: 0 | AK31: 5000 | AL31: 500 | AM31: 0 | AN31: 48000 | AO31: 8000 | AP31: 0 | AQ31: 0 | AR31: 0 | AS31: 0 | AT31: 0 | AU31: 0 | AV31: 0 | AW31: 0 | AX31: 1800 | AY31: 2499.7026 | AZ31: 0 | BA31: 0
B32: =B31+1 -> 46102 | C32: Sat (Ied 2) | D32: =SUM(E32:BA32) -> 94925.99 | E32: 0 | F32: 0 | G32: 1129.7313 | H32: 0 | I32: 300 | J32: 0 | K32: 0 | L32: 300 | M32: 0 | N32: 0 | O32: 0 | P32: 0 | Q32: 16500 | R32: 4800 | S32: 4000.0571 | T32: 0 | U32: 0 | V32: 0 | W32: 0 | X32: 0 | Y32: 0 | Z32: 89.451613 | AA32: 0 | AB32: 0 | AC32: 0 | AD32: 0 | AE32: 0 | AF32: 0 | AG32: 0 | AH32: 0 | AI32: 0 | AJ32: 0 | AK32: 11007.047 | AL32: 500 | AM32: 0 | AN32: 48000 | AO32: 4000 | AP32: 0 | AQ32: 0 | AR32: 0 | AS32: 0 | AT32: 0 | AU32: 0 | AV32: 0 | AW32: 0 | AX32: 1800 | AY32: 2499.7026 | AZ32: 0 | BA32: 0
B33: =B32+1 -> 46103 | C33: Sun | D33: =SUM(E33:BA33) -> 99885.858 | E33: 0 | F33: 0 | G33: 500 | H33: 0 | I33: 300 | J33: 0 | K33: 0 | L33: 300 | M33: 0 | N33: 0 | O33: 0 | P33: 0 | Q33: 16500 | R33: 4800 | S33: 4000.0571 | T33: 0 | U33: 0 | V33: 500 | W33: 0 | X33: 0 | Y33: 70.054839 | Z33: 89.451613 | AA33: 0 | AB33: 0 | AC33: 0 | AD33: 0 | AE33: 0 | AF33: 0 | AG33: 0 | AH33: 0 | AI33: 0 | AJ33: 0 | AK33: 11007.047 | AL33: 1519.5448 | AM33: 0 | AN33: 48000 | AO33: 8000 | AP33: 0 | AQ33: 0 | AR33: 0 | AS33: 0 | AT33: 0 | AU33: 0 | AV33: 0 | AW33: 0 | AX33: 1800 | AY33: 2499.7026 | AZ33: 0 | BA33: 0
B34: Sub Total | D34: =SUM(D27:D33) -> 830081.2 | E34: =SUM(E27:E33) -> 2399.1458 | F34: =SUM(F27:F33) -> 3500 | G34: =SUM(G27:G33) -> 7278.3877 | H34: =SUM(H27:H33) -> 1999.0323 | I34: =SUM(I27:I33) -> 2100 | J34: =SUM(J27:J33) -> 4000 | K34: =SUM(K27:K33) -> 0 | ... AY34: =SUM(AY27:AY33) -> 17497.918 | AZ34: 0 | BA34: =SUM(BA27:BA33) -> 0
A36: =WEEKNUM(B41) -> 13 | B36: =B33+1 -> 46104 | C36: Mon (cuti bersama) | D36: =SUM(E36:BA36) -> 98675.144 | E36: 0 | F36: 0 | G36: 1129.7313 | H36: 0 | I36: 300 | J36: 0 | K36: 0 | L36: 300 | M36: 0 | N36: 0 | O36: 0 | P36: 0 | Q36: 11659.555 | R36: 4800 | S36: 4000.0571 | T36: 0 | U36: 0 | V36: 0 | W36: 0 | X36: 0 | Y36: 70.054839 | Z36: 89.451613 | AA36: 3500 | AB36: 0 | AC36: 0 | AD36: 0 | AE36: 0 | AF36: 0 | AG36: 0 | AH36: 0 | AI36: 0 | AJ36: 0 | AK36: 11007.047 | AL36: 1519.5448 | AM36: 0 | AN36: 48000 | AO36: 8000 | AP36: 0 | AQ36: 0 | AR36: 0 | AS36: 0 | AT36: 0 | AU36: 0 | AV36: 0 | AW36: 0 | AX36: 1800 | AY36: 2499.7026 | AZ36: 0 | BA36: 0
B37: =B36+1 -> 46105 | C37: Tue (cuti bersama) | D37: =SUM(E37:BA37) -> 112371.85 | E37: 0 | F37: 3000 | G37: 1129.7313 | H37: 0 | I37: 300 | J37: 0 | K37: 0 | L37: 300 | M37: 300 | N37: 0 | O37: 0 | P37: 0 | Q37: 11659.555 | R37: 4800 | S37: 4000.0571 | T37: 2482.6897 | U37: 0 | V37: 0 | W37: 0 | X37: 0 | Y37: 70.054839 | Z37: 89.451613 | AA37: 3500 | AB37: 0 | AC37: 0 | AD37: 0 | AE37: 0 | AF37: 0 | AG37: 3499.8768 | AH37: 0 | AI37: 1999.5303 | AJ37: 0 | AK37: 11007.047 | AL37: 1519.5448 | AM37: 0 | AN37: 48000 | AO37: 8000 | AP37: 0 | AQ37: 0 | AR37: 0 | AS37: 0 | AT37: 2044.9997 | AU37: 369.61071 | AV37: 0 | AW37: 0 | AX37: 1800 | AY37: 2499.7026 | AZ37: 0 | BA37: 0
B38: =B37+1 -> 46106 | C38: Wed (cuti bersama) | D38: =SUM(E38:BA38) -> 131046.63 | E38: 0 | F38: 3000 | G38: 1129.7313 | H38: 0 | I38: 300 | J38: 2000 | K38: 499.97065 | L38: 603.76323 | M38: 673.27548 | N38: 0 | O38: 6600.0623 | P38: 2874.3265 | Q38: 11659.555 | R38: 4800 | S38: 4000.0571 | T38: 2482.6897 | U38: 2000 | V38: 0 | W38: 0 | X38: 0 | Y38: 70.054839 | Z38: 89.451613 | AA38: 3500 | AB38: 2901.4806 | AC38: 8500 | AD38: 0 | AE38: 0 | AF38: 0 | AG38: 3499.8768 | AH38: 0 | AI38: 1999.5303 | AJ38: 1000 | AK38: 11007.047 | AL38: 1519.5448 | AM38: 0 | AN38: 40000 | AO38: 6500 | AP38: 0 | AQ38: 0 | AR38: 0 | AS38: 0 | AT38: 2044.9997 | AU38: 369.61071 | AV38: 0 | AW38: 1121.9003 | AX38: 1800 | AY38: 2499.7026 | AZ38: 0 | BA38: 0
B39: =B38+1 -> 46107 | C39: Thu | D39: =SUM(E39:BA39) -> 148046.5 | E39: 1199.5729 | F39: 3000 | G39: 1129.7313 | H39: 0 | I39: 300 | J39: 2000 | K39: 499.97065 | L39: 603.76323 | M39: 673.27548 | N39: 0 | O39: 6600.0623 | P39: 2874.3265 | Q39: 11659.555 | R39: 9600 | S39: 9000.0571 | T39: 4482.6897 | U39: 7000 | V39: 500 | W39: 0 | X39: 2500 | Y39: 70.054839 | Z39: 89.451613 | AA39: 3500 | AB39: 2901.4806 | AC39: 8500 | AD39: 0 | AE39: 0 | AF39: 0 | AG39: 3499.8768 | AH39: 0 | AI39: 1999.5303 | AJ39: 1000 | AK39: 11007.047 | AL39: 1519.5448 | AM39: 0 | AN39: 22000 | AO39: 6500 | AP39: 3500 | AQ39: 0 | AR39: 0 | AS39: 0 | AT39: 2044.9997 | AU39: 369.61071 | AV39: 5000 | AW39: 1121.9003 | AX39: 1800 | AY39: =2500+5500 -> 8000 | AZ39: 0 | BA39: 0
B40: =B39+1 -> 46108 | C40: Fri | D40: =SUM(E40:BA40) -> 160029.79 | E40: 1199.5729 | F40: 3000 | G40: 1129.7313 | H40: 0 | I40: 644.02065 | J40: 2000 | K40: 499.97065 | L40: 603.76323 | M40: 673.27548 | N40: 0 | O40: 6600.0623 | P40: 2874.3265 | Q40: 11659.555 | R40: 9600 | S40: 9000.0571 | T40: 4482.6897 | U40: 7000 | V40: 500 | W40: 0 | X40: 5500 | Y40: 70.054839 | Z40: 89.451613 | AA40: 3500 | AB40: 2901.4806 | AC40: 8500 | AD40: 0 | AE40: 0 | AF40: 7121.8519 | AG40: 3499.8768 | AH40: 0 | AI40: 1999.5303 | AJ40: 1000 | AK40: 11007.047 | AL40: 1519.5448 | AM40: 3999.6742 | AN40: 22000 | AO40: 6500 | AP40: 3500 | AQ40: 0 | AR40: 0 | AS40: 3018.0416 | AT40: 2044.9997 | AU40: 369.61071 | AV40: 5000 | AW40: 1121.9003 | AX40: 1800 | AY40: 2499.7026 | AZ40: 0 | BA40: 0
B41: =B40+1 -> 46109 | C41: Sat | D41: =SUM(E41:BA41) -> 149529.91 | E41: 1199.5729 | F41: 3000 | G41: 1129.7313 | H41: 0 | I41: 644.02065 | J41: 2000 | K41: 499.97065 | L41: 603.76323 | M41: 673.27548 | N41: 0 | O41: 6600.0623 | P41: 2874.3265 | Q41: 11659.555 | R41: 9600 | S41: 9000.0571 | T41: 4482.6897 | U41: 0 | V41: 500 | W41: 0 | X41: 5500 | Y41: 70.054839 | Z41: 89.451613 | AA41: 3500 | AB41: 2901.4806 | AC41: 8500 | AD41: 0 | AE41: 0 | AF41: 7121.8519 | AG41: 0 | AH41: 0 | AI41: 1999.5303 | AJ41: 1000 | AK41: 11007.047 | AL41: 1519.5448 | AM41: 3999.6742 | AN41: 22000 | AO41: 6500 | AP41: 3500 | AQ41: 0 | AR41: 0 | AS41: 3018.0416 | AT41: 2044.9997 | AU41: 369.61071 | AV41: 5000 | AW41: 1121.9003 | AX41: 1800 | AY41: 2499.7026 | AZ41: 0 | BA41: 0
B42: =B41+1 -> 46110 | C42: Sun | D42: =SUM(E42:BA42) -> 145214.48 | E42: 733.5729 | F42: 3000 | G42: 500 | H42: 0 | I42: 644.02065 | J42: 2000 | K42: 499.97065 | L42: 603.76323 | M42: 673.27548 | N42: 0 | O42: 6600.0623 | P42: 300 | Q42: 6659.5545 | R42: 9600 | S42: 6000.0571 | T42: 4482.6897 | U42: 0 | V42: 500 | W42: 0 | X42: 2500 | Y42: 70.054839 | Z42: 89.451613 | AA42: 1000 | AB42: 0 | AC42: 8500 | AD42: 0 | AE42: 0 | AF42: 2999.8519 | AG42: 0 | AH42: 0 | AI42: 1999.5303 | AJ42: 0 | AK42: 11007.047 | AL42: 1519.5448 | AM42: 3999.6742 | AN42: 48000 | AO42: 6500 | AP42: 3500 | AQ42: 0 | AR42: 0 | AS42: 3018.0416 | AT42: 2044.9997 | AU42: 369.61071 | AV42: 1000 | AW42: 0 | AX42: 1800 | AY42: 2499.7026 | AZ42: 0 | BA42: 0
B43: Sub Total | D43: =SUM(D36:D42) -> 944914.31 | E43: =SUM(E36:E42) -> 4332.2916 | F43: =SUM(F36:F42) -> 18000 | G43: =SUM(G36:G42) -> 7278.3877 | H43: =SUM(H36:H42) -> 0 | I43: =SUM(I36:I42) -> 3132.0619 | J43: =SUM(J36:J42) -> 10000 | K43: =SUM(K36:K42) -> 2499.8532 | ... AY43: =SUM(AY36:AY42) -> 22998.215 | AZ43: 0 | BA43: =SUM(BA36:BA42) -> 0
A45: =WEEKNUM(B45) -> 14 | B45: =B42+1 -> 46111 | C45: Mon | D45: =SUM(E45:BA45) -> 204275.3 | E45: 1199.5729 | F45: 3000 | G45: 1129.7313 | H45: 3282.5161 | I45: 644.02065 | J45: 2000 | K45: 499.97065 | L45: 603.76323 | M45: 673.27548 | N45: 5514.199 | O45: 6600.0623 | P45: 2874.3265 | Q45: 11659.555 | R45: 9600 | S45: 9000.0571 | T45: 4482.6897 | U45: 7000 | V45: 500 | W45: 1000 | X45: 5500 | Y45: 70.054839 | Z45: 89.451613 | AA45: 3500 | AB45: 2901.4806 | AC45: 8500 | AD45: 0 | AE45: 678.7 | AF45: 7121.8519 | AG45: 3499.8768 | AH45: 2043.2745 | AI45: 1999.5303 | AJ45: 1000 | AK45: 11007.047 | AL45: 1519.5448 | AM45: 3999.6742 | AN45: 48000 | AO45: 8000 | AP45: 3500 | AQ45: 3500 | AR45: 726.81516 | AS45: 3018.0416 | AT45: 2044.9997 | AU45: 369.61071 | AV45: 5000 | AW45: 1121.9003 | AX45: 1800 | AY45: 2499.7026 | AZ45: 0 | BA45: 0
B46: =B45+1 -> 46112 | C46: Tue | D46: =SUM(E46:BA46) -> 206296.16 | E46: 1199.5729 | F46: 3000 | G46: 1129.7313 | H46: 3282.5161 | I46: 644.02065 | J46: 2000 | K46: 499.97065 | L46: 603.76323 | M46: 673.27548 | N46: 5514.199 | O46: 6600.0623 | P46: 2874.3265 | Q46: 11659.555 | R46: 9600 | S46: 9000.0571 | T46: 4482.6897 | U46: 7000 | V46: 500 | W46: 1000 | X46: 5500 | Y46: 70.054839 | Z46: 89.451613 | AA46: 3500 | AB46: 2901.4806 | AC46: 8500 | AD46: 2020.8603 | AE46: 678.7 | AF46: 7121.8519 | AG46: 3499.8768 | AH46: 2043.2745 | AI46: 1999.5303 | AJ46: 1000 | AK46: 11007.047 | AL46: 1519.5448 | AM46: 3999.6742 | AN46: 48000 | AO46: 8000 | AP46: 3500 | AQ46: 3500 | AR46: 726.81516 | AS46: 3018.0416 | AT46: 2044.9997 | AU46: 369.61071 | AV46: 5000 | AW46: 1121.9003 | AX46: 1800 | AY46: 2499.7026 | AZ46: 0 | BA46: 0
B47: Sub Total | D47: =SUM(D45:D46) -> 410571.45 | E47: =SUM(E45:E46) -> 2399.1458 | F47: =SUM(F45:F46) -> 6000 | G47: =SUM(G45:G46) -> 2259.4626 | H47: =SUM(H45:H46) -> 6565.0323 | I47: =SUM(I45:I46) -> 1288.0413 | J47: =SUM(J45:J46) -> 4000 | K47: =SUM(K45:K46) -> 999.94129 | ... AY47: =SUM(AY45:AY46) -> 4999.4052 | AZ47: 0 | BA47: =SUM(BA45:BA46) -> 0
...

Sheet KEBUTUHAN GAS
A1: KEBUTUHAN GAS
A4: ='SO Maret 2026 Rev 2'!A3 -> 46082 | E4: KEBUTUHAN GAS | I4: KUOTA GAS
A5: Week | B5: DATE | D5: SELISIH GAS | E5: JABAR | F5: JATENG | G5: JATIM | H5: TOTAL | I5: MS SETU | J5: MS KHT | K5: MS BLORA | L5: MS BITUNG | M5: MS ZEBRA | N5: MS TAMBAKLOROK | O5: MS WUNUT | P5: MS SADANG | Q5: TOTAL
A6: =WEEKNUM(B6) -> 10 | B6: 46082 | C6: =TEXT(B6,"ddd") -> Mgg | D6: =Q6-H6 -> -22036.184 | E6: =SUM('SO Maret 2026 Rev 2'!E6:AQ6) -> 148577.01 | F6: =SUM('SO Maret 2026 Rev 2'!AR6:AY6) -> 11459.17 | G6: =SUM('SO Maret 2026 Rev 2'!AZ6:BA6) -> 22500 | H6: =SUM(E6:G6) -> 182536.18 | I6: ='SO MS'!E6 -> 96000 | J6: ='SO MS'!F6 -> 31200 | K6: ='SO MS'!G6 -> 10800 | L6: ='SO MS'!H6 -> 0 | M6: ='SO MS'!I6 -> 13500 | N6: ='SO MS'!J6 -> 0 | O6: ='SO MS'!K6 -> 9000 | P6: ='SO MS'!L6 -> 0 | Q6: =SUM(I6:P6) -> 160500
B7: Sub Total | D7: =SUM(D3:D6) -> -22036.184 | E7: =SUM(E3:E6) -> 148577.01 | F7: =SUM(F3:F6) -> 11459.17 | G7: =SUM(G3:G6) -> 22500 | H7: =SUM(H3:H6) -> 182536.18 | I7: =SUM(I3:I6) -> 96000 | J7: =SUM(J3:J6) -> 31200 | K7: =SUM(K3:K6) -> 10800 | ... Q7: =SUM(Q3:Q6) -> 160500
A9: =WEEKNUM(B13) -> 10 | B9: 46083 | C9: =TEXT(B9,"ddd") -> Sen | D9: =Q9-H9 -> -42296.157 | E9: =SUM('SO Maret 2026 Rev 2'!E9:AQ9) -> 163715.09 | F9: =SUM('SO Maret 2026 Rev 2'!AR9:AY9) -> 16581.07 | G9: =SUM('SO Maret 2026 Rev 2'!AZ9:BA9) -> 22500 | H9: =SUM(E9:G9) -> 202796.16 | I9: ='SO MS'!E9 -> 96000 | J9: ='SO MS'!F9 -> 31200 | K9: ='SO MS'!G9 -> 10800 | L9: ='SO MS'!H9 -> 0 | M9: ='SO MS'!I9 -> 13500 | N9: ='SO MS'!J9 -> 0 | O9: ='SO MS'!K9 -> 9000 | P9: ='SO MS'!L9 -> 0 | Q9: =SUM(I9:P9) -> 160500
B10: 46084 | C10: =TEXT(B10,"ddd") -> Sel | D10: =Q10-H10 -> -42296.157 | E10: =SUM('SO Maret 2026 Rev 2'!E10:AQ10) -> 163715.09 | F10: =SUM('SO Maret 2026 Rev 2'!AR10:AY10) -> 16581.07 | G10: =SUM('SO Maret 2026 Rev 2'!AZ10:BA10) -> 22500 | H10: =SUM(E10:G10) -> 202796.16 | I10: ='SO MS'!E10 -> 96000 | J10: ='SO MS'!F10 -> 31200 | K10: ='SO MS'!G10 -> 10800 | L10: ='SO MS'!H10 -> 0 | M10: ='SO MS'!I10 -> 13500 | N10: ='SO MS'!J10 -> 0 | O10: ='SO MS'!K10 -> 9000 | P10: ='SO MS'!L10 -> 0 | Q10: =SUM(I10:P10) -> 160500
B11: 46085 | C11: =TEXT(B11,"ddd") -> Rab | D11: =Q11-H11 -> -42296.157 | E11: =SUM('SO Maret 2026 Rev 2'!E11:AQ11) -> 163715.09 | F11: =SUM('SO Maret 2026 Rev 2'!AR11:AY11) -> 16581.07 | G11: =SUM('SO Maret 2026 Rev 2'!AZ11:BA11) -> 22500 | H11: =SUM(E11:G11) -> 202796.16 | I11: ='SO MS'!E11 -> 96000 | J11: ='SO MS'!F11 -> 31200 | K11: ='SO MS'!G11 -> 10800 | L11: ='SO MS'!H11 -> 0 | M11: ='SO MS'!I11 -> 13500 | N11: ='SO MS'!J11 -> 0 | O11: ='SO MS'!K11 -> 9000 | P11: ='SO MS'!L11 -> 0 | Q11: =SUM(I11:P11) -> 160500
B12: 46086 | C12: =TEXT(B12,"ddd") -> Kam | D12: =Q12-H12 -> -42296.157 | E12: =SUM('SO Maret 2026 Rev 2'!E12:AQ12) -> 163715.09 | F12: =SUM('SO Maret 2026 Rev 2'!AR12:AY12) -> 16581.07 | G12: =SUM('SO Maret 2026 Rev 2'!AZ12:BA12) -> 22500 | H12: =SUM(E12:G12) -> 202796.16 | I12: ='SO MS'!E12 -> 96000 | J12: ='SO MS'!F12 -> 31200 | K12: ='SO MS'!G12 -> 10800 | L12: ='SO MS'!H12 -> 0 | M12: ='SO MS'!I12 -> 13500 | N12: ='SO MS'!J12 -> 0 | O12: ='SO MS'!K12 -> 9000 | P12: ='SO MS'!L12 -> 0 | Q12: =SUM(I12:P12) -> 160500
B13: 46087 | C13: =TEXT(B13,"ddd") -> Jum | D13: =Q13-H13 -> -42296.157 | E13: =SUM('SO Maret 2026 Rev 2'!E13:AQ13) -> 163715.09 | F13: =SUM('SO Maret 2026 Rev 2'!AR13:AY13) -> 16581.07 | G13: =SUM('SO Maret 2026 Rev 2'!AZ13:BA13) -> 22500 | H13: =SUM(E13:G13) -> 202796.16 | I13: ='SO MS'!E13 -> 96000 | J13: ='SO MS'!F13 -> 31200 | K13: ='SO MS'!G13 -> 10800 | L13: ='SO MS'!H13 -> 0 | M13: ='SO MS'!I13 -> 13500 | N13: ='SO MS'!J13 -> 0 | O13: ='SO MS'!K13 -> 9000 | P13: ='SO MS'!L13 -> 0 | Q13: =SUM(I13:P13) -> 160500
B14: 46088 | C14: =TEXT(B14,"ddd") -> Sab | D14: =Q14-H14 -> -37330.28 | E14: =SUM('SO Maret 2026 Rev 2'!E14:AQ14) -> 158749.21 | F14: =SUM('SO Maret 2026 Rev 2'!AR14:AY14) -> 16581.07 | G14: =SUM('SO Maret 2026 Rev 2'!AZ14:BA14) -> 22500 | H14: =SUM(E14:G14) -> 197830.28 | I14: ='SO MS'!E14 -> 96000 | J14: ='SO MS'!F14 -> 31200 | K14: ='SO MS'!G14 -> 10800 | L14: ='SO MS'!H14 -> 0 | M14: ='SO MS'!I14 -> 13500 | N14: ='SO MS'!J14 -> 0 | O14: ='SO MS'!K14 -> 9000 | P14: ='SO MS'!L14 -> 0 | Q14: =SUM(I14:P14) -> 160500
B15: 46089 | C15: =TEXT(B15,"ddd") -> Mgg | D15: =Q15-H15 -> -18504.972 | E15: =SUM('SO Maret 2026 Rev 2'!E15:AQ15) -> 145045.8 | F15: =SUM('SO Maret 2026 Rev 2'!AR15:AY15) -> 11459.17 | G15: =SUM('SO Maret 2026 Rev 2'!AZ15:BA15) -> 22500 | H15: =SUM(E15:G15) -> 179004.97 | I15: ='SO MS'!E15 -> 96000 | J15: ='SO MS'!F15 -> 31200 | K15: ='SO MS'!G15 -> 10800 | L15: ='SO MS'!H15 -> 0 | M15: ='SO MS'!I15 -> 13500 | N15: ='SO MS'!J15 -> 0 | O15: ='SO MS'!K15 -> 9000 | P15: ='SO MS'!L15 -> 0 | Q15: =SUM(I15:P15) -> 160500
B16: Sub Total | D16: =SUM(D9:D15) -> -267316.04 | E16: =SUM(E9:E15) -> 1122370.4 | F16: =SUM(F9:F15) -> 110945.59 | G16: =SUM(G9:G15) -> 157500 | H16: =SUM(H9:H15) -> 1390816 | I16: =SUM(I9:I15) -> 672000 | J16: =SUM(J9:J15) -> 218400 | K16: =SUM(K9:K15) -> 75600 | ... Q16: =SUM(Q9:Q15) -> 1123500
A18: =WEEKNUM(B22) -> 11 | B18: 46090 | C18: =TEXT(B18,"ddd") -> Sen | D18: =Q18-H18 -> -48336.602 | E18: =SUM('SO Maret 2026 Rev 2'!E18:AQ18) -> 169755.53 | F18: =SUM('SO Maret 2026 Rev 2'!AR18:AY18) -> 16581.07 | G18: =SUM('SO Maret 2026 Rev 2'!AZ18:BA18) -> 22500 | H18: =SUM(E18:G18) -> 208836.6 | I18: ='SO MS'!E18 -> 96000 | J18: ='SO MS'!F18 -> 31200 | K18: ='SO MS'!G18 -> 10800 | L18: ='SO MS'!H18 -> 0 | M18: ='SO MS'!I18 -> 13500 | N18: ='SO MS'!J18 -> 0 | O18: ='SO MS'!K18 -> 9000 | P18: ='SO MS'!L18 -> 0 | Q18: =SUM(I18:P18) -> 160500
B19: 46091 | C19: =TEXT(B19,"ddd") -> Sel | D19: =Q19-H19 -> -48336.602 | E19: =SUM('SO Maret 2026 Rev 2'!E19:AQ19) -> 169755.53 | F19: =SUM('SO Maret 2026 Rev 2'!AR19:AY19) -> 16581.07 | G19: =SUM('SO Maret 2026 Rev 2'!AZ19:BA19) -> 22500 | H19: =SUM(E19:G19) -> 208836.6 | I19: ='SO MS'!E19 -> 96000 | J19: ='SO MS'!F19 -> 31200 | K19: ='SO MS'!G19 -> 10800 | L19: ='SO MS'!H19 -> 0 | M19: ='SO MS'!I19 -> 13500 | N19: ='SO MS'!J19 -> 0 | O19: ='SO MS'!K19 -> 9000 | P19: ='SO MS'!L19 -> 0 | Q19: =SUM(I19:P19) -> 160500
B20: 46092 | C20: =TEXT(B20,"ddd") -> Rab | D20: =Q20-H20 -> -48336.602 | E20: =SUM('SO Maret 2026 Rev 2'!E20:AQ20) -> 169755.53 | F20: =SUM('SO Maret 2026 Rev 2'!AR20:AY20) -> 16581.07 | G20: =SUM('SO Maret 2026 Rev 2'!AZ20:BA20) -> 22500 | H20: =SUM(E20:G20) -> 208836.6 | I20: ='SO MS'!E20 -> 96000 | J20: ='SO MS'!F20 -> 31200 | K20: ='SO MS'!G20 -> 10800 | L20: ='SO MS'!H20 -> 0 | M20: ='SO MS'!I20 -> 13500 | N20: ='SO MS'!J20 -> 0 | O20: ='SO MS'!K20 -> 9000 | P20: ='SO MS'!L20 -> 0 | Q20: =SUM(I20:P20) -> 160500
B21: 46093 | C21: =TEXT(B21,"ddd") -> Kam | D21: =Q21-H21 -> -48336.602 | E21: =SUM('SO Maret 2026 Rev 2'!E21:AQ21) -> 169755.53 | F21: =SUM('SO Maret 2026 Rev 2'!AR21:AY21) -> 16581.07 | G21: =SUM('SO Maret 2026 Rev 2'!AZ21:BA21) -> 22500 | H21: =SUM(E21:G21) -> 208836.6 | I21: ='SO MS'!E21 -> 96000 | J21: ='SO MS'!F21 -> 31200 | K21: ='SO MS'!G21 -> 10800 | L21: ='SO MS'!H21 -> 0 | M21: ='SO MS'!I21 -> 13500 | N21: ='SO MS'!J21 -> 0 | O21: ='SO MS'!K21 -> 9000 | P21: ='SO MS'!L21 -> 0 | Q21: =SUM(I21:P21) -> 160500
B22: 46094 | C22: =TEXT(B22,"ddd") -> Jum | D22: =Q22-H22 -> -46157.932 | E22: =SUM('SO Maret 2026 Rev 2'!E22:AQ22) -> 167576.86 | F22: =SUM('SO Maret 2026 Rev 2'!AR22:AY22) -> 16581.07 | G22: =SUM('SO Maret 2026 Rev 2'!AZ22:BA22) -> 9000 | H22: =SUM(E22:G22) -> 193157.93 | I22: ='SO MS'!E22 -> 96000 | J22: ='SO MS'!F22 -> 31200 | K22: ='SO MS'!G22 -> 10800 | L22: ='SO MS'!H22 -> 0 | M22: ='SO MS'!I22 -> 0 | N22: ='SO MS'!J22 -> 0 | O22: ='SO MS'!K22 -> 9000 | P22: ='SO MS'!L22 -> 0 | Q22: =SUM(I22:P22) -> 147000
B23: 46095 | C23: =TEXT(B23,"ddd") -> Sab | D23: =Q23-H23 -> -37192.055 | E23: =SUM('SO Maret 2026 Rev 2'!E23:AQ23) -> 158610.98 | F23: =SUM('SO Maret 2026 Rev 2'!AR23:AY23) -> 16581.07 | G23: =SUM('SO Maret 2026 Rev 2'!AZ23:BA23) -> 0 | H23: =SUM(E23:G23) -> 175192.05 | I23: ='SO MS'!E23 -> 96000 | J23: ='SO MS'!F23 -> 31200 | K23: ='SO MS'!G23 -> 10800 | L23: ='SO MS'!H23 -> 0 | M23: ='SO MS'!I23 -> 0 | N23: ='SO MS'!J23 -> 0 | O23: ='SO MS'!K23 -> 0 | P23: ='SO MS'!L23 -> 0 | Q23: =SUM(I23:P23) -> 138000
B24: 46096 | C24: =TEXT(B24,"ddd") -> Mgg | D24: =Q24-H24 -> -14524.883 | E24: =SUM('SO Maret 2026 Rev 2'!E24:AQ24) -> 141065.71 | F24: =SUM('SO Maret 2026 Rev 2'!AR24:AY24) -> 11459.17 | G24: =SUM('SO Maret 2026 Rev 2'!AZ24:BA24) -> 0 | H24: =SUM(E24:G24) -> 152524.88 | I24: ='SO MS'!E24 -> 96000 | J24: ='SO MS'!F24 -> 31200 | K24: ='SO MS'!G24 -> 10800 | L24: ='SO MS'!H24 -> 0 | M24: ='SO MS'!I24 -> 0 | N24: ='SO MS'!J24 -> 0 | O24: ='SO MS'!K24 -> 0 | P24: ='SO MS'!L24 -> 0 | Q24: =SUM(I24:P24) -> 138000
B25: Sub Total | D25: =SUM(D18:D24) -> -291221.28 | E25: =SUM(E18:E24) -> 1146275.7 | F25: =SUM(F18:F24) -> 110945.59 | G25: =SUM(G18:G24) -> 99000 | H25: =SUM(H18:H24) -> 1356221.3 | I25: =SUM(I18:I24) -> 672000 | J25: =SUM(J18:J24) -> 218400 | K25: =SUM(K18:K24) -> 75600 | ... Q25: =SUM(Q18:Q24) -> 1065000
A27: =WEEKNUM(B31) -> 12 | B27: 46097 | C27: =TEXT(B27,"ddd") -> Sen | D27: =Q27-H27 -> -35436.377 | E27: =SUM('SO Maret 2026 Rev 2'!E27:AQ27) -> 146055.31 | F27: =SUM('SO Maret 2026 Rev 2'!AR27:AY27) -> 16581.07 | G27: =SUM('SO Maret 2026 Rev 2'!AZ27:BA27) -> 0 | H27: =SUM(E27:G27) -> 162636.38 | I27: ='SO MS'!E27 -> 96000 | J27: ='SO MS'!F27 -> 31200 | K27: ='SO MS'!G27 -> 0 | L27: ='SO MS'!H27 -> 0 | M27: ='SO MS'!I27 -> 0 | N27: ='SO MS'!J27 -> 0 | O27: ='SO MS'!K27 -> 0 | P27: ='SO MS'!L27 -> 0 | Q27: =SUM(I27:P27) -> 127200
B28: 46098 | C28: =TEXT(B28,"ddd") -> Sel | D28: =Q28-H28 -> -24314.525 | E28: =SUM('SO Maret 2026 Rev 2'!E28:AQ28) -> 134933.45 | F28: =SUM('SO Maret 2026 Rev 2'!AR28:AY28) -> 16581.07 | G28: =SUM('SO Maret 2026 Rev 2'!AZ28:BA28) -> 0 | H28: =SUM(E28:G28) -> 151514.52 | I28: ='SO MS'!E28 -> 96000 | J28: ='SO MS'!F28 -> 31200 | K28: ='SO MS'!G28 -> 0 | L28: ='SO MS'!H28 -> 0 | M28: ='SO MS'!I28 -> 0 | N28: ='SO MS'!J28 -> 0 | O28: ='SO MS'!K28 -> 0 | P28: ='SO MS'!L28 -> 0 | Q28: =SUM(I28:P28) -> 127200
B29: 46099 | C29: =TEXT(B29,"ddd") -> Rab | D29: =Q29-H29 -> -4869.2284 | E29: =SUM('SO Maret 2026 Rev 2'!E29:AQ29) -> 117902.77 | F29: =SUM('SO Maret 2026 Rev 2'!AR29:AY29) -> 14166.46 | G29: =SUM('SO Maret 2026 Rev 2'!AZ29:BA29) -> 0 | H29: =SUM(E29:G29) -> 132069.23 | I29: ='SO MS'!E29 -> 96000 | J29: ='SO MS'!F29 -> 31200 | K29: ='SO MS'!G29 -> 0 | L29: ='SO MS'!H29 -> 0 | M29: ='SO MS'!I29 -> 0 | N29: ='SO MS'!J29 -> 0 | O29: ='SO MS'!K29 -> 0 | P29: ='SO MS'!L29 -> 0 | Q29: =SUM(I29:P29) -> 127200
B30: 46100 | C30: =TEXT(B30,"ddd") -> Kam | D30: =Q30-H30 -> 21229.272 | E30: =SUM('SO Maret 2026 Rev 2'!E30:AQ30) -> 98652.984 | F30: =SUM('SO Maret 2026 Rev 2'!AR30:AY30) -> 7317.7442 | G30: =SUM('SO Maret 2026 Rev 2'!AZ30:BA30) -> 0 | H30: =SUM(E30:G30) -> 105970.73 | I30: ='SO MS'!E30 -> 96000 | J30: ='SO MS'!F30 -> 31200 | K30: ='SO MS'!G30 -> 0 | L30: ='SO MS'!H30 -> 0 | M30: ='SO MS'!I30 -> 0 | N30: ='SO MS'!J30 -> 0 | O30: ='SO MS'!K30 -> 0 | P30: ='SO MS'!L30 -> 0 | Q30: =SUM(I30:P30) -> 127200
B31: 46101 | C31: =TEXT(B31,"ddd") -> Jum | D31: =Q31-H31 -> 44121.503 | E31: =SUM('SO Maret 2026 Rev 2'!E31:AQ31) -> 78778.795 | F31: =SUM('SO Maret 2026 Rev 2'!AR31:AY31) -> 4299.7026 | G31: =SUM('SO Maret 2026 Rev 2'!AZ31:BA31) -> 0 | H31: =SUM(E31:G31) -> 83078.497 | I31: ='SO MS'!E31 -> 96000 | J31: ='SO MS'!F31 -> 31200 | K31: ='SO MS'!G31 -> 0 | L31: ='SO MS'!H31 -> 0 | M31: ='SO MS'!I31 -> 0 | N31: ='SO MS'!J31 -> 0 | O31: ='SO MS'!K31 -> 0 | P31: ='SO MS'!L31 -> 0 | Q31: =SUM(I31:P31) -> 127200
B32: 46102 | C32: =TEXT(B32,"ddd") -> Sab | D32: =Q32-H32 -> 32274.01 | E32: =SUM('SO Maret 2026 Rev 2'!E32:AQ32) -> 90626.287 | F32: =SUM('SO Maret 2026 Rev 2'!AR32:AY32) -> 4299.7026 | G32: =SUM('SO Maret 2026 Rev 2'!AZ32:BA32) -> 0 | H32: =SUM(E32:G32) -> 94925.99 | I32: ='SO MS'!E32 -> 96000 | J32: ='SO MS'!F32 -> 31200 | K32: ='SO MS'!G32 -> 0 | L32: ='SO MS'!H32 -> 0 | M32: ='SO MS'!I32 -> 0 | N32: ='SO MS'!J32 -> 0 | O32: ='SO MS'!K32 -> 0 | P32: ='SO MS'!L32 -> 0 | Q32: =SUM(I32:P32) -> 127200
B33: 46103 | C33: =TEXT(B33,"ddd") -> Mgg | D33: =Q33-H33 -> 27314.142 | E33: =SUM('SO Maret 2026 Rev 2'!E33:AQ33) -> 95586.156 | F33: =SUM('SO Maret 2026 Rev 2'!AR33:AY33) -> 4299.7026 | G33: =SUM('SO Maret 2026 Rev 2'!AZ33:BA33) -> 0 | H33: =SUM(E33:G33) -> 99885.858 | I33: ='SO MS'!E33 -> 96000 | J33: ='SO MS'!F33 -> 31200 | K33: ='SO MS'!G33 -> 0 | L33: ='SO MS'!H33 -> 0 | M33: ='SO MS'!I33 -> 0 | N33: ='SO MS'!J33 -> 0 | O33: ='SO MS'!K33 -> 0 | P33: ='SO MS'!L33 -> 0 | Q33: =SUM(I33:P33) -> 127200
B34: Sub Total | D34: =SUM(D27:D33) -> 60318.797 | E34: =SUM(E27:E33) -> 762535.75 | F34: =SUM(F27:F33) -> 67545.452 | G34: =SUM(G27:G33) -> 0 | H34: =SUM(H27:H33) -> 830081.2 | I34: =SUM(I27:I33) -> 672000 | J34: =SUM(J27:J33) -> 218400 | K34: =SUM(K27:K33) -> 0 | ... Q34: =SUM(Q27:Q33) -> 890400
A36: =WEEKNUM(B41) -> 13 | B36: 46104 | C36: =TEXT(B36,"ddd") -> Sen | D36: =Q36-H36 -> 28524.856 | E36: =SUM('SO Maret 2026 Rev 2'!E36:AQ36) -> 94375.442 | F36: =SUM('SO Maret 2026 Rev 2'!AR36:AY36) -> 4299.7026 | G36: =SUM('SO Maret 2026 Rev 2'!AZ36:BA36) -> 0 | H36: =SUM(E36:G36) -> 98675.144 | I36: ='SO MS'!E36 -> 96000 | J36: ='SO MS'!F36 -> 31200 | K36: ='SO MS'!G36 -> 0 | L36: ='SO MS'!H36 -> 0 | M36: ='SO MS'!I36 -> 0 | N36: ='SO MS'!J36 -> 0 | O36: ='SO MS'!K36 -> 0 | P36: ='SO MS'!L36 -> 0 | Q36: =SUM(I36:P36) -> 127200
B37: 46105 | C37: =TEXT(B37,"ddd") -> Sel | D37: =Q37-H37 -> 14828.149 | E37: =SUM('SO Maret 2026 Rev 2'!E37:AQ37) -> 105657.54 | F37: =SUM('SO Maret 2026 Rev 2'!AR37:AY37) -> 6714.313 | G37: =SUM('SO Maret 2026 Rev 2'!AZ37:BA37) -> 0 | H37: =SUM(E37:G37) -> 112371.85 | I37: ='SO MS'!E37 -> 96000 | J37: ='SO MS'!F37 -> 31200 | K37: ='SO MS'!G37 -> 0 | L37: ='SO MS'!H37 -> 0 | M37: ='SO MS'!I37 -> 0 | N37: ='SO MS'!J37 -> 0 | O37: ='SO MS'!K37 -> 0 | P37: ='SO MS'!L37 -> 0 | Q37: =SUM(I37:P37) -> 127200
B38: 46106 | C38: =TEXT(B38,"ddd") -> Rab | D38: =Q38-H38 -> -3846.6304 | E38: =SUM('SO Maret 2026 Rev 2'!E38:AQ38) -> 123210.42 | F38: =SUM('SO Maret 2026 Rev 2'!AR38:AY38) -> 7836.2133 | G38: =SUM('SO Maret 2026 Rev 2'!AZ38:BA38) -> 0 | H38: =SUM(E38:G38) -> 131046.63 | I38: ='SO MS'!E38 -> 96000 | J38: ='SO MS'!F38 -> 31200 | K38: ='SO MS'!G38 -> 0 | L38: ='SO MS'!H38 -> 0 | M38: ='SO MS'!I38 -> 0 | N38: ='SO MS'!J38 -> 0 | O38: ='SO MS'!K38 -> 0 | P38: ='SO MS'!L38 -> 0 | Q38: =SUM(I38:P38) -> 127200
B39: 46107 | C39: =TEXT(B39,"ddd") -> Kam | D39: =Q39-H39 -> -20846.501 | E39: =SUM('SO Maret 2026 Rev 2'!E39:AQ39) -> 129709.99 | F39: =SUM('SO Maret 2026 Rev 2'!AR39:AY39) -> 18336.511 | G39: =SUM('SO Maret 2026 Rev 2'!AZ39:BA39) -> 0 | H39: =SUM(E39:G39) -> 148046.5 | I39: ='SO MS'!E39 -> 96000 | J39: ='SO MS'!F39 -> 31200 | K39: ='SO MS'!G39 -> 0 | L39: ='SO MS'!H39 -> 0 | M39: ='SO MS'!I39 -> 0 | N39: ='SO MS'!J39 -> 0 | O39: ='SO MS'!K39 -> 0 | P39: ='SO MS'!L39 -> 0 | Q39: =SUM(I39:P39) -> 127200
B40: 46108 | C40: =TEXT(B40,"ddd") -> Jum | D40: =Q40-H40 -> -32829.792 | E40: =SUM('SO Maret 2026 Rev 2'!E40:AQ40) -> 144175.54 | F40: =SUM('SO Maret 2026 Rev 2'!AR40:AY40) -> 15854.255 | G40: =SUM('SO Maret 2026 Rev 2'!AZ40:BA40) -> 0 | H40: =SUM(E40:G40) -> 160029.79 | I40: ='SO MS'!E40 -> 96000 | J40: ='SO MS'!F40 -> 31200 | K40: ='SO MS'!G40 -> 0 | L40: ='SO MS'!H40 -> 0 | M40: ='SO MS'!I40 -> 0 | N40: ='SO MS'!J40 -> 0 | O40: ='SO MS'!K40 -> 0 | P40: ='SO MS'!L40 -> 0 | Q40: =SUM(I40:P40) -> 127200
B41: 46109 | C41: =TEXT(B41,"ddd") -> Sab | D41: =Q41-H41 -> -22329.915 | E41: =SUM('SO Maret 2026 Rev 2'!E41:AQ41) -> 133675.66 | F41: =SUM('SO Maret 2026 Rev 2'!AR41:AY41) -> 15854.255 | G41: =SUM('SO Maret 2026 Rev 2'!AZ41:BA41) -> 0 | H41: =SUM(E41:G41) -> 149529.91 | I41: ='SO MS'!E41 -> 96000 | J41: ='SO MS'!F41 -> 31200 | K41: ='SO MS'!G41 -> 0 | L41: ='SO MS'!H41 -> 0 | M41: ='SO MS'!I41 -> 0 | N41: ='SO MS'!J41 -> 0 | O41: ='SO MS'!K41 -> 0 | P41: ='SO MS'!L41 -> 0 | Q41: =SUM(I41:P41) -> 127200
B42: 46110 | C42: =TEXT(B42,"ddd") -> Mgg | D42: =Q42-H42 -> -18014.476 | E42: =SUM('SO Maret 2026 Rev 2'!E42:AQ42) -> 134482.12 | F42: =SUM('SO Maret 2026 Rev 2'!AR42:AY42) -> 10732.355 | G42: =SUM('SO Maret 2026 Rev 2'!AZ42:BA42) -> 0 | H42: =SUM(E42:G42) -> 145214.48 | I42: ='SO MS'!E42 -> 96000 | J42: ='SO MS'!F42 -> 31200 | K42: ='SO MS'!G42 -> 0 | L42: ='SO MS'!H42 -> 0 | M42: ='SO MS'!I42 -> 0 | N42: ='SO MS'!J42 -> 0 | O42: ='SO MS'!K42 -> 0 | P42: ='SO MS'!L42 -> 0 | Q42: =SUM(I42:P42) -> 127200
B43: Sub Total | D43: =SUM(D36:D42) -> -54514.31 | E43: =SUM(E36:E42) -> 865286.71 | F43: =SUM(F36:F42) -> 79627.604 | G43: =SUM(G36:G42) -> 0 | H43: =SUM(H36:H42) -> 944914.31 | I43: =SUM(I36:I42) -> 672000 | J43: =SUM(J36:J42) -> 218400 | K43: =SUM(K36:K42) -> 0 | ... Q43: =SUM(Q36:Q42) -> 890400
B45: 46111 | C45: =TEXT(B45,"ddd") -> Sen | D45: =Q45-H45 -> -204275.3 | E45: =SUM('SO Maret 2026 Rev 2'!E45:AQ45) -> 187694.23 | F45: =SUM('SO Maret 2026 Rev 2'!AR45:AY45) -> 16581.07 | G45: =SUM('SO Maret 2026 Rev 2'!AZ45:BA45) -> 0 | H45: =SUM(E45:G45) -> 204275.3 | I45: ='SO MS'!E48 -> 0 | J45: ='SO MS'!F48 -> 0 | K45: ='SO MS'!G48 -> 0 | L45: ='SO MS'!H48 -> 0 | M45: ='SO MS'!I48 -> 0 | N45: ='SO MS'!J48 -> 0 | O45: ='SO MS'!K48 -> 0 | P45: ='SO MS'!L48 -> 0 | Q45: =SUM(I45:P45) -> 0
B46: 46112 | C46: =TEXT(B46,"ddd") -> Sel | D46: =Q46-H46 -> 4177903.8 | E46: =SUM('SO Maret 2026 Rev 2'!E46:AQ46) -> 189715.09 | F46: =SUM('SO Maret 2026 Rev 2'!AR46:AY46) -> 16581.07 | G46: =SUM('SO Maret 2026 Rev 2'!AZ46:BA46) -> 0 | H46: =SUM(E46:G46) -> 206296.16 | I46: ='SO MS'!E49 -> 2976000 | J46: ='SO MS'!F49 -> 967200 | K46: ='SO MS'!G49 -> 162000 | L46: ='SO MS'!H49 -> 0 | M46: ='SO MS'!I49 -> 162000 | N46: ='SO MS'!J49 -> 0 | O46: ='SO MS'!K49 -> 117000 | P46: ='SO MS'!L49 -> 0 | Q46: =SUM(I46:P46) -> 4384200
B47: Sub Total | D47: =SUM(D40:D46) -> 3845940.1 | E47: =SUM(E45:E46) -> 377409.31 | F47: =SUM(F45:F46) -> 33162.14 | G47: =SUM(G45:G46) -> 0 | H47: =SUM(H45:H46) -> 410571.45 | I47: =SUM(I45:I46) -> 2976000 | J47: =SUM(J45:J46) -> 967200 | K47: =SUM(K45:K46) -> 162000 | L47: =SUM(L45:L46) -> 0 | ... Q47: =SUM(Q45:Q46) -> 4384200
...

Sheet SO MS
A1: SALES ORDER GAS
A4: ='KEBUTUHAN GAS'!A4 -> 46082
A5: Week | B5: DATE | D5: TOTAL | E5: MS SETU | F5: MS KHT | G5: MS BLORA | H5: MS BITUNG | I5: MS ZEBRA | J5: MS TAMBAKLOROK | K5: MS WUNUT | L5: MS SADANG
A6: =WEEKNUM(B6) -> 10 | B6: 46082 | C6: Sun | D6: =SUM(E6:O6) -> 160500 | E6: =4*24000 -> 96000 | F6: =1.3*24000 -> 31200 | G6: =0.45*24000 -> 10800 | I6: ='SO Maret 2026 Rev 2'!AZ6 -> 13500 | K6: ='SO Maret 2026 Rev 2'!BA6 -> 9000 | L6: ='Summary sales'!L8 -> 0
B7: Sub Total | D7: =SUM(D3:D6) -> 160500 | E7: =SUM(E3:E6) -> 96000 | F7: =SUM(F3:F6) -> 31200 | G7: =SUM(G3:G6) -> 10800 | H7: =SUM(H3:H6) -> 0 | I7: =SUM(I3:I6) -> 13500 | J7: =SUM(J3:J6) -> 0 | K7: =SUM(K3:K6) -> 9000 | L7: =SUM(L3:L6) -> 0
A9: =WEEKNUM(B13) -> 10 | B9: =B6+1 -> 46083 | C9: Mon | D9: =SUM(E9:O9) -> 160500 | E9: =4*24000 -> 96000 | F9: =1.3*24000 -> 31200 | G9: =0.45*24000 -> 10800 | I9: ='SO Maret 2026 Rev 2'!AZ9 -> 13500 | K9: ='SO Maret 2026 Rev 2'!BA9 -> 9000 | L9: ='Summary sales'!L11 -> 0
B10: =B9+1 -> 46084 | C10: Tue | D10: =SUM(E10:O10) -> 160500 | E10: =4*24000 -> 96000 | F10: =1.3*24000 -> 31200 | G10: =0.45*24000 -> 10800 | I10: ='SO Maret 2026 Rev 2'!AZ10 -> 13500 | K10: ='SO Maret 2026 Rev 2'!BA10 -> 9000 | L10: ='Summary sales'!L12 -> 0
B11: =B10+1 -> 46085 | C11: Wed | D11: =SUM(E11:O11) -> 160500 | E11: =4*24000 -> 96000 | F11: =1.3*24000 -> 31200 | G11: =0.45*24000 -> 10800 | I11: ='SO Maret 2026 Rev 2'!AZ11 -> 13500 | K11: ='SO Maret 2026 Rev 2'!BA11 -> 9000 | L11: ='Summary sales'!L13 -> 0
B12: =B11+1 -> 46086 | C12: Thu | D12: =SUM(E12:O12) -> 160500 | E12: =4*24000 -> 96000 | F12: =1.3*24000 -> 31200 | G12: =0.45*24000 -> 10800 | I12: ='SO Maret 2026 Rev 2'!AZ12 -> 13500 | K12: ='SO Maret 2026 Rev 2'!BA12 -> 9000 | L12: ='Summary sales'!L14 -> 0
B13: =B12+1 -> 46087 | C13: Fri | D13: =SUM(E13:O13) -> 160500 | E13: =4*24000 -> 96000 | F13: =1.3*24000 -> 31200 | G13: =0.45*24000 -> 10800 | I13: ='SO Maret 2026 Rev 2'!AZ13 -> 13500 | K13: ='SO Maret 2026 Rev 2'!BA13 -> 9000 | L13: ='Summary sales'!L15 -> 0
B14: =B13+1 -> 46088 | C14: Sat | D14: =SUM(E14:O14) -> 160500 | E14: =4*24000 -> 96000 | F14: =1.3*24000 -> 31200 | G14: =0.45*24000 -> 10800 | I14: ='SO Maret 2026 Rev 2'!AZ14 -> 13500 | K14: ='SO Maret 2026 Rev 2'!BA14 -> 9000 | L14: ='Summary sales'!L16 -> 0
B15: =B14+1 -> 46089 | C15: Sun | D15: =SUM(E15:O15) -> 160500 | E15: =4*24000 -> 96000 | F15: =1.3*24000 -> 31200 | G15: =0.45*24000 -> 10800 | I15: ='SO Maret 2026 Rev 2'!AZ15 -> 13500 | K15: ='SO Maret 2026 Rev 2'!BA15 -> 9000 | L15: ='Summary sales'!L17 -> 0
B16: Sub Total | D16: =SUM(D9:D15) -> 1123500 | E16: =SUM(E9:E15) -> 672000 | F16: =SUM(F9:F15) -> 218400 | G16: =SUM(G9:G15) -> 75600 | H16: =SUM(H9:H15) -> 0 | I16: ='SO Maret 2026 Rev 2'!AZ16 -> 94500 | J16: =SUM(J9:J15) -> 0 | K16: =SUM(K9:K15) -> 63000 | L16: =SUM(L9:L15) -> 0
A18: =WEEKNUM(B22) -> 11 | B18: =B15+1 -> 46090 | C18: Mon | D18: =SUM(E18:O18) -> 160500 | E18: =4*24000 -> 96000 | F18: =1.3*24000 -> 31200 | G18: =0.45*24000 -> 10800 | I18: ='SO Maret 2026 Rev 2'!AZ18 -> 13500 | K18: ='SO Maret 2026 Rev 2'!BA18 -> 9000 | L18: ='Summary sales'!L20 -> 0
B19: =B18+1 -> 46091 | C19: Tue | D19: =SUM(E19:O19) -> 160500 | E19: =4*24000 -> 96000 | F19: =1.3*24000 -> 31200 | G19: =0.45*24000 -> 10800 | I19: ='SO Maret 2026 Rev 2'!AZ19 -> 13500 | K19: ='SO Maret 2026 Rev 2'!BA19 -> 9000 | L19: ='Summary sales'!L21 -> 0
B20: =B19+1 -> 46092 | C20: Wed | D20: =SUM(E20:O20) -> 160500 | E20: =4*24000 -> 96000 | F20: =1.3*24000 -> 31200 | G20: =0.45*24000 -> 10800 | I20: ='SO Maret 2026 Rev 2'!AZ20 -> 13500 | K20: ='SO Maret 2026 Rev 2'!BA20 -> 9000 | L20: ='Summary sales'!L22 -> 0
B21: =B20+1 -> 46093 | C21: Thu | D21: =SUM(E21:O21) -> 160500 | E21: =4*24000 -> 96000 | F21: =1.3*24000 -> 31200 | G21: =0.45*24000 -> 10800 | I21: ='SO Maret 2026 Rev 2'!AZ21 -> 13500 | K21: ='SO Maret 2026 Rev 2'!BA21 -> 9000 | L21: ='Summary sales'!L23 -> 0
B22: =B21+1 -> 46094 | C22: Fri | D22: =SUM(E22:O22) -> 147000 | E22: =4*24000 -> 96000 | F22: =1.3*24000 -> 31200 | G22: =0.45*24000 -> 10800 | I22: ='SO Maret 2026 Rev 2'!AZ22 -> 0 | K22: ='SO Maret 2026 Rev 2'!BA22 -> 9000 | L22: ='Summary sales'!L24 -> 0
B23: =B22+1 -> 46095 | C23: Sat | D23: =SUM(E23:O23) -> 138000 | E23: =4*24000 -> 96000 | F23: =1.3*24000 -> 31200 | G23: =0.45*24000 -> 10800 | I23: ='SO Maret 2026 Rev 2'!AZ23 -> 0 | K23: ='SO Maret 2026 Rev 2'!BA23 -> 0 | L23: ='Summary sales'!L25 -> 0
B24: =B23+1 -> 46096 | C24: Sun | D24: =SUM(E24:O24) -> 138000 | E24: =4*24000 -> 96000 | F24: =1.3*24000 -> 31200 | G24: =0.45*24000 -> 10800 | I24: ='SO Maret 2026 Rev 2'!AZ24 -> 0 | K24: ='SO Maret 2026 Rev 2'!BA24 -> 0 | L24: ='Summary sales'!L26 -> 0
B25: Sub Total | D25: =SUM(D18:D24) -> 1065000 | E25: =SUM(E18:E24) -> 672000 | F25: =SUM(F18:F24) -> 218400 | G25: =SUM(G18:G24) -> 75600 | H25: =SUM(H18:H24) -> 0 | I25: =SUM(I18:I24) -> 54000 | J25: =SUM(J18:J24) -> 0 | K25: =SUM(K18:K24) -> 45000 | L25: =SUM(L18:L24) -> 0
A27: =WEEKNUM(B31) -> 12 | B27: =B24+1 -> 46097 | C27: Mon | D27: =SUM(E27:O27) -> 127200 | E27: =4*24000 -> 96000 | F27: =1.3*24000 -> 31200 | I27: ='SO Maret 2026 Rev 2'!AZ27 -> 0 | K27: ='SO Maret 2026 Rev 2'!BA27 -> 0 | L27: ='Summary sales'!L29 -> 0
B28: =B27+1 -> 46098 | C28: Tue | D28: =SUM(E28:O28) -> 127200 | E28: =4*24000 -> 96000 | F28: =1.3*24000 -> 31200 | I28: ='SO Maret 2026 Rev 2'!AZ28 -> 0 | K28: ='SO Maret 2026 Rev 2'!BA28 -> 0 | L28: ='Summary sales'!L30 -> 0
B29: =B28+1 -> 46099 | C29: Wed | D29: =SUM(E29:O29) -> 127200 | E29: =4*24000 -> 96000 | F29: =1.3*24000 -> 31200 | I29: ='SO Maret 2026 Rev 2'!AZ29 -> 0 | K29: ='SO Maret 2026 Rev 2'!BA29 -> 0 | L29: ='Summary sales'!L31 -> 0
B30: =B29+1 -> 46100 | C30: Thu | D30: =SUM(E30:O30) -> 127200 | E30: =4*24000 -> 96000 | F30: =1.3*24000 -> 31200 | I30: ='SO Maret 2026 Rev 2'!AZ30 -> 0 | K30: ='SO Maret 2026 Rev 2'!BA30 -> 0 | L30: ='Summary sales'!L32 -> 0
B31: =B30+1 -> 46101 | C31: Fri | D31: =SUM(E31:O31) -> 127200 | E31: =4*24000 -> 96000 | F31: =1.3*24000 -> 31200 | I31: ='SO Maret 2026 Rev 2'!AZ31 -> 0 | K31: ='SO Maret 2026 Rev 2'!BA31 -> 0 | L31: ='Summary sales'!L33 -> 0
B32: =B31+1 -> 46102 | C32: Sat | D32: =SUM(E32:O32) -> 127200 | E32: =4*24000 -> 96000 | F32: =1.3*24000 -> 31200 | I32: ='SO Maret 2026 Rev 2'!AZ32 -> 0 | K32: ='SO Maret 2026 Rev 2'!BA32 -> 0 | L32: ='Summary sales'!L34 -> 0
B33: =B32+1 -> 46103 | C33: Sun | D33: =SUM(E33:O33) -> 127200 | E33: =4*24000 -> 96000 | F33: =1.3*24000 -> 31200 | I33: ='SO Maret 2026 Rev 2'!AZ33 -> 0 | K33: ='SO Maret 2026 Rev 2'!BA33 -> 0 | L33: ='Summary sales'!L35 -> 0
B34: Sub Total | D34: =SUM(D27:D33) -> 890400 | E34: =SUM(E27:E33) -> 672000 | F34: =SUM(F27:F33) -> 218400 | G34: =SUM(G27:G33) -> 0 | H34: =SUM(H27:H33) -> 0 | I34: =SUM(I27:I33) -> 0 | J34: =SUM(J27:J33) -> 0 | K34: =SUM(K27:K33) -> 0 | L34: =SUM(L27:L33) -> 0
A36: =WEEKNUM(B41) -> 13 | B36: =B33+1 -> 46104 | C36: Mon | D36: =SUM(E36:O36) -> 127200 | E36: =4*24000 -> 96000 | F36: =1.3*24000 -> 31200 | I36: ='SO Maret 2026 Rev 2'!AZ36 -> 0 | K36: ='SO Maret 2026 Rev 2'!BA36 -> 0 | L36: ='Summary sales'!L40 -> 0
B37: =B36+1 -> 46105 | C37: Tue | D37: =SUM(E37:O37) -> 127200 | E37: =4*24000 -> 96000 | F37: =1.3*24000 -> 31200 | I37: ='SO Maret 2026 Rev 2'!AZ37 -> 0 | K37: ='SO Maret 2026 Rev 2'!BA37 -> 0 | L37: ='Summary sales'!L41 -> 0
B38: =B37+1 -> 46106 | C38: Wed | D38: =SUM(E38:O38) -> 127200 | E38: =4*24000 -> 96000 | F38: =1.3*24000 -> 31200 | I38: ='SO Maret 2026 Rev 2'!AZ38 -> 0 | K38: ='SO Maret 2026 Rev 2'!BA38 -> 0 | L38: ='Summary sales'!L42 -> 0
B39: =B38+1 -> 46107 | C39: Thu | D39: =SUM(E39:O39) -> 127200 | E39: =4*24000 -> 96000 | F39: =1.3*24000 -> 31200 | I39: ='SO Maret 2026 Rev 2'!AZ39 -> 0 | K39: ='SO Maret 2026 Rev 2'!BA39 -> 0 | L39: ='Summary sales'!L43 -> 0
B40: =B39+1 -> 46108 | C40: Fri | D40: =SUM(E40:O40) -> 127200 | E40: =4*24000 -> 96000 | F40: =1.3*24000 -> 31200 | I40: ='SO Maret 2026 Rev 2'!AZ40 -> 0 | K40: ='SO Maret 2026 Rev 2'!BA40 -> 0 | L40: ='Summary sales'!L44 -> 0
B41: =B40+1 -> 46109 | C41: Sat | D41: =SUM(E41:O41) -> 127200 | E41: =4*24000 -> 96000 | F41: =1.3*24000 -> 31200 | I41: ='SO Maret 2026 Rev 2'!AZ41 -> 0 | K41: ='SO Maret 2026 Rev 2'!BA41 -> 0 | L41: ='Summary sales'!L45 -> 0
B42: =B41+1 -> 46110 | C42: Sun | D42: =SUM(E42:O42) -> 127200 | E42: =4*24000 -> 96000 | F42: =1.3*24000 -> 31200 | I42: ='SO Maret 2026 Rev 2'!AZ42 -> 0 | K42: ='SO Maret 2026 Rev 2'!BA42 -> 0 | L42: ='Summary sales'!L46 -> 0
B43: Sub Total | D43: =SUM(D36:D42) -> 890400 | E43: =SUM(E36:E42) -> 672000 | F43: =SUM(F36:F42) -> 218400 | G43: =SUM(G36:G42) -> 0 | H43: =SUM(H36:H42) -> 0 | I43: =SUM(I36:I42) -> 0 | J43: =SUM(J36:J42) -> 0 | K43: =SUM(K36:K42) -> 0 | L43: =SUM(L36:L42) -> 0
B45: =B42+1 -> 46111 | C45: Mon | D45: =SUM(E45:O45) -> 127200 | E45: =4*24000 -> 96000 | F45: =1.3*24000 -> 31200 | I45: ='SO Maret 2026 Rev 2'!AZ45 -> 0 | K45: ='SO Maret 2026 Rev 2'!BA45 -> 0 | L45: ='Summary sales'!L49 -> 0
B46: =B45+1 -> 46112 | C46: Tue | D46: =SUM(E46:O46) -> 127200 | E46: =4*24000 -> 96000 | F46: =1.3*24000 -> 31200 | I46: ='SO Maret 2026 Rev 2'!AZ46 -> 0 | K46: ='SO Maret 2026 Rev 2'!BA46 -> 0 | L46: ='Summary sales'!L50 -> 0
B47: Sub Total | D47: =SUM(D45:D46) -> 254400 | E47: =SUM(E45:E46) -> 192000 | F47: =SUM(F45:F46) -> 62400 | G47: =SUM(G45:G46) -> 0 | H47: =SUM(H45:H46) -> 0 | I47: ='SO Maret 2026 Rev 2'!AZ47 -> 0 | J47: =SUM(J45:J46) -> 0 | K47: =SUM(K45:K46) -> 0 | L47: =SUM(L45:L46) -> 0
...

Sheet Summary Gas
A1: Summary Gas
L3: SO MS | AI3: SUMMARY FOB | AK3: SUMMARY SALES
A6: ='Daily Sales'!A2 -> 46082
A7: SERAPAN GAS MS | AE7: SALES
A8: Week | B8: DATE | C8: DAY | D8: Total Serapan Gas | G8: MS SETU | J8: MS KHT | M8: MS BLORA | P8: MS BITUNG | S8: MS ZEBRA | V8: MS TAMBAKLOROK | Y8: MS WUNUT | AB8: MS SADANG | AE8: Total sales | AH8: SALES FOB | AK8: SALES NON FOB
D9: TARGET | E9: ACTUAL | F9: SELISIH | G9: TARGET | H9: ACTUAL | I9: SELISIH | J9: TARGET | K9: ACTUAL | L9: SELISIH | M9: TARGET | N9: ACTUAL | O9: SELISIH | P9: TARGET | Q9: ACTUAL | R9: SELISIH | S9: TARGET | T9: ACTUAL | U9: SELISIH | V9: TARGET | W9: ACTUAL | X9: SELISIH | Y9: TARGET | Z9: ACTUAL | AA9: SELISIH | AB9: TARGET | AC9: ACTUAL | AD9: SELISIH | AE9: TARGET | AF9: ACTUAL | AG9: SELISIH | AH9: TARGET | AI9: ACTUAL | AJ9: SELISIH | AK9: TARGET | AL9: ACTUAL | AM9: SELISIH
A10: =WEEKNUM(B10) -> 10 | B10: 46082 | C10: =TEXT(B10,"ddd") -> Mgg | D10: =SUMIF($G$9:$AD$9,$D$9,G10:AD10) -> 160500 | E10: =SUMIF($G$9:$AD$9,$E$9,G10:AD10) -> 190198.35 | F10: =E10-D10 -> 29698.349 | G10: =VLOOKUP($B$10:$B$59,'SO MS'!$B$6:$L$50,4,TRUE) -> 96000 | H10: ='Summary sales'!D8 -> 107771.32 | I10: =H10-G10 -> 11771.32 | J10: =VLOOKUP($B$10:$B$59,'SO MS'!$B$6:$L$50,5,TRUE) -> 31200 | K10: ='Summary sales'!E8 -> 47254.13 | L10: =K10-J10 -> 16054.13 | M10: =VLOOKUP($B$10:$B$59,'SO MS'!$B$6:$L$50,6,TRUE) -> 10800 | N10: ='Summary sales'!F8 -> 23442.02 | O10: =N10-M10 -> 12642.02 | P10: =VLOOKUP($B$10:$B$59,'SO MS'!$B$6:$AS$50,7,TRUE) -> 0 | Q10: ='Summary sales'!G8 -> 0 | R10: =Q10-P10 -> 0 | S10: =VLOOKUP($B$10:$B$59,'SO MS'!$B$6:$AS$50,8,TRUE) -> 13500 | T10: ='Summary sales'!H8 -> 0 | U10: =T10-S10 -> -13500 | V10: =VLOOKUP($B$10:$B$59,'SO MS'!$B$6:$AS$50,9,TRUE) -> 0 | W10: =VLOOKUP($B$10:$B$59,'Summary sales'!$A$8:$M$58,9,TRUE) -> 2990.88 | X10: =W10-V10 -> 2990.88 | Y10: =VLOOKUP($B$10:$B$59,'SO MS'!$B$6:$AS$50,10,TRUE) -> 9000 | Z10: ='Summary sales'!K8 -> 8739.999 | AA10: =Z10-Y10 -> -260.001 | AB10: =VLOOKUP($B$10:$B$59,'SO MS'!$B$6:$AS$50,11,TRUE) -> 0 | AD10: =AC10-AB10 -> 0 | AE10: ='Daily Sales'!D5 -> 182536.18 | AF10: ='Daily Sales'!E5 -> 138896.08 | AG10: =AF10-AE10 -> -43640.101 | AH10: 0 | AI10: 0 | AJ10: =AI10-AH10 -> 0 | AK10: =VLOOKUP($B$10:$B$56,'Daily Sales'!$B$5:$F$46,3,TRUE) -> 182536.18 | AL10: =VLOOKUP($B$10:$B$56,'Daily Sales'!$B$5:$F$46,4,TRUE) -> 138896.08 | AM10: =AL10-AK10 -> -43640.101
B11: Sub Total | D11: =SUM(D7:D10) -> 160500 | E11: =SUM(E7:E10) -> 190198.35 | F11: =SUM(F7:F10) -> 29698.349 | G11: =SUM(G7:G10) -> 96000 | H11: =SUM(H7:H10) -> 107771.32 | I11: =SUM(I7:I10) -> 11771.32 | J11: =SUM(J7:J10) -> 31200 | K11: =SUM(K7:K10) -> 47254.13 | ... AM11: =SUM(AM7:AM10) -> -43640.101
