Workbook
Name ___xlnm._FilterDatabase_2: #REF!
Name ___xlnm._FilterDatabase_2: #REF!
Name ___xlnm._FilterDatabase_2: #REF!
Name ___xlnm._FilterDatabase_2: #REF!
Name ___xlnm._FilterDatabase_2: #REF!
Name ___xlnm._FilterDatabase_2: #REF!
Name ___xlnm._FilterDatabase_2: #REF!
Name ___xlnm._FilterDatabase_2: #REF!
Name ___xlnm._FilterDatabase_2: #REF!
Name ___xlnm._FilterDatabase_2: #REF!
Name ___xlnm._FilterDatabase_2: #REF!
Name __xlnm._FilterDatabase_2: #REF!
Name __xlnm._FilterDatabase_2: #REF!
Name __xlnm._FilterDatabase_2: #REF!
Name __xlnm._FilterDatabase_2: #REF!
Name __xlnm._FilterDatabase_2: #REF!
Name __xlnm._FilterDatabase_2: #REF!
Name __xlnm._FilterDatabase_2: #REF!
Name __xlnm._FilterDatabase_2: #REF!
Name __xlnm._FilterDatabase_2: #REF!
Name __xlnm._FilterDatabase_2: #REF!
Name __xlnm._FilterDatabase_2: #REF!
Name _TES46: #N/A
Name AAAA: #N/A
Name ati: #N/A
Name BS: #N/A
Name CCC: #N/A
Name depr9200: #N/A
Name dfsfd: #N/A
Name Excel_BuiltIn__FilterDatabase_1: #REF!
Name Excel_BuiltIn__FilterDatabase_1: #REF!
Name Excel_BuiltIn__FilterDatabase_1: #REF!
Name Excel_BuiltIn__FilterDatabase_1: #REF!
Name Excel_BuiltIn__FilterDatabase_1: #REF!
Name Excel_BuiltIn__FilterDatabase_1: #REF!
Name Excel_BuiltIn__FilterDatabase_1: #REF!
Name Excel_BuiltIn__FilterDatabase_1: #REF!
Name Excel_BuiltIn__FilterDatabase_1: #REF!
Name Excel_BuiltIn__FilterDatabase_1: #REF!
Name Excel_BuiltIn__FilterDatabase_1: #REF!
Name Excel_BuiltIn_Print_Titles: NA()
Name Export_3: #REF!
Name Export_3: #REF!
Name Export_3: #REF!
Name Export_3: #REF!
Name Export_3: #REF!
Name Export_3: #REF!
Name Export_3: #REF!
Name Export_3: #REF!
Name FOB: 'Summary FOB'!#REF!
Name FOB: 'Summary FOB'!#REF!
Name FOB: 'Summary FOB'!#REF!
Name FOB: 'Summary FOB'!#REF!
Name FOB: 'Summary FOB'!#REF!
Name FOB: 'Summary FOB'!#REF!
Name FOB: 'Summary FOB'!#REF!
Name FOB: 'Summary FOB'!#REF!
Name partt: #N/A
Name PRINT_TITLES_MI: #N/A
Name project: #N/A

Sheet SO APRIL 2026 Rev2
AF1: SMS | AG1: BMT
A2: SALES ORDER | U2: gf ranca
A3: 46113 | U3: =10500-6600 -> 3900
AS4: FOB PTGN
A5: Week | B5: DATE | D5: TOTAL | E5: CLIN | F5: BI | G5: MKG | H5: STM | I5: OAJ | J5: NNI | K5: SHB | L5: GTL | M5: TWK | N5: BYC | O5: GF RANCA | P5: SMA | Q5: UMI | R5: HLI | S5: ASAHIMAS | T5: DIC | U5: HCI | V5: KSN | W5: ADP | X5: ALT (KSO MASAMI) | Y5: IDP (KSO AAE) | Z5: FJI (KSO SALMAH) | AA5: WINGLOK (KSO EBM) | AB5: CISF (KSO RRS) | AC5: KGM | AD5: PUJ - LUBRICANT | AE5: CALBEE (KSO BMI) | AF5: IP | AG5: BEM | AH5: AMI | AI5: KA | AJ5: KTN | AK5: TOMIMOTO | AL5: NIAGA GARAM | AM5: PCI 84 | AN5: PCI MENGGER | AO5: INDOFOOD | AP5: CERES | AQ5: ABC KOGEN | AR5: TONGJI | AS5: PA | AT5: RB | AU5: GF ATOM | AV5: GF KULIT | AW5: HSK (KSO GAS) | AX5: SDM | AY5: JARGAS | AZ5: SBI | BA5: SP JES | BB5: SP GLOBAL | BC5: JIUQI
A6: =WEEKNUM(B6) -> 14 | B6: =A3 -> 46113 | C6: =TEXT(B6,"ddd") -> Rab | D6: =SUM(E6:BC6) -> 186311.43 | E6: 1199.5729 | F6: 1500 | G6: 1129.7313 | H6: 3282.5161 | I6: 644.02065 | J6: 0 | K6: 499.97065 | L6: 603.76323 | M6: 673.27548 | N6: 5514.199 | O6: 6600.0623 | P6: 2874.3265 | Q6: 11659.555 | R6: 9600 | S6: 26500 | T6: 7000 | U6: 7000 | V6: 5000 | W6: 500 | X6: 1000 | Y6: 5500 | Z6: 70.054839 | AA6: 89.451613 | AB6: 3500 | AC6: 1300 | AD6: 2900 | AE6: 8000 | AF6: 2020.8603 | AG6: 800 | AH6: 7200 | AI6: 3499.8768 | AJ6: 2043.2745 | AK6: 1999.5303 | AL6: 1000 | AM6: 11007.047 | AN6: 1519.5448 | AO6: 3999.6742 | AP6: 9000.0571 | AQ6: 8000 | AR6: 3500 | AS6: 726.81516 | AT6: 3018.0416 | AU6: 2044.9997 | AV6: 369.61071 | AW6: 5000 | AX6: 1121.9003 | AY6: 1800 | AZ6: 2499.7026 | BA6: 0 | BB6: 0 | BC6: 0
B7: =B6+1 -> 46114 | C7: =TEXT(B7,"ddd") -> Kam | D7: =SUM(E7:BC7) -> 186311.43 | E7: 1199.5729 | F7: 1500 | G7: 1129.7313 | H7: 3282.5161 | I7: 644.02065 | J7: 0 | K7: 499.97065 | L7: 603.76323 | M7: 673.27548 | N7: 5514.199 | O7: 6600.0623 | P7: 2874.3265 | Q7: 11659.555 | R7: 9600 | S7: 26500 | T7: 7000 | U7: 7000 | V7: 5000 | W7: 500 | X7: 1000 | Y7: 5500 | Z7: 70.054839 | AA7: 89.451613 | AB7: 3500 | AC7: 1300 | AD7: 2900 | AE7: 8000 | AF7: 2020.8603 | AG7: 800 | AH7: 7200 | AI7: 3499.8768 | AJ7: 2043.2745 | AK7: 1999.5303 | AL7: 1000 | AM7: 11007.047 | AN7: 1519.5448 | AO7: 3999.6742 | AP7: 9000.0571 | AQ7: 8000 | AR7: 3500 | AS7: 726.81516 | AT7: 3018.0416 | AU7: 2044.9997 | AV7: 369.61071 | AW7: 5000 | AX7: 1121.9003 | AY7: 1800 | AZ7: 2499.7026 | BA7: 0 | BB7: 0 | BC7: 0
B8: =B7+1 -> 46115 | C8: =TEXT(B8,"ddd") -> Jum | D8: =SUM(E8:BC8) -> 182811.43 | E8: 1199.5729 | F8: 1500 | G8: 1129.7313 | H8: 3282.5161 | I8: 644.02065 | J8: 0 | K8: 499.97065 | L8: 603.76323 | M8: 673.27548 | N8: 5514.199 | O8: 6600.0623 | P8: 2874.3265 | Q8: 11659.555 | R8: 9600 | S8: 26500 | T8: 7000 | U8: 7000 | V8: 5000 | W8: 500 | X8: 1000 | Y8: 5500 | Z8: 70.054839 | AA8: 89.451613 | AB8: 3500 | AC8: 1300 | AD8: 2900 | AE8: 8000 | AF8: 2020.8603 | AG8: 800 | AH8: 7200 | AI8: 3499.8768 | AJ8: 2043.2745 | AK8: 1999.5303 | AL8: 1000 | AM8: 11007.047 | AN8: 1519.5448 | AO8: 3999.6742 | AP8: 9000.0571 | AQ8: 8000 | AR8: 0 | AS8: 726.81516 | AT8: 3018.0416 | AU8: 2044.9997 | AV8: 369.61071 | AW8: 5000 | AX8: 1121.9003 | AY8: 1800 | AZ8: 2499.7026 | BA8: 0 | BB8: 0 | BC8: 0
B9: =B8+1 -> 46116 | C9: =TEXT(B9,"ddd") -> Sab | D9: =SUM(E9:BC9) -> 177845.56 | E9: 733.5729 | F9: 1500 | G9: 1129.7313 | H9: 3282.5161 | I9: 644.02065 | J9: 0 | K9: 499.97065 | L9: 603.76323 | M9: 673.27548 | N9: 4514.199 | O9: 6600.0623 | P9: 2874.3265 | Q9: 11659.555 | R9: 9600 | S9: 26500 | T9: 7000 | U9: 7000 | V9: 5000 | W9: 500 | X9: 1000 | Y9: 5500 | Z9: 70.054839 | AA9: 89.451613 | AB9: 3500 | AC9: 1300 | AD9: 2900 | AE9: 8000 | AF9: 2020.8603 | AG9: 800 | AH9: 7200 | AI9: 0 | AJ9: 2043.2745 | AK9: 1999.5303 | AL9: 1000 | AM9: 11007.047 | AN9: 1519.5448 | AO9: 3999.6742 | AP9: 9000.0571 | AQ9: 8000 | AR9: 0 | AS9: 726.81516 | AT9: 3018.0416 | AU9: 2044.9997 | AV9: 369.61071 | AW9: 5000 | AX9: 1121.9003 | AY9: 1800 | AZ9: 2499.7026 | BA9: 0 | BB9: 0 | BC9: 0
B10: =B9+1 -> 46117 | C10: =TEXT(B10,"ddd") -> Mgg | D10: =SUM(E10:BC10) -> 167452.01 | E10: 733.5729 | F10: 1000 | G10: 1129.7313 | H10: 999.51613 | I10: 644.02065 | J10: 0 | K10: 0 | L10: 603.76323 | M10: 673.27548 | N10: 0 | O10: 6600.0623 | P10: 300 | Q10: 6659.5545 | R10: 9600 | S10: 48000 | T10: 7000 | U10: 7000 | V10: 5000 | W10: 500 | X10: 0 | Y10: 2500 | Z10: 70.054839 | AA10: 89.451613 | AB10: 1000 | AC10: 1300 | AD10: 0 | AE10: 15000 | AF10: 2020.8603 | AG10: 0 | AH10: 2999.8519 | AI10: 0 | AJ10: 2043.2745 | AK10: 1999.5303 | AL10: 0 | AM10: 11007.047 | AN10: 1519.5448 | AO10: 3999.6742 | AP10: 6000.0571 | AQ10: 8000 | AR10: 0 | AS10: 726.81516 | AT10: 3018.0416 | AU10: 2044.9997 | AV10: 369.61071 | AW10: 1000 | AX10: 0 | AY10: 1800 | AZ10: 2499.7026 | BA10: 0 | BB10: 0 | BC10: 0
B11: Sub Total | D11: =SUM(D6:D10) -> 900731.88 | E11: =SUM(E6:E10) -> 5065.8645 | F11: =SUM(F6:F10) -> 7000 | G11: =SUM(G6:G10) -> 5648.6565 | H11: =SUM(H6:H10) -> 14129.581 | I11: =SUM(I6:I10) -> 3220.1032 | J11: =SUM(J6:J10) -> 0 | K11: =SUM(K6:K10) -> 1999.8826 | ... BC11: =SUM(BC6:BC10) -> 0
A13: =WEEKNUM(B13) -> 15 | B13: =B10+1 -> 46118 | C13: =TEXT(B13,"ddd") -> Sen | D13: =SUM(E13:BC13) -> 179511.43 | E13: 1199.5729 | F13: 1500 | G13: 1129.7313 | H13: 3282.5161 | I13: 644.02065 | J13: 0 | K13: 499.97065 | L13: 603.76323 | M13: 673.27548 | N13: 5514.199 | O13: 6600.0623 | P13: 2874.3265 | Q13: 11659.555 | R13: 4800 | S13: 26500 | T13: 5000 | U13: 7000 | V13: 5000 | W13: 500 | X13: 1000 | Y13: 5500 | Z13: 70.054839 | AA13: 89.451613 | AB13: 3500 | AC13: 1300 | AD13: 2900 | AE13: 8000 | AF13: 2020.8603 | AG13: 800 | AH13: 7200 | AI13: 3499.8768 | AJ13: 2043.2745 | AK13: 1999.5303 | AL13: 1000 | AM13: 11007.047 | AN13: 1519.5448 | AO13: 3999.6742 | AP13: 9000.0571 | AQ13: 8000 | AR13: 3500 | AS13: 726.81516 | AT13: 3018.0416 | AU13: 2044.9997 | AV13: 369.61071 | AW13: 5000 | AX13: 1121.9003 | AY13: 1800 | AZ13: 2499.7026 | BA13: 0 | BB13: 0 | BC13: 0
B14: =B13+1 -> 46119 | C14: =TEXT(B14,"ddd") -> Sel | D14: =SUM(E14:BC14) -> 179511.43 | E14: 1199.5729 | F14: 1500 | G14: 1129.7313 | H14: 3282.5161 | I14: 644.02065 | J14: 0 | K14: 499.97065 | L14: 603.76323 | M14: 673.27548 | N14: 5514.199 | O14: 6600.0623 | P14: 2874.3265 | Q14: 11659.555 | R14: 4800 | S14: 26500 | T14: 5000 | U14: 7000 | V14: 5000 | W14: 500 | X14: 1000 | Y14: 5500 | Z14: 70.054839 | AA14: 89.451613 | AB14: 3500 | AC14: 1300 | AD14: 2900 | AE14: 8000 | AF14: 2020.8603 | AG14: 800 | AH14: 7200 | AI14: 3499.8768 | AJ14: 2043.2745 | AK14: 1999.5303 | AL14: 1000 | AM14: 11007.047 | AN14: 1519.5448 | AO14: 3999.6742 | AP14: 9000.0571 | AQ14: 8000 | AR14: 3500 | AS14: 726.81516 | AT14: 3018.0416 | AU14: 2044.9997 | AV14: 369.61071 | AW14: 5000 | AX14: 1121.9003 | AY14: 1800 | AZ14: 2499.7026 | BA14: 0 | BB14: 0 | BC14: 0
B15: =B14+1 -> 46120 | C15: =TEXT(B15,"ddd") -> Rab | D15: =SUM(E15:BC15) -> 179511.43 | E15: 1199.5729 | F15: 1500 | G15: 1129.7313 | H15: 3282.5161 | I15: 644.02065 | J15: 0 | K15: 499.97065 | L15: 603.76323 | M15: 673.27548 | N15: 5514.199 | O15: 6600.0623 | P15: 2874.3265 | Q15: 11659.555 | R15: 4800 | S15: 26500 | T15: 5000 | U15: 7000 | V15: 5000 | W15: 500 | X15: 1000 | Y15: 5500 | Z15: 70.054839 | AA15: 89.451613 | AB15: 3500 | AC15: 1300 | AD15: 2900 | AE15: 8000 | AF15: 2020.8603 | AG15: 800 | AH15: 7200 | AI15: 3499.8768 | AJ15: 2043.2745 | AK15: 1999.5303 | AL15: 1000 | AM15: 11007.047 | AN15: 1519.5448 | AO15: 3999.6742 | AP15: 9000.0571 | AQ15: 8000 | AR15: 3500 | AS15: 726.81516 | AT15: 3018.0416 | AU15: 2044.9997 | AV15: 369.61071 | AW15: 5000 | AX15: 1121.9003 | AY15: 1800 | AZ15: 2499.7026 | BA15: 0 | BB15: 0 | BC15: 0
B16: =B15+1 -> 46121 | C16: =TEXT(B16,"ddd") -> Kam | D16: =SUM(E16:BC16) -> 177511.43 | E16: 1199.5729 | F16: 1500 | G16: 1129.7313 | H16: 3282.5161 | I16: 644.02065 | J16: 0 | K16: 499.97065 | L16: 603.76323 | M16: 673.27548 | N16: 5514.199 | O16: 6600.0623 | P16: 2874.3265 | Q16: 11659.555 | R16: 4800 | S16: 26500 | T16: 5000 | U16: 7000 | V16: 5000 | W16: 500 | X16: 1000 | Y16: 5500 | Z16: 70.054839 | AA16: 89.451613 | AB16: 3500 | AC16: 1300 | AD16: 2900 | AE16: 8000 | AF16: 2020.8603 | AG16: 800 | AH16: 7200 | AI16: 3499.8768 | AJ16: 2043.2745 | AK16: 1999.5303 | AL16: 1000 | AM16: 11007.047 | AN16: 1519.5448 | AO16: 3999.6742 | AP16: 9000.0571 | AQ16: 6000 | AR16: 3500 | AS16: 726.81516 | AT16: 3018.0416 | AU16: 2044.9997 | AV16: 369.61071 | AW16: 5000 | AX16: 1121.9003 | AY16: 1800 | AZ16: 2499.7026 | BA16: 0 | BB16: 0 | BC16: 0
B17: =B16+1 -> 46122 | C17: =TEXT(B17,"ddd") -> Jum | D17: =SUM(E17:BC17) -> 177511.43 | E17: 1199.5729 | F17: 1500 | G17: 1129.7313 | H17: 3282.5161 | I17: 644.02065 | J17: 0 | K17: 499.97065 | L17: 603.76323 | M17: 673.27548 | N17: 5514.199 | O17: 6600.0623 | P17: 2874.3265 | Q17: 11659.555 | R17: 4800 | S17: 26500 | T17: 5000 | U17: 7000 | V17: 5000 | W17: 500 | X17: 1000 | Y17: 5500 | Z17: 70.054839 | AA17: 89.451613 | AB17: 3500 | AC17: 1300 | AD17: 2900 | AE17: 8000 | AF17: 2020.8603 | AG17: 800 | AH17: 7200 | AI17: 3499.8768 | AJ17: 2043.2745 | AK17: 1999.5303 | AL17: 1000 | AM17: 11007.047 | AN17: 1519.5448 | AO17: 3999.6742 | AP17: 9000.0571 | AQ17: 6000 | AR17: 3500 | AS17: 726.81516 | AT17: 3018.0416 | AU17: 2044.9997 | AV17: 369.61071 | AW17: 5000 | AX17: 1121.9003 | AY17: 1800 | AZ17: 2499.7026 | BA17: 0 | BB17: 0 | BC17: 0
B18: =B17+1 -> 46123 | C18: =TEXT(B18,"ddd") -> Sab | D18: =SUM(E18:BC18) -> 172545.56 | E18: 733.5729 | F18: 1500 | G18: 1129.7313 | H18: 3282.5161 | I18: 644.02065 | J18: 0 | K18: 499.97065 | L18: 603.76323 | M18: 673.27548 | N18: 4514.199 | O18: 6600.0623 | P18: 2874.3265 | Q18: 11659.555 | R18: 4800 | S18: 26500 | T18: 5000 | U18: 7000 | V18: 5000 | W18: 500 | X18: 1000 | Y18: 5500 | Z18: 70.054839 | AA18: 89.451613 | AB18: 3500 | AC18: 1300 | AD18: 2900 | AE18: 8000 | AF18: 2020.8603 | AG18: 800 | AH18: 7200 | AI18: 0 | AJ18: 2043.2745 | AK18: 1999.5303 | AL18: 1000 | AM18: 11007.047 | AN18: 1519.5448 | AO18: 3999.6742 | AP18: 9000.0571 | AQ18: 6000 | AR18: 3500 | AS18: 726.81516 | AT18: 3018.0416 | AU18: 2044.9997 | AV18: 369.61071 | AW18: 5000 | AX18: 1121.9003 | AY18: 1800 | AZ18: 2499.7026 | BA18: 0 | BB18: 0 | BC18: 0
B19: =B18+1 -> 46124 | C19: =TEXT(B19,"ddd") -> Mgg | D19: =SUM(E19:BC19) -> 162152.01 | E19: 733.5729 | F19: 1000 | G19: 1129.7313 | H19: 999.51613 | I19: 644.02065 | J19: 0 | K19: 0 | L19: 603.76323 | M19: 673.27548 | N19: 0 | O19: 6600.0623 | P19: 300 | Q19: 6659.5545 | R19: 4800 | S19: 48000 | T19: 5000 | U19: 7000 | V19: 5000 | W19: 500 | X19: 0 | Y19: 2500 | Z19: 70.054839 | AA19: 89.451613 | AB19: 1000 | AC19: 1300 | AD19: 0 | AE19: 15000 | AF19: 2020.8603 | AG19: 0 | AH19: 2999.8519 | AI19: 0 | AJ19: 2043.2745 | AK19: 1999.5303 | AL19: 0 | AM19: 11007.047 | AN19: 1519.5448 | AO19: 3999.6742 | AP19: 6000.0571 | AQ19: 6000 | AR19: 3500 | AS19: 726.81516 | AT19: 3018.0416 | AU19: 2044.9997 | AV19: 369.61071 | AW19: 1000 | AX19: 0 | AY19: 1800 | AZ19: 2499.7026 | BA19: 0 | BB19: 0 | BC19: 0
B20: Sub Total | D20: =SUM(D13:D19) -> 1228254.7 | E20: =SUM(E13:E19) -> 7465.0103 | F20: =SUM(F13:F19) -> 10000 | G20: =SUM(G13:G19) -> 7908.119 | H20: =SUM(H13:H19) -> 20694.613 | I20: =SUM(I13:I19) -> 4508.1445 | J20: =SUM(J13:J19) -> 0 | K20: =SUM(K13:K19) -> 2999.8239 | ... BC20: =SUM(BC13:BC19) -> 0
A22: =WEEKNUM(B22) -> 16 | B22: =B19+1 -> 46125 | C22: =TEXT(B22,"ddd") -> Sen | D22: =SUM(E22:BC22) -> 175637.11 | E22: 1199.5729 | F22: 1500 | G22: 1129.7313 | H22: 3282.5161 | I22: 644.02065 | J22: 0 | K22: 499.97065 | L22: 603.76323 | M22: 673.27548 | N22: 5514.199 | O22: 6600.0623 | P22: 500 | Q22: 11659.555 | R22: 4800 | S22: 26500 | T22: 5000 | U22: 7000 | V22: 5000 | W22: 500 | X22: 1000 | Y22: 5500 | Z22: 70.054839 | AA22: 89.451613 | AB22: 3500 | AC22: 1300 | AD22: 2900 | AE22: 8000 | AF22: 2020.8603 | AG22: 800 | AH22: 7200 | AI22: 3499.8768 | AJ22: 2043.2745 | AK22: 1999.5303 | AL22: 1000 | AM22: 11007.047 | AN22: 1519.5448 | AO22: 3999.6742 | AP22: 9000.0571 | AQ22: 6500 | AR22: 3500 | AS22: 726.81516 | AT22: 3018.0416 | AU22: 2044.9997 | AV22: 369.61071 | AW22: 5000 | AX22: 1121.9003 | AY22: 1800 | AZ22: 2499.7026 | BA22: 0 | BB22: 0 | BC22: 0
B23: =B22+1 -> 46126 | C23: =TEXT(B23,"ddd") -> Sel | D23: =SUM(E23:BC23) -> 175637.11 | E23: 1199.5729 | F23: 1500 | G23: 1129.7313 | H23: 3282.5161 | I23: 644.02065 | J23: 0 | K23: 499.97065 | L23: 603.76323 | M23: 673.27548 | N23: 5514.199 | O23: 6600.0623 | P23: 500 | Q23: 11659.555 | R23: 4800 | S23: 26500 | T23: 5000 | U23: 7000 | V23: 5000 | W23: 500 | X23: 1000 | Y23: 5500 | Z23: 70.054839 | AA23: 89.451613 | AB23: 3500 | AC23: 1300 | AD23: 2900 | AE23: 8000 | AF23: 2020.8603 | AG23: 800 | AH23: 7200 | AI23: 3499.8768 | AJ23: 2043.2745 | AK23: 1999.5303 | AL23: 1000 | AM23: 11007.047 | AN23: 1519.5448 | AO23: 3999.6742 | AP23: 9000.0571 | AQ23: 6500 | AR23: 3500 | AS23: 726.81516 | AT23: 3018.0416 | AU23: 2044.9997 | AV23: 369.61071 | AW23: 5000 | AX23: 1121.9003 | AY23: 1800 | AZ23: 2499.7026 | BA23: 0 | BB23: 0 | BC23: 0
B24: =B23+1 -> 46127 | C24: =TEXT(B24,"ddd") -> Rab | D24: =SUM(E24:BC24) -> 177037.05 | E24: 1199.5729 | F24: 1500 | G24: 1129.7313 | H24: 3282.5161 | I24: 644.02065 | J24: 0 | K24: 499.97065 | L24: 603.76323 | M24: 673.27548 | N24: 5514.199 | O24: 8000 | P24: 500 | Q24: 11659.555 | R24: 4800 | S24: 26500 | T24: 5000 | U24: 7000 | V24: 5000 | W24: 500 | X24: 1000 | Y24: 5500 | Z24: 70.054839 | AA24: 89.451613 | AB24: 3500 | AC24: 1300 | AD24: 2900 | AE24: 8000 | AF24: 2020.8603 | AG24: 800 | AH24: 7200 | AI24: 3499.8768 | AJ24: 2043.2745 | AK24: 1999.5303 | AL24: 1000 | AM24: 11007.047 | AN24: 1519.5448 | AO24: 3999.6742 | AP24: 9000.0571 | AQ24: 6500 | AR24: 3500 | AS24: 726.81516 | AT24: 3018.0416 | AU24: 2044.9997 | AV24: 369.61071 | AW24: 5000 | AX24: 1121.9003 | AY24: 1800 | AZ24: 2499.7026 | BA24: 0 | BB24: 0 | BC24: 0
B25: =B24+1 -> 46128 | C25: =TEXT(B25,"ddd") -> Kam | D25: =SUM(E25:BC25) -> 174037.05 | E25: 1199.5729 | F25: 1500 | G25: 1129.7313 | H25: 3282.5161 | I25: 644.02065 | J25: 0 | K25: 499.97065 | L25: 603.76323 | M25: 673.27548 | N25: 5514.199 | O25: 8000 | P25: 500 | Q25: 11659.555 | R25: 4800 | S25: 26500 | T25: 5000 | U25: 7000 | V25: 5000 | W25: 500 | X25: 1000 | Y25: 5500 | Z25: 70.054839 | AA25: 89.451613 | AB25: 3500 | AC25: 1300 | AD25: 2900 | AE25: 5000 | AF25: 2020.8603 | AG25: 800 | AH25: 7200 | AI25: 3499.8768 | AJ25: 2043.2745 | AK25: 1999.5303 | AL25: 1000 | AM25: 11007.047 | AN25: 1519.5448 | AO25: 3999.6742 | AP25: 9000.0571 | AQ25: 6500 | AR25: 3500 | AS25: 726.81516 | AT25: 3018.0416 | AU25: 2044.9997 | AV25: 369.61071 | AW25: 5000 | AX25: 1121.9003 | AY25: 1800 | AZ25: 2499.7026 | BA25: 0 | BB25: 0 | BC25: 0
B26: =B25+1 -> 46129 | C26: =TEXT(B26,"ddd") -> Jum | D26: =SUM(E26:BC26) -> 174037.05 | E26: 1199.5729 | F26: 1500 | G26: 1129.7313 | H26: 3282.5161 | I26: 644.02065 | J26: 0 | K26: 499.97065 | L26: 603.76323 | M26: 673.27548 | N26: 5514.199 | O26: 8000 | P26: 500 | Q26: 11659.555 | R26: 4800 | S26: 26500 | T26: 5000 | U26: 7000 | V26: 5000 | W26: 500 | X26: 1000 | Y26: 5500 | Z26: 70.054839 | AA26: 89.451613 | AB26: 3500 | AC26: 1300 | AD26: 2900 | AE26: 5000 | AF26: 2020.8603 | AG26: 800 | AH26: 7200 | AI26: 3499.8768 | AJ26: 2043.2745 | AK26: 1999.5303 | AL26: 1000 | AM26: 11007.047 | AN26: 1519.5448 | AO26: 3999.6742 | AP26: 9000.0571 | AQ26: 6500 | AR26: 3500 | AS26: 726.81516 | AT26: 3018.0416 | AU26: 2044.9997 | AV26: 369.61071 | AW26: 5000 | AX26: 1121.9003 | AY26: 1800 | AZ26: 2499.7026 | BA26: 0 | BB26: 0 | BC26: 0
B27: =B26+1 -> 46130 | C27: =TEXT(B27,"ddd") -> Sab | D27: =SUM(E27:BC27) -> 160321.17 | E27: 733.5729 | F27: 1500 | G27: 1129.7313 | H27: 3282.5161 | I27: 644.02065 | J27: 0 | K27: 499.97065 | L27: 603.76323 | M27: 673.27548 | N27: 4514.199 | O27: 8000 | P27: 250 | Q27: 11659.555 | R27: 4800 | S27: 26500 | T27: 5000 | U27: 0 | V27: 5000 | W27: 500 | X27: 1000 | Y27: 5500 | Z27: 70.054839 | AA27: 89.451613 | AB27: 3500 | AC27: 1300 | AD27: 2900 | AE27: 5000 | AF27: 2020.8603 | AG27: 800 | AH27: 7200 | AI27: 0 | AJ27: 2043.2745 | AK27: 1999.5303 | AL27: 1000 | AM27: 11007.047 | AN27: 1519.5448 | AO27: 3999.6742 | AP27: 9000.0571 | AQ27: 5000 | AR27: 3500 | AS27: 726.81516 | AT27: 3018.0416 | AU27: 2044.9997 | AV27: 369.61071 | AW27: 5000 | AX27: 1121.9003 | AY27: 1800 | AZ27: 2499.7026 | BA27: 0 | BB27: 0 | BC27: 0
B28: =B27+1 -> 46131 | C28: =TEXT(B28,"ddd") -> Mgg | D28: =SUM(E28:BC28) -> 145501.95 | E28: 733.5729 | F28: 1000 | G28: 1129.7313 | H28: 999.51613 | I28: 644.02065 | J28: 0 | K28: 0 | L28: 603.76323 | M28: 673.27548 | N28: 0 | O28: 8000 | P28: 250 | Q28: 6659.5545 | R28: 4800 | S28: 48000 | T28: 5000 | U28: 0 | V28: 5000 | W28: 500 | X28: 0 | Y28: 2500 | Z28: 70.054839 | AA28: 89.451613 | AB28: 1000 | AC28: 1300 | AD28: 0 | AE28: 5000 | AF28: 2020.8603 | AG28: 0 | AH28: 2999.8519 | AI28: 0 | AJ28: 2043.2745 | AK28: 1999.5303 | AL28: 0 | AM28: 11007.047 | AN28: 1519.5448 | AO28: 3999.6742 | AP28: 6000.0571 | AQ28: 5000 | AR28: 3500 | AS28: 726.81516 | AT28: 3018.0416 | AU28: 2044.9997 | AV28: 369.61071 | AW28: 1000 | AX28: 0 | AY28: 1800 | AZ28: 2499.7026 | BA28: 0 | BB28: 0 | BC28: 0
B29: Sub Total | D29: =SUM(D22:D28) -> 1182208.5 | E29: =SUM(E22:E28) -> 7465.0103 | F29: =SUM(F22:F28) -> 10000 | G29: =SUM(G22:G28) -> 7908.119 | H29: =SUM(H22:H28) -> 20694.613 | I29: =SUM(I22:I28) -> 4508.1445 | J29: =SUM(J22:J28) -> 0 | K29: =SUM(K22:K28) -> 2999.8239 | ... BC29: =SUM(BC22:BC28) -> 0
A31: =WEEKNUM(B31) -> 17 | B31: =B28+1 -> 46132 | C31: =TEXT(B31,"ddd") -> Sen | D31: =SUM(E31:BC31) -> 174037.05 | E31: 1199.5729 | F31: 1500 | G31: 1129.7313 | H31: 3282.5161 | I31: 644.02065 | J31: 0 | K31: 499.97065 | L31: 603.76323 | M31: 673.27548 | N31: 5514.199 | O31: 8000 | P31: 500 | Q31: 11659.555 | R31: 4800 | S31: 26500 | T31: 5000 | U31: 7000 | V31: 5000 | W31: 500 | X31: 1000 | Y31: 5500 | Z31: 70.054839 | AA31: 89.451613 | AB31: 3500 | AC31: 1300 | AD31: 2900 | AE31: 5000 | AF31: 2020.8603 | AG31: 800 | AH31: 7200 | AI31: 3499.8768 | AJ31: 2043.2745 | AK31: 1999.5303 | AL31: 1000 | AM31: 11007.047 | AN31: 1519.5448 | AO31: 3999.6742 | AP31: 9000.0571 | AQ31: 6500 | AR31: 3500 | AS31: 726.81516 | AT31: 3018.0416 | AU31: 2044.9997 | AV31: 369.61071 | AW31: 5000 | AX31: 1121.9003 | AY31: 1800 | AZ31: 2499.7026 | BA31: 0 | BB31: 0 | BC31: 0
B32: =B31+1 -> 46133 | C32: =TEXT(B32,"ddd") -> Sel | D32: =SUM(E32:BC32) -> 174037.05 | E32: 1199.5729 | F32: 1500 | G32: 1129.7313 | H32: 3282.5161 | I32: 644.02065 | J32: 0 | K32: 499.97065 | L32: 603.76323 | M32: 673.27548 | N32: 5514.199 | O32: 8000 | P32: 500 | Q32: 11659.555 | R32: 4800 | S32: 26500 | T32: 5000 | U32: 7000 | V32: 5000 | W32: 500 | X32: 1000 | Y32: 5500 | Z32: 70.054839 | AA32: 89.451613 | AB32: 3500 | AC32: 1300 | AD32: 2900 | AE32: 5000 | AF32: 2020.8603 | AG32: 800 | AH32: 7200 | AI32: 3499.8768 | AJ32: 2043.2745 | AK32: 1999.5303 | AL32: 1000 | AM32: 11007.047 | AN32: 1519.5448 | AO32: 3999.6742 | AP32: 9000.0571 | AQ32: 6500 | AR32: 3500 | AS32: 726.81516 | AT32: 3018.0416 | AU32: 2044.9997 | AV32: 369.61071 | AW32: 5000 | AX32: 1121.9003 | AY32: 1800 | AZ32: 2499.7026 | BA32: 0 | BB32: 0 | BC32: 0
B33: =B32+1 -> 46134 | C33: =TEXT(B33,"ddd") -> Rab | D33: =SUM(E33:BC33) -> 174037.05 | E33: 1199.5729 | F33: 1500 | G33: 1129.7313 | H33: 3282.5161 | I33: 644.02065 | J33: 0 | K33: 499.97065 | L33: 603.76323 | M33: 673.27548 | N33: 5514.199 | O33: 8000 | P33: 500 | Q33: 11659.555 | R33: 4800 | S33: 26500 | T33: 5000 | U33: 7000 | V33: 5000 | W33: 500 | X33: 1000 | Y33: 5500 | Z33: 70.054839 | AA33: 89.451613 | AB33: 3500 | AC33: 1300 | AD33: 2900 | AE33: 5000 | AF33: 2020.8603 | AG33: 800 | AH33: 7200 | AI33: 3499.8768 | AJ33: 2043.2745 | AK33: 1999.5303 | AL33: 1000 | AM33: 11007.047 | AN33: 1519.5448 | AO33: 3999.6742 | AP33: 9000.0571 | AQ33: 6500 | AR33: 3500 | AS33: 726.81516 | AT33: 3018.0416 | AU33: 2044.9997 | AV33: 369.61071 | AW33: 5000 | AX33: 1121.9003 | AY33: 1800 | AZ33: 2499.7026 | BA33: 0 | BB33: 0 | BC33: 0
B34: =B33+1 -> 46135 | C34: =TEXT(B34,"ddd") -> Kam | D34: =SUM(E34:BC34) -> 174037.05 | E34: 1199.5729 | F34: 1500 | G34: 1129.7313 | H34: 3282.5161 | I34: 644.02065 | J34: 0 | K34: 499.97065 | L34: 603.76323 | M34: 673.27548 | N34: 5514.199 | O34: 8000 | P34: 500 | Q34: 11659.555 | R34: 4800 | S34: 26500 | T34: 5000 | U34: 7000 | V34: 5000 | W34: 500 | X34: 1000 | Y34: 5500 | Z34: 70.054839 | AA34: 89.451613 | AB34: 3500 | AC34: 1300 | AD34: 2900 | AE34: 5000 | AF34: 2020.8603 | AG34: 800 | AH34: 7200 | AI34: 3499.8768 | AJ34: 2043.2745 | AK34: 1999.5303 | AL34: 1000 | AM34: 11007.047 | AN34: 1519.5448 | AO34: 3999.6742 | AP34: 9000.0571 | AQ34: 6500 | AR34: 3500 | AS34: 726.81516 | AT34: 3018.0416 | AU34: 2044.9997 | AV34: 369.61071 | AW34: 5000 | AX34: 1121.9003 | AY34: 1800 | AZ34: 2499.7026 | BA34: 0 | BB34: 0 | BC34: 0
B35: =B34+1 -> 46136 | C35: =TEXT(B35,"ddd") -> Jum | D35: =SUM(E35:BC35) -> 174037.05 | E35: 1199.5729 | F35: 1500 | G35: 1129.7313 | H35: 3282.5161 | I35: 644.02065 | J35: 0 | K35: 499.97065 | L35: 603.76323 | M35: 673.27548 | N35: 5514.199 | O35: 8000 | P35: 500 | Q35: 11659.555 | R35: 4800 | S35: 26500 | T35: 5000 | U35: 7000 | V35: 5000 | W35: 500 | X35: 1000 | Y35: 5500 | Z35: 70.054839 | AA35: 89.451613 | AB35: 3500 | AC35: 1300 | AD35: 2900 | AE35: 5000 | AF35: 2020.8603 | AG35: 800 | AH35: 7200 | AI35: 3499.8768 | AJ35: 2043.2745 | AK35: 1999.5303 | AL35: 1000 | AM35: 11007.047 | AN35: 1519.5448 | AO35: 3999.6742 | AP35: 9000.0571 | AQ35: 6500 | AR35: 3500 | AS35: 726.81516 | AT35: 3018.0416 | AU35: 2044.9997 | AV35: 369.61071 | AW35: 5000 | AX35: 1121.9003 | AY35: 1800 | AZ35: 2499.7026 | BA35: 0 | BB35: 0 | BC35: 0
B36: =B35+1 -> 46137 | C36: =TEXT(B36,"ddd") -> Sab | D36: =SUM(E36:BC36) -> 160321.17 | E36: 733.5729 | F36: 1500 | G36: 1129.7313 | H36: 3282.5161 | I36: 644.02065 | J36: 0 | K36: 499.97065 | L36: 603.76323 | M36: 673.27548 | N36: 4514.199 | O36: 8000 | P36: 250 | Q36: 11659.555 | R36: 4800 | S36: 26500 | T36: 5000 | U36: 0 | V36: 5000 | W36: 500 | X36: 1000 | Y36: 5500 | Z36: 70.054839 | AA36: 89.451613 | AB36: 3500 | AC36: 1300 | AD36: 2900 | AE36: 5000 | AF36: 2020.8603 | AG36: 800 | AH36: 7200 | AI36: 0 | AJ36: 2043.2745 | AK36: 1999.5303 | AL36: 1000 | AM36: 11007.047 | AN36: 1519.5448 | AO36: 3999.6742 | AP36: 9000.0571 | AQ36: 5000 | AR36: 3500 | AS36: 726.81516 | AT36: 3018.0416 | AU36: 2044.9997 | AV36: 369.61071 | AW36: 5000 | AX36: 1121.9003 | AY36: 1800 | AZ36: 2499.7026 | BA36: 0 | BB36: 0 | BC36: 0
B37: =B36+1 -> 46138 | C37: =TEXT(B37,"ddd") -> Mgg | D37: =SUM(E37:BC37) -> 145501.95 | E37: 733.5729 | F37: 1000 | G37: 1129.7313 | H37: 999.51613 | I37: 644.02065 | J37: 0 | K37: 0 | L37: 603.76323 | M37: 673.27548 | N37: 0 | O37: 8000 | P37: 250 | Q37: 6659.5545 | R37: 4800 | S37: 48000 | T37: 5000 | U37: 0 | V37: 5000 | W37: 500 | X37: 0 | Y37: 2500 | Z37: 70.054839 | AA37: 89.451613 | AB37: 1000 | AC37: 1300 | AD37: 0 | AE37: 5000 | AF37: 2020.8603 | AG37: 0 | AH37: 2999.8519 | AI37: 0 | AJ37: 2043.2745 | AK37: 1999.5303 | AL37: 0 | AM37: 11007.047 | AN37: 1519.5448 | AO37: 3999.6742 | AP37: 6000.0571 | AQ37: 5000 | AR37: 3500 | AS37: 726.81516 | AT37: 3018.0416 | AU37: 2044.9997 | AV37: 369.61071 | AW37: 1000 | AX37: 0 | AY37: 1800 | AZ37: 2499.7026 | BA37: 0 | BB37: 0 | BC37: 0
B38: Sub Total | D38: =SUM(D31:D37) -> 1176008.3 | E38: =SUM(E31:E37) -> 7465.0103 | F38: =SUM(F31:F37) -> 10000 | G38: =SUM(G31:G37) -> 7908.119 | H38: =SUM(H31:H37) -> 20694.613 | I38: =SUM(I31:I37) -> 4508.1445 | J38: =SUM(J31:J37) -> 0 | K38: =SUM(K31:K37) -> 2999.8239 | ... BC38: =SUM(BC31:BC37) -> 0
A40: =WEEKNUM(B40) -> 18 | B40: =B37+1 -> 46139 | C40: =TEXT(B40,"ddd") -> Sen | D40: =SUM(E40:BC40) -> 178537.05 | E40: 1199.5729 | F40: 1500 | G40: 1129.7313 | H40: 3282.5161 | I40: 644.02065 | J40: 0 | K40: 499.97065 | L40: 603.76323 | M40: 673.27548 | N40: 5514.199 | O40: 8000 | P40: 500 | Q40: 11659.555 | R40: 4800 | S40: 26500 | T40: 5000 | U40: 7000 | V40: 5000 | W40: 500 | X40: 1000 | Y40: 5500 | Z40: 70.054839 | AA40: 89.451613 | AB40: 3500 | AC40: 1300 | AD40: 2900 | AE40: 5000 | AF40: 2020.8603 | AG40: 800 | AH40: 7200 | AI40: 3499.8768 | AJ40: 2043.2745 | AK40: 1999.5303 | AL40: 1000 | AM40: 11007.047 | AN40: 1519.5448 | AO40: 3999.6742 | AP40: 9000.0571 | AQ40: 6500 | AR40: 3500 | AS40: 726.81516 | AT40: 3018.0416 | AU40: 2044.9997 | AV40: 369.61071 | AW40: 5000 | AX40: 1121.9003 | AY40: 1800 | AZ40: 2499.7026 | BA40: 0 | BB40: 0 | BC40: 4500
B41: =B40+1 -> 46140 | C41: =TEXT(B41,"ddd") -> Sel | D41: =SUM(E41:BC41) -> 178537.05 | E41: 1199.5729 | F41: 1500 | G41: 1129.7313 | H41: 3282.5161 | I41: 644.02065 | J41: 0 | K41: 499.97065 | L41: 603.76323 | M41: 673.27548 | N41: 5514.199 | O41: 8000 | P41: 500 | Q41: 11659.555 | R41: 4800 | S41: 26500 | T41: 5000 | U41: 7000 | V41: 5000 | W41: 500 | X41: 1000 | Y41: 5500 | Z41: 70.054839 | AA41: 89.451613 | AB41: 3500 | AC41: 1300 | AD41: 2900 | AE41: 5000 | AF41: 2020.8603 | AG41: 800 | AH41: 7200 | AI41: 3499.8768 | AJ41: 2043.2745 | AK41: 1999.5303 | AL41: 1000 | AM41: 11007.047 | AN41: 1519.5448 | AO41: 3999.6742 | AP41: 9000.0571 | AQ41: 6500 | AR41: 3500 | AS41: 726.81516 | AT41: 3018.0416 | AU41: 2044.9997 | AV41: 369.61071 | AW41: 5000 | AX41: 1121.9003 | AY41: 1800 | AZ41: 2499.7026 | BA41: 0 | BB41: 0 | BC41: 4500
B42: =B41+1 -> 46141 | C42: =TEXT(B42,"ddd") -> Rab | D42: =SUM(E42:BC42) -> 178537.05 | E42: 1199.5729 | F42: 1500 | G42: 1129.7313 | H42: 3282.5161 | I42: 644.02065 | J42: 0 | K42: 499.97065 | L42: 603.76323 | M42: 673.27548 | N42: 5514.199 | O42: 8000 | P42: 500 | Q42: 11659.555 | R42: 4800 | S42: 26500 | T42: 5000 | U42: 7000 | V42: 5000 | W42: 500 | X42: 1000 | Y42: 5500 | Z42: 70.054839 | AA42: 89.451613 | AB42: 3500 | AC42: 1300 | AD42: 2900 | AE42: 5000 | AF42: 2020.8603 | AG42: 800 | AH42: 7200 | AI42: 3499.8768 | AJ42: 2043.2745 | AK42: 1999.5303 | AL42: 1000 | AM42: 11007.047 | AN42: 1519.5448 | AO42: 3999.6742 | AP42: 9000.0571 | AQ42: 6500 | AR42: 3500 | AS42: 726.81516 | AT42: 3018.0416 | AU42: 2044.9997 | AV42: 369.61071 | AW42: 5000 | AX42: 1121.9003 | AY42: 1800 | AZ42: 2499.7026 | BA42: 0 | BB42: 0 | BC42: 4500
B43: =B42+1 -> 46142 | C43: =TEXT(B43,"ddd") -> Kam | D43: =SUM(E43:BC43) -> 178537.05 | E43: 1199.5729 | F43: 1500 | G43: 1129.7313 | H43: 3282.5161 | I43: 644.02065 | J43: 0 | K43: 499.97065 | L43: 603.76323 | M43: 673.27548 | N43: 5514.199 | O43: 8000 | P43: 500 | Q43: 11659.555 | R43: 4800 | S43: 26500 | T43: 5000 | U43: 7000 | V43: 5000 | W43: 500 | X43: 1000 | Y43: 5500 | Z43: 70.054839 | AA43: 89.451613 | AB43: 3500 | AC43: 1300 | AD43: 2900 | AE43: 5000 | AF43: 2020.8603 | AG43: 800 | AH43: 7200 | AI43: 3499.8768 | AJ43: 2043.2745 | AK43: 1999.5303 | AL43: 1000 | AM43: 11007.047 | AN43: 1519.5448 | AO43: 3999.6742 | AP43: 9000.0571 | AQ43: 6500 | AR43: 3500 | AS43: 726.81516 | AT43: 3018.0416 | AU43: 2044.9997 | AV43: 369.61071 | AW43: 5000 | AX43: 1121.9003 | AY43: 1800 | AZ43: 2499.7026 | BA43: 0 | BB43: 0 | BC43: 4500
B44: Sub Total | D44: =SUM(D40:D43) -> 714148.18 | E44: =SUM(E40:E43) -> 4798.2916 | F44: =SUM(F40:F43) -> 6000 | G44: =SUM(G40:G43) -> 4518.9252 | H44: =SUM(H40:H43) -> 13130.065 | I44: =SUM(I40:I43) -> 2576.0826 | J44: =SUM(J40:J43) -> 0 | K44: =SUM(K40:K43) -> 1999.8826 | ... BC44: =SUM(BC40:BC43) -> 18000
...

Sheet KEBUTUHAN GAS
A1: KEBUTUHAN GAS
A4: ='SO APRIL 2026 Rev2'!A3 -> 46113 | E4: KEBUTUHAN GAS | I4: KUOTA GAS
A5: Week | B5: DATE | D5: SELISIH GAS | E5: JABAR | F5: JATENG | G5: JATIM | H5: TOTAL | I5: MS SETU | J5: MS KHT | K5: MS BLORA | L5: MS BITUNG | M5: MS ZEBRA | N5: MS TAMBAKLOROK | O5: MS WUNUT | P5: MS SADANG | Q5: TOTAL
A6: =WEEKNUM(B6) -> 14 | B6: =A4 -> 46113 | C6: =TEXT(B6,"ddd") -> Rab | D6: =Q6-H6 -> -42689.534 | E6: =SUM('SO APRIL 2026 Rev2'!E6:AR6) -> 169730.36 | F6: =SUM('SO APRIL 2026 Rev2'!AS6:AZ6) -> 16581.07 | G6: =SUM('SO APRIL 2026 Rev2'!BA6:BC6) -> 0 | H6: =SUM(E6:G6) -> 186311.43 | I6: ='SO MS'!E6 -> 84000 | J6: ='SO MS'!F6 -> 33600 | K6: ='SO MS'!G6 -> 9600 | L6: =2*5000 -> 10000 | M6: ='SO APRIL 2026 Rev2'!AY6 -> 1800 | N6: ='SO APRIL 2026 Rev2'!AR6 -> 3500 | O6: ='SO APRIL 2026 Rev2'!AX6 -> 1121.9003 | Q6: =SUM(I6:P6) -> 143621.9
B7: =B6+1 -> 46114 | C7: =TEXT(B7,"ddd") -> Kam | D7: =Q7-H7 -> -42689.534 | E7: =SUM('SO APRIL 2026 Rev2'!E7:AR7) -> 169730.36 | F7: =SUM('SO APRIL 2026 Rev2'!AS7:AZ7) -> 16581.07 | G7: =SUM('SO APRIL 2026 Rev2'!BA7:BC7) -> 0 | H7: =SUM(E7:G7) -> 186311.43 | I7: ='SO MS'!E7 -> 84000 | J7: ='SO MS'!F7 -> 33600 | K7: ='SO MS'!G7 -> 9600 | L7: =2*5000 -> 10000 | M7: ='SO APRIL 2026 Rev2'!AY7 -> 1800 | N7: ='SO APRIL 2026 Rev2'!AR7 -> 3500 | O7: ='SO APRIL 2026 Rev2'!AX7 -> 1121.9003 | Q7: =SUM(I7:P7) -> 143621.9
B8: =B7+1 -> 46115 | C8: =TEXT(B8,"ddd") -> Jum | D8: =Q8-H8 -> -42689.534 | E8: =SUM('SO APRIL 2026 Rev2'!E8:AR8) -> 166230.36 | F8: =SUM('SO APRIL 2026 Rev2'!AS8:AZ8) -> 16581.07 | G8: =SUM('SO APRIL 2026 Rev2'!BA8:BC8) -> 0 | H8: =SUM(E8:G8) -> 182811.43 | I8: ='SO MS'!E8 -> 84000 | J8: ='SO MS'!F8 -> 33600 | K8: ='SO MS'!G8 -> 9600 | L8: =2*5000 -> 10000 | M8: ='SO APRIL 2026 Rev2'!AY8 -> 1800 | N8: ='SO APRIL 2026 Rev2'!AR8 -> 0 | O8: ='SO APRIL 2026 Rev2'!AX8 -> 1121.9003 | Q8: =SUM(I8:P8) -> 140121.9
B9: =B8+1 -> 46116 | C9: =TEXT(B9,"ddd") -> Sab | D9: =Q9-H9 -> -37723.658 | E9: =SUM('SO APRIL 2026 Rev2'!E9:AR9) -> 161264.49 | F9: =SUM('SO APRIL 2026 Rev2'!AS9:AZ9) -> 16581.07 | G9: =SUM('SO APRIL 2026 Rev2'!BA9:BC9) -> 0 | H9: =SUM(E9:G9) -> 177845.56 | I9: ='SO MS'!E9 -> 84000 | J9: ='SO MS'!F9 -> 33600 | K9: ='SO MS'!G9 -> 9600 | L9: =2*5000 -> 10000 | M9: ='SO APRIL 2026 Rev2'!AY9 -> 1800 | N9: ='SO APRIL 2026 Rev2'!AR9 -> 0 | O9: ='SO APRIL 2026 Rev2'!AX9 -> 1121.9003 | Q9: =SUM(I9:P9) -> 140121.9
B10: =B9+1 -> 46117 | C10: =TEXT(B10,"ddd") -> Mgg | D10: =Q10-H10 -> -28452.013 | E10: =SUM('SO APRIL 2026 Rev2'!E10:AR10) -> 155992.84 | F10: =SUM('SO APRIL 2026 Rev2'!AS10:AZ10) -> 11459.17 | G10: =SUM('SO APRIL 2026 Rev2'!BA10:BC10) -> 0 | H10: =SUM(E10:G10) -> 167452.01 | I10: ='SO MS'!E10 -> 84000 | J10: ='SO MS'!F10 -> 33600 | K10: ='SO MS'!G10 -> 9600 | L10: =2*5000 -> 10000 | M10: ='SO APRIL 2026 Rev2'!AY10 -> 1800 | N10: ='SO APRIL 2026 Rev2'!AR10 -> 0 | O10: ='SO APRIL 2026 Rev2'!AX10 -> 0 | Q10: =SUM(I10:P10) -> 139000
B11: Sub Total | D11: =SUM(D6:D10) -> -194244.27 | E11: =SUM(E6:E10) -> 822948.42 | F11: =SUM(F6:F10) -> 77783.45 | G11: =SUM(G6:G10) -> 0 | H11: =SUM(H6:H10) -> 900731.88 | I11: =SUM(I6:I10) -> 420000 | J11: =SUM(J6:J10) -> 168000 | K11: =SUM(K6:K10) -> 48000 | ... O11: =SUM(O6:O10) -> 4487.6013 | Q11: =SUM(Q6:Q10) -> 706487.6
A13: =WEEKNUM(B13) -> 15 | B13: =B10+1 -> 46118 | C13: =TEXT(B13,"ddd") -> Sen | D13: =Q13-H13 -> -35889.534 | E13: =SUM('SO APRIL 2026 Rev2'!E13:AR13) -> 162930.36 | F13: =SUM('SO APRIL 2026 Rev2'!AS13:AZ13) -> 16581.07 | G13: =SUM('SO APRIL 2026 Rev2'!BA13:BC13) -> 0 | H13: =SUM(E13:G13) -> 179511.43 | I13: ='SO MS'!E13 -> 84000 | J13: ='SO MS'!F13 -> 33600 | K13: ='SO MS'!G13 -> 9600 | L13: =2*5000 -> 10000 | M13: ='SO APRIL 2026 Rev2'!AY13 -> 1800 | N13: ='SO APRIL 2026 Rev2'!AR13 -> 3500 | O13: ='SO APRIL 2026 Rev2'!AX13 -> 1121.9003 | Q13: =SUM(I13:P13) -> 143621.9
B14: =B13+1 -> 46119 | C14: =TEXT(B14,"ddd") -> Sel | D14: =Q14-H14 -> -35889.534 | E14: =SUM('SO APRIL 2026 Rev2'!E14:AR14) -> 162930.36 | F14: =SUM('SO APRIL 2026 Rev2'!AS14:AZ14) -> 16581.07 | G14: =SUM('SO APRIL 2026 Rev2'!BA14:BC14) -> 0 | H14: =SUM(E14:G14) -> 179511.43 | I14: ='SO MS'!E14 -> 84000 | J14: ='SO MS'!F14 -> 33600 | K14: ='SO MS'!G14 -> 9600 | L14: =2*5000 -> 10000 | M14: ='SO APRIL 2026 Rev2'!AY14 -> 1800 | N14: ='SO APRIL 2026 Rev2'!AR14 -> 3500 | O14: ='SO APRIL 2026 Rev2'!AX14 -> 1121.9003 | Q14: =SUM(I14:P14) -> 143621.9
B15: =B14+1 -> 46120 | C15: =TEXT(B15,"ddd") -> Rab | D15: =Q15-H15 -> -35889.534 | E15: =SUM('SO APRIL 2026 Rev2'!E15:AR15) -> 162930.36 | F15: =SUM('SO APRIL 2026 Rev2'!AS15:AZ15) -> 16581.07 | G15: =SUM('SO APRIL 2026 Rev2'!BA15:BC15) -> 0 | H15: =SUM(E15:G15) -> 179511.43 | I15: ='SO MS'!E15 -> 84000 | J15: ='SO MS'!F15 -> 33600 | K15: ='SO MS'!G15 -> 9600 | L15: =2*5000 -> 10000 | M15: ='SO APRIL 2026 Rev2'!AY15 -> 1800 | N15: ='SO APRIL 2026 Rev2'!AR15 -> 3500 | O15: ='SO APRIL 2026 Rev2'!AX15 -> 1121.9003 | Q15: =SUM(I15:P15) -> 143621.9
B16: =B15+1 -> 46121 | C16: =TEXT(B16,"ddd") -> Kam | D16: =Q16-H16 -> -33889.534 | E16: =SUM('SO APRIL 2026 Rev2'!E16:AR16) -> 160930.36 | F16: =SUM('SO APRIL 2026 Rev2'!AS16:AZ16) -> 16581.07 | G16: =SUM('SO APRIL 2026 Rev2'!BA16:BC16) -> 0 | H16: =SUM(E16:G16) -> 177511.43 | I16: ='SO MS'!E16 -> 84000 | J16: ='SO MS'!F16 -> 33600 | K16: ='SO MS'!G16 -> 9600 | L16: =2*5000 -> 10000 | M16: ='SO APRIL 2026 Rev2'!AY16 -> 1800 | N16: ='SO APRIL 2026 Rev2'!AR16 -> 3500 | O16: ='SO APRIL 2026 Rev2'!AX16 -> 1121.9003 | Q16: =SUM(I16:P16) -> 143621.9
B17: =B16+1 -> 46122 | C17: =TEXT(B17,"ddd") -> Jum | D17: =Q17-H17 -> -33889.534 | E17: =SUM('SO APRIL 2026 Rev2'!E17:AR17) -> 160930.36 | F17: =SUM('SO APRIL 2026 Rev2'!AS17:AZ17) -> 16581.07 | G17: =SUM('SO APRIL 2026 Rev2'!BA17:BC17) -> 0 | H17: =SUM(E17:G17) -> 177511.43 | I17: ='SO MS'!E17 -> 84000 | J17: ='SO MS'!F17 -> 33600 | K17: ='SO MS'!G17 -> 9600 | L17: =2*5000 -> 10000 | M17: ='SO APRIL 2026 Rev2'!AY17 -> 1800 | N17: ='SO APRIL 2026 Rev2'!AR17 -> 3500 | O17: ='SO APRIL 2026 Rev2'!AX17 -> 1121.9003 | Q17: =SUM(I17:P17) -> 143621.9
B18: =B17+1 -> 46123 | C18: =TEXT(B18,"ddd") -> Sab | D18: =Q18-H18 -> -28923.658 | E18: =SUM('SO APRIL 2026 Rev2'!E18:AR18) -> 155964.49 | F18: =SUM('SO APRIL 2026 Rev2'!AS18:AZ18) -> 16581.07 | G18: =SUM('SO APRIL 2026 Rev2'!BA18:BC18) -> 0 | H18: =SUM(E18:G18) -> 172545.56 | I18: ='SO MS'!E18 -> 84000 | J18: ='SO MS'!F18 -> 33600 | K18: ='SO MS'!G18 -> 9600 | L18: =2*5000 -> 10000 | M18: ='SO APRIL 2026 Rev2'!AY18 -> 1800 | N18: ='SO APRIL 2026 Rev2'!AR18 -> 3500 | O18: ='SO APRIL 2026 Rev2'!AX18 -> 1121.9003 | Q18: =SUM(I18:P18) -> 143621.9
B19: =B18+1 -> 46124 | C19: =TEXT(B19,"ddd") -> Mgg | D19: =Q19-H19 -> -19652.013 | E19: =SUM('SO APRIL 2026 Rev2'!E19:AR19) -> 150692.84 | F19: =SUM('SO APRIL 2026 Rev2'!AS19:AZ19) -> 11459.17 | G19: =SUM('SO APRIL 2026 Rev2'!BA19:BC19) -> 0 | H19: =SUM(E19:G19) -> 162152.01 | I19: ='SO MS'!E19 -> 84000 | J19: ='SO MS'!F19 -> 33600 | K19: ='SO MS'!G19 -> 9600 | L19: =2*5000 -> 10000 | M19: ='SO APRIL 2026 Rev2'!AY19 -> 1800 | N19: ='SO APRIL 2026 Rev2'!AR19 -> 3500 | O19: ='SO APRIL 2026 Rev2'!AX19 -> 0 | Q19: =SUM(I19:P19) -> 142500
B20: Sub Total | D20: =SUM(D13:D19) -> -224023.34 | E20: =SUM(E13:E19) -> 1117309.2 | F20: =SUM(F13:F19) -> 110945.59 | G20: =SUM(G13:G19) -> 0 | H20: =SUM(H13:H19) -> 1228254.7 | I20: =SUM(I13:I19) -> 588000 | J20: =SUM(J13:J19) -> 235200 | K20: =SUM(K13:K19) -> 67200 | ... O20: =SUM(O13:O19) -> 6731.4019 | Q20: =SUM(Q13:Q19) -> 1004231.4
A22: =WEEKNUM(B22) -> 16 | B22: =B19+1 -> 46125 | C22: =TEXT(B22,"ddd") -> Sen | D22: =Q22-H22 -> -32015.208 | E22: =SUM('SO APRIL 2026 Rev2'!E22:AR22) -> 159056.04 | F22: =SUM('SO APRIL 2026 Rev2'!AS22:AZ22) -> 16581.07 | G22: =SUM('SO APRIL 2026 Rev2'!BA22:BC22) -> 0 | H22: =SUM(E22:G22) -> 175637.11 | I22: ='SO MS'!E22 -> 84000 | J22: ='SO MS'!F22 -> 33600 | K22: ='SO MS'!G22 -> 9600 | L22: =2*5000 -> 10000 | M22: ='SO APRIL 2026 Rev2'!AY22 -> 1800 | N22: ='SO APRIL 2026 Rev2'!AR22 -> 3500 | O22: ='SO APRIL 2026 Rev2'!AX22 -> 1121.9003 | Q22: =SUM(I22:P22) -> 143621.9
B23: =B22+1 -> 46126 | C23: =TEXT(B23,"ddd") -> Sel | D23: =Q23-H23 -> -32015.208 | E23: =SUM('SO APRIL 2026 Rev2'!E23:AR23) -> 159056.04 | F23: =SUM('SO APRIL 2026 Rev2'!AS23:AZ23) -> 16581.07 | G23: =SUM('SO APRIL 2026 Rev2'!BA23:BC23) -> 0 | H23: =SUM(E23:G23) -> 175637.11 | I23: ='SO MS'!E23 -> 84000 | J23: ='SO MS'!F23 -> 33600 | K23: ='SO MS'!G23 -> 9600 | L23: =2*5000 -> 10000 | M23: ='SO APRIL 2026 Rev2'!AY23 -> 1800 | N23: ='SO APRIL 2026 Rev2'!AR23 -> 3500 | O23: ='SO APRIL 2026 Rev2'!AX23 -> 1121.9003 | Q23: =SUM(I23:P23) -> 143621.9
B24: =B23+1 -> 46127 | C24: =TEXT(B24,"ddd") -> Rab | D24: =Q24-H24 -> -33415.146 | E24: =SUM('SO APRIL 2026 Rev2'!E24:AR24) -> 160455.98 | F24: =SUM('SO APRIL 2026 Rev2'!AS24:AZ24) -> 16581.07 | G24: =SUM('SO APRIL 2026 Rev2'!BA24:BC24) -> 0 | H24: =SUM(E24:G24) -> 177037.05 | I24: ='SO MS'!E24 -> 84000 | J24: ='SO MS'!F24 -> 33600 | K24: ='SO MS'!G24 -> 9600 | L24: =2*5000 -> 10000 | M24: ='SO APRIL 2026 Rev2'!AY24 -> 1800 | N24: ='SO APRIL 2026 Rev2'!AR24 -> 3500 | O24: ='SO APRIL 2026 Rev2'!AX24 -> 1121.9003 | Q24: =SUM(I24:P24) -> 143621.9
B25: =B24+1 -> 46128 | C25: =TEXT(B25,"ddd") -> Kam | D25: =Q25-H25 -> -30415.146 | E25: =SUM('SO APRIL 2026 Rev2'!E25:AR25) -> 157455.98 | F25: =SUM('SO APRIL 2026 Rev2'!AS25:AZ25) -> 16581.07 | G25: =SUM('SO APRIL 2026 Rev2'!BA25:BC25) -> 0 | H25: =SUM(E25:G25) -> 174037.05 | I25: ='SO MS'!E25 -> 84000 | J25: ='SO MS'!F25 -> 33600 | K25: ='SO MS'!G25 -> 9600 | L25: =2*5000 -> 10000 | M25: ='SO APRIL 2026 Rev2'!AY25 -> 1800 | N25: ='SO APRIL 2026 Rev2'!AR25 -> 3500 | O25: ='SO APRIL 2026 Rev2'!AX25 -> 1121.9003 | Q25: =SUM(I25:P25) -> 143621.9
B26: =B25+1 -> 46129 | C26: =TEXT(B26,"ddd") -> Jum | D26: =Q26-H26 -> -30415.146 | E26: =SUM('SO APRIL 2026 Rev2'!E26:AR26) -> 157455.98 | F26: =SUM('SO APRIL 2026 Rev2'!AS26:AZ26) -> 16581.07 | G26: =SUM('SO APRIL 2026 Rev2'!BA26:BC26) -> 0 | H26: =SUM(E26:G26) -> 174037.05 | I26: ='SO MS'!E26 -> 84000 | J26: ='SO MS'!F26 -> 33600 | K26: ='SO MS'!G26 -> 9600 | L26: =2*5000 -> 10000 | M26: ='SO APRIL 2026 Rev2'!AY26 -> 1800 | N26: ='SO APRIL 2026 Rev2'!AR26 -> 3500 | O26: ='SO APRIL 2026 Rev2'!AX26 -> 1121.9003 | Q26: =SUM(I26:P26) -> 143621.9
B27: =B26+1 -> 46130 | C27: =TEXT(B27,"ddd") -> Sab | D27: =Q27-H27 -> -16699.269 | E27: =SUM('SO APRIL 2026 Rev2'!E27:AR27) -> 143740.1 | F27: =SUM('SO APRIL 2026 Rev2'!AS27:AZ27) -> 16581.07 | G27: =SUM('SO APRIL 2026 Rev2'!BA27:BC27) -> 0 | H27: =SUM(E27:G27) -> 160321.17 | I27: ='SO MS'!E27 -> 84000 | J27: ='SO MS'!F27 -> 33600 | K27: ='SO MS'!G27 -> 9600 | L27: =2*5000 -> 10000 | M27: ='SO APRIL 2026 Rev2'!AY27 -> 1800 | N27: ='SO APRIL 2026 Rev2'!AR27 -> 3500 | O27: ='SO APRIL 2026 Rev2'!AX27 -> 1121.9003 | Q27: =SUM(I27:P27) -> 143621.9
B28: =B27+1 -> 46131 | C28: =TEXT(B28,"ddd") -> Mgg | D28: =Q28-H28 -> -3001.9511 | E28: =SUM('SO APRIL 2026 Rev2'!E28:AR28) -> 134042.78 | F28: =SUM('SO APRIL 2026 Rev2'!AS28:AZ28) -> 11459.17 | G28: =SUM('SO APRIL 2026 Rev2'!BA28:BC28) -> 0 | H28: =SUM(E28:G28) -> 145501.95 | I28: ='SO MS'!E28 -> 84000 | J28: ='SO MS'!F28 -> 33600 | K28: ='SO MS'!G28 -> 9600 | L28: =2*5000 -> 10000 | M28: ='SO APRIL 2026 Rev2'!AY28 -> 1800 | N28: ='SO APRIL 2026 Rev2'!AR28 -> 3500 | O28: ='SO APRIL 2026 Rev2'!AX28 -> 0 | Q28: =SUM(I28:P28) -> 142500
B29: Sub Total | D29: =SUM(D22:D28) -> -177977.07 | E29: =SUM(E22:E28) -> 1071262.9 | F29: =SUM(F22:F28) -> 110945.59 | G29: =SUM(G22:G28) -> 0 | H29: =SUM(H22:H28) -> 1182208.5 | I29: =SUM(I22:I28) -> 588000 | J29: =SUM(J22:J28) -> 235200 | K29: =SUM(K22:K28) -> 67200 | ... O29: =SUM(O22:O28) -> 6731.4019 | Q29: =SUM(Q22:Q28) -> 1004231.4
A31: =WEEKNUM(B31) -> 17 | B31: =B28+1 -> 46132 | C31: =TEXT(B31,"ddd") -> Sen | D31: =Q31-H31 -> -30415.146 | E31: =SUM('SO APRIL 2026 Rev2'!E31:AR31) -> 157455.98 | F31: =SUM('SO APRIL 2026 Rev2'!AS31:AZ31) -> 16581.07 | G31: =SUM('SO APRIL 2026 Rev2'!BA31:BC31) -> 0 | H31: =SUM(E31:G31) -> 174037.05 | I31: ='SO MS'!E31 -> 84000 | J31: ='SO MS'!F31 -> 33600 | K31: ='SO MS'!G31 -> 9600 | L31: =2*5000 -> 10000 | M31: ='SO APRIL 2026 Rev2'!AY31 -> 1800 | N31: ='SO APRIL 2026 Rev2'!AR31 -> 3500 | O31: ='SO APRIL 2026 Rev2'!AX31 -> 1121.9003 | Q31: =SUM(I31:P31) -> 143621.9
B32: =B31+1 -> 46133 | C32: =TEXT(B32,"ddd") -> Sel | D32: =Q32-H32 -> -30415.146 | E32: =SUM('SO APRIL 2026 Rev2'!E32:AR32) -> 157455.98 | F32: =SUM('SO APRIL 2026 Rev2'!AS32:AZ32) -> 16581.07 | G32: =SUM('SO APRIL 2026 Rev2'!BA32:BC32) -> 0 | H32: =SUM(E32:G32) -> 174037.05 | I32: ='SO MS'!E32 -> 84000 | J32: ='SO MS'!F32 -> 33600 | K32: ='SO MS'!G32 -> 9600 | L32: =2*5000 -> 10000 | M32: ='SO APRIL 2026 Rev2'!AY32 -> 1800 | N32: ='SO APRIL 2026 Rev2'!AR32 -> 3500 | O32: ='SO APRIL 2026 Rev2'!AX32 -> 1121.9003 | Q32: =SUM(I32:P32) -> 143621.9
B33: =B32+1 -> 46134 | C33: =TEXT(B33,"ddd") -> Rab | D33: =Q33-H33 -> -30415.146 | E33: =SUM('SO APRIL 2026 Rev2'!E33:AR33) -> 157455.98 | F33: =SUM('SO APRIL 2026 Rev2'!AS33:AZ33) -> 16581.07 | G33: =SUM('SO APRIL 2026 Rev2'!BA33:BC33) -> 0 | H33: =SUM(E33:G33) -> 174037.05 | I33: ='SO MS'!E33 -> 84000 | J33: ='SO MS'!F33 -> 33600 | K33: ='SO MS'!G33 -> 9600 | L33: =2*5000 -> 10000 | M33: ='SO APRIL 2026 Rev2'!AY33 -> 1800 | N33: ='SO APRIL 2026 Rev2'!AR33 -> 3500 | O33: ='SO APRIL 2026 Rev2'!AX33 -> 1121.9003 | Q33: =SUM(I33:P33) -> 143621.9
B34: =B33+1 -> 46135 | C34: =TEXT(B34,"ddd") -> Kam | D34: =Q34-H34 -> -30415.146 | E34: =SUM('SO APRIL 2026 Rev2'!E34:AR34) -> 157455.98 | F34: =SUM('SO APRIL 2026 Rev2'!AS34:AZ34) -> 16581.07 | G34: =SUM('SO APRIL 2026 Rev2'!BA34:BC34) -> 0 | H34: =SUM(E34:G34) -> 174037.05 | I34: ='SO MS'!E34 -> 84000 | J34: ='SO MS'!F34 -> 33600 | K34: ='SO MS'!G34 -> 9600 | L34: =2*5000 -> 10000 | M34: ='SO APRIL 2026 Rev2'!AY34 -> 1800 | N34: ='SO APRIL 2026 Rev2'!AR34 -> 3500 | O34: ='SO APRIL 2026 Rev2'!AX34 -> 1121.9003 | Q34: =SUM(I34:P34) -> 143621.9
B35: =B34+1 -> 46136 | C35: =TEXT(B35,"ddd") -> Jum | D35: =Q35-H35 -> -30415.146 | E35: =SUM('SO APRIL 2026 Rev2'!E35:AR35) -> 157455.98 | F35: =SUM('SO APRIL 2026 Rev2'!AS35:AZ35) -> 16581.07 | G35: =SUM('SO APRIL 2026 Rev2'!BA35:BC35) -> 0 | H35: =SUM(E35:G35) -> 174037.05 | I35: ='SO MS'!E35 -> 84000 | J35: ='SO MS'!F35 -> 33600 | K35: ='SO MS'!G35 -> 9600 | L35: =2*5000 -> 10000 | M35: ='SO APRIL 2026 Rev2'!AY35 -> 1800 | N35: ='SO APRIL 2026 Rev2'!AR35 -> 3500 | O35: ='SO APRIL 2026 Rev2'!AX35 -> 1121.9003 | Q35: =SUM(I35:P35) -> 143621.9
B36: =B35+1 -> 46137 | C36: =TEXT(B36,"ddd") -> Sab | D36: =Q36-H36 -> -16699.269 | E36: =SUM('SO APRIL 2026 Rev2'!E36:AR36) -> 143740.1 | F36: =SUM('SO APRIL 2026 Rev2'!AS36:AZ36) -> 16581.07 | G36: =SUM('SO APRIL 2026 Rev2'!BA36:BC36) -> 0 | H36: =SUM(E36:G36) -> 160321.17 | I36: ='SO MS'!E36 -> 84000 | J36: ='SO MS'!F36 -> 33600 | K36: ='SO MS'!G36 -> 9600 | L36: =2*5000 -> 10000 | M36: ='SO APRIL 2026 Rev2'!AY36 -> 1800 | N36: ='SO APRIL 2026 Rev2'!AR36 -> 3500 | O36: ='SO APRIL 2026 Rev2'!AX36 -> 1121.9003 | Q36: =SUM(I36:P36) -> 143621.9
B37: =B36+1 -> 46138 | C37: =TEXT(B37,"ddd") -> Mgg | D37: =Q37-H37 -> -3001.9511 | E37: =SUM('SO APRIL 2026 Rev2'!E37:AR37) -> 134042.78 | F37: =SUM('SO APRIL 2026 Rev2'!AS37:AZ37) -> 11459.17 | G37: =SUM('SO APRIL 2026 Rev2'!BA37:BC37) -> 0 | H37: =SUM(E37:G37) -> 145501.95 | I37: ='SO MS'!E37 -> 84000 | J37: ='SO MS'!F37 -> 33600 | K37: ='SO MS'!G37 -> 9600 | L37: =2*5000 -> 10000 | M37: ='SO APRIL 2026 Rev2'!AY37 -> 1800 | N37: ='SO APRIL 2026 Rev2'!AR37 -> 3500 | O37: ='SO APRIL 2026 Rev2'!AX37 -> 0 | Q37: =SUM(I37:P37) -> 142500
B38: Sub Total | D38: =SUM(D31:D37) -> -171776.95 | E38: =SUM(E31:E37) -> 1065062.8 | F38: =SUM(F31:F37) -> 110945.59 | G38: =SUM(G31:G37) -> 0 | H38: =SUM(H31:H37) -> 1176008.3 | I38: =SUM(I31:I37) -> 588000 | J38: =SUM(J31:J37) -> 235200 | K38: =SUM(K31:K37) -> 67200 | ... O38: =SUM(O31:O37) -> 6731.4019 | Q38: =SUM(Q31:Q37) -> 1004231.4
A40: =WEEKNUM(B40) -> 18 | B40: =B37+1 -> 46139 | C40: =TEXT(B40,"ddd") -> Sen | D40: =Q40-H40 -> -17925.28 | E40: =SUM('SO APRIL 2026 Rev2'!E40:AR40) -> 157455.98 | F40: =SUM('SO APRIL 2026 Rev2'!AS40:AZ40) -> 16581.07 | G40: =SUM('SO APRIL 2026 Rev2'!BA40:BC40) -> 4500 | H40: =SUM(E40:G40) -> 178537.05 | I40: ='SO MS'!E40 -> 84000 | J40: =SUM('SO APRIL 2026 Rev2'!AF40:AQ40) -> 50589.865 | K40: ='SO MS'!G40 -> 9600 | L40: =2*5000 -> 10000 | M40: ='SO APRIL 2026 Rev2'!AY40 -> 1800 | N40: ='SO APRIL 2026 Rev2'!AR40 -> 3500 | O40: ='SO APRIL 2026 Rev2'!AX40 -> 1121.9003 | Q40: =SUM(I40:P40) -> 160611.77
B41: =B40+1 -> 46140 | C41: =TEXT(B41,"ddd") -> Sel | D41: =Q41-H41 -> -17925.28 | E41: =SUM('SO APRIL 2026 Rev2'!E41:AR41) -> 157455.98 | F41: =SUM('SO APRIL 2026 Rev2'!AS41:AZ41) -> 16581.07 | G41: =SUM('SO APRIL 2026 Rev2'!BA41:BC41) -> 4500 | H41: =SUM(E41:G41) -> 178537.05 | I41: ='SO MS'!E41 -> 84000 | J41: =SUM('SO APRIL 2026 Rev2'!AF41:AQ41) -> 50589.865 | K41: ='SO MS'!G41 -> 9600 | L41: =2*5000 -> 10000 | M41: ='SO APRIL 2026 Rev2'!AY41 -> 1800 | N41: ='SO APRIL 2026 Rev2'!AR41 -> 3500 | O41: ='SO APRIL 2026 Rev2'!AX41 -> 1121.9003 | Q41: =SUM(I41:P41) -> 160611.77
B42: =B41+1 -> 46141 | C42: =TEXT(B42,"ddd") -> Rab | D42: =Q42-H42 -> -17925.28 | E42: =SUM('SO APRIL 2026 Rev2'!E42:AR42) -> 157455.98 | F42: =SUM('SO APRIL 2026 Rev2'!AS42:AZ42) -> 16581.07 | G42: =SUM('SO APRIL 2026 Rev2'!BA42:BC42) -> 4500 | H42: =SUM(E42:G42) -> 178537.05 | I42: ='SO MS'!E42 -> 84000 | J42: =SUM('SO APRIL 2026 Rev2'!AF42:AQ42) -> 50589.865 | K42: ='SO MS'!G42 -> 9600 | L42: =2*5000 -> 10000 | M42: ='SO APRIL 2026 Rev2'!AY42 -> 1800 | N42: ='SO APRIL 2026 Rev2'!AR42 -> 3500 | O42: ='SO APRIL 2026 Rev2'!AX42 -> 1121.9003 | Q42: =SUM(I42:P42) -> 160611.77
B43: =B42+1 -> 46142 | C43: =TEXT(B43,"ddd") -> Kam | D43: =SUM(D40:D42) -> -53775.84 | E43: =SUM(E40:E42) -> 472367.93 | F43: =SUM(F40:F42) -> 49743.21 | G43: =SUM(G40:G42) -> 13500 | H43: =SUM(H40:H42) -> 535611.14 | I43: =SUM(I40:I42) -> 252000 | J43: =SUM(J40:J42) -> 151769.6 | K43: =SUM(K40:K42) -> 28800 | ... O43: =SUM(O40:O42) -> 3365.701 | Q43: =SUM(Q40:Q42) -> 481835.3
B44: Sub Total
B46: Sub Total | D46: =SUM(D43,D38,D29,D20,D11) -> -821797.48 | E46: =SUM(E43,E38,E29,E20,E11) -> 4548951.2 | F46: =SUM(F43,F38,F29,F20,F11) -> 460363.43 | G46: =SUM(G43,G38,G29,G20,G11) -> 13500 | H46: =SUM(H43,H38,H29,H20,H11) -> 5022814.6 | I46: =SUM(I43,I38,I29,I20,I11) -> 2436000 | J46: =SUM(J43,J38,J29,J20,J11) -> 1025369.6 | K46: =SUM(K43,K38,K29,K20,K11) -> 278400 | ... Q46: =SUM(Q43,Q38,Q29,Q20,Q11) -> 4201017.1
B47: Total | D47: =SUM(D40:D42,D31:D37,D22:D28,D13:D19,D6:D10) -> -821797.48 | E47: =SUM(E40:E42,E31:E37,E22:E28,E13:E19,E6:E10) -> 4548951.2 | F47: =SUM(F40:F42,F31:F37,F22:F28,F13:F19,F6:F10) -> 460363.43 | G47: =SUM(G40:G42,G31:G37,G22:G28,G13:G19,G6:G10) -> 13500 | H47: =SUM(H40:H42,H31:H37,H22:H28,H13:H19,H6:H10) -> 5022814.6 | I47: =SUM(I40:I42,I31:I37,I22:I28,I13:I19,I6:I10) -> 2436000 | J47: =SUM(J40:J42,J31:J37,J22:J28,J13:J19,J6:J10) -> 1025369.6 | K47: =SUM(K40:K42,K31:K37,K22:K28,K13:K19,K6:K10) -> 278400 | ... Q47: =SUM(Q40:Q42,Q31:Q37,Q22:Q28,Q13:Q19,Q6:Q10) -> 4201017.1

Sheet Daily serapan Gas
A1: KEBUTUHAN GAS
A4: ='SO APRIL 2026 Rev2'!A3 -> 46113 | E4: KEBUTUHAN GAS (SO) | I4: KUOTA GAS
A5: Week | B5: DATE | D5: Sales Order vs Kuota Gas | E5: JABAR | F5: JATENG | G5: JATIM | H5: TOTAL | I5: MS SETU | J5: MS KHT | K5: MS BLORA | L5: MS BITUNG | M5: MS ZEBRA | N5: MS TAMBAKLOROK | O5: MS WUNUT | P5: MS SADANG | Q5: TOTAL
A6: =WEEKNUM(B6) -> 14 | B6: =A4 -> 46113 | C6: =TEXT(B6,"ddd") -> Rab | D6: =Q6-H6 -> -14962.445 | E6: =SUM('SO APRIL 2026 Rev2'!E6:AR6) -> 169730.36 | F6: =SUM('SO APRIL 2026 Rev2'!AS6:BC6) -> 16581.07 | G6: =SUM('SO APRIL 2026 Rev2'!AX6:AY6) -> 2921.9003 | H6: =SUM(E6:G6) -> 189233.33 | I6: ='Summary sales'!D8 -> 100928.31 | J6: ='Summary sales'!E8 -> 42523.65 | K6: ='Summary sales'!F8 -> 18037.29 | L6: ='Summary sales'!G8 -> 4177.39 | N6: ='Summary sales'!I8 -> 8604.25 | Q6: =SUM(I6:P6) -> 174270.89
B7: =B6+1 -> 46114 | C7: =TEXT(B7,"ddd") -> Kam | D7: =Q7-H7 -> -39515.105 | E7: =SUM('SO APRIL 2026 Rev2'!E7:AR7) -> 169730.36 | F7: =SUM('SO APRIL 2026 Rev2'!AS7:BC7) -> 16581.07 | G7: =SUM('SO APRIL 2026 Rev2'!AX7:AY7) -> 2921.9003 | H7: =SUM(E7:G7) -> 189233.33 | I7: ='Summary sales'!D9 -> 78845.78 | J7: ='Summary sales'!E9 -> 44578.75 | K7: ='Summary sales'!F9 -> 16718.5 | L7: ='Summary sales'!G9 -> 9575.2 | N7: ='Summary sales'!I9 -> 0 | Q7: =SUM(I7:P7) -> 149718.23
B8: =B7+1 -> 46115 | C8: =TEXT(B8,"ddd") -> Jum | D8: =Q8-H8 -> -21885.455 | E8: =SUM('SO APRIL 2026 Rev2'!E8:AR8) -> 166230.36 | F8: =SUM('SO APRIL 2026 Rev2'!AS8:BC8) -> 16581.07 | G8: =SUM('SO APRIL 2026 Rev2'!AX8:AY8) -> 2921.9003 | H8: =SUM(E8:G8) -> 185733.33 | I8: ='Summary sales'!D10 -> 105631.06 | J8: ='Summary sales'!E10 -> 40111.83 | K8: ='Summary sales'!F10 -> 13672.35 | L8: ='Summary sales'!G10 -> 0 | N8: ='Summary sales'!I10 -> 4432.64 | Q8: =SUM(I8:P8) -> 163847.88
B9: =B8+1 -> 46116 | C9: =TEXT(B9,"ddd") -> Sab | D9: =Q9-H9 -> 7351.1418 | E9: =SUM('SO APRIL 2026 Rev2'!E9:AR9) -> 161264.49 | F9: =SUM('SO APRIL 2026 Rev2'!AS9:BC9) -> 16581.07 | G9: =SUM('SO APRIL 2026 Rev2'!AX9:AY9) -> 2921.9003 | H9: =SUM(E9:G9) -> 180767.46 | I9: ='Summary sales'!D11 -> 116238.76 | J9: ='Summary sales'!E11 -> 46923.09 | K9: ='Summary sales'!F11 -> 13011.65 | L9: ='Summary sales'!G11 -> 11945.1 | N9: ='Summary sales'!I11 -> 0 | Q9: =SUM(I9:P9) -> 188118.6
B10: =B9+1 -> 46117 | C10: =TEXT(B10,"ddd") -> Mgg | D10: =Q10-H10 -> 470.54668 | E10: =SUM('SO APRIL 2026 Rev2'!E10:AR10) -> 155992.84 | F10: =SUM('SO APRIL 2026 Rev2'!AS10:BC10) -> 11459.17 | G10: =SUM('SO APRIL 2026 Rev2'!AX10:AY10) -> 1800 | H10: =SUM(E10:G10) -> 169252.01 | I10: ='Summary sales'!D12 -> 101567.04 | J10: ='Summary sales'!E12 -> 48679.31 | K10: ='Summary sales'!F12 -> 14923.66 | L10: ='Summary sales'!G12 -> 4552.55 | N10: ='Summary sales'!I12 -> 0 | Q10: =SUM(I10:P10) -> 169722.56
B11: Sub Total | D11: =SUM(D6:D10) -> -68541.316 | E11: =SUM(E6:E10) -> 822948.42 | F11: =SUM(F6:F10) -> 77783.45 | G11: =SUM(G6:G10) -> 13487.601 | H11: =SUM(H6:H10) -> 914219.48 | I11: =SUM(I6:I10) -> 503210.95 | J11: =SUM(J6:J10) -> 222816.63 | K11: =SUM(K6:K10) -> 76363.45 | ... O11: =SUM(O6:O10) -> 0 | Q11: =SUM(Q6:Q10) -> 845678.16
A13: =WEEKNUM(B13) -> 15 | B13: =B10+1 -> 46118 | C13: =TEXT(B13,"ddd") -> Sen | D13: =Q13-H13 -> -9391.3949 | E13: =SUM('SO APRIL 2026 Rev2'!E13:AR13) -> 162930.36 | F13: =SUM('SO APRIL 2026 Rev2'!AS13:BC13) -> 16581.07 | G13: =SUM('SO APRIL 2026 Rev2'!AX13:AY13) -> 2921.9003 | H13: =SUM(E13:G13) -> 182433.33 | I13: ='Summary sales'!D13 -> 101450.25 | J13: ='Summary sales'!E13 -> 47032.04 | K13: ='Summary sales'!F13 -> 13171.59 | L13: ='Summary sales'!G13 -> 7328.12 | N13: ='Summary sales'!I13 -> 4059.94 | Q13: =SUM(I13:P13) -> 173041.94
B14: =B13+1 -> 46119 | C14: =TEXT(B14,"ddd") -> Sel | D14: =Q14-H14 -> 12567.735 | E14: =SUM('SO APRIL 2026 Rev2'!E14:AR14) -> 162930.36 | F14: =SUM('SO APRIL 2026 Rev2'!AS14:BC14) -> 16581.07 | G14: =SUM('SO APRIL 2026 Rev2'!AX14:AY14) -> 2921.9003 | H14: =SUM(E14:G14) -> 182433.33 | I14: ='Summary sales'!D14 -> 110281.66 | J14: ='Summary sales'!E14 -> 47943.57 | K14: ='Summary sales'!F14 -> 18857.27 | L14: ='Summary sales'!G14 -> 13891.13 | N14: ='Summary sales'!I14 -> 4027.44 | Q14: =SUM(I14:P14) -> 195001.07
B15: =B14+1 -> 46120 | C15: =TEXT(B15,"ddd") -> Rab | D15: =Q15-H15 -> -3658.6249 | E15: =SUM('SO APRIL 2026 Rev2'!E15:AR15) -> 162930.36 | F15: =SUM('SO APRIL 2026 Rev2'!AS15:BC15) -> 16581.07 | G15: =SUM('SO APRIL 2026 Rev2'!AX15:AY15) -> 2921.9003 | H15: =SUM(E15:G15) -> 182433.33 | I15: ='Summary sales'!D15 -> 102703.51 | J15: ='Summary sales'!E15 -> 49471.31 | K15: ='Summary sales'!F15 -> 17319.8 | L15: ='Summary sales'!G15 -> 5278.75 | N15: ='Summary sales'!I15 -> 4001.34 | Q15: =SUM(I15:P15) -> 178774.71
B16: =B15+1 -> 46121 | C16: =TEXT(B16,"ddd") -> Kam | D16: =Q16-H16 -> -21833.085 | E16: =SUM('SO APRIL 2026 Rev2'!E16:AR16) -> 160930.36 | F16: =SUM('SO APRIL 2026 Rev2'!AS16:BC16) -> 16581.07 | G16: =SUM('SO APRIL 2026 Rev2'!AX16:AY16) -> 2921.9003 | H16: =SUM(E16:G16) -> 180433.33 | I16: ='Summary sales'!D16 -> 97551.65 | J16: ='Summary sales'!E16 -> 42173.36 | K16: ='Summary sales'!F16 -> 13291.76 | L16: ='Summary sales'!G16 -> 5583.48 | N16: ='Summary sales'!I16 -> 0 | Q16: =SUM(I16:P16) -> 158600.25
B17: =B16+1 -> 46122 | C17: =TEXT(B17,"ddd") -> Jum | D17: =Q17-H17 -> -8233.4949 | E17: =SUM('SO APRIL 2026 Rev2'!E17:AR17) -> 160930.36 | F17: =SUM('SO APRIL 2026 Rev2'!AS17:BC17) -> 16581.07 | G17: =SUM('SO APRIL 2026 Rev2'!AX17:AY17) -> 2921.9003 | H17: =SUM(E17:G17) -> 180433.33 | I17: ='Summary sales'!D17 -> 97398.1 | J17: ='Summary sales'!E17 -> 42410.79 | K17: ='Summary sales'!F17 -> 23124 | L17: ='Summary sales'!G17 -> 5126.19 | N17: ='Summary sales'!I17 -> 4140.76 | Q17: =SUM(I17:P17) -> 172199.84
B18: =B17+1 -> 46123 | C18: =TEXT(B18,"ddd") -> Sab | D18: =Q18-H18 -> 7220.7218 | E18: =SUM('SO APRIL 2026 Rev2'!E18:AR18) -> 155964.49 | F18: =SUM('SO APRIL 2026 Rev2'!AS18:BC18) -> 16581.07 | G18: =SUM('SO APRIL 2026 Rev2'!AX18:AY18) -> 2921.9003 | H18: =SUM(E18:G18) -> 175467.46 | I18: ='Summary sales'!D18 -> 100310.68 | J18: ='Summary sales'!E18 -> 50442.79 | K18: ='Summary sales'!F18 -> 22294.95 | L18: ='Summary sales'!G18 -> 5385.79 | N18: ='Summary sales'!I18 -> 4253.97 | Q18: =SUM(I18:P18) -> 182688.18
B19: =B18+1 -> 46124 | C19: =TEXT(B19,"ddd") -> Mgg | D19: =Q19-H19 -> 3619.2067 | E19: =SUM('SO APRIL 2026 Rev2'!E19:AR19) -> 150692.84 | F19: =SUM('SO APRIL 2026 Rev2'!AS19:BC19) -> 11459.17 | G19: =SUM('SO APRIL 2026 Rev2'!AX19:AY19) -> 1800 | H19: =SUM(E19:G19) -> 163952.01 | I19: ='Summary sales'!D19 -> 99786.09 | J19: ='Summary sales'!E19 -> 37464.35 | K19: ='Summary sales'!F19 -> 21534 | L19: ='Summary sales'!G19 -> 4201.42 | N19: ='Summary sales'!I19 -> 4585.36 | Q19: =SUM(I19:P19) -> 167571.22
B20: Sub Total | D20: =SUM(D13:D19) -> -19708.936 | E20: =SUM(E13:E19) -> 1117309.2 | F20: =SUM(F13:F19) -> 110945.59 | G20: =SUM(G13:G19) -> 19331.402 | H20: =SUM(H13:H19) -> 1247586.1 | I20: =SUM(I13:I19) -> 709481.94 | J20: =SUM(J13:J19) -> 316938.21 | K20: =SUM(K13:K19) -> 129593.37 | ... O20: =SUM(O13:O19) -> 0 | Q20: =SUM(Q13:Q19) -> 1227877.2
A22: =WEEKNUM(B22) -> 16 | B22: =B19+1 -> 46125 | C22: =TEXT(B22,"ddd") -> Sen | D22: =Q22-H22 -> -10578.218 | E22: =SUM('SO APRIL 2026 Rev2'!E22:AR22) -> 159056.04 | F22: =SUM('SO APRIL 2026 Rev2'!AS22:BC22) -> 16581.07 | G22: =SUM('SO APRIL 2026 Rev2'!AX22:AY22) -> 2921.9003 | H22: =SUM(E22:G22) -> 178559.01 | I22: ='Summary sales'!D20 -> 96651.08 | J22: ='Summary sales'!E20 -> 39592.39 | K22: ='Summary sales'!F20 -> 21876.28 | L22: ='Summary sales'!G20 -> 5515.69 | N22: ='Summary sales'!I20 -> 4345.35 | Q22: =SUM(I22:P22) -> 167980.79
B23: =B22+1 -> 46126 | C23: =TEXT(B23,"ddd") -> Sel | D23: =Q23-H23 -> -10619.088 | E23: =SUM('SO APRIL 2026 Rev2'!E23:AR23) -> 159056.04 | F23: =SUM('SO APRIL 2026 Rev2'!AS23:BC23) -> 16581.07 | G23: =SUM('SO APRIL 2026 Rev2'!AX23:AY23) -> 2921.9003 | H23: =SUM(E23:G23) -> 178559.01 | I23: ='Summary sales'!D21 -> 103628.61 | J23: ='Summary sales'!E21 -> 43687.96 | K23: ='Summary sales'!F21 -> 16442.93 | L23: ='Summary sales'!G21 -> 0 | N23: ='Summary sales'!I21 -> 4180.42 | Q23: =SUM(I23:P23) -> 167939.92
B24: =B23+1 -> 46127 | C24: =TEXT(B24,"ddd") -> Rab | D24: =Q24-H24 -> 5982.4938 | E24: =SUM('SO APRIL 2026 Rev2'!E24:AR24) -> 160455.98 | F24: =SUM('SO APRIL 2026 Rev2'!AS24:BC24) -> 16581.07 | G24: =SUM('SO APRIL 2026 Rev2'!AX24:AY24) -> 2921.9003 | H24: =SUM(E24:G24) -> 179958.95 | I24: ='Summary sales'!D22 -> 108635.65 | J24: ='Summary sales'!E22 -> 51750.7 | K24: ='Summary sales'!F22 -> 16865.67 | L24: ='Summary sales'!G22 -> 4818.12 | N24: ='Summary sales'!I22 -> 3871.3 | Q24: =SUM(I24:P24) -> 185941.44
B25: =B24+1 -> 46128 | C25: =TEXT(B25,"ddd") -> Kam | D25: =Q25-H25 -> 1816.1238 | E25: =SUM('SO APRIL 2026 Rev2'!E25:AR25) -> 157455.98 | F25: =SUM('SO APRIL 2026 Rev2'!AS25:BC25) -> 16581.07 | G25: =SUM('SO APRIL 2026 Rev2'!AX25:AY25) -> 2921.9003 | H25: =SUM(E25:G25) -> 176958.95 | I25: ='Summary sales'!D23 -> 104676.46 | J25: ='Summary sales'!E23 -> 43682.68 | K25: ='Summary sales'!F23 -> 20901.12 | L25: ='Summary sales'!G23 -> 5197.6 | N25: ='Summary sales'!I23 -> 4317.21 | Q25: =SUM(I25:P25) -> 178775.07
B26: =B25+1 -> 46129 | C26: =TEXT(B26,"ddd") -> Jum | D26: =Q26-H26 -> -537.36623 | E26: =SUM('SO APRIL 2026 Rev2'!E26:AR26) -> 157455.98 | F26: =SUM('SO APRIL 2026 Rev2'!AS26:BC26) -> 16581.07 | G26: =SUM('SO APRIL 2026 Rev2'!AX26:AY26) -> 2921.9003 | H26: =SUM(E26:G26) -> 176958.95 | I26: ='Summary sales'!D24 -> 103424.7 | J26: ='Summary sales'!E24 -> 45057.78 | K26: ='Summary sales'!F24 -> 15669.73 | L26: ='Summary sales'!G24 -> 8154.8 | N26: ='Summary sales'!I24 -> 4114.57 | Q26: =SUM(I26:P26) -> 176421.58
B27: =B26+1 -> 46130 | C27: =TEXT(B27,"ddd") -> Sab | D27: =Q27-H27 -> -2809.6795 | E27: =SUM('SO APRIL 2026 Rev2'!E27:AR27) -> 143740.1 | F27: =SUM('SO APRIL 2026 Rev2'!AS27:BC27) -> 16581.07 | G27: =SUM('SO APRIL 2026 Rev2'!AX27:AY27) -> 2921.9003 | H27: =SUM(E27:G27) -> 163243.07 | I27: ='Summary sales'!D25 -> 95235.31 | J27: ='Summary sales'!E25 -> 43895.5 | K27: ='Summary sales'!F25 -> 16164.65 | L27: ='Summary sales'!G25 -> 5137.93 | N27: ='Summary sales'!I25 -> 0 | Q27: =SUM(I27:P27) -> 160433.39
B28: =B27+1 -> 46131 | C28: =TEXT(B28,"ddd") -> Mgg | D28: =Q28-H28 -> 34510.669 | E28: =SUM('SO APRIL 2026 Rev2'!E28:AR28) -> 134042.78 | F28: =SUM('SO APRIL 2026 Rev2'!AS28:BC28) -> 11459.17 | G28: =SUM('SO APRIL 2026 Rev2'!AX28:AY28) -> 1800 | H28: =SUM(E28:G28) -> 147301.95 | I28: ='Summary sales'!D26 -> 98590.65 | J28: ='Summary sales'!E26 -> 48717.44 | K28: ='Summary sales'!F26 -> 22980.89 | L28: ='Summary sales'!G26 -> 3184.95 | N28: ='Summary sales'!I26 -> 8338.69 | Q28: =SUM(I28:P28) -> 181812.62
B29: Sub Total | D29: =SUM(D22:D28) -> 17764.934 | E29: =SUM(E22:E28) -> 1071262.9 | F29: =SUM(F22:F28) -> 110945.59 | G29: =SUM(G22:G28) -> 19331.402 | H29: =SUM(H22:H28) -> 1201539.9 | I29: =SUM(I22:I28) -> 710842.46 | J29: =SUM(J22:J28) -> 316384.45 | K29: =SUM(K22:K28) -> 130901.27 | ... O29: =SUM(O22:O28) -> 0 | Q29: =SUM(Q22:Q28) -> 1219304.8
