Workbook
Name ___xlnm._FilterDatabase_2: #REF!
Name ___xlnm._FilterDatabase_2: #REF!
Name ___xlnm._FilterDatabase_2: #REF!
Name ___xlnm._FilterDatabase_2: #REF!
Name ___xlnm._FilterDatabase_2: #REF!
Name ___xlnm._FilterDatabase_2: #REF!
Name ___xlnm._FilterDatabase_2: #REF!
Name ___xlnm._FilterDatabase_2: #REF!
Name ___xlnm._FilterDatabase_2: #REF!
Name ___xlnm._FilterDatabase_2: #REF!
Name ___xlnm._FilterDatabase_2: #REF!
Name __xlnm._FilterDatabase_2: #REF!
Name __xlnm._FilterDatabase_2: #REF!
Name __xlnm._FilterDatabase_2: #REF!
Name __xlnm._FilterDatabase_2: #REF!
Name __xlnm._FilterDatabase_2: #REF!
Name __xlnm._FilterDatabase_2: #REF!
Name __xlnm._FilterDatabase_2: #REF!
Name __xlnm._FilterDatabase_2: #REF!
Name __xlnm._FilterDatabase_2: #REF!
Name __xlnm._FilterDatabase_2: #REF!
Name __xlnm._FilterDatabase_2: #REF!
Name _TES46: #N/A
Name AAAA: #N/A
Name ati: #N/A
Name BS: #N/A
Name CCC: #N/A
Name depr9200: #N/A
Name dfsfd: #N/A
Name Excel_BuiltIn__FilterDatabase_1: #REF!
Name Excel_BuiltIn__FilterDatabase_1: #REF!
Name Excel_BuiltIn__FilterDatabase_1: #REF!
Name Excel_BuiltIn__FilterDatabase_1: #REF!
Name Excel_BuiltIn__FilterDatabase_1: #REF!
Name Excel_BuiltIn__FilterDatabase_1: #REF!
Name Excel_BuiltIn__FilterDatabase_1: #REF!
Name Excel_BuiltIn__FilterDatabase_1: #REF!
Name Excel_BuiltIn__FilterDatabase_1: #REF!
Name Excel_BuiltIn__FilterDatabase_1: #REF!
Name Excel_BuiltIn__FilterDatabase_1: #REF!
Name Excel_BuiltIn_Print_Titles: NA()
Name Export_3: #REF!
Name Export_3: #REF!
Name Export_3: #REF!
Name Export_3: #REF!
Name Export_3: #REF!
Name Export_3: #REF!
Name Export_3: #REF!
Name Export_3: #REF!
Name FOB: 'Summary FOB'!#REF!
Name FOB: 'Summary FOB'!#REF!
Name FOB: 'Summary FOB'!#REF!
Name FOB: 'Summary FOB'!#REF!
Name FOB: 'Summary FOB'!#REF!
Name FOB: 'Summary FOB'!#REF!
Name FOB: 'Summary FOB'!#REF!
Name FOB: 'Summary FOB'!#REF!
Name partt: #N/A
Name PRINT_TITLES_MI: #N/A
Name project: #N/A

Sheet SO MEI 2026 REV 4
AG1: SMS | AH1: BMT
A2: SALES ORDER | U2: gf ranca
A3: 46143 | U3: =10500-6600 -> 3900
AT4: FOB PTGN
A5: Week | B5: DATE | D5: TOTAL | E5: CLIN | F5: BI | G5: MKG | H5: STM | I5: OAJ | J5: NNI | K5: SHB | L5: GTL | M5: TWK | N5: BYC | O5: GF RANCA | P5: SMA | Q5: UMI | R5: HLI | S5: ASAHIMAS | T5: DIC | U5: HCI | V5: HANKOOK | W5: KSN | X5: ADP | Y5: ALT (KSO MASAMI) | Z5: IDP (KSO AAE) | AA5: FJI (KSO SALMAH) | AB5: WINGLOK (KSO EBM) | AC5: CISF (KSO RRS) | AD5: KGM | AE5: PUJ - LUBRICANT | AF5: CALBEE (KSO BMI) | AG5: IP | AH5: BEM | AI5: AMI | AJ5: KA | AK5: KTN | AL5: TOMIMOTO | AM5: NIAGA GARAM | AN5: PCI 84 | AO5: PCI MENGGER | AP5: INDOFOOD | AQ5: CERES | AR5: ABC KOGEN | AS5: TONGJI | AT5: PA | AU5: RB | AV5: GF ATOM | AW5: GF KULIT | AX5: HSK (KSO GAS) | AY5: SDM | AZ5: JARGAS | BA5: SBI | BB5: SP JES | BC5: SP GLOBAL | BD5: JIUQI
A6: =WEEKNUM(B6) -> 18 | B6: =A3 -> 46143 | C6: =TEXT(B6,"ddd") -> Jum | D6: =SUM(E6:BD6) -> 109615.85 | E6: 0 | F6: 1000 | G6: 500 | H6: 0 | I6: 644.02065 | J6: 0 | K6: 0 | L6: 603.76323 | M6: 673.27548 | N6: 2500 | O6: 0 | P6: 300 | Q6: 4000 | R6: 4000 | S6: 48000 | T6: 5000 | U6: 0 | V6: 0 | W6: 0 | X6: 0 | Y6: 0 | Z6: 0 | AA6: 70.054839 | AB6: 89.451613 | AC6: 1000 | AD6: 1300 | AE6: 0 | AF6: 3000 | AG6: 2020.8603 | AH6: 800 | AI6: 1000 | AJ6: 0 | AK6: 2043.2745 | AL6: 0 | AM6: 1000 | AN6: 11007.047 | AO6: 1519.5448 | AP6: 1000 | AQ6: 0 | AR6: 8000 | AS6: 500 | AT6: 726.81516 | AU6: 3018.0416 | AV6: 0 | AW6: 0 | AX6: 0 | AY6: 0 | AZ6: 1800 | BA6: 2499.7026 | BB6: 0 | BC6: 0 | BD6: 0
B7: =B6+1 -> 46144 | C7: =TEXT(B7,"ddd") -> Sab | D7: =SUM(E7:BD7) -> 169830.56 | E7: 0 | F7: 3000 | G7: 1129.7313 | H7: 3282.5161 | I7: 644.02065 | J7: 0 | K7: 0 | L7: 603.76323 | M7: 673.27548 | N7: 4514.199 | O7: 6600.0623 | P7: 2874.3265 | Q7: 16000 | R7: 4000 | S7: 40000 | T7: 5000 | U7: 0 | V7: 0 | W7: 2000 | X7: 500 | Y7: 1000 | Z7: 5500 | AA7: 70.054839 | AB7: 89.451613 | AC7: 3500 | AD7: 1300 | AE7: 3000 | AF7: 5000 | AG7: 2020.8603 | AH7: 800 | AI7: 7200 | AJ7: 0 | AK7: 2043.2745 | AL7: 1999.5303 | AM7: 1000 | AN7: 11007.047 | AO7: 1519.5448 | AP7: 3999.6742 | AQ7: 9000.0571 | AR7: 8000 | AS7: 500 | AT7: 726.81516 | AU7: 3018.0416 | AV7: 2044.9997 | AW7: 369.61071 | AX7: 0 | AY7: 0 | AZ7: 1800 | BA7: 2499.7026 | BB7: 0 | BC7: 0 | BD7: 0
B8: =B7+1 -> 46145 | C8: =TEXT(B8,"ddd") -> Mgg | D8: =SUM(E8:BD8) -> 148952.01 | E8: 733.5729 | F8: 1000 | G8: 1129.7313 | H8: 999.51613 | I8: 644.02065 | J8: 0 | K8: 0 | L8: 603.76323 | M8: 673.27548 | N8: 0 | O8: 6600.0623 | P8: 300 | Q8: 6659.5545 | R8: 4000 | S8: 48000 | T8: 5000 | U8: 0 | V8: 0 | W8: 2000 | X8: 500 | Y8: 0 | Z8: 2500 | AA8: 70.054839 | AB8: 89.451613 | AC8: 1000 | AD8: 1300 | AE8: 0 | AF8: 5000 | AG8: 2020.8603 | AH8: 0 | AI8: 2999.8519 | AJ8: 0 | AK8: 2043.2745 | AL8: 1999.5303 | AM8: 0 | AN8: 11007.047 | AO8: 1519.5448 | AP8: 3999.6742 | AQ8: 6000.0571 | AR8: 8000 | AS8: 3500 | AT8: 726.81516 | AU8: 3018.0416 | AV8: 2044.9997 | AW8: 369.61071 | AX8: 0 | AY8: 0 | AZ8: 1800 | BA8: 2499.7026 | BB8: 0 | BC8: 0 | BD8: 6600
B9: Sub Total | D9: =SUM(D6:D8) -> 428398.43 | E9: =SUM(E6:E8) -> 733.5729 | F9: =SUM(F6:F8) -> 5000 | G9: =SUM(G6:G8) -> 2759.4626 | H9: =SUM(H6:H8) -> 4282.0323 | I9: =SUM(I6:I8) -> 1932.0619 | J9: =SUM(J6:J8) -> 0 | K9: =SUM(K6:K8) -> 0 | ... BD9: =SUM(BD6:BD8) -> 6600
A11: =WEEKNUM(B11) -> 19 | B11: =B8+1 -> 46146 | C11: =TEXT(B11,"ddd") -> Sen | D11: =SUM(E11:BD11) -> 180251.94 | E11: 1199.5729 | F11: 3000 | G11: 1129.7313 | H11: 3282.5161 | I11: 644.02065 | J11: 0 | K11: 499.97065 | L11: 603.76323 | M11: 673.27548 | N11: 5514.199 | O11: 6600.0623 | P11: 2874.3265 | Q11: 16000 | R11: 4000 | S11: 26500 | T11: 5000 | U11: 7000 | V11: 0 | W11: 2000 | X11: 500 | Y11: 1000 | Z11: 5500 | AA11: 70.054839 | AB11: 89.451613 | AC11: 3500 | AD11: 1300 | AE11: 3000 | AF11: 5000 | AG11: 2020.8603 | AH11: 800 | AI11: 7200 | AJ11: 3499.8768 | AK11: 2043.2745 | AL11: 1999.5303 | AM11: 1000 | AN11: 11007.047 | AO11: 1519.5448 | AP11: 3999.6742 | AQ11: 9000.0571 | AR11: 8000 | AS11: 3500 | AT11: 726.81516 | AU11: 3018.0416 | AV11: 2044.9997 | AW11: 369.61071 | AX11: 0 | AY11: 1121.9003 | AZ11: 1800 | BA11: 2499.7026 | BB11: 0 | BC11: 0 | BD11: 6600.0623
B12: =B11+1 -> 46147 | C12: =TEXT(B12,"ddd") -> Sel | D12: =SUM(E12:BD12) -> 180251.94 | E12: 1199.5729 | F12: 3000 | G12: 1129.7313 | H12: 3282.5161 | I12: 644.02065 | J12: 0 | K12: 499.97065 | L12: 603.76323 | M12: 673.27548 | N12: 5514.199 | O12: 6600.0623 | P12: 2874.3265 | Q12: 16000 | R12: 4000 | S12: 26500 | T12: 5000 | U12: 7000 | V12: 0 | W12: 2000 | X12: 500 | Y12: 1000 | Z12: 5500 | AA12: 70.054839 | AB12: 89.451613 | AC12: 3500 | AD12: 1300 | AE12: 3000 | AF12: 5000 | AG12: 2020.8603 | AH12: 800 | AI12: 7200 | AJ12: 3499.8768 | AK12: 2043.2745 | AL12: 1999.5303 | AM12: 1000 | AN12: 11007.047 | AO12: 1519.5448 | AP12: 3999.6742 | AQ12: 9000.0571 | AR12: 8000 | AS12: 3500 | AT12: 726.81516 | AU12: 3018.0416 | AV12: 2044.9997 | AW12: 369.61071 | AX12: 0 | AY12: 1121.9003 | AZ12: 1800 | BA12: 2499.7026 | BB12: 0 | BC12: 0 | BD12: 6600.0623
B13: =B12+1 -> 46148 | C13: =TEXT(B13,"ddd") -> Rab | D13: =SUM(E13:BD13) -> 189751.94 | E13: 1199.5729 | F13: 3000 | G13: 1129.7313 | H13: 3282.5161 | I13: 644.02065 | J13: 0 | K13: 499.97065 | L13: 603.76323 | M13: 673.27548 | N13: 5514.199 | O13: 6600.0623 | P13: 2874.3265 | Q13: 16000 | R13: 4000 | S13: 36000 | T13: 5000 | U13: 7000 | V13: 0 | W13: 2000 | X13: 500 | Y13: 1000 | Z13: 5500 | AA13: 70.054839 | AB13: 89.451613 | AC13: 3500 | AD13: 1300 | AE13: 3000 | AF13: 5000 | AG13: 2020.8603 | AH13: 800 | AI13: 7200 | AJ13: 3499.8768 | AK13: 2043.2745 | AL13: 1999.5303 | AM13: 1000 | AN13: 11007.047 | AO13: 1519.5448 | AP13: 3999.6742 | AQ13: 9000.0571 | AR13: 8000 | AS13: 3500 | AT13: 726.81516 | AU13: 3018.0416 | AV13: 2044.9997 | AW13: 369.61071 | AX13: 0 | AY13: 1121.9003 | AZ13: 1800 | BA13: 2499.7026 | BB13: 0 | BC13: 0 | BD13: 6600.0623
B14: =B13+1 -> 46149 | C14: =TEXT(B14,"ddd") -> Kam | D14: =SUM(E14:BD14) -> 189751.94 | E14: 1199.5729 | F14: 3000 | G14: 1129.7313 | H14: 3282.5161 | I14: 644.02065 | J14: 0 | K14: 499.97065 | L14: 603.76323 | M14: 673.27548 | N14: 5514.199 | O14: 6600.0623 | P14: 2874.3265 | Q14: 16000 | R14: 4000 | S14: 36000 | T14: 5000 | U14: 7000 | V14: 0 | W14: 2000 | X14: 500 | Y14: 1000 | Z14: 5500 | AA14: 70.054839 | AB14: 89.451613 | AC14: 3500 | AD14: 1300 | AE14: 3000 | AF14: 5000 | AG14: 2020.8603 | AH14: 800 | AI14: 7200 | AJ14: 3499.8768 | AK14: 2043.2745 | AL14: 1999.5303 | AM14: 1000 | AN14: 11007.047 | AO14: 1519.5448 | AP14: 3999.6742 | AQ14: 9000.0571 | AR14: 8000 | AS14: 3500 | AT14: 726.81516 | AU14: 3018.0416 | AV14: 2044.9997 | AW14: 369.61071 | AX14: 0 | AY14: 1121.9003 | AZ14: 1800 | BA14: 2499.7026 | BB14: 0 | BC14: 0 | BD14: 6600.0623
B15: =B14+1 -> 46150 | C15: =TEXT(B15,"ddd") -> Jum | D15: =SUM(E15:BD15) -> 189751.94 | E15: 1199.5729 | F15: 3000 | G15: 1129.7313 | H15: 3282.5161 | I15: 644.02065 | J15: 0 | K15: 499.97065 | L15: 603.76323 | M15: 673.27548 | N15: 5514.199 | O15: 6600.0623 | P15: 2874.3265 | Q15: 16000 | R15: 4000 | S15: 36000 | T15: 5000 | U15: 7000 | V15: 0 | W15: 2000 | X15: 500 | Y15: 1000 | Z15: 5500 | AA15: 70.054839 | AB15: 89.451613 | AC15: 3500 | AD15: 1300 | AE15: 3000 | AF15: 5000 | AG15: 2020.8603 | AH15: 800 | AI15: 7200 | AJ15: 3499.8768 | AK15: 2043.2745 | AL15: 1999.5303 | AM15: 1000 | AN15: 11007.047 | AO15: 1519.5448 | AP15: 3999.6742 | AQ15: 9000.0571 | AR15: 8000 | AS15: 3500 | AT15: 726.81516 | AU15: 3018.0416 | AV15: 2044.9997 | AW15: 369.61071 | AX15: 0 | AY15: 1121.9003 | AZ15: 1800 | BA15: 2499.7026 | BB15: 0 | BC15: 0 | BD15: 6600.0623
B16: =B15+1 -> 46151 | C16: =TEXT(B16,"ddd") -> Sab | D16: =SUM(E16:BD16) -> 176664.17 | E16: 733.5729 | F16: 3000 | G16: 1129.7313 | H16: 3282.5161 | I16: 644.02065 | J16: 0 | K16: 499.97065 | L16: 603.76323 | M16: 673.27548 | N16: 4514.199 | O16: 6600.0623 | P16: 2874.3265 | Q16: 16000 | R16: 4000 | S16: 36000 | T16: 5000 | U16: 0 | V16: 0 | W16: 2000 | X16: 500 | Y16: 1000 | Z16: 5500 | AA16: 70.054839 | AB16: 89.451613 | AC16: 3500 | AD16: 1300 | AE16: 3000 | AF16: 5000 | AG16: 2020.8603 | AH16: 800 | AI16: 7200 | AJ16: 0 | AK16: 2043.2745 | AL16: 1999.5303 | AM16: 1000 | AN16: 11007.047 | AO16: 1519.5448 | AP16: 3999.6742 | AQ16: 9000.0571 | AR16: 8000 | AS16: 3500 | AT16: 726.81516 | AU16: 3018.0416 | AV16: 2044.9997 | AW16: 369.61071 | AX16: 0 | AY16: 0 | AZ16: 1800 | BA16: 2499.7026 | BB16: 0 | BC16: 0 | BD16: 6600.0623
B17: =B16+1 -> 46152 | C17: =TEXT(B17,"ddd") -> Mgg | D17: =SUM(E17:BD17) -> 128352.01 | E17: 733.5729 | F17: 1000 | G17: 1129.7313 | H17: 999.51613 | I17: 644.02065 | J17: 0 | K17: 0 | L17: 603.76323 | M17: 673.27548 | N17: 0 | O17: 6600.0623 | P17: 300 | Q17: 6659.5545 | R17: 4000 | S17: 36000 | T17: 5000 | U17: 0 | V17: 0 | W17: 2000 | X17: 500 | Y17: 0 | Z17: 2500 | AA17: 70.054839 | AB17: 89.451613 | AC17: 1000 | AD17: 1300 | AE17: 0 | AF17: 5000 | AG17: 2020.8603 | AH17: 0 | AI17: 2999.8519 | AJ17: 0 | AK17: 2043.2745 | AL17: 1999.5303 | AM17: 0 | AN17: 11007.047 | AO17: 1519.5448 | AP17: 3999.6742 | AQ17: 6000.0571 | AR17: 6000 | AS17: 3500 | AT17: 726.81516 | AU17: 3018.0416 | AV17: 2044.9997 | AW17: 369.61071 | AX17: 0 | AY17: 0 | AZ17: 1800 | BA17: 2499.7026 | BB17: 0 | BC17: 0 | BD17: 0
B18: Sub Total | D18: =SUM(D11:D17) -> 1234775.9 | E18: =SUM(E11:E17) -> 7465.0103 | F18: =SUM(F11:F17) -> 19000 | G18: =SUM(G11:G17) -> 7908.119 | H18: =SUM(H11:H17) -> 20694.613 | I18: =SUM(I11:I17) -> 4508.1445 | J18: =SUM(J11:J17) -> 0 | K18: =SUM(K11:K17) -> 2999.8239 | ... BD18: =SUM(BD11:BD17) -> 39600.374
A20: =WEEKNUM(B20) -> 20 | B20: =B17+1 -> 46153 | C20: =TEXT(B20,"ddd") -> Sen | D20: =SUM(E20:BD20) -> 186877.62 | E20: 1199.5729 | F20: 2000 | G20: 1129.7313 | H20: 3282.5161 | I20: 644.02065 | J20: 0 | K20: 499.97065 | L20: 603.76323 | M20: 673.27548 | N20: 5514.199 | O20: 6600.0623 | P20: 1000 | Q20: 16000 | R20: 4000 | S20: 36000 | T20: 5000 | U20: 7000 | V20: 0 | W20: 2000 | X20: 500 | Y20: 1000 | Z20: 5500 | AA20: 70.054839 | AB20: 89.451613 | AC20: 3500 | AD20: 1300 | AE20: 3000 | AF20: 5000 | AG20: 2020.8603 | AH20: 800 | AI20: 7200 | AJ20: 3499.8768 | AK20: 2043.2745 | AL20: 1999.5303 | AM20: 1000 | AN20: 11007.047 | AO20: 1519.5448 | AP20: 3999.6742 | AQ20: 9000.0571 | AR20: 8000 | AS20: 3500 | AT20: 726.81516 | AU20: 3018.0416 | AV20: 2044.9997 | AW20: 369.61071 | AX20: 0 | AY20: 1121.9003 | AZ20: 1800 | BA20: 2499.7026 | BB20: 0 | BC20: 0 | BD20: 6600.0623
B21: =B20+1 -> 46154 | C21: =TEXT(B21,"ddd") -> Sel | D21: =SUM(E21:BD21) -> 218877.62 | E21: 1199.5729 | F21: 2000 | G21: 1129.7313 | H21: 3282.5161 | I21: 644.02065 | J21: 0 | K21: 499.97065 | L21: 603.76323 | M21: 673.27548 | N21: 5514.199 | O21: 6600.0623 | P21: 1000 | Q21: 16000 | R21: 4000 | S21: 48000 | T21: 5000 | U21: 7000 | V21: 0 | W21: 2000 | X21: 500 | Y21: 1000 | Z21: 5500 | AA21: 70.054839 | AB21: 89.451613 | AC21: 3500 | AD21: 1300 | AE21: 3000 | AF21: 5000 | AG21: 2020.8603 | AH21: 800 | AI21: 7200 | AJ21: 3499.8768 | AK21: 2043.2745 | AL21: 1999.5303 | AM21: 1000 | AN21: 11007.047 | AO21: 1519.5448 | AP21: 3999.6742 | AQ21: 9000.0571 | AR21: 8000 | AS21: 3500 | AT21: 726.81516 | AU21: 3018.0416 | AV21: 2044.9997 | AW21: 369.61071 | AX21: 0 | AY21: 1121.9003 | AZ21: 1800 | BA21: 2499.7026 | BB21: 0 | BC21: 20000 | BD21: 6600.0623
B22: =B21+1 -> 46155 | C22: =TEXT(B22,"ddd") -> Rab | D22: =SUM(E22:BD22) -> 218877.62 | E22: 1199.5729 | F22: 2000 | G22: 1129.7313 | H22: 3282.5161 | I22: 644.02065 | J22: 0 | K22: 499.97065 | L22: 603.76323 | M22: 673.27548 | N22: 5514.199 | O22: 6600.0623 | P22: 1000 | Q22: 16000 | R22: 4000 | S22: 48000 | T22: 5000 | U22: 7000 | V22: 0 | W22: 2000 | X22: 500 | Y22: 1000 | Z22: 5500 | AA22: 70.054839 | AB22: 89.451613 | AC22: 3500 | AD22: 1300 | AE22: 3000 | AF22: 5000 | AG22: 2020.8603 | AH22: 800 | AI22: 7200 | AJ22: 3499.8768 | AK22: 2043.2745 | AL22: 1999.5303 | AM22: 1000 | AN22: 11007.047 | AO22: 1519.5448 | AP22: 3999.6742 | AQ22: 9000.0571 | AR22: 8000 | AS22: 3500 | AT22: 726.81516 | AU22: 3018.0416 | AV22: 2044.9997 | AW22: 369.61071 | AX22: 0 | AY22: 1121.9003 | AZ22: 1800 | BA22: 2499.7026 | BB22: 0 | BC22: 20000 | BD22: 6600.0623
B23: =B22+1 -> 46156 | C23: =TEXT(B23,"ddd") -> Kam | D23: =SUM(E23:BD23) -> 179649.02 | E23: 1199.5729 | F23: 2000 | G23: 1129.7313 | H23: 3282.5161 | I23: 644.02065 | J23: 0 | K23: 499.97065 | L23: 603.76323 | M23: 673.27548 | N23: 5514.199 | O23: 0 | P23: 1000 | Q23: 6000 | R23: 4000 | S23: 60000 | T23: 5000 | U23: 0 | V23: 0 | W23: 0 | X23: 0 | Y23: 0 | Z23: 5500 | AA23: 70.054839 | AB23: 89.451613 | AC23: 3500 | AD23: 1300 | AE23: 0 | AF23: 0 | AG23: 2020.8603 | AH23: 800 | AI23: 7200 | AJ23: 3499.8768 | AK23: 2043.2745 | AL23: 0 | AM23: 1000 | AN23: 5000 | AO23: 1519.5448 | AP23: 3999.6742 | AQ23: 2000 | AR23: 8000 | AS23: 3500 | AT23: 726.81516 | AU23: 3018.0416 | AV23: 2044.9997 | AW23: 369.61071 | AX23: 0 | AY23: 0 | AZ23: 1800 | BA23: 2499.7026 | BB23: 0 | BC23: 20000 | BD23: 6600.0623
B24: =B23+1 -> 46157 | C24: =TEXT(B24,"ddd") -> Jum | D24: =SUM(E24:BD24) -> 211877.62 | E24: 1199.5729 | F24: 2000 | G24: 1129.7313 | H24: 3282.5161 | I24: 644.02065 | J24: 0 | K24: 499.97065 | L24: 603.76323 | M24: 673.27548 | N24: 5514.199 | O24: 6600.0623 | P24: 1000 | Q24: 16000 | R24: 4000 | S24: 48000 | T24: 5000 | U24: 7000 | V24: 0 | W24: 0 | X24: 500 | Y24: 1000 | Z24: 5500 | AA24: 70.054839 | AB24: 89.451613 | AC24: 3500 | AD24: 1300 | AE24: 3000 | AF24: 0 | AG24: 2020.8603 | AH24: 800 | AI24: 7200 | AJ24: 3499.8768 | AK24: 2043.2745 | AL24: 1999.5303 | AM24: 1000 | AN24: 11007.047 | AO24: 1519.5448 | AP24: 3999.6742 | AQ24: 9000.0571 | AR24: 8000 | AS24: 3500 | AT24: 726.81516 | AU24: 3018.0416 | AV24: 2044.9997 | AW24: 369.61071 | AX24: 0 | AY24: 1121.9003 | AZ24: 1800 | BA24: 2499.7026 | BB24: 0 | BC24: 20000 | BD24: 6600.0623
B25: =B24+1 -> 46158 | C25: =TEXT(B25,"ddd") -> Sab | D25: =SUM(E25:BD25) -> 217789.84 | E25: 733.5729 | F25: 2000 | G25: 1129.7313 | H25: 3282.5161 | I25: 644.02065 | J25: 0 | K25: 499.97065 | L25: 603.76323 | M25: 673.27548 | N25: 4514.199 | O25: 6600.0623 | P25: 1000 | Q25: 16000 | R25: 4000 | S25: 60000 | T25: 5000 | U25: 0 | V25: 0 | W25: 2000 | X25: 500 | Y25: 1000 | Z25: 5500 | AA25: 70.054839 | AB25: 89.451613 | AC25: 3500 | AD25: 1300 | AE25: 3000 | AF25: 5000 | AG25: 2020.8603 | AH25: 800 | AI25: 7200 | AJ25: 0 | AK25: 2043.2745 | AL25: 1999.5303 | AM25: 1000 | AN25: 11007.047 | AO25: 1519.5448 | AP25: 3999.6742 | AQ25: 9000.0571 | AR25: 8000 | AS25: 3500 | AT25: 726.81516 | AU25: 3018.0416 | AV25: 2044.9997 | AW25: 369.61071 | AX25: 0 | AY25: 0 | AZ25: 1800 | BA25: 2499.7026 | BB25: 0 | BC25: 20000 | BD25: 6600.0623
B26: =B25+1 -> 46159 | C26: =TEXT(B26,"ddd") -> Mgg | D26: =SUM(E26:BD26) -> 172352.01 | E26: 733.5729 | F26: 1000 | G26: 1129.7313 | H26: 999.51613 | I26: 644.02065 | J26: 0 | K26: 0 | L26: 603.76323 | M26: 673.27548 | N26: 0 | O26: 6600.0623 | P26: 300 | Q26: 6659.5545 | R26: 4000 | S26: 60000 | T26: 5000 | U26: 0 | V26: 0 | W26: 2000 | X26: 500 | Y26: 0 | Z26: 2500 | AA26: 70.054839 | AB26: 89.451613 | AC26: 1000 | AD26: 1300 | AE26: 0 | AF26: 5000 | AG26: 2020.8603 | AH26: 0 | AI26: 2999.8519 | AJ26: 0 | AK26: 2043.2745 | AL26: 1999.5303 | AM26: 0 | AN26: 11007.047 | AO26: 1519.5448 | AP26: 3999.6742 | AQ26: 6000.0571 | AR26: 6000 | AS26: 3500 | AT26: 726.81516 | AU26: 3018.0416 | AV26: 2044.9997 | AW26: 369.61071 | AX26: 0 | AY26: 0 | AZ26: 1800 | BA26: 2499.7026 | BB26: 0 | BC26: 20000 | BD26: 0
B27: Sub Total | D27: =SUM(D20:D26) -> 1406301.3 | E27: =SUM(E20:E26) -> 7465.0103 | F27: =SUM(F20:F26) -> 13000 | G27: =SUM(G20:G26) -> 7908.119 | H27: =SUM(H20:H26) -> 20694.613 | I27: =SUM(I20:I26) -> 4508.1445 | J27: =SUM(J20:J26) -> 0 | K27: =SUM(K20:K26) -> 2999.8239 | ... BD27: =SUM(BD20:BD26) -> 39600.374
A29: =WEEKNUM(B29) -> 21 | B29: =B26+1 -> 46160 | C29: =TEXT(B29,"ddd") -> Sen | D29: =SUM(E29:BD29) -> 212877.62 | E29: 1199.5729 | F29: 2000 | G29: 1129.7313 | H29: 3282.5161 | I29: 644.02065 | J29: 0 | K29: 499.97065 | L29: 603.76323 | M29: 673.27548 | N29: 5514.199 | O29: 6600.0623 | P29: 1000 | Q29: 16000 | R29: 4000 | S29: 42000 | T29: 5000 | U29: 7000 | V29: 0 | W29: 2000 | X29: 500 | Y29: 1000 | Z29: 5500 | AA29: 70.054839 | AB29: 89.451613 | AC29: 3500 | AD29: 1300 | AE29: 3000 | AF29: 5000 | AG29: 2020.8603 | AH29: 800 | AI29: 7200 | AJ29: 3499.8768 | AK29: 2043.2745 | AL29: 1999.5303 | AM29: 1000 | AN29: 11007.047 | AO29: 1519.5448 | AP29: 3999.6742 | AQ29: 9000.0571 | AR29: 8000 | AS29: 3500 | AT29: 726.81516 | AU29: 3018.0416 | AV29: 2044.9997 | AW29: 369.61071 | AX29: 0 | AY29: 1121.9003 | AZ29: 1800 | BA29: 2499.7026 | BB29: 0 | BC29: 20000 | BD29: 6600.0623
B30: =B29+1 -> 46161 | C30: =TEXT(B30,"ddd") -> Sel | D30: =SUM(E30:BD30) -> 212877.62 | E30: 1199.5729 | F30: 2000 | G30: 1129.7313 | H30: 3282.5161 | I30: 644.02065 | J30: 0 | K30: 499.97065 | L30: 603.76323 | M30: 673.27548 | N30: 5514.199 | O30: 6600.0623 | P30: 1000 | Q30: 16000 | R30: 4000 | S30: 42000 | T30: 5000 | U30: 7000 | V30: 0 | W30: 2000 | X30: 500 | Y30: 1000 | Z30: 5500 | AA30: 70.054839 | AB30: 89.451613 | AC30: 3500 | AD30: 1300 | AE30: 3000 | AF30: 5000 | AG30: 2020.8603 | AH30: 800 | AI30: 7200 | AJ30: 3499.8768 | AK30: 2043.2745 | AL30: 1999.5303 | AM30: 1000 | AN30: 11007.047 | AO30: 1519.5448 | AP30: 3999.6742 | AQ30: 9000.0571 | AR30: 8000 | AS30: 3500 | AT30: 726.81516 | AU30: 3018.0416 | AV30: 2044.9997 | AW30: 369.61071 | AX30: 0 | AY30: 1121.9003 | AZ30: 1800 | BA30: 2499.7026 | BB30: 0 | BC30: 20000 | BD30: 6600.0623
B31: =B30+1 -> 46162 | C31: =TEXT(B31,"ddd") -> Rab | D31: =SUM(E31:BD31) -> 212877.62 | E31: 1199.5729 | F31: 2000 | G31: 1129.7313 | H31: 3282.5161 | I31: 644.02065 | J31: 0 | K31: 499.97065 | L31: 603.76323 | M31: 673.27548 | N31: 5514.199 | O31: 6600.0623 | P31: 1000 | Q31: 16000 | R31: 4000 | S31: 42000 | T31: 5000 | U31: 7000 | V31: 0 | W31: 2000 | X31: 500 | Y31: 1000 | Z31: 5500 | AA31: 70.054839 | AB31: 89.451613 | AC31: 3500 | AD31: 1300 | AE31: 3000 | AF31: 5000 | AG31: 2020.8603 | AH31: 800 | AI31: 7200 | AJ31: 3499.8768 | AK31: 2043.2745 | AL31: 1999.5303 | AM31: 1000 | AN31: 11007.047 | AO31: 1519.5448 | AP31: 3999.6742 | AQ31: 9000.0571 | AR31: 8000 | AS31: 3500 | AT31: 726.81516 | AU31: 3018.0416 | AV31: 2044.9997 | AW31: 369.61071 | AX31: 0 | AY31: 1121.9003 | AZ31: 1800 | BA31: 2499.7026 | BB31: 0 | BC31: 20000 | BD31: 6600.0623
B32: =B31+1 -> 46163 | C32: =TEXT(B32,"ddd") -> Kam | D32: =SUM(E32:BD32) -> 212877.62 | E32: 1199.5729 | F32: 2000 | G32: 1129.7313 | H32: 3282.5161 | I32: 644.02065 | J32: 0 | K32: 499.97065 | L32: 603.76323 | M32: 673.27548 | N32: 5514.199 | O32: 6600.0623 | P32: 1000 | Q32: 16000 | R32: 4000 | S32: 42000 | T32: 5000 | U32: 7000 | V32: 0 | W32: 2000 | X32: 500 | Y32: 1000 | Z32: 5500 | AA32: 70.054839 | AB32: 89.451613 | AC32: 3500 | AD32: 1300 | AE32: 3000 | AF32: 5000 | AG32: 2020.8603 | AH32: 800 | AI32: 7200 | AJ32: 3499.8768 | AK32: 2043.2745 | AL32: 1999.5303 | AM32: 1000 | AN32: 11007.047 | AO32: 1519.5448 | AP32: 3999.6742 | AQ32: 9000.0571 | AR32: 8000 | AS32: 3500 | AT32: 726.81516 | AU32: 3018.0416 | AV32: 2044.9997 | AW32: 369.61071 | AX32: 0 | AY32: 1121.9003 | AZ32: 1800 | BA32: 2499.7026 | BB32: 0 | BC32: 20000 | BD32: 6600.0623
B33: =B32+1 -> 46164 | C33: =TEXT(B33,"ddd") -> Jum | D33: =SUM(E33:BD33) -> 201277.55 | E33: 1199.5729 | F33: 2000 | G33: 1129.7313 | H33: 3282.5161 | I33: 644.02065 | J33: 0 | K33: 499.97065 | L33: 603.76323 | M33: 673.27548 | N33: 5514.199 | O33: 6600.0623 | P33: 1000 | Q33: 16000 | R33: 4000 | S33: 42000 | T33: 5000 | U33: 7000 | V33: 0 | W33: 2000 | X33: 500 | Y33: 1000 | Z33: 5500 | AA33: 70.054839 | AB33: 89.451613 | AC33: 3500 | AD33: 1300 | AE33: 3000 | AF33: 5000 | AG33: 2020.8603 | AH33: 800 | AI33: 7200 | AJ33: 3499.8768 | AK33: 2043.2745 | AL33: 1999.5303 | AM33: 1000 | AN33: 11007.047 | AO33: 1519.5448 | AP33: 3999.6742 | AQ33: 9000.0571 | AR33: 8000 | AS33: 3500 | AT33: 726.81516 | AU33: 3018.0416 | AV33: 2044.9997 | AW33: 369.61071 | AX33: 0 | AY33: 1121.9003 | AZ33: 1800 | BA33: 2499.7026 | BB33: 0 | BC33: 15000 | BD33: 0
B34: =B33+1 -> 46165 | C34: =TEXT(B34,"ddd") -> Sab | D34: =SUM(E34:BD34) -> 206189.78 | E34: 733.5729 | F34: 2000 | G34: 1129.7313 | H34: 3282.5161 | I34: 644.02065 | J34: 0 | K34: 499.97065 | L34: 603.76323 | M34: 673.27548 | N34: 4514.199 | O34: 6600.0623 | P34: 1000 | Q34: 16000 | R34: 4000 | S34: 60000 | T34: 5000 | U34: 0 | V34: 0 | W34: 2000 | X34: 500 | Y34: 1000 | Z34: 5500 | AA34: 70.054839 | AB34: 89.451613 | AC34: 3500 | AD34: 1300 | AE34: 3000 | AF34: 5000 | AG34: 2020.8603 | AH34: 800 | AI34: 7200 | AJ34: 0 | AK34: 2043.2745 | AL34: 1999.5303 | AM34: 1000 | AN34: 11007.047 | AO34: 1519.5448 | AP34: 3999.6742 | AQ34: 9000.0571 | AR34: 8000 | AS34: 3500 | AT34: 726.81516 | AU34: 3018.0416 | AV34: 2044.9997 | AW34: 369.61071 | AX34: 0 | AY34: 0 | AZ34: 1800 | BA34: 2499.7026 | BB34: 0 | BC34: 15000 | BD34: 0
B35: =B34+1 -> 46166 | C35: =TEXT(B35,"ddd") -> Mgg | D35: =SUM(E35:BD35) -> 167352.01 | E35: 733.5729 | F35: 1000 | G35: 1129.7313 | H35: 999.51613 | I35: 644.02065 | J35: 0 | K35: 0 | L35: 603.76323 | M35: 673.27548 | N35: 0 | O35: 6600.0623 | P35: 300 | Q35: 6659.5545 | R35: 4000 | S35: 60000 | T35: 5000 | U35: 0 | V35: 0 | W35: 2000 | X35: 500 | Y35: 0 | Z35: 2500 | AA35: 70.054839 | AB35: 89.451613 | AC35: 1000 | AD35: 1300 | AE35: 0 | AF35: 5000 | AG35: 2020.8603 | AH35: 0 | AI35: 2999.8519 | AJ35: 0 | AK35: 2043.2745 | AL35: 1999.5303 | AM35: 0 | AN35: 11007.047 | AO35: 1519.5448 | AP35: 3999.6742 | AQ35: 6000.0571 | AR35: 6000 | AS35: 3500 | AT35: 726.81516 | AU35: 3018.0416 | AV35: 2044.9997 | AW35: 369.61071 | AX35: 0 | AY35: 0 | AZ35: 1800 | BA35: 2499.7026 | BB35: 0 | BC35: 15000 | BD35: 0
B36: Sub Total | D36: =SUM(D29:D35) -> 1426329.8 | E36: =SUM(E29:E35) -> 7465.0103 | F36: =SUM(F29:F35) -> 13000 | G36: =SUM(G29:G35) -> 7908.119 | H36: =SUM(H29:H35) -> 20694.613 | I36: =SUM(I29:I35) -> 4508.1445 | J36: =SUM(J29:J35) -> 0 | K36: =SUM(K29:K35) -> 2999.8239 | ... BD36: =SUM(BD29:BD35) -> 26400.249
A38: =WEEKNUM(B38) -> 22 | B38: =B35+1 -> 46167 | C38: =TEXT(B38,"ddd") -> Sen | D38: =SUM(E38:BD38) -> 196277.55 | E38: 1199.5729 | F38: 2000 | G38: 1129.7313 | H38: 3282.5161 | I38: 644.02065 | J38: 0 | K38: 499.97065 | L38: 603.76323 | M38: 673.27548 | N38: 5514.199 | O38: 6600.0623 | P38: 1000 | Q38: 16000 | R38: 4000 | S38: 42000 | T38: 0 | U38: 7000 | V38: 0 | W38: 2000 | X38: 500 | Y38: 1000 | Z38: 5500 | AA38: 70.054839 | AB38: 89.451613 | AC38: 3500 | AD38: 1300 | AE38: 3000 | AF38: 5000 | AG38: 2020.8603 | AH38: 800 | AI38: 7200 | AJ38: 3499.8768 | AK38: 2043.2745 | AL38: 1999.5303 | AM38: 1000 | AN38: 11007.047 | AO38: 1519.5448 | AP38: 3999.6742 | AQ38: 9000.0571 | AR38: 8000 | AS38: 3500 | AT38: 726.81516 | AU38: 3018.0416 | AV38: 2044.9997 | AW38: 369.61071 | AX38: 0 | AY38: 1121.9003 | AZ38: 1800 | BA38: 2499.7026 | BB38: 0 | BC38: 15000 | BD38: 0
B39: =B38+1 -> 46168 | C39: =TEXT(B39,"ddd") -> Sel | D39: =SUM(E39:BD39) -> 196277.55 | E39: 1199.5729 | F39: 2000 | G39: 1129.7313 | H39: 3282.5161 | I39: 644.02065 | J39: 0 | K39: 499.97065 | L39: 603.76323 | M39: 673.27548 | N39: 5514.199 | O39: 6600.0623 | P39: 1000 | Q39: 16000 | R39: 4000 | S39: 42000 | T39: 0 | U39: 7000 | V39: 0 | W39: 2000 | X39: 500 | Y39: 1000 | Z39: 5500 | AA39: 70.054839 | AB39: 89.451613 | AC39: 3500 | AD39: 1300 | AE39: 3000 | AF39: 5000 | AG39: 2020.8603 | AH39: 800 | AI39: 7200 | AJ39: 3499.8768 | AK39: 2043.2745 | AL39: 1999.5303 | AM39: 1000 | AN39: 11007.047 | AO39: 1519.5448 | AP39: 3999.6742 | AQ39: 9000.0571 | AR39: 8000 | AS39: 3500 | AT39: 726.81516 | AU39: 3018.0416 | AV39: 2044.9997 | AW39: 369.61071 | AX39: 0 | AY39: 1121.9003 | AZ39: 1800 | BA39: 2499.7026 | BB39: 0 | BC39: 15000 | BD39: 0
B40: =B39+1 -> 46169 | C40: =TEXT(B40,"ddd") -> Rab | D40: =SUM(E40:BD40) -> 116944.64 | E40: 0 | F40: 0 | G40: 500 | H40: 1000 | I40: 644.02065 | J40: 0 | K40: 499.97065 | L40: 603.76323 | M40: 673.27548 | N40: 0 | O40: 0 | P40: 0 | Q40: 6000 | R40: 4000 | S40: 60000 | T40: 0 | U40: 0 | V40: 0 | W40: 2000 | X40: 0 | Y40: 0 | Z40: 0 | AA40: 70.054839 | AB40: 89.451613 | AC40: 0 | AD40: 1300 | AE40: 0 | AF40: 0 | AG40: 0 | AH40: 0 | AI40: 0 | AJ40: 0 | AK40: 0 | AL40: 0 | AM40: 0 | AN40: 5000 | AO40: 1519.5448 | AP40: 0 | AQ40: 2000 | AR40: 8000 | AS40: 0 | AT40: 726.81516 | AU40: 3018.0416 | AV40: 0 | AW40: 0 | AX40: 0 | AY40: 0 | AZ40: 1800 | BA40: 2499.7026 | BB40: 0 | BC40: 15000 | BD40: 0
B41: =B40+1 -> 46170 | C41: =TEXT(B41,"ddd") -> Kam | D41: =SUM(E41:BD41) -> 158565.95 | E41: 0 | F41: 1000 | G41: 500 | H41: 1000 | I41: 644.02065 | J41: 0 | K41: 499.97065 | L41: 603.76323 | M41: 673.27548 | N41: 5514.199 | O41: 6600.0623 | P41: 0 | Q41: 16000 | R41: 4000 | S41: 60000 | T41: 0 | U41: 7000 | V41: 0 | W41: 2000 | X41: 500 | Y41: 0 | Z41: 0 | AA41: 70.054839 | AB41: 89.451613 | AC41: 0 | AD41: 1300 | AE41: 0 | AF41: 5000 | AG41: 0 | AH41: 0 | AI41: 0 | AJ41: 0 | AK41: 0 | AL41: 0 | AM41: 0 | AN41: 11007.047 | AO41: 1519.5448 | AP41: 0 | AQ41: 2000 | AR41: 8000 | AS41: 0 | AT41: 726.81516 | AU41: 3018.0416 | AV41: 0 | AW41: 0 | AX41: 0 | AY41: 0 | AZ41: 1800 | BA41: 2499.7026 | BB41: 0 | BC41: 15000 | BD41: 0
B42: =B41+1 -> 46171 | C42: =TEXT(B42,"ddd") -> Jum | D42: =SUM(E42:BD42) -> 202277.55 | E42: 1199.5729 | F42: 2000 | G42: 1129.7313 | H42: 3282.5161 | I42: 644.02065 | J42: 0 | K42: 499.97065 | L42: 603.76323 | M42: 673.27548 | N42: 5514.199 | O42: 6600.0623 | P42: 1000 | Q42: 16000 | R42: 4000 | S42: 48000 | T42: 0 | U42: 7000 | V42: 0 | W42: 2000 | X42: 500 | Y42: 1000 | Z42: 5500 | AA42: 70.054839 | AB42: 89.451613 | AC42: 3500 | AD42: 1300 | AE42: 3000 | AF42: 5000 | AG42: 2020.8603 | AH42: 800 | AI42: 7200 | AJ42: 3499.8768 | AK42: 2043.2745 | AL42: 1999.5303 | AM42: 1000 | AN42: 11007.047 | AO42: 1519.5448 | AP42: 3999.6742 | AQ42: 9000.0571 | AR42: 8000 | AS42: 3500 | AT42: 726.81516 | AU42: 3018.0416 | AV42: 2044.9997 | AW42: 369.61071 | AX42: 0 | AY42: 1121.9003 | AZ42: 1800 | BA42: 2499.7026 | BB42: 0 | BC42: 15000 | BD42: 0
B43: =B42+1 -> 46172 | C43: =TEXT(B43,"ddd") -> Sab | D43: =SUM(E43:BD43) -> 201189.78 | E43: 733.5729 | F43: 2000 | G43: 1129.7313 | H43: 3282.5161 | I43: 644.02065 | J43: 0 | K43: 499.97065 | L43: 603.76323 | M43: 673.27548 | N43: 4514.199 | O43: 6600.0623 | P43: 1000 | Q43: 16000 | R43: 4000 | S43: 60000 | T43: 0 | U43: 0 | V43: 0 | W43: 2000 | X43: 500 | Y43: 1000 | Z43: 5500 | AA43: 70.054839 | AB43: 89.451613 | AC43: 3500 | AD43: 1300 | AE43: 3000 | AF43: 5000 | AG43: 2020.8603 | AH43: 800 | AI43: 7200 | AJ43: 0 | AK43: 2043.2745 | AL43: 1999.5303 | AM43: 1000 | AN43: 11007.047 | AO43: 1519.5448 | AP43: 3999.6742 | AQ43: 9000.0571 | AR43: 8000 | AS43: 3500 | AT43: 726.81516 | AU43: 3018.0416 | AV43: 2044.9997 | AW43: 369.61071 | AX43: 0 | AY43: 0 | AZ43: 1800 | BA43: 2499.7026 | BB43: 0 | BC43: 15000 | BD43: 0
B44: =B43+1 -> 46173 | C44: =TEXT(B44,"ddd") -> Mgg | D44: =SUM(E44:BD44) -> 129553.09 | E44: 733.5729 | F44: 1000 | G44: 500 | H44: 999.51613 | I44: 644.02065 | J44: 0 | K44: 0 | L44: 603.76323 | M44: 673.27548 | N44: 0 | O44: 0 | P44: 300 | Q44: 6659.5545 | R44: 4000 | S44: 60000 | T44: 0 | U44: 0 | V44: 0 | W44: 2000 | X44: 0 | Y44: 0 | Z44: 0 | AA44: 70.054839 | AB44: 89.451613 | AC44: 1000 | AD44: 1300 | AE44: 0 | AF44: 0 | AG44: 2020.8603 | AH44: 0 | AI44: 2999.8519 | AJ44: 0 | AK44: 0 | AL44: 0 | AM44: 0 | AN44: 5000 | AO44: 0 | AP44: 2000 | AQ44: 2000 | AR44: 6000 | AS44: 3500 | AT44: 726.81516 | AU44: 3018.0416 | AV44: 2044.9997 | AW44: 369.61071 | AX44: 0 | AY44: 0 | AZ44: 1800 | BA44: 2499.7026 | BB44: 0 | BC44: 15000 | BD44: 0
...

Sheet KEBUTUHAN GAS
A1: KEBUTUHAN GAS
A4: ='SO MEI 2026 REV 4'!A3 -> 46143 | E4: KEBUTUHAN GAS | I4: KUOTA GAS
A5: Week | B5: DATE | D5: SELISIH GAS | E5: JABAR | F5: JATENG | G5: JATIM | H5: TOTAL | I5: MS SETU | J5: MS KHT | K5: MS BLORA | L5: MS BITUNG | M5: MS ZEBRA | N5: MS TAMBAKLOROK | O5: MS WUNUT | P5: MS SADANG | Q5: TOTAL
A6: =WEEKNUM(B6) -> 18 | B6: =A4 -> 46143 | C6: =TEXT(B6,"ddd") -> Jum | D6: =Q6-H6 -> 29884.148 | E6: =SUM('SO MEI 2026 REV 4'!E6:AS6) -> 101571.29 | F6: =SUM('SO MEI 2026 REV 4'!AT6:BA6) -> 8044.5594 | G6: =SUM('SO MEI 2026 REV 4'!BB6:BD6) -> 0 | H6: =SUM(E6:G6) -> 109615.85 | I6: ='SO MS'!E6 -> 84000 | J6: ='SO MS'!F6 -> 33600 | K6: ='SO MS'!G6 -> 9600 | L6: =2*5000 -> 10000 | M6: ='SO MEI 2026 REV 4'!AZ6 -> 1800 | N6: ='SO MEI 2026 REV 4'!AS6 -> 500 | O6: ='SO MEI 2026 REV 4'!AY6 -> 0 | Q6: =SUM(I6:P6) -> 139500
B7: =B6+1 -> 46144 | C7: =TEXT(B7,"ddd") -> Sab | D7: =Q7-H7 -> -30330.559 | E7: =SUM('SO MEI 2026 REV 4'!E7:AS7) -> 159371.39 | F7: =SUM('SO MEI 2026 REV 4'!AT7:BA7) -> 10459.17 | G7: =SUM('SO MEI 2026 REV 4'!BB7:BD7) -> 0 | H7: =SUM(E7:G7) -> 169830.56 | I7: ='SO MS'!E7 -> 84000 | J7: ='SO MS'!F7 -> 33600 | K7: ='SO MS'!G7 -> 9600 | L7: =2*5000 -> 10000 | M7: ='SO MEI 2026 REV 4'!AZ7 -> 1800 | N7: ='SO MEI 2026 REV 4'!AS7 -> 500 | O7: ='SO MEI 2026 REV 4'!AY7 -> 0 | Q7: =SUM(I7:P7) -> 139500
B8: =B7+1 -> 46145 | C8: =TEXT(B8,"ddd") -> Mgg | D8: =Q8-H8 -> -6452.0133 | E8: =SUM('SO MEI 2026 REV 4'!E8:AS8) -> 131892.84 | F8: =SUM('SO MEI 2026 REV 4'!AT8:BA8) -> 10459.17 | G8: =SUM('SO MEI 2026 REV 4'!BB8:BD8) -> 6600 | H8: =SUM(E8:G8) -> 148952.01 | I8: ='SO MS'!E8 -> 84000 | J8: ='SO MS'!F8 -> 33600 | K8: ='SO MS'!G8 -> 9600 | L8: =2*5000 -> 10000 | M8: ='SO MEI 2026 REV 4'!AZ8 -> 1800 | N8: ='SO MEI 2026 REV 4'!AS8 -> 3500 | O8: ='SO MEI 2026 REV 4'!AY8 -> 0 | Q8: =SUM(I8:P8) -> 142500
B9: Sub Total | D9: =SUM(D6:D8) -> -6898.425 | E9: =SUM(E6:E8) -> 392835.53 | F9: =SUM(F6:F8) -> 28962.899 | G9: =SUM(G6:G8) -> 6600 | H9: =SUM(H6:H8) -> 428398.43 | I9: =SUM(I6:I8) -> 252000 | J9: =SUM(J6:J8) -> 100800 | K9: =SUM(K6:K8) -> 28800 | ... Q9: =SUM(Q6:Q8) -> 421500
A11: =WEEKNUM(B11) -> 19 | B11: =B8+1 -> 46146 | C11: =TEXT(B11,"ddd") -> Sen | D11: =Q11-H11 -> -36630.042 | E11: =SUM('SO MEI 2026 REV 4'!E11:AS11) -> 162070.81 | F11: =SUM('SO MEI 2026 REV 4'!AT11:BA11) -> 11581.07 | G11: =SUM('SO MEI 2026 REV 4'!BB11:BD11) -> 6600.0623 | H11: =SUM(E11:G11) -> 180251.94 | I11: ='SO MS'!E11 -> 84000 | J11: ='SO MS'!F11 -> 33600 | K11: ='SO MS'!G11 -> 9600 | L11: =2*5000 -> 10000 | M11: ='SO MEI 2026 REV 4'!AZ11 -> 1800 | N11: ='SO MEI 2026 REV 4'!AS11 -> 3500 | O11: ='SO MEI 2026 REV 4'!AY11 -> 1121.9003 | Q11: =SUM(I11:P11) -> 143621.9
B12: =B11+1 -> 46147 | C12: =TEXT(B12,"ddd") -> Sel | D12: =Q12-H12 -> -36630.042 | E12: =SUM('SO MEI 2026 REV 4'!E12:AS12) -> 162070.81 | F12: =SUM('SO MEI 2026 REV 4'!AT12:BA12) -> 11581.07 | G12: =SUM('SO MEI 2026 REV 4'!BB12:BD12) -> 6600.0623 | H12: =SUM(E12:G12) -> 180251.94 | I12: ='SO MS'!E12 -> 84000 | J12: ='SO MS'!F12 -> 33600 | K12: ='SO MS'!G12 -> 9600 | L12: =2*5000 -> 10000 | M12: ='SO MEI 2026 REV 4'!AZ12 -> 1800 | N12: ='SO MEI 2026 REV 4'!AS12 -> 3500 | O12: ='SO MEI 2026 REV 4'!AY12 -> 1121.9003 | Q12: =SUM(I12:P12) -> 143621.9
B13: =B12+1 -> 46148 | C13: =TEXT(B13,"ddd") -> Rab | D13: =Q13-H13 -> -46130.042 | E13: =SUM('SO MEI 2026 REV 4'!E13:AS13) -> 171570.81 | F13: =SUM('SO MEI 2026 REV 4'!AT13:BA13) -> 11581.07 | G13: =SUM('SO MEI 2026 REV 4'!BB13:BD13) -> 6600.0623 | H13: =SUM(E13:G13) -> 189751.94 | I13: ='SO MS'!E13 -> 84000 | J13: ='SO MS'!F13 -> 33600 | K13: ='SO MS'!G13 -> 9600 | L13: =2*5000 -> 10000 | M13: ='SO MEI 2026 REV 4'!AZ13 -> 1800 | N13: ='SO MEI 2026 REV 4'!AS13 -> 3500 | O13: ='SO MEI 2026 REV 4'!AY13 -> 1121.9003 | Q13: =SUM(I13:P13) -> 143621.9
B14: =B13+1 -> 46149 | C14: =TEXT(B14,"ddd") -> Kam | D14: =Q14-H14 -> -46130.042 | E14: =SUM('SO MEI 2026 REV 4'!E14:AS14) -> 171570.81 | F14: =SUM('SO MEI 2026 REV 4'!AT14:BA14) -> 11581.07 | G14: =SUM('SO MEI 2026 REV 4'!BB14:BD14) -> 6600.0623 | H14: =SUM(E14:G14) -> 189751.94 | I14: ='SO MS'!E14 -> 84000 | J14: ='SO MS'!F14 -> 33600 | K14: ='SO MS'!G14 -> 9600 | L14: =2*5000 -> 10000 | M14: ='SO MEI 2026 REV 4'!AZ14 -> 1800 | N14: ='SO MEI 2026 REV 4'!AS14 -> 3500 | O14: ='SO MEI 2026 REV 4'!AY14 -> 1121.9003 | Q14: =SUM(I14:P14) -> 143621.9
B15: =B14+1 -> 46150 | C15: =TEXT(B15,"ddd") -> Jum | D15: =Q15-H15 -> -46130.042 | E15: =SUM('SO MEI 2026 REV 4'!E15:AS15) -> 171570.81 | F15: =SUM('SO MEI 2026 REV 4'!AT15:BA15) -> 11581.07 | G15: =SUM('SO MEI 2026 REV 4'!BB15:BD15) -> 6600.0623 | H15: =SUM(E15:G15) -> 189751.94 | I15: ='SO MS'!E15 -> 84000 | J15: ='SO MS'!F15 -> 33600 | K15: ='SO MS'!G15 -> 9600 | L15: =2*5000 -> 10000 | M15: ='SO MEI 2026 REV 4'!AZ15 -> 1800 | N15: ='SO MEI 2026 REV 4'!AS15 -> 3500 | O15: ='SO MEI 2026 REV 4'!AY15 -> 1121.9003 | Q15: =SUM(I15:P15) -> 143621.9
B16: =B15+1 -> 46151 | C16: =TEXT(B16,"ddd") -> Sab | D16: =Q16-H16 -> -34164.165 | E16: =SUM('SO MEI 2026 REV 4'!E16:AS16) -> 159604.93 | F16: =SUM('SO MEI 2026 REV 4'!AT16:BA16) -> 10459.17 | G16: =SUM('SO MEI 2026 REV 4'!BB16:BD16) -> 6600.0623 | H16: =SUM(E16:G16) -> 176664.17 | I16: ='SO MS'!E16 -> 84000 | J16: ='SO MS'!F16 -> 33600 | K16: ='SO MS'!G16 -> 9600 | L16: =2*5000 -> 10000 | M16: ='SO MEI 2026 REV 4'!AZ16 -> 1800 | N16: ='SO MEI 2026 REV 4'!AS16 -> 3500 | O16: ='SO MEI 2026 REV 4'!AY16 -> 0 | Q16: =SUM(I16:P16) -> 142500
B17: =B16+1 -> 46152 | C17: =TEXT(B17,"ddd") -> Mgg | D17: =Q17-H17 -> 14147.987 | E17: =SUM('SO MEI 2026 REV 4'!E17:AS17) -> 117892.84 | F17: =SUM('SO MEI 2026 REV 4'!AT17:BA17) -> 10459.17 | G17: =SUM('SO MEI 2026 REV 4'!BB17:BD17) -> 0 | H17: =SUM(E17:G17) -> 128352.01 | I17: ='SO MS'!E17 -> 84000 | J17: ='SO MS'!F17 -> 33600 | K17: ='SO MS'!G17 -> 9600 | L17: =2*5000 -> 10000 | M17: ='SO MEI 2026 REV 4'!AZ17 -> 1800 | N17: ='SO MEI 2026 REV 4'!AS17 -> 3500 | O17: ='SO MEI 2026 REV 4'!AY17 -> 0 | Q17: =SUM(I17:P17) -> 142500
B18: Sub Total | D18: =SUM(D11:D17) -> -231666.39 | E18: =SUM(E11:E17) -> 1116351.8 | F18: =SUM(F11:F17) -> 78823.69 | G18: =SUM(G11:G17) -> 39600.374 | H18: =SUM(H11:H17) -> 1234775.9 | I18: =SUM(I11:I17) -> 588000 | J18: =SUM(J11:J17) -> 235200 | K18: =SUM(K11:K17) -> 67200 | ... Q18: =SUM(Q11:Q17) -> 1003109.5
A20: =WEEKNUM(B20) -> 20 | B20: =B17+1 -> 46153 | C20: =TEXT(B20,"ddd") -> Sen | D20: =Q20-H20 -> -43255.716 | E20: =SUM('SO MEI 2026 REV 4'!E20:AS20) -> 168696.48 | F20: =SUM('SO MEI 2026 REV 4'!AT20:BA20) -> 11581.07 | G20: =SUM('SO MEI 2026 REV 4'!BB20:BD20) -> 6600.0623 | H20: =SUM(E20:G20) -> 186877.62 | I20: ='SO MS'!E20 -> 84000 | J20: ='SO MS'!F20 -> 33600 | K20: ='SO MS'!G20 -> 9600 | L20: =2*5000 -> 10000 | M20: ='SO MEI 2026 REV 4'!AZ20 -> 1800 | N20: ='SO MEI 2026 REV 4'!AS20 -> 3500 | O20: ='SO MEI 2026 REV 4'!AY20 -> 1121.9003 | Q20: =SUM(I20:P20) -> 143621.9
B21: =B20+1 -> 46154 | C21: =TEXT(B21,"ddd") -> Sel | D21: =Q21-H21 -> -75255.716 | E21: =SUM('SO MEI 2026 REV 4'!E21:AS21) -> 180696.48 | F21: =SUM('SO MEI 2026 REV 4'!AT21:BA21) -> 11581.07 | G21: =SUM('SO MEI 2026 REV 4'!BB21:BD21) -> 26600.062 | H21: =SUM(E21:G21) -> 218877.62 | I21: ='SO MS'!E21 -> 84000 | J21: ='SO MS'!F21 -> 33600 | K21: ='SO MS'!G21 -> 9600 | L21: =2*5000 -> 10000 | M21: ='SO MEI 2026 REV 4'!AZ21 -> 1800 | N21: ='SO MEI 2026 REV 4'!AS21 -> 3500 | O21: ='SO MEI 2026 REV 4'!AY21 -> 1121.9003 | Q21: =SUM(I21:P21) -> 143621.9
B22: =B21+1 -> 46155 | C22: =TEXT(B22,"ddd") -> Rab | D22: =Q22-H22 -> -75255.716 | E22: =SUM('SO MEI 2026 REV 4'!E22:AS22) -> 180696.48 | F22: =SUM('SO MEI 2026 REV 4'!AT22:BA22) -> 11581.07 | G22: =SUM('SO MEI 2026 REV 4'!BB22:BD22) -> 26600.062 | H22: =SUM(E22:G22) -> 218877.62 | I22: ='SO MS'!E22 -> 84000 | J22: ='SO MS'!F22 -> 33600 | K22: ='SO MS'!G22 -> 9600 | L22: =2*5000 -> 10000 | M22: ='SO MEI 2026 REV 4'!AZ22 -> 1800 | N22: ='SO MEI 2026 REV 4'!AS22 -> 3500 | O22: ='SO MEI 2026 REV 4'!AY22 -> 1121.9003 | Q22: =SUM(I22:P22) -> 143621.9
B23: =B22+1 -> 46156 | C23: =TEXT(B23,"ddd") -> Kam | D23: =Q23-H23 -> -37149.018 | E23: =SUM('SO MEI 2026 REV 4'!E23:AS23) -> 142589.79 | F23: =SUM('SO MEI 2026 REV 4'!AT23:BA23) -> 10459.17 | G23: =SUM('SO MEI 2026 REV 4'!BB23:BD23) -> 26600.062 | H23: =SUM(E23:G23) -> 179649.02 | I23: ='SO MS'!E23 -> 84000 | J23: ='SO MS'!F23 -> 33600 | K23: ='SO MS'!G23 -> 9600 | L23: =2*5000 -> 10000 | M23: ='SO MEI 2026 REV 4'!AZ23 -> 1800 | N23: ='SO MEI 2026 REV 4'!AS23 -> 3500 | O23: ='SO MEI 2026 REV 4'!AY23 -> 0 | Q23: =SUM(I23:P23) -> 142500
B24: =B23+1 -> 46157 | C24: =TEXT(B24,"ddd") -> Jum | D24: =Q24-H24 -> -68255.716 | E24: =SUM('SO MEI 2026 REV 4'!E24:AS24) -> 173696.48 | F24: =SUM('SO MEI 2026 REV 4'!AT24:BA24) -> 11581.07 | G24: =SUM('SO MEI 2026 REV 4'!BB24:BD24) -> 26600.062 | H24: =SUM(E24:G24) -> 211877.62 | I24: ='SO MS'!E24 -> 84000 | J24: ='SO MS'!F24 -> 33600 | K24: ='SO MS'!G24 -> 9600 | L24: =2*5000 -> 10000 | M24: ='SO MEI 2026 REV 4'!AZ24 -> 1800 | N24: ='SO MEI 2026 REV 4'!AS24 -> 3500 | O24: ='SO MEI 2026 REV 4'!AY24 -> 1121.9003 | Q24: =SUM(I24:P24) -> 143621.9
B25: =B24+1 -> 46158 | C25: =TEXT(B25,"ddd") -> Sab | D25: =Q25-H25 -> -75289.839 | E25: =SUM('SO MEI 2026 REV 4'!E25:AS25) -> 180730.61 | F25: =SUM('SO MEI 2026 REV 4'!AT25:BA25) -> 10459.17 | G25: =SUM('SO MEI 2026 REV 4'!BB25:BD25) -> 26600.062 | H25: =SUM(E25:G25) -> 217789.84 | I25: ='SO MS'!E25 -> 84000 | J25: ='SO MS'!F25 -> 33600 | K25: ='SO MS'!G25 -> 9600 | L25: =2*5000 -> 10000 | M25: ='SO MEI 2026 REV 4'!AZ25 -> 1800 | N25: ='SO MEI 2026 REV 4'!AS25 -> 3500 | O25: ='SO MEI 2026 REV 4'!AY25 -> 0 | Q25: =SUM(I25:P25) -> 142500
B26: =B25+1 -> 46159 | C26: =TEXT(B26,"ddd") -> Mgg | D26: =Q26-H26 -> -29852.013 | E26: =SUM('SO MEI 2026 REV 4'!E26:AS26) -> 141892.84 | F26: =SUM('SO MEI 2026 REV 4'!AT26:BA26) -> 10459.17 | G26: =SUM('SO MEI 2026 REV 4'!BB26:BD26) -> 20000 | H26: =SUM(E26:G26) -> 172352.01 | I26: ='SO MS'!E26 -> 84000 | J26: ='SO MS'!F26 -> 33600 | K26: ='SO MS'!G26 -> 9600 | L26: =2*5000 -> 10000 | M26: ='SO MEI 2026 REV 4'!AZ26 -> 1800 | N26: ='SO MEI 2026 REV 4'!AS26 -> 3500 | O26: ='SO MEI 2026 REV 4'!AY26 -> 0 | Q26: =SUM(I26:P26) -> 142500
B27: Sub Total | D27: =SUM(D20:D26) -> -404313.73 | E27: =SUM(E20:E26) -> 1168999.2 | F27: =SUM(F20:F26) -> 77701.789 | G27: =SUM(G20:G26) -> 159600.37 | H27: =SUM(H20:H26) -> 1406301.3 | I27: =SUM(I20:I26) -> 588000 | J27: =SUM(J20:J26) -> 235200 | K27: =SUM(K20:K26) -> 67200 | ... Q27: =SUM(Q20:Q26) -> 1001987.6
A29: =WEEKNUM(B29) -> 21 | B29: =B26+1 -> 46160 | C29: =TEXT(B29,"ddd") -> Sen | D29: =Q29-H29 -> -69255.716 | E29: =SUM('SO MEI 2026 REV 4'!E29:AS29) -> 174696.48 | F29: =SUM('SO MEI 2026 REV 4'!AT29:BA29) -> 11581.07 | G29: =SUM('SO MEI 2026 REV 4'!BB29:BD29) -> 26600.062 | H29: =SUM(E29:G29) -> 212877.62 | I29: ='SO MS'!E29 -> 84000 | J29: ='SO MS'!F29 -> 33600 | K29: ='SO MS'!G29 -> 9600 | L29: =2*5000 -> 10000 | M29: ='SO MEI 2026 REV 4'!AZ29 -> 1800 | N29: ='SO MEI 2026 REV 4'!AS29 -> 3500 | O29: ='SO MEI 2026 REV 4'!AY29 -> 1121.9003 | Q29: =SUM(I29:P29) -> 143621.9
B30: =B29+1 -> 46161 | C30: =TEXT(B30,"ddd") -> Sel | D30: =Q30-H30 -> -69255.716 | E30: =SUM('SO MEI 2026 REV 4'!E30:AS30) -> 174696.48 | F30: =SUM('SO MEI 2026 REV 4'!AT30:BA30) -> 11581.07 | G30: =SUM('SO MEI 2026 REV 4'!BB30:BD30) -> 26600.062 | H30: =SUM(E30:G30) -> 212877.62 | I30: ='SO MS'!E30 -> 84000 | J30: ='SO MS'!F30 -> 33600 | K30: ='SO MS'!G30 -> 9600 | L30: =2*5000 -> 10000 | M30: ='SO MEI 2026 REV 4'!AZ30 -> 1800 | N30: ='SO MEI 2026 REV 4'!AS30 -> 3500 | O30: ='SO MEI 2026 REV 4'!AY30 -> 1121.9003 | Q30: =SUM(I30:P30) -> 143621.9
B31: =B30+1 -> 46162 | C31: =TEXT(B31,"ddd") -> Rab | D31: =Q31-H31 -> -69255.716 | E31: =SUM('SO MEI 2026 REV 4'!E31:AS31) -> 174696.48 | F31: =SUM('SO MEI 2026 REV 4'!AT31:BA31) -> 11581.07 | G31: =SUM('SO MEI 2026 REV 4'!BB31:BD31) -> 26600.062 | H31: =SUM(E31:G31) -> 212877.62 | I31: ='SO MS'!E31 -> 84000 | J31: ='SO MS'!F31 -> 33600 | K31: ='SO MS'!G31 -> 9600 | L31: =2*5000 -> 10000 | M31: ='SO MEI 2026 REV 4'!AZ31 -> 1800 | N31: ='SO MEI 2026 REV 4'!AS31 -> 3500 | O31: ='SO MEI 2026 REV 4'!AY31 -> 1121.9003 | Q31: =SUM(I31:P31) -> 143621.9
B32: =B31+1 -> 46163 | C32: =TEXT(B32,"ddd") -> Kam | D32: =Q32-H32 -> -69255.716 | E32: =SUM('SO MEI 2026 REV 4'!E32:AS32) -> 174696.48 | F32: =SUM('SO MEI 2026 REV 4'!AT32:BA32) -> 11581.07 | G32: =SUM('SO MEI 2026 REV 4'!BB32:BD32) -> 26600.062 | H32: =SUM(E32:G32) -> 212877.62 | I32: ='SO MS'!E32 -> 84000 | J32: ='SO MS'!F32 -> 33600 | K32: ='SO MS'!G32 -> 9600 | L32: =2*5000 -> 10000 | M32: ='SO MEI 2026 REV 4'!AZ32 -> 1800 | N32: ='SO MEI 2026 REV 4'!AS32 -> 3500 | O32: ='SO MEI 2026 REV 4'!AY32 -> 1121.9003 | Q32: =SUM(I32:P32) -> 143621.9
B33: =B32+1 -> 46164 | C33: =TEXT(B33,"ddd") -> Jum | D33: =Q33-H33 -> -57655.653 | E33: =SUM('SO MEI 2026 REV 4'!E33:AS33) -> 174696.48 | F33: =SUM('SO MEI 2026 REV 4'!AT33:BA33) -> 11581.07 | G33: =SUM('SO MEI 2026 REV 4'!BB33:BD33) -> 15000 | H33: =SUM(E33:G33) -> 201277.55 | I33: ='SO MS'!E33 -> 84000 | J33: ='SO MS'!F33 -> 33600 | K33: ='SO MS'!G33 -> 9600 | L33: =2*5000 -> 10000 | M33: ='SO MEI 2026 REV 4'!AZ33 -> 1800 | N33: ='SO MEI 2026 REV 4'!AS33 -> 3500 | O33: ='SO MEI 2026 REV 4'!AY33 -> 1121.9003 | Q33: =SUM(I33:P33) -> 143621.9
B34: =B33+1 -> 46165 | C34: =TEXT(B34,"ddd") -> Sab | D34: =Q34-H34 -> -63689.777 | E34: =SUM('SO MEI 2026 REV 4'!E34:AS34) -> 180730.61 | F34: =SUM('SO MEI 2026 REV 4'!AT34:BA34) -> 10459.17 | G34: =SUM('SO MEI 2026 REV 4'!BB34:BD34) -> 15000 | H34: =SUM(E34:G34) -> 206189.78 | I34: ='SO MS'!E34 -> 84000 | J34: ='SO MS'!F34 -> 33600 | K34: ='SO MS'!G34 -> 9600 | L34: =2*5000 -> 10000 | M34: ='SO MEI 2026 REV 4'!AZ34 -> 1800 | N34: ='SO MEI 2026 REV 4'!AS34 -> 3500 | O34: ='SO MEI 2026 REV 4'!AY34 -> 0 | Q34: =SUM(I34:P34) -> 142500
B35: =B34+1 -> 46166 | C35: =TEXT(B35,"ddd") -> Mgg | D35: =Q35-H35 -> -24852.013 | E35: =SUM('SO MEI 2026 REV 4'!E35:AS35) -> 141892.84 | F35: =SUM('SO MEI 2026 REV 4'!AT35:BA35) -> 10459.17 | G35: =SUM('SO MEI 2026 REV 4'!BB35:BD35) -> 15000 | H35: =SUM(E35:G35) -> 167352.01 | I35: ='SO MS'!E35 -> 84000 | J35: ='SO MS'!F35 -> 33600 | K35: ='SO MS'!G35 -> 9600 | L35: =2*5000 -> 10000 | M35: ='SO MEI 2026 REV 4'!AZ35 -> 1800 | N35: ='SO MEI 2026 REV 4'!AS35 -> 3500 | O35: ='SO MEI 2026 REV 4'!AY35 -> 0 | Q35: =SUM(I35:P35) -> 142500
B36: Sub Total | D36: =SUM(D29:D35) -> -423220.31 | E36: =SUM(E29:E35) -> 1196105.9 | F36: =SUM(F29:F35) -> 78823.69 | G36: =SUM(G29:G35) -> 151400.25 | H36: =SUM(H29:H35) -> 1426329.8 | I36: =SUM(I29:I35) -> 588000 | J36: =SUM(J29:J35) -> 235200 | K36: =SUM(K29:K35) -> 67200 | ... Q36: =SUM(Q29:Q35) -> 1003109.5
A38: =WEEKNUM(B38) -> 22 | B38: =B35+1 -> 46167 | C38: =TEXT(B38,"ddd") -> Sen | D38: =Q38-H38 -> -34165.788 | E38: =SUM('SO MEI 2026 REV 4'!E38:AS38) -> 169696.48 | F38: =SUM('SO MEI 2026 REV 4'!AT38:BA38) -> 11581.07 | G38: =SUM('SO MEI 2026 REV 4'!BB38:BD38) -> 15000 | H38: =SUM(E38:G38) -> 196277.55 | I38: ='SO MS'!E38 -> 84000 | J38: =SUM('SO MEI 2026 REV 4'!AG38:AR38) -> 52089.865 | K38: ='SO MS'!G38 -> 9600 | L38: =2*5000 -> 10000 | M38: ='SO MEI 2026 REV 4'!AZ38 -> 1800 | N38: ='SO MEI 2026 REV 4'!AS38 -> 3500 | O38: ='SO MEI 2026 REV 4'!AY38 -> 1121.9003 | Q38: =SUM(I38:P38) -> 162111.77
B39: =B38+1 -> 46168 | C39: =TEXT(B39,"ddd") -> Sel | D39: =Q39-H39 -> -193777.85 | E39: =SUM('SO MEI 2026 REV 4'!E39:AS39) -> 169696.48 | F39: =SUM('SO MEI 2026 REV 4'!AT39:BA39) -> 11581.07 | G39: =SUM('SO MEI 2026 REV 4'!BB39:BD39) -> 15000 | H39: =SUM(E39:G39) -> 196277.55 | I39: ='SO MS'!E39 -> 84000 | J39: =SUM('SO MEI 2026 REV 4'!AG39:AR39) -> 52089.865 | K39: ='SO MS'!G39 -> 9600 | L39: =2*5000 -> 10000 | M39: ='SO MEI 2026 REV 4'!AZ39 -> 1800 | N39: ='SO MEI 2026 REV 4'!AS39 -> 3500 | O39: ='SO MEI 2026 REV 4'!AY39 -> 1121.9003 | P39: ='SO MEI 2026 REV 4'!AU39 -> 3018.0416 | Q39: ='SO MEI 2026 REV 4'!BA39 -> 2499.7026
B40: =B39+1 -> 46169 | C40: =TEXT(B40,"ddd") -> Rab | D40: =Q40-H40 -> -114444.94 | E40: =SUM('SO MEI 2026 REV 4'!E40:AS40) -> 93900.081 | F40: =SUM('SO MEI 2026 REV 4'!AT40:BA40) -> 8044.5594 | G40: =SUM('SO MEI 2026 REV 4'!BB40:BD40) -> 15000 | H40: =SUM(E40:G40) -> 116944.64 | I40: ='SO MS'!E40 -> 84000 | J40: =SUM('SO MEI 2026 REV 4'!AG40:AR40) -> 16519.545 | K40: ='SO MS'!G40 -> 9600 | L40: =2*5000 -> 10000 | M40: ='SO MEI 2026 REV 4'!AZ40 -> 1800 | N40: ='SO MEI 2026 REV 4'!AS40 -> 0 | O40: ='SO MEI 2026 REV 4'!AY40 -> 0 | P40: ='SO MEI 2026 REV 4'!AU40 -> 3018.0416 | Q40: ='SO MEI 2026 REV 4'!BA40 -> 2499.7026
B41: =B40+1 -> 46170 | C41: =TEXT(B41,"ddd") -> Kam | D41: =Q41-H41 -> -156066.25 | E41: =SUM('SO MEI 2026 REV 4'!E41:AS41) -> 135521.39 | F41: =SUM('SO MEI 2026 REV 4'!AT41:BA41) -> 8044.5594 | G41: =SUM('SO MEI 2026 REV 4'!BB41:BD41) -> 15000 | H41: =SUM(E41:G41) -> 158565.95 | I41: ='SO MS'!E41 -> 84000 | J41: =SUM('SO MEI 2026 REV 4'!AG41:AR41) -> 22526.592 | K41: ='SO MS'!G41 -> 9600 | L41: =2*5000 -> 10000 | M41: ='SO MEI 2026 REV 4'!AZ41 -> 1800 | N41: ='SO MEI 2026 REV 4'!AS41 -> 0 | O41: ='SO MEI 2026 REV 4'!AY41 -> 0 | P41: ='SO MEI 2026 REV 4'!AU41 -> 3018.0416 | Q41: ='SO MEI 2026 REV 4'!BA41 -> 2499.7026
B42: =B41+1 -> 46171 | C42: =TEXT(B42,"ddd") -> Jum | D42: =Q42-H42 -> -199777.85 | E42: =SUM('SO MEI 2026 REV 4'!E42:AS42) -> 175696.48 | F42: =SUM('SO MEI 2026 REV 4'!AT42:BA42) -> 11581.07 | G42: =SUM('SO MEI 2026 REV 4'!BB42:BD42) -> 15000 | H42: =SUM(E42:G42) -> 202277.55 | I42: ='SO MS'!E42 -> 84000 | J42: =SUM('SO MEI 2026 REV 4'!AG42:AR42) -> 52089.865 | K42: ='SO MS'!G42 -> 9600 | L42: =2*5000 -> 10000 | M42: ='SO MEI 2026 REV 4'!AZ42 -> 1800 | N42: ='SO MEI 2026 REV 4'!AS42 -> 3500 | O42: ='SO MEI 2026 REV 4'!AY42 -> 1121.9003 | P42: ='SO MEI 2026 REV 4'!AU42 -> 3018.0416 | Q42: ='SO MEI 2026 REV 4'!BA42 -> 2499.7026
B43: =B42+1 -> 46172 | C43: =TEXT(B43,"ddd") -> Sab | D43: =Q43-H43 -> -198690.07 | E43: =SUM('SO MEI 2026 REV 4'!E43:AS43) -> 175730.61 | F43: =SUM('SO MEI 2026 REV 4'!AT43:BA43) -> 10459.17 | G43: =SUM('SO MEI 2026 REV 4'!BB43:BD43) -> 15000 | H43: =SUM(E43:G43) -> 201189.78 | I43: ='SO MS'!E43 -> 84000 | J43: =SUM('SO MEI 2026 REV 4'!AG43:AR43) -> 48589.989 | K43: ='SO MS'!G43 -> 9600 | L43: =2*5000 -> 10000 | M43: ='SO MEI 2026 REV 4'!AZ43 -> 1800 | N43: ='SO MEI 2026 REV 4'!AS43 -> 3500 | O43: ='SO MEI 2026 REV 4'!AY43 -> 0 | P43: ='SO MEI 2026 REV 4'!AU43 -> 3018.0416 | Q43: ='SO MEI 2026 REV 4'!BA43 -> 2499.7026
B44: =B43+1 -> 46173 | C44: =TEXT(B44,"ddd") -> Mgg | D44: =Q44-H44 -> -127053.39 | E44: =SUM('SO MEI 2026 REV 4'!E44:AS44) -> 104093.92 | F44: =SUM('SO MEI 2026 REV 4'!AT44:BA44) -> 10459.17 | G44: =SUM('SO MEI 2026 REV 4'!BB44:BD44) -> 15000 | H44: =SUM(E44:G44) -> 129553.09 | I44: ='SO MS'!E44 -> 84000 | J44: =SUM('SO MEI 2026 REV 4'!AG44:AR44) -> 20020.712 | K44: ='SO MS'!G44 -> 9600 | L44: =2*5000 -> 10000 | M44: ='SO MEI 2026 REV 4'!AZ44 -> 1800 | N44: ='SO MEI 2026 REV 4'!AS44 -> 3500 | O44: ='SO MEI 2026 REV 4'!AY44 -> 0 | P44: ='SO MEI 2026 REV 4'!AU44 -> 3018.0416 | Q44: ='SO MEI 2026 REV 4'!BA44 -> 2499.7026
B45: Sub Total | D45: =SUM(D38:D44) -> -1023976.1 | E45: =SUM(E38:E44) -> 1024335.5 | F45: =SUM(F38:F44) -> 71750.668 | G45: =SUM(G38:G44) -> 105000 | H45: =SUM(H38:H44) -> 1201086.1 | I45: =SUM(I38:I44) -> 588000 | J45: =SUM(J38:J44) -> 263926.43 | K45: =SUM(K38:K44) -> 67200 | ... Q45: =SUM(Q38:Q44) -> 177109.98
B47: Sub Total | D47: =SUM(D45,D36,D27,D18,D9) -> -2090075 | E47: =SUM(E45,E36,E27,E18,E9) -> 4898627.8 | F47: =SUM(F45,F36,F27,F18,F9) -> 336062.74 | G47: =SUM(G45,G36,G27,G18,G9) -> 462201 | H47: =SUM(H45,H36,H27,H18,H9) -> 5696891.6 | I47: =SUM(I45,I36,I27,I18,I9) -> 2604000 | J47: =SUM(J45,J36,J27,J18,J9) -> 1070326.4 | K47: =SUM(K45,K36,K27,K18,K9) -> 297600 | ... Q47: =SUM(Q45,Q36,Q27,Q18,Q9) -> 3606816.6
...

Sheet Daily serapan Gas
A1: KEBUTUHAN GAS
A4: ='SO MEI 2026 REV 4'!A3 -> 46143 | E4: KEBUTUHAN GAS (SO) | I4: KUOTA GAS
A5: Week | B5: DATE | D5: Sales Order vs Kuota Gas | E5: JABAR | F5: JATENG | G5: JATIM | H5: TOTAL | I5: MS SETU | J5: MS KHT | K5: MS BLORA | L5: MS BITUNG | M5: MS ZEBRA | N5: MS TAMBAKLOROK | O5: MS WUNUT | P5: MS SADANG | Q5: TOTAL
A6: =WEEKNUM(B6) -> 18 | B6: =A4 -> 46143 | C6: =TEXT(B6,"ddd") -> Jum | D6: =Q6-H6 -> 30406.308 | E6: =SUM('SO MEI 2026 REV 4'!E6:AS6) -> 101571.29 | F6: =SUM('SO MEI 2026 REV 4'!AT6:BD6) -> 8044.5594 | G6: =SUM('SO MEI 2026 REV 4'!AY6:AZ6) -> 1800 | H6: =SUM(E6:G6) -> 111415.85 | I6: ='Summary sales'!D8 -> 88799.98 | J6: ='Summary sales'!E8 -> 36939.92 | K6: ='Summary sales'!F8 -> 11931.04 | L6: ='Summary sales'!G8 -> 0 | N6: ='Summary sales'!I8 -> 4151.22 | Q6: =SUM(I6:P6) -> 141822.16
B7: =B6+1 -> 46144 | C7: =TEXT(B7,"ddd") -> Sab | D7: =Q7-H7 -> -45086.759 | E7: =SUM('SO MEI 2026 REV 4'!E7:AS7) -> 159371.39 | F7: =SUM('SO MEI 2026 REV 4'!AT7:BD7) -> 10459.17 | G7: =SUM('SO MEI 2026 REV 4'!AY7:AZ7) -> 1800 | H7: =SUM(E7:G7) -> 171630.56 | I7: ='Summary sales'!D9 -> 74793.17 | J7: ='Summary sales'!E9 -> 36903.17 | K7: ='Summary sales'!F9 -> 14847.46 | L7: ='Summary sales'!G9 -> 0 | N7: ='Summary sales'!I9 -> 0 | Q7: =SUM(I7:P7) -> 126543.8
B8: =B7+1 -> 46145 | C8: =TEXT(B8,"ddd") -> Mgg | D8: =Q8-H8 -> -34095.513 | E8: =SUM('SO MEI 2026 REV 4'!E8:AS8) -> 131892.84 | F8: =SUM('SO MEI 2026 REV 4'!AT8:BD8) -> 17059.17 | G8: =SUM('SO MEI 2026 REV 4'!AY8:AZ8) -> 1800 | H8: =SUM(E8:G8) -> 150752.01 | I8: ='Summary sales'!D10 -> 70666.34 | J8: ='Summary sales'!E10 -> 35544.79 | K8: ='Summary sales'!F10 -> 6126.35 | L8: ='Summary sales'!G10 -> 0 | N8: ='Summary sales'!I10 -> 4319.02 | Q8: =SUM(I8:P8) -> 116656.5
B9: Sub Total | D9: =SUM(D6:D8) -> -48775.965 | E9: =SUM(E6:E8) -> 392835.53 | F9: =SUM(F6:F8) -> 35562.899 | G9: =SUM(G6:G8) -> 5400 | H9: =SUM(H6:H8) -> 433798.43 | I9: =SUM(I6:I8) -> 234259.49 | J9: =SUM(J6:J8) -> 109387.88 | K9: =SUM(K6:K8) -> 32904.85 | ... Q9: =SUM(Q6:Q8) -> 385022.46
A11: =WEEKNUM(B11) -> 19 | B11: =B8+1 -> 46146 | C11: =TEXT(B11,"ddd") -> Sen | D11: =Q11-H11 -> -46673.753 | E11: =SUM('SO MEI 2026 REV 4'!E11:AS11) -> 162070.81 | F11: =SUM('SO MEI 2026 REV 4'!AT11:BD11) -> 18181.132 | G11: =SUM('SO MEI 2026 REV 4'!AY11:AZ11) -> 2921.9003 | H11: =SUM(E11:G11) -> 183173.84 | I11: ='Summary sales'!D11 -> 94817.75 | J11: ='Summary sales'!E11 -> 33219.9 | K11: ='Summary sales'!F11 -> 8462.44 | L11: ='Summary sales'!G11 -> 0 | N11: ='Summary sales'!I11 -> 0 | Q11: =SUM(I11:P11) -> 136500.09
B12: =B11+1 -> 46147 | C12: =TEXT(B12,"ddd") -> Sel | D12: =Q12-H12 -> -32409.543 | E12: =SUM('SO MEI 2026 REV 4'!E12:AS12) -> 162070.81 | F12: =SUM('SO MEI 2026 REV 4'!AT12:BD12) -> 18181.132 | G12: =SUM('SO MEI 2026 REV 4'!AY12:AZ12) -> 2921.9003 | H12: =SUM(E12:G12) -> 183173.84 | I12: ='Summary sales'!D12 -> 91432.48 | J12: ='Summary sales'!E12 -> 40799.43 | K12: ='Summary sales'!F12 -> 14176.27 | L12: ='Summary sales'!G12 -> 0 | N12: ='Summary sales'!I12 -> 4356.12 | Q12: =SUM(I12:P12) -> 150764.3
B13: =B12+1 -> 46148 | C13: =TEXT(B13,"ddd") -> Rab | D13: =Q13-H13 -> -28167.953 | E13: =SUM('SO MEI 2026 REV 4'!E13:AS13) -> 171570.81 | F13: =SUM('SO MEI 2026 REV 4'!AT13:BD13) -> 18181.132 | G13: =SUM('SO MEI 2026 REV 4'!AY13:AZ13) -> 2921.9003 | H13: =SUM(E13:G13) -> 192673.84 | I13: ='Summary sales'!D13 -> 101637.21 | J13: ='Summary sales'!E13 -> 48456.05 | K13: ='Summary sales'!F13 -> 14412.63 | L13: ='Summary sales'!G13 -> 0 | N13: ='Summary sales'!I13 -> 0 | Q13: =SUM(I13:P13) -> 164505.89
B14: =B13+1 -> 46149 | C14: =TEXT(B14,"ddd") -> Kam | D14: =Q14-H14 -> -19494.533 | E14: =SUM('SO MEI 2026 REV 4'!E14:AS14) -> 171570.81 | F14: =SUM('SO MEI 2026 REV 4'!AT14:BD14) -> 18181.132 | G14: =SUM('SO MEI 2026 REV 4'!AY14:AZ14) -> 2921.9003 | H14: =SUM(E14:G14) -> 192673.84 | I14: ='Summary sales'!D14 -> 107063.17 | J14: ='Summary sales'!E14 -> 50488.72 | K14: ='Summary sales'!F14 -> 11245.13 | L14: ='Summary sales'!G14 -> 0 | N14: ='Summary sales'!I14 -> 4382.29 | Q14: =SUM(I14:P14) -> 173179.31
B15: =B14+1 -> 46150 | C15: =TEXT(B15,"ddd") -> Jum | D15: =Q15-H15 -> -7680.2026 | E15: =SUM('SO MEI 2026 REV 4'!E15:AS15) -> 171570.81 | F15: =SUM('SO MEI 2026 REV 4'!AT15:BD15) -> 18181.132 | G15: =SUM('SO MEI 2026 REV 4'!AY15:AZ15) -> 2921.9003 | H15: =SUM(E15:G15) -> 192673.84 | I15: ='Summary sales'!D15 -> 121704.89 | J15: ='Summary sales'!E15 -> 45455.76 | K15: ='Summary sales'!F15 -> 13549.73 | L15: ='Summary sales'!G15 -> 0 | N15: ='Summary sales'!I15 -> 4283.26 | Q15: =SUM(I15:P15) -> 184993.64
B16: =B15+1 -> 46151 | C16: =TEXT(B16,"ddd") -> Sab | D16: =Q16-H16 -> 12445.795 | E16: =SUM('SO MEI 2026 REV 4'!E16:AS16) -> 159604.93 | F16: =SUM('SO MEI 2026 REV 4'!AT16:BD16) -> 17059.232 | G16: =SUM('SO MEI 2026 REV 4'!AY16:AZ16) -> 1800 | H16: =SUM(E16:G16) -> 178464.17 | I16: ='Summary sales'!D16 -> 125522.15 | J16: ='Summary sales'!E16 -> 49391.79 | K16: ='Summary sales'!F16 -> 11813.01 | L16: ='Summary sales'!G16 -> 0 | N16: ='Summary sales'!I16 -> 4183.01 | Q16: =SUM(I16:P16) -> 190909.96
B17: =B16+1 -> 46152 | C17: =TEXT(B17,"ddd") -> Mgg | D17: =Q17-H17 -> 53468.987 | E17: =SUM('SO MEI 2026 REV 4'!E17:AS17) -> 117892.84 | F17: =SUM('SO MEI 2026 REV 4'!AT17:BD17) -> 10459.17 | G17: =SUM('SO MEI 2026 REV 4'!AY17:AZ17) -> 1800 | H17: =SUM(E17:G17) -> 130152.01 | I17: ='Summary sales'!D17 -> 116303.78 | J17: ='Summary sales'!E17 -> 48512.85 | K17: ='Summary sales'!F17 -> 14457.76 | L17: ='Summary sales'!G17 -> 0 | N17: ='Summary sales'!I17 -> 4346.61 | Q17: =SUM(I17:P17) -> 183621
B18: Sub Total | D18: =SUM(D11:D17) -> -68511.202 | E18: =SUM(E11:E17) -> 1116351.8 | F18: =SUM(F11:F17) -> 118424.06 | G18: =SUM(G11:G17) -> 18209.502 | H18: =SUM(H11:H17) -> 1252985.4 | I18: =SUM(I11:I17) -> 758481.43 | J18: =SUM(J11:J17) -> 316324.5 | K18: =SUM(K11:K17) -> 88116.97 | ... Q18: =SUM(Q11:Q17) -> 1184474.2
A20: =WEEKNUM(B20) -> 20 | B20: =B17+1 -> 46153 | C20: =TEXT(B20,"ddd") -> Sen | D20: =Q20-H20 -> -46400.826 | E20: =SUM('SO MEI 2026 REV 4'!E20:AS20) -> 168696.48 | F20: =SUM('SO MEI 2026 REV 4'!AT20:BD20) -> 18181.132 | G20: =SUM('SO MEI 2026 REV 4'!AY20:AZ20) -> 2921.9003 | H20: =SUM(E20:G20) -> 189799.52 | I20: ='Summary sales'!D18 -> 91741.1 | J20: ='Summary sales'!E18 -> 35132.77 | K20: ='Summary sales'!F18 -> 12116.85 | L20: ='Summary sales'!G18 -> 0 | N20: ='Summary sales'!I18 -> 4407.97 | Q20: =SUM(I20:P20) -> 143398.69
B21: =B20+1 -> 46154 | C21: =TEXT(B21,"ddd") -> Sel | D21: =Q21-H21 -> -35528.676 | E21: =SUM('SO MEI 2026 REV 4'!E21:AS21) -> 180696.48 | F21: =SUM('SO MEI 2026 REV 4'!AT21:BD21) -> 38181.132 | G21: =SUM('SO MEI 2026 REV 4'!AY21:AZ21) -> 2921.9003 | H21: =SUM(E21:G21) -> 221799.52 | I21: ='Summary sales'!D19 -> 130825.25 | J21: ='Summary sales'!E19 -> 49979.36 | K21: ='Summary sales'!F19 -> 5466.23 | L21: ='Summary sales'!G19 -> 0 | N21: ='Summary sales'!I19 -> 0 | Q21: =SUM(I21:P21) -> 186270.84
B22: =B21+1 -> 46155 | C22: =TEXT(B22,"ddd") -> Rab | D22: =Q22-H22 -> -19769.956 | E22: =SUM('SO MEI 2026 REV 4'!E22:AS22) -> 180696.48 | F22: =SUM('SO MEI 2026 REV 4'!AT22:BD22) -> 38181.132 | G22: =SUM('SO MEI 2026 REV 4'!AY22:AZ22) -> 2921.9003 | H22: =SUM(E22:G22) -> 221799.52 | I22: ='Summary sales'!D20 -> 136699.67 | J22: ='Summary sales'!E20 -> 49054.89 | K22: ='Summary sales'!F20 -> 12417.76 | L22: ='Summary sales'!G20 -> 0 | N22: ='Summary sales'!I20 -> 3857.24 | Q22: =SUM(I22:P22) -> 202029.56
B23: =B22+1 -> 46156 | C23: =TEXT(B23,"ddd") -> Kam | D23: =Q23-H23 -> 15769.312 | E23: =SUM('SO MEI 2026 REV 4'!E23:AS23) -> 142589.79 | F23: =SUM('SO MEI 2026 REV 4'!AT23:BD23) -> 37059.232 | G23: =SUM('SO MEI 2026 REV 4'!AY23:AZ23) -> 1800 | H23: =SUM(E23:G23) -> 181449.02 | I23: ='Summary sales'!D21 -> 137046.59 | J23: ='Summary sales'!E21 -> 46514.38 | K23: ='Summary sales'!F21 -> 13657.36 | L23: ='Summary sales'!G21 -> 0 | N23: ='Summary sales'!I21 -> 0 | Q23: =SUM(I23:P23) -> 197218.33
B24: =B23+1 -> 46157 | C24: =TEXT(B24,"ddd") -> Jum | D24: =Q24-H24 -> -49220.086 | E24: =SUM('SO MEI 2026 REV 4'!E24:AS24) -> 173696.48 | F24: =SUM('SO MEI 2026 REV 4'!AT24:BD24) -> 38181.132 | G24: =SUM('SO MEI 2026 REV 4'!AY24:AZ24) -> 2921.9003 | H24: =SUM(E24:G24) -> 214799.52 | I24: ='Summary sales'!D22 -> 108544.78 | J24: ='Summary sales'!E22 -> 44253.46 | K24: ='Summary sales'!F22 -> 8763.02 | L24: ='Summary sales'!G22 -> 0 | N24: ='Summary sales'!I22 -> 4018.17 | Q24: =SUM(I24:P24) -> 165579.43
B25: =B24+1 -> 46158 | C25: =TEXT(B25,"ddd") -> Sab | D25: =Q25-H25 -> -41540.429 | E25: =SUM('SO MEI 2026 REV 4'!E25:AS25) -> 180730.61 | F25: =SUM('SO MEI 2026 REV 4'!AT25:BD25) -> 37059.232 | G25: =SUM('SO MEI 2026 REV 4'!AY25:AZ25) -> 1800 | H25: =SUM(E25:G25) -> 219589.84 | I25: ='Summary sales'!D23 -> 122655.85 | J25: ='Summary sales'!E23 -> 49842.33 | K25: ='Summary sales'!F23 -> 5551.23 | L25: ='Summary sales'!G23 -> 0 | N25: ='Summary sales'!I23 -> 0 | Q25: =SUM(I25:P25) -> 178049.41
B26: =B25+1 -> 46159 | C26: =TEXT(B26,"ddd") -> Mgg | D26: =Q26-H26 -> 4682.9367 | E26: =SUM('SO MEI 2026 REV 4'!E26:AS26) -> 141892.84 | F26: =SUM('SO MEI 2026 REV 4'!AT26:BD26) -> 30459.17 | G26: =SUM('SO MEI 2026 REV 4'!AY26:AZ26) -> 1800 | H26: =SUM(E26:G26) -> 174152.01 | I26: ='Summary sales'!D24 -> 109034.5 | J26: ='Summary sales'!E24 -> 47108.01 | K26: ='Summary sales'!F24 -> 13506.93 | L26: ='Summary sales'!G24 -> 0 | N26: ='Summary sales'!I24 -> 9185.51 | Q26: =SUM(I26:P26) -> 178834.95
B27: Sub Total | D27: =SUM(D20:D26) -> -172007.73 | E27: =SUM(E20:E26) -> 1168999.2 | F27: =SUM(F20:F26) -> 237302.16 | G27: =SUM(G20:G26) -> 17087.601 | H27: =SUM(H20:H26) -> 1423388.9 | I27: =SUM(I20:I26) -> 836547.74 | J27: =SUM(J20:J26) -> 321885.2 | K27: =SUM(K20:K26) -> 71479.38 | ... Q27: =SUM(Q20:Q26) -> 1251381.2
A29: =WEEKNUM(B29) -> 21 | B29: =B26+1 -> 46160 | C29: =TEXT(B29,"ddd") -> Sen | D29: =Q29-H29 -> -35627.446 | E29: =SUM('SO MEI 2026 REV 4'!E29:AS29) -> 174696.48 | F29: =SUM('SO MEI 2026 REV 4'!AT29:BD29) -> 38181.132 | G29: =SUM('SO MEI 2026 REV 4'!AY29:AZ29) -> 2921.9003 | H29: =SUM(E29:G29) -> 215799.52 | I29: ='Summary sales'!D25 -> 115587.64 | J29: ='Summary sales'!E25 -> 45558.88 | K29: ='Summary sales'!F25 -> 14942.65 | L29: ='Summary sales'!G25 -> 0 | N29: ='Summary sales'!I25 -> 4082.9 | Q29: =SUM(I29:P29) -> 180172.07
