Workbook
Name ___xlnm._FilterDatabase_2: #REF!
Name ___xlnm._FilterDatabase_2: #REF!
Name ___xlnm._FilterDatabase_2: #REF!
Name ___xlnm._FilterDatabase_2: #REF!
Name ___xlnm._FilterDatabase_2: #REF!
Name ___xlnm._FilterDatabase_2: #REF!
Name ___xlnm._FilterDatabase_2: #REF!
Name ___xlnm._FilterDatabase_2: #REF!
Name ___xlnm._FilterDatabase_2: #REF!
Name ___xlnm._FilterDatabase_2: #REF!
Name ___xlnm._FilterDatabase_2: #REF!
Name __xlnm._FilterDatabase_2: #REF!
Name __xlnm._FilterDatabase_2: #REF!
Name __xlnm._FilterDatabase_2: #REF!
Name __xlnm._FilterDatabase_2: #REF!
Name __xlnm._FilterDatabase_2: #REF!
Name __xlnm._FilterDatabase_2: #REF!
Name __xlnm._FilterDatabase_2: #REF!
Name __xlnm._FilterDatabase_2: #REF!
Name __xlnm._FilterDatabase_2: #REF!
Name __xlnm._FilterDatabase_2: #REF!
Name __xlnm._FilterDatabase_2: #REF!
Name _TES46: #N/A
Name AAAA: #N/A
Name ati: #N/A
Name BS: #N/A
Name CCC: #N/A
Name depr9200: #N/A
Name dfsfd: #N/A
Name Excel_BuiltIn__FilterDatabase_1: #REF!
Name Excel_BuiltIn__FilterDatabase_1: #REF!
Name Excel_BuiltIn__FilterDatabase_1: #REF!
Name Excel_BuiltIn__FilterDatabase_1: #REF!
Name Excel_BuiltIn__FilterDatabase_1: #REF!
Name Excel_BuiltIn__FilterDatabase_1: #REF!
Name Excel_BuiltIn__FilterDatabase_1: #REF!
Name Excel_BuiltIn__FilterDatabase_1: #REF!
Name Excel_BuiltIn__FilterDatabase_1: #REF!
Name Excel_BuiltIn__FilterDatabase_1: #REF!
Name Excel_BuiltIn__FilterDatabase_1: #REF!
Name Excel_BuiltIn_Print_Titles: NA()
Name Export_3: #REF!
Name Export_3: #REF!
Name Export_3: #REF!
Name Export_3: #REF!
Name Export_3: #REF!
Name Export_3: #REF!
Name Export_3: #REF!
Name Export_3: #REF!
Name FOB: 'Summary FOB'!#REF!
Name FOB: 'Summary FOB'!#REF!
Name FOB: 'Summary FOB'!#REF!
Name FOB: 'Summary FOB'!#REF!
Name FOB: 'Summary FOB'!#REF!
Name FOB: 'Summary FOB'!#REF!
Name FOB: 'Summary FOB'!#REF!
Name FOB: 'Summary FOB'!#REF!
Name partt: #N/A
Name PRINT_TITLES_MI: #N/A
Name project: #N/A

Sheet SO JUNI 2026 (Rev.2)
AH1: SMS | AI1: BMT
A2: SALES ORDER | U2: gf ranca
A3: 46174 | U3: =10500-6600 -> 3900
AU4: FOB PTGN
A5: Week | B5: DATE | D5: TOTAL | E5: CLIN | F5: BI | G5: MKG | H5: STM | I5: OAJ | J5: NNI | K5: SHB | L5: GTL | M5: TWK | N5: BYC | O5: GF RANCA | P5: SMA | Q5: UMI | R5: HLI | S5: ASAHIMAS | T5: DIC | U5: HCI | V5: HANKOOK | W5: KSN | X5: KSN RANCA | Y5: ADP | Z5: ALT (KSO MASAMI) | AA5: IDP (KSO AAE) | AB5: FJI (KSO SALMAH) | AC5: WINGLOK (KSO EBM) | AD5: CISF (KSO RRS) | AE5: KGM | AF5: PUJ - LUBRICANT | AG5: CALBEE (KSO BMI) | AH5: IP | AI5: BEM | AJ5: AMI | AK5: KA | AL5: KTN | AM5: TOMIMOTO | AN5: NIAGA GARAM | AO5: PCI 84 | AP5: PCI MENGGER | AQ5: INDOFOOD | AR5: CERES | AS5: ABC KOGEN | AT5: TONGJI | AU5: PA | AV5: RB | AW5: GF ATOM | AX5: GF KULIT | AY5: HSK (KSO GAS) | AZ5: SDM | BA5: JARGAS | BB5: SBI | BC5: SP JES | BD5: SP GLOBAL | BE5: PENTAWIRA
A6: =WEEKNUM(B6) -> 23 | B6: 46174 | C6: =TEXT(B6,"ddd") -> Sen | D6: =SUM(E6:BE6) -> 177245.12 | E6: 1199.5729 | F6: 2000 | G6: 1200 | H6: 3300 | I6: 644.02065 | J6: 0 | K6: 150 | L6: 603.76323 | M6: 673.27548 | N6: 0 | O6: 0 | P6: 2000 | Q6: 10000 | R6: =4000+5300 -> 9300 | S6: 29000 | T6: 0 | U6: 7000 | V6: 0 | W6: 4000 | X6: 2500 | Y6: 750 | Z6: 1000 | AA6: 5500 | AB6: 0 | AC6: 89.451613 | AD6: 3500 | AE6: 1300 | AF6: 5500 | AG6: 8000 | AH6: 2020.8603 | AI6: 800 | AJ6: 7200 | AK6: 3499.8768 | AL6: 2043.2745 | AM6: 0 | AN6: 1000 | AO6: 11007.047 | AP6: 1519.5448 | AQ6: 3999.6742 | AR6: 9000.0571 | AS6: 8000 | AT6: 3500 | AU6: 800 | AV6: 3800 | AW6: 2044.9997 | AX6: 0 | AY6: 0 | AZ6: 0 | BA6: 1800 | BB6: 2499.7026 | BC6: 0 | BD6: 13500 | BE6: 0
B7: =B6+1 -> 46175 | C7: =TEXT(B7,"ddd") -> Sel | D7: =SUM(E7:BE7) -> 206786.63 | E7: 1199.5729 | F7: 2000 | G7: 1200 | H7: 3300 | I7: 644.02065 | J7: 0 | K7: 150 | L7: 603.76323 | M7: 673.27548 | N7: 5500 | O7: 6000 | P7: 2000 | Q7: 16000 | R7: 9300 | S7: 29000 | T7: 8000 | U7: 7000 | V7: 0 | W7: 4000 | X7: 5000 | Y7: 750 | Z7: 1000 | AA7: 5500 | AB7: 0 | AC7: 89.451613 | AD7: 3500 | AE7: 1300 | AF7: 5500 | AG7: 8000 | AH7: 2020.8603 | AI7: 800 | AJ7: 7200 | AK7: 3499.8768 | AL7: 2043.2745 | AM7: 0 | AN7: 1000 | AO7: 11007.047 | AP7: 1519.5448 | AQ7: 3999.6742 | AR7: 9000.0571 | AS7: 8000 | AT7: 3500 | AU7: 850 | AV7: 3800 | AW7: 2044.9997 | AX7: 369.61071 | AY7: 0 | AZ7: 1121.9003 | BA7: 1800 | BB7: 2499.7026 | BC7: 0 | BD7: 13500 | BE7: 0
B8: =B7+1 -> 46176 | C8: =TEXT(B8,"ddd") -> Rab | D8: =SUM(E8:BE8) -> 206786.63 | E8: 1199.5729 | F8: 2000 | G8: 1200 | H8: 3300 | I8: 644.02065 | J8: 0 | K8: 150 | L8: 603.76323 | M8: 673.27548 | N8: 5500 | O8: 6000 | P8: 2000 | Q8: 16000 | R8: 9300 | S8: 29000 | T8: 8000 | U8: 7000 | V8: 0 | W8: 4000 | X8: 5000 | Y8: 750 | Z8: 1000 | AA8: 5500 | AB8: 0 | AC8: 89.451613 | AD8: 3500 | AE8: 1300 | AF8: 5500 | AG8: 8000 | AH8: 2020.8603 | AI8: 800 | AJ8: 7200 | AK8: 3499.8768 | AL8: 2043.2745 | AM8: 0 | AN8: 1000 | AO8: 11007.047 | AP8: 1519.5448 | AQ8: 3999.6742 | AR8: 9000.0571 | AS8: 8000 | AT8: 3500 | AU8: 850 | AV8: 3800 | AW8: 2044.9997 | AX8: 369.61071 | AY8: 0 | AZ8: 1121.9003 | BA8: 1800 | BB8: 2499.7026 | BC8: 0 | BD8: 13500 | BE8: 0
A9: =WEEKNUM(B9) -> 23 | B9: =B8+1 -> 46177 | C9: =TEXT(B9,"ddd") -> Kam | D9: =SUM(E9:BE9) -> 206786.63 | E9: 1199.5729 | F9: 2000 | G9: 1200 | H9: 3300 | I9: 644.02065 | J9: 0 | K9: 150 | L9: 603.76323 | M9: 673.27548 | N9: 5500 | O9: 6000 | P9: 2000 | Q9: 16000 | R9: 9300 | S9: 29000 | T9: 8000 | U9: 7000 | V9: 0 | W9: 4000 | X9: 5000 | Y9: 750 | Z9: 1000 | AA9: 5500 | AB9: 0 | AC9: 89.451613 | AD9: 3500 | AE9: 1300 | AF9: 5500 | AG9: 8000 | AH9: 2020.8603 | AI9: 800 | AJ9: 7200 | AK9: 3499.8768 | AL9: 2043.2745 | AM9: 0 | AN9: 1000 | AO9: 11007.047 | AP9: 1519.5448 | AQ9: 3999.6742 | AR9: 9000.0571 | AS9: 8000 | AT9: 3500 | AU9: 850 | AV9: 3800 | AW9: 2044.9997 | AX9: 369.61071 | AY9: 0 | AZ9: 1121.9003 | BA9: 1800 | BB9: 2499.7026 | BC9: 0 | BD9: 13500 | BE9: 0
B10: =B9+1 -> 46178 | C10: =TEXT(B10,"ddd") -> Jum | D10: =SUM(E10:BE10) -> 206786.63 | E10: 1199.5729 | F10: 2000 | G10: 1200 | H10: 3300 | I10: 644.02065 | J10: 0 | K10: 150 | L10: 603.76323 | M10: 673.27548 | N10: 5500 | O10: 6000 | P10: 2000 | Q10: 16000 | R10: 9300 | S10: 29000 | T10: 8000 | U10: 7000 | V10: 0 | W10: 4000 | X10: 5000 | Y10: 750 | Z10: 1000 | AA10: 5500 | AB10: 0 | AC10: 89.451613 | AD10: 3500 | AE10: 1300 | AF10: 5500 | AG10: 8000 | AH10: 2020.8603 | AI10: 800 | AJ10: 7200 | AK10: 3499.8768 | AL10: 2043.2745 | AM10: 0 | AN10: 1000 | AO10: 11007.047 | AP10: 1519.5448 | AQ10: 3999.6742 | AR10: 9000.0571 | AS10: 8000 | AT10: 3500 | AU10: 850 | AV10: 3800 | AW10: 2044.9997 | AX10: 369.61071 | AY10: 0 | AZ10: 1121.9003 | BA10: 1800 | BB10: 2499.7026 | BC10: 0 | BD10: 13500 | BE10: 0
B11: =B10+1 -> 46179 | C11: =TEXT(B11,"ddd") -> Sab | D11: =SUM(E11:BE11) -> 205148.86 | E11: 733.5729 | F11: 1000 | G11: 1200 | H11: 3300 | I11: 644.02065 | J11: 0 | K11: 150 | L11: 603.76323 | M11: 673.27548 | N11: 4500 | O11: 6000 | P11: 1000 | Q11: 16000 | R11: 9300 | S11: 48000 | T11: 8000 | U11: 0 | V11: 0 | W11: 4000 | X11: 5000 | Y11: 750 | Z11: 1000 | AA11: 5500 | AB11: 0 | AC11: 89.451613 | AD11: 3500 | AE11: 1300 | AF11: 0 | AG11: 8000 | AH11: 2020.8603 | AI11: 800 | AJ11: 7200 | AK11: 0 | AL11: 2043.2745 | AM11: 0 | AN11: 1000 | AO11: 11007.047 | AP11: 1519.5448 | AQ11: 3999.6742 | AR11: 9000.0571 | AS11: 8000 | AT11: 3500 | AU11: 800 | AV11: 3800 | AW11: 2044.9997 | AX11: 369.61071 | AY11: 0 | AZ11: 0 | BA11: 1800 | BB11: 2499.7026 | BC11: 0 | BD11: 13500 | BE11: 0
B12: =B11+1 -> 46180 | C12: =TEXT(B12,"ddd") -> Mgg | D12: =SUM(E12:BE12) -> 178657.78 | E12: 733.5729 | F12: 1000 | G12: 1200 | H12: 999.51613 | I12: 644.02065 | J12: 0 | K12: 0 | L12: 603.76323 | M12: 673.27548 | N12: 0 | O12: 6000 | P12: 300 | Q12: 6659.5545 | R12: 9300 | S12: =48000+6000 -> 54000 | T12: 8000 | U12: 0 | V12: 0 | W12: 4000 | X12: 5000 | Y12: 750 | Z12: 0 | AA12: 2500 | AB12: 0 | AC12: 89.451613 | AD12: 1000 | AE12: 1300 | AF12: 0 | AG12: 8000 | AH12: 2020.8603 | AI12: 0 | AJ12: 2999.8519 | AK12: 0 | AL12: 2043.2745 | AM12: 0 | AN12: 0 | AO12: 11007.047 | AP12: 1519.5448 | AQ12: 3999.6742 | AR12: 6000.0571 | AS12: 8000 | AT12: 3500 | AU12: 800 | AV12: 3800 | AW12: 2044.9997 | AX12: 369.61071 | AY12: 0 | AZ12: 0 | BA12: 1800 | BB12: 2499.7026 | BC12: 0 | BD12: 13500 | BE12: 0
B13: Sub Total | D13: =SUM(D6:D12) -> 1388198.3 | E13: =SUM(E6:E12) -> 7465.0103 | F13: =SUM(F6:F12) -> 12000 | G13: =SUM(G6:G12) -> 8400 | H13: =SUM(H6:H12) -> 20799.516 | I13: =SUM(I6:I12) -> 4508.1445 | J13: =SUM(J6:J12) -> 0 | K13: =SUM(K6:K12) -> 900 | ... AA13: =SUM(AA6:AA12) -> 35500 | AB13: =SUM(AB10:AB12) -> 0 | AC13: =SUM(AC6:AC12) -> 626.16129 | AD13: =SUM(AD6:AD12) -> 22000 | AE13: =SUM(AE6:AE12) -> 9100 | AF13: =SUM(AF6:AF12) -> 27500 | AG13: =SUM(AG6:AG12) -> 56000 | AH13: =SUM(AH6:AH12) -> 14146.022 | AI13: =SUM(AI6:AI12) -> 4800 | AJ13: =SUM(AJ6:AJ12) -> 46199.852 | ... BE13: =SUM(BE6:BE12) -> 0
B15: =B12+1 -> 46181 | C15: =TEXT(B15,"ddd") -> Sen | D15: =SUM(E15:BE15) -> 221786.63 | E15: 1199.5729 | F15: 2000 | G15: 1200 | H15: 3300 | I15: 644.02065 | J15: 0 | K15: 150 | L15: 603.76323 | M15: 673.27548 | N15: 5500 | O15: 6000 | P15: 2000 | Q15: 16000 | R15: 9300 | S15: 29000 | T15: 8000 | U15: 7000 | V15: 0 | W15: 4000 | X15: 5000 | Y15: 750 | Z15: 1000 | AA15: 5500 | AB15: 0 | AC15: 89.451613 | AD15: 3500 | AE15: 1300 | AF15: 5500 | AG15: 8000 | AH15: 2020.8603 | AI15: 800 | AJ15: 7200 | AK15: 3499.8768 | AL15: 2043.2745 | AM15: 0 | AN15: 1000 | AO15: 11007.047 | AP15: 1519.5448 | AQ15: 3999.6742 | AR15: 9000.0571 | AS15: 8000 | AT15: 3500 | AU15: 850 | AV15: 3800 | AW15: 2044.9997 | AX15: 369.61071 | AY15: 0 | AZ15: 1121.9003 | BA15: 1800 | BB15: 2499.7026 | BC15: 0 | BD15: 13500 | BE15: 15000
B16: =B15+1 -> 46182 | C16: =TEXT(B16,"ddd") -> Sel | D16: =SUM(E16:BE16) -> 221786.63 | E16: 1199.5729 | F16: 2000 | G16: 1200 | H16: 3300 | I16: 644.02065 | J16: 0 | K16: 150 | L16: 603.76323 | M16: 673.27548 | N16: 5500 | O16: 6000 | P16: 2000 | Q16: 16000 | R16: 9300 | S16: 29000 | T16: 8000 | U16: 7000 | V16: 0 | W16: 4000 | X16: 5000 | Y16: 750 | Z16: 1000 | AA16: 5500 | AB16: 0 | AC16: 89.451613 | AD16: 3500 | AE16: 1300 | AF16: 5500 | AG16: 8000 | AH16: 2020.8603 | AI16: 800 | AJ16: 7200 | AK16: 3499.8768 | AL16: 2043.2745 | AM16: 0 | AN16: 1000 | AO16: 11007.047 | AP16: 1519.5448 | AQ16: 3999.6742 | AR16: 9000.0571 | AS16: 8000 | AT16: 3500 | AU16: 850 | AV16: 3800 | AW16: 2044.9997 | AX16: 369.61071 | AY16: 0 | AZ16: 1121.9003 | BA16: 1800 | BB16: 2499.7026 | BC16: 0 | BD16: 13500 | BE16: 15000
B17: =B16+1 -> 46183 | C17: =TEXT(B17,"ddd") -> Rab | D17: =SUM(E17:BE17) -> 221786.63 | E17: 1199.5729 | F17: 2000 | G17: 1200 | H17: 3300 | I17: 644.02065 | J17: 0 | K17: 150 | L17: 603.76323 | M17: 673.27548 | N17: 5500 | O17: 6000 | P17: 2000 | Q17: 16000 | R17: 9300 | S17: 29000 | T17: 8000 | U17: 7000 | V17: 0 | W17: 4000 | X17: 5000 | Y17: 750 | Z17: 1000 | AA17: 5500 | AB17: 0 | AC17: 89.451613 | AD17: 3500 | AE17: 1300 | AF17: 5500 | AG17: 8000 | AH17: 2020.8603 | AI17: 800 | AJ17: 7200 | AK17: 3499.8768 | AL17: 2043.2745 | AM17: 0 | AN17: 1000 | AO17: 11007.047 | AP17: 1519.5448 | AQ17: 3999.6742 | AR17: 9000.0571 | AS17: 8000 | AT17: 3500 | AU17: 850 | AV17: 3800 | AW17: 2044.9997 | AX17: 369.61071 | AY17: 0 | AZ17: 1121.9003 | BA17: 1800 | BB17: 2499.7026 | BC17: 0 | BD17: 13500 | BE17: 15000
A18: =WEEKNUM(B18) -> 24 | B18: =B17+1 -> 46184 | C18: =TEXT(B18,"ddd") -> Kam | D18: =SUM(E18:BE18) -> 221786.63 | E18: 1199.5729 | F18: 2000 | G18: 1200 | H18: 3300 | I18: 644.02065 | J18: 0 | K18: 150 | L18: 603.76323 | M18: 673.27548 | N18: 5500 | O18: 6000 | P18: 2000 | Q18: 16000 | R18: 9300 | S18: 29000 | T18: 8000 | U18: 7000 | V18: 0 | W18: 4000 | X18: 5000 | Y18: 750 | Z18: 1000 | AA18: 5500 | AB18: 0 | AC18: 89.451613 | AD18: 3500 | AE18: 1300 | AF18: 5500 | AG18: 8000 | AH18: 2020.8603 | AI18: 800 | AJ18: 7200 | AK18: 3499.8768 | AL18: 2043.2745 | AM18: 0 | AN18: 1000 | AO18: 11007.047 | AP18: 1519.5448 | AQ18: 3999.6742 | AR18: 9000.0571 | AS18: 8000 | AT18: 3500 | AU18: 850 | AV18: 3800 | AW18: 2044.9997 | AX18: 369.61071 | AY18: 0 | AZ18: 1121.9003 | BA18: 1800 | BB18: 2499.7026 | BC18: 0 | BD18: 13500 | BE18: 15000
B19: =B18+1 -> 46185 | C19: =TEXT(B19,"ddd") -> Jum | D19: =SUM(E19:BE19) -> 221786.63 | E19: 1199.5729 | F19: 2000 | G19: 1200 | H19: 3300 | I19: 644.02065 | J19: 0 | K19: 150 | L19: 603.76323 | M19: 673.27548 | N19: 5500 | O19: 6000 | P19: 2000 | Q19: 16000 | R19: 9300 | S19: 29000 | T19: 8000 | U19: 7000 | V19: 0 | W19: 4000 | X19: 5000 | Y19: 750 | Z19: 1000 | AA19: 5500 | AB19: 0 | AC19: 89.451613 | AD19: 3500 | AE19: 1300 | AF19: 5500 | AG19: 8000 | AH19: 2020.8603 | AI19: 800 | AJ19: 7200 | AK19: 3499.8768 | AL19: 2043.2745 | AM19: 0 | AN19: 1000 | AO19: 11007.047 | AP19: 1519.5448 | AQ19: 3999.6742 | AR19: 9000.0571 | AS19: 8000 | AT19: 3500 | AU19: 850 | AV19: 3800 | AW19: 2044.9997 | AX19: 369.61071 | AY19: 0 | AZ19: 1121.9003 | BA19: 1800 | BB19: 2499.7026 | BC19: 0 | BD19: 13500 | BE19: 15000
B20: =B19+1 -> 46186 | C20: =TEXT(B20,"ddd") -> Sab | D20: =SUM(E20:BE20) -> 220148.86 | E20: 733.5729 | F20: 1000 | G20: 1200 | H20: 3300 | I20: 644.02065 | J20: 0 | K20: 150 | L20: 603.76323 | M20: 673.27548 | N20: 4500 | O20: 6000 | P20: 1000 | Q20: 16000 | R20: 9300 | S20: 48000 | T20: 8000 | U20: 0 | V20: 0 | W20: 4000 | X20: 5000 | Y20: 750 | Z20: 1000 | AA20: 5500 | AB20: 0 | AC20: 89.451613 | AD20: 3500 | AE20: 1300 | AF20: 0 | AG20: 8000 | AH20: 2020.8603 | AI20: 800 | AJ20: 7200 | AK20: 0 | AL20: 2043.2745 | AM20: 0 | AN20: 1000 | AO20: 11007.047 | AP20: 1519.5448 | AQ20: 3999.6742 | AR20: 9000.0571 | AS20: 8000 | AT20: 3500 | AU20: 800 | AV20: 3800 | AW20: 2044.9997 | AX20: 369.61071 | AY20: 0 | AZ20: 0 | BA20: 1800 | BB20: 2499.7026 | BC20: 0 | BD20: 13500 | BE20: 15000
B21: =B20+1 -> 46187 | C21: =TEXT(B21,"ddd") -> Mgg | D21: =SUM(E21:BE21) -> 193657.78 | E21: 733.5729 | F21: 1000 | G21: 1200 | H21: 999.51613 | I21: 644.02065 | J21: 0 | K21: 0 | L21: 603.76323 | M21: 673.27548 | N21: 0 | O21: 6000 | P21: 300 | Q21: 6659.5545 | R21: 9300 | S21: =48000+6000 -> 54000 | T21: 8000 | U21: 0 | V21: 0 | W21: 4000 | X21: 5000 | Y21: 750 | Z21: 0 | AA21: 2500 | AB21: 0 | AC21: 89.451613 | AD21: 1000 | AE21: 1300 | AF21: 0 | AG21: 8000 | AH21: 2020.8603 | AI21: 0 | AJ21: 2999.8519 | AK21: 0 | AL21: 2043.2745 | AM21: 0 | AN21: 0 | AO21: 11007.047 | AP21: 1519.5448 | AQ21: 3999.6742 | AR21: 6000.0571 | AS21: 8000 | AT21: 3500 | AU21: 800 | AV21: 3800 | AW21: 2044.9997 | AX21: 369.61071 | AY21: 0 | AZ21: 0 | BA21: 1800 | BB21: 2499.7026 | BC21: 0 | BD21: 13500 | BE21: 15000
B22: Sub Total | D22: =SUM(D15:D21) -> 1522739.8 | E22: =SUM(E15:E21) -> 7465.0103 | F22: =SUM(F15:F21) -> 12000 | G22: =SUM(G15:G21) -> 8400 | H22: =SUM(H15:H21) -> 20799.516 | I22: =SUM(I15:I21) -> 4508.1445 | J22: =SUM(J15:J21) -> 0 | K22: =SUM(K15:K21) -> 900 | ... BE22: =SUM(BE15:BE21) -> 105000
B24: =B21+1 -> 46188 | C24: =TEXT(B24,"ddd") -> Sen | D24: =SUM(E24:BE24) -> 222286.63 | E24: 1199.5729 | F24: 2000 | G24: 1200 | H24: 3300 | I24: 644.02065 | J24: 0 | K24: 150 | L24: 603.76323 | M24: 673.27548 | N24: 5500 | O24: 6000 | P24: 2500 | Q24: 16000 | R24: 9300 | S24: 29000 | T24: 8000 | U24: 7000 | V24: 0 | W24: 4000 | X24: 5000 | Y24: 750 | Z24: 1000 | AA24: 5500 | AB24: 0 | AC24: 89.451613 | AD24: 3500 | AE24: 1300 | AF24: 5500 | AG24: 8000 | AH24: 2020.8603 | AI24: 800 | AJ24: 7200 | AK24: 3499.8768 | AL24: 2043.2745 | AM24: 0 | AN24: 1000 | AO24: 11007.047 | AP24: 1519.5448 | AQ24: 3999.6742 | AR24: 9000.0571 | AS24: 8000 | AT24: 3500 | AU24: 850 | AV24: 3800 | AW24: 2044.9997 | AX24: 369.61071 | AY24: 0 | AZ24: 1121.9003 | BA24: 1800 | BB24: 2499.7026 | BC24: 0 | BD24: 13500 | BE24: 15000
B25: =B24+1 -> 46189 | C25: =TEXT(B25,"ddd") -> Sel | D25: =SUM(E25:BE25) -> 206115.16 | E25: 0 | F25: 1000 | G25: 1200 | H25: 3300 | I25: 644.02065 | J25: 0 | K25: 150 | L25: 603.76323 | M25: 673.27548 | N25: 0 | O25: 0 | P25: 1000 | Q25: 10000 | R25: 9300 | S25: 54000 | T25: 8000 | U25: 7000 | V25: 0 | W25: 2000 | X25: 2500 | Y25: 750 | Z25: 1000 | AA25: 5500 | AB25: 0 | AC25: 89.451613 | AD25: 3500 | AE25: 1300 | AF25: 0 | AG25: 0 | AH25: 2020.8603 | AI25: 800 | AJ25: 7200 | AK25: 3499.8768 | AL25: 2043.2745 | AM25: 0 | AN25: 1000 | AO25: 11007.047 | AP25: 1519.5448 | AQ25: 3999.6742 | AR25: 9000.0571 | AS25: 8000 | AT25: 3500 | AU25: 0 | AV25: 3800 | AW25: 2044.9997 | AX25: 369.61071 | AY25: 0 | AZ25: 0 | BA25: 1800 | BB25: 2499.7026 | BC25: 0 | BD25: 13500 | BE25: 15000
B26: =B25+1 -> 46190 | C26: =TEXT(B26,"ddd") -> Rab | D26: =SUM(E26:BE26) -> 222286.63 | E26: 1199.5729 | F26: 2000 | G26: 1200 | H26: 3300 | I26: 644.02065 | J26: 0 | K26: 150 | L26: 603.76323 | M26: 673.27548 | N26: 5500 | O26: 6000 | P26: 2500 | Q26: 16000 | R26: 9300 | S26: 29000 | T26: 8000 | U26: 7000 | V26: 0 | W26: 4000 | X26: 5000 | Y26: 750 | Z26: 1000 | AA26: 5500 | AB26: 0 | AC26: 89.451613 | AD26: 3500 | AE26: 1300 | AF26: 5500 | AG26: 8000 | AH26: 2020.8603 | AI26: 800 | AJ26: 7200 | AK26: 3499.8768 | AL26: 2043.2745 | AM26: 0 | AN26: 1000 | AO26: 11007.047 | AP26: 1519.5448 | AQ26: 3999.6742 | AR26: 9000.0571 | AS26: 8000 | AT26: 3500 | AU26: 850 | AV26: 3800 | AW26: 2044.9997 | AX26: 369.61071 | AY26: 0 | AZ26: 1121.9003 | BA26: 1800 | BB26: 2499.7026 | BC26: 0 | BD26: 13500 | BE26: 15000
A27: =WEEKNUM(B27) -> 25 | B27: =B26+1 -> 46191 | C27: =TEXT(B27,"ddd") -> Kam | D27: =SUM(E27:BE27) -> 222286.63 | E27: 1199.5729 | F27: 2000 | G27: 1200 | H27: 3300 | I27: 644.02065 | J27: 0 | K27: 150 | L27: 603.76323 | M27: 673.27548 | N27: 5500 | O27: 6000 | P27: 2500 | Q27: 16000 | R27: 9300 | S27: 29000 | T27: 8000 | U27: 7000 | V27: 0 | W27: 4000 | X27: 5000 | Y27: 750 | Z27: 1000 | AA27: 5500 | AB27: 0 | AC27: 89.451613 | AD27: 3500 | AE27: 1300 | AF27: 5500 | AG27: 8000 | AH27: 2020.8603 | AI27: 800 | AJ27: 7200 | AK27: 3499.8768 | AL27: 2043.2745 | AM27: 0 | AN27: 1000 | AO27: 11007.047 | AP27: 1519.5448 | AQ27: 3999.6742 | AR27: 9000.0571 | AS27: 8000 | AT27: 3500 | AU27: 850 | AV27: 3800 | AW27: 2044.9997 | AX27: 369.61071 | AY27: 0 | AZ27: 1121.9003 | BA27: 1800 | BB27: 2499.7026 | BC27: 0 | BD27: 13500 | BE27: 15000
B28: =B27+1 -> 46192 | C28: =TEXT(B28,"ddd") -> Jum | D28: =SUM(E28:BE28) -> 222286.63 | E28: 1199.5729 | F28: 2000 | G28: 1200 | H28: 3300 | I28: 644.02065 | J28: 0 | K28: 150 | L28: 603.76323 | M28: 673.27548 | N28: 5500 | O28: 6000 | P28: 2500 | Q28: 16000 | R28: 9300 | S28: 29000 | T28: 8000 | U28: 7000 | V28: 0 | W28: 4000 | X28: 5000 | Y28: 750 | Z28: 1000 | AA28: 5500 | AB28: 0 | AC28: 89.451613 | AD28: 3500 | AE28: 1300 | AF28: 5500 | AG28: 8000 | AH28: 2020.8603 | AI28: 800 | AJ28: 7200 | AK28: 3499.8768 | AL28: 2043.2745 | AM28: 0 | AN28: 1000 | AO28: 11007.047 | AP28: 1519.5448 | AQ28: 3999.6742 | AR28: 9000.0571 | AS28: 8000 | AT28: 3500 | AU28: 850 | AV28: 3800 | AW28: 2044.9997 | AX28: 369.61071 | AY28: 0 | AZ28: 1121.9003 | BA28: 1800 | BB28: 2499.7026 | BC28: 0 | BD28: 13500 | BE28: 15000
B29: =B28+1 -> 46193 | C29: =TEXT(B29,"ddd") -> Sab | D29: =SUM(E29:BE29) -> 220148.86 | E29: 733.5729 | F29: 1000 | G29: 1200 | H29: 3300 | I29: 644.02065 | J29: 0 | K29: 150 | L29: 603.76323 | M29: 673.27548 | N29: 4500 | O29: 6000 | P29: 1000 | Q29: 16000 | R29: 9300 | S29: 48000 | T29: 8000 | U29: 0 | V29: 0 | W29: 4000 | X29: 5000 | Y29: 750 | Z29: 1000 | AA29: 5500 | AB29: 0 | AC29: 89.451613 | AD29: 3500 | AE29: 1300 | AF29: 0 | AG29: 8000 | AH29: 2020.8603 | AI29: 800 | AJ29: 7200 | AK29: 0 | AL29: 2043.2745 | AM29: 0 | AN29: 1000 | AO29: 11007.047 | AP29: 1519.5448 | AQ29: 3999.6742 | AR29: 9000.0571 | AS29: 8000 | AT29: 3500 | AU29: 800 | AV29: 3800 | AW29: 2044.9997 | AX29: 369.61071 | AY29: 0 | AZ29: 0 | BA29: 1800 | BB29: 2499.7026 | BC29: 0 | BD29: 13500 | BE29: 15000
B30: =B29+1 -> 46194 | C30: =TEXT(B30,"ddd") -> Mgg | D30: =SUM(E30:BE30) -> 193657.78 | E30: 733.5729 | F30: 1000 | G30: 1200 | H30: 999.51613 | I30: 644.02065 | J30: 0 | K30: 0 | L30: 603.76323 | M30: 673.27548 | N30: 0 | O30: 6000 | P30: 300 | Q30: 6659.5545 | R30: 9300 | S30: =48000+6000 -> 54000 | T30: 8000 | U30: 0 | V30: 0 | W30: 4000 | X30: 5000 | Y30: 750 | Z30: 0 | AA30: 2500 | AB30: 0 | AC30: 89.451613 | AD30: 1000 | AE30: 1300 | AF30: 0 | AG30: 8000 | AH30: 2020.8603 | AI30: 0 | AJ30: 2999.8519 | AK30: 0 | AL30: 2043.2745 | AM30: 0 | AN30: 0 | AO30: 11007.047 | AP30: 1519.5448 | AQ30: 3999.6742 | AR30: 6000.0571 | AS30: 8000 | AT30: 3500 | AU30: 800 | AV30: 3800 | AW30: 2044.9997 | AX30: 369.61071 | AY30: 0 | AZ30: 0 | BA30: 1800 | BB30: 2499.7026 | BC30: 0 | BD30: 13500 | BE30: 15000
B31: Sub Total | D31: =SUM(D24:D30) -> 1509068.3 | E31: =SUM(E24:E30) -> 6265.4374 | F31: =SUM(F24:F30) -> 11000 | G31: =SUM(G24:G30) -> 8400 | H31: =SUM(H24:H30) -> 20799.516 | I31: =SUM(I24:I30) -> 4508.1445 | J31: =SUM(J24:J30) -> 0 | K31: =SUM(K24:K30) -> 900 | ... BE31: =SUM(BE24:BE30) -> 105000
B33: =B30+1 -> 46195 | C33: =TEXT(B33,"ddd") -> Sen | D33: =SUM(E33:BE33) -> 222286.63 | E33: 1199.5729 | F33: 2000 | G33: 1200 | H33: 3300 | I33: 644.02065 | J33: 0 | K33: 150 | L33: 603.76323 | M33: 673.27548 | N33: 5500 | O33: 6000 | P33: 2500 | Q33: 16000 | R33: 9300 | S33: 29000 | T33: 8000 | U33: 7000 | V33: 0 | W33: 4000 | X33: 5000 | Y33: 750 | Z33: 1000 | AA33: 5500 | AB33: 0 | AC33: 89.451613 | AD33: 3500 | AE33: 1300 | AF33: 5500 | AG33: 8000 | AH33: 2020.8603 | AI33: 800 | AJ33: 7200 | AK33: 3499.8768 | AL33: 2043.2745 | AM33: 0 | AN33: 1000 | AO33: 11007.047 | AP33: 1519.5448 | AQ33: 3999.6742 | AR33: 9000.0571 | AS33: 8000 | AT33: 3500 | AU33: 850 | AV33: 3800 | AW33: 2044.9997 | AX33: 369.61071 | AY33: 0 | AZ33: 1121.9003 | BA33: 1800 | BB33: 2499.7026 | BC33: 0 | BD33: 13500 | BE33: 15000
B34: =B33+1 -> 46196 | C34: =TEXT(B34,"ddd") -> Sel | D34: =SUM(E34:BE34) -> 222286.63 | E34: 1199.5729 | F34: 2000 | G34: 1200 | H34: 3300 | I34: 644.02065 | J34: 0 | K34: 150 | L34: 603.76323 | M34: 673.27548 | N34: 5500 | O34: 6000 | P34: 2500 | Q34: 16000 | R34: 9300 | S34: 29000 | T34: 8000 | U34: 7000 | V34: 0 | W34: 4000 | X34: 5000 | Y34: 750 | Z34: 1000 | AA34: 5500 | AB34: 0 | AC34: 89.451613 | AD34: 3500 | AE34: 1300 | AF34: 5500 | AG34: 8000 | AH34: 2020.8603 | AI34: 800 | AJ34: 7200 | AK34: 3499.8768 | AL34: 2043.2745 | AM34: 0 | AN34: 1000 | AO34: 11007.047 | AP34: 1519.5448 | AQ34: 3999.6742 | AR34: 9000.0571 | AS34: 8000 | AT34: 3500 | AU34: 850 | AV34: 3800 | AW34: 2044.9997 | AX34: 369.61071 | AY34: 0 | AZ34: 1121.9003 | BA34: 1800 | BB34: 2499.7026 | BC34: 0 | BD34: 13500 | BE34: 15000
B35: =B34+1 -> 46197 | C35: =TEXT(B35,"ddd") -> Rab | D35: =SUM(E35:BE35) -> 222286.63 | E35: 1199.5729 | F35: 2000 | G35: 1200 | H35: 3300 | I35: 644.02065 | J35: 0 | K35: 150 | L35: 603.76323 | M35: 673.27548 | N35: 5500 | O35: 6000 | P35: 2500 | Q35: 16000 | R35: 9300 | S35: 29000 | T35: 8000 | U35: 7000 | V35: 0 | W35: 4000 | X35: 5000 | Y35: 750 | Z35: 1000 | AA35: 5500 | AB35: 0 | AC35: 89.451613 | AD35: 3500 | AE35: 1300 | AF35: 5500 | AG35: 8000 | AH35: 2020.8603 | AI35: 800 | AJ35: 7200 | AK35: 3499.8768 | AL35: 2043.2745 | AM35: 0 | AN35: 1000 | AO35: 11007.047 | AP35: 1519.5448 | AQ35: 3999.6742 | AR35: 9000.0571 | AS35: 8000 | AT35: 3500 | AU35: 850 | AV35: 3800 | AW35: 2044.9997 | AX35: 369.61071 | AY35: 0 | AZ35: 1121.9003 | BA35: 1800 | BB35: 2499.7026 | BC35: 0 | BD35: 13500 | BE35: 15000
A36: =WEEKNUM(B36) -> 26 | B36: =B35+1 -> 46198 | C36: =TEXT(B36,"ddd") -> Kam | D36: =SUM(E36:BE36) -> 222286.63 | E36: 1199.5729 | F36: 2000 | G36: 1200 | H36: 3300 | I36: 644.02065 | J36: 0 | K36: 150 | L36: 603.76323 | M36: 673.27548 | N36: 5500 | O36: 6000 | P36: 2500 | Q36: 16000 | R36: 9300 | S36: 29000 | T36: 8000 | U36: 7000 | V36: 0 | W36: 4000 | X36: 5000 | Y36: 750 | Z36: 1000 | AA36: 5500 | AB36: 0 | AC36: 89.451613 | AD36: 3500 | AE36: 1300 | AF36: 5500 | AG36: 8000 | AH36: 2020.8603 | AI36: 800 | AJ36: 7200 | AK36: 3499.8768 | AL36: 2043.2745 | AM36: 0 | AN36: 1000 | AO36: 11007.047 | AP36: 1519.5448 | AQ36: 3999.6742 | AR36: 9000.0571 | AS36: 8000 | AT36: 3500 | AU36: 850 | AV36: 3800 | AW36: 2044.9997 | AX36: 369.61071 | AY36: 0 | AZ36: 1121.9003 | BA36: 1800 | BB36: 2499.7026 | BC36: 0 | BD36: 13500 | BE36: 15000
B37: =B36+1 -> 46199 | C37: =TEXT(B37,"ddd") -> Jum | D37: =SUM(E37:BE37) -> 222286.63 | E37: 1199.5729 | F37: 2000 | G37: 1200 | H37: 3300 | I37: 644.02065 | J37: 0 | K37: 150 | L37: 603.76323 | M37: 673.27548 | N37: 5500 | O37: 6000 | P37: 2500 | Q37: 16000 | R37: 9300 | S37: 29000 | T37: 8000 | U37: 7000 | V37: 0 | W37: 4000 | X37: 5000 | Y37: 750 | Z37: 1000 | AA37: 5500 | AB37: 0 | AC37: 89.451613 | AD37: 3500 | AE37: 1300 | AF37: 5500 | AG37: 8000 | AH37: 2020.8603 | AI37: 800 | AJ37: 7200 | AK37: 3499.8768 | AL37: 2043.2745 | AM37: 0 | AN37: 1000 | AO37: 11007.047 | AP37: 1519.5448 | AQ37: 3999.6742 | AR37: 9000.0571 | AS37: 8000 | AT37: 3500 | AU37: 850 | AV37: 3800 | AW37: 2044.9997 | AX37: 369.61071 | AY37: 0 | AZ37: 1121.9003 | BA37: 1800 | BB37: 2499.7026 | BC37: 0 | BD37: 13500 | BE37: 15000
B38: =B37+1 -> 46200 | C38: =TEXT(B38,"ddd") -> Sab | D38: =SUM(E38:BE38) -> 220148.86 | E38: 733.5729 | F38: 1000 | G38: 1200 | H38: 3300 | I38: 644.02065 | J38: 0 | K38: 150 | L38: 603.76323 | M38: 673.27548 | N38: 4500 | O38: 6000 | P38: 1000 | Q38: 16000 | R38: 9300 | S38: 48000 | T38: 8000 | U38: 0 | V38: 0 | W38: 4000 | X38: 5000 | Y38: 750 | Z38: 1000 | AA38: 5500 | AB38: 0 | AC38: 89.451613 | AD38: 3500 | AE38: 1300 | AF38: 0 | AG38: 8000 | AH38: 2020.8603 | AI38: 800 | AJ38: 7200 | AK38: 0 | AL38: 2043.2745 | AM38: 0 | AN38: 1000 | AO38: 11007.047 | AP38: 1519.5448 | AQ38: 3999.6742 | AR38: 9000.0571 | AS38: 8000 | AT38: 3500 | AU38: 800 | AV38: 3800 | AW38: 2044.9997 | AX38: 369.61071 | AY38: 0 | AZ38: 0 | BA38: 1800 | BB38: 2499.7026 | BC38: 0 | BD38: 13500 | BE38: 15000
B39: =B38+1 -> 46201 | C39: =TEXT(B39,"ddd") -> Mgg | D39: =SUM(E39:BE39) -> 193657.78 | E39: 733.5729 | F39: 1000 | G39: 1200 | H39: 999.51613 | I39: 644.02065 | J39: 0 | K39: 0 | L39: 603.76323 | M39: 673.27548 | N39: 0 | O39: 6000 | P39: 300 | Q39: 6659.5545 | R39: 9300 | S39: =48000+6000 -> 54000 | T39: 8000 | U39: 0 | V39: 0 | W39: 4000 | X39: 5000 | Y39: 750 | Z39: 0 | AA39: 2500 | AB39: 0 | AC39: 89.451613 | AD39: 1000 | AE39: 1300 | AF39: 0 | AG39: 8000 | AH39: 2020.8603 | AI39: 0 | AJ39: 2999.8519 | AK39: 0 | AL39: 2043.2745 | AM39: 0 | AN39: 0 | AO39: 11007.047 | AP39: 1519.5448 | AQ39: 3999.6742 | AR39: 6000.0571 | AS39: 8000 | AT39: 3500 | AU39: 800 | AV39: 3800 | AW39: 2044.9997 | AX39: 369.61071 | AY39: 0 | AZ39: 0 | BA39: 1800 | BB39: 2499.7026 | BC39: 0 | BD39: 13500 | BE39: 15000
B40: Sub Total | D40: =SUM(D33:D39) -> 1525239.8 | E40: =SUM(E33:E39) -> 7465.0103 | F40: =SUM(F33:F39) -> 12000 | G40: =SUM(G33:G39) -> 8400 | H40: =SUM(H33:H39) -> 20799.516 | I40: =SUM(I33:I39) -> 4508.1445 | J40: =SUM(J33:J39) -> 0 | K40: =SUM(K33:K39) -> 900 | ... BE40: =SUM(BE33:BE39) -> 105000
B42: =B39+1 -> 46202 | C42: =TEXT(B42,"ddd") -> Sen | D42: =SUM(E42:BE42) -> 222286.63 | E42: 1199.5729 | F42: 2000 | G42: 1200 | H42: 3300 | I42: 644.02065 | J42: 0 | K42: 150 | L42: 603.76323 | M42: 673.27548 | N42: 5500 | O42: 6000 | P42: 2500 | Q42: 16000 | R42: 9300 | S42: 29000 | T42: 8000 | U42: 7000 | V42: 0 | W42: 4000 | X42: 5000 | Y42: 750 | Z42: 1000 | AA42: 5500 | AB42: 0 | AC42: 89.451613 | AD42: 3500 | AE42: 1300 | AF42: 5500 | AG42: 8000 | AH42: 2020.8603 | AI42: 800 | AJ42: 7200 | AK42: 3499.8768 | AL42: 2043.2745 | AM42: 0 | AN42: 1000 | AO42: 11007.047 | AP42: 1519.5448 | AQ42: 3999.6742 | AR42: 9000.0571 | AS42: 8000 | AT42: 3500 | AU42: 850 | AV42: 3800 | AW42: 2044.9997 | AX42: 369.61071 | AY42: 0 | AZ42: 1121.9003 | BA42: 1800 | BB42: 2499.7026 | BC42: 0 | BD42: 13500 | BE42: 15000
B43: =B42+1 -> 46203 | C43: =TEXT(B43,"ddd") -> Sel | D43: =SUM(E43:BE43) -> 222286.63 | E43: 1199.5729 | F43: 2000 | G43: 1200 | H43: 3300 | I43: 644.02065 | J43: 0 | K43: 150 | L43: 603.76323 | M43: 673.27548 | N43: 5500 | O43: 6000 | P43: 2500 | Q43: 16000 | R43: 9300 | S43: 29000 | T43: 8000 | U43: 7000 | V43: 0 | W43: 4000 | X43: 5000 | Y43: 750 | Z43: 1000 | AA43: 5500 | AB43: 0 | AC43: 89.451613 | AD43: 3500 | AE43: 1300 | AF43: 5500 | AG43: 8000 | AH43: 2020.8603 | AI43: 800 | AJ43: 7200 | AK43: 3499.8768 | AL43: 2043.2745 | AM43: 0 | AN43: 1000 | AO43: 11007.047 | AP43: 1519.5448 | AQ43: 3999.6742 | AR43: 9000.0571 | AS43: 8000 | AT43: 3500 | AU43: 850 | AV43: 3800 | AW43: 2044.9997 | AX43: 369.61071 | AY43: 0 | AZ43: 1121.9003 | BA43: 1800 | BB43: 2499.7026 | BC43: 0 | BD43: 13500 | BE43: 15000
B44: Sub Total | D44: =SUM(D42:D43) -> 444573.26 | E44: =SUM(E42:E43) -> 2399.1458 | F44: =SUM(F42:F43) -> 4000 | G44: =SUM(G42:G43) -> 2400 | H44: =SUM(H42:H43) -> 6600 | I44: =SUM(I42:I43) -> 1288.0413 | J44: =SUM(J42:J43) -> 0 | K44: =SUM(K42:K43) -> 300 | ... BE44: =SUM(BE42:BE43) -> 30000
...

Sheet KEBUTUHAN GAS
A1: KEBUTUHAN GAS
A4: ='SO JUNI 2026 (Rev.2)'!A3 -> 46174 | E4: KEBUTUHAN GAS | I4: KUOTA GAS
A5: Week | B5: DATE | D5: SELISIH GAS | E5: JABAR | F5: JATENG | G5: JATIM | H5: TOTAL | I5: MS SETU | J5: MS KHT | K5: MS BLORA | L5: MS BITUNG | M5: MS ZEBRA | N5: MS TAMBAKLOROK | O5: MS WUNUT | P5: MS SADANG | Q5: TOTAL
A6: =WEEKNUM(B6) -> 23 | B6: 46174 | C6: =TEXT(B6,"ddd") -> Sen | D6: =Q6-H6 -> -10025.121 | E6: =SUM('SO JUNI 2026 (Rev.2)'!E6:AT6) -> 152800.42 | F6: =SUM('SO JUNI 2026 (Rev.2)'!AU6:BB6) -> 10944.702 | G6: =SUM('SO JUNI 2026 (Rev.2)'!BC6:BE6) -> 13500 | H6: =SUM(E6:G6) -> 177245.12 | I6: ='SO MS'!E6 -> 108000 | J6: ='SO MS'!F6 -> 34320 | K6: ='SO MS'!G6 -> 9600 | L6: =2*5000 -> 10000 | M6: ='SO JUNI 2026 (Rev.2)'!BA6 -> 1800 | N6: ='SO JUNI 2026 (Rev.2)'!AT6 -> 3500 | O6: ='SO JUNI 2026 (Rev.2)'!AZ6 -> 0 | Q6: =SUM(I6:P6) -> 167220
B7: =B6+1 -> 46175 | C7: =TEXT(B7,"ddd") -> Sel | D7: =Q7-H7 -> -38444.732 | E7: =SUM('SO JUNI 2026 (Rev.2)'!E7:AT7) -> 180800.42 | F7: =SUM('SO JUNI 2026 (Rev.2)'!AU7:BB7) -> 12486.213 | G7: =SUM('SO JUNI 2026 (Rev.2)'!BC7:BE7) -> 13500 | H7: =SUM(E7:G7) -> 206786.63 | I7: ='SO MS'!E7 -> 108000 | J7: ='SO MS'!F7 -> 34320 | K7: ='SO MS'!G7 -> 9600 | L7: =2*5000 -> 10000 | M7: ='SO JUNI 2026 (Rev.2)'!BA7 -> 1800 | N7: ='SO JUNI 2026 (Rev.2)'!AT7 -> 3500 | O7: ='SO JUNI 2026 (Rev.2)'!AZ7 -> 1121.9003 | Q7: =SUM(I7:P7) -> 168341.9
B8: =B7+1 -> 46176 | C8: =TEXT(B8,"ddd") -> Rab | D8: =Q8-H8 -> -38444.732 | E8: =SUM('SO JUNI 2026 (Rev.2)'!E8:AT8) -> 180800.42 | F8: =SUM('SO JUNI 2026 (Rev.2)'!AU8:BB8) -> 12486.213 | G8: =SUM('SO JUNI 2026 (Rev.2)'!BC8:BE8) -> 13500 | H8: =SUM(E8:G8) -> 206786.63 | I8: ='SO MS'!E8 -> 108000 | J8: ='SO MS'!F8 -> 34320 | K8: ='SO MS'!G8 -> 9600 | L8: =2*5000 -> 10000 | M8: ='SO JUNI 2026 (Rev.2)'!BA8 -> 1800 | N8: ='SO JUNI 2026 (Rev.2)'!AT8 -> 3500 | O8: ='SO JUNI 2026 (Rev.2)'!AZ8 -> 1121.9003 | Q8: =SUM(I8:P8) -> 168341.9
B9: =B8+1 -> 46177 | C9: =TEXT(B9,"ddd") -> Kam | D9: =Q9-H9 -> -38444.732 | E9: =SUM('SO JUNI 2026 (Rev.2)'!E9:AT9) -> 180800.42 | F9: =SUM('SO JUNI 2026 (Rev.2)'!AU9:BB9) -> 12486.213 | G9: =SUM('SO JUNI 2026 (Rev.2)'!BC9:BE9) -> 13500 | H9: =SUM(E9:G9) -> 206786.63 | I9: ='SO MS'!E9 -> 108000 | J9: ='SO MS'!F9 -> 34320 | K9: ='SO MS'!G9 -> 9600 | L9: =2*5000 -> 10000 | M9: ='SO JUNI 2026 (Rev.2)'!BA9 -> 1800 | N9: ='SO JUNI 2026 (Rev.2)'!AT9 -> 3500 | O9: ='SO JUNI 2026 (Rev.2)'!AZ9 -> 1121.9003 | Q9: =SUM(I9:P9) -> 168341.9
B10: =B9+1 -> 46178 | C10: =TEXT(B10,"ddd") -> Jum | D10: =Q10-H10 -> -38444.732 | E10: =SUM('SO JUNI 2026 (Rev.2)'!E10:AT10) -> 180800.42 | F10: =SUM('SO JUNI 2026 (Rev.2)'!AU10:BB10) -> 12486.213 | G10: =SUM('SO JUNI 2026 (Rev.2)'!BC10:BE10) -> 13500 | H10: =SUM(E10:G10) -> 206786.63 | I10: ='SO MS'!E10 -> 108000 | J10: ='SO MS'!F10 -> 34320 | K10: ='SO MS'!G10 -> 9600 | L10: =2*5000 -> 10000 | M10: ='SO JUNI 2026 (Rev.2)'!BA10 -> 1800 | N10: ='SO JUNI 2026 (Rev.2)'!AT10 -> 3500 | O10: ='SO JUNI 2026 (Rev.2)'!AZ10 -> 1121.9003 | Q10: =SUM(I10:P10) -> 168341.9
B11: =B10+1 -> 46179 | C11: =TEXT(B11,"ddd") -> Sab | D11: =Q11-H11 -> -37928.855 | E11: =SUM('SO JUNI 2026 (Rev.2)'!E11:AT11) -> 180334.54 | F11: =SUM('SO JUNI 2026 (Rev.2)'!AU11:BB11) -> 11314.313 | G11: =SUM('SO JUNI 2026 (Rev.2)'!BC11:BE11) -> 13500 | H11: =SUM(E11:G11) -> 205148.86 | I11: ='SO MS'!E11 -> 108000 | J11: ='SO MS'!F11 -> 34320 | K11: ='SO MS'!G11 -> 9600 | L11: =2*5000 -> 10000 | M11: ='SO JUNI 2026 (Rev.2)'!BA11 -> 1800 | N11: ='SO JUNI 2026 (Rev.2)'!AT11 -> 3500 | O11: ='SO JUNI 2026 (Rev.2)'!AZ11 -> 0 | Q11: =SUM(I11:P11) -> 167220
B12: =B11+1 -> 46180 | C12: =TEXT(B12,"ddd") -> Mgg | D12: =Q12-H12 -> -11437.778 | E12: =SUM('SO JUNI 2026 (Rev.2)'!E12:AT12) -> 153843.46 | F12: =SUM('SO JUNI 2026 (Rev.2)'!AU12:BB12) -> 11314.313 | G12: =SUM('SO JUNI 2026 (Rev.2)'!BC12:BE12) -> 13500 | H12: =SUM(E12:G12) -> 178657.78 | I12: ='SO MS'!E12 -> 108000 | J12: ='SO MS'!F12 -> 34320 | K12: ='SO MS'!G12 -> 9600 | L12: =2*5000 -> 10000 | M12: ='SO JUNI 2026 (Rev.2)'!BA12 -> 1800 | N12: ='SO JUNI 2026 (Rev.2)'!AT12 -> 3500 | O12: ='SO JUNI 2026 (Rev.2)'!AZ12 -> 0 | Q12: =SUM(I12:P12) -> 167220
B13: Sub Total | D13: =SUM(D6:D12) -> -213170.68 | E13: =SUM(E6:E12) -> 1210180.1 | F13: =SUM(F6:F12) -> 83518.181 | G13: =SUM(G6:G12) -> 94500 | H13: =SUM(H6:H12) -> 1388198.3 | I13: =SUM(I6:I12) -> 756000 | J13: =SUM(J6:J12) -> 240240 | K13: =SUM(K6:K12) -> 67200 | ... Q13: =SUM(Q6:Q12) -> 1175027.6
A15: =WEEKNUM(B15) -> 24 | B15: =B12+1 -> 46181 | C15: =TEXT(B15,"ddd") -> Sen | D15: =Q15-H15 -> -53444.732 | E15: =SUM('SO JUNI 2026 (Rev.2)'!E15:AT15) -> 180800.42 | F15: =SUM('SO JUNI 2026 (Rev.2)'!AU15:BB15) -> 12486.213 | G15: =SUM('SO JUNI 2026 (Rev.2)'!BC15:BE15) -> 28500 | H15: =SUM(E15:G15) -> 221786.63 | I15: ='SO MS'!E15 -> 108000 | J15: ='SO MS'!F15 -> 34320 | K15: ='SO MS'!G15 -> 9600 | L15: =2*5000 -> 10000 | M15: ='SO JUNI 2026 (Rev.2)'!BA15 -> 1800 | N15: ='SO JUNI 2026 (Rev.2)'!AT15 -> 3500 | O15: ='SO JUNI 2026 (Rev.2)'!AZ15 -> 1121.9003 | Q15: =SUM(I15:P15) -> 168341.9
B16: =B15+1 -> 46182 | C16: =TEXT(B16,"ddd") -> Sel | D16: =Q16-H16 -> -53444.732 | E16: =SUM('SO JUNI 2026 (Rev.2)'!E16:AT16) -> 180800.42 | F16: =SUM('SO JUNI 2026 (Rev.2)'!AU16:BB16) -> 12486.213 | G16: =SUM('SO JUNI 2026 (Rev.2)'!BC16:BE16) -> 28500 | H16: =SUM(E16:G16) -> 221786.63 | I16: ='SO MS'!E16 -> 108000 | J16: ='SO MS'!F16 -> 34320 | K16: ='SO MS'!G16 -> 9600 | L16: =2*5000 -> 10000 | M16: ='SO JUNI 2026 (Rev.2)'!BA16 -> 1800 | N16: ='SO JUNI 2026 (Rev.2)'!AT16 -> 3500 | O16: ='SO JUNI 2026 (Rev.2)'!AZ16 -> 1121.9003 | Q16: =SUM(I16:P16) -> 168341.9
B17: =B16+1 -> 46183 | C17: =TEXT(B17,"ddd") -> Rab | D17: =Q17-H17 -> -53444.732 | E17: =SUM('SO JUNI 2026 (Rev.2)'!E17:AT17) -> 180800.42 | F17: =SUM('SO JUNI 2026 (Rev.2)'!AU17:BB17) -> 12486.213 | G17: =SUM('SO JUNI 2026 (Rev.2)'!BC17:BE17) -> 28500 | H17: =SUM(E17:G17) -> 221786.63 | I17: ='SO MS'!E17 -> 108000 | J17: ='SO MS'!F17 -> 34320 | K17: ='SO MS'!G17 -> 9600 | L17: =2*5000 -> 10000 | M17: ='SO JUNI 2026 (Rev.2)'!BA17 -> 1800 | N17: ='SO JUNI 2026 (Rev.2)'!AT17 -> 3500 | O17: ='SO JUNI 2026 (Rev.2)'!AZ17 -> 1121.9003 | Q17: =SUM(I17:P17) -> 168341.9
B18: =B17+1 -> 46184 | C18: =TEXT(B18,"ddd") -> Kam | D18: =Q18-H18 -> -53444.732 | E18: =SUM('SO JUNI 2026 (Rev.2)'!E18:AT18) -> 180800.42 | F18: =SUM('SO JUNI 2026 (Rev.2)'!AU18:BB18) -> 12486.213 | G18: =SUM('SO JUNI 2026 (Rev.2)'!BC18:BE18) -> 28500 | H18: =SUM(E18:G18) -> 221786.63 | I18: ='SO MS'!E18 -> 108000 | J18: ='SO MS'!F18 -> 34320 | K18: ='SO MS'!G18 -> 9600 | L18: =2*5000 -> 10000 | M18: ='SO JUNI 2026 (Rev.2)'!BA18 -> 1800 | N18: ='SO JUNI 2026 (Rev.2)'!AT18 -> 3500 | O18: ='SO JUNI 2026 (Rev.2)'!AZ18 -> 1121.9003 | Q18: =SUM(I18:P18) -> 168341.9
B19: =B18+1 -> 46185 | C19: =TEXT(B19,"ddd") -> Jum | D19: =Q19-H19 -> -53444.732 | E19: =SUM('SO JUNI 2026 (Rev.2)'!E19:AT19) -> 180800.42 | F19: =SUM('SO JUNI 2026 (Rev.2)'!AU19:BB19) -> 12486.213 | G19: =SUM('SO JUNI 2026 (Rev.2)'!BC19:BE19) -> 28500 | H19: =SUM(E19:G19) -> 221786.63 | I19: ='SO MS'!E19 -> 108000 | J19: ='SO MS'!F19 -> 34320 | K19: ='SO MS'!G19 -> 9600 | L19: =2*5000 -> 10000 | M19: ='SO JUNI 2026 (Rev.2)'!BA19 -> 1800 | N19: ='SO JUNI 2026 (Rev.2)'!AT19 -> 3500 | O19: ='SO JUNI 2026 (Rev.2)'!AZ19 -> 1121.9003 | Q19: =SUM(I19:P19) -> 168341.9
B20: =B19+1 -> 46186 | C20: =TEXT(B20,"ddd") -> Sab | D20: =Q20-H20 -> -52928.855 | E20: =SUM('SO JUNI 2026 (Rev.2)'!E20:AT20) -> 180334.54 | F20: =SUM('SO JUNI 2026 (Rev.2)'!AU20:BB20) -> 11314.313 | G20: =SUM('SO JUNI 2026 (Rev.2)'!BC20:BE20) -> 28500 | H20: =SUM(E20:G20) -> 220148.86 | I20: ='SO MS'!E20 -> 108000 | J20: ='SO MS'!F20 -> 34320 | K20: ='SO MS'!G20 -> 9600 | L20: =2*5000 -> 10000 | M20: ='SO JUNI 2026 (Rev.2)'!BA20 -> 1800 | N20: ='SO JUNI 2026 (Rev.2)'!AT20 -> 3500 | O20: ='SO JUNI 2026 (Rev.2)'!AZ20 -> 0 | Q20: =SUM(I20:P20) -> 167220
B21: =B20+1 -> 46187 | C21: =TEXT(B21,"ddd") -> Mgg | D21: =Q21-H21 -> -26437.778 | E21: =SUM('SO JUNI 2026 (Rev.2)'!E21:AT21) -> 153843.46 | F21: =SUM('SO JUNI 2026 (Rev.2)'!AU21:BB21) -> 11314.313 | G21: =SUM('SO JUNI 2026 (Rev.2)'!BC21:BE21) -> 28500 | H21: =SUM(E21:G21) -> 193657.78 | I21: ='SO MS'!E21 -> 108000 | J21: ='SO MS'!F21 -> 34320 | K21: ='SO MS'!G21 -> 9600 | L21: =2*5000 -> 10000 | M21: ='SO JUNI 2026 (Rev.2)'!BA21 -> 1800 | N21: ='SO JUNI 2026 (Rev.2)'!AT21 -> 3500 | O21: ='SO JUNI 2026 (Rev.2)'!AZ21 -> 0 | Q21: =SUM(I21:P21) -> 167220
B22: Sub Total | D22: =SUM(D15:D21) -> -346590.29 | E22: =SUM(E15:E21) -> 1238180.1 | F22: =SUM(F15:F21) -> 85059.692 | G22: =SUM(G15:G21) -> 199500 | H22: =SUM(H15:H21) -> 1522739.8 | I22: =SUM(I15:I21) -> 756000 | J22: =SUM(J15:J21) -> 240240 | K22: =SUM(K15:K21) -> 67200 | ... Q22: =SUM(Q15:Q21) -> 1176149.5
A24: =WEEKNUM(B24) -> 25 | B24: =B21+1 -> 46188 | C24: =TEXT(B24,"ddd") -> Sen | D24: =Q24-H24 -> -53944.732 | E24: =SUM('SO JUNI 2026 (Rev.2)'!E24:AT24) -> 181300.42 | F24: =SUM('SO JUNI 2026 (Rev.2)'!AU24:BB24) -> 12486.213 | G24: =SUM('SO JUNI 2026 (Rev.2)'!BC24:BE24) -> 28500 | H24: =SUM(E24:G24) -> 222286.63 | I24: ='SO MS'!E24 -> 108000 | J24: ='SO MS'!F24 -> 34320 | K24: ='SO MS'!G24 -> 9600 | L24: =2*5000 -> 10000 | M24: ='SO JUNI 2026 (Rev.2)'!BA24 -> 1800 | N24: ='SO JUNI 2026 (Rev.2)'!AT24 -> 3500 | O24: ='SO JUNI 2026 (Rev.2)'!AZ24 -> 1121.9003 | Q24: =SUM(I24:P24) -> 168341.9
B25: =B24+1 -> 46189 | C25: =TEXT(B25,"ddd") -> Sel | D25: =Q25-H25 -> -38895.159 | E25: =SUM('SO JUNI 2026 (Rev.2)'!E25:AT25) -> 167100.85 | F25: =SUM('SO JUNI 2026 (Rev.2)'!AU25:BB25) -> 10514.313 | G25: =SUM('SO JUNI 2026 (Rev.2)'!BC25:BE25) -> 28500 | H25: =SUM(E25:G25) -> 206115.16 | I25: ='SO MS'!E25 -> 108000 | J25: ='SO MS'!F25 -> 34320 | K25: ='SO MS'!G25 -> 9600 | L25: =2*5000 -> 10000 | M25: ='SO JUNI 2026 (Rev.2)'!BA25 -> 1800 | N25: ='SO JUNI 2026 (Rev.2)'!AT25 -> 3500 | O25: ='SO JUNI 2026 (Rev.2)'!AZ25 -> 0 | Q25: =SUM(I25:P25) -> 167220
B26: =B25+1 -> 46190 | C26: =TEXT(B26,"ddd") -> Rab | D26: =Q26-H26 -> -53944.732 | E26: =SUM('SO JUNI 2026 (Rev.2)'!E26:AT26) -> 181300.42 | F26: =SUM('SO JUNI 2026 (Rev.2)'!AU26:BB26) -> 12486.213 | G26: =SUM('SO JUNI 2026 (Rev.2)'!BC26:BE26) -> 28500 | H26: =SUM(E26:G26) -> 222286.63 | I26: ='SO MS'!E26 -> 108000 | J26: ='SO MS'!F26 -> 34320 | K26: ='SO MS'!G26 -> 9600 | L26: =2*5000 -> 10000 | M26: ='SO JUNI 2026 (Rev.2)'!BA26 -> 1800 | N26: ='SO JUNI 2026 (Rev.2)'!AT26 -> 3500 | O26: ='SO JUNI 2026 (Rev.2)'!AZ26 -> 1121.9003 | Q26: =SUM(I26:P26) -> 168341.9
B27: =B26+1 -> 46191 | C27: =TEXT(B27,"ddd") -> Kam | D27: =Q27-H27 -> -53944.732 | E27: =SUM('SO JUNI 2026 (Rev.2)'!E27:AT27) -> 181300.42 | F27: =SUM('SO JUNI 2026 (Rev.2)'!AU27:BB27) -> 12486.213 | G27: =SUM('SO JUNI 2026 (Rev.2)'!BC27:BE27) -> 28500 | H27: =SUM(E27:G27) -> 222286.63 | I27: ='SO MS'!E27 -> 108000 | J27: ='SO MS'!F27 -> 34320 | K27: ='SO MS'!G27 -> 9600 | L27: =2*5000 -> 10000 | M27: ='SO JUNI 2026 (Rev.2)'!BA27 -> 1800 | N27: ='SO JUNI 2026 (Rev.2)'!AT27 -> 3500 | O27: ='SO JUNI 2026 (Rev.2)'!AZ27 -> 1121.9003 | Q27: =SUM(I27:P27) -> 168341.9
B28: =B27+1 -> 46192 | C28: =TEXT(B28,"ddd") -> Jum | D28: =Q28-H28 -> -53944.732 | E28: =SUM('SO JUNI 2026 (Rev.2)'!E28:AT28) -> 181300.42 | F28: =SUM('SO JUNI 2026 (Rev.2)'!AU28:BB28) -> 12486.213 | G28: =SUM('SO JUNI 2026 (Rev.2)'!BC28:BE28) -> 28500 | H28: =SUM(E28:G28) -> 222286.63 | I28: ='SO MS'!E28 -> 108000 | J28: ='SO MS'!F28 -> 34320 | K28: ='SO MS'!G28 -> 9600 | L28: =2*5000 -> 10000 | M28: ='SO JUNI 2026 (Rev.2)'!BA28 -> 1800 | N28: ='SO JUNI 2026 (Rev.2)'!AT28 -> 3500 | O28: ='SO JUNI 2026 (Rev.2)'!AZ28 -> 1121.9003 | Q28: =SUM(I28:P28) -> 168341.9
B29: =B28+1 -> 46193 | C29: =TEXT(B29,"ddd") -> Sab | D29: =Q29-H29 -> -52928.855 | E29: =SUM('SO JUNI 2026 (Rev.2)'!E29:AT29) -> 180334.54 | F29: =SUM('SO JUNI 2026 (Rev.2)'!AU29:BB29) -> 11314.313 | G29: =SUM('SO JUNI 2026 (Rev.2)'!BC29:BE29) -> 28500 | H29: =SUM(E29:G29) -> 220148.86 | I29: ='SO MS'!E29 -> 108000 | J29: ='SO MS'!F29 -> 34320 | K29: ='SO MS'!G29 -> 9600 | L29: =2*5000 -> 10000 | M29: ='SO JUNI 2026 (Rev.2)'!BA29 -> 1800 | N29: ='SO JUNI 2026 (Rev.2)'!AT29 -> 3500 | O29: ='SO JUNI 2026 (Rev.2)'!AZ29 -> 0 | Q29: =SUM(I29:P29) -> 167220
B30: =B29+1 -> 46194 | C30: =TEXT(B30,"ddd") -> Mgg | D30: =Q30-H30 -> -26437.778 | E30: =SUM('SO JUNI 2026 (Rev.2)'!E30:AT30) -> 153843.46 | F30: =SUM('SO JUNI 2026 (Rev.2)'!AU30:BB30) -> 11314.313 | G30: =SUM('SO JUNI 2026 (Rev.2)'!BC30:BE30) -> 28500 | H30: =SUM(E30:G30) -> 193657.78 | I30: ='SO MS'!E30 -> 108000 | J30: ='SO MS'!F30 -> 34320 | K30: ='SO MS'!G30 -> 9600 | L30: =2*5000 -> 10000 | M30: ='SO JUNI 2026 (Rev.2)'!BA30 -> 1800 | N30: ='SO JUNI 2026 (Rev.2)'!AT30 -> 3500 | O30: ='SO JUNI 2026 (Rev.2)'!AZ30 -> 0 | Q30: =SUM(I30:P30) -> 167220
B31: Sub Total | D31: =SUM(D24:D30) -> -334040.72 | E31: =SUM(E24:E30) -> 1226480.5 | F31: =SUM(F24:F30) -> 83087.792 | G31: =SUM(G24:G30) -> 199500 | H31: =SUM(H24:H30) -> 1509068.3 | I31: =SUM(I24:I30) -> 756000 | J31: =SUM(J24:J30) -> 240240 | K31: =SUM(K24:K30) -> 67200 | ... Q31: =SUM(Q24:Q30) -> 1175027.6
A33: =WEEKNUM(B33) -> 26 | B33: =B30+1 -> 46195 | C33: =TEXT(B33,"ddd") -> Sen | D33: =Q33-H33 -> -53944.732 | E33: =SUM('SO JUNI 2026 (Rev.2)'!E33:AT33) -> 181300.42 | F33: =SUM('SO JUNI 2026 (Rev.2)'!AU33:BB33) -> 12486.213 | G33: =SUM('SO JUNI 2026 (Rev.2)'!BC33:BE33) -> 28500 | H33: =SUM(E33:G33) -> 222286.63 | I33: ='SO MS'!E33 -> 108000 | J33: ='SO MS'!F33 -> 34320 | K33: ='SO MS'!G33 -> 9600 | L33: =2*5000 -> 10000 | M33: ='SO JUNI 2026 (Rev.2)'!BA33 -> 1800 | N33: ='SO JUNI 2026 (Rev.2)'!AT33 -> 3500 | O33: ='SO JUNI 2026 (Rev.2)'!AZ33 -> 1121.9003 | Q33: =SUM(I33:P33) -> 168341.9
B34: =B33+1 -> 46196 | C34: =TEXT(B34,"ddd") -> Sel | D34: =Q34-H34 -> -53944.732 | E34: =SUM('SO JUNI 2026 (Rev.2)'!E34:AT34) -> 181300.42 | F34: =SUM('SO JUNI 2026 (Rev.2)'!AU34:BB34) -> 12486.213 | G34: =SUM('SO JUNI 2026 (Rev.2)'!BC34:BE34) -> 28500 | H34: =SUM(E34:G34) -> 222286.63 | I34: ='SO MS'!E34 -> 108000 | J34: ='SO MS'!F34 -> 34320 | K34: ='SO MS'!G34 -> 9600 | L34: =2*5000 -> 10000 | M34: ='SO JUNI 2026 (Rev.2)'!BA34 -> 1800 | N34: ='SO JUNI 2026 (Rev.2)'!AT34 -> 3500 | O34: ='SO JUNI 2026 (Rev.2)'!AZ34 -> 1121.9003 | Q34: =SUM(I34:P34) -> 168341.9
B35: =B34+1 -> 46197 | C35: =TEXT(B35,"ddd") -> Rab | D35: =Q35-H35 -> -53944.732 | E35: =SUM('SO JUNI 2026 (Rev.2)'!E35:AT35) -> 181300.42 | F35: =SUM('SO JUNI 2026 (Rev.2)'!AU35:BB35) -> 12486.213 | G35: =SUM('SO JUNI 2026 (Rev.2)'!BC35:BE35) -> 28500 | H35: =SUM(E35:G35) -> 222286.63 | I35: ='SO MS'!E35 -> 108000 | J35: ='SO MS'!F35 -> 34320 | K35: ='SO MS'!G35 -> 9600 | L35: =2*5000 -> 10000 | M35: ='SO JUNI 2026 (Rev.2)'!BA35 -> 1800 | N35: ='SO JUNI 2026 (Rev.2)'!AT35 -> 3500 | O35: ='SO JUNI 2026 (Rev.2)'!AZ35 -> 1121.9003 | Q35: =SUM(I35:P35) -> 168341.9
B36: =B35+1 -> 46198 | C36: =TEXT(B36,"ddd") -> Kam | D36: =Q36-H36 -> -38174.397 | E36: =SUM('SO JUNI 2026 (Rev.2)'!E36:AT36) -> 181300.42 | F36: =SUM('SO JUNI 2026 (Rev.2)'!AU36:BB36) -> 12486.213 | G36: =SUM('SO JUNI 2026 (Rev.2)'!BC36:BE36) -> 28500 | H36: =SUM(E36:G36) -> 222286.63 | I36: ='SO MS'!E36 -> 108000 | J36: =SUM('SO JUNI 2026 (Rev.2)'!AH36:AS36) -> 50090.335 | K36: ='SO MS'!G36 -> 9600 | L36: =2*5000 -> 10000 | M36: ='SO JUNI 2026 (Rev.2)'!BA36 -> 1800 | N36: ='SO JUNI 2026 (Rev.2)'!AT36 -> 3500 | O36: ='SO JUNI 2026 (Rev.2)'!AZ36 -> 1121.9003 | Q36: =SUM(I36:P36) -> 184112.24
B37: =B36+1 -> 46199 | C37: =TEXT(B37,"ddd") -> Jum | D37: =Q37-H37 -> -38174.397 | E37: =SUM('SO JUNI 2026 (Rev.2)'!E37:AT37) -> 181300.42 | F37: =SUM('SO JUNI 2026 (Rev.2)'!AU37:BB37) -> 12486.213 | G37: =SUM('SO JUNI 2026 (Rev.2)'!BC37:BE37) -> 28500 | H37: =SUM(E37:G37) -> 222286.63 | I37: ='SO MS'!E37 -> 108000 | J37: =SUM('SO JUNI 2026 (Rev.2)'!AH37:AS37) -> 50090.335 | K37: ='SO MS'!G37 -> 9600 | L37: =2*5000 -> 10000 | M37: ='SO JUNI 2026 (Rev.2)'!BA37 -> 1800 | N37: ='SO JUNI 2026 (Rev.2)'!AT37 -> 3500 | O37: ='SO JUNI 2026 (Rev.2)'!AZ37 -> 1121.9003 | Q37: =SUM(I37:P37) -> 184112.24
B38: =B37+1 -> 46200 | C38: =TEXT(B38,"ddd") -> Sab | D38: =Q38-H38 -> -40658.397 | E38: =SUM('SO JUNI 2026 (Rev.2)'!E38:AT38) -> 180334.54 | F38: =SUM('SO JUNI 2026 (Rev.2)'!AU38:BB38) -> 11314.313 | G38: =SUM('SO JUNI 2026 (Rev.2)'!BC38:BE38) -> 28500 | H38: =SUM(E38:G38) -> 220148.86 | I38: ='SO MS'!E38 -> 108000 | J38: =SUM('SO JUNI 2026 (Rev.2)'!AH38:AS38) -> 46590.458 | K38: ='SO MS'!G38 -> 9600 | L38: =2*5000 -> 10000 | M38: ='SO JUNI 2026 (Rev.2)'!BA38 -> 1800 | N38: ='SO JUNI 2026 (Rev.2)'!AT38 -> 3500 | O38: ='SO JUNI 2026 (Rev.2)'!AZ38 -> 0 | Q38: =SUM(I38:P38) -> 179490.46
B39: =B38+1 -> 46201 | C39: =TEXT(B39,"ddd") -> Mgg | D39: =Q39-H39 -> -23167.468 | E39: =SUM('SO JUNI 2026 (Rev.2)'!E39:AT39) -> 153843.46 | F39: =SUM('SO JUNI 2026 (Rev.2)'!AU39:BB39) -> 11314.313 | G39: =SUM('SO JUNI 2026 (Rev.2)'!BC39:BE39) -> 28500 | H39: =SUM(E39:G39) -> 193657.78 | I39: ='SO MS'!E39 -> 108000 | J39: =SUM('SO JUNI 2026 (Rev.2)'!AH39:AS39) -> 37590.31 | K39: ='SO MS'!G39 -> 9600 | L39: =2*5000 -> 10000 | M39: ='SO JUNI 2026 (Rev.2)'!BA39 -> 1800 | N39: ='SO JUNI 2026 (Rev.2)'!AT39 -> 3500 | O39: ='SO JUNI 2026 (Rev.2)'!AZ39 -> 0 | Q39: =SUM(I39:P39) -> 170490.31
B40: Sub Total | D40: =SUM(D33:D39) -> -302008.85 | E40: =SUM(E33:E39) -> 1240680.1 | F40: =SUM(F33:F39) -> 85059.692 | G40: =SUM(G33:G39) -> 199500 | H40: =SUM(H33:H39) -> 1525239.8 | I40: =SUM(I33:I39) -> 756000 | J40: =SUM(J33:J39) -> 287321.44 | K40: =SUM(K33:K39) -> 67200 | ... Q40: =SUM(Q33:Q39) -> 1223230.9
A42: =WEEKNUM(B42) -> 27 | B42: =B39+1 -> 46202 | C42: =TEXT(B42,"ddd") -> Sen | D42: =Q42-H42 -> -38174.397 | E42: =SUM('SO JUNI 2026 (Rev.2)'!E42:AT42) -> 181300.42 | F42: =SUM('SO JUNI 2026 (Rev.2)'!AU42:BB42) -> 12486.213 | G42: =SUM('SO JUNI 2026 (Rev.2)'!BC42:BE42) -> 28500 | H42: =SUM(E42:G42) -> 222286.63 | I42: ='SO MS'!E42 -> 108000 | J42: =SUM('SO JUNI 2026 (Rev.2)'!AH42:AS42) -> 50090.335 | K42: ='SO MS'!G42 -> 9600 | L42: =2*5000 -> 10000 | M42: ='SO JUNI 2026 (Rev.2)'!BA42 -> 1800 | N42: ='SO JUNI 2026 (Rev.2)'!AT42 -> 3500 | O42: ='SO JUNI 2026 (Rev.2)'!AZ42 -> 1121.9003 | Q42: =SUM(I42:P42) -> 184112.24
B43: =B42+1 -> 46203 | C43: =TEXT(B43,"ddd") -> Sel | D43: =Q43-H43 -> -38174.397 | E43: =SUM('SO JUNI 2026 (Rev.2)'!E43:AT43) -> 181300.42 | F43: =SUM('SO JUNI 2026 (Rev.2)'!AU43:BB43) -> 12486.213 | G43: =SUM('SO JUNI 2026 (Rev.2)'!BC43:BE43) -> 28500 | H43: =SUM(E43:G43) -> 222286.63 | I43: ='SO MS'!E43 -> 108000 | J43: =SUM('SO JUNI 2026 (Rev.2)'!AH43:AS43) -> 50090.335 | K43: ='SO MS'!G43 -> 9600 | L43: =2*5000 -> 10000 | M43: ='SO JUNI 2026 (Rev.2)'!BA43 -> 1800 | N43: ='SO JUNI 2026 (Rev.2)'!AT43 -> 3500 | O43: ='SO JUNI 2026 (Rev.2)'!AZ43 -> 1121.9003 | Q43: =SUM(I43:P43) -> 184112.24
B44: Sub Total | D44: =SUM(D42:D43) -> -76348.794 | E44: =SUM(E42:E43) -> 362600.84 | F44: =SUM(F42:F43) -> 24972.427 | G44: =SUM(G42:G43) -> 57000 | H44: =SUM(H42:H43) -> 444573.26 | I44: =SUM(I42:I43) -> 216000 | J44: =SUM(J42:J43) -> 100180.67 | K44: =SUM(K42:K43) -> 19200 | ... Q44: =SUM(Q42:Q43) -> 368224.47
B46: Sub Total | D46: =SUM(D13+D22+D31+D40+D44) -> -1272159.3 | E46: =SUM(E13+E22+E31+E40+E44) -> 5278121.7 | F46: =SUM(F13+F22+F31+F40+F44) -> 361697.78 | G46: =SUM(G13+G22+G31+G40+G44) -> 750000 | H46: =SUM(H13+H22+H31+H40+H44) -> 6389819.5 | I46: =SUM(I13+I22+I31+I40+I44) -> 3240000 | J46: =SUM(J13+J22+J31+J40+J44) -> 1108222.1 | K46: =SUM(K13+K22+K31+K40+K44) -> 288000 | ... Q46: =SUM(Q13+Q22+Q31+Q40+Q44) -> 5117660.1
B47: Total | D47: =SUM(D6:D12,D15:D21,D24:D30,D33:D39,D42:D43) -> -1272159.3 | E47: =SUM(E6:E12,E15:E21,E24:E30,E33:E39,E42:E43) -> 5278121.7 | F47: =SUM(F6:F12,F15:F21,F24:F30,F33:F39,F42:F43) -> 361697.78 | G47: =SUM(G6:G12,G15:G21,G24:G30,G33:G39,G42:G43) -> 750000 | H47: =SUM(H6:H12,H15:H21,H24:H30,H33:H39,H42:H43) -> 6389819.5 | I47: =SUM(I6:I12,I15:I21,I24:I30,I33:I39,I42:I43) -> 3240000 | J47: =SUM(J6:J12,J15:J21,J24:J30,J33:J39,J42:J43) -> 1108222.1 | K47: =SUM(K6:K12,K15:K21,K24:K30,K33:K39,K42:K43) -> 288000 | ... Q47: =SUM(Q6:Q12,Q15:Q21,Q24:Q30,Q33:Q39,Q42:Q43) -> 5117660.1

Sheet Daily serapan Gas
A1: KEBUTUHAN GAS
A4: ='SO JUNI 2026 (Rev.2)'!A3 -> 46174 | E4: KEBUTUHAN GAS (SO) | I4: KUOTA GAS
A5: Week | B5: DATE | D5: Sales Order vs Kuota Gas | E5: JABAR | F5: JATENG | G5: JATIM | H5: TOTAL | I5: MS SETU | J5: MS KHT | K5: MS BLORA | L5: MS BITUNG | M5: MS ZEBRA | N5: MS TAMBAKLOROK | O5: MS WUNUT | P5: MS SADANG | Q5: TOTAL
A6: =WEEKNUM(B6) -> 23 | B6: =A4 -> 46174 | C6: =TEXT(B6,"ddd") -> Sen | D6: =Q6-H6 -> -46104.241 | E6: =SUM('SO JUNI 2026 (Rev.2)'!E6:AT6) -> 152800.42 | F6: =SUM('SO JUNI 2026 (Rev.2)'!AU6:BE6) -> 24444.702 | G6: =SUM('SO JUNI 2026 (Rev.2)'!AZ6:BA6) -> 1800 | H6: =SUM(E6:G6) -> 179045.12 | I6: ='Summary sales'!D8 -> 88200.22 | J6: ='Summary sales'!E8 -> 36130.03 | K6: ='Summary sales'!F8 -> 8610.63 | L6: ='Summary sales'!G8 -> 0 | N6: ='Summary sales'!I8 -> 0 | Q6: =SUM(I6:P6) -> 132940.88
B7: =B6+1 -> 46175 | C7: =TEXT(B7,"ddd") -> Sel | D7: =Q7-H7 -> -66522.393 | E7: =SUM('SO JUNI 2026 (Rev.2)'!E7:AT7) -> 180800.42 | F7: =SUM('SO JUNI 2026 (Rev.2)'!AU7:BE7) -> 25986.213 | G7: =SUM('SO JUNI 2026 (Rev.2)'!AZ7:BA7) -> 2921.9003 | H7: =SUM(E7:G7) -> 209708.53 | I7: ='Summary sales'!D9 -> 103046.29 | J7: ='Summary sales'!E9 -> 36697.27 | K7: ='Summary sales'!F9 -> 3442.58 | L7: ='Summary sales'!G9 -> 0 | N7: ='Summary sales'!I9 -> 0 | Q7: =SUM(I7:P7) -> 143186.14
B8: =B7+1 -> 46176 | C8: =TEXT(B8,"ddd") -> Rab | D8: =Q8-H8 -> -28334.943 | E8: =SUM('SO JUNI 2026 (Rev.2)'!E8:AT8) -> 180800.42 | F8: =SUM('SO JUNI 2026 (Rev.2)'!AU8:BE8) -> 25986.213 | G8: =SUM('SO JUNI 2026 (Rev.2)'!AZ8:BA8) -> 2921.9003 | H8: =SUM(E8:G8) -> 209708.53 | I8: ='Summary sales'!D10 -> 131646.3 | J8: ='Summary sales'!E10 -> 46224.41 | K8: ='Summary sales'!F10 -> 3502.88 | L8: ='Summary sales'!G10 -> 0 | N8: ='Summary sales'!I10 -> 0 | Q8: =SUM(I8:P8) -> 181373.59
B9: =B8+1 -> 46177 | C9: =TEXT(B9,"ddd") -> Kam | D9: =Q9-H9 -> -29777.253 | E9: =SUM('SO JUNI 2026 (Rev.2)'!E9:AT9) -> 180800.42 | F9: =SUM('SO JUNI 2026 (Rev.2)'!AU9:BE9) -> 25986.213 | G9: =SUM('SO JUNI 2026 (Rev.2)'!AZ9:BA9) -> 2921.9003 | H9: =SUM(E9:G9) -> 209708.53 | I9: ='Summary sales'!D11 -> 129880.06 | J9: ='Summary sales'!E11 -> 37276.4 | K9: ='Summary sales'!F11 -> 8719.67 | L9: ='Summary sales'!G11 -> 0 | N9: ='Summary sales'!I11 -> 4055.15 | Q9: =SUM(I9:P9) -> 179931.28
B10: =B9+1 -> 46178 | C10: =TEXT(B10,"ddd") -> Jum | D10: =Q10-H10 -> -11021.103 | E10: =SUM('SO JUNI 2026 (Rev.2)'!E10:AT10) -> 180800.42 | F10: =SUM('SO JUNI 2026 (Rev.2)'!AU10:BE10) -> 25986.213 | G10: =SUM('SO JUNI 2026 (Rev.2)'!AZ10:BA10) -> 2921.9003 | H10: =SUM(E10:G10) -> 209708.53 | I10: ='Summary sales'!D12 -> 131577.8 | J10: ='Summary sales'!E12 -> 42409.96 | K10: ='Summary sales'!F12 -> 13049.65 | L10: ='Summary sales'!G12 -> 7939.9 | N10: ='Summary sales'!I12 -> 3710.12 | Q10: =SUM(I10:P10) -> 198687.43
B11: =B10+1 -> 46179 | C11: =TEXT(B11,"ddd") -> Sab | D11: =Q11-H11 -> -17333.845 | E11: =SUM('SO JUNI 2026 (Rev.2)'!E11:AT11) -> 180334.54 | F11: =SUM('SO JUNI 2026 (Rev.2)'!AU11:BE11) -> 24814.313 | G11: =SUM('SO JUNI 2026 (Rev.2)'!AZ11:BA11) -> 1800 | H11: =SUM(E11:G11) -> 206948.86 | I11: ='Summary sales'!D13 -> 127620.56 | J11: ='Summary sales'!E13 -> 47833.25 | K11: ='Summary sales'!F13 -> 14161.2 | L11: ='Summary sales'!G13 -> 0 | N11: ='Summary sales'!I13 -> 0 | Q11: =SUM(I11:P11) -> 189615.01
B12: =B11+1 -> 46180 | C12: =TEXT(B12,"ddd") -> Mgg | D12: =Q12-H12 -> -12257.988 | E12: =SUM('SO JUNI 2026 (Rev.2)'!E12:AT12) -> 153843.46 | F12: =SUM('SO JUNI 2026 (Rev.2)'!AU12:BE12) -> 24814.313 | G12: =SUM('SO JUNI 2026 (Rev.2)'!AZ12:BA12) -> 1800 | H12: =SUM(E12:G12) -> 180457.78 | I12: ='Summary sales'!D14 -> 119461.99 | J12: ='Summary sales'!E14 -> 31263.59 | K12: ='Summary sales'!F14 -> 13423.17 | L12: ='Summary sales'!G14 -> 0 | N12: ='Summary sales'!I14 -> 4051.04 | Q12: =SUM(I12:P12) -> 168199.79
B13: Sub Total | D13: =SUM(D6:D12) -> -211351.76 | E13: =SUM(E6:E12) -> 1210180.1 | F13: =SUM(F6:F12) -> 178018.18 | G13: =SUM(G6:G12) -> 17087.601 | H13: =SUM(H6:H12) -> 1405285.9 | I13: =SUM(I6:I12) -> 831433.22 | J13: =SUM(J6:J12) -> 277834.91 | K13: =SUM(K6:K12) -> 64909.78 | ... Q13: =SUM(Q6:Q12) -> 1193934.1
A15: =WEEKNUM(B15) -> 24 | B15: =B12+1 -> 46181 | C15: =TEXT(B15,"ddd") -> Sen | D15: =Q15-H15 -> -25252.373 | E15: =SUM('SO JUNI 2026 (Rev.2)'!E15:AT15) -> 180800.42 | F15: =SUM('SO JUNI 2026 (Rev.2)'!AU15:BE15) -> 40986.213 | G15: =SUM('SO JUNI 2026 (Rev.2)'!AZ15:BA15) -> 2921.9003 | H15: =SUM(E15:G15) -> 224708.53 | I15: ='Summary sales'!D15 -> 139463.82 | J15: ='Summary sales'!E15 -> 41229.24 | K15: ='Summary sales'!F15 -> 14547.9 | L15: ='Summary sales'!G15 -> 0 | N15: ='Summary sales'!I15 -> 4215.2 | Q15: =SUM(I15:P15) -> 199456.16
B16: =B15+1 -> 46182 | C16: =TEXT(B16,"ddd") -> Sel | D16: =Q16-H16 -> -33661.073 | E16: =SUM('SO JUNI 2026 (Rev.2)'!E16:AT16) -> 180800.42 | F16: =SUM('SO JUNI 2026 (Rev.2)'!AU16:BE16) -> 40986.213 | G16: =SUM('SO JUNI 2026 (Rev.2)'!AZ16:BA16) -> 2921.9003 | H16: =SUM(E16:G16) -> 224708.53 | I16: ='Summary sales'!D16 -> 137865 | J16: ='Summary sales'!E16 -> 38300.38 | K16: ='Summary sales'!F16 -> 10612.04 | L16: ='Summary sales'!G16 -> 0 | N16: ='Summary sales'!I16 -> 4270.04 | Q16: =SUM(I16:P16) -> 191047.46
B17: =B16+1 -> 46183 | C17: =TEXT(B17,"ddd") -> Rab | D17: =Q17-H17 -> -54227.433 | E17: =SUM('SO JUNI 2026 (Rev.2)'!E17:AT17) -> 180800.42 | F17: =SUM('SO JUNI 2026 (Rev.2)'!AU17:BE17) -> 40986.213 | G17: =SUM('SO JUNI 2026 (Rev.2)'!AZ17:BA17) -> 2921.9003 | H17: =SUM(E17:G17) -> 224708.53 | I17: ='Summary sales'!D17 -> 117095.25 | J17: ='Summary sales'!E17 -> 43994.02 | K17: ='Summary sales'!F17 -> 9391.83 | L17: ='Summary sales'!G17 -> 0 | N17: ='Summary sales'!I17 -> 0 | Q17: =SUM(I17:P17) -> 170481.1
B18: =B17+1 -> 46184 | C18: =TEXT(B18,"ddd") -> Kam | D18: =Q18-H18 -> -44850.613 | E18: =SUM('SO JUNI 2026 (Rev.2)'!E18:AT18) -> 180800.42 | F18: =SUM('SO JUNI 2026 (Rev.2)'!AU18:BE18) -> 40986.213 | G18: =SUM('SO JUNI 2026 (Rev.2)'!AZ18:BA18) -> 2921.9003 | H18: =SUM(E18:G18) -> 224708.53 | I18: ='Summary sales'!D18 -> 116202.4 | J18: ='Summary sales'!E18 -> 46370.97 | K18: ='Summary sales'!F18 -> 8828.92 | L18: ='Summary sales'!G18 -> 4606.87 | N18: ='Summary sales'!I18 -> 3848.76 | Q18: =SUM(I18:P18) -> 179857.92
B19: =B18+1 -> 46185 | C19: =TEXT(B19,"ddd") -> Jum | D19: =Q19-H19 -> -30611.633 | E19: =SUM('SO JUNI 2026 (Rev.2)'!E19:AT19) -> 180800.42 | F19: =SUM('SO JUNI 2026 (Rev.2)'!AU19:BE19) -> 40986.213 | G19: =SUM('SO JUNI 2026 (Rev.2)'!AZ19:BA19) -> 2921.9003 | H19: =SUM(E19:G19) -> 224708.53 | I19: ='Summary sales'!D19 -> 136058.13 | J19: ='Summary sales'!E19 -> 43566.5 | K19: ='Summary sales'!F19 -> 10493.44 | L19: ='Summary sales'!G19 -> 0 | N19: ='Summary sales'!I19 -> 3978.83 | Q19: =SUM(I19:P19) -> 194096.9
B20: =B19+1 -> 46186 | C20: =TEXT(B20,"ddd") -> Sab | D20: =Q20-H20 -> -18070.755 | E20: =SUM('SO JUNI 2026 (Rev.2)'!E20:AT20) -> 180334.54 | F20: =SUM('SO JUNI 2026 (Rev.2)'!AU20:BE20) -> 39814.313 | G20: =SUM('SO JUNI 2026 (Rev.2)'!AZ20:BA20) -> 1800 | H20: =SUM(E20:G20) -> 221948.86 | I20: ='Summary sales'!D20 -> 143783.76 | J20: ='Summary sales'!E20 -> 39521.45 | K20: ='Summary sales'!F20 -> 16723.93 | L20: ='Summary sales'!G20 -> 0 | N20: ='Summary sales'!I20 -> 3848.96 | Q20: =SUM(I20:P20) -> 203878.1
B21: =B20+1 -> 46187 | C21: =TEXT(B21,"ddd") -> Mgg | D21: =Q21-H21 -> -5440.6678 | E21: =SUM('SO JUNI 2026 (Rev.2)'!E21:AT21) -> 153843.46 | F21: =SUM('SO JUNI 2026 (Rev.2)'!AU21:BE21) -> 39814.313 | G21: =SUM('SO JUNI 2026 (Rev.2)'!AZ21:BA21) -> 1800 | H21: =SUM(E21:G21) -> 195457.78 | I21: ='Summary sales'!D21 -> 133555.4 | J21: ='Summary sales'!E21 -> 40758.09 | K21: ='Summary sales'!F21 -> 11702.49 | L21: ='Summary sales'!G21 -> 0 | N21: ='Summary sales'!I21 -> 4001.13 | Q21: =SUM(I21:P21) -> 190017.11
B22: Sub Total | D22: =SUM(D15:D21) -> -212114.55 | E22: =SUM(E15:E21) -> 1238180.1 | F22: =SUM(F15:F21) -> 284559.69 | G22: =SUM(G15:G21) -> 18209.502 | H22: =SUM(H15:H21) -> 1540949.3 | I22: =SUM(I15:I21) -> 924023.76 | J22: =SUM(J15:J21) -> 293740.65 | K22: =SUM(K15:K21) -> 82300.55 | ... Q22: =SUM(Q15:Q21) -> 1328834.8
A24: =WEEKNUM(B24) -> 25 | B24: =B21+1 -> 46188 | C24: =TEXT(B24,"ddd") -> Sen | D24: =Q24-H24 -> -56151.033 | E24: =SUM('SO JUNI 2026 (Rev.2)'!E24:AT24) -> 181300.42 | F24: =SUM('SO JUNI 2026 (Rev.2)'!AU24:BE24) -> 40986.213 | G24: =SUM('SO JUNI 2026 (Rev.2)'!AZ24:BA24) -> 2921.9003 | H24: =SUM(E24:G24) -> 225208.53 | I24: ='Summary sales'!D22 -> 118170.43 | J24: ='Summary sales'!E22 -> 36952.98 | K24: ='Summary sales'!F22 -> 10113.52 | L24: ='Summary sales'!G22 -> 0 | N24: ='Summary sales'!I22 -> 3820.57 | Q24: =SUM(I24:P24) -> 169057.5
B25: =B24+1 -> 46189 | C25: =TEXT(B25,"ddd") -> Sel | D25: =Q25-H25 -> -22275.109 | E25: =SUM('SO JUNI 2026 (Rev.2)'!E25:AT25) -> 167100.85 | F25: =SUM('SO JUNI 2026 (Rev.2)'!AU25:BE25) -> 39014.313 | G25: =SUM('SO JUNI 2026 (Rev.2)'!AZ25:BA25) -> 1800 | H25: =SUM(E25:G25) -> 207915.16 | I25: ='Summary sales'!D23 -> 127789.56 | J25: ='Summary sales'!E23 -> 43424.11 | K25: ='Summary sales'!F23 -> 10727.65 | L25: ='Summary sales'!G23 -> 0 | N25: ='Summary sales'!I23 -> 3698.73 | Q25: =SUM(I25:P25) -> 185640.05
B26: =B25+1 -> 46190 | C26: =TEXT(B26,"ddd") -> Rab | D26: =Q26-H26 -> -65250.063 | E26: =SUM('SO JUNI 2026 (Rev.2)'!E26:AT26) -> 181300.42 | F26: =SUM('SO JUNI 2026 (Rev.2)'!AU26:BE26) -> 40986.213 | G26: =SUM('SO JUNI 2026 (Rev.2)'!AZ26:BA26) -> 2921.9003 | H26: =SUM(E26:G26) -> 225208.53 | I26: ='Summary sales'!D24 -> 116941.68 | J26: ='Summary sales'!E24 -> 34590.46 | K26: ='Summary sales'!F24 -> 8426.33 | L26: ='Summary sales'!G24 -> 0 | N26: ='Summary sales'!I24 -> 0 | Q26: =SUM(I26:P26) -> 159958.47
B27: =B26+1 -> 46191 | C27: =TEXT(B27,"ddd") -> Kam | D27: =Q27-H27 -> -46249.673 | E27: =SUM('SO JUNI 2026 (Rev.2)'!E27:AT27) -> 181300.42 | F27: =SUM('SO JUNI 2026 (Rev.2)'!AU27:BE27) -> 40986.213 | G27: =SUM('SO JUNI 2026 (Rev.2)'!AZ27:BA27) -> 2921.9003 | H27: =SUM(E27:G27) -> 225208.53 | I27: ='Summary sales'!D25 -> 120941.24 | J27: ='Summary sales'!E25 -> 49206.21 | K27: ='Summary sales'!F25 -> 8811.41 | L27: ='Summary sales'!G25 -> 0 | N27: ='Summary sales'!I25 -> 0 | Q27: =SUM(I27:P27) -> 178958.86
B28: =B27+1 -> 46192 | C28: =TEXT(B28,"ddd") -> Jum | D28: =Q28-H28 -> -23802.503 | E28: =SUM('SO JUNI 2026 (Rev.2)'!E28:AT28) -> 181300.42 | F28: =SUM('SO JUNI 2026 (Rev.2)'!AU28:BE28) -> 40986.213 | G28: =SUM('SO JUNI 2026 (Rev.2)'!AZ28:BA28) -> 2921.9003 | H28: =SUM(E28:G28) -> 225208.53 | I28: ='Summary sales'!D26 -> 145887.64 | J28: ='Summary sales'!E26 -> 48018.99 | K28: ='Summary sales'!F26 -> 7499.4 | L28: ='Summary sales'!G26 -> 0 | N28: ='Summary sales'!I26 -> 0 | Q28: =SUM(I28:P28) -> 201406.03
