Workbook
Name ___xlnm._FilterDatabase_2: #REF!
Name ___xlnm._FilterDatabase_2: #REF!
Name ___xlnm._FilterDatabase_2: #REF!
Name ___xlnm._FilterDatabase_2: #REF!
Name ___xlnm._FilterDatabase_2: #REF!
Name ___xlnm._FilterDatabase_2: #REF!
Name ___xlnm._FilterDatabase_2: #REF!
Name ___xlnm._FilterDatabase_2: #REF!
Name ___xlnm._FilterDatabase_2: #REF!
Name ___xlnm._FilterDatabase_2: #REF!
Name ___xlnm._FilterDatabase_2: #REF!
Name ___xlnm._FilterDatabase_2: #REF!
Name ___xlnm._FilterDatabase_2: #REF!
Name ___xlnm._FilterDatabase_2: #REF!
Name ___xlnm._FilterDatabase_2: #REF!
Name ___xlnm._FilterDatabase_2: #REF!
Name ___xlnm._FilterDatabase_2: #REF!
Name __xlnm._FilterDatabase_2: #REF!
Name __xlnm._FilterDatabase_2: #REF!
Name __xlnm._FilterDatabase_2: #REF!
Name __xlnm._FilterDatabase_2: #REF!
Name __xlnm._FilterDatabase_2: #REF!
Name __xlnm._FilterDatabase_2: #REF!
Name __xlnm._FilterDatabase_2: #REF!
Name __xlnm._FilterDatabase_2: #REF!
Name __xlnm._FilterDatabase_2: #REF!
Name __xlnm._FilterDatabase_2: #REF!
Name __xlnm._FilterDatabase_2: #REF!
Name __xlnm._FilterDatabase_2: #REF!
Name __xlnm._FilterDatabase_2: #REF!
Name __xlnm._FilterDatabase_2: #REF!
Name __xlnm._FilterDatabase_2: #REF!
Name __xlnm._FilterDatabase_2: #REF!
Name __xlnm._FilterDatabase_2: #REF!
Name _TES46: #N/A
Name AAAA: #N/A
Name ati: #N/A
Name BS: #N/A
Name CCC: #N/A
Name depr9200: #N/A
Name dfsfd: #N/A
Name Excel_BuiltIn__FilterDatabase_1: #REF!
Name Excel_BuiltIn__FilterDatabase_1: #REF!
Name Excel_BuiltIn__FilterDatabase_1: #REF!
Name Excel_BuiltIn__FilterDatabase_1: #REF!
Name Excel_BuiltIn__FilterDatabase_1: #REF!
Name Excel_BuiltIn__FilterDatabase_1: #REF!
Name Excel_BuiltIn__FilterDatabase_1: #REF!
Name Excel_BuiltIn__FilterDatabase_1: #REF!
Name Excel_BuiltIn__FilterDatabase_1: #REF!
Name Excel_BuiltIn__FilterDatabase_1: #REF!
Name Excel_BuiltIn__FilterDatabase_1: #REF!
Name Excel_BuiltIn__FilterDatabase_1: #REF!
Name Excel_BuiltIn__FilterDatabase_1: #REF!
Name Excel_BuiltIn__FilterDatabase_1: #REF!
Name Excel_BuiltIn__FilterDatabase_1: #REF!
Name Excel_BuiltIn__FilterDatabase_1: #REF!
Name Excel_BuiltIn__FilterDatabase_1: #REF!
Name Excel_BuiltIn_Print_Titles: NA()
Name Export_3: #REF!

Sheet SO FOB Agustus 2026
A2: SALES ORDER
A4: 46235
A6: Week | B6: DATE | D6: TOTAL | E6: FOB SETU-AAE | F6: FOB SETU- SIDO | G6: FOB SETU - GIG | H6: FOB SETU - SALMAH | I6: FOB SETU - NNE | J6: FOB SETU - GAS | K6: FOB SETU -SBE | L6: FOB SETU -DAMASINDO | M6: FOB SETU-LARAS | N6: FOB SETU-KIRANA | O6: FOB KHT-APE | P6: FOB KHT - JPEN | Q6: FOB KHT - Laras | R6: FOB KHT - ANAGATA
A7: =WEEKNUM(B7) -> 31 | B7: =A4 -> 46235 | C7: Sun | D7: =SUM(E7:R7) -> 0 | E7: 0 | F7: 0 | G7: 0 | H7: 0 | I7: 0 | J7: 0 | K7: 0 | L7: 0 | M7: 0 | N7: 0 | O7: 0 | P7: 0 | Q7: 0 | R7: 0
B8: Sub Total | D8: =SUM(D4:D7) -> 0 | E8: =SUM(E4:E7) -> 0 | F8: =SUM(F4:F7) -> 0 | G8: =SUM(G4:G7) -> 0 | H8: =SUM(H4:H7) -> 0 | I8: =SUM(I4:I7) -> 0 | J8: =SUM(J4:J7) -> 0 | K8: =SUM(K4:K7) -> 0 | ... R8: =SUM(R4:R7) -> 0
A10: =WEEKNUM(B10) -> 32 | B10: =B7+1 -> 46236 | C10: Mon | D10: =SUM(E10:R10) -> 0 | E10: 0 | F10: 0 | G10: 0 | H10: 0 | I10: 0 | J10: 0 | K10: 0 | L10: 0 | M10: 0 | N10: 0 | O10: 0 | P10: 0 | Q10: 0 | R10: 0
B11: =B10+1 -> 46237 | C11: Tue | D11: =SUM(E11:R11) -> 0 | E11: 0 | F11: 0 | G11: 0 | H11: 0 | I11: 0 | J11: 0 | K11: 0 | L11: 0 | M11: 0 | N11: 0 | O11: 0 | P11: 0 | Q11: 0 | R11: 0
B12: =B11+1 -> 46238 | C12: Wed | D12: =SUM(E12:R12) -> 0 | E12: 0 | F12: 0 | G12: 0 | H12: 0 | I12: 0 | J12: 0 | K12: 0 | L12: 0 | M12: 0 | N12: 0 | O12: 0 | P12: 0 | Q12: 0 | R12: 0
B13: =B12+1 -> 46239 | C13: Thu | D13: =SUM(E13:R13) -> 0 | E13: 0 | F13: 0 | G13: 0 | H13: 0 | I13: 0 | J13: 0 | K13: 0 | L13: 0 | M13: 0 | N13: 0 | O13: 0 | P13: 0 | Q13: 0 | R13: 0
B14: =B13+1 -> 46240 | C14: Fri | D14: =SUM(E14:R14) -> 0 | E14: 0 | F14: 0 | G14: 0 | H14: 0 | I14: 0 | J14: 0 | K14: 0 | L14: 0 | M14: 0 | N14: 0 | O14: 0 | P14: 0 | Q14: 0 | R14: 0
B15: =B14+1 -> 46241 | C15: Sat | D15: =SUM(E15:R15) -> 0 | E15: 0 | F15: 0 | G15: 0 | H15: 0 | I15: 0 | J15: 0 | K15: 0 | L15: 0 | M15: 0 | N15: 0 | O15: 0 | P15: 0 | Q15: 0 | R15: 0
B16: =B15+1 -> 46242 | C16: Sun | D16: =SUM(E16:R16) -> 0 | E16: 0 | F16: 0 | G16: 0 | H16: 0 | I16: 0 | J16: 0 | K16: 0 | L16: 0 | M16: 0 | N16: 0 | O16: 0 | P16: 0 | Q16: 0 | R16: 0
B17: Sub Total | D17: =SUM(D10:D16) -> 0 | E17: =SUM(E10:E16) -> 0 | F17: =SUM(F10:F16) -> 0 | G17: =SUM(G10:G16) -> 0 | H17: =SUM(H10:H16) -> 0 | I17: =SUM(I10:I16) -> 0 | J17: =SUM(J10:J16) -> 0 | K17: =SUM(K10:K16) -> 0 | ... R17: =SUM(R10:R16) -> 0
A19: =WEEKNUM(B24) -> 33 | B19: =B16+1 -> 46243 | C19: Mon | D19: =SUM(E19:R19) -> 0 | E19: 0 | F19: 0 | G19: 0 | H19: 0 | I19: 0 | J19: 0 | K19: 0 | L19: 0 | M19: 0 | N19: 0 | O19: 0 | P19: 0 | Q19: 0 | R19: 0
B20: =B19+1 -> 46244 | C20: Tue | D20: =SUM(E20:R20) -> 0 | E20: 0 | F20: 0 | G20: 0 | H20: 0 | I20: 0 | J20: 0 | K20: 0 | L20: 0 | M20: 0 | N20: 0 | O20: 0 | P20: 0 | Q20: 0 | R20: 0
B21: =B20+1 -> 46245 | C21: Wed | D21: =SUM(E21:R21) -> 0 | E21: 0 | F21: 0 | G21: 0 | H21: 0 | I21: 0 | J21: 0 | K21: 0 | L21: 0 | M21: 0 | N21: 0 | O21: 0 | P21: 0 | Q21: 0 | R21: 0
B22: =B21+1 -> 46246 | C22: Thu | D22: =SUM(E22:R22) -> 0 | E22: 0 | F22: 0 | G22: 0 | H22: 0 | I22: 0 | J22: 0 | K22: 0 | L22: 0 | M22: 0 | N22: 0 | O22: 0 | P22: 0 | Q22: 0 | R22: 0
B23: =B22+1 -> 46247 | C23: Fri | D23: =SUM(E23:R23) -> 0 | E23: 0 | F23: 0 | G23: 0 | H23: 0 | I23: 0 | J23: 0 | K23: 0 | L23: 0 | M23: 0 | N23: 0 | O23: 0 | P23: 0 | Q23: 0 | R23: 0
B24: =B23+1 -> 46248 | C24: Sat | D24: =SUM(E24:R24) -> 0 | E24: 0 | F24: 0 | G24: 0 | H24: 0 | I24: 0 | J24: 0 | K24: 0 | L24: 0 | M24: 0 | N24: 0 | O24: 0 | P24: 0 | Q24: 0 | R24: 0
B25: =B24+1 -> 46249 | C25: Sun | D25: =SUM(E25:R25) -> 0 | E25: 0 | F25: 0 | G25: 0 | H25: 0 | I25: 0 | J25: 0 | K25: 0 | L25: 0 | M25: 0 | N25: 0 | O25: 0 | P25: 0 | Q25: 0 | R25: 0
B26: Sub Total | D26: =SUM(D19:D25) -> 0 | E26: =SUM(E19:E25) -> 0 | F26: =SUM(F19:F25) -> 0 | G26: =SUM(G19:G25) -> 0 | H26: =SUM(H19:H25) -> 0 | I26: =SUM(I19:I25) -> 0 | J26: =SUM(J19:J25) -> 0 | K26: =SUM(K19:K25) -> 0 | ... R26: =SUM(R19:R25) -> 0
A28: =WEEKNUM(B33) -> 34 | B28: =B25+1 -> 46250 | C28: Mon | D28: =SUM(E28:R28) -> 0 | E28: 0 | F28: 0 | G28: 0 | H28: 0 | I28: 0 | J28: 0 | K28: 0 | L28: 0 | M28: 0 | N28: 0 | O28: 0 | P28: 0 | Q28: 0 | R28: 0
B29: =B28+1 -> 46251 | C29: Tue | D29: =SUM(E29:R29) -> 0 | E29: 0 | F29: 0 | G29: 0 | H29: 0 | I29: 0 | J29: 0 | K29: 0 | L29: 0 | M29: 0 | N29: 0 | O29: 0 | P29: 0 | Q29: 0 | R29: 0
B30: =B29+1 -> 46252 | C30: Wed | D30: =SUM(E30:R30) -> 0 | E30: 0 | F30: 0 | G30: 0 | H30: 0 | I30: 0 | J30: 0 | K30: 0 | L30: 0 | M30: 0 | N30: 0 | O30: 0 | P30: 0 | Q30: 0 | R30: 0
B31: =B30+1 -> 46253 | C31: Thu | D31: =SUM(E31:R31) -> 0 | E31: 0 | F31: 0 | G31: 0 | H31: 0 | I31: 0 | J31: 0 | K31: 0 | L31: 0 | M31: 0 | N31: 0 | O31: 0 | P31: 0 | Q31: 0 | R31: 0
B32: =B31+1 -> 46254 | C32: Fri | D32: =SUM(E32:R32) -> 0 | E32: 0 | F32: 0 | G32: 0 | H32: 0 | I32: 0 | J32: 0 | K32: 0 | L32: 0 | M32: 0 | N32: 0 | O32: 0 | P32: 0 | Q32: 0 | R32: 0
B33: =B32+1 -> 46255 | C33: Sat | D33: =SUM(E33:R33) -> 0 | E33: 0 | F33: 0 | G33: 0 | H33: 0 | I33: 0 | J33: 0 | K33: 0 | L33: 0 | M33: 0 | N33: 0 | O33: 0 | P33: 0 | Q33: 0 | R33: 0
B34: =B33+1 -> 46256 | C34: Sun | D34: =SUM(E34:R34) -> 0 | E34: 0 | F34: 0 | G34: 0 | H34: 0 | I34: 0 | J34: 0 | K34: 0 | L34: 0 | M34: 0 | N34: 0 | O34: 0 | P34: 0 | Q34: 0 | R34: 0
B35: Sub Total | D35: =SUM(D28:D34) -> 0 | E35: =SUM(E28:E34) -> 0 | F35: =SUM(F28:F34) -> 0 | G35: =SUM(G28:G34) -> 0 | H35: =SUM(H28:H34) -> 0 | I35: =SUM(I28:I34) -> 0 | J35: =SUM(J28:J34) -> 0 | K35: =SUM(K28:K34) -> 0 | ... R35: =SUM(R28:R34) -> 0
A37: =WEEKNUM(B42) -> 35 | B37: =B34+1 -> 46257 | C37: Mon | D37: =SUM(E37:R37) -> 0 | E37: 0 | F37: 0 | G37: 0 | H37: 0 | I37: 0 | J37: 0 | K37: 0 | L37: 0 | M37: 0 | N37: 0 | O37: 0 | P37: 0 | Q37: 0 | R37: 0
B38: =B37+1 -> 46258 | C38: Tue | D38: =SUM(E38:R38) -> 0 | E38: 0 | F38: 0 | G38: 0 | H38: 0 | I38: 0 | J38: 0 | K38: 0 | L38: 0 | M38: 0 | N38: 0 | O38: 0 | P38: 0 | Q38: 0 | R38: 0
B39: =B38+1 -> 46259 | C39: Wed | D39: =SUM(E39:R39) -> 0 | E39: 0 | F39: 0 | G39: 0 | H39: 0 | I39: 0 | J39: 0 | K39: 0 | L39: 0 | M39: 0 | N39: 0 | O39: 0 | P39: 0 | Q39: 0 | R39: 0
B40: =B39+1 -> 46260 | C40: Thu | D40: =SUM(E40:R40) -> 0 | E40: 0 | F40: 0 | G40: 0 | H40: 0 | I40: 0 | J40: 0 | K40: 0 | L40: 0 | M40: 0 | N40: 0 | O40: 0 | P40: 0 | Q40: 0 | R40: 0
B41: =B40+1 -> 46261 | C41: Fri | D41: =SUM(E41:R41) -> 0 | E41: 0 | F41: 0 | G41: 0 | H41: 0 | I41: 0 | J41: 0 | K41: 0 | L41: 0 | M41: 0 | N41: 0 | O41: 0 | P41: 0 | Q41: 0 | R41: 0
B42: =B41+1 -> 46262 | C42: Sat | D42: =SUM(E42:R42) -> 0 | E42: 0 | F42: 0 | G42: 0 | H42: 0 | I42: 0 | J42: 0 | K42: 0 | L42: 0 | M42: 0 | N42: 0 | O42: 0 | P42: 0 | Q42: 0 | R42: 0
B43: =B42+1 -> 46263 | C43: Sun | D43: =SUM(E43:R43) -> 0 | E43: 0 | F43: 0 | G43: 0 | H43: 0 | I43: 0 | J43: 0 | K43: 0 | L43: 0 | M43: 0 | N43: 0 | O43: 0 | P43: 0 | Q43: 0 | R43: 0
B44: Sub Total | D44: =SUM(D37:D43) -> 0 | E44: =SUM(E37:E43) -> 0 | F44: =SUM(F37:F43) -> 0 | G44: =SUM(G37:G43) -> 0 | H44: =SUM(H37:H43) -> 0 | I44: =SUM(I37:I43) -> 0 | J44: =SUM(J37:J43) -> 0 | K44: =SUM(K37:K43) -> 0 | ... R44: =SUM(R37:R43) -> 0
A46: =WEEKNUM(B46) -> 36 | B46: =B43+1 -> 46264 | C46: Mon | D46: =SUM(E46:R46) -> 0 | E46: 0 | F46: 0 | G46: 0 | H46: 0 | I46: 0 | J46: 0 | K46: 0 | L46: 0 | M46: 0 | N46: 0 | O46: 0 | P46: 0 | Q46: 0 | R46: 0
B47: =B46+1 -> 46265 | C47: Tue | D47: =SUM(E47:R47) -> 0 | E47: 0 | F47: 0 | G47: 0 | H47: 0 | I47: 0 | J47: 0 | K47: 0 | L47: 0 | M47: 0 | N47: 0 | O47: 0 | P47: 0 | Q47: 0 | R47: 0
B48: Sub Total | D48: =SUM(D41:D47) -> 0 | E48: =SUM(E41:E47) -> 0 | F48: =SUM(F41:F47) -> 0 | G48: =SUM(G41:G47) -> 0 | H48: =SUM(H41:H47) -> 0 | I48: =SUM(I41:I47) -> 0 | J48: =SUM(J41:J47) -> 0 | K48: =SUM(K41:K47) -> 0 | ... R48: =SUM(R41:R47) -> 0
...

Sheet SO Agustus 2026 Rev.3
A2: SALES ORDER
A3: 46235 | O3: =O21/24 -> 208.33333
X4: =X6/24 -> 270.83333
A5: Week | B5: DATE | D5: TOTAL | E5: CLIN | F5: BI | G5: MKG | H5: STM | I5: OAJ | J5: NNI | K5: SHB | L5: GTL | M5: TWK | N5: BYC | O5: GF RANCA | P5: SMA | Q5: UMI | R5: HLI | S5: ASAHIMAS | T5: DIC | U5: HCI | V5: KSN | W5: ADP | X5: KSN RANCA | Y5: Greenpulse | Z5: ALT (KSO MASAMI) | AA5: IDP (KSO AAE) | AB5: FJI (KSO SALMAH) | AC5: WINGLOK (KSO EBM) | AD5: CISF (KSO RRS) | AE5: KGM (KSO RRS) | AF5: PUJ - LUBRICANT | AG5: CALBEE (KSO BMI) | AH5: IP | AI5: BEM | AJ5: AMI | AK5: KA | AL5: KTN | AM5: NIAGA GARAM | AN5: PCI 84 | AO5: PCI MENGGER | AP5: INDOFOOD | AQ5: CERES | AR5: ABC KOGEN | AS5: TONGJI ( KSO GAS) | AT5: CITYMALL GARUT | AU5: PERHUTANI (KSO PTGN) | AV5: PA | AW5: RB | AX5: GF ATOM | AY5: GF KULIT | AZ5: SDM | BA5: JARGAS | BB5: SBI | BC5: DJARUM | BD5: SP GLOBAL | BE5: PENTAWIRA (KSO REN)
A6: =WEEKNUM(B6) -> 31 | B6: =A3 -> 46235 | C6: =TEXT(B6,"ddd") -> Sab | D6: =SUM(E6:BE6) -> 187116.62 | E6: 700 | F6: 1000 | G6: 1200 | H6: 3300 | I6: 644.02065 | J6: 0 | K6: 150 | L6: 603.76323 | M6: 673.27548 | N6: 4500 | O6: 5000 | P6: 1000 | Q6: 16000 | R6: 10300 | S6: 19000 | T6: 5000 | U6: 0 | V6: 6500 | W6: 500 | X6: 6500 | Y6: 500 | Z6: 1000 | AA6: 5500 | AB6: 0 | AC6: 89.451613 | AD6: 3500 | AE6: 1300 | AF6: 0 | AG6: 15000 | AH6: 2000 | AI6: 800 | AJ6: 7200 | AK6: 0 | AL6: 2000 | AM6: 1000 | AN6: 11000 | AO6: 2000 | AP6: 5500 | AQ6: 6000 | AR6: 8000 | AS6: 3500 | AV6: 700 | AW6: 3500 | AX6: 2000 | AY6: 369.61071 | AZ6: 0 | BA6: 2499.7026 | BB6: 2499.7026 | BC6: =111200/31 -> 3587.0968 | BD6: 0 | BE6: =4500*3 -> 13500
B7: =B6+1 -> 46236 | C7: =TEXT(B7,"ddd") -> Mgg | D7: =SUM(E7:BE7) -> 156625.55 | E7: 700 | F7: 1000 | G7: 1200 | H7: 999.51613 | I7: 644.02065 | J7: 0 | K7: 0 | L7: 603.76323 | M7: 673.27548 | N7: 0 | O7: 5000 | P7: 300 | Q7: 6659.5545 | R7: 10300 | S7: 19000 | T7: 5000 | U7: 0 | V7: 6500 | W7: 500 | X7: 6500 | Y7: 500 | Z7: 0 | AA7: 2500 | AB7: 0 | AC7: 89.451613 | AD7: 1000 | AE7: 1300 | AF7: 0 | AG7: 15000 | AH7: 2000 | AI7: 0 | AJ7: 2999.8519 | AK7: 0 | AL7: 2000 | AM7: 0 | AN7: 11000 | AO7: 2000 | AP7: 5500 | AQ7: 5000 | AR7: 8000 | AS7: 3500 | AT7: 0 | AU7: 0 | AV7: 700 | AW7: 3500 | AX7: 2000 | AY7: 369.61071 | AZ7: 0 | BA7: 2499.7026 | BB7: 2499.7026 | BC7: 3587.0968 | BD7: 0 | BE7: 13500
B8: Sub Total | D8: =SUM(D6:D7) -> 343742.17 | E8: =SUM(E6:E7) -> 1400 | F8: =SUM(F6:F7) -> 2000 | G8: =SUM(G6:G7) -> 2400 | H8: 4299.5161 | I8: 1288.0413 | J8: =SUM(J6:J7) -> 0 | K8: 150 | L8: 1207.5265 | M8: =SUM(M6:M7) -> 1346.551 | N8: =SUM(N6:N7) -> 4500 | O8: 10000 | P8: =SUM(P6:P7) -> 1300 | Q8: =SUM(Q6:Q7) -> 22659.555 | R8: =SUM(R6:R7) -> 20600 | S8: =SUM(S6:S7) -> 38000 | T8: =SUM(T6:T7) -> 10000 | U8: =SUM(U6:U7) -> 0 | V8: =SUM(V6:V7) -> 13000 | W8: =SUM(W6:W7) -> 1000 | ... AF8: =SUM(AF6:AF7) -> 0 | AG8: 30000 | AH8: =SUM(AH6:AH7) -> 4000 | AI8: =SUM(AI6:AI7) -> 800 | AJ8: =SUM(AJ6:AJ7) -> 10199.852 | AK8: =SUM(AK6:AK7) -> 0 | AL8: =SUM(AL6:AL7) -> 4000 | AM8: =SUM(AM6:AM7) -> 1000 | AN8: =SUM(AN6:AN7) -> 22000 | AO8: =SUM(AO6:AO7) -> 4000 | ... BE8: =SUM(BE6:BE7) -> 27000
A10: =WEEKNUM(B10) -> 32 | B10: =B7+1 -> 46237 | C10: =TEXT(B10,"ddd") -> Sen | D10: =SUM(E10:BE10) -> 206238.15 | E10: 1199.5729 | F10: 2000 | G10: 1200 | H10: 3300 | I10: 644.02065 | J10: 0 | K10: 150 | L10: 603.76323 | M10: 673.27548 | N10: 5500 | O10: 5000 | P10: 2500 | Q10: 16000 | R10: 10300 | S10: 19000 | T10: 5000 | U10: 7000 | V10: 6500 | W10: 500 | X10: 6500 | Y10: 500 | Z10: 1000 | AA10: 5500 | AB10: 0 | AC10: 89.451613 | AD10: 3500 | AE10: 1300 | AF10: 3000 | AG10: 15000 | AH10: 2000 | AI10: 800 | AJ10: 7200 | AK10: 2500 | AL10: 2000 | AM10: 1000 | AN10: 11000 | AO10: 2000 | AP10: 4000 | AQ10: 9000.0571 | AR10: 8000 | AS10: 3500 | AT10: 0 | AU10: 0 | AV10: 700 | AW10: 3500 | AX10: 2000 | AY10: 369.61071 | AZ10: 1121.9003 | BA10: 2499.7026 | BB10: 2499.7026 | BC10: 3587.0968 | BD10: 0 | BE10: 13500
B11: =B10+1 -> 46238 | C11: =TEXT(B11,"ddd") -> Sel | D11: =SUM(E11:BE11) -> 206238.15 | E11: 1199.5729 | F11: 2000 | G11: 1200 | H11: 3300 | I11: 644.02065 | J11: 0 | K11: 150 | L11: 603.76323 | M11: 673.27548 | N11: 5500 | O11: 5000 | P11: 2500 | Q11: 16000 | R11: 10300 | S11: 19000 | T11: 5000 | U11: 7000 | V11: 6500 | W11: 500 | X11: 6500 | Y11: 500 | Z11: 1000 | AA11: 5500 | AB11: 0 | AC11: 89.451613 | AD11: 3500 | AE11: 1300 | AF11: 3000 | AG11: 15000 | AH11: 2000 | AI11: 800 | AJ11: 7200 | AK11: 2500 | AL11: 2000 | AM11: 1000 | AN11: 11000 | AO11: 2000 | AP11: 4000 | AQ11: 9000.0571 | AR11: 8000 | AS11: 3500 | AT11: 0 | AU11: 0 | AV11: 700 | AW11: 3500 | AX11: 2000 | AY11: 369.61071 | AZ11: 1121.9003 | BA11: 2499.7026 | BB11: 2499.7026 | BC11: 3587.0968 | BD11: 0 | BE11: 13500
B12: =B11+1 -> 46239 | C12: =TEXT(B12,"ddd") -> Rab | D12: =SUM(E12:BE12) -> 206238.15 | E12: 1199.5729 | F12: 2000 | G12: 1200 | H12: 3300 | I12: 644.02065 | J12: 0 | K12: 150 | L12: 603.76323 | M12: 673.27548 | N12: 5500 | O12: 5000 | P12: 2500 | Q12: 16000 | R12: 10300 | S12: 19000 | T12: 5000 | U12: 7000 | V12: 6500 | W12: 500 | X12: 6500 | Y12: 500 | Z12: 1000 | AA12: 5500 | AB12: 0 | AC12: 89.451613 | AD12: 3500 | AE12: 1300 | AF12: 3000 | AG12: 15000 | AH12: 2000 | AI12: 800 | AJ12: 7200 | AK12: 2500 | AL12: 2000 | AM12: 1000 | AN12: 11000 | AO12: 2000 | AP12: 4000 | AQ12: 9000.0571 | AR12: 8000 | AS12: 3500 | AT12: 0 | AU12: 0 | AV12: 700 | AW12: 3500 | AX12: 2000 | AY12: 369.61071 | AZ12: 1121.9003 | BA12: 2499.7026 | BB12: 2499.7026 | BC12: 3587.0968 | BD12: 0 | BE12: 13500
B13: =B12+1 -> 46240 | C13: =TEXT(B13,"ddd") -> Kam | D13: =SUM(E13:BE13) -> 206238.15 | E13: 1199.5729 | F13: 2000 | G13: 1200 | H13: 3300 | I13: 644.02065 | J13: 0 | K13: 150 | L13: 603.76323 | M13: 673.27548 | N13: 5500 | O13: 5000 | P13: 2500 | Q13: 16000 | R13: 10300 | S13: 19000 | T13: 5000 | U13: 7000 | V13: 6500 | W13: 500 | X13: 6500 | Y13: 500 | Z13: 1000 | AA13: 5500 | AB13: 0 | AC13: 89.451613 | AD13: 3500 | AE13: 1300 | AF13: 3000 | AG13: 15000 | AH13: 2000 | AI13: 800 | AJ13: 7200 | AK13: 2500 | AL13: 2000 | AM13: 1000 | AN13: 11000 | AO13: 2000 | AP13: 4000 | AQ13: 9000.0571 | AR13: 8000 | AS13: 3500 | AT13: 0 | AU13: 0 | AV13: 700 | AW13: 3500 | AX13: 2000 | AY13: 369.61071 | AZ13: 1121.9003 | BA13: 2499.7026 | BB13: 2499.7026 | BC13: 3587.0968 | BD13: 0 | BE13: 13500
B14: =B13+1 -> 46241 | C14: =TEXT(B14,"ddd") -> Jum | D14: =SUM(E14:BE14) -> 206238.15 | E14: 1199.5729 | F14: 2000 | G14: 1200 | H14: 3300 | I14: 644.02065 | J14: 0 | K14: 150 | L14: 603.76323 | M14: 673.27548 | N14: 5500 | O14: 5000 | P14: 2500 | Q14: 16000 | R14: 10300 | S14: 19000 | T14: 5000 | U14: 7000 | V14: 6500 | W14: 500 | X14: 6500 | Y14: 500 | Z14: 1000 | AA14: 5500 | AB14: 0 | AC14: 89.451613 | AD14: 3500 | AE14: 1300 | AF14: 3000 | AG14: 15000 | AH14: 2000 | AI14: 800 | AJ14: 7200 | AK14: 2500 | AL14: 2000 | AM14: 1000 | AN14: 11000 | AO14: 2000 | AP14: 4000 | AQ14: 9000.0571 | AR14: 8000 | AS14: 3500 | AT14: 0 | AU14: 0 | AV14: 700 | AW14: 3500 | AX14: 2000 | AY14: 369.61071 | AZ14: 1121.9003 | BA14: 2499.7026 | BB14: 2499.7026 | BC14: 3587.0968 | BD14: 0 | BE14: 13500
B15: =B14+1 -> 46242 | C15: =TEXT(B15,"ddd") -> Sab | D15: =SUM(E15:BE15) -> 187116.62 | E15: 700 | F15: 1000 | G15: 1200 | H15: 3300 | I15: 644.02065 | J15: 0 | K15: 150 | L15: 603.76323 | M15: 673.27548 | N15: 4500 | O15: 5000 | P15: 1000 | Q15: 16000 | R15: 10300 | S15: 19000 | T15: 5000 | U15: 0 | V15: 6500 | W15: 500 | X15: 6500 | Y15: 500 | Z15: 1000 | AA15: 5500 | AB15: 0 | AC15: 89.451613 | AD15: 3500 | AE15: 1300 | AF15: 0 | AG15: 15000 | AH15: 2000 | AI15: 800 | AJ15: 7200 | AK15: 0 | AL15: 2000 | AM15: 1000 | AN15: 11000 | AO15: 2000 | AP15: 5500 | AQ15: 6000 | AR15: 8000 | AS15: 3500 | AT15: 0 | AU15: 0 | AV15: 700 | AW15: 3500 | AX15: 2000 | AY15: 369.61071 | AZ15: 0 | BA15: 2499.7026 | BB15: 2499.7026 | BC15: 3587.0968 | BD15: 0 | BE15: 13500
B16: =B15+1 -> 46243 | C16: =TEXT(B16,"ddd") -> Mgg | D16: =SUM(E16:BE16) -> 156625.55 | E16: 700 | F16: 1000 | G16: 1200 | H16: 999.51613 | I16: 644.02065 | J16: 0 | K16: 0 | L16: 603.76323 | M16: 673.27548 | N16: 0 | O16: 5000 | P16: 300 | Q16: 6659.5545 | R16: 10300 | S16: 19000 | T16: 5000 | U16: 0 | V16: 6500 | W16: 500 | X16: 6500 | Y16: 500 | Z16: 0 | AA16: 2500 | AB16: 0 | AC16: 89.451613 | AD16: 1000 | AE16: 1300 | AF16: 0 | AG16: 15000 | AH16: 2000 | AI16: 0 | AJ16: 2999.8519 | AK16: 0 | AL16: 2000 | AM16: 0 | AN16: 11000 | AO16: 2000 | AP16: 5500 | AQ16: 5000 | AR16: 8000 | AS16: 3500 | AT16: 0 | AU16: 0 | AV16: 700 | AW16: 3500 | AX16: 2000 | AY16: 369.61071 | AZ16: 0 | BA16: 2499.7026 | BB16: 2499.7026 | BC16: 3587.0968 | BD16: 0 | BE16: 13500
B17: Sub Total | D17: =SUM(D10:D16) -> 1374932.9 | E17: =SUM(E10:E16) -> 7397.8645 | F17: =SUM(F10:F16) -> 12000 | G17: =SUM(G10:G16) -> 8400 | H17: 20799.516 | I17: 4508.1445 | J17: =SUM(J10:J16) -> 0 | K17: 900 | L17: 4226.3426 | M17: =SUM(M10:M16) -> 4712.9284 | N17: =SUM(N10:N16) -> 32000 | O17: 35000 | P17: =SUM(P10:P16) -> 13800 | Q17: =SUM(Q10:Q16) -> 102659.55 | R17: =SUM(R10:R16) -> 72100 | S17: =SUM(S10:S16) -> 133000 | T17: =SUM(T10:T16) -> 35000 | U17: =SUM(U10:U16) -> 35000 | V17: =SUM(V10:V16) -> 45500 | W17: =SUM(W10:W16) -> 3500 | ... AF17: =SUM(AF10:AF16) -> 15000 | AG17: 105000 | AH17: =SUM(AH10:AH16) -> 14000 | AI17: =SUM(AI10:AI16) -> 4800 | AJ17: =SUM(AJ10:AJ16) -> 46199.852 | AK17: =SUM(AK10:AK16) -> 12500 | AL17: =SUM(AL10:AL16) -> 14000 | AM17: =SUM(AM10:AM16) -> 6000 | AN17: =SUM(AN10:AN16) -> 77000 | AO17: =SUM(AO10:AO16) -> 14000 | ... BE17: =SUM(BE10:BE16) -> 94500
A19: =WEEKNUM(B19) -> 33 | B19: =B16+1 -> 46244 | C19: =TEXT(B19,"ddd") -> Sen | D19: =SUM(E19:BE19) -> 191194.13 | E19: 1199.5729 | F19: 1300 | G19: 1200 | H19: 3300 | I19: 800 | J19: 1500 | K19: 150 | L19: 603.76323 | M19: 673.27548 | N19: 5500 | O19: 5000 | P19: 2500 | Q19: 16000 | R19: 10300 | S19: 19000 | T19: 5000 | U19: 7000 | V19: 6500 | W19: 500 | X19: 6500 | Y19: 0 | Z19: 1000 | AA19: 5500 | AB19: 0 | AC19: 89.451613 | AD19: 3500 | AE19: 1300 | AF19: 3000 | AG19: 0 | AH19: 2000 | AI19: 800 | AJ19: 7200 | AK19: 2000 | AL19: 2000 | AM19: 1000 | AN19: 11000 | AO19: 2000 | AP19: 4000 | AQ19: 9000.0571 | AR19: 8000 | AS19: 3500 | AT19: 0 | AU19: 0 | AV19: 700 | AW19: 3500 | AX19: 2000 | AY19: 369.61071 | AZ19: 1121.9003 | BA19: 2499.7026 | BB19: 2499.7026 | BC19: 3587.0968 | BD19: 0 | BE19: 13500
B20: =B19+1 -> 46245 | C20: =TEXT(B20,"ddd") -> Sel | D20: =SUM(E20:BE20) -> 191194.13 | E20: 1199.5729 | F20: 1300 | G20: 1200 | H20: 3300 | I20: 800 | J20: 1500 | K20: 150 | L20: 603.76323 | M20: 673.27548 | N20: 5500 | O20: 5000 | P20: 2500 | Q20: 16000 | R20: 10300 | S20: 19000 | T20: 5000 | U20: 7000 | V20: 6500 | W20: 500 | X20: 6500 | Y20: 0 | Z20: 1000 | AA20: 5500 | AB20: 0 | AC20: 89.451613 | AD20: 3500 | AE20: 1300 | AF20: 3000 | AG20: 0 | AH20: 2000 | AI20: 800 | AJ20: 7200 | AK20: 2000 | AL20: 2000 | AM20: 1000 | AN20: 11000 | AO20: 2000 | AP20: 4000 | AQ20: 9000.0571 | AR20: 8000 | AS20: 3500 | AT20: 0 | AU20: 0 | AV20: 700 | AW20: 3500 | AX20: 2000 | AY20: 369.61071 | AZ20: 1121.9003 | BA20: 2499.7026 | BB20: 2499.7026 | BC20: 3587.0968 | BD20: 0 | BE20: 13500
B21: =B20+1 -> 46246 | C21: =TEXT(B21,"ddd") -> Rab | D21: =SUM(E21:BE21) -> 191194.13 | E21: 1199.5729 | F21: 1300 | G21: 1200 | H21: 3300 | I21: 800 | J21: 1500 | K21: 150 | L21: 603.76323 | M21: 673.27548 | N21: 5500 | O21: 5000 | P21: 2500 | Q21: 16000 | R21: 10300 | S21: 19000 | T21: 5000 | U21: 7000 | V21: 6500 | W21: 500 | X21: 6500 | Y21: 0 | Z21: 1000 | AA21: 5500 | AC21: 89.451613 | AD21: 3500 | AE21: 1300 | AF21: 3000 | AG21: 0 | AH21: 2000 | AI21: 800 | AJ21: 7200 | AK21: 2000 | AL21: 2000 | AM21: 1000 | AN21: 11000 | AO21: 2000 | AP21: 4000 | AQ21: 9000.0571 | AR21: 8000 | AS21: 3500 | AV21: 700 | AW21: 3500 | AX21: 2000 | AY21: 369.61071 | AZ21: 1121.9003 | BA21: 2499.7026 | BB21: 2499.7026 | BC21: 3587.0968 | BD21: 0 | BE21: 13500
B22: =B21+1 -> 46247 | C22: =TEXT(B22,"ddd") -> Kam | D22: =SUM(E22:BE22) -> 191194.13 | E22: 1199.5729 | F22: 1300 | G22: 1200 | H22: 3300 | I22: 800 | J22: 1500 | K22: 150 | L22: 603.76323 | M22: 673.27548 | N22: 5500 | O22: 5000 | P22: 2500 | Q22: 16000 | R22: 10300 | S22: 19000 | T22: 5000 | U22: 7000 | V22: 6500 | W22: 500 | X22: 6500 | Y22: 0 | Z22: 1000 | AA22: 5500 | AB22: 0 | AC22: 89.451613 | AD22: 3500 | AE22: 1300 | AF22: 3000 | AG22: 0 | AH22: 2000 | AI22: 800 | AJ22: 7200 | AK22: 2000 | AL22: 2000 | AM22: 1000 | AN22: 11000 | AO22: 2000 | AP22: 4000 | AQ22: 9000.0571 | AR22: 8000 | AS22: 3500 | AT22: 0 | AU22: 0 | AV22: 700 | AW22: 3500 | AX22: 2000 | AY22: 369.61071 | AZ22: 1121.9003 | BA22: 2499.7026 | BB22: 2499.7026 | BC22: 3587.0968 | BD22: 0 | BE22: 13500
B23: =B22+1 -> 46248 | C23: =TEXT(B23,"ddd") -> Jum | D23: =SUM(E23:BE23) -> 191194.13 | E23: 1199.5729 | F23: 1300 | G23: 1200 | H23: 3300 | I23: 800 | J23: 1500 | K23: 150 | L23: 603.76323 | M23: 673.27548 | N23: 5500 | O23: 5000 | P23: 2500 | Q23: 16000 | R23: 10300 | S23: 19000 | T23: 5000 | U23: 7000 | V23: 6500 | W23: 500 | X23: 6500 | Y23: 0 | Z23: 1000 | AA23: 5500 | AB23: 0 | AC23: 89.451613 | AD23: 3500 | AE23: 1300 | AF23: 3000 | AG23: 0 | AH23: 2000 | AI23: 800 | AJ23: 7200 | AK23: 2000 | AL23: 2000 | AM23: 1000 | AN23: 11000 | AO23: 2000 | AP23: 4000 | AQ23: 9000.0571 | AR23: 8000 | AS23: 3500 | AT23: =SUM(AT16:AT22) -> 0 | AU23: =SUM(AU16:AU22) -> 0 | AV23: 700 | AW23: 3500 | AX23: 2000 | AY23: 369.61071 | AZ23: 1121.9003 | BA23: 2499.7026 | BB23: 2499.7026 | BC23: 3587.0968 | BD23: 0 | BE23: 13500
B24: =B23+1 -> 46249 | C24: =TEXT(B24,"ddd") -> Sab | D24: =SUM(E24:BE24) -> 172272.6 | E24: 700 | F24: 500 | G24: 1000 | H24: 3300 | I24: 500 | J24: 1000 | K24: 150 | L24: 603.76323 | M24: 673.27548 | N24: 4500 | O24: 2000 | P24: 1000 | Q24: 16000 | R24: 10300 | S24: 19000 | T24: 5000 | U24: 3500 | V24: 6500 | W24: 500 | X24: 6500 | Y24: 0 | Z24: 1000 | AA24: 5500 | AB24: 0 | AC24: 89.451613 | AD24: 3500 | AE24: 1300 | AF24: 0 | AG24: 0 | AH24: 2000 | AI24: 800 | AJ24: 7200 | AK24: 0 | AL24: 2000 | AM24: 1000 | AN24: 11000 | AO24: 2000 | AP24: 5500 | AQ24: 6000 | AR24: 8000 | AS24: 3500 | AV24: 700 | AW24: 3500 | AX24: 2000 | AY24: 369.61071 | AZ24: 0 | BA24: 2499.7026 | BB24: 2499.7026 | BC24: 3587.0968 | BD24: 0 | BE24: 13500
B25: =B24+1 -> 46250 | C25: =TEXT(B25,"ddd") -> Mgg | D25: =SUM(E25:BE25) -> 136781.53 | E25: 700 | F25: 500 | G25: 1000 | H25: 999.51613 | I25: 500 | J25: 1000 | K25: 0 | L25: 603.76323 | M25: 673.27548 | N25: 0 | O25: 2000 | P25: 300 | Q25: 6659.5545 | R25: 10300 | S25: 19000 | T25: 5000 | U25: 0 | V25: 6500 | W25: 500 | X25: 6500 | Y25: 0 | Z25: 0 | AA25: 2500 | AB25: 0 | AC25: 89.451613 | AD25: 1000 | AE25: 1300 | AF25: 0 | AG25: 0 | AH25: 500 | AI25: 0 | AJ25: 2999.8519 | AK25: 0 | AL25: 2000 | AM25: 0 | AN25: 11000 | AO25: 2000 | AP25: 5500 | AQ25: 5000 | AR25: 8000 | AS25: 3500 | AT25: 0 | AU25: 0 | AV25: 700 | AW25: 3500 | AX25: 2000 | AY25: 369.61071 | AZ25: 0 | BA25: 2499.7026 | BB25: 2499.7026 | BC25: 3587.0968 | BD25: 0 | BE25: 13500
B26: Sub Total | D26: =SUM(D19:D25) -> 1265024.8 | E26: =SUM(E19:E25) -> 7397.8645 | F26: =SUM(F19:F25) -> 7500 | G26: =SUM(G19:G25) -> 8000 | H26: 20799.516 | I26: 5000 | J26: =SUM(J19:J25) -> 9500 | K26: 900 | L26: 4226.3426 | M26: =SUM(M19:M25) -> 4712.9284 | N26: =SUM(N19:N25) -> 32000 | O26: 29000 | P26: =SUM(P19:P25) -> 13800 | Q26: =SUM(Q19:Q25) -> 102659.55 | R26: =SUM(R19:R25) -> 72100 | S26: =SUM(S19:S25) -> 133000 | T26: =SUM(T19:T25) -> 35000 | U26: =SUM(U19:U25) -> 38500 | V26: =SUM(V19:V25) -> 45500 | W26: =SUM(W19:W25) -> 3500 | ... AF26: =SUM(AF19:AF25) -> 15000 | AG26: 0 | AH26: =SUM(AH19:AH25) -> 12500 | AI26: =SUM(AI19:AI25) -> 4800 | AJ26: =SUM(AJ19:AJ25) -> 46199.852 | AK26: =SUM(AK19:AK25) -> 10000 | AL26: =SUM(AL19:AL25) -> 14000 | AM26: =SUM(AM19:AM25) -> 6000 | AN26: =SUM(AN19:AN25) -> 77000 | AO26: =SUM(AO19:AO25) -> 14000 | ... BE26: =SUM(BE19:BE25) -> 94500
A28: =WEEKNUM(B28) -> 34 | B28: =B25+1 -> 46251 | C28: =TEXT(B28,"ddd") -> Sen | D28: =SUM(E28:BE28) -> 109622.6 | E28: 0 | F28: 0 | G28: 1200 | H28: 1000 | I28: 800 | J28: 0 | K28: 0 | L28: 603.76323 | M28: 673.27548 | N28: 0 | O28: 0 | P28: 300 | Q28: 6500 | R28: 10300 | S28: 19000 | T28: 0 | U28: 0 | V28: 6500 | W28: 0 | X28: 6500 | Y28: 500 | Z28: 0 | AA28: 0 | AB28: 0 | AC28: 89.451613 | AD28: 0 | AE28: 1300 | AF28: 0 | AG28: 0 | AH28: 0 | AI28: 0 | AJ28: 7200 | AK28: 0 | AL28: 0 | AM28: 0 | AN28: 5000 | AO28: 1000 | AP28: 0 | AQ28: 4500 | AR28: 8000 | AS28: 0 | AT28: 0 | AU28: 0 | AV28: 700 | AW28: 3500 | AX28: 2000 | AY28: 369.61071 | AZ28: 0 | BA28: 2499.7026 | BB28: 2499.7026 | BC28: 3587.0968 | BD28: 0 | BE28: 13500
B29: =B28+1 -> 46252 | C29: =TEXT(B29,"ddd") -> Sel | D29: =SUM(E29:BE29) -> 187194.13 | E29: 1199.5729 | F29: 1300 | G29: 1200 | H29: 3300 | I29: 800 | J29: 1000 | K29: 150 | L29: 603.76323 | M29: 673.27548 | N29: 5500 | O29: 5000 | P29: 2500 | Q29: 16000 | R29: 10300 | S29: 19000 | T29: 5000 | U29: 7000 | V29: 6500 | W29: 500 | X29: 6500 | Y29: 500 | Z29: 1000 | AA29: 5500 | AB29: 0 | AC29: 89.451613 | AD29: 3500 | AE29: 1300 | AF29: 3000 | AG29: 0 | AH29: 2000 | AI29: 800 | AJ29: 7200 | AK29: 2000 | AL29: 2000 | AM29: 1000 | AN29: 11000 | AO29: 2000 | AP29: 4000 | AQ29: 9000.0571 | AR29: 4000 | AS29: 3500 | AT29: 0 | AU29: 0 | AV29: 700 | AW29: 3500 | AX29: 2000 | AY29: 369.61071 | AZ29: 1121.9003 | BA29: 2499.7026 | BB29: 2499.7026 | BC29: 3587.0968 | BD29: 0 | BE29: 13500
B30: =B29+1 -> 46253 | C30: =TEXT(B30,"ddd") -> Rab | D30: =SUM(E30:BE30) -> 187194.13 | E30: 1199.5729 | F30: 1300 | G30: 1200 | H30: 3300 | I30: 800 | J30: 1000 | K30: 150 | L30: 603.76323 | M30: 673.27548 | N30: 5500 | O30: 5000 | P30: 2500 | Q30: 16000 | R30: 10300 | S30: 19000 | T30: 5000 | U30: 7000 | V30: 6500 | W30: 500 | X30: 6500 | Y30: 500 | Z30: 1000 | AA30: 5500 | AC30: 89.451613 | AD30: 3500 | AE30: 1300 | AF30: 3000 | AG30: 0 | AH30: 2000 | AI30: 800 | AJ30: 7200 | AK30: 2000 | AL30: 2000 | AM30: 1000 | AN30: 11000 | AO30: 2000 | AP30: 4000 | AQ30: 9000.0571 | AR30: 4000 | AS30: 3500 | AV30: 700 | AW30: 3500 | AX30: 2000 | AY30: 369.61071 | AZ30: 1121.9003 | BA30: 2499.7026 | BB30: 2499.7026 | BC30: 3587.0968 | BD30: 0 | BE30: 13500
B31: =B30+1 -> 46254 | C31: =TEXT(B31,"ddd") -> Kam | D31: =SUM(E31:BE31) -> 187194.13 | E31: 1199.5729 | F31: 1300 | G31: 1200 | H31: 3300 | I31: 800 | J31: 1000 | K31: 150 | L31: 603.76323 | M31: 673.27548 | N31: 5500 | O31: 5000 | P31: 2500 | Q31: 16000 | R31: 10300 | S31: 19000 | T31: 5000 | U31: 7000 | V31: 6500 | W31: 500 | X31: 6500 | Y31: 500 | Z31: 1000 | AA31: 5500 | AB31: 0 | AC31: 89.451613 | AD31: 3500 | AE31: 1300 | AF31: 3000 | AG31: 0 | AH31: 2000 | AI31: 800 | AJ31: 7200 | AK31: 2000 | AL31: 2000 | AM31: 1000 | AN31: 11000 | AO31: 2000 | AP31: 4000 | AQ31: 9000.0571 | AR31: 4000 | AS31: 3500 | AT31: 0 | AU31: 0 | AV31: 700 | AW31: 3500 | AX31: 2000 | AY31: 369.61071 | AZ31: 1121.9003 | BA31: 2499.7026 | BB31: 2499.7026 | BC31: 3587.0968 | BD31: 0 | BE31: 13500
B32: =B31+1 -> 46255 | C32: =TEXT(B32,"ddd") -> Jum | D32: =SUM(E32:BE32) -> 187194.13 | E32: 1199.5729 | F32: 1300 | G32: 1200 | H32: 3300 | I32: 800 | J32: 1000 | K32: 150 | L32: 603.76323 | M32: 673.27548 | N32: 5500 | O32: 5000 | P32: 2500 | Q32: 16000 | R32: 10300 | S32: 19000 | T32: 5000 | U32: 7000 | V32: 6500 | W32: 500 | X32: 6500 | Y32: 500 | Z32: 1000 | AA32: 5500 | AB32: 0 | AC32: 89.451613 | AD32: 3500 | AE32: 1300 | AF32: 3000 | AG32: 0 | AH32: 2000 | AI32: 800 | AJ32: 7200 | AK32: 2000 | AL32: 2000 | AM32: 1000 | AN32: 11000 | AO32: 2000 | AP32: 4000 | AQ32: 9000.0571 | AR32: 4000 | AS32: 3500 | AT32: =SUM(AT25:AT31) -> 0 | AU32: =SUM(AU25:AU31) -> 0 | AV32: 700 | AW32: 3500 | AX32: 2000 | AY32: 369.61071 | AZ32: 1121.9003 | BA32: 2499.7026 | BB32: 2499.7026 | BC32: 3587.0968 | BD32: 0 | BE32: 13500
B33: =B32+1 -> 46256 | C33: =TEXT(B33,"ddd") -> Sab | D33: =SUM(E33:BE33) -> 181272.6 | E33: 700 | F33: 500 | G33: 1000 | H33: 3300 | I33: 500 | J33: 1000 | K33: 150 | L33: 603.76323 | M33: 673.27548 | N33: 4500 | O33: 2000 | P33: 1000 | Q33: 16000 | R33: 10300 | S33: 19000 | T33: 5000 | U33: 0 | V33: 6500 | W33: 500 | X33: 6500 | Y33: 500 | Z33: 1000 | AA33: 5500 | AB33: 0 | AC33: 89.451613 | AD33: 3500 | AE33: 1300 | AF33: 0 | AG33: 12000 | AH33: 2000 | AI33: 800 | AJ33: 7200 | AK33: 0 | AL33: 2000 | AM33: 1000 | AN33: 11000 | AO33: 2000 | AP33: 5500 | AQ33: 6000 | AR33: 8000 | AS33: 3500 | AV33: 700 | AW33: 3500 | AX33: 2000 | AY33: 369.61071 | AZ33: 0 | BA33: 2499.7026 | BB33: 2499.7026 | BC33: 3587.0968 | BD33: 0 | BE33: 13500
B34: =B33+1 -> 46257 | C34: =TEXT(B34,"ddd") -> Mgg | D34: =SUM(E34:BE34) -> 148281.53 | E34: 700 | F34: 500 | G34: 1000 | H34: 999.51613 | I34: 500 | J34: 0 | K34: 0 | L34: 603.76323 | M34: 673.27548 | N34: 0 | O34: 2000 | P34: 300 | Q34: 6659.5545 | R34: 10300 | S34: 19000 | T34: 5000 | U34: 0 | V34: 6500 | W34: 500 | X34: 6500 | Y34: 500 | Z34: 0 | AA34: 2500 | AB34: 0 | AC34: 89.451613 | AD34: 1000 | AE34: 1300 | AF34: 0 | AG34: 12000 | AH34: 500 | AI34: 0 | AJ34: 2999.8519 | AK34: 0 | AL34: 2000 | AM34: 0 | AN34: 11000 | AO34: 2000 | AP34: 5500 | AQ34: 5000 | AR34: 8000 | AS34: 3500 | AT34: 0 | AU34: 0 | AV34: 700 | AW34: 3500 | AX34: 2000 | AY34: 369.61071 | AZ34: 0 | BA34: 2499.7026 | BB34: 2499.7026 | BC34: 3587.0968 | BD34: 0 | BE34: 13500
B35: Sub Total | D35: =SUM(D28:D34) -> 1187953.3 | E35: =SUM(E28:E34) -> 6198.2916 | F35: =SUM(F28:F34) -> 6200 | G35: =SUM(G28:G34) -> 8000 | H35: 18499.516 | I35: 5000 | J35: =SUM(J28:J34) -> 5000 | K35: 750 | L35: 4226.3426 | M35: =SUM(M28:M34) -> 4712.9284 | N35: =SUM(N28:N34) -> 26500 | O35: 24000 | P35: =SUM(P28:P34) -> 11600 | Q35: =SUM(Q28:Q34) -> 93159.555 | R35: =SUM(R28:R34) -> 72100 | S35: =SUM(S28:S34) -> 133000 | T35: =SUM(T28:T34) -> 30000 | U35: =SUM(U28:U34) -> 28000 | V35: =SUM(V28:V34) -> 45500 | W35: =SUM(W28:W34) -> 3000 | ... AF35: =SUM(AF28:AF34) -> 12000 | AG35: 24000 | AH35: =SUM(AH28:AH34) -> 10500 | AI35: =SUM(AI28:AI34) -> 4000 | AJ35: =SUM(AJ28:AJ34) -> 46199.852 | AK35: =SUM(AK28:AK34) -> 8000 | AL35: =SUM(AL28:AL34) -> 12000 | AM35: =SUM(AM28:AM34) -> 5000 | AN35: =SUM(AN28:AN34) -> 71000 | AO35: =SUM(AO28:AO34) -> 13000 | ... BE35: =SUM(BE28:BE34) -> 94500
A37: =WEEKNUM(B37) -> 35 | B37: =B34+1 -> 46258 | C37: =TEXT(B37,"ddd") -> Sen | D37: =SUM(E37:BE37) -> 203194.13 | E37: 1199.5729 | F37: 1300 | G37: 1200 | H37: 3300 | I37: 800 | J37: 1000 | K37: 150 | L37: 603.76323 | M37: 673.27548 | N37: 5500 | O37: 5000 | P37: 2500 | Q37: 16000 | R37: 10300 | S37: 19000 | T37: 5000 | U37: 7000 | V37: 6500 | W37: 500 | X37: 6500 | Y37: 500 | Z37: 1000 | AA37: 5500 | AB37: 0 | AC37: 89.451613 | AD37: 3500 | AE37: 1300 | AF37: 3000 | AG37: 12000 | AH37: 2000 | AI37: 800 | AJ37: 7200 | AK37: 2000 | AL37: 2000 | AM37: 1000 | AN37: 11000 | AO37: 2000 | AP37: 4000 | AQ37: 9000.0571 | AR37: 8000 | AS37: 3500 | AT37: 0 | AU37: 0 | AV37: 700 | AW37: 3500 | AX37: 2000 | AY37: 369.61071 | AZ37: 1121.9003 | BA37: 2499.7026 | BB37: 2499.7026 | BC37: 3587.0968 | BD37: 0 | BE37: 13500
B38: =B37+1 -> 46259 | C38: =TEXT(B38,"ddd") -> Sel | D38: =SUM(E38:BE38) -> 187194.13 | E38: 1199.5729 | F38: 1300 | G38: 1200 | H38: 3300 | I38: 800 | J38: 0 | K38: 150 | L38: 603.76323 | M38: 673.27548 | N38: 5500 | O38: 5000 | P38: 2500 | Q38: 16000 | R38: 10300 | S38: 19000 | T38: 0 | U38: 0 | V38: 6500 | W38: 500 | X38: 6500 | Y38: 500 | Z38: 1000 | AA38: 5500 | AB38: =SUM(AB31:AB37) -> 0 | AC38: 89.451613 | AD38: 3500 | AE38: 1300 | AF38: 0 | AG38: 12000 | AH38: 2000 | AI38: 800 | AJ38: 7200 | AK38: 2000 | AL38: 2000 | AM38: 1000 | AN38: 11000 | AO38: 2000 | AP38: 4000 | AQ38: 9000.0571 | AR38: 8000 | AS38: 3500 | AT38: =SUM(AT31:AT37) -> 0 | AU38: =SUM(AU31:AU37) -> 0 | AV38: 700 | AW38: 3500 | AX38: 2000 | AY38: 369.61071 | AZ38: 1121.9003 | BA38: 2499.7026 | BB38: 2499.7026 | BC38: 3587.0968 | BD38: 0 | BE38: 13500
B39: =B38+1 -> 46260 | C39: =TEXT(B39,"ddd") -> Rab | D39: =SUM(E39:BE39) -> 203194.13 | E39: 1199.5729 | F39: 1300 | G39: 1200 | H39: 3300 | I39: 800 | J39: 1000 | K39: 150 | L39: 603.76323 | M39: 673.27548 | N39: 5500 | O39: 5000 | P39: 2500 | Q39: 16000 | R39: 10300 | S39: 19000 | T39: 5000 | U39: 7000 | V39: 6500 | W39: 500 | X39: 6500 | Y39: 500 | Z39: 1000 | AA39: 5500 | AC39: 89.451613 | AD39: 3500 | AE39: 1300 | AF39: 3000 | AG39: 12000 | AH39: 2000 | AI39: 800 | AJ39: 7200 | AK39: 2000 | AL39: 2000 | AM39: 1000 | AN39: 11000 | AO39: 2000 | AP39: 4000 | AQ39: 9000.0571 | AR39: 8000 | AS39: 3500 | AV39: 700 | AW39: 3500 | AX39: 2000 | AY39: 369.61071 | AZ39: 1121.9003 | BA39: 2499.7026 | BB39: 2499.7026 | BC39: 3587.0968 | BD39: 0 | BE39: 13500
B40: =B39+1 -> 46261 | C40: =TEXT(B40,"ddd") -> Kam | D40: =SUM(E40:BE40) -> 203194.13 | E40: 1199.5729 | F40: 1300 | G40: 1200 | H40: 3300 | I40: 800 | J40: 1000 | K40: 150 | L40: 603.76323 | M40: 673.27548 | N40: 5500 | O40: 5000 | P40: 2500 | Q40: 16000 | R40: 10300 | S40: 19000 | T40: 5000 | U40: 7000 | V40: 6500 | W40: 500 | X40: 6500 | Y40: 500 | Z40: 1000 | AA40: 5500 | AB40: 0 | AC40: 89.451613 | AD40: 3500 | AE40: 1300 | AF40: 3000 | AG40: 12000 | AH40: 2000 | AI40: 800 | AJ40: 7200 | AK40: 2000 | AL40: 2000 | AM40: 1000 | AN40: 11000 | AO40: 2000 | AP40: 4000 | AQ40: 9000.0571 | AR40: 8000 | AS40: 3500 | AT40: 0 | AU40: 0 | AV40: 700 | AW40: 3500 | AX40: 2000 | AY40: 369.61071 | AZ40: 1121.9003 | BA40: 2499.7026 | BB40: 2499.7026 | BC40: 3587.0968 | BD40: 0 | BE40: 13500
B41: =B40+1 -> 46262 | C41: =TEXT(B41,"ddd") -> Jum | D41: =SUM(E41:BE41) -> 203194.13 | E41: 1199.5729 | F41: 1300 | G41: 1200 | H41: 3300 | I41: 800 | J41: 1000 | K41: 150 | L41: 603.76323 | M41: 673.27548 | N41: 5500 | O41: 5000 | P41: 2500 | Q41: 16000 | R41: 10300 | S41: 19000 | T41: 5000 | U41: 7000 | V41: 6500 | W41: 500 | X41: 6500 | Y41: 500 | Z41: 1000 | AA41: 5500 | AB41: 0 | AC41: 89.451613 | AD41: 3500 | AE41: 1300 | AF41: 3000 | AG41: 12000 | AH41: 2000 | AI41: 800 | AJ41: 7200 | AK41: 2000 | AL41: 2000 | AM41: 1000 | AN41: 11000 | AO41: 2000 | AP41: 4000 | AQ41: 9000.0571 | AR41: 8000 | AS41: 3500 | AT41: 0 | AU41: 0 | AV41: 700 | AW41: 3500 | AX41: 2000 | AY41: 369.61071 | AZ41: 1121.9003 | BA41: 2499.7026 | BB41: 2499.7026 | BC41: 3587.0968 | BD41: 0 | BE41: 13500
B42: =B41+1 -> 46263 | C42: =TEXT(B42,"ddd") -> Sab | D42: =SUM(E42:BE42) -> 181272.6 | E42: 700 | F42: 500 | G42: 1000 | H42: 3300 | I42: 500 | J42: 1000 | K42: 150 | L42: 603.76323 | M42: 673.27548 | N42: 4500 | O42: 2000 | P42: 1000 | Q42: 16000 | R42: 10300 | S42: 19000 | T42: 5000 | U42: 0 | V42: 6500 | W42: 500 | X42: 6500 | Y42: 500 | Z42: 1000 | AA42: 5500 | AB42: 0 | AC42: 89.451613 | AD42: 3500 | AE42: 1300 | AF42: 0 | AG42: 12000 | AH42: 2000 | AI42: 800 | AJ42: 7200 | AK42: 0 | AL42: 2000 | AM42: 1000 | AN42: 11000 | AO42: 2000 | AP42: 5500 | AQ42: 6000 | AR42: 8000 | AS42: 3500 | AT42: 0 | AU42: 0 | AV42: 700 | AW42: 3500 | AX42: 2000 | AY42: 369.61071 | AZ42: 0 | BA42: 2499.7026 | BB42: 2499.7026 | BC42: 3587.0968 | BD42: 0 | BE42: 13500
B43: =B42+1 -> 46264 | C43: =TEXT(B43,"ddd") -> Mgg | D43: =SUM(E43:BE43) -> 149281.53 | E43: 700 | F43: 500 | G43: 1000 | H43: 999.51613 | I43: 500 | J43: 1000 | K43: 0 | L43: 603.76323 | M43: 673.27548 | N43: 0 | O43: 2000 | P43: 300 | Q43: 6659.5545 | R43: 10300 | S43: 19000 | T43: 5000 | U43: 0 | V43: 6500 | W43: 500 | X43: 6500 | Y43: 500 | Z43: 0 | AA43: 2500 | AB43: 0 | AC43: 89.451613 | AD43: 1000 | AE43: 1300 | AF43: 0 | AG43: 12000 | AH43: 500 | AI43: 0 | AJ43: 2999.8519 | AK43: 0 | AL43: 2000 | AM43: 0 | AN43: 11000 | AO43: 2000 | AP43: 5500 | AQ43: 5000 | AR43: 8000 | AS43: 3500 | AT43: 0 | AU43: 0 | AV43: 700 | AW43: 3500 | AX43: 2000 | AY43: 369.61071 | AZ43: 0 | BA43: 2499.7026 | BB43: 2499.7026 | BC43: 3587.0968 | BD43: 0 | BE43: 13500
B44: Sub Total | D44: =SUM(D37:D43) -> 1330524.8 | E44: =SUM(E37:E43) -> 7397.8645 | F44: =SUM(F37:F43) -> 7500 | G44: =SUM(G37:G43) -> 8000 | H44: 20799.516 | I44: 5000 | J44: =SUM(J37:J43) -> 6000 | K44: 900 | L44: 4226.3426 | M44: =SUM(M37:M43) -> 4712.9284 | N44: =SUM(N37:N43) -> 32000 | O44: 29000 | P44: =SUM(P37:P43) -> 13800 | Q44: =SUM(Q37:Q43) -> 102659.55 | R44: =SUM(R37:R43) -> 72100 | S44: =SUM(S37:S43) -> 133000 | T44: =SUM(T37:T43) -> 30000 | U44: =SUM(U37:U43) -> 28000 | V44: =SUM(V37:V43) -> 45500 | W44: =SUM(W37:W43) -> 3500 | ... AF44: =SUM(AF37:AF43) -> 12000 | AG44: 84000 | AH44: =SUM(AH37:AH43) -> 12500 | AI44: =SUM(AI37:AI43) -> 4800 | AJ44: =SUM(AJ37:AJ43) -> 46199.852 | AK44: =SUM(AK37:AK43) -> 10000 | AL44: =SUM(AL37:AL43) -> 14000 | AM44: =SUM(AM37:AM43) -> 6000 | AN44: =SUM(AN37:AN43) -> 77000 | AO44: =SUM(AO37:AO43) -> 14000 | ... BE44: =SUM(BE37:BE43) -> 94500
A46: =WEEKNUM(B46) -> 36 | B46: =B43+1 -> 46265 | C46: =TEXT(B46,"ddd") -> Sen | D46: =SUM(E46:BE46) -> 196194.13 | E46: 1199.5729 | F46: 1300 | G46: 1200 | H46: 3300 | I46: 800 | J46: 1000 | K46: 150 | L46: 603.76323 | M46: 673.27548 | N46: 5500 | O46: 5000 | P46: 2500 | Q46: 16000 | R46: 10300 | S46: 19000 | T46: 5000 | U46: 0 | V46: 6500 | W46: 500 | X46: 6500 | Y46: 500 | Z46: 1000 | AA46: 5500 | AB46: 0 | AC46: 89.451613 | AD46: 3500 | AE46: 1300 | AF46: 3000 | AG46: 12000 | AH46: 2000 | AI46: 800 | AJ46: 7200 | AK46: 2000 | AL46: 2000 | AM46: 1000 | AN46: 11000 | AO46: 2000 | AP46: 4000 | AQ46: 9000.0571 | AR46: 8000 | AS46: 3500 | AT46: 0 | AU46: 0 | AV46: 700 | AW46: 3500 | AX46: 2000 | AY46: 369.61071 | AZ46: 1121.9003 | BA46: 2499.7026 | BB46: 2499.7026 | BC46: 3587.0968 | BD46: 0 | BE46: 13500
...

Sheet KEBUTUHAN GAS
A1: KEBUTUHAN GAS
A4: ='SO FOB Agustus 2026'!A4 -> 46235 | F4: KEBUTUHAN GAS | J4: KUOTA GAS
A5: Week | B5: DATE | D5: SELISIH GAS JABAR | E5: SELISIH GAS TOTAL | F5: JABAR | G5: JATENG | H5: JATIM | I5: TOTAL | J5: MS SETU | K5: MS KHT | L5: MS BLORA | M5: MS BITUNG | N5: MS ZEBRA | O5: MS TAMBAKLOROK | P5: MS BaGS | Q5: MS SADANG | R5: TOTAL
A6: =WEEKNUM(B6) -> 31 | B6: =A4 -> 46235 | C6: =TEXT(B6,"ddd") -> Sab | D6: =(J6+K6)-F6 -> -15953.511 | E6: =R6-I6 -> -16722.527 | F6: =SUM('SO Agustus 2026 Rev.3'!E6:AS6) -> 158460.51 | G6: =SUM('SO Agustus 2026 Rev.3'!AV6:BB6) -> 11569.016 | H6: =SUM('SO Agustus 2026 Rev.3'!BC6:BE6) -> 17087.097 | I6: =SUM(F6:H6) -> 187116.62 | J6: ='SO MS'!E6 -> 108187 | K6: ='SO MS'!F6 -> 34320 | L6: ='SO MS'!G6 -> 10800 | M6: ='SO MS'!H6 -> 0 | N6: ='SO MS'!I6 -> 3587.0968 | O6: ='SO MS'!J6 -> 0 | P6: ='SO MS'!K6 -> 13500 | Q6: ='SO MS'!L6 -> 0 | R6: =SUM(J6:Q6) -> 170394.1
B7: =B6+1 -> 46236 | C7: =TEXT(B7,"ddd") -> Mgg | D7: =(J7+K7)-F7 -> 14777.566 | E7: =R7-I7 -> 14008.551 | F7: =SUM('SO Agustus 2026 Rev.3'!E7:AS7) -> 127969.43 | G7: =SUM('SO Agustus 2026 Rev.3'!AV7:BB7) -> 11569.016 | H7: =SUM('SO Agustus 2026 Rev.3'!BC7:BE7) -> 17087.097 | I7: =SUM(F7:H7) -> 156625.55 | J7: ='SO MS'!E7 -> 108187 | K7: ='SO MS'!F7 -> 34560 | L7: ='SO MS'!G7 -> 10800 | M7: ='SO MS'!H7 -> 0 | N7: ='SO MS'!I7 -> 3587.0968 | O7: ='SO MS'!J7 -> 0 | P7: ='SO MS'!K7 -> 13500 | Q7: ='SO MS'!L7 -> 0 | R7: =SUM(J7:Q7) -> 170634.1
B8: Sub Total | D8: =SUM(D6:D7) -> -1175.9445 | E8: =SUM(E6:E7) -> -2713.9763 | F8: =SUM(F6:F7) -> 286429.94 | G8: =SUM(G6:G7) -> 23138.032 | H8: =SUM(H6:H7) -> 34174.194 | I8: =SUM(I6:I7) -> 343742.17 | J8: =SUM(J6:J7) -> 216374 | K8: =SUM(K6:K7) -> 68880 | ... R8: =SUM(R6:R7) -> 341028.19
B10: =B7+1 -> 46237 | C10: =TEXT(B10,"ddd") -> Sen | D10: =(J10+K10)-F10 -> -33713.141 | E10: =R10-I10 -> -35604.057 | F10: =SUM('SO Agustus 2026 Rev.3'!E10:AS10) -> 176460.14 | G10: =SUM('SO Agustus 2026 Rev.3'!AV10:BB10) -> 12690.916 | H10: =SUM('SO Agustus 2026 Rev.3'!BC10:BE10) -> 17087.097 | I10: =SUM(F10:H10) -> 206238.15 | J10: ='SO MS'!E10 -> 108187 | K10: ='SO MS'!F10 -> 34560 | L10: ='SO MS'!G10 -> 10800 | M10: ='SO MS'!H10 -> 0 | N10: ='SO MS'!I10 -> 3587.0968 | O10: ='SO MS'!J10 -> 0 | P10: ='SO MS'!K10 -> 13500 | Q10: ='SO MS'!L10 -> 0 | R10: =SUM(J10:Q10) -> 170634.1
B11: =B10+1 -> 46238 | C11: =TEXT(B11,"ddd") -> Sel | D11: =(J11+K11)-F11 -> -33713.141 | E11: =R11-I11 -> -35604.057 | F11: =SUM('SO Agustus 2026 Rev.3'!E11:AS11) -> 176460.14 | G11: =SUM('SO Agustus 2026 Rev.3'!AV11:BB11) -> 12690.916 | H11: =SUM('SO Agustus 2026 Rev.3'!BC11:BE11) -> 17087.097 | I11: =SUM(F11:H11) -> 206238.15 | J11: ='SO MS'!E11 -> 108187 | K11: ='SO MS'!F11 -> 34560 | L11: ='SO MS'!G11 -> 10800 | M11: ='SO MS'!H11 -> 0 | N11: ='SO MS'!I11 -> 3587.0968 | O11: ='SO MS'!J11 -> 0 | P11: ='SO MS'!K11 -> 13500 | Q11: ='SO MS'!L11 -> 0 | R11: =SUM(J11:Q11) -> 170634.1
B12: =B11+1 -> 46239 | C12: =TEXT(B12,"ddd") -> Rab | D12: =(J12+K12)-F12 -> -33713.141 | E12: =R12-I12 -> -35604.057 | F12: =SUM('SO Agustus 2026 Rev.3'!E12:AS12) -> 176460.14 | G12: =SUM('SO Agustus 2026 Rev.3'!AV12:BB12) -> 12690.916 | H12: =SUM('SO Agustus 2026 Rev.3'!BC12:BE12) -> 17087.097 | I12: =SUM(F12:H12) -> 206238.15 | J12: ='SO MS'!E12 -> 108187 | K12: ='SO MS'!F12 -> 34560 | L12: ='SO MS'!G12 -> 10800 | M12: ='SO MS'!H12 -> 0 | N12: ='SO MS'!I12 -> 3587.0968 | O12: ='SO MS'!J12 -> 0 | P12: ='SO MS'!K12 -> 13500 | Q12: ='SO MS'!L12 -> 0 | R12: =SUM(J12:Q12) -> 170634.1
A13: =WEEKNUM(B13) -> 32 | B13: =B12+1 -> 46240 | C13: =TEXT(B13,"ddd") -> Kam | D13: =(J13+K13)-F13 -> -22273.141 | E13: =R13-I13 -> -24164.057 | F13: =SUM('SO Agustus 2026 Rev.3'!E13:AS13) -> 176460.14 | G13: =SUM('SO Agustus 2026 Rev.3'!AV13:BB13) -> 12690.916 | H13: =SUM('SO Agustus 2026 Rev.3'!BC13:BE13) -> 17087.097 | I13: =SUM(F13:H13) -> 206238.15 | J13: ='SO MS'!E13 -> 108187 | K13: ='SO MS'!F13 -> 46000 | L13: ='SO MS'!G13 -> 10800 | M13: ='SO MS'!H13 -> 0 | N13: ='SO MS'!I13 -> 3587.0968 | O13: ='SO MS'!J13 -> 0 | P13: ='SO MS'!K13 -> 13500 | Q13: ='SO MS'!L13 -> 0 | R13: =SUM(J13:Q13) -> 182074.1
B14: =B13+1 -> 46241 | C14: =TEXT(B14,"ddd") -> Jum | D14: =(J14+K14)-F14 -> 12365.859 | E14: =R14-I14 -> 10474.943 | F14: =SUM('SO Agustus 2026 Rev.3'!E14:AS14) -> 176460.14 | G14: =SUM('SO Agustus 2026 Rev.3'!AV14:BB14) -> 12690.916 | H14: =SUM('SO Agustus 2026 Rev.3'!BC14:BE14) -> 17087.097 | I14: =SUM(F14:H14) -> 206238.15 | J14: ='SO MS'!E14 -> 142826 | K14: ='SO MS'!F14 -> 46000 | L14: ='SO MS'!G14 -> 10800 | M14: ='SO MS'!H14 -> 0 | N14: ='SO MS'!I14 -> 3587.0968 | O14: ='SO MS'!J14 -> 0 | P14: ='SO MS'!K14 -> 13500 | Q14: ='SO MS'!L14 -> 0 | R14: =SUM(J14:Q14) -> 216713.1
B15: =B14+1 -> 46242 | C15: =TEXT(B15,"ddd") -> Sab | D15: =(J15+K15)-F15 -> 30365.489 | E15: =R15-I15 -> 29596.473 | F15: =SUM('SO Agustus 2026 Rev.3'!E15:AS15) -> 158460.51 | G15: =SUM('SO Agustus 2026 Rev.3'!AV15:BB15) -> 11569.016 | H15: =SUM('SO Agustus 2026 Rev.3'!BC15:BE15) -> 17087.097 | I15: =SUM(F15:H15) -> 187116.62 | J15: ='SO MS'!E15 -> 142826 | K15: ='SO MS'!F15 -> 46000 | L15: ='SO MS'!G15 -> 10800 | M15: ='SO MS'!H15 -> 0 | N15: ='SO MS'!I15 -> 3587.0968 | O15: ='SO MS'!J15 -> 0 | P15: ='SO MS'!K15 -> 13500 | Q15: ='SO MS'!L15 -> 0 | R15: =SUM(J15:Q15) -> 216713.1
B16: =B15+1 -> 46243 | C16: =TEXT(B16,"ddd") -> Mgg | D16: =(J16+K16)-F16 -> 60856.566 | E16: =R16-I16 -> 60087.551 | F16: =SUM('SO Agustus 2026 Rev.3'!E16:AS16) -> 127969.43 | G16: =SUM('SO Agustus 2026 Rev.3'!AV16:BB16) -> 11569.016 | H16: =SUM('SO Agustus 2026 Rev.3'!BC16:BE16) -> 17087.097 | I16: =SUM(F16:H16) -> 156625.55 | J16: ='SO MS'!E16 -> 142826 | K16: ='SO MS'!F16 -> 46000 | L16: ='SO MS'!G16 -> 10800 | M16: ='SO MS'!H16 -> 0 | N16: ='SO MS'!I16 -> 3587.0968 | O16: ='SO MS'!J16 -> 0 | P16: ='SO MS'!K16 -> 13500 | Q16: ='SO MS'!L16 -> 0 | R16: =SUM(J16:Q16) -> 216713.1
B17: Sub Total | D17: =SUM(D10:D16) -> -19824.649 | E17: =SUM(E10:E16) -> -30817.262 | F17: =SUM(F10:F16) -> 1168730.6 | G17: =SUM(G10:G16) -> 86592.613 | H17: =SUM(H10:H16) -> 119609.68 | I17: =SUM(I10:I16) -> 1374932.9 | J17: =SUM(J10:J16) -> 861226 | K17: =SUM(K10:K16) -> 287680 | ... R17: =SUM(R10:R16) -> 1344115.7
B19: =B16+1 -> 46244 | C19: =TEXT(B19,"ddd") -> Sen | D19: =(J19+K19)-F19 -> 27409.88 | E19: =R19-I19 -> 25518.963 | F19: =SUM('SO Agustus 2026 Rev.3'!E19:AS19) -> 161416.12 | G19: =SUM('SO Agustus 2026 Rev.3'!AV19:BB19) -> 12690.916 | H19: =SUM('SO Agustus 2026 Rev.3'!BC19:BE19) -> 17087.097 | I19: =SUM(F19:H19) -> 191194.13 | J19: ='SO MS'!E19 -> 142826 | K19: ='SO MS'!F19 -> 46000 | L19: ='SO MS'!G19 -> 10800 | M19: ='SO MS'!H19 -> 0 | N19: ='SO MS'!I19 -> 3587.0968 | O19: ='SO MS'!J19 -> 0 | P19: ='SO MS'!K19 -> 13500 | Q19: ='SO MS'!L19 -> 0 | R19: =SUM(J19:Q19) -> 216713.1
B20: =B19+1 -> 46245 | C20: =TEXT(B20,"ddd") -> Sel | D20: =(J20+K20)-F20 -> 27409.88 | E20: =R20-I20 -> 25518.963 | F20: =SUM('SO Agustus 2026 Rev.3'!E20:AS20) -> 161416.12 | G20: =SUM('SO Agustus 2026 Rev.3'!AV20:BB20) -> 12690.916 | H20: =SUM('SO Agustus 2026 Rev.3'!BC20:BE20) -> 17087.097 | I20: =SUM(F20:H20) -> 191194.13 | J20: ='SO MS'!E20 -> 142826 | K20: ='SO MS'!F20 -> 46000 | L20: ='SO MS'!G20 -> 10800 | M20: ='SO MS'!H20 -> 0 | N20: ='SO MS'!I20 -> 3587.0968 | O20: ='SO MS'!J20 -> 0 | P20: ='SO MS'!K20 -> 13500 | Q20: ='SO MS'!L20 -> 0 | R20: =SUM(J20:Q20) -> 216713.1
B21: =B20+1 -> 46246 | C21: =TEXT(B21,"ddd") -> Rab | D21: =(J21+K21)-F21 -> 27409.88 | E21: =R21-I21 -> 25518.963 | F21: =SUM('SO Agustus 2026 Rev.3'!E21:AS21) -> 161416.12 | G21: =SUM('SO Agustus 2026 Rev.3'!AV21:BB21) -> 12690.916 | H21: =SUM('SO Agustus 2026 Rev.3'!BC21:BE21) -> 17087.097 | I21: =SUM(F21:H21) -> 191194.13 | J21: ='SO MS'!E21 -> 142826 | K21: ='SO MS'!F21 -> 46000 | L21: ='SO MS'!G21 -> 10800 | M21: ='SO MS'!H21 -> 0 | N21: ='SO MS'!I21 -> 3587.0968 | O21: ='SO MS'!J21 -> 0 | P21: ='SO MS'!K21 -> 13500 | Q21: ='SO MS'!L21 -> 0 | R21: =SUM(J21:Q21) -> 216713.1
A22: =WEEKNUM(B22) -> 33 | B22: =B21+1 -> 46247 | C22: =TEXT(B22,"ddd") -> Kam | D22: =(J22+K22)-F22 -> 27409.88 | E22: =R22-I22 -> 25518.963 | F22: =SUM('SO Agustus 2026 Rev.3'!E22:AS22) -> 161416.12 | G22: =SUM('SO Agustus 2026 Rev.3'!AV22:BB22) -> 12690.916 | H22: =SUM('SO Agustus 2026 Rev.3'!BC22:BE22) -> 17087.097 | I22: =SUM(F22:H22) -> 191194.13 | J22: ='SO MS'!E22 -> 142826 | K22: ='SO MS'!F22 -> 46000 | L22: ='SO MS'!G22 -> 10800 | M22: ='SO MS'!H22 -> 0 | N22: ='SO MS'!I22 -> 3587.0968 | O22: ='SO MS'!J22 -> 0 | P22: ='SO MS'!K22 -> 13500 | Q22: ='SO MS'!L22 -> 0 | R22: =SUM(J22:Q22) -> 216713.1
B23: =B22+1 -> 46248 | C23: =TEXT(B23,"ddd") -> Jum | D23: =(J23+K23)-F23 -> 27409.88 | E23: =R23-I23 -> 25518.963 | F23: =SUM('SO Agustus 2026 Rev.3'!E23:AS23) -> 161416.12 | G23: =SUM('SO Agustus 2026 Rev.3'!AV23:BB23) -> 12690.916 | H23: =SUM('SO Agustus 2026 Rev.3'!BC23:BE23) -> 17087.097 | I23: =SUM(F23:H23) -> 191194.13 | J23: ='SO MS'!E23 -> 142826 | K23: ='SO MS'!F23 -> 46000 | L23: ='SO MS'!G23 -> 10800 | M23: ='SO MS'!H23 -> 0 | N23: ='SO MS'!I23 -> 3587.0968 | O23: ='SO MS'!J23 -> 0 | P23: ='SO MS'!K23 -> 13500 | Q23: ='SO MS'!L23 -> 0 | R23: =SUM(J23:Q23) -> 216713.1
B24: =B23+1 -> 46249 | C24: =TEXT(B24,"ddd") -> Sab | D24: =(J24+K24)-F24 -> 45209.51 | E24: =R24-I24 -> 44440.494 | F24: =SUM('SO Agustus 2026 Rev.3'!E24:AS24) -> 143616.49 | G24: =SUM('SO Agustus 2026 Rev.3'!AV24:BB24) -> 11569.016 | H24: =SUM('SO Agustus 2026 Rev.3'!BC24:BE24) -> 17087.097 | I24: =SUM(F24:H24) -> 172272.6 | J24: ='SO MS'!E24 -> 142826 | K24: ='SO MS'!F24 -> 46000 | L24: ='SO MS'!G24 -> 10800 | M24: ='SO MS'!H24 -> 0 | N24: ='SO MS'!I24 -> 3587.0968 | O24: ='SO MS'!J24 -> 0 | P24: ='SO MS'!K24 -> 13500 | Q24: ='SO MS'!L24 -> 0 | R24: =SUM(J24:Q24) -> 216713.1
B25: =B24+1 -> 46250 | C25: =TEXT(B25,"ddd") -> Mgg | D25: =(J25+K25)-F25 -> 80700.587 | E25: =R25-I25 -> 79931.571 | F25: =SUM('SO Agustus 2026 Rev.3'!E25:AS25) -> 108125.41 | G25: =SUM('SO Agustus 2026 Rev.3'!AV25:BB25) -> 11569.016 | H25: =SUM('SO Agustus 2026 Rev.3'!BC25:BE25) -> 17087.097 | I25: =SUM(F25:H25) -> 136781.53 | J25: ='SO MS'!E25 -> 142826 | K25: ='SO MS'!F25 -> 46000 | L25: ='SO MS'!G25 -> 10800 | M25: ='SO MS'!H25 -> 0 | N25: ='SO MS'!I25 -> 3587.0968 | O25: ='SO MS'!J25 -> 0 | P25: ='SO MS'!K25 -> 13500 | Q25: ='SO MS'!L25 -> 0 | R25: =SUM(J25:Q25) -> 216713.1
B26: Sub Total | D26: =SUM(D19:D25) -> 262959.5 | E26: =SUM(E19:E25) -> 251966.88 | F26: =SUM(F19:F25) -> 1058822.5 | G26: =SUM(G19:G25) -> 86592.613 | H26: =SUM(H19:H25) -> 119609.68 | I26: =SUM(I19:I25) -> 1265024.8 | J26: =SUM(J19:J25) -> 999782 | K26: =SUM(K19:K25) -> 322000 | ... R26: =SUM(R19:R25) -> 1516991.7
B28: =B25+1 -> 46251 | C28: =TEXT(B28,"ddd") -> Sen | D28: =(J28+K28)-F28 -> 107859.51 | E28: =R28-I28 -> 107090.49 | F28: =SUM('SO Agustus 2026 Rev.3'!E28:AS28) -> 80966.49 | G28: =SUM('SO Agustus 2026 Rev.3'!AV28:BB28) -> 11569.016 | H28: =SUM('SO Agustus 2026 Rev.3'!BC28:BE28) -> 17087.097 | I28: =SUM(F28:H28) -> 109622.6 | J28: ='SO MS'!E28 -> 142826 | K28: ='SO MS'!F28 -> 46000 | L28: ='SO MS'!G28 -> 10800 | M28: ='SO MS'!H28 -> 0 | N28: ='SO MS'!I28 -> 3587.0968 | O28: ='SO MS'!J28 -> 0 | P28: ='SO MS'!K28 -> 13500 | Q28: ='SO MS'!L28 -> 0 | R28: =SUM(J28:Q28) -> 216713.1
B29: =B28+1 -> 46252 | C29: =TEXT(B29,"ddd") -> Sel | D29: =(J29+K29)-F29 -> 31409.88 | E29: =R29-I29 -> 29518.963 | F29: =SUM('SO Agustus 2026 Rev.3'!E29:AS29) -> 157416.12 | G29: =SUM('SO Agustus 2026 Rev.3'!AV29:BB29) -> 12690.916 | H29: =SUM('SO Agustus 2026 Rev.3'!BC29:BE29) -> 17087.097 | I29: =SUM(F29:H29) -> 187194.13 | J29: ='SO MS'!E29 -> 142826 | K29: ='SO MS'!F29 -> 46000 | L29: ='SO MS'!G29 -> 10800 | M29: ='SO MS'!H29 -> 0 | N29: ='SO MS'!I29 -> 3587.0968 | O29: ='SO MS'!J29 -> 0 | P29: ='SO MS'!K29 -> 13500 | Q29: ='SO MS'!L29 -> 0 | R29: =SUM(J29:Q29) -> 216713.1
B30: =B29+1 -> 46253 | C30: =TEXT(B30,"ddd") -> Rab | D30: =(J30+K30)-F30 -> 31409.88 | E30: =R30-I30 -> 29518.963 | F30: =SUM('SO Agustus 2026 Rev.3'!E30:AS30) -> 157416.12 | G30: =SUM('SO Agustus 2026 Rev.3'!AV30:BB30) -> 12690.916 | H30: =SUM('SO Agustus 2026 Rev.3'!BC30:BE30) -> 17087.097 | I30: =SUM(F30:H30) -> 187194.13 | J30: ='SO MS'!E30 -> 142826 | K30: ='SO MS'!F30 -> 46000 | L30: ='SO MS'!G30 -> 10800 | M30: ='SO MS'!H30 -> 0 | N30: ='SO MS'!I30 -> 3587.0968 | O30: ='SO MS'!J30 -> 0 | P30: ='SO MS'!K30 -> 13500 | Q30: ='SO MS'!L30 -> 0 | R30: =SUM(J30:Q30) -> 216713.1
A31: =WEEKNUM(B31) -> 34 | B31: =B30+1 -> 46254 | C31: =TEXT(B31,"ddd") -> Kam | D31: =(J31+K31)-F31 -> 31409.88 | E31: =R31-I31 -> 29518.963 | F31: =SUM('SO Agustus 2026 Rev.3'!E31:AS31) -> 157416.12 | G31: =SUM('SO Agustus 2026 Rev.3'!AV31:BB31) -> 12690.916 | H31: =SUM('SO Agustus 2026 Rev.3'!BC31:BE31) -> 17087.097 | I31: =SUM(F31:H31) -> 187194.13 | J31: ='SO MS'!E31 -> 142826 | K31: ='SO MS'!F31 -> 46000 | L31: ='SO MS'!G31 -> 10800 | M31: ='SO MS'!H31 -> 0 | N31: ='SO MS'!I31 -> 3587.0968 | O31: ='SO MS'!J31 -> 0 | P31: ='SO MS'!K31 -> 13500 | Q31: ='SO MS'!L31 -> 0 | R31: =SUM(J31:Q31) -> 216713.1
B32: =B31+1 -> 46255 | C32: =TEXT(B32,"ddd") -> Jum | D32: =(J32+K32)-F32 -> 31409.88 | E32: =R32-I32 -> 29518.963 | F32: =SUM('SO Agustus 2026 Rev.3'!E32:AS32) -> 157416.12 | G32: =SUM('SO Agustus 2026 Rev.3'!AV32:BB32) -> 12690.916 | H32: =SUM('SO Agustus 2026 Rev.3'!BC32:BE32) -> 17087.097 | I32: =SUM(F32:H32) -> 187194.13 | J32: ='SO MS'!E32 -> 142826 | K32: ='SO MS'!F32 -> 46000 | L32: ='SO MS'!G32 -> 10800 | M32: ='SO MS'!H32 -> 0 | N32: ='SO MS'!I32 -> 3587.0968 | O32: ='SO MS'!J32 -> 0 | P32: ='SO MS'!K32 -> 13500 | Q32: ='SO MS'!L32 -> 0 | R32: =SUM(J32:Q32) -> 216713.1
B33: =B32+1 -> 46256 | C33: =TEXT(B33,"ddd") -> Sab | D33: =(J33+K33)-F33 -> 36209.51 | E33: =R33-I33 -> 35440.494 | F33: =SUM('SO Agustus 2026 Rev.3'!E33:AS33) -> 152616.49 | G33: =SUM('SO Agustus 2026 Rev.3'!AV33:BB33) -> 11569.016 | H33: =SUM('SO Agustus 2026 Rev.3'!BC33:BE33) -> 17087.097 | I33: =SUM(F33:H33) -> 181272.6 | J33: ='SO MS'!E33 -> 142826 | K33: ='SO MS'!F33 -> 46000 | L33: ='SO MS'!G33 -> 10800 | M33: ='SO MS'!H33 -> 0 | N33: ='SO MS'!I33 -> 3587.0968 | O33: ='SO MS'!J33 -> 0 | P33: ='SO MS'!K33 -> 13500 | Q33: ='SO MS'!L33 -> 0 | R33: =SUM(J33:Q33) -> 216713.1
B34: =B33+1 -> 46257 | C34: =TEXT(B34,"ddd") -> Mgg | D34: =(J34+K34)-F34 -> 69200.587 | E34: =R34-I34 -> 68431.571 | F34: =SUM('SO Agustus 2026 Rev.3'!E34:AS34) -> 119625.41 | G34: =SUM('SO Agustus 2026 Rev.3'!AV34:BB34) -> 11569.016 | H34: =SUM('SO Agustus 2026 Rev.3'!BC34:BE34) -> 17087.097 | I34: =SUM(F34:H34) -> 148281.53 | J34: ='SO MS'!E34 -> 142826 | K34: ='SO MS'!F34 -> 46000 | L34: ='SO MS'!G34 -> 10800 | M34: ='SO MS'!H34 -> 0 | N34: ='SO MS'!I34 -> 3587.0968 | O34: ='SO MS'!J34 -> 0 | P34: ='SO MS'!K34 -> 13500 | Q34: ='SO MS'!L34 -> 0 | R34: =SUM(J34:Q34) -> 216713.1
B35: Sub Total | D35: =SUM(D28:D34) -> 338909.13 | E35: =SUM(E28:E34) -> 329038.41 | F35: =SUM(F28:F34) -> 982872.87 | G35: =SUM(G28:G34) -> 85470.712 | H35: =SUM(H28:H34) -> 119609.68 | I35: =SUM(I28:I34) -> 1187953.3 | J35: =SUM(J28:J34) -> 999782 | K35: =SUM(K28:K34) -> 322000 | ... R35: =SUM(R28:R34) -> 1516991.7
B37: =B34+1 -> 46258 | C37: =TEXT(B37,"ddd") -> Sen | D37: =(J37+K37)-F37 -> 15409.88 | E37: =R37-I37 -> 13518.963 | F37: =SUM('SO Agustus 2026 Rev.3'!E37:AS37) -> 173416.12 | G37: =SUM('SO Agustus 2026 Rev.3'!AV37:BB37) -> 12690.916 | H37: =SUM('SO Agustus 2026 Rev.3'!BC37:BE37) -> 17087.097 | I37: =SUM(F37:H37) -> 203194.13 | J37: ='SO MS'!E37 -> 142826 | K37: ='SO MS'!F37 -> 46000 | L37: ='SO MS'!G37 -> 10800 | M37: ='SO MS'!H37 -> 0 | N37: ='SO MS'!I37 -> 3587.0968 | O37: ='SO MS'!J37 -> 0 | P37: ='SO MS'!K37 -> 13500 | Q37: ='SO MS'!L37 -> 0 | R37: =SUM(J37:Q37) -> 216713.1
B38: =B37+1 -> 46259 | C38: =TEXT(B38,"ddd") -> Sel | D38: =(J38+K38)-F38 -> 31409.88 | E38: =R38-I38 -> 29518.963 | F38: =SUM('SO Agustus 2026 Rev.3'!E38:AS38) -> 157416.12 | G38: =SUM('SO Agustus 2026 Rev.3'!AV38:BB38) -> 12690.916 | H38: =SUM('SO Agustus 2026 Rev.3'!BC38:BE38) -> 17087.097 | I38: =SUM(F38:H38) -> 187194.13 | J38: ='SO MS'!E38 -> 142826 | K38: ='SO MS'!F38 -> 46000 | L38: ='SO MS'!G38 -> 10800 | M38: ='SO MS'!H38 -> 0 | N38: ='SO MS'!I38 -> 3587.0968 | O38: ='SO MS'!J38 -> 0 | P38: ='SO MS'!K38 -> 13500 | Q38: ='SO MS'!L38 -> 0 | R38: =SUM(J38:Q38) -> 216713.1
B39: =B38+1 -> 46260 | C39: =TEXT(B39,"ddd") -> Rab | D39: =(J39+K39)-F39 -> 15409.88 | E39: =R39-I39 -> 13518.963 | F39: =SUM('SO Agustus 2026 Rev.3'!E39:AS39) -> 173416.12 | G39: =SUM('SO Agustus 2026 Rev.3'!AV39:BB39) -> 12690.916 | H39: =SUM('SO Agustus 2026 Rev.3'!BC39:BE39) -> 17087.097 | I39: =SUM(F39:H39) -> 203194.13 | J39: ='SO MS'!E39 -> 142826 | K39: ='SO MS'!F39 -> 46000 | L39: ='SO MS'!G39 -> 10800 | M39: ='SO MS'!H39 -> 0 | N39: ='SO MS'!I39 -> 3587.0968 | O39: ='SO MS'!J39 -> 0 | P39: ='SO MS'!K39 -> 13500 | Q39: ='SO MS'!L39 -> 0 | R39: =SUM(J39:Q39) -> 216713.1
A40: =WEEKNUM(B40) -> 35 | B40: =B39+1 -> 46261 | C40: =TEXT(B40,"ddd") -> Kam | D40: =(J40+K40)-F40 -> 15409.88 | E40: =R40-I40 -> 13518.963 | F40: =SUM('SO Agustus 2026 Rev.3'!E40:AS40) -> 173416.12 | G40: =SUM('SO Agustus 2026 Rev.3'!AV40:BB40) -> 12690.916 | H40: =SUM('SO Agustus 2026 Rev.3'!BC40:BE40) -> 17087.097 | I40: =SUM(F40:H40) -> 203194.13 | J40: ='SO MS'!E40 -> 142826 | K40: ='SO MS'!F40 -> 46000 | L40: ='SO MS'!G40 -> 10800 | M40: ='SO MS'!H40 -> 0 | N40: ='SO MS'!I40 -> 3587.0968 | O40: ='SO MS'!J40 -> 0 | P40: ='SO MS'!K40 -> 13500 | Q40: ='SO MS'!L40 -> 0 | R40: =SUM(J40:Q40) -> 216713.1
B41: =B40+1 -> 46262 | C41: =TEXT(B41,"ddd") -> Jum | D41: =(J41+K41)-F41 -> 15409.88 | E41: =R41-I41 -> 13518.963 | F41: =SUM('SO Agustus 2026 Rev.3'!E41:AS41) -> 173416.12 | G41: =SUM('SO Agustus 2026 Rev.3'!AV41:BB41) -> 12690.916 | H41: =SUM('SO Agustus 2026 Rev.3'!BC41:BE41) -> 17087.097 | I41: =SUM(F41:H41) -> 203194.13 | J41: ='SO MS'!E41 -> 142826 | K41: ='SO MS'!F41 -> 46000 | L41: ='SO MS'!G41 -> 10800 | M41: ='SO MS'!H41 -> 0 | N41: ='SO MS'!I41 -> 3587.0968 | O41: ='SO MS'!J41 -> 0 | P41: ='SO MS'!K41 -> 13500 | Q41: ='SO MS'!L41 -> 0 | R41: =SUM(J41:Q41) -> 216713.1
B42: =B41+1 -> 46263 | C42: =TEXT(B42,"ddd") -> Sab | D42: =(J42+K42)-F42 -> 36209.51 | E42: =R42-I42 -> 35440.494 | F42: =SUM('SO Agustus 2026 Rev.3'!E42:AS42) -> 152616.49 | G42: =SUM('SO Agustus 2026 Rev.3'!AV42:BB42) -> 11569.016 | H42: =SUM('SO Agustus 2026 Rev.3'!BC42:BE42) -> 17087.097 | I42: =SUM(F42:H42) -> 181272.6 | J42: ='SO MS'!E42 -> 142826 | K42: ='SO MS'!F42 -> 46000 | L42: ='SO MS'!G42 -> 10800 | M42: ='SO MS'!H42 -> 0 | N42: ='SO MS'!I42 -> 3587.0968 | O42: ='SO MS'!J42 -> 0 | P42: ='SO MS'!K42 -> 13500 | Q42: ='SO MS'!L42 -> 0 | R42: =SUM(J42:Q42) -> 216713.1
B43: =B42+1 -> 46264 | C43: =TEXT(B43,"ddd") -> Mgg | D43: =(J43+K43)-F43 -> 68200.587 | E43: =R43-I43 -> 67431.571 | F43: =SUM('SO Agustus 2026 Rev.3'!E43:AS43) -> 120625.41 | G43: =SUM('SO Agustus 2026 Rev.3'!AV43:BB43) -> 11569.016 | H43: =SUM('SO Agustus 2026 Rev.3'!BC43:BE43) -> 17087.097 | I43: =SUM(F43:H43) -> 149281.53 | J43: ='SO MS'!E43 -> 142826 | K43: ='SO MS'!F43 -> 46000 | L43: ='SO MS'!G43 -> 10800 | M43: ='SO MS'!H43 -> 0 | N43: ='SO MS'!I43 -> 3587.0968 | O43: ='SO MS'!J43 -> 0 | P43: ='SO MS'!K43 -> 13500 | Q43: ='SO MS'!L43 -> 0 | R43: =SUM(J43:Q43) -> 216713.1
B44: Sub Total | D44: =SUM(D37:D43) -> 197459.5 | E44: =SUM(E37:E43) -> 186466.88 | F44: =SUM(F37:F43) -> 1124322.5 | G44: =SUM(G37:G43) -> 86592.613 | H44: =SUM(H37:H43) -> 119609.68 | I44: =SUM(I37:I43) -> 1330524.8 | J44: =SUM(J37:J43) -> 999782 | K44: =SUM(K37:K43) -> 322000 | ... R44: =SUM(R37:R43) -> 1516991.7
B46: =B43+1 -> 46265 | C46: =TEXT(B46,"ddd") -> Sen | D46: =(J46+K46)-F46 -> 22409.88 | E46: =R46-I46 -> 20518.963 | F46: =SUM('SO Agustus 2026 Rev.3'!E46:AS46) -> 166416.12 | G46: =SUM('SO Agustus 2026 Rev.3'!AV46:BB46) -> 12690.916 | H46: =SUM('SO Agustus 2026 Rev.3'!BC46:BE46) -> 17087.097 | I46: =SUM(F46:H46) -> 196194.13 | J46: ='SO MS'!E37 -> 142826 | K46: ='SO MS'!F46 -> 46000 | L46: ='SO MS'!G46 -> 10800 | M46: ='SO MS'!H46 -> 0 | N46: ='SO MS'!I46 -> 3587.0968 | O46: ='SO MS'!J46 -> 0 | P46: ='SO MS'!K46 -> 13500 | Q46: ='SO MS'!L46 -> 0 | R46: =SUM(J46:Q46) -> 216713.1
D47: =SUM(D45:D46) -> 22409.88 | E47: =SUM(E45:E46) -> 20518.963 | F47: =SUM(F45:F46) -> 166416.12 | G47: =SUM(G45:G46) -> 12690.916 | H47: =SUM(H45:H46) -> 17087.097 | I47: =SUM(I45:I46) -> 196194.13 | J47: =SUM(J45:J46) -> 142826 | K47: =SUM(K45:K46) -> 46000 | ... R47: =SUM(R45:R46) -> 216713.1
...

Sheet SO MS
A1: SALES ORDER GAS
A4: ='SO FOB Agustus 2026'!A4 -> 46235
