Workbook
Name ___xlnm._FilterDatabase_2: #REF!
Name ___xlnm._FilterDatabase_2: #REF!
Name ___xlnm._FilterDatabase_2: #REF!
Name ___xlnm._FilterDatabase_2: #REF!
Name ___xlnm._FilterDatabase_2: #REF!
Name ___xlnm._FilterDatabase_2: #REF!
Name ___xlnm._FilterDatabase_2: #REF!
Name ___xlnm._FilterDatabase_2: #REF!
Name ___xlnm._FilterDatabase_2: #REF!
Name ___xlnm._FilterDatabase_2: #REF!
Name ___xlnm._FilterDatabase_2: #REF!
Name ___xlnm._FilterDatabase_2: #REF!
Name ___xlnm._FilterDatabase_2: #REF!
Name ___xlnm._FilterDatabase_2: #REF!
Name ___xlnm._FilterDatabase_2: #REF!
Name ___xlnm._FilterDatabase_2: #REF!
Name ___xlnm._FilterDatabase_2: #REF!
Name __xlnm._FilterDatabase_2: #REF!
Name __xlnm._FilterDatabase_2: #REF!
Name __xlnm._FilterDatabase_2: #REF!
Name __xlnm._FilterDatabase_2: #REF!
Name __xlnm._FilterDatabase_2: #REF!
Name __xlnm._FilterDatabase_2: #REF!
Name __xlnm._FilterDatabase_2: #REF!
Name __xlnm._FilterDatabase_2: #REF!
Name __xlnm._FilterDatabase_2: #REF!
Name __xlnm._FilterDatabase_2: #REF!
Name __xlnm._FilterDatabase_2: #REF!
Name __xlnm._FilterDatabase_2: #REF!
Name __xlnm._FilterDatabase_2: #REF!
Name __xlnm._FilterDatabase_2: #REF!
Name __xlnm._FilterDatabase_2: #REF!
Name __xlnm._FilterDatabase_2: #REF!
Name __xlnm._FilterDatabase_2: #REF!
Name _TES46: #N/A
Name AAAA: #N/A
Name ati: #N/A
Name BS: #N/A
Name CCC: #N/A
Name depr9200: #N/A
Name dfsfd: #N/A
Name Excel_BuiltIn__FilterDatabase_1: #REF!
Name Excel_BuiltIn__FilterDatabase_1: #REF!
Name Excel_BuiltIn__FilterDatabase_1: #REF!
Name Excel_BuiltIn__FilterDatabase_1: #REF!
Name Excel_BuiltIn__FilterDatabase_1: #REF!
Name Excel_BuiltIn__FilterDatabase_1: #REF!
Name Excel_BuiltIn__FilterDatabase_1: #REF!
Name Excel_BuiltIn__FilterDatabase_1: #REF!
Name Excel_BuiltIn__FilterDatabase_1: #REF!
Name Excel_BuiltIn__FilterDatabase_1: #REF!
Name Excel_BuiltIn__FilterDatabase_1: #REF!
Name Excel_BuiltIn__FilterDatabase_1: #REF!
Name Excel_BuiltIn__FilterDatabase_1: #REF!
Name Excel_BuiltIn__FilterDatabase_1: #REF!
Name Excel_BuiltIn__FilterDatabase_1: #REF!
Name Excel_BuiltIn__FilterDatabase_1: #REF!
Name Excel_BuiltIn__FilterDatabase_1: #REF!
Name Excel_BuiltIn_Print_Titles: NA()
Name Export_3: #REF!

Sheet SO FOB Agustus 2026
A2: SALES ORDER
A4: 46235
A6: Week | B6: DATE | D6: TOTAL | E6: FOB SETU-AAE | F6: FOB SETU- SIDO | G6: FOB SETU - GIG | H6: FOB SETU - SALMAH | I6: FOB SETU - NNE | J6: FOB SETU - GAS | K6: FOB SETU -SBE | L6: FOB SETU -DAMASINDO | M6: FOB SETU-LARAS | N6: FOB SETU-KIRANA | O6: FOB KHT-APE | P6: FOB KHT - JPEN | Q6: FOB KHT - Laras | R6: FOB KHT - ANAGATA
A7: =WEEKNUM(B7) -> 31 | B7: =A4 -> 46235 | C7: Sun | D7: =SUM(E7:R7) -> 0 | E7: 0 | F7: 0 | G7: 0 | H7: 0 | I7: 0 | J7: 0 | K7: 0 | L7: 0 | M7: 0 | N7: 0 | O7: 0 | P7: 0 | Q7: 0 | R7: 0
B8: Sub Total | D8: =SUM(D4:D7) -> 0 | E8: =SUM(E4:E7) -> 0 | F8: =SUM(F4:F7) -> 0 | G8: =SUM(G4:G7) -> 0 | H8: =SUM(H4:H7) -> 0 | I8: =SUM(I4:I7) -> 0 | J8: =SUM(J4:J7) -> 0 | K8: =SUM(K4:K7) -> 0 | ... R8: =SUM(R4:R7) -> 0
A10: =WEEKNUM(B10) -> 32 | B10: =B7+1 -> 46236 | C10: Mon | D10: =SUM(E10:R10) -> 0 | E10: 0 | F10: 0 | G10: 0 | H10: 0 | I10: 0 | J10: 0 | K10: 0 | L10: 0 | M10: 0 | N10: 0 | O10: 0 | P10: 0 | Q10: 0 | R10: 0
B11: =B10+1 -> 46237 | C11: Tue | D11: =SUM(E11:R11) -> 0 | E11: 0 | F11: 0 | G11: 0 | H11: 0 | I11: 0 | J11: 0 | K11: 0 | L11: 0 | M11: 0 | N11: 0 | O11: 0 | P11: 0 | Q11: 0 | R11: 0
B12: =B11+1 -> 46238 | C12: Wed | D12: =SUM(E12:R12) -> 0 | E12: 0 | F12: 0 | G12: 0 | H12: 0 | I12: 0 | J12: 0 | K12: 0 | L12: 0 | M12: 0 | N12: 0 | O12: 0 | P12: 0 | Q12: 0 | R12: 0
B13: =B12+1 -> 46239 | C13: Thu | D13: =SUM(E13:R13) -> 0 | E13: 0 | F13: 0 | G13: 0 | H13: 0 | I13: 0 | J13: 0 | K13: 0 | L13: 0 | M13: 0 | N13: 0 | O13: 0 | P13: 0 | Q13: 0 | R13: 0
B14: =B13+1 -> 46240 | C14: Fri | D14: =SUM(E14:R14) -> 0 | E14: 0 | F14: 0 | G14: 0 | H14: 0 | I14: 0 | J14: 0 | K14: 0 | L14: 0 | M14: 0 | N14: 0 | O14: 0 | P14: 0 | Q14: 0 | R14: 0
B15: =B14+1 -> 46241 | C15: Sat | D15: =SUM(E15:R15) -> 0 | E15: 0 | F15: 0 | G15: 0 | H15: 0 | I15: 0 | J15: 0 | K15: 0 | L15: 0 | M15: 0 | N15: 0 | O15: 0 | P15: 0 | Q15: 0 | R15: 0
B16: =B15+1 -> 46242 | C16: Sun | D16: =SUM(E16:R16) -> 0 | E16: 0 | F16: 0 | G16: 0 | H16: 0 | I16: 0 | J16: 0 | K16: 0 | L16: 0 | M16: 0 | N16: 0 | O16: 0 | P16: 0 | Q16: 0 | R16: 0
B17: Sub Total | D17: =SUM(D10:D16) -> 0 | E17: =SUM(E10:E16) -> 0 | F17: =SUM(F10:F16) -> 0 | G17: =SUM(G10:G16) -> 0 | H17: =SUM(H10:H16) -> 0 | I17: =SUM(I10:I16) -> 0 | J17: =SUM(J10:J16) -> 0 | K17: =SUM(K10:K16) -> 0 | ... R17: =SUM(R10:R16) -> 0
A19: =WEEKNUM(B24) -> 33 | B19: =B16+1 -> 46243 | C19: Mon | D19: =SUM(E19:R19) -> 0 | E19: 0 | F19: 0 | G19: 0 | H19: 0 | I19: 0 | J19: 0 | K19: 0 | L19: 0 | M19: 0 | N19: 0 | O19: 0 | P19: 0 | Q19: 0 | R19: 0
B20: =B19+1 -> 46244 | C20: Tue | D20: =SUM(E20:R20) -> 0 | E20: 0 | F20: 0 | G20: 0 | H20: 0 | I20: 0 | J20: 0 | K20: 0 | L20: 0 | M20: 0 | N20: 0 | O20: 0 | P20: 0 | Q20: 0 | R20: 0
B21: =B20+1 -> 46245 | C21: Wed | D21: =SUM(E21:R21) -> 0 | E21: 0 | F21: 0 | G21: 0 | H21: 0 | I21: 0 | J21: 0 | K21: 0 | L21: 0 | M21: 0 | N21: 0 | O21: 0 | P21: 0 | Q21: 0 | R21: 0
B22: =B21+1 -> 46246 | C22: Thu | D22: =SUM(E22:R22) -> 0 | E22: 0 | F22: 0 | G22: 0 | H22: 0 | I22: 0 | J22: 0 | K22: 0 | L22: 0 | M22: 0 | N22: 0 | O22: 0 | P22: 0 | Q22: 0 | R22: 0
B23: =B22+1 -> 46247 | C23: Fri | D23: =SUM(E23:R23) -> 0 | E23: 0 | F23: 0 | G23: 0 | H23: 0 | I23: 0 | J23: 0 | K23: 0 | L23: 0 | M23: 0 | N23: 0 | O23: 0 | P23: 0 | Q23: 0 | R23: 0
B24: =B23+1 -> 46248 | C24: Sat | D24: =SUM(E24:R24) -> 0 | E24: 0 | F24: 0 | G24: 0 | H24: 0 | I24: 0 | J24: 0 | K24: 0 | L24: 0 | M24: 0 | N24: 0 | O24: 0 | P24: 0 | Q24: 0 | R24: 0
B25: =B24+1 -> 46249 | C25: Sun | D25: =SUM(E25:R25) -> 0 | E25: 0 | F25: 0 | G25: 0 | H25: 0 | I25: 0 | J25: 0 | K25: 0 | L25: 0 | M25: 0 | N25: 0 | O25: 0 | P25: 0 | Q25: 0 | R25: 0
B26: Sub Total | D26: =SUM(D19:D25) -> 0 | E26: =SUM(E19:E25) -> 0 | F26: =SUM(F19:F25) -> 0 | G26: =SUM(G19:G25) -> 0 | H26: =SUM(H19:H25) -> 0 | I26: =SUM(I19:I25) -> 0 | J26: =SUM(J19:J25) -> 0 | K26: =SUM(K19:K25) -> 0 | ... R26: =SUM(R19:R25) -> 0
A28: =WEEKNUM(B33) -> 34 | B28: =B25+1 -> 46250 | C28: Mon | D28: =SUM(E28:R28) -> 0 | E28: 0 | F28: 0 | G28: 0 | H28: 0 | I28: 0 | J28: 0 | K28: 0 | L28: 0 | M28: 0 | N28: 0 | O28: 0 | P28: 0 | Q28: 0 | R28: 0
B29: =B28+1 -> 46251 | C29: Tue | D29: =SUM(E29:R29) -> 0 | E29: 0 | F29: 0 | G29: 0 | H29: 0 | I29: 0 | J29: 0 | K29: 0 | L29: 0 | M29: 0 | N29: 0 | O29: 0 | P29: 0 | Q29: 0 | R29: 0
B30: =B29+1 -> 46252 | C30: Wed | D30: =SUM(E30:R30) -> 0 | E30: 0 | F30: 0 | G30: 0 | H30: 0 | I30: 0 | J30: 0 | K30: 0 | L30: 0 | M30: 0 | N30: 0 | O30: 0 | P30: 0 | Q30: 0 | R30: 0
B31: =B30+1 -> 46253 | C31: Thu | D31: =SUM(E31:R31) -> 0 | E31: 0 | F31: 0 | G31: 0 | H31: 0 | I31: 0 | J31: 0 | K31: 0 | L31: 0 | M31: 0 | N31: 0 | O31: 0 | P31: 0 | Q31: 0 | R31: 0
B32: =B31+1 -> 46254 | C32: Fri | D32: =SUM(E32:R32) -> 0 | E32: 0 | F32: 0 | G32: 0 | H32: 0 | I32: 0 | J32: 0 | K32: 0 | L32: 0 | M32: 0 | N32: 0 | O32: 0 | P32: 0 | Q32: 0 | R32: 0
B33: =B32+1 -> 46255 | C33: Sat | D33: =SUM(E33:R33) -> 0 | E33: 0 | F33: 0 | G33: 0 | H33: 0 | I33: 0 | J33: 0 | K33: 0 | L33: 0 | M33: 0 | N33: 0 | O33: 0 | P33: 0 | Q33: 0 | R33: 0
B34: =B33+1 -> 46256 | C34: Sun | D34: =SUM(E34:R34) -> 0 | E34: 0 | F34: 0 | G34: 0 | H34: 0 | I34: 0 | J34: 0 | K34: 0 | L34: 0 | M34: 0 | N34: 0 | O34: 0 | P34: 0 | Q34: 0 | R34: 0
B35: Sub Total | D35: =SUM(D28:D34) -> 0 | E35: =SUM(E28:E34) -> 0 | F35: =SUM(F28:F34) -> 0 | G35: =SUM(G28:G34) -> 0 | H35: =SUM(H28:H34) -> 0 | I35: =SUM(I28:I34) -> 0 | J35: =SUM(J28:J34) -> 0 | K35: =SUM(K28:K34) -> 0 | ... R35: =SUM(R28:R34) -> 0
A37: =WEEKNUM(B42) -> 35 | B37: =B34+1 -> 46257 | C37: Mon | D37: =SUM(E37:R37) -> 0 | E37: 0 | F37: 0 | G37: 0 | H37: 0 | I37: 0 | J37: 0 | K37: 0 | L37: 0 | M37: 0 | N37: 0 | O37: 0 | P37: 0 | Q37: 0 | R37: 0
B38: =B37+1 -> 46258 | C38: Tue | D38: =SUM(E38:R38) -> 0 | E38: 0 | F38: 0 | G38: 0 | H38: 0 | I38: 0 | J38: 0 | K38: 0 | L38: 0 | M38: 0 | N38: 0 | O38: 0 | P38: 0 | Q38: 0 | R38: 0
B39: =B38+1 -> 46259 | C39: Wed | D39: =SUM(E39:R39) -> 0 | E39: 0 | F39: 0 | G39: 0 | H39: 0 | I39: 0 | J39: 0 | K39: 0 | L39: 0 | M39: 0 | N39: 0 | O39: 0 | P39: 0 | Q39: 0 | R39: 0
B40: =B39+1 -> 46260 | C40: Thu | D40: =SUM(E40:R40) -> 0 | E40: 0 | F40: 0 | G40: 0 | H40: 0 | I40: 0 | J40: 0 | K40: 0 | L40: 0 | M40: 0 | N40: 0 | O40: 0 | P40: 0 | Q40: 0 | R40: 0
B41: =B40+1 -> 46261 | C41: Fri | D41: =SUM(E41:R41) -> 0 | E41: 0 | F41: 0 | G41: 0 | H41: 0 | I41: 0 | J41: 0 | K41: 0 | L41: 0 | M41: 0 | N41: 0 | O41: 0 | P41: 0 | Q41: 0 | R41: 0
B42: =B41+1 -> 46262 | C42: Sat | D42: =SUM(E42:R42) -> 0 | E42: 0 | F42: 0 | G42: 0 | H42: 0 | I42: 0 | J42: 0 | K42: 0 | L42: 0 | M42: 0 | N42: 0 | O42: 0 | P42: 0 | Q42: 0 | R42: 0
B43: =B42+1 -> 46263 | C43: Sun | D43: =SUM(E43:R43) -> 0 | E43: 0 | F43: 0 | G43: 0 | H43: 0 | I43: 0 | J43: 0 | K43: 0 | L43: 0 | M43: 0 | N43: 0 | O43: 0 | P43: 0 | Q43: 0 | R43: 0
B44: Sub Total | D44: =SUM(D37:D43) -> 0 | E44: =SUM(E37:E43) -> 0 | F44: =SUM(F37:F43) -> 0 | G44: =SUM(G37:G43) -> 0 | H44: =SUM(H37:H43) -> 0 | I44: =SUM(I37:I43) -> 0 | J44: =SUM(J37:J43) -> 0 | K44: =SUM(K37:K43) -> 0 | ... R44: =SUM(R37:R43) -> 0
A46: =WEEKNUM(B46) -> 36 | B46: =B43+1 -> 46264 | C46: Mon | D46: =SUM(E46:R46) -> 0 | E46: 0 | F46: 0 | G46: 0 | H46: 0 | I46: 0 | J46: 0 | K46: 0 | L46: 0 | M46: 0 | N46: 0 | O46: 0 | P46: 0 | Q46: 0 | R46: 0
B47: =B46+1 -> 46265 | C47: Tue | D47: =SUM(E47:R47) -> 0 | E47: 0 | F47: 0 | G47: 0 | H47: 0 | I47: 0 | J47: 0 | K47: 0 | L47: 0 | M47: 0 | N47: 0 | O47: 0 | P47: 0 | Q47: 0 | R47: 0
B48: Sub Total | D48: =SUM(D41:D47) -> 0 | E48: =SUM(E41:E47) -> 0 | F48: =SUM(F41:F47) -> 0 | G48: =SUM(G41:G47) -> 0 | H48: =SUM(H41:H47) -> 0 | I48: =SUM(I41:I47) -> 0 | J48: =SUM(J41:J47) -> 0 | K48: =SUM(K41:K47) -> 0 | ... R48: =SUM(R41:R47) -> 0
...

Sheet SO September 2026 Rev.6
A2: SALES ORDER | E2: =E6/24 -> 49.982204 | F2: =F6/24 -> 50 | G2: =G6/24 -> 137.5 | H2: =H6/24 -> 33.333333 | I2: =I6/24 -> 6.25 | J2: =J6/24 -> 25.156801 | K2: =K6/24 -> 28.053145 | L2: =L6/24 -> 229.16667 | ... O2: =O6/24 -> 666.66667 | P2: =P38/24 -> 450 | Q2: =Q6/24 -> 791.66667 | R2: =R6/24 -> 208.33333 | S2: =S6/24 -> 291.66667 | T2: =T6/24 -> 270.83333 | U2: =U6/24 -> 20.833333 | V2: =V6/24 -> 270.83333 | W2: =W6/24 -> 41.666667 | X2: =X6/24 -> 83.333333 | ... BE2: =BE6/24 -> 1125
A3: 46266
V4: =V6/24 -> 270.83333
A5: Week | B5: DATE | D5: TOTAL | E5: CLIN | F5: MKG | G5: STM | H5: OAJ | I5: SHB | J5: GTL | K5: TWK | L5: BYC | M5: GF RANCA | N5: SMA | O5: UMI | P5: HLI | Q5: ASAHIMAS | R5: DIC | S5: HCI | T5: KSN | U5: ADP | V5: KSN RANCA | W5: NNI | X5: Greenpulse | Y5: Concord | Z5: ALT (KSO MASAMI) | AA5: IDP (KSO AAE) | AB5: WINGLOK (KSO EBM) | AC5: CISF (KSO RRS) | AD5: KGM (KSO RRS) | AE5: PUJ - LUBRICANT | AF5: CALBEE (KSO BMI) | AG5: KF | AH5: IP | AI5: BEM | AJ5: AMI | AK5: KA | AL5: KTN | AM5: NIAGA GARAM | AN5: PCI 84 | AO5: PCI MENGGER | AP5: INDOFOOD | AQ5: CERES | AR5: ABC KOGEN | AS5: TONGJI ( KSO GAS) | AT5: CITYMALL GARUT | AU5: PERHUTANI (KSO PTGN) | AV5: PA | AW5: RB | AX5: GF ATOM | AY5: GF KULIT | AZ5: SDM | BA5: JARGAS | BB5: SBI | BC5: DJARUM | BD5: SP GLOBAL | BE5: PENTAWIRA (KSO REN)
A6: =WEEKNUM(B6) -> 36 | B6: =A3 -> 46266 | C6: =TEXT(B6,"ddd") -> Tue | D6: =SUM(E6:BE6) -> 224572.23 | E6: 1199.5729 | F6: 1200 | G6: 3300 | H6: 800 | I6: 150 | J6: 603.76323 | K6: 673.27548 | L6: 5500 | M6: 5000 | N6: 2500 | O6: 16000 | P6: =650*24 -> 15600 | Q6: 19000 | R6: 5000 | S6: 7000 | T6: 6500 | U6: 500 | V6: 6500 | W6: 1000 | X6: 2000 | Y6: 0 | Z6: 1000 | AA6: 5500 | AB6: 89.451613 | AC6: 3500 | AD6: 1300 | AE6: 3000 | AF6: 12000 | AG6: 3000 | AH6: 2000 | AI6: 800 | AJ6: 7200 | AK6: 2500 | AL6: 2000 | AM6: 1000 | AN6: 11000 | AO6: 2000 | AP6: 4000 | AQ6: 9000.0571 | AR6: 8000 | AS6: 3500 | AV6: 700 | AW6: 3500 | AX6: 2000 | AY6: 369.61071 | BA6: 2499.7026 | BB6: 2499.7026 | BC6: 3587.0968 | BD6: 0 | BE6: 27000
B7: =B6+1 -> 46267 | C7: =TEXT(B7,"ddd") -> Wed | D7: =SUM(E7:BE7) -> 225694.13 | E7: 1199.5729 | F7: 1200 | G7: 3300 | H7: 800 | I7: 150 | J7: 603.76323 | K7: 673.27548 | L7: 5500 | M7: 5000 | N7: 2500 | O7: 16000 | P7: 15600 | Q7: 19000 | R7: 5000 | S7: 7000 | T7: 6500 | U7: 500 | V7: 6500 | W7: 1000 | X7: 2000 | Y7: 0 | Z7: 1000 | AA7: 5500 | AB7: 89.451613 | AC7: 3500 | AD7: 1300 | AE7: 3000 | AF7: 12000 | AG7: 3000 | AH7: 2000 | AI7: 800 | AJ7: 7200 | AK7: 2500 | AL7: 2000 | AM7: 1000 | AN7: 11000 | AO7: 2000 | AP7: 4000 | AQ7: 9000.0571 | AR7: 8000 | AS7: 3500 | AT7: 0 | AU7: 0 | AV7: 700 | AW7: 3500 | AX7: 2000 | AY7: 369.61071 | AZ7: 1121.9003 | BA7: 2499.7026 | BB7: 2499.7026 | BC7: 3587.0968 | BD7: 0 | BE7: 27000
B8: =B7+1 -> 46268 | C8: =TEXT(B8,"ddd") -> Thu | D8: =SUM(E8:BE8) -> 202694.13 | E8: 1199.5729 | F8: 1200 | G8: 3300 | H8: 800 | I8: 150 | J8: 603.76323 | K8: 673.27548 | L8: 5500 | M8: 5000 | N8: 2500 | O8: 16000 | P8: 15600 | Q8: 19000 | R8: 5000 | S8: 7000 | T8: 6000 | U8: 500 | V8: 6500 | W8: 1000 | X8: 1000 | Y8: 0 | Z8: 1000 | AA8: 5500 | AB8: 89.451613 | AC8: 3500 | AD8: 1300 | AE8: 3000 | AF8: 12000 | AG8: 3000 | AH8: 2000 | AI8: 800 | AJ8: 7200 | AK8: 2500 | AL8: 2000 | AM8: 1000 | AN8: 11000 | AO8: 2000 | AP8: 4000 | AQ8: 9000.0571 | AR8: 8000 | AS8: 3500 | AT8: =SUM(AT6:AT7) -> 0 | AU8: =SUM(AU6:AU7) -> 0 | AV8: 700 | AW8: 0 | AX8: 2000 | AY8: 369.61071 | AZ8: 1121.9003 | BA8: 2499.7026 | BB8: 2499.7026 | BC8: 3587.0968 | BD8: 0 | BE8: =4500*2 -> 9000
B9: =B8+1 -> 46269 | C9: =TEXT(B9,"ddd") -> Fri | D9: =SUM(E9:BE9) -> 198694.08 | E9: 1199.5729 | F9: 1200 | G9: 3300 | H9: 800 | I9: 150 | J9: 603.76323 | K9: 673.27548 | L9: 5500 | M9: 5000 | N9: 2500 | O9: 16000 | P9: 15600 | Q9: 17000 | R9: 5000 | S9: 7000 | T9: 6000 | U9: 500 | V9: 6500 | W9: 1000 | X9: 1000 | Y9: 0 | Z9: 1000 | AA9: 5500 | AB9: 89.451613 | AC9: 3500 | AD9: 1300 | AE9: 3000 | AF9: 12000 | AG9: 3000 | AH9: 2000 | AI9: 800 | AJ9: 7200 | AK9: 2500 | AL9: 2000 | AM9: 1000 | AN9: 10000 | AO9: 2000 | AP9: 4000 | AQ9: 8000 | AR9: 8000 | AS9: 3500 | AV9: 700 | AW9: 0 | AX9: 2000 | AY9: 369.61071 | AZ9: 1121.9003 | BA9: 2499.7026 | BB9: 2499.7026 | BC9: 3587.0968 | BD9: 0 | BE9: 9000
B10: =B9+1 -> 46270 | C10: =TEXT(B10,"ddd") -> Sat | D10: =SUM(E10:BE10) -> 188572.6 | E10: 700 | F10: 1000 | G10: 3300 | H10: 500 | I10: 150 | J10: 603.76323 | K10: 673.27548 | L10: 4500 | M10: 2000 | N10: 1000 | O10: 16000 | P10: 15600 | Q10: 27000 | R10: 5000 | S10: 3500 | T10: 6000 | U10: 500 | V10: 6500 | W10: 1000 | X10: 1000 | Y10: 0 | Z10: 1000 | AA10: 5500 | AB10: 89.451613 | AC10: 3500 | AD10: 1300 | AE10: 0 | AF10: 12000 | AG10: 0 | AH10: 2000 | AI10: 800 | AJ10: 7200 | AK10: 0 | AL10: 2000 | AM10: 1000 | AN10: 10000 | AO10: 2000 | AP10: 5500 | AQ10: 6000 | AR10: 8000 | AS10: 3500 | AT10: 0 | AU10: 0 | AV10: 700 | AW10: 0 | AX10: 2000 | AY10: 369.61071 | AZ10: 0 | BA10: 2499.7026 | BB10: 2499.7026 | BC10: 3587.0968 | BD10: 0 | BE10: 9000
B11: =B10+1 -> 46271 | C11: =TEXT(B11,"ddd") -> Sun | D11: =SUM(E11:BE11) -> 157581.53 | E11: 700 | F11: 1000 | G11: 999.51613 | H11: 500 | I11: 0 | J11: 603.76323 | K11: 673.27548 | L11: 0 | M11: 2000 | N11: 300 | O11: 6659.5545 | P11: 15600 | Q11: 27000 | R11: 5000 | S11: 0 | T11: 6000 | U11: 500 | V11: 6500 | W11: 1000 | X11: 1000 | Y11: 0 | Z11: 0 | AA11: 2500 | AB11: 89.451613 | AC11: 1000 | AD11: 1300 | AE11: 0 | AF11: 12000 | AG11: 0 | AH11: 2000 | AI11: 0 | AJ11: 2999.8519 | AK11: 0 | AL11: 2000 | AM11: 0 | AN11: 10000 | AO11: 2000 | AP11: 5500 | AQ11: 5000 | AR11: 8000 | AS11: 3500 | AT11: 0 | AU11: 0 | AV11: 700 | AW11: 0 | AX11: 2000 | AY11: 369.61071 | AZ11: 0 | BA11: 2499.7026 | BB11: 2499.7026 | BC11: 3587.0968 | BD11: 3000 | BE11: 9000
B12: Sub Total | D12: =SUM(D6:D11) -> 1197808.7 | E12: =SUM(E6:E11) -> 6198.2916 | F12: =SUM(F6:F11) -> 6800 | G12: =SUM(G6:G11) -> 17499.516 | H12: =SUM(H6:H11) -> 4200 | I12: =SUM(I6:I11) -> 750 | J12: =SUM(J6:J11) -> 3622.5794 | K12: =SUM(K6:K11) -> 4039.6529 | ... AS12: =SUM(AS6:AS11) -> 21000 | AT12: =SUM(AT10:AT11) -> 0 | AU12: =SUM(AU10:AU11) -> 0 | AV12: =SUM(AV6:AV11) -> 4200 | AW12: =SUM(AW6:AW11) -> 7000 | AX12: =SUM(AX6:AX11) -> 12000 | AY12: =SUM(AY6:AY11) -> 2217.6643 | AZ12: =SUM(AZ6:AZ11) -> 3365.701 | BA12: =SUM(BA6:BA11) -> 14998.215 | BB12: =SUM(BB6:BB11) -> 14998.215 | BC12: =SUM(BC6:BC11) -> 21522.581 | ... BE12: =SUM(BE6:BE11) -> 90000
A14: =WEEKNUM(B19) -> 37 | B14: =B11+1 -> 46272 | C14: =TEXT(B14,"ddd") -> Mon | D14: =SUM(E14:BE14) -> 201994.08 | E14: 1199.5729 | F14: 1200 | G14: 3300 | H14: 800 | I14: 150 | J14: 603.76323 | K14: 673.27548 | L14: 5500 | M14: 5000 | N14: 2500 | O14: 16000 | P14: 15600 | Q14: 17000 | R14: 5000 | S14: 7000 | T14: 6000 | U14: 1300 | V14: 6500 | W14: 1000 | X14: 1000 | Y14: 0 | Z14: 1000 | AA14: 5500 | AB14: 89.451613 | AC14: 3500 | AD14: 1300 | AE14: 3000 | AF14: 12000 | AG14: 3000 | AH14: 2000 | AI14: 800 | AJ14: 7200 | AK14: 2000 | AL14: 2000 | AM14: 1000 | AN14: 10000 | AO14: 2000 | AP14: 4000 | AQ14: 8000 | AR14: 8000 | AS14: 3500 | AT14: 0 | AU14: 0 | AV14: 700 | AW14: 0 | AX14: 2000 | AY14: 369.61071 | AZ14: 1121.9003 | BA14: 2499.7026 | BB14: 2499.7026 | BC14: 3587.0968 | BD14: 3000 | BE14: 9000
B15: =B14+1 -> 46273 | C15: =TEXT(B15,"ddd") -> Tue | D15: =SUM(E15:BE15) -> 201994.08 | E15: 1199.5729 | F15: 1200 | G15: 3300 | H15: 800 | I15: 150 | J15: 603.76323 | K15: 673.27548 | L15: 5500 | M15: 5000 | N15: 2500 | O15: 16000 | P15: 15600 | Q15: 17000 | R15: 5000 | S15: 7000 | T15: 6000 | U15: 1300 | V15: 6500 | W15: 1000 | X15: 1000 | Y15: 0 | Z15: 1000 | AA15: 5500 | AB15: 89.451613 | AC15: 3500 | AD15: 1300 | AE15: 3000 | AF15: 12000 | AG15: 3000 | AH15: 2000 | AI15: 800 | AJ15: 7200 | AK15: 2000 | AL15: 2000 | AM15: 1000 | AN15: 10000 | AO15: 2000 | AP15: 4000 | AQ15: 8000 | AR15: 8000 | AS15: 3500 | AT15: 0 | AU15: 0 | AV15: 700 | AW15: 0 | AX15: 2000 | AY15: 369.61071 | AZ15: 1121.9003 | BA15: 2499.7026 | BB15: 2499.7026 | BC15: 3587.0968 | BD15: 3000 | BE15: 9000
B16: =B15+1 -> 46274 | C16: =TEXT(B16,"ddd") -> Wed | D16: =SUM(E16:BE16) -> 201994.08 | E16: 1199.5729 | F16: 1200 | G16: 3300 | H16: 800 | I16: 150 | J16: 603.76323 | K16: 673.27548 | L16: 5500 | M16: 5000 | N16: 2500 | O16: 16000 | P16: 15600 | Q16: 17000 | R16: 5000 | S16: 7000 | T16: 6000 | U16: 1300 | V16: 6500 | W16: 1000 | X16: 1000 | Y16: 0 | Z16: 1000 | AA16: 5500 | AB16: 89.451613 | AC16: 3500 | AD16: 1300 | AE16: 3000 | AF16: 12000 | AG16: 3000 | AH16: 2000 | AI16: 800 | AJ16: 7200 | AK16: 2000 | AL16: 2000 | AM16: 1000 | AN16: 10000 | AO16: 2000 | AP16: 4000 | AQ16: 8000 | AR16: 8000 | AS16: 3500 | AT16: 0 | AU16: 0 | AV16: 700 | AW16: 0 | AX16: 2000 | AY16: 369.61071 | AZ16: 1121.9003 | BA16: 2499.7026 | BB16: 2499.7026 | BC16: 3587.0968 | BD16: 3000 | BE16: 9000
B17: =B16+1 -> 46275 | C17: =TEXT(B17,"ddd") -> Thu | D17: =SUM(E17:BE17) -> 216994.08 | E17: 1199.5729 | F17: 1200 | G17: 3300 | H17: 800 | I17: 150 | J17: 603.76323 | K17: 673.27548 | L17: 5500 | M17: 5000 | N17: 2500 | O17: 16000 | P17: 15600 | Q17: 17000 | R17: 5000 | S17: 7000 | T17: 6000 | U17: 1300 | V17: 6500 | W17: 1000 | X17: 1000 | Y17: 0 | Z17: 1000 | AA17: 5500 | AB17: 89.451613 | AC17: 3500 | AD17: 1300 | AE17: 3000 | AF17: 12000 | AG17: 3000 | AH17: 2000 | AI17: 800 | AJ17: 7200 | AK17: 2000 | AL17: 2000 | AM17: 1000 | AN17: 10000 | AO17: 2000 | AP17: 4000 | AQ17: 8000 | AR17: 8000 | AS17: 3500 | AT17: =SUM(AT10:AT16) -> 0 | AU17: =SUM(AU10:AU16) -> 0 | AV17: 700 | AW17: 0 | AX17: 2000 | AY17: 369.61071 | AZ17: 1121.9003 | BA17: 2499.7026 | BB17: 2499.7026 | BC17: 3587.0968 | BD17: =4500*4 -> 18000 | BE17: 9000
B18: =B17+1 -> 46276 | C18: =TEXT(B18,"ddd") -> Fri | D18: =SUM(E18:BE18) -> 230494.08 | E18: 1199.5729 | F18: 1200 | G18: 3300 | H18: 800 | I18: 150 | J18: 603.76323 | K18: 673.27548 | L18: 5500 | M18: 5000 | N18: 2500 | O18: 16000 | P18: 15600 | Q18: 17000 | R18: 5000 | S18: 7000 | T18: 6000 | U18: 1300 | V18: 6500 | W18: 1000 | X18: 1000 | Y18: 0 | Z18: 1000 | AA18: 5500 | AB18: 89.451613 | AC18: 3500 | AD18: 1300 | AE18: 3000 | AF18: 12000 | AG18: 3000 | AH18: 2000 | AI18: 800 | AJ18: 7200 | AK18: 2000 | AL18: 2000 | AM18: 1000 | AN18: 10000 | AO18: 2000 | AP18: 4000 | AQ18: 8000 | AR18: 8000 | AS18: 3500 | AV18: 700 | AW18: 0 | AX18: 2000 | AY18: 369.61071 | AZ18: 1121.9003 | BA18: 2499.7026 | BB18: 2499.7026 | BC18: 3587.0968 | BD18: 31500 | BE18: 9000
B19: =B18+1 -> 46277 | C19: =TEXT(B19,"ddd") -> Sat | D19: =SUM(E19:BE19) -> 220872.6 | E19: 700 | F19: 1000 | G19: 3300 | H19: 500 | I19: 150 | J19: 603.76323 | K19: 673.27548 | L19: 4500 | M19: 2000 | N19: 1000 | O19: 16000 | P19: 15600 | Q19: 27000 | R19: 5000 | S19: 3500 | T19: 6000 | U19: 1300 | V19: 6500 | W19: 1000 | X19: 1000 | Y19: 0 | Z19: 1000 | AA19: 5500 | AB19: 89.451613 | AC19: 3500 | AD19: 1300 | AE19: 0 | AF19: 12000 | AG19: 0 | AH19: 2000 | AI19: 800 | AJ19: 7200 | AK19: 0 | AL19: 2000 | AM19: 1000 | AN19: 10000 | AO19: 2000 | AP19: 5500 | AQ19: 6000 | AR19: 8000 | AS19: 3500 | AT19: 0 | AU19: 0 | AV19: 700 | AW19: 0 | AX19: 2000 | AY19: 369.61071 | AZ19: 0 | BA19: 2499.7026 | BB19: 2499.7026 | BC19: 3587.0968 | BD19: 31500 | BE19: 9000
B20: =B19+1 -> 46278 | C20: =TEXT(B20,"ddd") -> Sun | D20: =SUM(E20:BE20) -> 184381.53 | E20: 700 | F20: 1000 | G20: 999.51613 | H20: 500 | I20: 0 | J20: 603.76323 | K20: 673.27548 | L20: 0 | M20: 2000 | N20: 300 | O20: 6659.5545 | P20: 15600 | Q20: 27000 | R20: 5000 | S20: 0 | T20: 6000 | U20: 1300 | V20: 6500 | W20: 0 | X20: 1000 | Y20: 0 | Z20: 0 | AA20: 2500 | AB20: 89.451613 | AC20: 1000 | AD20: 1300 | AE20: 0 | AF20: 12000 | AG20: 0 | AH20: 500 | AI20: 0 | AJ20: 2999.8519 | AK20: 0 | AL20: 2000 | AM20: 0 | AN20: 10000 | AO20: 2000 | AP20: 5500 | AQ20: 5000 | AR20: 8000 | AS20: 3500 | AT20: 0 | AU20: 0 | AV20: 700 | AW20: 0 | AX20: 2000 | AY20: 369.61071 | AZ20: 0 | BA20: 2499.7026 | BB20: 2499.7026 | BC20: 3587.0968 | BD20: 31500 | BE20: 9000
B21: Sub Total | D21: =SUM(D14:D20) -> 1458724.5 | E21: =SUM(E14:E20) -> 7397.8645 | F21: =SUM(F14:F20) -> 8000 | G21: =SUM(G14:G20) -> 20799.516 | H21: =SUM(H14:H20) -> 5000 | I21: =SUM(I14:I20) -> 900 | J21: =SUM(J14:J20) -> 4226.3426 | K21: =SUM(K14:K20) -> 4712.9284 | ... BE21: =SUM(BE14:BE20) -> 63000
A23: =WEEKNUM(B28) -> 38 | B23: =B20+1 -> 46279 | C23: =TEXT(B23,"ddd") -> Mon | D23: =SUM(E23:BE23) -> 231494.08 | E23: 1199.5729 | F23: 1200 | G23: 3300 | H23: 800 | I23: 150 | J23: 603.76323 | K23: 673.27548 | L23: 5500 | M23: 5000 | N23: 2500 | O23: 16000 | P23: 15600 | Q23: 17000 | R23: 5000 | S23: 7000 | T23: 6000 | U23: 1300 | V23: 6500 | W23: 1000 | X23: 2000 | Y23: 0 | Z23: 1000 | AA23: 5500 | AB23: 89.451613 | AC23: 3500 | AD23: 1300 | AE23: 3000 | AF23: 12000 | AG23: 3000 | AH23: 2000 | AI23: 800 | AJ23: 7200 | AK23: 2000 | AL23: 2000 | AM23: 1000 | AN23: 10000 | AO23: 2000 | AP23: 4000 | AQ23: 8000 | AR23: 8000 | AS23: 3500 | AT23: =SUM(AT16:AT22) -> 0 | AU23: =SUM(AU16:AU22) -> 0 | AV23: 700 | AW23: 0 | AX23: 2000 | AY23: 369.61071 | AZ23: 1121.9003 | BA23: 2499.7026 | BB23: 2499.7026 | BC23: 3587.0968 | BD23: 31500 | BE23: 9000
B24: =B23+1 -> 46280 | C24: =TEXT(B24,"ddd") -> Tue | D24: =SUM(E24:BE24) -> 231494.08 | E24: 1199.5729 | F24: 1200 | G24: 3300 | H24: 800 | I24: 150 | J24: 603.76323 | K24: 673.27548 | L24: 5500 | M24: 5000 | N24: 2500 | O24: 16000 | P24: 15600 | Q24: 17000 | R24: 5000 | S24: 7000 | T24: 6000 | U24: 1300 | V24: 6500 | W24: 1000 | X24: 2000 | Y24: 0 | Z24: 1000 | AA24: 5500 | AB24: 89.451613 | AC24: 3500 | AD24: 1300 | AE24: 3000 | AF24: 12000 | AG24: 3000 | AH24: 2000 | AI24: 800 | AJ24: 7200 | AK24: 2000 | AL24: 2000 | AM24: 1000 | AN24: 10000 | AO24: 2000 | AP24: 4000 | AQ24: 8000 | AR24: 8000 | AS24: 3500 | AV24: 700 | AW24: 0 | AX24: 2000 | AY24: 369.61071 | AZ24: 1121.9003 | BA24: 2499.7026 | BB24: 2499.7026 | BC24: 3587.0968 | BD24: 31500 | BE24: 9000
B25: =B24+1 -> 46281 | C25: =TEXT(B25,"ddd") -> Wed | D25: =SUM(E25:BE25) -> 210094.08 | E25: 1199.5729 | F25: 1200 | G25: 3300 | H25: 800 | I25: 150 | J25: 603.76323 | K25: 673.27548 | L25: 5500 | M25: 5000 | N25: 2500 | O25: 13500 | P25: 15600 | Q25: 12000 | R25: 5000 | S25: 7000 | T25: 4000 | U25: 1300 | V25: 6000 | W25: 1000 | X25: 1000 | Y25: 0 | Z25: 1000 | AA25: 5500 | AB25: 89.451613 | AC25: 3100 | AD25: 1300 | AE25: 3000 | AF25: 4000 | AG25: 2000 | AH25: 2000 | AI25: 800 | AJ25: 7200 | AK25: 2000 | AL25: 2000 | AM25: 1000 | AN25: 10000 | AO25: 2000 | AP25: 5500 | AQ25: 8000 | AR25: 6000 | AS25: 3000 | AT25: 0 | AU25: 0 | AV25: 700 | AW25: 0 | AX25: 2000 | AY25: 369.61071 | AZ25: 1121.9003 | BA25: 2499.7026 | BB25: 2499.7026 | BC25: 3587.0968 | BD25: 31500 | BE25: 9000
B26: =B25+1 -> 46282 | C26: =TEXT(B26,"ddd") -> Thu | D26: =SUM(E26:BE26) -> 210094.08 | E26: 1199.5729 | F26: 1200 | G26: 3300 | H26: 800 | I26: 150 | J26: 603.76323 | K26: 673.27548 | L26: 5500 | M26: 5000 | N26: 2500 | O26: 13500 | P26: 15600 | Q26: 12000 | R26: 5000 | S26: 7000 | T26: 4000 | U26: 1300 | V26: 6000 | W26: 1000 | X26: 1000 | Y26: 0 | Z26: 1000 | AA26: 5500 | AB26: 89.451613 | AC26: 3100 | AD26: 1300 | AE26: 3000 | AF26: 4000 | AG26: 2000 | AH26: 2000 | AI26: 800 | AJ26: 7200 | AK26: 2000 | AL26: 2000 | AM26: 1000 | AN26: 10000 | AO26: 2000 | AP26: 5500 | AQ26: 8000 | AR26: 6000 | AS26: 3000 | AT26: =SUM(AT19:AT25) -> 0 | AU26: =SUM(AU19:AU25) -> 0 | AV26: 700 | AW26: 0 | AX26: 2000 | AY26: 369.61071 | AZ26: 1121.9003 | BA26: 2499.7026 | BB26: 2499.7026 | BC26: 3587.0968 | BD26: 31500 | BE26: 9000
B27: =B26+1 -> 46283 | C27: =TEXT(B27,"ddd") -> Fri | D27: =SUM(E27:BE27) -> 210094.08 | E27: 1199.5729 | F27: 1200 | G27: 3300 | H27: 800 | I27: 150 | J27: 603.76323 | K27: 673.27548 | L27: 5500 | M27: 5000 | N27: 2500 | O27: 13500 | P27: 15600 | Q27: 12000 | R27: 5000 | S27: 7000 | T27: 4000 | U27: 1300 | V27: 6000 | W27: 1000 | X27: 1000 | Y27: 0 | Z27: 1000 | AA27: 5500 | AB27: 89.451613 | AC27: 3100 | AD27: 1300 | AE27: 3000 | AF27: 4000 | AG27: 2000 | AH27: 2000 | AI27: 800 | AJ27: 7200 | AK27: 2000 | AL27: 2000 | AM27: 1000 | AN27: 10000 | AO27: 2000 | AP27: 5500 | AQ27: 8000 | AR27: 6000 | AS27: 3000 | AV27: 700 | AW27: 0 | AX27: 2000 | AY27: 369.61071 | AZ27: 1121.9003 | BA27: 2499.7026 | BB27: 2499.7026 | BC27: 3587.0968 | BD27: 31500 | BE27: 9000
B28: =B27+1 -> 46284 | C28: =TEXT(B28,"ddd") -> Sat | D28: =SUM(E28:BE28) -> 207972.6 | E28: 700 | F28: 1000 | G28: 3300 | H28: 500 | I28: 150 | J28: 603.76323 | K28: 673.27548 | L28: 4500 | M28: 2000 | N28: 1000 | O28: 13500 | P28: 15600 | Q28: 30000 | R28: 5000 | S28: 3500 | T28: 4000 | U28: 1300 | V28: 6000 | W28: 1000 | X28: 1000 | Y28: 0 | Z28: 1000 | AA28: 5500 | AB28: 89.451613 | AC28: 3100 | AD28: 1300 | AE28: 0 | AF28: 4000 | AG28: 0 | AH28: 2000 | AI28: 800 | AJ28: 7200 | AK28: 0 | AL28: 2000 | AM28: 1000 | AN28: 10000 | AO28: 2000 | AP28: 5500 | AQ28: 6000 | AR28: 6000 | AS28: 3000 | AT28: 0 | AU28: 0 | AV28: 700 | AW28: 0 | AX28: 2000 | AY28: 369.61071 | AZ28: 0 | BA28: 2499.7026 | BB28: 2499.7026 | BC28: 3587.0968 | BD28: 31500 | BE28: 9000
B29: =B28+1 -> 46285 | C29: =TEXT(B29,"ddd") -> Sun | D29: =SUM(E29:BE29) -> 200381.53 | E29: 700 | F29: 1000 | G29: 999.51613 | H29: 500 | I29: 0 | J29: 603.76323 | K29: 673.27548 | L29: 0 | M29: 2000 | N29: 300 | O29: 6659.5545 | P29: 15600 | Q29: 45000 | R29: 5000 | S29: 0 | T29: 4000 | U29: 1300 | V29: 6000 | W29: 1000 | X29: 1000 | Y29: 10000 | Z29: 0 | AA29: 2500 | AB29: 89.451613 | AC29: 1000 | AD29: 1300 | AE29: 0 | AF29: 4000 | AG29: 0 | AH29: 500 | AI29: 0 | AJ29: 2999.8519 | AK29: 0 | AL29: 2000 | AM29: 0 | AN29: 10000 | AO29: 2000 | AP29: 5500 | AQ29: 5000 | AR29: 6000 | AS29: 3000 | AT29: 0 | AU29: 0 | AV29: 700 | AW29: 0 | AX29: 2000 | AY29: 369.61071 | AZ29: 0 | BA29: 2499.7026 | BB29: 2499.7026 | BC29: 3587.0968 | BD29: 31500 | BE29: 9000
B30: Sub Total | D30: =SUM(D23:D29) -> 1501624.5 | E30: =SUM(E23:E29) -> 7397.8645 | F30: =SUM(F23:F29) -> 8000 | G30: =SUM(G23:G29) -> 20799.516 | H30: =SUM(H23:H29) -> 5000 | I30: =SUM(I23:I29) -> 900 | J30: =SUM(J23:J29) -> 4226.3426 | K30: =SUM(K23:K29) -> 4712.9284 | ... BE30: =SUM(BE23:BE29) -> 63000
A32: =WEEKNUM(B37) -> 39 | B32: =B29+1 -> 46286 | C32: =TEXT(B32,"ddd") -> Mon | D32: =SUM(E32:BE32) -> 223594.08 | E32: 1199.5729 | F32: 1200 | G32: 3300 | H32: 800 | I32: 150 | J32: 603.76323 | K32: 673.27548 | L32: 5500 | M32: 5000 | N32: 2500 | O32: 13500 | P32: 15600 | Q32: 12000 | R32: 5000 | S32: 7000 | T32: 4000 | U32: 1300 | V32: 6000 | W32: 1000 | X32: 1000 | Y32: 10000 | Z32: 1000 | AA32: 5500 | AB32: 89.451613 | AC32: 3100 | AD32: 1300 | AE32: 3000 | AF32: 4000 | AG32: 2000 | AH32: 2000 | AI32: 800 | AJ32: 7200 | AK32: 2000 | AL32: 2000 | AM32: 1000 | AN32: 10000 | AO32: 2000 | AP32: 5500 | AQ32: 8000 | AR32: 6000 | AS32: 3000 | AT32: =SUM(AT25:AT31) -> 0 | AU32: =SUM(AU25:AU31) -> 0 | AV32: 700 | AW32: 3500 | AX32: 2000 | AY32: 369.61071 | AZ32: 1121.9003 | BA32: 2499.7026 | BB32: 2499.7026 | BC32: 3587.0968 | BD32: 31500 | BE32: 9000
B33: =B32+1 -> 46287 | C33: =TEXT(B33,"ddd") -> Tue | D33: =SUM(E33:BE33) -> 222794.08 | E33: 1199.5729 | F33: 1200 | G33: 3300 | H33: 800 | I33: 150 | J33: 603.76323 | K33: 673.27548 | L33: 5500 | M33: 5000 | N33: 1500 | O33: 13500 | P33: =450*24 -> 10800 | Q33: 12000 | R33: 5000 | S33: 12000 | T33: 4000 | U33: 1300 | V33: 6000 | W33: 1000 | X33: 7000 | Y33: 10000 | Z33: 1000 | AA33: 5500 | AB33: 89.451613 | AC33: 3100 | AD33: 1300 | AE33: 3000 | AF33: 0 | AG33: 2000 | AH33: 2000 | AI33: 800 | AJ33: 7200 | AK33: 2000 | AL33: 2000 | AM33: 1000 | AN33: 10000 | AO33: 2000 | AP33: 5500 | AQ33: 8000 | AR33: 4000 | AS33: 3000 | AV33: 700 | AW33: 3500 | AX33: 2000 | AY33: 369.61071 | AZ33: 1121.9003 | BA33: 2499.7026 | BB33: 2499.7026 | BC33: 3587.0968 | BD33: 31500 | BE33: 9000
B34: =B33+1 -> 46288 | C34: =TEXT(B34,"ddd") -> Wed | D34: =SUM(E34:BE34) -> 224794.08 | E34: 1199.5729 | F34: 1200 | G34: 3300 | H34: 800 | I34: 150 | J34: 603.76323 | K34: 673.27548 | L34: 5500 | M34: 5000 | N34: 1500 | O34: 13500 | P34: 10800 | Q34: 12000 | R34: 5000 | S34: 12000 | T34: 4000 | U34: 1300 | V34: 6000 | W34: 1000 | X34: 7000 | Y34: 12000 | Z34: 1000 | AA34: 5500 | AB34: 89.451613 | AC34: 3100 | AD34: 1300 | AE34: 3000 | AF34: 0 | AG34: 2000 | AH34: 2000 | AI34: 800 | AJ34: 7200 | AK34: 2000 | AL34: 2000 | AM34: 1000 | AN34: 10000 | AO34: 2000 | AP34: 5500 | AQ34: 8000 | AR34: 4000 | AS34: 3000 | AT34: 0 | AU34: 0 | AV34: 700 | AW34: 3500 | AX34: 2000 | AY34: 369.61071 | AZ34: 1121.9003 | BA34: 2499.7026 | BB34: 2499.7026 | BC34: 3587.0968 | BD34: 31500 | BE34: 9000
B35: =B34+1 -> 46289 | C35: =TEXT(B35,"ddd") -> Thu | D35: =SUM(E35:BE35) -> 223494.08 | E35: 1199.5729 | F35: 1200 | G35: 3300 | H35: 800 | I35: 150 | J35: 603.76323 | K35: 673.27548 | L35: 5500 | M35: 5000 | N35: 1500 | O35: 13500 | P35: 10800 | Q35: 12000 | R35: 5000 | S35: 12000 | T35: 4000 | U35: 1300 | V35: 6000 | W35: 1000 | X35: 7000 | Y35: 12000 | Z35: 1000 | AA35: 5500 | AB35: 89.451613 | AC35: 3100 | AD35: 0 | AE35: 3000 | AF35: 0 | AG35: 2000 | AH35: 2000 | AI35: 800 | AJ35: 7200 | AK35: 2000 | AL35: 2000 | AM35: 1000 | AN35: 10000 | AO35: 2000 | AP35: 5500 | AQ35: 8000 | AR35: 4000 | AS35: 3000 | AT35: =SUM(AT28:AT34) -> 0 | AU35: =SUM(AU28:AU34) -> 0 | AV35: 700 | AW35: 3500 | AX35: 2000 | AY35: 369.61071 | AZ35: 1121.9003 | BA35: 2499.7026 | BB35: 2499.7026 | BC35: 3587.0968 | BD35: 31500 | BE35: 9000
B36: =B35+1 -> 46290 | C36: =TEXT(B36,"ddd") -> Fri | D36: =SUM(E36:BE36) -> 223494.08 | E36: 1199.5729 | F36: 1200 | G36: 3300 | H36: 800 | I36: 150 | J36: 603.76323 | K36: 673.27548 | L36: 5500 | M36: 5000 | N36: 1500 | O36: 13500 | P36: 10800 | Q36: 12000 | R36: 5000 | S36: 12000 | T36: 4000 | U36: 1300 | V36: 6000 | W36: 1000 | X36: 7000 | Y36: 12000 | Z36: 1000 | AA36: 5500 | AB36: 89.451613 | AC36: 3100 | AD36: 0 | AE36: 3000 | AF36: 0 | AG36: 2000 | AH36: 2000 | AI36: 800 | AJ36: 7200 | AK36: 2000 | AL36: 2000 | AM36: 1000 | AN36: 10000 | AO36: 2000 | AP36: 5500 | AQ36: 8000 | AR36: 4000 | AS36: 3000 | AV36: 700 | AW36: 3500 | AX36: 2000 | AY36: 369.61071 | AZ36: 1121.9003 | BA36: 2499.7026 | BB36: 2499.7026 | BC36: 3587.0968 | BD36: 31500 | BE36: 9000
B37: =B36+1 -> 46291 | C37: =TEXT(B37,"ddd") -> Sat | D37: =SUM(E37:BE37) -> 225872.6 | E37: 700 | F37: 1000 | G37: 3300 | H37: 500 | I37: 150 | J37: 603.76323 | K37: 673.27548 | L37: 4500 | M37: 2000 | N37: 1000 | O37: 13500 | P37: 10800 | Q37: 30000 | R37: 5000 | S37: 12000 | T37: 4000 | U37: 1300 | V37: 6000 | W37: 1000 | X37: 7000 | Y37: 12000 | Z37: 1000 | AA37: 5500 | AB37: 89.451613 | AC37: 3100 | AD37: 0 | AE37: 0 | AF37: 0 | AG37: 0 | AH37: 2000 | AI37: 800 | AJ37: 7200 | AK37: 0 | AL37: 2000 | AM37: 1000 | AN37: 10000 | AO37: 2000 | AP37: 5500 | AQ37: 6000 | AR37: 4000 | AS37: 3000 | AT37: 0 | AU37: 0 | AV37: 700 | AW37: 3500 | AX37: 2000 | AY37: 369.61071 | AZ37: 0 | BA37: 2499.7026 | BB37: 2499.7026 | BC37: 3587.0968 | BD37: 31500 | BE37: 9000
B38: =B37+1 -> 46292 | C38: =TEXT(B38,"ddd") -> Sun | D38: =SUM(E38:BE38) -> 210781.53 | E38: 700 | F38: 1000 | G38: 999.51613 | H38: 500 | I38: 0 | J38: 603.76323 | K38: 673.27548 | L38: 0 | M38: 2000 | N38: 300 | O38: 6659.5545 | P38: 10800 | Q38: 45000 | R38: 5000 | S38: 12000 | T38: 4000 | U38: 1300 | V38: 6000 | W38: 0 | X38: 7000 | Y38: 12000 | Z38: 0 | AA38: 2500 | AB38: 89.451613 | AC38: 1000 | AD38: 0 | AE38: 0 | AF38: 0 | AG38: 0 | AH38: 500 | AI38: 0 | AJ38: 2999.8519 | AK38: 0 | AL38: 2000 | AM38: 0 | AN38: 10000 | AO38: 2000 | AP38: 5500 | AQ38: 5000 | AR38: 4000 | AS38: 3000 | AT38: =SUM(AT31:AT37) -> 0 | AU38: =SUM(AU31:AU37) -> 0 | AV38: 700 | AW38: 3500 | AX38: 2000 | AY38: 369.61071 | AZ38: 0 | BA38: 2499.7026 | BB38: 2499.7026 | BC38: 3587.0968 | BD38: 31500 | BE38: 9000
B39: Sub Total | D39: =SUM(D32:D38) -> 1554824.5 | E39: =SUM(E32:E38) -> 7397.8645 | F39: =SUM(F32:F38) -> 8000 | G39: =SUM(G32:G38) -> 20799.516 | H39: =SUM(H32:H38) -> 5000 | I39: =SUM(I32:I38) -> 900 | J39: =SUM(J32:J38) -> 4226.3426 | K39: =SUM(K32:K38) -> 4712.9284 | ... BE39: =SUM(BE32:BE38) -> 63000
A41: =WEEKNUM(B41) -> 40 | B41: =B38+1 -> 46293 | C41: =TEXT(B41,"ddd") -> Mon | D41: =SUM(E41:BE41) -> 223494.08 | E41: 1199.5729 | F41: 1200 | G41: 3300 | H41: 800 | I41: 150 | J41: 603.76323 | K41: 673.27548 | L41: 5500 | M41: 5000 | N41: 1500 | O41: 13500 | P41: 10800 | Q41: 12000 | R41: 5000 | S41: 12000 | T41: 4000 | U41: 1300 | V41: 6000 | W41: 1000 | X41: 7000 | Y41: 12000 | Z41: 1000 | AA41: 5500 | AB41: 89.451613 | AC41: 3100 | AD41: 0 | AE41: 3000 | AF41: 0 | AG41: 2000 | AH41: 2000 | AI41: 800 | AJ41: 7200 | AK41: 2000 | AL41: 2000 | AM41: 1000 | AN41: 10000 | AO41: 2000 | AP41: 5500 | AQ41: 8000 | AR41: 4000 | AS41: 3000 | AT41: 0 | AU41: 0 | AV41: 700 | AW41: 3500 | AX41: 2000 | AY41: 369.61071 | AZ41: 1121.9003 | BA41: 2499.7026 | BB41: 2499.7026 | BC41: 3587.0968 | BD41: 31500 | BE41: 9000
B42: =B41+1 -> 46294 | C42: =TEXT(B42,"ddd") -> Tue | D42: =SUM(E42:BE42) -> 223494.08 | E42: 1199.5729 | F42: 1200 | G42: 3300 | H42: 800 | I42: 150 | J42: 603.76323 | K42: 673.27548 | L42: 5500 | M42: 5000 | N42: 1500 | O42: 13500 | P42: 10800 | Q42: 12000 | R42: 5000 | S42: 12000 | T42: 4000 | U42: 1300 | V42: 6000 | W42: 1000 | X42: 7000 | Y42: 12000 | Z42: 1000 | AA42: 5500 | AB42: 89.451613 | AC42: 3100 | AD42: 0 | AE42: 3000 | AF42: 0 | AG42: 2000 | AH42: 2000 | AI42: 800 | AJ42: 7200 | AK42: 2000 | AL42: 2000 | AM42: 1000 | AN42: 10000 | AO42: 2000 | AP42: 5500 | AQ42: 8000 | AR42: 4000 | AS42: 3000 | AT42: 0 | AU42: 0 | AV42: 700 | AW42: 3500 | AX42: 2000 | AY42: 369.61071 | AZ42: 1121.9003 | BA42: 2499.7026 | BB42: 2499.7026 | BC42: 3587.0968 | BD42: 31500 | BE42: 9000
B43: =B42+1 -> 46295 | C43: =TEXT(B43,"ddd") -> Wed | D43: =SUM(E43:BE43) -> 223494.08 | E43: 1199.5729 | F43: 1200 | G43: 3300 | H43: 800 | I43: 150 | J43: 603.76323 | K43: 673.27548 | L43: 5500 | M43: 5000 | N43: 1500 | O43: 13500 | P43: 10800 | Q43: 12000 | R43: 5000 | S43: 12000 | T43: 4000 | U43: 1300 | V43: 6000 | W43: 1000 | X43: 7000 | Y43: 12000 | Z43: 1000 | AA43: 5500 | AB43: 89.451613 | AC43: 3100 | AD43: 0 | AE43: 3000 | AF43: 0 | AG43: 2000 | AH43: 2000 | AI43: 800 | AJ43: 7200 | AK43: 2000 | AL43: 2000 | AM43: 1000 | AN43: 10000 | AO43: 2000 | AP43: 5500 | AQ43: 8000 | AR43: 4000 | AS43: 3000 | AT43: 0 | AU43: 0 | AV43: 700 | AW43: 3500 | AX43: 2000 | AY43: 369.61071 | AZ43: 1121.9003 | BA43: 2499.7026 | BB43: 2499.7026 | BC43: 3587.0968 | BD43: 31500 | BE43: 9000
B44: Sub Total | D44: =SUM(D41:D43) -> 670482.23 | E44: =SUM(E41:E43) -> 3598.7187 | F44: =SUM(F41:F43) -> 3600 | G44: =SUM(G41:G43) -> 9900 | H44: =SUM(H41:H43) -> 2400 | I44: =SUM(I41:I43) -> 450 | J44: =SUM(J41:J43) -> 1811.2897 | K44: =SUM(K41:K43) -> 2019.8265 | ... AS44: =SUM(AS41:AS43) -> 9000 | AT44: =SUM(AT37:AT43) -> 0 | AU44: =SUM(AU37:AU43) -> 0 | AV44: =SUM(AV41:AV43) -> 2100 | AW44: =SUM(AW41:AW43) -> 10500 | AX44: =SUM(AX41:AX43) -> 6000 | AY44: =SUM(AY41:AY43) -> 1108.8321 | AZ44: =SUM(AZ41:AZ43) -> 3365.701 | BA44: =SUM(BA41:BA43) -> 7499.1077 | BB44: =SUM(BB41:BB43) -> 7499.1077 | BC44: =SUM(BC41:BC43) -> 10761.29 | ... BE44: =SUM(BE41:BE43) -> 27000
B49: Sub Total | D49: =SUM(D44,D39,D30,D21,D12) -> 6383464.5 | E49: =SUM(E44,E39,E30,E21,E12) -> 31990.604 | F49: =SUM(F44,F39,F30,F21,F12) -> 34400 | G49: =SUM(G44,G39,G30,G21,G12) -> 89798.065 | H49: =SUM(H44,H39,H30,H21,H12) -> 21600 | I49: =SUM(I44,I39,I30,I21,I12) -> 3900 | J49: =SUM(J44,J39,J30,J21,J12) -> 18112.897 | K49: =SUM(K44,K39,K30,K21,K12) -> 20198.265 | ... BE49: =SUM(BE44,BE39,BE30,BE21,BE12) -> 306000
...

Sheet KEBUTUHAN GAS
A1: KEBUTUHAN GAS
A4: 46266 | F4: KEBUTUHAN GAS | J4: KUOTA GAS
A5: Week | B5: DATE | D5: SELISIH GAS JABAR | E5: SELISIH GAS TOTAL | F5: JABAR | G5: JATENG | H5: JATIM | I5: TOTAL | J5: MS SETU | K5: MS KHT | L5: MS BLORA | M5: MS BITUNG | N5: MS ZEBRA | O5: MS TAMBAKLOROK | P5: MS BaGS | Q5: MS SADANG | R5: TOTAL
A6: =WEEKNUM(B6) -> 36 | B6: =A4 -> 46266 | C6: =TEXT(B6,"ddd") -> Tue | D6: =(J6+K6)-F6 -> -39909.12 | E6: =R6-I6 -> -40678.136 | F6: =SUM('SO September 2026 Rev.6'!E6:AS6) -> 182416.12 | G6: =SUM('SO September 2026 Rev.6'!AV6:BB6) -> 11569.016 | H6: =SUM('SO September 2026 Rev.6'!BC6:BE6) -> 30587.097 | I6: =SUM(F6:H6) -> 224572.23 | J6: ='SO MS'!E6 -> 108187 | K6: ='SO MS'!F6 -> 34320 | L6: ='SO MS'!G6 -> 10800 | M6: ='SO MS'!H6 -> 0 | N6: ='SO MS'!I6 -> 3587.0968 | O6: ='SO MS'!J6 -> 0 | P6: ='SO MS'!K6 -> 27000 | Q6: ='SO MS'!L6 -> 0 | R6: =SUM(J6:Q6) -> 183894.1
B7: =B6+1 -> 46267 | C7: =TEXT(B7,"ddd") -> Wed | D7: =(J7+K7)-F7 -> -39669.12 | E7: =R7-I7 -> -41560.037 | F7: =SUM('SO September 2026 Rev.6'!E7:AS7) -> 182416.12 | G7: =SUM('SO September 2026 Rev.6'!AV7:BB7) -> 12690.916 | H7: =SUM('SO September 2026 Rev.6'!BC7:BE7) -> 30587.097 | I7: =SUM(F7:H7) -> 225694.13 | J7: ='SO MS'!E7 -> 108187 | K7: ='SO MS'!F7 -> 34560 | L7: ='SO MS'!G7 -> 10800 | M7: ='SO MS'!H7 -> 0 | N7: ='SO MS'!I7 -> 3587.0968 | O7: ='SO MS'!J7 -> 0 | P7: ='SO MS'!K7 -> 27000 | Q7: ='SO MS'!L7 -> 0 | R7: =SUM(J7:Q7) -> 184134.1
B8: =B7+1 -> 46268 | C8: =TEXT(B8,"ddd") -> Thu | D8: =(J8+K8)-F8 -> -38169.12 | E8: =R8-I8 -> -36560.037 | F8: =SUM('SO September 2026 Rev.6'!E8:AS8) -> 180916.12 | G8: =SUM('SO September 2026 Rev.6'!AV8:BB8) -> 9190.9162 | H8: =SUM('SO September 2026 Rev.6'!BC8:BE8) -> 12587.097 | I8: =SUM(F8:H8) -> 202694.13 | J8: ='SO MS'!E8 -> 108187 | K8: ='SO MS'!F8 -> 34560 | L8: ='SO MS'!G8 -> 10800 | M8: ='SO MS'!H8 -> 0 | N8: ='SO MS'!I8 -> 3587.0968 | O8: ='SO MS'!J8 -> 0 | P8: ='SO MS'!K8 -> 9000 | Q8: ='SO MS'!L8 -> 0 | R8: =SUM(J8:Q8) -> 166134.1
B9: =B8+1 -> 46269 | C9: =TEXT(B9,"ddd") -> Fri | D9: =(J9+K9)-F9 -> -34169.063 | E9: =R9-I9 -> -32559.979 | F9: =SUM('SO September 2026 Rev.6'!E9:AS9) -> 176916.06 | G9: =SUM('SO September 2026 Rev.6'!AV9:BB9) -> 9190.9162 | H9: =SUM('SO September 2026 Rev.6'!BC9:BE9) -> 12587.097 | I9: =SUM(F9:H9) -> 198694.08 | J9: ='SO MS'!E9 -> 108187 | K9: ='SO MS'!F9 -> 34560 | L9: ='SO MS'!G9 -> 10800 | M9: ='SO MS'!H9 -> 0 | N9: ='SO MS'!I9 -> 3587.0968 | O9: ='SO MS'!J9 -> 0 | P9: ='SO MS'!K9 -> 9000 | Q9: ='SO MS'!L9 -> 0 | R9: =SUM(J9:Q9) -> 166134.1
B10: =B9+1 -> 46270 | C10: =TEXT(B10,"ddd") -> Sat | D10: =(J10+K10)-F10 -> -25169.49 | E10: =R10-I10 -> -22438.506 | F10: =SUM('SO September 2026 Rev.6'!E10:AS10) -> 167916.49 | G10: =SUM('SO September 2026 Rev.6'!AV10:BB10) -> 8069.0159 | H10: =SUM('SO September 2026 Rev.6'!BC10:BE10) -> 12587.097 | I10: =SUM(F10:H10) -> 188572.6 | J10: ='SO MS'!E10 -> 108187 | K10: ='SO MS'!F10 -> 34560 | L10: ='SO MS'!G10 -> 10800 | M10: ='SO MS'!H10 -> 0 | N10: ='SO MS'!I10 -> 3587.0968 | O10: ='SO MS'!J10 -> 0 | P10: ='SO MS'!K10 -> 9000 | Q10: ='SO MS'!L10 -> 0 | R10: =SUM(J10:Q10) -> 166134.1
B11: =B10+1 -> 46271 | C11: =TEXT(B11,"ddd") -> Sun | D11: =(J11+K11)-F11 -> 8821.5871 | E11: =R11-I11 -> 11552.571 | F11: =SUM('SO September 2026 Rev.6'!E11:AS11) -> 133925.41 | G11: =SUM('SO September 2026 Rev.6'!AV11:BB11) -> 8069.0159 | H11: =SUM('SO September 2026 Rev.6'!BC11:BE11) -> 15587.097 | I11: =SUM(F11:H11) -> 157581.53 | J11: ='SO MS'!E11 -> 108187 | K11: ='SO MS'!F11 -> 34560 | L11: ='SO MS'!G11 -> 10800 | M11: ='SO MS'!H11 -> 0 | N11: ='SO MS'!I11 -> 6587.0968 | O11: ='SO MS'!J11 -> 0 | P11: ='SO MS'!K11 -> 9000 | Q11: ='SO MS'!L11 -> 0 | R11: =SUM(J11:Q11) -> 169134.1
B12: Sub Total | D12: =SUM(D6:D11) -> -168264.33 | E12: =SUM(E6:E11) -> -162244.12 | F12: =SUM(F6:F11) -> 1024506.3 | G12: =SUM(G6:G11) -> 58779.796 | H12: =SUM(H6:H11) -> 114522.58 | I12: =SUM(I6:I11) -> 1197808.7 | J12: =SUM(J6:J11) -> 649122 | K12: =SUM(K6:K11) -> 207120 | ... R12: =SUM(R6:R11) -> 1035564.6
A13: =WEEKNUM(B13) -> 37 | B13: =B11+1 -> 46272 | C13: =TEXT(B13,"ddd") -> Mon | D13: =(J13+K13)-F13 -> 0 | E13: =R13-I13 -> 0 | F13: =SUM('SO September 2026 Rev.6'!E13:AS13) -> 0 | G13: =SUM('SO September 2026 Rev.6'!AV13:BB13) -> 0 | H13: =SUM('SO September 2026 Rev.6'!BC13:BE13) -> 0 | I13: =SUM(F13:H13) -> 0 | J13: ='SO MS'!E13 -> 0 | K13: ='SO MS'!F13 -> 0 | L13: ='SO MS'!G13 -> 0 | M13: ='SO MS'!H13 -> 0 | N13: ='SO MS'!I13 -> 0 | O13: ='SO MS'!J13 -> 0 | P13: ='SO MS'!K13 -> 0 | Q13: ='SO MS'!L13 -> 0 | R13: =SUM(J13:Q13) -> 0
B14: =B13+1 -> 46273 | C14: =TEXT(B14,"ddd") -> Tue | D14: =(J14+K14)-F14 -> 11609.937 | E14: =R14-I14 -> 13219.021 | F14: =SUM('SO September 2026 Rev.6'!E14:AS14) -> 177216.06 | G14: =SUM('SO September 2026 Rev.6'!AV14:BB14) -> 9190.9162 | H14: =SUM('SO September 2026 Rev.6'!BC14:BE14) -> 15587.097 | I14: =SUM(F14:H14) -> 201994.08 | J14: ='SO MS'!E14 -> 142826 | K14: ='SO MS'!F14 -> 46000 | L14: ='SO MS'!G14 -> 10800 | M14: ='SO MS'!H14 -> 0 | N14: ='SO MS'!I14 -> 6587.0968 | O14: ='SO MS'!J14 -> 0 | P14: ='SO MS'!K14 -> 9000 | Q14: ='SO MS'!L14 -> 0 | R14: =SUM(J14:Q14) -> 215213.1
B15: =B14+1 -> 46274 | C15: =TEXT(B15,"ddd") -> Wed | D15: =(J15+K15)-F15 -> 11609.937 | E15: =R15-I15 -> 13219.021 | F15: =SUM('SO September 2026 Rev.6'!E15:AS15) -> 177216.06 | G15: =SUM('SO September 2026 Rev.6'!AV15:BB15) -> 9190.9162 | H15: =SUM('SO September 2026 Rev.6'!BC15:BE15) -> 15587.097 | I15: =SUM(F15:H15) -> 201994.08 | J15: ='SO MS'!E15 -> 142826 | K15: ='SO MS'!F15 -> 46000 | L15: ='SO MS'!G15 -> 10800 | M15: ='SO MS'!H15 -> 0 | N15: ='SO MS'!I15 -> 6587.0968 | O15: ='SO MS'!J15 -> 0 | P15: ='SO MS'!K15 -> 9000 | Q15: ='SO MS'!L15 -> 0 | R15: =SUM(J15:Q15) -> 215213.1
B16: =B15+1 -> 46275 | C16: =TEXT(B16,"ddd") -> Thu | D16: =(J16+K16)-F16 -> 11609.937 | E16: =R16-I16 -> 13219.021 | F16: =SUM('SO September 2026 Rev.6'!E16:AS16) -> 177216.06 | G16: =SUM('SO September 2026 Rev.6'!AV16:BB16) -> 9190.9162 | H16: =SUM('SO September 2026 Rev.6'!BC16:BE16) -> 15587.097 | I16: =SUM(F16:H16) -> 201994.08 | J16: ='SO MS'!E16 -> 142826 | K16: ='SO MS'!F16 -> 46000 | L16: ='SO MS'!G16 -> 10800 | M16: ='SO MS'!H16 -> 0 | N16: ='SO MS'!I16 -> 6587.0968 | O16: ='SO MS'!J16 -> 0 | P16: ='SO MS'!K16 -> 9000 | Q16: ='SO MS'!L16 -> 0 | R16: =SUM(J16:Q16) -> 215213.1
B17: =B16+1 -> 46276 | C17: =TEXT(B17,"ddd") -> Fri | D17: =(J17+K17)-F17 -> 11609.937 | E17: =R17-I17 -> 13219.021 | F17: =SUM('SO September 2026 Rev.6'!E17:AS17) -> 177216.06 | G17: =SUM('SO September 2026 Rev.6'!AV17:BB17) -> 9190.9162 | H17: =SUM('SO September 2026 Rev.6'!BC17:BE17) -> 30587.097 | I17: =SUM(F17:H17) -> 216994.08 | J17: ='SO MS'!E17 -> 142826 | K17: ='SO MS'!F17 -> 46000 | L17: ='SO MS'!G17 -> 10800 | M17: ='SO MS'!H17 -> 0 | N17: ='SO MS'!I17 -> 21587.097 | O17: ='SO MS'!J17 -> 0 | P17: ='SO MS'!K17 -> 9000 | Q17: ='SO MS'!L17 -> 0 | R17: =SUM(J17:Q17) -> 230213.1
B18: =B17+1 -> 46277 | C18: =TEXT(B18,"ddd") -> Sat | D18: =(J18+K18)-F18 -> 11609.937 | E18: =R18-I18 -> 13219.021 | F18: =SUM('SO September 2026 Rev.6'!E18:AS18) -> 177216.06 | G18: =SUM('SO September 2026 Rev.6'!AV18:BB18) -> 9190.9162 | H18: =SUM('SO September 2026 Rev.6'!BC18:BE18) -> 44087.097 | I18: =SUM(F18:H18) -> 230494.08 | J18: ='SO MS'!E18 -> 142826 | K18: ='SO MS'!F18 -> 46000 | L18: ='SO MS'!G18 -> 10800 | M18: ='SO MS'!H18 -> 0 | N18: ='SO MS'!I18 -> 35087.097 | O18: ='SO MS'!J18 -> 0 | P18: ='SO MS'!K18 -> 9000 | Q18: ='SO MS'!L18 -> 0 | R18: =SUM(J18:Q18) -> 243713.1
B19: =B18+1 -> 46278 | C19: =TEXT(B19,"ddd") -> Sun | D19: =(J19+K19)-F19 -> 20109.51 | E19: =R19-I19 -> 22840.494 | F19: =SUM('SO September 2026 Rev.6'!E19:AS19) -> 168716.49 | G19: =SUM('SO September 2026 Rev.6'!AV19:BB19) -> 8069.0159 | H19: =SUM('SO September 2026 Rev.6'!BC19:BE19) -> 44087.097 | I19: =SUM(F19:H19) -> 220872.6 | J19: ='SO MS'!E19 -> 142826 | K19: ='SO MS'!F19 -> 46000 | L19: ='SO MS'!G19 -> 10800 | M19: ='SO MS'!H19 -> 0 | N19: ='SO MS'!I19 -> 35087.097 | O19: ='SO MS'!J19 -> 0 | P19: ='SO MS'!K19 -> 9000 | Q19: ='SO MS'!L19 -> 0 | R19: =SUM(J19:Q19) -> 243713.1
B20: Sub Total | D20: =SUM(D13:D19) -> 78159.194 | E20: =SUM(E13:E19) -> 88935.597 | F20: =SUM(F13:F19) -> 1054796.8 | G20: =SUM(G13:G19) -> 54023.597 | H20: =SUM(H13:H19) -> 165522.58 | I20: =SUM(I13:I19) -> 1274343 | J20: =SUM(J13:J19) -> 856956 | K20: =SUM(K13:K19) -> 276000 | ... R20: =SUM(R13:R19) -> 1363278.6
A21: =WEEKNUM(B22) -> 38 | B21: =B19+1 -> 46279 | C21: =TEXT(B21,"ddd") -> Mon | D21: =(J21+K21)-F21 -> 134759.78 | E21: =R21-I21 -> 148267.17 | F21: =SUM('SO September 2026 Rev.6'!E21:AS21) -> 1187022.2 | G21: =SUM('SO September 2026 Rev.6'!AV21:BB21) -> 62092.613 | H21: =SUM('SO September 2026 Rev.6'!BC21:BE21) -> 209609.68 | I21: =SUM(F21:H21) -> 1458724.5 | J21: ='SO MS'!E21 -> 999782 | K21: ='SO MS'!F21 -> 322000 | L21: ='SO MS'!G21 -> 75600 | M21: ='SO MS'!H21 -> 0 | N21: ='SO MS'!I21 -> 146609.68 | O21: ='SO MS'!J21 -> 0 | P21: ='SO MS'!K21 -> 63000 | Q21: ='SO MS'!L21 -> 0 | R21: =SUM(J21:Q21) -> 1606991.7
B22: =B21+1 -> 46280 | C22: =TEXT(B22,"ddd") -> Tue | D22: =(J22+K22)-F22 -> 0 | E22: =R22-I22 -> 0 | F22: =SUM('SO September 2026 Rev.6'!E22:AS22) -> 0 | G22: =SUM('SO September 2026 Rev.6'!AV22:BB22) -> 0 | H22: =SUM('SO September 2026 Rev.6'!BC22:BE22) -> 0 | I22: =SUM(F22:H22) -> 0 | J22: ='SO MS'!E22 -> 0 | K22: ='SO MS'!F22 -> 0 | L22: ='SO MS'!G22 -> 0 | M22: ='SO MS'!H22 -> 0 | N22: ='SO MS'!I22 -> 0 | O22: ='SO MS'!J22 -> 0 | P22: ='SO MS'!K22 -> 0 | Q22: ='SO MS'!L22 -> 0 | R22: =SUM(J22:Q22) -> 0
B23: =B22+1 -> 46281 | C23: =TEXT(B23,"ddd") -> Wed | D23: =(J23+K23)-F23 -> 10609.937 | E23: =R23-I23 -> 12219.021 | F23: =SUM('SO September 2026 Rev.6'!E23:AS23) -> 178216.06 | G23: =SUM('SO September 2026 Rev.6'!AV23:BB23) -> 9190.9162 | H23: =SUM('SO September 2026 Rev.6'!BC23:BE23) -> 44087.097 | I23: =SUM(F23:H23) -> 231494.08 | J23: ='SO MS'!E23 -> 142826 | K23: ='SO MS'!F23 -> 46000 | L23: ='SO MS'!G23 -> 10800 | M23: ='SO MS'!H23 -> 0 | N23: ='SO MS'!I23 -> 35087.097 | O23: ='SO MS'!J23 -> 0 | P23: ='SO MS'!K23 -> 9000 | Q23: ='SO MS'!L23 -> 0 | R23: =SUM(J23:Q23) -> 243713.1
B24: =B23+1 -> 46282 | C24: =TEXT(B24,"ddd") -> Thu | D24: =(J24+K24)-F24 -> 10609.937 | E24: =R24-I24 -> 12219.021 | F24: =SUM('SO September 2026 Rev.6'!E24:AS24) -> 178216.06 | G24: =SUM('SO September 2026 Rev.6'!AV24:BB24) -> 9190.9162 | H24: =SUM('SO September 2026 Rev.6'!BC24:BE24) -> 44087.097 | I24: =SUM(F24:H24) -> 231494.08 | J24: ='SO MS'!E24 -> 142826 | K24: ='SO MS'!F24 -> 46000 | L24: ='SO MS'!G24 -> 10800 | M24: ='SO MS'!H24 -> 0 | N24: ='SO MS'!I24 -> 35087.097 | O24: ='SO MS'!J24 -> 0 | P24: ='SO MS'!K24 -> 9000 | Q24: ='SO MS'!L24 -> 0 | R24: =SUM(J24:Q24) -> 243713.1
B25: =B24+1 -> 46283 | C25: =TEXT(B25,"ddd") -> Fri | D25: =(J25+K25)-F25 -> 32009.937 | E25: =R25-I25 -> 33619.021 | F25: =SUM('SO September 2026 Rev.6'!E25:AS25) -> 156816.06 | G25: =SUM('SO September 2026 Rev.6'!AV25:BB25) -> 9190.9162 | H25: =SUM('SO September 2026 Rev.6'!BC25:BE25) -> 44087.097 | I25: =SUM(F25:H25) -> 210094.08 | J25: ='SO MS'!E25 -> 142826 | K25: ='SO MS'!F25 -> 46000 | L25: ='SO MS'!G25 -> 10800 | M25: ='SO MS'!H25 -> 0 | N25: ='SO MS'!I25 -> 35087.097 | O25: ='SO MS'!J25 -> 0 | P25: ='SO MS'!K25 -> 9000 | Q25: ='SO MS'!L25 -> 0 | R25: =SUM(J25:Q25) -> 243713.1
B26: =B25+1 -> 46284 | C26: =TEXT(B26,"ddd") -> Sat | D26: =(J26+K26)-F26 -> 32009.937 | E26: =R26-I26 -> 33619.021 | F26: =SUM('SO September 2026 Rev.6'!E26:AS26) -> 156816.06 | G26: =SUM('SO September 2026 Rev.6'!AV26:BB26) -> 9190.9162 | H26: =SUM('SO September 2026 Rev.6'!BC26:BE26) -> 44087.097 | I26: =SUM(F26:H26) -> 210094.08 | J26: ='SO MS'!E26 -> 142826 | K26: ='SO MS'!F26 -> 46000 | L26: ='SO MS'!G26 -> 10800 | M26: ='SO MS'!H26 -> 0 | N26: ='SO MS'!I26 -> 35087.097 | O26: ='SO MS'!J26 -> 0 | P26: ='SO MS'!K26 -> 9000 | Q26: ='SO MS'!L26 -> 0 | R26: =SUM(J26:Q26) -> 243713.1
B27: =B26+1 -> 46285 | C27: =TEXT(B27,"ddd") -> Sun | D27: =(J27+K27)-F27 -> 32009.937 | E27: =R27-I27 -> 33619.021 | F27: =SUM('SO September 2026 Rev.6'!E27:AS27) -> 156816.06 | G27: =SUM('SO September 2026 Rev.6'!AV27:BB27) -> 9190.9162 | H27: =SUM('SO September 2026 Rev.6'!BC27:BE27) -> 44087.097 | I27: =SUM(F27:H27) -> 210094.08 | J27: ='SO MS'!E27 -> 142826 | K27: ='SO MS'!F27 -> 46000 | L27: ='SO MS'!G27 -> 10800 | M27: ='SO MS'!H27 -> 0 | N27: ='SO MS'!I27 -> 35087.097 | O27: ='SO MS'!J27 -> 0 | P27: ='SO MS'!K27 -> 9000 | Q27: ='SO MS'!L27 -> 0 | R27: =SUM(J27:Q27) -> 243713.1
B28: Sub Total | D28: =SUM(D21:D27) -> 252009.46 | E28: =SUM(E21:E27) -> 273562.27 | F28: =SUM(F21:F27) -> 2013902.5 | G28: =SUM(G21:G27) -> 108047.19 | H28: =SUM(H21:H27) -> 430045.16 | I28: =SUM(I21:I27) -> 2551994.9 | J28: =SUM(J21:J27) -> 1713912 | K28: =SUM(K21:K27) -> 552000 | ... R28: =SUM(R21:R27) -> 2825557.2
A29: =WEEKNUM(B31) -> 39 | B29: =B27+1 -> 46286 | C29: =TEXT(B29,"ddd") -> Mon | D29: =(J29+K29)-F29 -> 40600.587 | E29: =R29-I29 -> 43331.571 | F29: =SUM('SO September 2026 Rev.6'!E29:AS29) -> 148225.41 | G29: =SUM('SO September 2026 Rev.6'!AV29:BB29) -> 8069.0159 | H29: =SUM('SO September 2026 Rev.6'!BC29:BE29) -> 44087.097 | I29: =SUM(F29:H29) -> 200381.53 | J29: ='SO MS'!E29 -> 142826 | K29: ='SO MS'!F29 -> 46000 | L29: ='SO MS'!G29 -> 10800 | M29: ='SO MS'!H29 -> 0 | N29: ='SO MS'!I29 -> 35087.097 | O29: ='SO MS'!J29 -> 0 | P29: ='SO MS'!K29 -> 9000 | Q29: ='SO MS'!L29 -> 0 | R29: =SUM(J29:Q29) -> 243713.1
B30: =B29+1 -> 46287 | C30: =TEXT(B30,"ddd") -> Tue | D30: =(J30+K30)-F30 -> 190859.78 | E30: =R30-I30 -> 204367.17 | F30: =SUM('SO September 2026 Rev.6'!E30:AS30) -> 1130922.2 | G30: =SUM('SO September 2026 Rev.6'!AV30:BB30) -> 62092.613 | H30: =SUM('SO September 2026 Rev.6'!BC30:BE30) -> 308609.68 | I30: =SUM(F30:H30) -> 1501624.5 | J30: ='SO MS'!E30 -> 999782 | K30: ='SO MS'!F30 -> 322000 | L30: ='SO MS'!G30 -> 75600 | M30: ='SO MS'!H30 -> 0 | N30: ='SO MS'!I30 -> 245609.68 | O30: ='SO MS'!J30 -> 0 | P30: ='SO MS'!K30 -> 63000 | Q30: ='SO MS'!L30 -> 0 | R30: =SUM(J30:Q30) -> 1705991.7
B31: =B30+1 -> 46288 | C31: =TEXT(B31,"ddd") -> Wed | D31: =(J31+K31)-F31 -> 0 | E31: =R31-I31 -> 0 | F31: =SUM('SO September 2026 Rev.6'!E31:AS31) -> 0 | G31: =SUM('SO September 2026 Rev.6'!AV31:BB31) -> 0 | H31: =SUM('SO September 2026 Rev.6'!BC31:BE31) -> 0 | I31: =SUM(F31:H31) -> 0 | J31: ='SO MS'!E31 -> 0 | K31: ='SO MS'!F31 -> 0 | L31: ='SO MS'!G31 -> 0 | M31: ='SO MS'!H31 -> 0 | N31: ='SO MS'!I31 -> 0 | O31: ='SO MS'!J31 -> 0 | P31: ='SO MS'!K31 -> 0 | Q31: ='SO MS'!L31 -> 0 | R31: =SUM(J31:Q31) -> 0
B32: =B31+1 -> 46289 | C32: =TEXT(B32,"ddd") -> Thu | D32: =(J32+K32)-F32 -> 22009.937 | E32: =R32-I32 -> 20119.021 | F32: =SUM('SO September 2026 Rev.6'!E32:AS32) -> 166816.06 | G32: =SUM('SO September 2026 Rev.6'!AV32:BB32) -> 12690.916 | H32: =SUM('SO September 2026 Rev.6'!BC32:BE32) -> 44087.097 | I32: =SUM(F32:H32) -> 223594.08 | J32: ='SO MS'!E32 -> 142826 | K32: ='SO MS'!F32 -> 46000 | L32: ='SO MS'!G32 -> 10800 | M32: ='SO MS'!H32 -> 0 | N32: ='SO MS'!I32 -> 35087.097 | O32: ='SO MS'!J32 -> 0 | P32: ='SO MS'!K32 -> 9000 | Q32: ='SO MS'!L32 -> 0 | R32: =SUM(J32:Q32) -> 243713.1
B33: =B32+1 -> 46290 | C33: =TEXT(B33,"ddd") -> Fri | D33: =(J33+K33)-F33 -> 22809.937 | E33: =R33-I33 -> 20919.021 | F33: =SUM('SO September 2026 Rev.6'!E33:AS33) -> 166016.06 | G33: =SUM('SO September 2026 Rev.6'!AV33:BB33) -> 12690.916 | H33: =SUM('SO September 2026 Rev.6'!BC33:BE33) -> 44087.097 | I33: =SUM(F33:H33) -> 222794.08 | J33: ='SO MS'!E33 -> 142826 | K33: ='SO MS'!F33 -> 46000 | L33: ='SO MS'!G33 -> 10800 | M33: ='SO MS'!H33 -> 0 | N33: ='SO MS'!I33 -> 35087.097 | O33: ='SO MS'!J33 -> 0 | P33: ='SO MS'!K33 -> 9000 | Q33: ='SO MS'!L33 -> 0 | R33: =SUM(J33:Q33) -> 243713.1
B34: =B33+1 -> 46291 | C34: =TEXT(B34,"ddd") -> Sat | D34: =(J34+K34)-F34 -> 20809.937 | E34: =R34-I34 -> 18919.021 | F34: =SUM('SO September 2026 Rev.6'!E34:AS34) -> 168016.06 | G34: =SUM('SO September 2026 Rev.6'!AV34:BB34) -> 12690.916 | H34: =SUM('SO September 2026 Rev.6'!BC34:BE34) -> 44087.097 | I34: =SUM(F34:H34) -> 224794.08 | J34: ='SO MS'!E34 -> 142826 | K34: ='SO MS'!F34 -> 46000 | L34: ='SO MS'!G34 -> 10800 | M34: ='SO MS'!H34 -> 0 | N34: ='SO MS'!I34 -> 35087.097 | O34: ='SO MS'!J34 -> 0 | P34: ='SO MS'!K34 -> 9000 | Q34: ='SO MS'!L34 -> 0 | R34: =SUM(J34:Q34) -> 243713.1
B35: =B34+1 -> 46292 | C35: =TEXT(B35,"ddd") -> Sun | D35: =(J35+K35)-F35 -> 22109.937 | E35: =R35-I35 -> 20219.021 | F35: =SUM('SO September 2026 Rev.6'!E35:AS35) -> 166716.06 | G35: =SUM('SO September 2026 Rev.6'!AV35:BB35) -> 12690.916 | H35: =SUM('SO September 2026 Rev.6'!BC35:BE35) -> 44087.097 | I35: =SUM(F35:H35) -> 223494.08 | J35: ='SO MS'!E35 -> 142826 | K35: ='SO MS'!F35 -> 46000 | L35: ='SO MS'!G35 -> 10800 | M35: ='SO MS'!H35 -> 0 | N35: ='SO MS'!I35 -> 35087.097 | O35: ='SO MS'!J35 -> 0 | P35: ='SO MS'!K35 -> 9000 | Q35: ='SO MS'!L35 -> 0 | R35: =SUM(J35:Q35) -> 243713.1
B36: Sub Total | D36: =SUM(D29:D35) -> 319200.11 | E36: =SUM(E29:E35) -> 327874.82 | F36: =SUM(F29:F35) -> 1946711.9 | G36: =SUM(G29:G35) -> 120925.29 | H36: =SUM(H29:H35) -> 529045.16 | I36: =SUM(I29:I35) -> 2596682.3 | J36: =SUM(J29:J35) -> 1713912 | K36: =SUM(K29:K35) -> 552000 | ... R36: =SUM(R29:R35) -> 2924557.2
A37: =WEEKNUM(B39) -> 40 | B37: =B35+1 -> 46293 | C37: =TEXT(B37,"ddd") -> Mon | D37: =(J37+K37)-F37 -> 18609.51 | E37: =R37-I37 -> 17840.494 | F37: =SUM('SO September 2026 Rev.6'!E37:AS37) -> 170216.49 | G37: =SUM('SO September 2026 Rev.6'!AV37:BB37) -> 11569.016 | H37: =SUM('SO September 2026 Rev.6'!BC37:BE37) -> 44087.097 | I37: =SUM(F37:H37) -> 225872.6 | J37: ='SO MS'!E37 -> 142826 | K37: ='SO MS'!F37 -> 46000 | L37: ='SO MS'!G37 -> 10800 | M37: ='SO MS'!H37 -> 0 | N37: ='SO MS'!I37 -> 35087.097 | O37: ='SO MS'!J37 -> 0 | P37: ='SO MS'!K37 -> 9000 | Q37: ='SO MS'!L37 -> 0 | R37: =SUM(J37:Q37) -> 243713.1
B38: =B37+1 -> 46294 | C38: =TEXT(B38,"ddd") -> Tue | D38: =(J38+K38)-F38 -> 33700.587 | E38: =R38-I38 -> 32931.571 | F38: =SUM('SO September 2026 Rev.6'!E38:AS38) -> 155125.41 | G38: =SUM('SO September 2026 Rev.6'!AV38:BB38) -> 11569.016 | H38: =SUM('SO September 2026 Rev.6'!BC38:BE38) -> 44087.097 | I38: =SUM(F38:H38) -> 210781.53 | J38: ='SO MS'!E38 -> 142826 | K38: ='SO MS'!F38 -> 46000 | L38: ='SO MS'!G38 -> 10800 | M38: ='SO MS'!H38 -> 0 | N38: ='SO MS'!I38 -> 35087.097 | O38: ='SO MS'!J38 -> 0 | P38: ='SO MS'!K38 -> 9000 | Q38: ='SO MS'!L38 -> 0 | R38: =SUM(J38:Q38) -> 243713.1
B39: =B38+1 -> 46295 | C39: =TEXT(B39,"ddd") -> Wed | D39: =(J39+K39)-F39 -> 162159.78 | E39: =R39-I39 -> 151167.17 | F39: =SUM('SO September 2026 Rev.6'!E39:AS39) -> 1159622.2 | G39: =SUM('SO September 2026 Rev.6'!AV39:BB39) -> 86592.613 | H39: =SUM('SO September 2026 Rev.6'!BC39:BE39) -> 308609.68 | I39: =SUM(F39:H39) -> 1554824.5 | J39: ='SO MS'!E39 -> 999782 | K39: ='SO MS'!F39 -> 322000 | L39: ='SO MS'!G39 -> 75600 | M39: ='SO MS'!H39 -> 0 | N39: ='SO MS'!I39 -> 245609.68 | O39: ='SO MS'!J39 -> 0 | P39: ='SO MS'!K39 -> 63000 | Q39: ='SO MS'!L39 -> 0 | R39: =SUM(J39:Q39) -> 1705991.7
B40: Sub Total | D40: =SUM(D37:D39) -> 214469.88 | E40: =SUM(E37:E39) -> 201939.23 | F40: =SUM(F37:F39) -> 1484964.1 | G40: =SUM(G37:G39) -> 109730.64 | H40: =SUM(H37:H39) -> 396783.87 | I40: =SUM(I37:I39) -> 1991478.6 | J40: =SUM(J37:J39) -> 1285434 | K40: =SUM(K37:K39) -> 414000 | ... R40: =SUM(R37:R39) -> 2193417.9
B42: Sub Total | D42: =D12+D20+D28+D36+D40 -> 695574.32 | E42: =E12+E20+E28+E36+E40 -> 730067.8 | F42: =F12+F20+F28+F36+F40 -> 7524881.7 | G42: =G12+G20+G28+G36+G40 -> 451506.52 | H42: =H12+H20+H28+H36+H40 -> 1635919.4 | I42: =I12+I20+I28+I36+I40 -> 9612307.6 | J42: =J12+J20+J28+J36+J40 -> 6219336 | K42: =K12+K20+K28+K36+K40 -> 2001120 | ... R42: =R12+R20+R28+R36+R40 -> 10342375
B43: Total | D43: =SUM(D6:D11,D13:D19,D21:D27,D29:D35,D37:D39) -> 695574.32 | E43: =SUM(E6:E11,E13:E19,E21:E27,E29:E35,E37:E39) -> 730067.8 | F43: =SUM(F6:F11,F13:F19,F21:F27,F29:F35,F37:F39) -> 7524881.7 | G43: =SUM(G6:G11,G13:G19,G21:G27,G29:G35,G37:G39) -> 451506.52 | H43: =SUM(H6:H11,H13:H19,H21:H27,H29:H35,H37:H39) -> 1635919.4 | I43: =SUM(I6:I11,I13:I19,I21:I27,I29:I35,I37:I39) -> 9612307.6 | J43: =SUM(J6:J11,J13:J19,J21:J27,J29:J35,J37:J39) -> 6219336 | K43: =SUM(K6:K11,K13:K19,K21:K27,K29:K35,K37:K39) -> 2001120 | ... R43: =SUM(R6:R11,R13:R19,R21:R27,R29:R35,R37:R39) -> 10342375

Sheet SO MS
A1: SALES ORDER GAS
A4: 46266
A5: Week | B5: DATE | D5: TOTAL | E5: MS SETU | F5: MS KHT | G5: MS BLORA | H5: MS BITUNG | I5: MS ZEBRA | J5: MS TAMBAKLOROK | K5: MS BaGS | L5: MS SADANG
A6: =WEEKNUM(B6) -> 36 | B6: =A4 -> 46266 | C6: =TEXT(B6,"ddd") -> Tue | D6: =SUM(E6:O6) -> 183894.1 | E6: 108187 | F6: =1.43*24000 -> 34320 | G6: =0.45*24000 -> 10800 | H6: 0 | I6: ='SO September 2026 Rev.6'!BC6+'SO September 2026 Rev.6'!BD6 -> 3587.0968 | J6: 0 | K6: ='SO September 2026 Rev.6'!BE6 -> 27000 | L6: ='Summary sales'!L8 -> 0
B7: =B6+1 -> 46267 | C7: =TEXT(B7,"ddd") -> Wed | D7: =SUM(E7:O7) -> 184134.1 | E7: 108187 | F7: =1.44*24000 -> 34560 | G7: =0.45*24000 -> 10800 | H7: 0 | I7: ='SO September 2026 Rev.6'!BC7+'SO September 2026 Rev.6'!BD7 -> 3587.0968 | J7: 0 | K7: ='SO September 2026 Rev.6'!BE7 -> 27000 | L7: ='Summary sales'!L9 -> 0
B8: =B7+1 -> 46268 | C8: =TEXT(B8,"ddd") -> Thu | D8: =SUM(E8:O8) -> 166134.1 | E8: 108187 | F8: =1.44*24000 -> 34560 | G8: =0.45*24000 -> 10800 | H8: 0 | I8: ='SO September 2026 Rev.6'!BC8+'SO September 2026 Rev.6'!BD8 -> 3587.0968 | J8: 0 | K8: ='SO September 2026 Rev.6'!BE8 -> 9000 | L8: ='Summary sales'!L10 -> 0
B9: =B8+1 -> 46269 | C9: =TEXT(B9,"ddd") -> Fri | D9: =SUM(E9:O9) -> 166134.1 | E9: 108187 | F9: =1.44*24000 -> 34560 | G9: =0.45*24000 -> 10800 | H9: 0 | I9: ='SO September 2026 Rev.6'!BC9+'SO September 2026 Rev.6'!BD9 -> 3587.0968 | J9: 0 | K9: ='SO September 2026 Rev.6'!BE9 -> 9000 | L9: ='Summary sales'!L11 -> 0
B10: =B9+1 -> 46270 | C10: =TEXT(B10,"ddd") -> Sat | D10: =SUM(E10:O10) -> 166134.1 | E10: 108187 | F10: =1.44*24000 -> 34560 | G10: =0.45*24000 -> 10800 | H10: 0 | I10: ='SO September 2026 Rev.6'!BC10+'SO September 2026 Rev.6'!BD10 -> 3587.0968 | J10: 0 | K10: ='SO September 2026 Rev.6'!BE10 -> 9000 | L10: ='Summary sales'!L12 -> 0
