Workbook
Name ___xlnm._FilterDatabase_2: #REF!
Name ___xlnm._FilterDatabase_2: #REF!
Name ___xlnm._FilterDatabase_2: #REF!
Name ___xlnm._FilterDatabase_2: #REF!
Name ___xlnm._FilterDatabase_2: #REF!
Name ___xlnm._FilterDatabase_2: #REF!
Name ___xlnm._FilterDatabase_2: #REF!
Name ___xlnm._FilterDatabase_2: #REF!
Name ___xlnm._FilterDatabase_2: #REF!
Name ___xlnm._FilterDatabase_2: #REF!
Name ___xlnm._FilterDatabase_2: #REF!
Name ___xlnm._FilterDatabase_2: #REF!
Name ___xlnm._FilterDatabase_2: #REF!
Name ___xlnm._FilterDatabase_2: #REF!
Name ___xlnm._FilterDatabase_2: #REF!
Name ___xlnm._FilterDatabase_2: #REF!
Name ___xlnm._FilterDatabase_2: #REF!
Name __xlnm._FilterDatabase_2: #REF!
Name __xlnm._FilterDatabase_2: #REF!
Name __xlnm._FilterDatabase_2: #REF!
Name __xlnm._FilterDatabase_2: #REF!
Name __xlnm._FilterDatabase_2: #REF!
Name __xlnm._FilterDatabase_2: #REF!
Name __xlnm._FilterDatabase_2: #REF!
Name __xlnm._FilterDatabase_2: #REF!
Name __xlnm._FilterDatabase_2: #REF!
Name __xlnm._FilterDatabase_2: #REF!
Name __xlnm._FilterDatabase_2: #REF!
Name __xlnm._FilterDatabase_2: #REF!
Name __xlnm._FilterDatabase_2: #REF!
Name __xlnm._FilterDatabase_2: #REF!
Name __xlnm._FilterDatabase_2: #REF!
Name __xlnm._FilterDatabase_2: #REF!
Name __xlnm._FilterDatabase_2: #REF!
Name _TES46: #N/A
Name AAAA: #N/A
Name ati: #N/A
Name BS: #N/A
Name CCC: #N/A
Name depr9200: #N/A
Name dfsfd: #N/A
Name Excel_BuiltIn__FilterDatabase_1: #REF!
Name Excel_BuiltIn__FilterDatabase_1: #REF!
Name Excel_BuiltIn__FilterDatabase_1: #REF!
Name Excel_BuiltIn__FilterDatabase_1: #REF!
Name Excel_BuiltIn__FilterDatabase_1: #REF!
Name Excel_BuiltIn__FilterDatabase_1: #REF!
Name Excel_BuiltIn__FilterDatabase_1: #REF!
Name Excel_BuiltIn__FilterDatabase_1: #REF!
Name Excel_BuiltIn__FilterDatabase_1: #REF!
Name Excel_BuiltIn__FilterDatabase_1: #REF!
Name Excel_BuiltIn__FilterDatabase_1: #REF!
Name Excel_BuiltIn__FilterDatabase_1: #REF!
Name Excel_BuiltIn__FilterDatabase_1: #REF!
Name Excel_BuiltIn__FilterDatabase_1: #REF!
Name Excel_BuiltIn__FilterDatabase_1: #REF!
Name Excel_BuiltIn__FilterDatabase_1: #REF!
Name Excel_BuiltIn__FilterDatabase_1: #REF!
Name Excel_BuiltIn_Print_Titles: NA()
Name Export_3: #REF!

Sheet SO FOB Agustus 2026
A2: SALES ORDER
A4: 46235
A6: Week | B6: DATE | D6: TOTAL | E6: FOB SETU-AAE | F6: FOB SETU- SIDO | G6: FOB SETU - GIG | H6: FOB SETU - SALMAH | I6: FOB SETU - NNE | J6: FOB SETU - GAS | K6: FOB SETU -SBE | L6: FOB SETU -DAMASINDO | M6: FOB SETU-LARAS | N6: FOB SETU-KIRANA | O6: FOB KHT-APE | P6: FOB KHT - JPEN | Q6: FOB KHT - Laras | R6: FOB KHT - ANAGATA
A7: =WEEKNUM(B7) -> 31 | B7: =A4 -> 46235 | C7: Sun | D7: =SUM(E7:R7) -> 0 | E7: 0 | F7: 0 | G7: 0 | H7: 0 | I7: 0 | J7: 0 | K7: 0 | L7: 0 | M7: 0 | N7: 0 | O7: 0 | P7: 0 | Q7: 0 | R7: 0
B8: Sub Total | D8: =SUM(D4:D7) -> 0 | E8: =SUM(E4:E7) -> 0 | F8: =SUM(F4:F7) -> 0 | G8: =SUM(G4:G7) -> 0 | H8: =SUM(H4:H7) -> 0 | I8: =SUM(I4:I7) -> 0 | J8: =SUM(J4:J7) -> 0 | K8: =SUM(K4:K7) -> 0 | ... R8: =SUM(R4:R7) -> 0
A10: =WEEKNUM(B10) -> 32 | B10: =B7+1 -> 46236 | C10: Mon | D10: =SUM(E10:R10) -> 0 | E10: 0 | F10: 0 | G10: 0 | H10: 0 | I10: 0 | J10: 0 | K10: 0 | L10: 0 | M10: 0 | N10: 0 | O10: 0 | P10: 0 | Q10: 0 | R10: 0
B11: =B10+1 -> 46237 | C11: Tue | D11: =SUM(E11:R11) -> 0 | E11: 0 | F11: 0 | G11: 0 | H11: 0 | I11: 0 | J11: 0 | K11: 0 | L11: 0 | M11: 0 | N11: 0 | O11: 0 | P11: 0 | Q11: 0 | R11: 0
B12: =B11+1 -> 46238 | C12: Wed | D12: =SUM(E12:R12) -> 0 | E12: 0 | F12: 0 | G12: 0 | H12: 0 | I12: 0 | J12: 0 | K12: 0 | L12: 0 | M12: 0 | N12: 0 | O12: 0 | P12: 0 | Q12: 0 | R12: 0
B13: =B12+1 -> 46239 | C13: Thu | D13: =SUM(E13:R13) -> 0 | E13: 0 | F13: 0 | G13: 0 | H13: 0 | I13: 0 | J13: 0 | K13: 0 | L13: 0 | M13: 0 | N13: 0 | O13: 0 | P13: 0 | Q13: 0 | R13: 0
B14: =B13+1 -> 46240 | C14: Fri | D14: =SUM(E14:R14) -> 0 | E14: 0 | F14: 0 | G14: 0 | H14: 0 | I14: 0 | J14: 0 | K14: 0 | L14: 0 | M14: 0 | N14: 0 | O14: 0 | P14: 0 | Q14: 0 | R14: 0
B15: =B14+1 -> 46241 | C15: Sat | D15: =SUM(E15:R15) -> 0 | E15: 0 | F15: 0 | G15: 0 | H15: 0 | I15: 0 | J15: 0 | K15: 0 | L15: 0 | M15: 0 | N15: 0 | O15: 0 | P15: 0 | Q15: 0 | R15: 0
B16: =B15+1 -> 46242 | C16: Sun | D16: =SUM(E16:R16) -> 0 | E16: 0 | F16: 0 | G16: 0 | H16: 0 | I16: 0 | J16: 0 | K16: 0 | L16: 0 | M16: 0 | N16: 0 | O16: 0 | P16: 0 | Q16: 0 | R16: 0
B17: Sub Total | D17: =SUM(D10:D16) -> 0 | E17: =SUM(E10:E16) -> 0 | F17: =SUM(F10:F16) -> 0 | G17: =SUM(G10:G16) -> 0 | H17: =SUM(H10:H16) -> 0 | I17: =SUM(I10:I16) -> 0 | J17: =SUM(J10:J16) -> 0 | K17: =SUM(K10:K16) -> 0 | ... R17: =SUM(R10:R16) -> 0
A19: =WEEKNUM(B24) -> 33 | B19: =B16+1 -> 46243 | C19: Mon | D19: =SUM(E19:R19) -> 0 | E19: 0 | F19: 0 | G19: 0 | H19: 0 | I19: 0 | J19: 0 | K19: 0 | L19: 0 | M19: 0 | N19: 0 | O19: 0 | P19: 0 | Q19: 0 | R19: 0
B20: =B19+1 -> 46244 | C20: Tue | D20: =SUM(E20:R20) -> 0 | E20: 0 | F20: 0 | G20: 0 | H20: 0 | I20: 0 | J20: 0 | K20: 0 | L20: 0 | M20: 0 | N20: 0 | O20: 0 | P20: 0 | Q20: 0 | R20: 0
B21: =B20+1 -> 46245 | C21: Wed | D21: =SUM(E21:R21) -> 0 | E21: 0 | F21: 0 | G21: 0 | H21: 0 | I21: 0 | J21: 0 | K21: 0 | L21: 0 | M21: 0 | N21: 0 | O21: 0 | P21: 0 | Q21: 0 | R21: 0
B22: =B21+1 -> 46246 | C22: Thu | D22: =SUM(E22:R22) -> 0 | E22: 0 | F22: 0 | G22: 0 | H22: 0 | I22: 0 | J22: 0 | K22: 0 | L22: 0 | M22: 0 | N22: 0 | O22: 0 | P22: 0 | Q22: 0 | R22: 0
B23: =B22+1 -> 46247 | C23: Fri | D23: =SUM(E23:R23) -> 0 | E23: 0 | F23: 0 | G23: 0 | H23: 0 | I23: 0 | J23: 0 | K23: 0 | L23: 0 | M23: 0 | N23: 0 | O23: 0 | P23: 0 | Q23: 0 | R23: 0
B24: =B23+1 -> 46248 | C24: Sat | D24: =SUM(E24:R24) -> 0 | E24: 0 | F24: 0 | G24: 0 | H24: 0 | I24: 0 | J24: 0 | K24: 0 | L24: 0 | M24: 0 | N24: 0 | O24: 0 | P24: 0 | Q24: 0 | R24: 0
B25: =B24+1 -> 46249 | C25: Sun | D25: =SUM(E25:R25) -> 0 | E25: 0 | F25: 0 | G25: 0 | H25: 0 | I25: 0 | J25: 0 | K25: 0 | L25: 0 | M25: 0 | N25: 0 | O25: 0 | P25: 0 | Q25: 0 | R25: 0
B26: Sub Total | D26: =SUM(D19:D25) -> 0 | E26: =SUM(E19:E25) -> 0 | F26: =SUM(F19:F25) -> 0 | G26: =SUM(G19:G25) -> 0 | H26: =SUM(H19:H25) -> 0 | I26: =SUM(I19:I25) -> 0 | J26: =SUM(J19:J25) -> 0 | K26: =SUM(K19:K25) -> 0 | ... R26: =SUM(R19:R25) -> 0
A28: =WEEKNUM(B33) -> 34 | B28: =B25+1 -> 46250 | C28: Mon | D28: =SUM(E28:R28) -> 0 | E28: 0 | F28: 0 | G28: 0 | H28: 0 | I28: 0 | J28: 0 | K28: 0 | L28: 0 | M28: 0 | N28: 0 | O28: 0 | P28: 0 | Q28: 0 | R28: 0
B29: =B28+1 -> 46251 | C29: Tue | D29: =SUM(E29:R29) -> 0 | E29: 0 | F29: 0 | G29: 0 | H29: 0 | I29: 0 | J29: 0 | K29: 0 | L29: 0 | M29: 0 | N29: 0 | O29: 0 | P29: 0 | Q29: 0 | R29: 0
B30: =B29+1 -> 46252 | C30: Wed | D30: =SUM(E30:R30) -> 0 | E30: 0 | F30: 0 | G30: 0 | H30: 0 | I30: 0 | J30: 0 | K30: 0 | L30: 0 | M30: 0 | N30: 0 | O30: 0 | P30: 0 | Q30: 0 | R30: 0
B31: =B30+1 -> 46253 | C31: Thu | D31: =SUM(E31:R31) -> 0 | E31: 0 | F31: 0 | G31: 0 | H31: 0 | I31: 0 | J31: 0 | K31: 0 | L31: 0 | M31: 0 | N31: 0 | O31: 0 | P31: 0 | Q31: 0 | R31: 0
B32: =B31+1 -> 46254 | C32: Fri | D32: =SUM(E32:R32) -> 0 | E32: 0 | F32: 0 | G32: 0 | H32: 0 | I32: 0 | J32: 0 | K32: 0 | L32: 0 | M32: 0 | N32: 0 | O32: 0 | P32: 0 | Q32: 0 | R32: 0
B33: =B32+1 -> 46255 | C33: Sat | D33: =SUM(E33:R33) -> 0 | E33: 0 | F33: 0 | G33: 0 | H33: 0 | I33: 0 | J33: 0 | K33: 0 | L33: 0 | M33: 0 | N33: 0 | O33: 0 | P33: 0 | Q33: 0 | R33: 0
B34: =B33+1 -> 46256 | C34: Sun | D34: =SUM(E34:R34) -> 0 | E34: 0 | F34: 0 | G34: 0 | H34: 0 | I34: 0 | J34: 0 | K34: 0 | L34: 0 | M34: 0 | N34: 0 | O34: 0 | P34: 0 | Q34: 0 | R34: 0
B35: Sub Total | D35: =SUM(D28:D34) -> 0 | E35: =SUM(E28:E34) -> 0 | F35: =SUM(F28:F34) -> 0 | G35: =SUM(G28:G34) -> 0 | H35: =SUM(H28:H34) -> 0 | I35: =SUM(I28:I34) -> 0 | J35: =SUM(J28:J34) -> 0 | K35: =SUM(K28:K34) -> 0 | ... R35: =SUM(R28:R34) -> 0
A37: =WEEKNUM(B42) -> 35 | B37: =B34+1 -> 46257 | C37: Mon | D37: =SUM(E37:R37) -> 0 | E37: 0 | F37: 0 | G37: 0 | H37: 0 | I37: 0 | J37: 0 | K37: 0 | L37: 0 | M37: 0 | N37: 0 | O37: 0 | P37: 0 | Q37: 0 | R37: 0
B38: =B37+1 -> 46258 | C38: Tue | D38: =SUM(E38:R38) -> 0 | E38: 0 | F38: 0 | G38: 0 | H38: 0 | I38: 0 | J38: 0 | K38: 0 | L38: 0 | M38: 0 | N38: 0 | O38: 0 | P38: 0 | Q38: 0 | R38: 0
B39: =B38+1 -> 46259 | C39: Wed | D39: =SUM(E39:R39) -> 0 | E39: 0 | F39: 0 | G39: 0 | H39: 0 | I39: 0 | J39: 0 | K39: 0 | L39: 0 | M39: 0 | N39: 0 | O39: 0 | P39: 0 | Q39: 0 | R39: 0
B40: =B39+1 -> 46260 | C40: Thu | D40: =SUM(E40:R40) -> 0 | E40: 0 | F40: 0 | G40: 0 | H40: 0 | I40: 0 | J40: 0 | K40: 0 | L40: 0 | M40: 0 | N40: 0 | O40: 0 | P40: 0 | Q40: 0 | R40: 0
B41: =B40+1 -> 46261 | C41: Fri | D41: =SUM(E41:R41) -> 0 | E41: 0 | F41: 0 | G41: 0 | H41: 0 | I41: 0 | J41: 0 | K41: 0 | L41: 0 | M41: 0 | N41: 0 | O41: 0 | P41: 0 | Q41: 0 | R41: 0
B42: =B41+1 -> 46262 | C42: Sat | D42: =SUM(E42:R42) -> 0 | E42: 0 | F42: 0 | G42: 0 | H42: 0 | I42: 0 | J42: 0 | K42: 0 | L42: 0 | M42: 0 | N42: 0 | O42: 0 | P42: 0 | Q42: 0 | R42: 0
B43: =B42+1 -> 46263 | C43: Sun | D43: =SUM(E43:R43) -> 0 | E43: 0 | F43: 0 | G43: 0 | H43: 0 | I43: 0 | J43: 0 | K43: 0 | L43: 0 | M43: 0 | N43: 0 | O43: 0 | P43: 0 | Q43: 0 | R43: 0
B44: Sub Total | D44: =SUM(D37:D43) -> 0 | E44: =SUM(E37:E43) -> 0 | F44: =SUM(F37:F43) -> 0 | G44: =SUM(G37:G43) -> 0 | H44: =SUM(H37:H43) -> 0 | I44: =SUM(I37:I43) -> 0 | J44: =SUM(J37:J43) -> 0 | K44: =SUM(K37:K43) -> 0 | ... R44: =SUM(R37:R43) -> 0
A46: =WEEKNUM(B46) -> 36 | B46: =B43+1 -> 46264 | C46: Mon | D46: =SUM(E46:R46) -> 0 | E46: 0 | F46: 0 | G46: 0 | H46: 0 | I46: 0 | J46: 0 | K46: 0 | L46: 0 | M46: 0 | N46: 0 | O46: 0 | P46: 0 | Q46: 0 | R46: 0
B47: =B46+1 -> 46265 | C47: Tue | D47: =SUM(E47:R47) -> 0 | E47: 0 | F47: 0 | G47: 0 | H47: 0 | I47: 0 | J47: 0 | K47: 0 | L47: 0 | M47: 0 | N47: 0 | O47: 0 | P47: 0 | Q47: 0 | R47: 0
B48: Sub Total | D48: =SUM(D41:D47) -> 0 | E48: =SUM(E41:E47) -> 0 | F48: =SUM(F41:F47) -> 0 | G48: =SUM(G41:G47) -> 0 | H48: =SUM(H41:H47) -> 0 | I48: =SUM(I41:I47) -> 0 | J48: =SUM(J41:J47) -> 0 | K48: =SUM(K41:K47) -> 0 | ... R48: =SUM(R41:R47) -> 0
...

Sheet SO Oktober 2026 Rev3
A2: SALES ORDER | E2: =E6/24 -> 33.333333 | F2: =F6/24 -> 50 | G2: =G6/24 -> 137.5 | H2: =H6/24 -> 33.333333 | I2: =I6/24 -> 6.25 | J2: =J6/24 -> 25.156801 | K2: =K6/24 -> 28.053145 | L2: =L6/24 -> 229.16667 | ... O2: =O6/24 -> 520.83333 | P2: =P38/24 -> 0 | Q2: =Q6/24 -> 500 | R2: =R6/24 -> 125 | S2: =S6/24 -> 291.66667 | T2: =T6/24 -> 0 | U2: =U6/24 -> 20.833333 | V2: =V6/24 -> 270.83333 | W2: =W6/24 -> 41.666667 | X2: =X6/24 -> 0 | ... BC2: =BC6/24 -> 375
A3: 46296
V4: =V6/24 -> 270.83333
A5: Week | B5: DATE | D5: TOTAL | E5: CLIN | F5: MKG | G5: STM | H5: OAJ | I5: SHB | J5: GTL | K5: TWK | L5: BYC | M5: GF RANCA | N5: SMA | O5: UMI | P5: HLI | Q5: ASAHIMAS | R5: DIC | S5: HCI | T5: KSN | U5: ADP | V5: KSN RANCA | W5: NNI | X5: Greenpulse | Y5: Concord | Z5: ALT (KSO MASAMI) | AA5: IDP (KSO AAE) | AB5: WINGLOK (KSO EBM) | AC5: CISF (KSO RRS) | AD5: KGM (KSO RRS) | AE5: PUJ - LUBRICANT | AF5: CALBEE (KSO BMI) | AG5: KF | AH5: IP | AI5: BEM | AJ5: AMI | AK5: KA | AL5: KTN | AM5: NIAGA GARAM | AN5: PCI 84 | AO5: PCI MENGGER | AP5: INDOFOOD | AQ5: CERES | AR5: ABC KOGEN | AS5: TONGJI ( KSO GAS) | AT5: PA | AU5: RB | AV5: GF ATOM | AW5: GF KULIT | AX5: SDM | AY5: JARGAS | AZ5: SBI | BA5: DJARUM | BB5: SP GLOBAL | BC5: PENTAWIRA (KSO REN)
A6: =WEEKNUM(B6) -> 40 | B6: =A3 -> 46296 | C6: =TEXT(B6,"ddd") -> Thu | D6: =SUM(E6:BC6) -> 203407.46 | E6: 800 | F6: 1200 | G6: 3300 | H6: 800 | I6: 150 | J6: 603.76323 | K6: 673.27548 | L6: 5500 | M6: 5000 | N6: 1500 | O6: 12500 | P6: =10800 -> 10800 | Q6: 12000 | R6: 3000 | S6: 7000 | T6: 0 | U6: 500 | V6: 6500 | W6: 1000 | X6: 0 | Y6: 10000 | Z6: 1000 | AA6: 3000 | AB6: 89.451613 | AC6: 3000 | AD6: 1000 | AE6: 3000 | AF6: 0 | AG6: 2000 | AH6: 2000 | AI6: 800 | AJ6: 7200 | AK6: 2500 | AL6: 2000 | AM6: 1000 | AN6: 11000 | AO6: 2000 | AP6: 4500 | AQ6: 9000.0571 | AR6: 4000 | AS6: 3500 | AT6: 500 | AU6: 3500 | AV6: 2000 | AW6: 369.61071 | AX6: 1121.9003 | AY6: 2499.7026 | AZ6: 2499.7026 | BA6: 5000 | BB6: 31500 | BC6: =4500*2 -> 9000
B7: =B6+1 -> 46297 | C7: =TEXT(B7,"ddd") -> Fri | D7: =SUM(E7:BC7) -> 203306.98 | E7: 1199.5729 | F7: 1200 | G7: 3300 | H7: 800 | I7: 150 | J7: 603.76323 | K7: 673.27548 | L7: 5500 | M7: 5000 | N7: 1500 | O7: 12500 | P7: 10800 | Q7: 12000 | R7: 3000 | S7: 7000 | T7: 0 | U7: 500 | V7: 6500 | W7: 1000 | X7: 0 | Y7: 10000 | Z7: 1000 | AA7: 3000 | AB7: 89.451613 | AC7: 3000 | AD7: 1000 | AE7: 3000 | AF7: 0 | AG7: 2000 | AH7: 2000 | AI7: 800 | AJ7: 7200 | AK7: 2500 | AL7: 2000 | AM7: 1000 | AN7: 10000 | AO7: 2000 | AP7: 6000 | AQ7: 8000 | AR7: 4000 | AS7: 3500 | AT7: 500 | AU7: 3500 | AV7: 2000 | AW7: 369.61071 | AX7: 1121.9003 | AY7: 2499.7026 | AZ7: 2499.7026 | BA7: 5000 | BB7: 31500 | BC7: 9000
B8: =B7+1 -> 46298 | C8: =TEXT(B8,"ddd") -> Sat | D8: =SUM(E8:BC8) -> 199685.51 | E8: 700 | F8: 1000 | G8: 3300 | H8: 500 | I8: 150 | J8: 603.76323 | K8: 673.27548 | L8: 4500 | M8: 2000 | N8: 1000 | O8: 12500 | P8: 12800 | Q8: 30000 | R8: 3000 | S8: 3500 | T8: 0 | U8: 500 | V8: 6500 | W8: 1000 | X8: 0 | Y8: 10000 | Z8: 1000 | AA8: 3000 | AB8: 89.451613 | AC8: 3000 | AD8: 1000 | AE8: 0 | AF8: 0 | AG8: 0 | AH8: 2000 | AI8: 800 | AJ8: 7200 | AK8: 0 | AL8: 2000 | AM8: 1000 | AN8: 10000 | AO8: 2000 | AP8: 6000 | AQ8: 6000 | AR8: 4000 | AS8: 3500 | AT8: 500 | AU8: 3500 | AV8: 2000 | AW8: 369.61071 | AX8: 0 | AY8: 2499.7026 | AZ8: 2499.7026 | BA8: 1000 | BB8: 31500 | BC8: 9000
B9: =B8+1 -> 46299 | C9: =TEXT(B9,"ddd") -> Sun | D9: =SUM(E9:BC9) -> 192394.43 | E9: 700 | F9: 1000 | G9: 999.51613 | H9: 500 | I9: 0 | J9: 603.76323 | K9: 673.27548 | L9: 0 | M9: 2000 | N9: 300 | O9: 6659.5545 | P9: 16000 | Q9: 45000 | R9: 3000 | S9: 0 | T9: 0 | U9: 500 | V9: 6500 | W9: 1000 | X9: 0 | Y9: 10000 | Z9: 0 | AA9: 2500 | AB9: 89.451613 | AC9: 3000 | AD9: 1000 | AE9: 0 | AF9: 0 | AG9: 0 | AH9: 2000 | AI9: 0 | AJ9: 2999.8519 | AK9: 0 | AL9: 2000 | AM9: 0 | AN9: 10000 | AO9: 2000 | AP9: 6000 | AQ9: 5000 | AR9: 4000 | AS9: 3500 | AT9: 500 | AU9: 3500 | AV9: 2000 | AW9: 369.61071 | AX9: 0 | AY9: 2499.7026 | AZ9: 2499.7026 | BA9: 1000 | BB9: 31500 | BC9: 9000
B10: Sub Total | D10: =SUM(D6:D9) -> 798794.38 | E10: =SUM(E6:E9) -> 3399.5729 | F10: =SUM(F6:F9) -> 4400 | G10: =SUM(G6:G9) -> 10899.516 | H10: =SUM(H6:H9) -> 2600 | I10: =SUM(I6:I9) -> 450 | J10: =SUM(J6:J9) -> 2415.0529 | K10: =SUM(K6:K9) -> 2693.1019 | ... AE10: =SUM(AE6:AE9) -> 6000 | AF10: 0 | AG10: =SUM(AG6:AG9) -> 4000 | AH10: =SUM(AH6:AH9) -> 8000 | AI10: =SUM(AI6:AI9) -> 2400 | AJ10: =SUM(AJ6:AJ9) -> 24599.852 | AK10: =SUM(AK6:AK9) -> 5000 | AL10: =SUM(AL6:AL9) -> 8000 | AM10: =SUM(AM6:AM9) -> 3000 | AN10: =SUM(AN6:AN9) -> 41000 | ... BC10: =SUM(BC6:BC9) -> 36000
B12: =B9+1 -> 46300 | C12: =TEXT(B12,"ddd") -> Mon | D12: =SUM(E12:BC12) -> 203606.98 | E12: 1199.5729 | F12: 1200 | G12: 3300 | H12: 800 | I12: 150 | J12: 603.76323 | K12: 673.27548 | L12: 5500 | M12: 5000 | N12: 1500 | O12: 12500 | P12: 10800 | Q12: 12000 | R12: 3000 | S12: 7000 | T12: 0 | U12: 1300 | V12: 6500 | W12: 1000 | X12: 0 | Y12: 10000 | Z12: 1000 | AA12: 3000 | AB12: 89.451613 | AC12: 3000 | AD12: 1000 | AE12: 3000 | AF12: 0 | AG12: 2000 | AH12: 2000 | AI12: 800 | AJ12: 7200 | AK12: 2000 | AL12: 2000 | AM12: 1000 | AN12: 10000 | AO12: 2000 | AP12: 6000 | AQ12: 8000 | AR12: 4000 | AS12: 3500 | AT12: 500 | AU12: 3500 | AV12: 2000 | AW12: 369.61071 | AX12: 1121.9003 | AY12: 2499.7026 | AZ12: 2499.7026 | BA12: 5000 | BB12: 31500 | BC12: 9000
B13: =B12+1 -> 46301 | C13: =TEXT(B13,"ddd") -> Tue | D13: =SUM(E13:BC13) -> 203606.98 | E13: 1199.5729 | F13: 1200 | G13: 3300 | H13: 800 | I13: 150 | J13: 603.76323 | K13: 673.27548 | L13: 5500 | M13: 5000 | N13: 1500 | O13: 12500 | P13: 10800 | Q13: 12000 | R13: 3000 | S13: 7000 | T13: 0 | U13: 1300 | V13: 6500 | W13: 1000 | X13: 0 | Y13: 10000 | Z13: 1000 | AA13: 3000 | AB13: 89.451613 | AC13: 3000 | AD13: 1000 | AE13: 3000 | AF13: 0 | AG13: 2000 | AH13: 2000 | AI13: 800 | AJ13: 7200 | AK13: 2000 | AL13: 2000 | AM13: 1000 | AN13: 10000 | AO13: 2000 | AP13: 6000 | AQ13: 8000 | AR13: 4000 | AS13: 3500 | AT13: 500 | AU13: 3500 | AV13: 2000 | AW13: 369.61071 | AX13: 1121.9003 | AY13: 2499.7026 | AZ13: 2499.7026 | BA13: 5000 | BB13: 31500 | BC13: 9000
A14: =WEEKNUM(B12) -> 41 | B14: =B13+1 -> 46302 | C14: =TEXT(B14,"ddd") -> Wed | D14: =SUM(E14:BC14) -> 203606.98 | E14: 1199.5729 | F14: 1200 | G14: 3300 | H14: 800 | I14: 150 | J14: 603.76323 | K14: 673.27548 | L14: 5500 | M14: 5000 | N14: 1500 | O14: 12500 | P14: 10800 | Q14: 12000 | R14: 3000 | S14: 7000 | T14: 0 | U14: 1300 | V14: 6500 | W14: 1000 | X14: 0 | Y14: 10000 | Z14: 1000 | AA14: 3000 | AB14: 89.451613 | AC14: 3000 | AD14: 1000 | AE14: 3000 | AF14: 0 | AG14: 2000 | AH14: 2000 | AI14: 800 | AJ14: 7200 | AK14: 2000 | AL14: 2000 | AM14: 1000 | AN14: 10000 | AO14: 2000 | AP14: 6000 | AQ14: 8000 | AR14: 4000 | AS14: 3500 | AT14: 500 | AU14: 3500 | AV14: 2000 | AW14: 369.61071 | AX14: 1121.9003 | AY14: 2499.7026 | AZ14: 2499.7026 | BA14: 5000 | BB14: 31500 | BC14: 9000
B15: =B14+1 -> 46303 | C15: =TEXT(B15,"ddd") -> Thu | D15: =SUM(E15:BC15) -> 205606.98 | E15: 1199.5729 | F15: 1200 | G15: 3300 | H15: 800 | I15: 150 | J15: 603.76323 | K15: 673.27548 | L15: 5500 | M15: 5000 | N15: 1500 | O15: 12500 | P15: 10800 | Q15: 12000 | R15: 3000 | S15: 7000 | T15: 0 | U15: 1300 | V15: 6500 | W15: 1000 | X15: 2000 | Y15: 10000 | Z15: 1000 | AA15: 3000 | AB15: 89.451613 | AC15: 3000 | AD15: 1000 | AE15: 3000 | AF15: 0 | AG15: 2000 | AH15: 2000 | AI15: 800 | AJ15: 7200 | AK15: 2000 | AL15: 2000 | AM15: 1000 | AN15: 10000 | AO15: 2000 | AP15: 6000 | AQ15: 8000 | AR15: 4000 | AS15: 3500 | AT15: 500 | AU15: 3500 | AV15: 2000 | AW15: 369.61071 | AX15: 1121.9003 | AY15: 2499.7026 | AZ15: 2499.7026 | BA15: 5000 | BB15: 31500 | BC15: 9000
B16: =B15+1 -> 46304 | C16: =TEXT(B16,"ddd") -> Fri | D16: =SUM(E16:BC16) -> 205606.98 | E16: 1199.5729 | F16: 1200 | G16: 3300 | H16: 800 | I16: 150 | J16: 603.76323 | K16: 673.27548 | L16: 5500 | M16: 5000 | N16: 1500 | O16: 12500 | P16: 10800 | Q16: 12000 | R16: 3000 | S16: 7000 | T16: 0 | U16: 1300 | V16: 6500 | W16: 1000 | X16: 2000 | Y16: 10000 | Z16: 1000 | AA16: 3000 | AB16: 89.451613 | AC16: 3000 | AD16: 1000 | AE16: 3000 | AF16: 0 | AG16: 2000 | AH16: 2000 | AI16: 800 | AJ16: 7200 | AK16: 2000 | AL16: 2000 | AM16: 1000 | AN16: 10000 | AO16: 2000 | AP16: 6000 | AQ16: 8000 | AR16: 4000 | AS16: 3500 | AT16: 500 | AU16: 3500 | AV16: 2000 | AW16: 369.61071 | AX16: 1121.9003 | AY16: 2499.7026 | AZ16: 2499.7026 | BA16: 5000 | BB16: 31500 | BC16: 9000
B17: =B16+1 -> 46305 | C17: =TEXT(B17,"ddd") -> Sat | D17: =SUM(E17:BC17) -> 202485.51 | E17: 700 | F17: 1000 | G17: 3300 | H17: 500 | I17: 150 | J17: 603.76323 | K17: 673.27548 | L17: 4500 | M17: 2000 | N17: 1000 | O17: 12500 | P17: 12800 | Q17: 30000 | R17: 3000 | S17: 3500 | T17: 0 | U17: 1300 | V17: 6500 | W17: 1000 | X17: 2000 | Y17: 10000 | Z17: 1000 | AA17: 3000 | AB17: 89.451613 | AC17: 3000 | AD17: 1000 | AE17: 0 | AF17: 0 | AG17: 0 | AH17: 2000 | AI17: 800 | AJ17: 7200 | AK17: 0 | AL17: 2000 | AM17: 1000 | AN17: 10000 | AO17: 2000 | AP17: 6000 | AQ17: 6000 | AR17: 4000 | AS17: 3500 | AT17: 500 | AU17: 3500 | AV17: 2000 | AW17: 369.61071 | AX17: 0 | AY17: 2499.7026 | AZ17: 2499.7026 | BA17: 1000 | BB17: 31500 | BC17: 9000
B18: =B17+1 -> 46306 | C18: =TEXT(B18,"ddd") -> Sun | D18: =SUM(E18:BC18) -> 192694.43 | E18: 700 | F18: 1000 | G18: 999.51613 | H18: 500 | I18: 0 | J18: 603.76323 | K18: 673.27548 | L18: 0 | M18: 2000 | N18: 300 | O18: 6659.5545 | P18: 16000 | Q18: 45000 | R18: 3000 | S18: 0 | T18: 0 | U18: 1300 | V18: 6500 | W18: 0 | X18: 2000 | Y18: 10000 | Z18: 0 | AA18: 2500 | AB18: 89.451613 | AC18: 3000 | AD18: 1000 | AE18: 0 | AF18: 0 | AG18: 0 | AH18: 500 | AI18: 0 | AJ18: 2999.8519 | AK18: 0 | AL18: 2000 | AM18: 0 | AN18: 10000 | AO18: 2000 | AP18: 6000 | AQ18: 5000 | AR18: 4000 | AS18: 3500 | AT18: 500 | AU18: 3500 | AV18: 2000 | AW18: 369.61071 | AX18: 0 | AY18: 2499.7026 | AZ18: 2499.7026 | BA18: 1000 | BB18: 31500 | BC18: 9000
B19: Sub Total | D19: =SUM(D12:D18) -> 1417214.8 | E19: =SUM(E12:E18) -> 7397.8645 | F19: =SUM(F12:F18) -> 8000 | G19: =SUM(G12:G18) -> 20799.516 | H19: =SUM(H12:H18) -> 5000 | I19: =SUM(I12:I18) -> 900 | J19: =SUM(J12:J18) -> 4226.3426 | K19: =SUM(K12:K18) -> 4712.9284 | ... AE19: =SUM(AE12:AE18) -> 15000 | AF19: 0 | AG19: =SUM(AG12:AG18) -> 10000 | AH19: =SUM(AH12:AH18) -> 12500 | AI19: =SUM(AI12:AI18) -> 4800 | AJ19: =SUM(AJ12:AJ18) -> 46199.852 | AK19: =SUM(AK12:AK18) -> 10000 | AL19: =SUM(AL12:AL18) -> 14000 | AM19: =SUM(AM12:AM18) -> 6000 | AN19: =SUM(AN12:AN18) -> 70000 | ... BC19: =SUM(BC12:BC18) -> 63000
B21: =B18+1 -> 46307 | C21: =TEXT(B21,"ddd") -> Mon | D21: =SUM(E21:BC21) -> 211606.98 | E21: 1199.5729 | F21: 1200 | G21: 3300 | H21: 800 | I21: 150 | J21: 603.76323 | K21: 673.27548 | L21: 5500 | M21: 5000 | N21: 1500 | O21: 12500 | P21: 10800 | Q21: 12000 | R21: 3000 | S21: 12000 | T21: 0 | U21: 1300 | V21: 6500 | W21: 1000 | X21: 2000 | Y21: 10000 | Z21: 1000 | AA21: 3000 | AB21: 89.451613 | AC21: 3000 | AD21: 1000 | AE21: 3000 | AF21: 0 | AG21: 2000 | AH21: 2000 | AI21: 800 | AJ21: 7200 | AK21: 2000 | AL21: 2000 | AM21: 1000 | AN21: 10000 | AO21: 2000 | AP21: 6000 | AQ21: 8000 | AR21: 5000 | AS21: 3500 | AT21: 500 | AU21: 3500 | AV21: 2000 | AW21: 369.61071 | AX21: 1121.9003 | AY21: 2499.7026 | AZ21: 2499.7026 | BA21: 5000 | BB21: 31500 | BC21: 9000
B22: =B21+1 -> 46308 | C22: =TEXT(B22,"ddd") -> Tue | D22: =SUM(E22:BC22) -> 228606.98 | E22: 1199.5729 | F22: 1200 | G22: 3300 | H22: 800 | I22: 150 | J22: 603.76323 | K22: 673.27548 | L22: 5500 | M22: 5000 | N22: 2000 | O22: 9000 | P22: 10800 | Q22: 17000 | R22: 5000 | S22: 12000 | T22: 4000 | U22: 1300 | V22: 6500 | W22: 1000 | X22: 7000 | Y22: 10000 | Z22: 1000 | AA22: 5500 | AB22: 89.451613 | AC22: 3500 | AD22: 1000 | AE22: 3000 | AF22: 0 | AG22: 3000 | AH22: 2000 | AI22: 800 | AJ22: 7200 | AK22: 2000 | AL22: 2000 | AM22: 1000 | AN22: 10000 | AO22: 2000 | AP22: 6000 | AQ22: 8000 | AR22: 5000 | AS22: 3500 | AT22: 500 | AU22: 3500 | AV22: 2000 | AW22: 369.61071 | AX22: 1121.9003 | AY22: 2499.7026 | AZ22: 2499.7026 | BA22: 5000 | BB22: 31500 | BC22: 9000
A23: =WEEKNUM(B21) -> 42 | B23: =B22+1 -> 46309 | C23: =TEXT(B23,"ddd") -> Wed | D23: =SUM(E23:BC23) -> 222806.98 | E23: 1199.5729 | F23: 1200 | G23: 3300 | H23: 800 | I23: 150 | J23: 603.76323 | K23: 673.27548 | L23: 5500 | M23: 4000 | N23: 2000 | O23: 9000 | P23: 10800 | Q23: 17000 | R23: 5000 | S23: 12000 | T23: 4000 | U23: 1000 | V23: 6500 | W23: 0 | X23: 5000 | Y23: 10000 | Z23: 1000 | AA23: 5500 | AB23: 89.451613 | AC23: 3500 | AD23: 1000 | AE23: 3000 | AF23: 0 | AG23: 2000 | AH23: 2000 | AI23: 800 | AJ23: 7200 | AK23: 2000 | AL23: 1500 | AM23: 1000 | AN23: 10000 | AO23: 2000 | AP23: 6000 | AQ23: 8000 | AR23: 5000 | AS23: 3500 | AT23: 500 | AU23: 3500 | AV23: 2000 | AW23: 369.61071 | AX23: 1121.9003 | AY23: 2499.7026 | AZ23: 2499.7026 | BA23: 5000 | BB23: 31500 | BC23: 9000
B24: =B23+1 -> 46310 | C24: =TEXT(B24,"ddd") -> Thu | D24: =SUM(E24:BC24) -> 224806.98 | E24: 1199.5729 | F24: 1200 | G24: 3300 | H24: 800 | I24: 150 | J24: 603.76323 | K24: 673.27548 | L24: 5500 | M24: 4000 | N24: 2000 | O24: 9000 | P24: 10800 | Q24: 17000 | R24: 5000 | S24: 12000 | T24: 4000 | U24: 1000 | V24: 6500 | W24: 0 | X24: 5000 | Y24: 10000 | Z24: 1000 | AA24: 5500 | AB24: 89.451613 | AC24: 3500 | AD24: 1000 | AE24: 3000 | AF24: 0 | AG24: 2000 | AH24: 2000 | AI24: 800 | AJ24: 7200 | AK24: 2000 | AL24: 1500 | AM24: 1000 | AN24: 10000 | AO24: 2000 | AP24: 6000 | AQ24: 8000 | AR24: 7000 | AS24: 3500 | AT24: 500 | AU24: 3500 | AV24: 2000 | AW24: 369.61071 | AX24: 1121.9003 | AY24: 2499.7026 | AZ24: 2499.7026 | BA24: 5000 | BB24: 31500 | BC24: 9000
B25: =B24+1 -> 46311 | C25: =TEXT(B25,"ddd") -> Fri | D25: =SUM(E25:BC25) -> 224806.98 | E25: 1199.5729 | F25: 1200 | G25: 3300 | H25: 800 | I25: 150 | J25: 603.76323 | K25: 673.27548 | L25: 5500 | M25: 4000 | N25: 2000 | O25: 9000 | P25: 10800 | Q25: 17000 | R25: 5000 | S25: 12000 | T25: 4000 | U25: 1000 | V25: 6500 | W25: 0 | X25: 5000 | Y25: 10000 | Z25: 1000 | AA25: 5500 | AB25: 89.451613 | AC25: 3500 | AD25: 1000 | AE25: 3000 | AF25: 0 | AG25: 2000 | AH25: 2000 | AI25: 800 | AJ25: 7200 | AK25: 2000 | AL25: 1500 | AM25: 1000 | AN25: 10000 | AO25: 2000 | AP25: 6000 | AQ25: 8000 | AR25: 7000 | AS25: 3500 | AT25: 500 | AU25: 3500 | AV25: 2000 | AW25: 369.61071 | AX25: 1121.9003 | AY25: 2499.7026 | AZ25: 2499.7026 | BA25: 5000 | BB25: 31500 | BC25: 9000
B26: =B25+1 -> 46312 | C26: =TEXT(B26,"ddd") -> Sat | D26: =SUM(E26:BC26) -> 215685.51 | E26: 700 | F26: 1000 | G26: 3300 | H26: 500 | I26: 150 | J26: 603.76323 | K26: 673.27548 | L26: 4500 | M26: 4000 | N26: 1000 | O26: 9000 | P26: 10800 | Q26: 25000 | R26: 5000 | S26: 12000 | T26: 4000 | U26: 1000 | V26: 6500 | W26: 0 | X26: 5000 | Y26: 10000 | Z26: 1000 | AA26: 5500 | AB26: 89.451613 | AC26: 3500 | AD26: 1000 | AE26: 0 | AF26: 0 | AG26: 0 | AH26: 2000 | AI26: 800 | AJ26: 7200 | AK26: 0 | AL26: 1500 | AM26: 1000 | AN26: 10000 | AO26: 2000 | AP26: 6000 | AQ26: 6000 | AR26: 7000 | AS26: 3500 | AT26: 500 | AU26: 3500 | AV26: 2000 | AW26: 369.61071 | AX26: 0 | AY26: 2499.7026 | AZ26: 2499.7026 | BA26: 1000 | BB26: 31500 | BC26: 9000
B27: =B26+1 -> 46313 | C27: =TEXT(B27,"ddd") -> Sun | D27: =SUM(E27:BC27) -> 178694.43 | E27: 700 | F27: 1000 | G27: 999.51613 | H27: 500 | I27: 0 | J27: 603.76323 | K27: 673.27548 | L27: 0 | M27: 4000 | N27: 300 | O27: 6659.5545 | P27: 10800 | Q27: 25000 | R27: 5000 | S27: 0 | T27: 4000 | U27: 1000 | V27: 6500 | W27: 0 | X27: 5000 | Y27: 10000 | Z27: 0 | AA27: 2500 | AB27: 89.451613 | AC27: 1000 | AD27: 1000 | AE27: 0 | AF27: 0 | AG27: 0 | AH27: 500 | AI27: 0 | AJ27: 2999.8519 | AK27: 0 | AL27: 1500 | AM27: 0 | AN27: 10000 | AO27: 2000 | AP27: 6000 | AQ27: 5000 | AR27: 7000 | AS27: 3500 | AT27: 500 | AU27: 3500 | AV27: 2000 | AW27: 369.61071 | AX27: 0 | AY27: 2499.7026 | AZ27: 2499.7026 | BA27: 1000 | BB27: 31500 | BC27: 9000
B28: Sub Total | D28: =SUM(D21:D27) -> 1507014.8 | E28: =SUM(E21:E27) -> 7397.8645 | F28: =SUM(F21:F27) -> 8000 | G28: =SUM(G21:G27) -> 20799.516 | H28: =SUM(H21:H27) -> 5000 | I28: =SUM(I21:I27) -> 900 | J28: =SUM(J21:J27) -> 4226.3426 | K28: =SUM(K21:K27) -> 4712.9284 | ... AE28: =SUM(AE21:AE27) -> 15000 | AF28: 0 | AG28: =SUM(AG21:AG27) -> 11000 | AH28: =SUM(AH21:AH27) -> 12500 | AI28: =SUM(AI21:AI27) -> 4800 | AJ28: =SUM(AJ21:AJ27) -> 46199.852 | AK28: =SUM(AK21:AK27) -> 10000 | AL28: =SUM(AL21:AL27) -> 11500 | AM28: =SUM(AM21:AM27) -> 6000 | AN28: =SUM(AN21:AN27) -> 70000 | ... BC28: =SUM(BC21:BC27) -> 63000
B30: =B27+1 -> 46314 | C30: =TEXT(B30,"ddd") -> Mon | D30: =SUM(E30:BC30) -> 234806.98 | E30: 1199.5729 | F30: 1200 | G30: 3300 | H30: 800 | I30: 150 | J30: 603.76323 | K30: 673.27548 | L30: 5500 | M30: 4000 | N30: 2000 | O30: 9000 | P30: 10800 | Q30: 17000 | R30: 5000 | S30: 12000 | T30: 4000 | U30: 1000 | V30: 6500 | W30: 8000 | X30: 7000 | Y30: 10000 | Z30: 1000 | AA30: 5500 | AB30: 89.451613 | AC30: 3500 | AD30: 1000 | AE30: 3000 | AF30: 0 | AG30: 2000 | AH30: 2000 | AI30: 800 | AJ30: 7200 | AK30: 2000 | AL30: 1500 | AM30: 1000 | AN30: 10000 | AO30: 2000 | AP30: 6000 | AQ30: 8000 | AR30: 7000 | AS30: 3500 | AT30: 500 | AU30: 3500 | AV30: 2000 | AW30: 369.61071 | AX30: 1121.9003 | AY30: 2499.7026 | AZ30: 2499.7026 | BA30: 5000 | BB30: 31500 | BC30: 9000
B31: =B30+1 -> 46315 | C31: =TEXT(B31,"ddd") -> Tue | D31: =SUM(E31:BC31) -> 244806.98 | E31: 1199.5729 | F31: 1200 | G31: 3300 | H31: 800 | I31: 150 | J31: 603.76323 | K31: 673.27548 | L31: 5500 | M31: 4000 | N31: 2000 | O31: 9000 | P31: 10800 | Q31: 17000 | R31: 5000 | S31: 12000 | T31: 4000 | U31: 1000 | V31: 6500 | W31: 8000 | X31: 7000 | Y31: 20000 | Z31: 1000 | AA31: 5500 | AB31: 89.451613 | AC31: 3500 | AD31: 1000 | AE31: 3000 | AF31: 0 | AG31: 2000 | AH31: 2000 | AI31: 800 | AJ31: 7200 | AK31: 2000 | AL31: 1500 | AM31: 1000 | AN31: 10000 | AO31: 2000 | AP31: 6000 | AQ31: 8000 | AR31: 7000 | AS31: 3500 | AT31: 500 | AU31: 3500 | AV31: 2000 | AW31: 369.61071 | AX31: 1121.9003 | AY31: 2499.7026 | AZ31: 2499.7026 | BA31: 5000 | BB31: 31500 | BC31: 9000
A32: =WEEKNUM(B30) -> 43 | B32: =B31+1 -> 46316 | C32: =TEXT(B32,"ddd") -> Wed | D32: =SUM(E32:BC32) -> 257106.98 | E32: 1199.5729 | F32: 1200 | G32: 3300 | H32: 800 | I32: 150 | J32: 603.76323 | K32: 673.27548 | L32: 5500 | M32: 4000 | N32: 2500 | O32: 16000 | P32: 15600 | Q32: 17000 | R32: 5000 | S32: 12000 | T32: 4000 | U32: 1000 | V32: 6500 | W32: 8000 | X32: 7000 | Y32: 20000 | Z32: 1000 | AA32: 5500 | AB32: 89.451613 | AC32: 3500 | AD32: 1000 | AE32: 3000 | AF32: 0 | AG32: 2000 | AH32: 2000 | AI32: 800 | AJ32: 7200 | AK32: 2000 | AL32: 1500 | AM32: 1000 | AN32: 10000 | AO32: 2000 | AP32: 6000 | AQ32: 8000 | AR32: 7000 | AS32: 3500 | AT32: 500 | AU32: 3500 | AV32: 2000 | AW32: 369.61071 | AX32: 1121.9003 | AY32: 2499.7026 | AZ32: 2499.7026 | BA32: 5000 | BB32: 31500 | BC32: 9000
B33: =B32+1 -> 46317 | C33: =TEXT(B33,"ddd") -> Thu | D33: =SUM(E33:BC33) -> 257106.98 | E33: 1199.5729 | F33: 1200 | G33: 3300 | H33: 800 | I33: 150 | J33: 603.76323 | K33: 673.27548 | L33: 5500 | M33: 4000 | N33: 2500 | O33: 16000 | P33: 15600 | Q33: 17000 | R33: 5000 | S33: 12000 | T33: 4000 | U33: 1000 | V33: 6500 | W33: 8000 | X33: 7000 | Y33: 20000 | Z33: 1000 | AA33: 5500 | AB33: 89.451613 | AC33: 3500 | AD33: 1000 | AE33: 3000 | AF33: 0 | AG33: 2000 | AH33: 2000 | AI33: 800 | AJ33: 7200 | AK33: 2000 | AL33: 1500 | AM33: 1000 | AN33: 10000 | AO33: 2000 | AP33: 6000 | AQ33: 8000 | AR33: 7000 | AS33: 3500 | AT33: 500 | AU33: 3500 | AV33: 2000 | AW33: 369.61071 | AX33: 1121.9003 | AY33: 2499.7026 | AZ33: 2499.7026 | BA33: 5000 | BB33: 31500 | BC33: 9000
B34: =B33+1 -> 46318 | C34: =TEXT(B34,"ddd") -> Fri | D34: =SUM(E34:BC34) -> 257106.98 | E34: 1199.5729 | F34: 1200 | G34: 3300 | H34: 800 | I34: 150 | J34: 603.76323 | K34: 673.27548 | L34: 5500 | M34: 4000 | N34: 2500 | O34: 16000 | P34: 15600 | Q34: 17000 | R34: 5000 | S34: 12000 | T34: 4000 | U34: 1000 | V34: 6500 | W34: 8000 | X34: 7000 | Y34: 20000 | Z34: 1000 | AA34: 5500 | AB34: 89.451613 | AC34: 3500 | AD34: 1000 | AE34: 3000 | AF34: 0 | AG34: 2000 | AH34: 2000 | AI34: 800 | AJ34: 7200 | AK34: 2000 | AL34: 1500 | AM34: 1000 | AN34: 10000 | AO34: 2000 | AP34: 6000 | AQ34: 8000 | AR34: 7000 | AS34: 3500 | AT34: 500 | AU34: 3500 | AV34: 2000 | AW34: 369.61071 | AX34: 1121.9003 | AY34: 2499.7026 | AZ34: 2499.7026 | BA34: 5000 | BB34: 31500 | BC34: 9000
B35: =B34+1 -> 46319 | C35: =TEXT(B35,"ddd") -> Sat | D35: =SUM(E35:BC35) -> 255485.51 | E35: 700 | F35: 1000 | G35: 3300 | H35: 500 | I35: 150 | J35: 603.76323 | K35: 673.27548 | L35: 4500 | M35: 4000 | N35: 1000 | O35: 16000 | P35: 15600 | Q35: =25000+8000 -> 33000 | R35: 5000 | S35: 12000 | T35: 4000 | U35: 1000 | V35: 6500 | W35: 8000 | X35: 7000 | Y35: 20000 | Z35: 1000 | AA35: 5500 | AB35: 89.451613 | AC35: 3500 | AD35: 1000 | AE35: 0 | AF35: 0 | AG35: 0 | AH35: 2000 | AI35: 800 | AJ35: 7200 | AK35: 0 | AL35: 1500 | AM35: 1000 | AN35: 10000 | AO35: 2000 | AP35: 6000 | AQ35: 6000 | AR35: 7000 | AS35: 3500 | AT35: 500 | AU35: 3500 | AV35: 2000 | AW35: 369.61071 | AX35: 0 | AY35: 2499.7026 | AZ35: 2499.7026 | BA35: 1000 | BB35: 31500 | BC35: 9000
B36: =B35+1 -> 46320 | C36: =TEXT(B36,"ddd") -> Sun | D36: =SUM(E36:BC36) -> 223494.43 | E36: 700 | F36: 1000 | G36: 999.51613 | H36: 500 | I36: 0 | J36: 603.76323 | K36: 673.27548 | L36: 0 | M36: 4000 | N36: 300 | O36: 6659.5545 | P36: 15600 | Q36: =25000+20000 -> 45000 | R36: 5000 | S36: 0 | T36: 4000 | U36: 1000 | V36: 6500 | W36: 8000 | X36: 7000 | Y36: 20000 | Z36: 0 | AA36: 2500 | AB36: 89.451613 | AC36: 1000 | AD36: 1000 | AE36: 0 | AF36: 0 | AG36: 0 | AH36: 500 | AI36: 0 | AJ36: 2999.8519 | AK36: 0 | AL36: 1500 | AM36: 0 | AN36: 10000 | AO36: 2000 | AP36: 6000 | AQ36: 5000 | AR36: 7000 | AS36: 3500 | AT36: 500 | AU36: 3500 | AV36: 2000 | AW36: 369.61071 | AX36: 0 | AY36: 2499.7026 | AZ36: 2499.7026 | BA36: 1000 | BB36: 31500 | BC36: 9000
B37: Sub Total | D37: =SUM(D30:D36) -> 1729914.8 | E37: =SUM(E30:E36) -> 7397.8645 | F37: =SUM(F30:F36) -> 8000 | G37: =SUM(G30:G36) -> 20799.516 | H37: =SUM(H30:H36) -> 5000 | I37: =SUM(I30:I36) -> 900 | J37: =SUM(J30:J36) -> 4226.3426 | K37: =SUM(K30:K36) -> 4712.9284 | ... AE37: =SUM(AE30:AE36) -> 15000 | AF37: 0 | AG37: =SUM(AG30:AG36) -> 10000 | AH37: =SUM(AH30:AH36) -> 12500 | AI37: =SUM(AI30:AI36) -> 4800 | AJ37: =SUM(AJ30:AJ36) -> 46199.852 | AK37: =SUM(AK30:AK36) -> 10000 | AL37: =SUM(AL30:AL36) -> 10500 | AM37: =SUM(AM30:AM36) -> 6000 | AN37: =SUM(AN30:AN36) -> 70000 | ... BC37: =SUM(BC30:BC36) -> 63000
B39: =B36+1 -> 46321 | C39: =TEXT(B39,"ddd") -> Mon | D39: =SUM(E39:BC39) -> 257106.98 | E39: 1199.5729 | F39: 1200 | G39: 3300 | H39: 800 | I39: 150 | J39: 603.76323 | K39: 673.27548 | L39: 5500 | M39: 4000 | N39: 2500 | O39: 16000 | P39: 15600 | Q39: 17000 | R39: 5000 | S39: 12000 | T39: 4000 | U39: 1000 | V39: 6500 | W39: 8000 | X39: 7000 | Y39: 20000 | Z39: 1000 | AA39: 5500 | AB39: 89.451613 | AC39: 3500 | AD39: 1000 | AE39: 3000 | AF39: 0 | AG39: 2000 | AH39: 2000 | AI39: 800 | AJ39: 7200 | AK39: 2000 | AL39: 1500 | AM39: 1000 | AN39: 10000 | AO39: 2000 | AP39: 6000 | AQ39: 8000 | AR39: 7000 | AS39: 3500 | AT39: 500 | AU39: 3500 | AV39: 2000 | AW39: 369.61071 | AX39: 1121.9003 | AY39: 2499.7026 | AZ39: 2499.7026 | BA39: 5000 | BB39: 31500 | BC39: 9000
B40: =B39+1 -> 46322 | C40: =TEXT(B40,"ddd") -> Tue | D40: =SUM(E40:BC40) -> 257106.98 | E40: 1199.5729 | F40: 1200 | G40: 3300 | H40: 800 | I40: 150 | J40: 603.76323 | K40: 673.27548 | L40: 5500 | M40: 4000 | N40: 2500 | O40: 16000 | P40: 15600 | Q40: 17000 | R40: 5000 | S40: 12000 | T40: 4000 | U40: 1000 | V40: 6500 | W40: 8000 | X40: 7000 | Y40: 20000 | Z40: 1000 | AA40: 5500 | AB40: 89.451613 | AC40: 3500 | AD40: 1000 | AE40: 3000 | AF40: 0 | AG40: 2000 | AH40: 2000 | AI40: 800 | AJ40: 7200 | AK40: 2000 | AL40: 1500 | AM40: 1000 | AN40: 10000 | AO40: 2000 | AP40: 6000 | AQ40: 8000 | AR40: 7000 | AS40: 3500 | AT40: 500 | AU40: 3500 | AV40: 2000 | AW40: 369.61071 | AX40: 1121.9003 | AY40: 2499.7026 | AZ40: 2499.7026 | BA40: 5000 | BB40: 31500 | BC40: 9000
A41: =WEEKNUM(B39) -> 44 | B41: =B40+1 -> 46323 | C41: =TEXT(B41,"ddd") -> Wed | D41: =SUM(E41:BC41) -> 257106.98 | E41: 1199.5729 | F41: 1200 | G41: 3300 | H41: 800 | I41: 150 | J41: 603.76323 | K41: 673.27548 | L41: 5500 | M41: 4000 | N41: 2500 | O41: 16000 | P41: 15600 | Q41: 17000 | R41: 5000 | S41: 12000 | T41: 4000 | U41: 1000 | V41: 6500 | W41: 8000 | X41: 7000 | Y41: 20000 | Z41: 1000 | AA41: 5500 | AB41: 89.451613 | AC41: 3500 | AD41: 1000 | AE41: 3000 | AF41: 0 | AG41: 2000 | AH41: 2000 | AI41: 800 | AJ41: 7200 | AK41: 2000 | AL41: 1500 | AM41: 1000 | AN41: 10000 | AO41: 2000 | AP41: 6000 | AQ41: 8000 | AR41: 7000 | AS41: 3500 | AT41: 500 | AU41: 3500 | AV41: 2000 | AW41: 369.61071 | AX41: 1121.9003 | AY41: 2499.7026 | AZ41: 2499.7026 | BA41: 5000 | BB41: 31500 | BC41: 9000
B42: =B41+1 -> 46324 | C42: =TEXT(B42,"ddd") -> Thu | D42: =SUM(E42:BC42) -> 257106.98 | E42: 1199.5729 | F42: 1200 | G42: 3300 | H42: 800 | I42: 150 | J42: 603.76323 | K42: 673.27548 | L42: 5500 | M42: 4000 | N42: 2500 | O42: 16000 | P42: 15600 | Q42: 17000 | R42: 5000 | S42: 12000 | T42: 4000 | U42: 1000 | V42: 6500 | W42: 8000 | X42: 7000 | Y42: 20000 | Z42: 1000 | AA42: 5500 | AB42: 89.451613 | AC42: 3500 | AD42: 1000 | AE42: 3000 | AF42: 0 | AG42: 2000 | AH42: 2000 | AI42: 800 | AJ42: 7200 | AK42: 2000 | AL42: 1500 | AM42: 1000 | AN42: 10000 | AO42: 2000 | AP42: 6000 | AQ42: 8000 | AR42: 7000 | AS42: 3500 | AT42: 500 | AU42: 3500 | AV42: 2000 | AW42: 369.61071 | AX42: 1121.9003 | AY42: 2499.7026 | AZ42: 2499.7026 | BA42: 5000 | BB42: 31500 | BC42: 9000
B43: =B42+1 -> 46325 | C43: =TEXT(B43,"ddd") -> Fri | D43: =SUM(E43:BC43) -> 257106.98 | E43: 1199.5729 | F43: 1200 | G43: 3300 | H43: 800 | I43: 150 | J43: 603.76323 | K43: 673.27548 | L43: 5500 | M43: 4000 | N43: 2500 | O43: 16000 | P43: 15600 | Q43: 17000 | R43: 5000 | S43: 12000 | T43: 4000 | U43: 1000 | V43: 6500 | W43: 8000 | X43: 7000 | Y43: 20000 | Z43: 1000 | AA43: 5500 | AB43: 89.451613 | AC43: 3500 | AD43: 1000 | AE43: 3000 | AF43: 0 | AG43: 2000 | AH43: 2000 | AI43: 800 | AJ43: 7200 | AK43: 2000 | AL43: 1500 | AM43: 1000 | AN43: 10000 | AO43: 2000 | AP43: 6000 | AQ43: 8000 | AR43: 7000 | AS43: 3500 | AT43: 500 | AU43: 3500 | AV43: 2000 | AW43: 369.61071 | AX43: 1121.9003 | AY43: 2499.7026 | AZ43: 2499.7026 | BA43: 5000 | BB43: 31500 | BC43: 9000
B44: =B43+1 -> 46326 | C44: =TEXT(B44,"ddd") -> Sat | D44: =SUM(E44:BC44) -> 256707.41 | E44: 700 | F44: 1000 | G44: 3300 | H44: 500 | I44: 150 | J44: 603.76323 | K44: 673.27548 | L44: 4500 | M44: 4000 | N44: 1000 | O44: 16000 | P44: 15600 | Q44: =25000+4500 -> 29500 | R44: 5000 | S44: 12000 | T44: 4000 | U44: 1000 | V44: 6500 | W44: 8000 | X44: 7000 | Y44: 20000 | Z44: 1000 | AA44: 5500 | AB44: 89.451613 | AC44: 3100 | AD44: 1000 | AE44: 0 | AF44: 0 | AG44: 0 | AH44: 2000 | AI44: 800 | AJ44: 7200 | AK44: 2000 | AL44: 1500 | AM44: 1000 | AN44: 10000 | AO44: 2000 | AP44: 6000 | AQ44: 8000 | AR44: 7000 | AS44: 3500 | AT44: 500 | AU44: 3500 | AV44: 2000 | AW44: 369.61071 | AX44: 1121.9003 | AY44: 2499.7026 | AZ44: 2499.7026 | BA44: 1000 | BB44: 31500 | BC44: 9000
B45: Sub Total | D45: =SUM(D39:D44) -> 1542242.3 | E45: =SUM(E39:E44) -> 6697.8645 | F45: =SUM(F39:F44) -> 7000 | G45: =SUM(G39:G44) -> 19800 | H45: =SUM(H39:H44) -> 4500 | I45: =SUM(I39:I44) -> 900 | J45: =SUM(J39:J44) -> 3622.5794 | K45: =SUM(K39:K44) -> 4039.6529 | ... AE45: =SUM(AE39:AE44) -> 15000 | AF45: 0 | AG45: =SUM(AG39:AG44) -> 10000 | AH45: =SUM(AH39:AH44) -> 12000 | AI45: =SUM(AI39:AI44) -> 4800 | AJ45: =SUM(AJ39:AJ44) -> 43200 | AK45: =SUM(AK39:AK44) -> 12000 | AL45: =SUM(AL39:AL44) -> 9000 | AM45: =SUM(AM39:AM44) -> 6000 | AN45: =SUM(AN39:AN44) -> 60000 | ... BC45: =SUM(BC39:BC44) -> 54000
...

Sheet KEBUTUHAN GAS
A1: KEBUTUHAN GAS
A4: 46296 | F4: KEBUTUHAN GAS | J4: KUOTA GAS
A5: Week | B5: DATE | D5: SELISIH GAS JABAR | E5: SELISIH GAS TOTAL | F5: JABAR | G5: JATENG | H5: JATIM | I5: TOTAL | J5: MS SETU | K5: MS KHT | L5: MS BLORA | M5: MS BITUNG | N5: MS ZEBRA | O5: MS TAMBAKLOROK | P5: MS BaGS | Q5: MS WUNUT | R5: TOTAL
A6: =WEEKNUM(B6) -> 40 | B6: =A4 -> 46296 | C6: =TEXT(B6,"ddd") -> Thu | D6: =(J6+K6)-F6 -> -2121.9528 | E6: =R6-I6 -> 7687.131 | F6: =SUM('SO Oktober 2026 Rev3'!E6:AS6) -> 145416.55 | G6: =SUM('SO Oktober 2026 Rev3'!AV6:BB6) -> 44990.916 | H6: =SUM('SO Oktober 2026 Rev3'!BC6:BC6) -> 9000 | I6: =SUM(F6:H6) -> 199407.46 | J6: ='SO MS'!E6 -> 106038 | K6: ='SO MS'!F6 -> 37256.595 | L6: ='SO MS'!G6 -> 10800 | M6: ='SO MS'!H6 -> 0 | N6: ='SO MS'!I6 -> 9000 | O6: ='SO Oktober 2026 Rev3'!AS6 -> 3500 | P6: ='SO MS'!K6 -> 9000 | Q6: ='SO MS'!L6 -> 31500 | R6: =SUM(J6:Q6) -> 207094.59
B7: =B6+1 -> 46297 | C7: =TEXT(B7,"ddd") -> Fri | D7: =(J7+K7)-F7 -> -2021.4686 | E7: =R7-I7 -> 7787.6152 | F7: =SUM('SO Oktober 2026 Rev3'!E7:AS7) -> 145316.06 | G7: =SUM('SO Oktober 2026 Rev3'!AV7:BB7) -> 44990.916 | H7: =SUM('SO Oktober 2026 Rev3'!BC7:BC7) -> 9000 | I7: =SUM(F7:H7) -> 199306.98 | J7: ='SO MS'!E7 -> 106038 | K7: ='SO MS'!F7 -> 37256.595 | L7: ='SO MS'!G7 -> 10800 | M7: ='SO MS'!H7 -> 0 | N7: ='SO MS'!I7 -> 9000 | O7: ='SO Oktober 2026 Rev3'!AS7 -> 3500 | P7: ='SO MS'!K7 -> 9000 | Q7: ='SO MS'!L7 -> 31500 | R7: =SUM(J7:Q7) -> 207094.59
B8: =B7+1 -> 46298 | C8: =TEXT(B8,"ddd") -> Sat | D8: =(J8+K8)-F8 -> -3521.8957 | E8: =R8-I8 -> 11409.088 | F8: =SUM('SO Oktober 2026 Rev3'!E8:AS8) -> 146816.49 | G8: =SUM('SO Oktober 2026 Rev3'!AV8:BB8) -> 39869.016 | H8: =SUM('SO Oktober 2026 Rev3'!BC8:BC8) -> 9000 | I8: =SUM(F8:H8) -> 195685.51 | J8: ='SO MS'!E8 -> 106038 | K8: ='SO MS'!F8 -> 37256.595 | L8: ='SO MS'!G8 -> 10800 | M8: ='SO MS'!H8 -> 0 | N8: ='SO MS'!I8 -> 9000 | O8: ='SO Oktober 2026 Rev3'!AS8 -> 3500 | P8: ='SO MS'!K8 -> 9000 | Q8: ='SO MS'!L8 -> 31500 | R8: =SUM(J8:Q8) -> 207094.59
B9: =B8+1 -> 46299 | C9: =TEXT(B9,"ddd") -> Sun | D9: =(J9+K9)-F9 -> 3769.1817 | E9: =R9-I9 -> 18700.166 | F9: =SUM('SO Oktober 2026 Rev3'!E9:AS9) -> 139525.41 | G9: =SUM('SO Oktober 2026 Rev3'!AV9:BB9) -> 39869.016 | H9: =SUM('SO Oktober 2026 Rev3'!BC9:BC9) -> 9000 | I9: =SUM(F9:H9) -> 188394.43 | J9: ='SO MS'!E9 -> 106038 | K9: ='SO MS'!F9 -> 37256.595 | L9: ='SO MS'!G9 -> 10800 | M9: ='SO MS'!H9 -> 0 | N9: ='SO MS'!I9 -> 9000 | O9: ='SO Oktober 2026 Rev3'!AS9 -> 3500 | P9: ='SO MS'!K9 -> 9000 | Q9: ='SO MS'!L9 -> 31500 | R9: =SUM(J9:Q9) -> 207094.59
B10: Sub Total | D10: =SUM(D6:D9) -> -3896.1355 | E10: =SUM(E6:E9) -> 45584 | F10: =SUM(F6:F9) -> 577074.51 | G10: =SUM(G6:G9) -> 169719.86 | H10: =SUM(H6:H9) -> 36000 | I10: =SUM(I6:I9) -> 782794.38 | J10: =SUM(J6:J9) -> 424152 | K10: =SUM(K6:K9) -> 149026.38 | ... R10: =SUM(R6:R9) -> 828378.38
B12: =B9+1 -> 46300 | C12: =TEXT(B12,"ddd") -> Mon | D12: =(J12+K12)-F12 -> -2321.4686 | E12: =R12-I12 -> 7487.6152 | F12: =SUM('SO Oktober 2026 Rev3'!E12:AS12) -> 145616.06 | G12: =SUM('SO Oktober 2026 Rev3'!AV12:BB12) -> 44990.916 | H12: =SUM('SO Oktober 2026 Rev3'!BC12:BC12) -> 9000 | I12: =SUM(F12:H12) -> 199606.98 | J12: ='SO MS'!E12 -> 106038 | K12: ='SO MS'!F12 -> 37256.595 | L12: ='SO MS'!G12 -> 10800 | M12: ='SO MS'!H12 -> 0 | N12: ='SO MS'!I12 -> 9000 | O12: ='SO Oktober 2026 Rev3'!AS12 -> 3500 | P12: ='SO MS'!K12 -> 9000 | Q12: ='SO MS'!L12 -> 31500 | R12: =SUM(J12:Q12) -> 207094.59
A13: =WEEKNUM(B13) -> 41 | B13: =B12+1 -> 46301 | C13: =TEXT(B13,"ddd") -> Tue | D13: =(J13+K13)-F13 -> -2321.4686 | E13: =R13-I13 -> 7487.6152 | F13: =SUM('SO Oktober 2026 Rev3'!E13:AS13) -> 145616.06 | G13: =SUM('SO Oktober 2026 Rev3'!AV13:BB13) -> 44990.916 | H13: =SUM('SO Oktober 2026 Rev3'!BC13:BC13) -> 9000 | I13: =SUM(F13:H13) -> 199606.98 | J13: ='SO MS'!E13 -> 106038 | K13: ='SO MS'!F13 -> 37256.595 | L13: ='SO MS'!G13 -> 10800 | M13: ='SO MS'!H13 -> 0 | N13: ='SO MS'!I13 -> 9000 | O13: ='SO Oktober 2026 Rev3'!AS13 -> 3500 | P13: ='SO MS'!K13 -> 9000 | Q13: ='SO MS'!L13 -> 31500 | R13: =SUM(J13:Q13) -> 207094.59
B14: =B13+1 -> 46302 | C14: =TEXT(B14,"ddd") -> Wed | D14: =(J14+K14)-F14 -> -2321.4686 | E14: =R14-I14 -> 7487.6152 | F14: =SUM('SO Oktober 2026 Rev3'!E14:AS14) -> 145616.06 | G14: =SUM('SO Oktober 2026 Rev3'!AV14:BB14) -> 44990.916 | H14: =SUM('SO Oktober 2026 Rev3'!BC14:BC14) -> 9000 | I14: =SUM(F14:H14) -> 199606.98 | J14: ='SO MS'!E14 -> 106038 | K14: ='SO MS'!F14 -> 37256.595 | L14: ='SO MS'!G14 -> 10800 | M14: ='SO MS'!H14 -> 0 | N14: ='SO MS'!I14 -> 9000 | O14: ='SO Oktober 2026 Rev3'!AS14 -> 3500 | P14: ='SO MS'!K14 -> 9000 | Q14: ='SO MS'!L14 -> 31500 | R14: =SUM(J14:Q14) -> 207094.59
B15: =B14+1 -> 46303 | C15: =TEXT(B15,"ddd") -> Thu | D15: =(J15+K15)-F15 -> -4321.4686 | E15: =R15-I15 -> 5487.6152 | F15: =SUM('SO Oktober 2026 Rev3'!E15:AS15) -> 147616.06 | G15: =SUM('SO Oktober 2026 Rev3'!AV15:BB15) -> 44990.916 | H15: =SUM('SO Oktober 2026 Rev3'!BC15:BC15) -> 9000 | I15: =SUM(F15:H15) -> 201606.98 | J15: ='SO MS'!E15 -> 106038 | K15: ='SO MS'!F15 -> 37256.595 | L15: ='SO MS'!G15 -> 10800 | M15: ='SO MS'!H15 -> 0 | N15: ='SO MS'!I15 -> 9000 | O15: ='SO Oktober 2026 Rev3'!AS15 -> 3500 | P15: ='SO MS'!K15 -> 9000 | Q15: ='SO MS'!L15 -> 31500 | R15: =SUM(J15:Q15) -> 207094.59
B16: =B15+1 -> 46304 | C16: =TEXT(B16,"ddd") -> Fri | D16: =(J16+K16)-F16 -> -4321.4686 | E16: =R16-I16 -> 5487.6152 | F16: =SUM('SO Oktober 2026 Rev3'!E16:AS16) -> 147616.06 | G16: =SUM('SO Oktober 2026 Rev3'!AV16:BB16) -> 44990.916 | H16: =SUM('SO Oktober 2026 Rev3'!BC16:BC16) -> 9000 | I16: =SUM(F16:H16) -> 201606.98 | J16: ='SO MS'!E16 -> 106038 | K16: ='SO MS'!F16 -> 37256.595 | L16: ='SO MS'!G16 -> 10800 | M16: ='SO MS'!H16 -> 0 | N16: ='SO MS'!I16 -> 9000 | O16: ='SO Oktober 2026 Rev3'!AS16 -> 3500 | P16: ='SO MS'!K16 -> 9000 | Q16: ='SO MS'!L16 -> 31500 | R16: =SUM(J16:Q16) -> 207094.59
B17: =B16+1 -> 46305 | C17: =TEXT(B17,"ddd") -> Sat | D17: =(J17+K17)-F17 -> -6321.8957 | E17: =R17-I17 -> 8609.0884 | F17: =SUM('SO Oktober 2026 Rev3'!E17:AS17) -> 149616.49 | G17: =SUM('SO Oktober 2026 Rev3'!AV17:BB17) -> 39869.016 | H17: =SUM('SO Oktober 2026 Rev3'!BC17:BC17) -> 9000 | I17: =SUM(F17:H17) -> 198485.51 | J17: ='SO MS'!E17 -> 106038 | K17: ='SO MS'!F17 -> 37256.595 | L17: ='SO MS'!G17 -> 10800 | M17: ='SO MS'!H17 -> 0 | N17: ='SO MS'!I17 -> 9000 | O17: ='SO Oktober 2026 Rev3'!AS17 -> 3500 | P17: ='SO MS'!K17 -> 9000 | Q17: ='SO MS'!L17 -> 31500 | R17: =SUM(J17:Q17) -> 207094.59
B18: =B17+1 -> 46306 | C18: =TEXT(B18,"ddd") -> Sun | D18: =(J18+K18)-F18 -> 3469.1817 | E18: =R18-I18 -> 18400.166 | F18: =SUM('SO Oktober 2026 Rev3'!E18:AS18) -> 139825.41 | G18: =SUM('SO Oktober 2026 Rev3'!AV18:BB18) -> 39869.016 | H18: =SUM('SO Oktober 2026 Rev3'!BC18:BC18) -> 9000 | I18: =SUM(F18:H18) -> 188694.43 | J18: ='SO MS'!E18 -> 106038 | K18: ='SO MS'!F18 -> 37256.595 | L18: ='SO MS'!G18 -> 10800 | M18: ='SO MS'!H18 -> 0 | N18: ='SO MS'!I18 -> 9000 | O18: ='SO Oktober 2026 Rev3'!AS18 -> 3500 | P18: ='SO MS'!K18 -> 9000 | Q18: ='SO MS'!L18 -> 31500 | R18: =SUM(J18:Q18) -> 207094.59
B19: Sub Total | D19: =SUM(D12:D18) -> -18460.057 | E19: =SUM(E12:E18) -> 60447.33 | F19: =SUM(F12:F18) -> 1021522.2 | G19: =SUM(G12:G18) -> 304692.61 | H19: =SUM(H12:H18) -> 63000 | I19: =SUM(I12:I18) -> 1389214.8 | J19: =SUM(J12:J18) -> 742266 | K19: =SUM(K12:K18) -> 260796.16 | ... R19: =SUM(R12:R18) -> 1449662.2
B21: =B18+1 -> 46307 | C21: =TEXT(B21,"ddd") -> Mon | D21: =(J21+K21)-F21 -> -10321.469 | E21: =R21-I21 -> -512.38482 | F21: =SUM('SO Oktober 2026 Rev3'!E21:AS21) -> 153616.06 | G21: =SUM('SO Oktober 2026 Rev3'!AV21:BB21) -> 44990.916 | H21: =SUM('SO Oktober 2026 Rev3'!BC21:BC21) -> 9000 | I21: =SUM(F21:H21) -> 207606.98 | J21: ='SO MS'!E21 -> 106038 | K21: ='SO MS'!F21 -> 37256.595 | L21: ='SO MS'!G21 -> 10800 | M21: ='SO MS'!H21 -> 0 | N21: ='SO MS'!I21 -> 9000 | O21: ='SO Oktober 2026 Rev3'!AS21 -> 3500 | P21: ='SO MS'!K21 -> 9000 | Q21: ='SO MS'!L21 -> 31500 | R21: =SUM(J21:Q21) -> 207094.59
A22: =WEEKNUM(B23) -> 42 | B22: =B21+1 -> 46308 | C22: =TEXT(B22,"ddd") -> Tue | D22: =(J22+K22)-F22 -> -27321.469 | E22: =R22-I22 -> -17512.385 | F22: =SUM('SO Oktober 2026 Rev3'!E22:AS22) -> 170616.06 | G22: =SUM('SO Oktober 2026 Rev3'!AV22:BB22) -> 44990.916 | H22: =SUM('SO Oktober 2026 Rev3'!BC22:BC22) -> 9000 | I22: =SUM(F22:H22) -> 224606.98 | J22: ='SO MS'!E22 -> 106038 | K22: ='SO MS'!F22 -> 37256.595 | L22: ='SO MS'!G22 -> 10800 | M22: ='SO MS'!H22 -> 0 | N22: ='SO MS'!I22 -> 9000 | O22: ='SO Oktober 2026 Rev3'!AS22 -> 3500 | P22: ='SO MS'!K22 -> 9000 | Q22: ='SO MS'!L22 -> 31500 | R22: =SUM(J22:Q22) -> 207094.59
B23: =B22+1 -> 46309 | C23: =TEXT(B23,"ddd") -> Wed | D23: =(J23+K23)-F23 -> -21521.469 | E23: =R23-I23 -> -11712.385 | F23: =SUM('SO Oktober 2026 Rev3'!E23:AS23) -> 164816.06 | G23: =SUM('SO Oktober 2026 Rev3'!AV23:BB23) -> 44990.916 | H23: =SUM('SO Oktober 2026 Rev3'!BC23:BC23) -> 9000 | I23: =SUM(F23:H23) -> 218806.98 | J23: ='SO MS'!E23 -> 106038 | K23: ='SO MS'!F23 -> 37256.595 | L23: ='SO MS'!G23 -> 10800 | M23: ='SO MS'!H23 -> 0 | N23: ='SO MS'!I23 -> 9000 | O23: ='SO Oktober 2026 Rev3'!AS23 -> 3500 | P23: ='SO MS'!K23 -> 9000 | Q23: ='SO MS'!L23 -> 31500 | R23: =SUM(J23:Q23) -> 207094.59
B24: =B23+1 -> 46310 | C24: =TEXT(B24,"ddd") -> Thu | D24: =(J24+K24)-F24 -> -23521.469 | E24: =R24-I24 -> -13712.385 | F24: =SUM('SO Oktober 2026 Rev3'!E24:AS24) -> 166816.06 | G24: =SUM('SO Oktober 2026 Rev3'!AV24:BB24) -> 44990.916 | H24: =SUM('SO Oktober 2026 Rev3'!BC24:BC24) -> 9000 | I24: =SUM(F24:H24) -> 220806.98 | J24: ='SO MS'!E24 -> 106038 | K24: ='SO MS'!F24 -> 37256.595 | L24: ='SO MS'!G24 -> 10800 | M24: ='SO MS'!H24 -> 0 | N24: ='SO MS'!I24 -> 9000 | O24: ='SO Oktober 2026 Rev3'!AS24 -> 3500 | P24: ='SO MS'!K24 -> 9000 | Q24: ='SO MS'!L24 -> 31500 | R24: =SUM(J24:Q24) -> 207094.59
B25: =B24+1 -> 46311 | C25: =TEXT(B25,"ddd") -> Fri | D25: =(J25+K25)-F25 -> -23521.469 | E25: =R25-I25 -> -13712.385 | F25: =SUM('SO Oktober 2026 Rev3'!E25:AS25) -> 166816.06 | G25: =SUM('SO Oktober 2026 Rev3'!AV25:BB25) -> 44990.916 | H25: =SUM('SO Oktober 2026 Rev3'!BC25:BC25) -> 9000 | I25: =SUM(F25:H25) -> 220806.98 | J25: ='SO MS'!E25 -> 106038 | K25: ='SO MS'!F25 -> 37256.595 | L25: ='SO MS'!G25 -> 10800 | M25: ='SO MS'!H25 -> 0 | N25: ='SO MS'!I25 -> 9000 | O25: ='SO Oktober 2026 Rev3'!AS25 -> 3500 | P25: ='SO MS'!K25 -> 9000 | Q25: ='SO MS'!L25 -> 31500 | R25: =SUM(J25:Q25) -> 207094.59
B26: =B25+1 -> 46312 | C26: =TEXT(B26,"ddd") -> Sat | D26: =(J26+K26)-F26 -> -19521.896 | E26: =R26-I26 -> -4590.9116 | F26: =SUM('SO Oktober 2026 Rev3'!E26:AS26) -> 162816.49 | G26: =SUM('SO Oktober 2026 Rev3'!AV26:BB26) -> 39869.016 | H26: =SUM('SO Oktober 2026 Rev3'!BC26:BC26) -> 9000 | I26: =SUM(F26:H26) -> 211685.51 | J26: ='SO MS'!E26 -> 106038 | K26: ='SO MS'!F26 -> 37256.595 | L26: ='SO MS'!G26 -> 10800 | M26: ='SO MS'!H26 -> 0 | N26: ='SO MS'!I26 -> 9000 | O26: ='SO Oktober 2026 Rev3'!AS26 -> 3500 | P26: ='SO MS'!K26 -> 9000 | Q26: ='SO MS'!L26 -> 31500 | R26: =SUM(J26:Q26) -> 207094.59
B27: =B26+1 -> 46313 | C27: =TEXT(B27,"ddd") -> Sun | D27: =(J27+K27)-F27 -> 17469.182 | E27: =R27-I27 -> 32400.166 | F27: =SUM('SO Oktober 2026 Rev3'!E27:AS27) -> 125825.41 | G27: =SUM('SO Oktober 2026 Rev3'!AV27:BB27) -> 39869.016 | H27: =SUM('SO Oktober 2026 Rev3'!BC27:BC27) -> 9000 | I27: =SUM(F27:H27) -> 174694.43 | J27: ='SO MS'!E27 -> 106038 | K27: ='SO MS'!F27 -> 37256.595 | L27: ='SO MS'!G27 -> 10800 | M27: ='SO MS'!H27 -> 0 | N27: ='SO MS'!I27 -> 9000 | O27: ='SO Oktober 2026 Rev3'!AS27 -> 3500 | P27: ='SO MS'!K27 -> 9000 | Q27: ='SO MS'!L27 -> 31500 | R27: =SUM(J27:Q27) -> 207094.59
B28: Sub Total | D28: =SUM(D21:D27) -> -108260.06 | E28: =SUM(E21:E27) -> -29352.67 | F28: =SUM(F21:F27) -> 1111322.2 | G28: =SUM(G21:G27) -> 304692.61 | H28: =SUM(H21:H27) -> 63000 | I28: =SUM(I21:I27) -> 1479014.8 | J28: =SUM(J21:J27) -> 742266 | K28: =SUM(K21:K27) -> 260796.16 | ... R28: =SUM(R21:R27) -> 1449662.2
A30: =WEEKNUM(B32) -> 43 | B30: =B27+1 -> 46314 | C30: =TEXT(B30,"ddd") -> Mon | D30: =(J30+K30)-F30 -> -33521.469 | E30: =R30-I30 -> -23712.385 | F30: =SUM('SO Oktober 2026 Rev3'!E30:AS30) -> 176816.06 | G30: =SUM('SO Oktober 2026 Rev3'!AV30:BB30) -> 44990.916 | H30: =SUM('SO Oktober 2026 Rev3'!BC30:BC30) -> 9000 | I30: =SUM(F30:H30) -> 230806.98 | J30: ='SO MS'!E30 -> 106038 | K30: ='SO MS'!F30 -> 37256.595 | L30: ='SO MS'!G30 -> 10800 | M30: ='SO MS'!H30 -> 0 | N30: ='SO MS'!I30 -> 9000 | O30: ='SO Oktober 2026 Rev3'!AS30 -> 3500 | P30: ='SO MS'!K30 -> 9000 | Q30: ='SO MS'!L30 -> 31500 | R30: =SUM(J30:Q30) -> 207094.59
B31: =B30+1 -> 46315 | C31: =TEXT(B31,"ddd") -> Tue | D31: =(J31+K31)-F31 -> -43521.469 | E31: =R31-I31 -> -33712.385 | F31: =SUM('SO Oktober 2026 Rev3'!E31:AS31) -> 186816.06 | G31: =SUM('SO Oktober 2026 Rev3'!AV31:BB31) -> 44990.916 | H31: =SUM('SO Oktober 2026 Rev3'!BC31:BC31) -> 9000 | I31: =SUM(F31:H31) -> 240806.98 | J31: ='SO MS'!E31 -> 106038 | K31: ='SO MS'!F31 -> 37256.595 | L31: ='SO MS'!G31 -> 10800 | M31: ='SO MS'!H31 -> 0 | N31: ='SO MS'!I31 -> 9000 | O31: ='SO Oktober 2026 Rev3'!AS31 -> 3500 | P31: ='SO MS'!K31 -> 9000 | Q31: ='SO MS'!L31 -> 31500 | R31: =SUM(J31:Q31) -> 207094.59
B32: =B31+1 -> 46316 | C32: =TEXT(B32,"ddd") -> Wed | D32: =(J32+K32)-F32 -> -55821.469 | E32: =R32-I32 -> -46012.385 | F32: =SUM('SO Oktober 2026 Rev3'!E32:AS32) -> 199116.06 | G32: =SUM('SO Oktober 2026 Rev3'!AV32:BB32) -> 44990.916 | H32: =SUM('SO Oktober 2026 Rev3'!BC32:BC32) -> 9000 | I32: =SUM(F32:H32) -> 253106.98 | J32: ='SO MS'!E32 -> 106038 | K32: ='SO MS'!F32 -> 37256.595 | L32: ='SO MS'!G32 -> 10800 | M32: ='SO MS'!H32 -> 0 | N32: ='SO MS'!I32 -> 9000 | O32: ='SO Oktober 2026 Rev3'!AS32 -> 3500 | P32: ='SO MS'!K32 -> 9000 | Q32: ='SO MS'!L32 -> 31500 | R32: =SUM(J32:Q32) -> 207094.59
B33: =B32+1 -> 46317 | C33: =TEXT(B33,"ddd") -> Thu | D33: =(J33+K33)-F33 -> -55821.469 | E33: =R33-I33 -> -46012.385 | F33: =SUM('SO Oktober 2026 Rev3'!E33:AS33) -> 199116.06 | G33: =SUM('SO Oktober 2026 Rev3'!AV33:BB33) -> 44990.916 | H33: =SUM('SO Oktober 2026 Rev3'!BC33:BC33) -> 9000 | I33: =SUM(F33:H33) -> 253106.98 | J33: ='SO MS'!E33 -> 106038 | K33: ='SO MS'!F33 -> 37256.595 | L33: ='SO MS'!G33 -> 10800 | M33: ='SO MS'!H33 -> 0 | N33: ='SO MS'!I33 -> 9000 | O33: ='SO Oktober 2026 Rev3'!AS33 -> 3500 | P33: ='SO MS'!K33 -> 9000 | Q33: ='SO MS'!L33 -> 31500 | R33: =SUM(J33:Q33) -> 207094.59
B34: =B33+1 -> 46318 | C34: =TEXT(B34,"ddd") -> Fri | D34: =(J34+K34)-F34 -> -55821.469 | E34: =R34-I34 -> -46012.385 | F34: =SUM('SO Oktober 2026 Rev3'!E34:AS34) -> 199116.06 | G34: =SUM('SO Oktober 2026 Rev3'!AV34:BB34) -> 44990.916 | H34: =SUM('SO Oktober 2026 Rev3'!BC34:BC34) -> 9000 | I34: =SUM(F34:H34) -> 253106.98 | J34: ='SO MS'!E34 -> 106038 | K34: ='SO MS'!F34 -> 37256.595 | L34: ='SO MS'!G34 -> 10800 | M34: ='SO MS'!H34 -> 0 | N34: ='SO MS'!I34 -> 9000 | O34: ='SO Oktober 2026 Rev3'!AS34 -> 3500 | P34: ='SO MS'!K34 -> 9000 | Q34: ='SO MS'!L34 -> 31500 | R34: =SUM(J34:Q34) -> 207094.59
B35: =B34+1 -> 46319 | C35: =TEXT(B35,"ddd") -> Sat | D35: =(J35+K35)-F35 -> -59321.896 | E35: =R35-I35 -> -44390.912 | F35: =SUM('SO Oktober 2026 Rev3'!E35:AS35) -> 202616.49 | G35: =SUM('SO Oktober 2026 Rev3'!AV35:BB35) -> 39869.016 | H35: =SUM('SO Oktober 2026 Rev3'!BC35:BC35) -> 9000 | I35: =SUM(F35:H35) -> 251485.51 | J35: ='SO MS'!E35 -> 106038 | K35: ='SO MS'!F35 -> 37256.595 | L35: ='SO MS'!G35 -> 10800 | M35: ='SO MS'!H35 -> 0 | N35: ='SO MS'!I35 -> 9000 | O35: ='SO Oktober 2026 Rev3'!AS35 -> 3500 | P35: ='SO MS'!K35 -> 9000 | Q35: ='SO MS'!L35 -> 31500 | R35: =SUM(J35:Q35) -> 207094.59
B36: =B35+1 -> 46320 | C36: =TEXT(B36,"ddd") -> Sun | D36: =(J36+K36)-F36 -> -27330.818 | E36: =R36-I36 -> -12399.834 | F36: =SUM('SO Oktober 2026 Rev3'!E36:AS36) -> 170625.41 | G36: =SUM('SO Oktober 2026 Rev3'!AV36:BB36) -> 39869.016 | H36: =SUM('SO Oktober 2026 Rev3'!BC36:BC36) -> 9000 | I36: =SUM(F36:H36) -> 219494.43 | J36: ='SO MS'!E36 -> 106038 | K36: ='SO MS'!F36 -> 37256.595 | L36: ='SO MS'!G36 -> 10800 | M36: ='SO MS'!H36 -> 0 | N36: ='SO MS'!I36 -> 9000 | O36: ='SO Oktober 2026 Rev3'!AS36 -> 3500 | P36: ='SO MS'!K36 -> 9000 | Q36: ='SO MS'!L36 -> 31500 | R36: =SUM(J36:Q36) -> 207094.59
B37: Sub Total | D37: =SUM(D30:D36) -> -331160.06 | E37: =SUM(E30:E36) -> -252252.67 | F37: =SUM(F30:F36) -> 1334222.2 | G37: =SUM(G30:G36) -> 304692.61 | H37: =SUM(H30:H36) -> 63000 | I37: =SUM(I30:I36) -> 1701914.8 | J37: =SUM(J30:J36) -> 742266 | K37: =SUM(K30:K36) -> 260796.16 | ... R37: =SUM(R30:R36) -> 1449662.2
A38: =WEEKNUM(B41) -> 44
B39: =B36+1 -> 46321 | C39: =TEXT(B39,"ddd") -> Mon | D39: =(J39+K39)-F39 -> -55821.469 | E39: =R39-I39 -> -46012.385 | F39: =SUM('SO Oktober 2026 Rev3'!E39:AS39) -> 199116.06 | G39: =SUM('SO Oktober 2026 Rev3'!AV39:BB39) -> 44990.916 | H39: =SUM('SO Oktober 2026 Rev3'!BC39:BC39) -> 9000 | I39: =SUM(F39:H39) -> 253106.98 | J39: ='SO MS'!E39 -> 106038 | K39: ='SO MS'!F39 -> 37256.595 | L39: ='SO MS'!G39 -> 10800 | M39: ='SO MS'!H39 -> 0 | N39: ='SO MS'!I39 -> 9000 | O39: ='SO Oktober 2026 Rev3'!AS39 -> 3500 | P39: ='SO MS'!K39 -> 9000 | Q39: ='SO MS'!L39 -> 31500 | R39: =SUM(J39:Q39) -> 207094.59
B40: =B39+1 -> 46322 | C40: =TEXT(B40,"ddd") -> Tue | D40: =(J40+K40)-F40 -> -55821.469 | E40: =R40-I40 -> -46012.385 | F40: =SUM('SO Oktober 2026 Rev3'!E40:AS40) -> 199116.06 | G40: =SUM('SO Oktober 2026 Rev3'!AV40:BB40) -> 44990.916 | H40: =SUM('SO Oktober 2026 Rev3'!BC40:BC40) -> 9000 | I40: =SUM(F40:H40) -> 253106.98 | J40: ='SO MS'!E40 -> 106038 | K40: ='SO MS'!F40 -> 37256.595 | L40: ='SO MS'!G40 -> 10800 | M40: ='SO MS'!H40 -> 0 | N40: ='SO MS'!I40 -> 9000 | O40: ='SO Oktober 2026 Rev3'!AS40 -> 3500 | P40: ='SO MS'!K40 -> 9000 | Q40: ='SO MS'!L40 -> 31500 | R40: =SUM(J40:Q40) -> 207094.59
B41: =B40+1 -> 46323 | C41: =TEXT(B41,"ddd") -> Wed | D41: =(J41+K41)-F41 -> -55821.469 | E41: =R41-I41 -> -46012.385 | F41: =SUM('SO Oktober 2026 Rev3'!E41:AS41) -> 199116.06 | G41: =SUM('SO Oktober 2026 Rev3'!AV41:BB41) -> 44990.916 | H41: =SUM('SO Oktober 2026 Rev3'!BC41:BC41) -> 9000 | I41: =SUM(F41:H41) -> 253106.98 | J41: ='SO MS'!E41 -> 106038 | K41: ='SO MS'!F41 -> 37256.595 | L41: ='SO MS'!G41 -> 10800 | M41: ='SO MS'!H41 -> 0 | N41: ='SO MS'!I41 -> 9000 | O41: ='SO Oktober 2026 Rev3'!AS41 -> 3500 | P41: ='SO MS'!K41 -> 9000 | Q41: ='SO MS'!L41 -> 31500 | R41: =SUM(J41:Q41) -> 207094.59
B42: =B41+1 -> 46324 | C42: =TEXT(B42,"ddd") -> Thu | D42: =(J42+K42)-F42 -> -55821.469 | E42: =R42-I42 -> -46012.385 | F42: =SUM('SO Oktober 2026 Rev3'!E42:AS42) -> 199116.06 | G42: =SUM('SO Oktober 2026 Rev3'!AV42:BB42) -> 44990.916 | H42: =SUM('SO Oktober 2026 Rev3'!BC42:BC42) -> 9000 | I42: =SUM(F42:H42) -> 253106.98 | J42: ='SO MS'!E42 -> 106038 | K42: ='SO MS'!F42 -> 37256.595 | L42: ='SO MS'!G42 -> 10800 | M42: ='SO MS'!H42 -> 0 | N42: ='SO MS'!I42 -> 9000 | O42: ='SO Oktober 2026 Rev3'!AS42 -> 3500 | P42: ='SO MS'!K42 -> 9000 | Q42: ='SO MS'!L42 -> 31500 | R42: =SUM(J42:Q42) -> 207094.59
B43: =B42+1 -> 46325 | C43: =TEXT(B43,"ddd") -> Fri | D43: =(J43+K43)-F43 -> -55821.469 | E43: =R43-I43 -> -46012.385 | F43: =SUM('SO Oktober 2026 Rev3'!E43:AS43) -> 199116.06 | G43: =SUM('SO Oktober 2026 Rev3'!AV43:BB43) -> 44990.916 | H43: =SUM('SO Oktober 2026 Rev3'!BC43:BC43) -> 9000 | I43: =SUM(F43:H43) -> 253106.98 | J43: ='SO MS'!E43 -> 106038 | K43: ='SO MS'!F43 -> 37256.595 | L43: ='SO MS'!G43 -> 10800 | M43: ='SO MS'!H43 -> 0 | N43: ='SO MS'!I43 -> 9000 | O43: ='SO Oktober 2026 Rev3'!AS43 -> 3500 | P43: ='SO MS'!K43 -> 9000 | Q43: ='SO MS'!L43 -> 31500 | R43: =SUM(J43:Q43) -> 207094.59
B44: =B43+1 -> 46326 | C44: =TEXT(B44,"ddd") -> Sat | D44: =(J44+K44)-F44 -> -59421.896 | E44: =R44-I44 -> -45612.812 | F44: =SUM('SO Oktober 2026 Rev3'!E44:AS44) -> 202716.49 | G44: =SUM('SO Oktober 2026 Rev3'!AV44:BB44) -> 40990.916 | H44: =SUM('SO Oktober 2026 Rev3'!BC44:BC44) -> 9000 | I44: =SUM(F44:H44) -> 252707.41 | J44: ='SO MS'!E44 -> 106038 | K44: ='SO MS'!F44 -> 37256.595 | L44: ='SO MS'!G44 -> 10800 | M44: ='SO MS'!H44 -> 0 | N44: ='SO MS'!I44 -> 9000 | O44: ='SO Oktober 2026 Rev3'!AS44 -> 3500 | P44: ='SO MS'!K44 -> 9000 | Q44: ='SO MS'!L44 -> 31500 | R44: =SUM(J44:Q44) -> 207094.59
B45: Sub Total | D45: =SUM(D39:D44) -> -338529.24 | E45: =SUM(E39:E44) -> -275674.74 | F45: =SUM(F39:F44) -> 1198296.8 | G45: =SUM(G39:G44) -> 265945.5 | H45: =SUM(H39:H44) -> 54000 | I45: =SUM(I39:I44) -> 1518242.3 | J45: =SUM(J39:J44) -> 636228 | K45: =SUM(K39:K44) -> 223539.57 | ... R45: =SUM(R39:R44) -> 1242567.6
...

Sheet SO MS
A1: SALES ORDER GAS
A4: 46296
A5: Week | B5: DATE | D5: TOTAL | E5: MS SETU | F5: MS KHT | G5: MS BLORA | H5: MS BITUNG | I5: MS ZEBRA | J5: MS TAMBAKLOROK | K5: MS BaGS | L5: MS WUNUT
A6: =WEEKNUM(B6) -> 40 | B6: =A4 -> 46296 | C6: =TEXT(B6,"ddd") -> Thu | D6: =SUM(E6:O6) -> 207094.59 | E6: 106038 | F6: 37256.595 | G6: =0.45*24000 -> 10800 | H6: 0 | I6: ='SO Oktober 2026 Rev3'!BC6 -> 9000 | J6: ='SO Oktober 2026 Rev3'!AS6 -> 3500 | K6: ='SO Oktober 2026 Rev3'!BC6 -> 9000 | L6: ='SO Oktober 2026 Rev3'!BB6 -> 31500
B7: =B6+1 -> 46297 | C7: =TEXT(B7,"ddd") -> Fri | D7: =SUM(E7:O7) -> 207094.59 | E7: 106038 | F7: 37256.595 | G7: =0.45*24000 -> 10800 | H7: 0 | I7: ='SO Oktober 2026 Rev3'!BC7 -> 9000 | J7: ='SO Oktober 2026 Rev3'!AS7 -> 3500 | K7: ='SO Oktober 2026 Rev3'!BC7 -> 9000 | L7: ='SO Oktober 2026 Rev3'!BB7 -> 31500
B8: =B7+1 -> 46298 | C8: =TEXT(B8,"ddd") -> Sat | D8: =SUM(E8:O8) -> 207094.59 | E8: 106038 | F8: 37256.595 | G8: =0.45*24000 -> 10800 | H8: 0 | I8: ='SO Oktober 2026 Rev3'!BC8 -> 9000 | J8: ='SO Oktober 2026 Rev3'!AS8 -> 3500 | K8: ='SO Oktober 2026 Rev3'!BC8 -> 9000 | L8: ='SO Oktober 2026 Rev3'!BB8 -> 31500
B9: =B8+1 -> 46299 | C9: =TEXT(B9,"ddd") -> Sun | D9: =SUM(E9:O9) -> 207094.59 | E9: 106038 | F9: 37256.595 | G9: =0.45*24000 -> 10800 | H9: 0 | I9: ='SO Oktober 2026 Rev3'!BC9 -> 9000 | J9: ='SO Oktober 2026 Rev3'!AS9 -> 3500 | K9: ='SO Oktober 2026 Rev3'!BC9 -> 9000 | L9: ='SO Oktober 2026 Rev3'!BB9 -> 31500
