Workbook
Name ___xlnm._FilterDatabase_2: #REF!
Name ___xlnm._FilterDatabase_2: #REF!
Name ___xlnm._FilterDatabase_2: #REF!
Name ___xlnm._FilterDatabase_2: #REF!
Name ___xlnm._FilterDatabase_2: #REF!
Name ___xlnm._FilterDatabase_2: #REF!
Name ___xlnm._FilterDatabase_2: #REF!
Name ___xlnm._FilterDatabase_2: #REF!
Name ___xlnm._FilterDatabase_2: #REF!
Name ___xlnm._FilterDatabase_2: #REF!
Name ___xlnm._FilterDatabase_2: #REF!
Name ___xlnm._FilterDatabase_2: #REF!
Name ___xlnm._FilterDatabase_2: #REF!
Name ___xlnm._FilterDatabase_2: #REF!
Name ___xlnm._FilterDatabase_2: #REF!
Name ___xlnm._FilterDatabase_2: #REF!
Name ___xlnm._FilterDatabase_2: #REF!
Name __xlnm._FilterDatabase_2: #REF!
Name __xlnm._FilterDatabase_2: #REF!
Name __xlnm._FilterDatabase_2: #REF!
Name __xlnm._FilterDatabase_2: #REF!
Name __xlnm._FilterDatabase_2: #REF!
Name __xlnm._FilterDatabase_2: #REF!
Name __xlnm._FilterDatabase_2: #REF!
Name __xlnm._FilterDatabase_2: #REF!
Name __xlnm._FilterDatabase_2: #REF!
Name __xlnm._FilterDatabase_2: #REF!
Name __xlnm._FilterDatabase_2: #REF!
Name __xlnm._FilterDatabase_2: #REF!
Name __xlnm._FilterDatabase_2: #REF!
Name __xlnm._FilterDatabase_2: #REF!
Name __xlnm._FilterDatabase_2: #REF!
Name __xlnm._FilterDatabase_2: #REF!
Name __xlnm._FilterDatabase_2: #REF!
Name _TES46: #N/A
Name AAAA: #N/A
Name ati: #N/A
Name BS: #N/A
Name CCC: #N/A
Name depr9200: #N/A
Name dfsfd: #N/A
Name Excel_BuiltIn__FilterDatabase_1: #REF!
Name Excel_BuiltIn__FilterDatabase_1: #REF!
Name Excel_BuiltIn__FilterDatabase_1: #REF!
Name Excel_BuiltIn__FilterDatabase_1: #REF!
Name Excel_BuiltIn__FilterDatabase_1: #REF!
Name Excel_BuiltIn__FilterDatabase_1: #REF!
Name Excel_BuiltIn__FilterDatabase_1: #REF!
Name Excel_BuiltIn__FilterDatabase_1: #REF!
Name Excel_BuiltIn__FilterDatabase_1: #REF!
Name Excel_BuiltIn__FilterDatabase_1: #REF!
Name Excel_BuiltIn__FilterDatabase_1: #REF!
Name Excel_BuiltIn__FilterDatabase_1: #REF!
Name Excel_BuiltIn__FilterDatabase_1: #REF!
Name Excel_BuiltIn__FilterDatabase_1: #REF!
Name Excel_BuiltIn__FilterDatabase_1: #REF!
Name Excel_BuiltIn__FilterDatabase_1: #REF!
Name Excel_BuiltIn__FilterDatabase_1: #REF!
Name Excel_BuiltIn_Print_Titles: NA()
Name Export_3: #REF!

Sheet SO FOB Juli 2026
A2: SALES ORDER
A4: 46204
A6: Week | B6: DATE | D6: TOTAL | E6: FOB SETU-AAE | F6: FOB SETU- SIDO | G6: FOB SETU - GIG | H6: FOB SETU - SALMAH | I6: FOB SETU - NNE | J6: FOB SETU - GAS | K6: FOB SETU -SBE | L6: FOB SETU -DAMASINDO | M6: FOB SETU-LARAS | N6: FOB SETU-KIRANA | O6: FOB KHT-APE | P6: FOB KHT - JPEN | Q6: FOB KHT - Laras | R6: FOB KHT - ANAGATA
A7: =WEEKNUM(B7) -> 27 | B7: =A4 -> 46204 | C7: Sun | D7: =SUM(E7:R7) -> 0 | E7: 0 | F7: 0 | G7: 0 | H7: 0 | I7: 0 | J7: 0 | K7: 0 | L7: 0 | M7: 0 | N7: 0 | O7: 0 | P7: 0 | Q7: 0 | R7: 0
B8: Sub Total | D8: =SUM(D4:D7) -> 0 | E8: =SUM(E4:E7) -> 0 | F8: =SUM(F4:F7) -> 0 | G8: =SUM(G4:G7) -> 0 | H8: =SUM(H4:H7) -> 0 | I8: =SUM(I4:I7) -> 0 | J8: =SUM(J4:J7) -> 0 | K8: =SUM(K4:K7) -> 0 | ... R8: =SUM(R4:R7) -> 0
A10: =WEEKNUM(B10) -> 27 | B10: =B7+1 -> 46205 | C10: Mon | D10: =SUM(E10:R10) -> 0 | E10: 0 | F10: 0 | G10: 0 | H10: 0 | I10: 0 | J10: 0 | K10: 0 | L10: 0 | M10: 0 | N10: 0 | O10: 0 | P10: 0 | Q10: 0 | R10: 0
B11: =B10+1 -> 46206 | C11: Tue | D11: =SUM(E11:R11) -> 0 | E11: 0 | F11: 0 | G11: 0 | H11: 0 | I11: 0 | J11: 0 | K11: 0 | L11: 0 | M11: 0 | N11: 0 | O11: 0 | P11: 0 | Q11: 0 | R11: 0
B12: =B11+1 -> 46207 | C12: Wed | D12: =SUM(E12:R12) -> 0 | E12: 0 | F12: 0 | G12: 0 | H12: 0 | I12: 0 | J12: 0 | K12: 0 | L12: 0 | M12: 0 | N12: 0 | O12: 0 | P12: 0 | Q12: 0 | R12: 0
B13: =B12+1 -> 46208 | C13: Thu | D13: =SUM(E13:R13) -> 0 | E13: 0 | F13: 0 | G13: 0 | H13: 0 | I13: 0 | J13: 0 | K13: 0 | L13: 0 | M13: 0 | N13: 0 | O13: 0 | P13: 0 | Q13: 0 | R13: 0
B14: =B13+1 -> 46209 | C14: Fri | D14: =SUM(E14:R14) -> 0 | E14: 0 | F14: 0 | G14: 0 | H14: 0 | I14: 0 | J14: 0 | K14: 0 | L14: 0 | M14: 0 | N14: 0 | O14: 0 | P14: 0 | Q14: 0 | R14: 0
B15: =B14+1 -> 46210 | C15: Sat | D15: =SUM(E15:R15) -> 0 | E15: 0 | F15: 0 | G15: 0 | H15: 0 | I15: 0 | J15: 0 | K15: 0 | L15: 0 | M15: 0 | N15: 0 | O15: 0 | P15: 0 | Q15: 0 | R15: 0
B16: =B15+1 -> 46211 | C16: Sun | D16: =SUM(E16:R16) -> 0 | E16: 0 | F16: 0 | G16: 0 | H16: 0 | I16: 0 | J16: 0 | K16: 0 | L16: 0 | M16: 0 | N16: 0 | O16: 0 | P16: 0 | Q16: 0 | R16: 0
B17: Sub Total | D17: =SUM(D10:D16) -> 0 | E17: =SUM(E10:E16) -> 0 | F17: =SUM(F10:F16) -> 0 | G17: =SUM(G10:G16) -> 0 | H17: =SUM(H10:H16) -> 0 | I17: =SUM(I10:I16) -> 0 | J17: =SUM(J10:J16) -> 0 | K17: =SUM(K10:K16) -> 0 | ... R17: =SUM(R10:R16) -> 0
A19: =WEEKNUM(B24) -> 29 | B19: =B16+1 -> 46212 | C19: Mon | D19: =SUM(E19:R19) -> 0 | E19: 0 | F19: 0 | G19: 0 | H19: 0 | I19: 0 | J19: 0 | K19: 0 | L19: 0 | M19: 0 | N19: 0 | O19: 0 | P19: 0 | Q19: 0 | R19: 0
B20: =B19+1 -> 46213 | C20: Tue | D20: =SUM(E20:R20) -> 0 | E20: 0 | F20: 0 | G20: 0 | H20: 0 | I20: 0 | J20: 0 | K20: 0 | L20: 0 | M20: 0 | N20: 0 | O20: 0 | P20: 0 | Q20: 0 | R20: 0
B21: =B20+1 -> 46214 | C21: Wed | D21: =SUM(E21:R21) -> 0 | E21: 0 | F21: 0 | G21: 0 | H21: 0 | I21: 0 | J21: 0 | K21: 0 | L21: 0 | M21: 0 | N21: 0 | O21: 0 | P21: 0 | Q21: 0 | R21: 0
B22: =B21+1 -> 46215 | C22: Thu | D22: =SUM(E22:R22) -> 0 | E22: 0 | F22: 0 | G22: 0 | H22: 0 | I22: 0 | J22: 0 | K22: 0 | L22: 0 | M22: 0 | N22: 0 | O22: 0 | P22: 0 | Q22: 0 | R22: 0
B23: =B22+1 -> 46216 | C23: Fri | D23: =SUM(E23:R23) -> 0 | E23: 0 | F23: 0 | G23: 0 | H23: 0 | I23: 0 | J23: 0 | K23: 0 | L23: 0 | M23: 0 | N23: 0 | O23: 0 | P23: 0 | Q23: 0 | R23: 0
B24: =B23+1 -> 46217 | C24: Sat | D24: =SUM(E24:R24) -> 0 | E24: 0 | F24: 0 | G24: 0 | H24: 0 | I24: 0 | J24: 0 | K24: 0 | L24: 0 | M24: 0 | N24: 0 | O24: 0 | P24: 0 | Q24: 0 | R24: 0
B25: =B24+1 -> 46218 | C25: Sun | D25: =SUM(E25:R25) -> 0 | E25: 0 | F25: 0 | G25: 0 | H25: 0 | I25: 0 | J25: 0 | K25: 0 | L25: 0 | M25: 0 | N25: 0 | O25: 0 | P25: 0 | Q25: 0 | R25: 0
B26: Sub Total | D26: =SUM(D19:D25) -> 0 | E26: =SUM(E19:E25) -> 0 | F26: =SUM(F19:F25) -> 0 | G26: =SUM(G19:G25) -> 0 | H26: =SUM(H19:H25) -> 0 | I26: =SUM(I19:I25) -> 0 | J26: =SUM(J19:J25) -> 0 | K26: =SUM(K19:K25) -> 0 | ... R26: =SUM(R19:R25) -> 0
A28: =WEEKNUM(B33) -> 30 | B28: =B25+1 -> 46219 | C28: Mon | D28: =SUM(E28:R28) -> 0 | E28: 0 | F28: 0 | G28: 0 | H28: 0 | I28: 0 | J28: 0 | K28: 0 | L28: 0 | M28: 0 | N28: 0 | O28: 0 | P28: 0 | Q28: 0 | R28: 0
B29: =B28+1 -> 46220 | C29: Tue | D29: =SUM(E29:R29) -> 0 | E29: 0 | F29: 0 | G29: 0 | H29: 0 | I29: 0 | J29: 0 | K29: 0 | L29: 0 | M29: 0 | N29: 0 | O29: 0 | P29: 0 | Q29: 0 | R29: 0
B30: =B29+1 -> 46221 | C30: Wed | D30: =SUM(E30:R30) -> 0 | E30: 0 | F30: 0 | G30: 0 | H30: 0 | I30: 0 | J30: 0 | K30: 0 | L30: 0 | M30: 0 | N30: 0 | O30: 0 | P30: 0 | Q30: 0 | R30: 0
B31: =B30+1 -> 46222 | C31: Thu | D31: =SUM(E31:R31) -> 0 | E31: 0 | F31: 0 | G31: 0 | H31: 0 | I31: 0 | J31: 0 | K31: 0 | L31: 0 | M31: 0 | N31: 0 | O31: 0 | P31: 0 | Q31: 0 | R31: 0
B32: =B31+1 -> 46223 | C32: Fri | D32: =SUM(E32:R32) -> 0 | E32: 0 | F32: 0 | G32: 0 | H32: 0 | I32: 0 | J32: 0 | K32: 0 | L32: 0 | M32: 0 | N32: 0 | O32: 0 | P32: 0 | Q32: 0 | R32: 0
B33: =B32+1 -> 46224 | C33: Sat | D33: =SUM(E33:R33) -> 0 | E33: 0 | F33: 0 | G33: 0 | H33: 0 | I33: 0 | J33: 0 | K33: 0 | L33: 0 | M33: 0 | N33: 0 | O33: 0 | P33: 0 | Q33: 0 | R33: 0
B34: =B33+1 -> 46225 | C34: Sun | D34: =SUM(E34:R34) -> 0 | E34: 0 | F34: 0 | G34: 0 | H34: 0 | I34: 0 | J34: 0 | K34: 0 | L34: 0 | M34: 0 | N34: 0 | O34: 0 | P34: 0 | Q34: 0 | R34: 0
B35: Sub Total | D35: =SUM(D28:D34) -> 0 | E35: =SUM(E28:E34) -> 0 | F35: =SUM(F28:F34) -> 0 | G35: =SUM(G28:G34) -> 0 | H35: =SUM(H28:H34) -> 0 | I35: =SUM(I28:I34) -> 0 | J35: =SUM(J28:J34) -> 0 | K35: =SUM(K28:K34) -> 0 | ... R35: =SUM(R28:R34) -> 0
A37: =WEEKNUM(B42) -> 31 | B37: =B34+1 -> 46226 | C37: Mon | D37: =SUM(E37:R37) -> 0 | E37: 0 | F37: 0 | G37: 0 | H37: 0 | I37: 0 | J37: 0 | K37: 0 | L37: 0 | M37: 0 | N37: 0 | O37: 0 | P37: 0 | Q37: 0 | R37: 0
B38: =B37+1 -> 46227 | C38: Tue | D38: =SUM(E38:R38) -> 0 | E38: 0 | F38: 0 | G38: 0 | H38: 0 | I38: 0 | J38: 0 | K38: 0 | L38: 0 | M38: 0 | N38: 0 | O38: 0 | P38: 0 | Q38: 0 | R38: 0
B39: =B38+1 -> 46228 | C39: Wed | D39: =SUM(E39:R39) -> 0 | E39: 0 | F39: 0 | G39: 0 | H39: 0 | I39: 0 | J39: 0 | K39: 0 | L39: 0 | M39: 0 | N39: 0 | O39: 0 | P39: 0 | Q39: 0 | R39: 0
B40: =B39+1 -> 46229 | C40: Thu | D40: =SUM(E40:R40) -> 0 | E40: 0 | F40: 0 | G40: 0 | H40: 0 | I40: 0 | J40: 0 | K40: 0 | L40: 0 | M40: 0 | N40: 0 | O40: 0 | P40: 0 | Q40: 0 | R40: 0
B41: =B40+1 -> 46230 | C41: Fri | D41: =SUM(E41:R41) -> 0 | E41: 0 | F41: 0 | G41: 0 | H41: 0 | I41: 0 | J41: 0 | K41: 0 | L41: 0 | M41: 0 | N41: 0 | O41: 0 | P41: 0 | Q41: 0 | R41: 0
B42: =B41+1 -> 46231 | C42: Sat | D42: =SUM(E42:R42) -> 0 | E42: 0 | F42: 0 | G42: 0 | H42: 0 | I42: 0 | J42: 0 | K42: 0 | L42: 0 | M42: 0 | N42: 0 | O42: 0 | P42: 0 | Q42: 0 | R42: 0
B43: =B42+1 -> 46232 | C43: Sun | D43: =SUM(E43:R43) -> 0 | E43: 0 | F43: 0 | G43: 0 | H43: 0 | I43: 0 | J43: 0 | K43: 0 | L43: 0 | M43: 0 | N43: 0 | O43: 0 | P43: 0 | Q43: 0 | R43: 0
B44: Sub Total | D44: =SUM(D37:D43) -> 0 | E44: =SUM(E37:E43) -> 0 | F44: =SUM(F37:F43) -> 0 | G44: =SUM(G37:G43) -> 0 | H44: =SUM(H37:H43) -> 0 | I44: =SUM(I37:I43) -> 0 | J44: =SUM(J37:J43) -> 0 | K44: =SUM(K37:K43) -> 0 | ... R44: =SUM(R37:R43) -> 0
A46: =WEEKNUM(B46) -> 31 | B46: =B43+1 -> 46233 | C46: Mon | D46: =SUM(E46:R46) -> 0 | E46: 0 | F46: 0 | G46: 0 | H46: 0 | I46: 0 | J46: 0 | K46: 0 | L46: 0 | M46: 0 | N46: 0 | O46: 0 | P46: 0 | Q46: 0 | R46: 0
B47: =B46+1 -> 46234 | C47: Tue | D47: =SUM(E47:R47) -> 0 | E47: 0 | F47: 0 | G47: 0 | H47: 0 | I47: 0 | J47: 0 | K47: 0 | L47: 0 | M47: 0 | N47: 0 | O47: 0 | P47: 0 | Q47: 0 | R47: 0
B48: Sub Total | D48: =SUM(D41:D47) -> 0 | E48: =SUM(E41:E47) -> 0 | F48: =SUM(F41:F47) -> 0 | G48: =SUM(G41:G47) -> 0 | H48: =SUM(H41:H47) -> 0 | I48: =SUM(I41:I47) -> 0 | J48: =SUM(J41:J47) -> 0 | K48: =SUM(K41:K47) -> 0 | ... R48: =SUM(R41:R47) -> 0
...

Sheet SO Juli 2026 Rev 2
A2: SALES ORDER
A3: 46204 | O3: =O4/2 -> 0
A5: Week | B5: DATE | D5: TOTAL | E5: CLIN | F5: BI | G5: MKG | H5: STM | I5: OAJ | J5: NNI | K5: SHB | L5: GTL | M5: TWK | N5: BYC | O5: GF RANCA | P5: SMA | Q5: UMI | R5: HLI | S5: ASAHIMAS | T5: DIC | U5: HCI | V5: KSN | W5: ADP | X5: KSN RANCA | Y5: ALT (KSO MASAMI) | Z5: IDP (KSO AAE) | AA5: FJI (KSO SALMAH) | AB5: WINGLOK (KSO EBM) | AC5: CISF (KSO RRS) | AD5: KGM (KSO RRS) | AE5: PUJ - LUBRICANT | AF5: CALBEE (KSO BMI) | AG5: IP | AH5: BEM | AI5: AMI | AJ5: KA | AK5: KTN | AL5: NIAGA GARAM | AM5: PCI 84 | AN5: PCI MENGGER | AO5: INDOFOOD | AP5: CERES | AQ5: ABC KOGEN | AR5: TONGJI ( KSO GAS) | AS5: CITYMALL GARUT | AT5: PERHUTANI (KSO PTGN) | AU5: PA | AV5: RB | AW5: GF ATOM | AX5: GF KULIT | AY5: SDM | AZ5: JARGAS | BA5: SBI | BB5: SP GLOBAL | BC5: PENTAWIRA (KSO REN)
A6: =WEEKNUM(B6) -> 27 | B6: =A3 -> 46204 | C6: =TEXT(B6,"ddd") -> Wed | D6: =SUM(E6:BC6) -> 216250.93 | E6: 1199.5729 | F6: 2000 | G6: 1200 | H6: 3300 | I6: 644.02065 | J6: 0 | K6: 150 | L6: 603.76323 | M6: 673.27548 | N6: 5500 | O6: 5000 | P6: 2500 | Q6: 16000 | R6: 10300 | S6: 35000 | T6: 5000 | U6: 7000 | V6: 6500 | W6: 500 | X6: 5600 | Y6: 1000 | Z6: 5500 | AA6: 0 | AB6: 89.451613 | AC6: 3500 | AD6: 1300 | AE6: 3000 | AF6: 10000 | AG6: 2000 | AH6: 800 | AI6: 7200 | AJ6: 3499.8768 | AK6: 2000 | AL6: 1000 | AM6: 11000 | AN6: 2000 | AO6: 7000 | AP6: 9000.0571 | AQ6: 8000 | AR6: 3500 | AU6: 700 | AV6: 3500 | AW6: 2000 | AX6: 369.61071 | AY6: 1121.9003 | AZ6: 2499.7026 | BA6: 2499.7026 | BB6: 0 | BC6: 13500
B7: =B6+1 -> 46205 | C7: =TEXT(B7,"ddd") -> Thu | D7: =SUM(E7:BC7) -> 216250.93 | E7: 1199.5729 | F7: 2000 | G7: 1200 | H7: 3300 | I7: 644.02065 | J7: 0 | K7: 150 | L7: 603.76323 | M7: 673.27548 | N7: 5500 | O7: 5000 | P7: 2500 | Q7: 16000 | R7: 10300 | S7: 35000 | T7: 5000 | U7: 7000 | V7: 6500 | W7: 500 | X7: 5600 | Y7: 1000 | Z7: 5500 | AA7: 0 | AB7: 89.451613 | AC7: 3500 | AD7: 1300 | AE7: 3000 | AF7: 10000 | AG7: 2000 | AH7: 800 | AI7: 7200 | AJ7: 3499.8768 | AK7: 2000 | AL7: 1000 | AM7: 11000 | AN7: 2000 | AO7: 7000 | AP7: 9000.0571 | AQ7: 8000 | AR7: 3500 | AS7: 0 | AT7: 0 | AU7: 700 | AV7: 3500 | AW7: 2000 | AX7: 369.61071 | AY7: 1121.9003 | AZ7: 2499.7026 | BA7: 2499.7026 | BB7: 0 | BC7: 13500
B8: =B7+1 -> 46206 | C8: =TEXT(B8,"ddd") -> Fri | D8: =SUM(E8:BC8) -> 216250.93 | E8: 1199.5729 | F8: 2000 | G8: 1200 | H8: 3300 | I8: 644.02065 | J8: 0 | K8: 150 | L8: 603.76323 | M8: 673.27548 | N8: 5500 | O8: 5000 | P8: 2500 | Q8: 16000 | R8: 10300 | S8: 35000 | T8: 5000 | U8: 7000 | V8: 6500 | W8: 500 | X8: 5600 | Y8: 1000 | Z8: 5500 | AA8: 0 | AB8: 89.451613 | AC8: 3500 | AD8: 1300 | AE8: 3000 | AF8: 10000 | AG8: 2000 | AH8: 800 | AI8: 7200 | AJ8: 3499.8768 | AK8: 2000 | AL8: 1000 | AM8: 11000 | AN8: 2000 | AO8: 7000 | AP8: 9000.0571 | AQ8: 8000 | AR8: 3500 | AS8: 0 | AT8: 0 | AU8: 700 | AV8: 3500 | AW8: 2000 | AX8: 369.61071 | AY8: 1121.9003 | AZ8: 2499.7026 | BA8: 2499.7026 | BB8: 0 | BC8: 13500
B9: =B8+1 -> 46207 | C9: =TEXT(B9,"ddd") -> Sat | D9: =SUM(E9:BC9) -> 210629.53 | E9: 700 | F9: 1000 | G9: 1200 | H9: 3300 | I9: 644.02065 | J9: 0 | K9: 150 | L9: 603.76323 | M9: 673.27548 | N9: 4500 | O9: 5000 | P9: 1000 | Q9: 16000 | R9: 10300 | S9: 48000 | T9: 5000 | U9: 0 | V9: 6500 | W9: 500 | X9: 5600 | Y9: 1000 | Z9: 5500 | AA9: 0 | AB9: 89.451613 | AC9: 3500 | AD9: 1300 | AE9: 0 | AF9: 10000 | AG9: 2000 | AH9: 800 | AI9: 7200 | AJ9: 0 | AK9: 2000 | AL9: 1000 | AM9: 11000 | AN9: 2000 | AO9: 10000 | AP9: 6000 | AQ9: 8000 | AR9: 3500 | AS9: 0 | AT9: 0 | AU9: 700 | AV9: 3500 | AW9: 2000 | AX9: 369.61071 | AY9: 0 | AZ9: 2499.7026 | BA9: 2499.7026 | BB9: 0 | BC9: 13500
B10: =B9+1 -> 46208 | C10: =TEXT(B10,"ddd") -> Sun | D10: =SUM(E10:BC10) -> 186138.45 | E10: 700 | F10: 1000 | G10: 1200 | H10: 999.51613 | I10: 644.02065 | J10: 0 | K10: 0 | L10: 603.76323 | M10: 673.27548 | N10: 0 | O10: 5000 | P10: 300 | Q10: 6659.5545 | R10: 10300 | S10: =48000+6000 -> 54000 | T10: 5000 | U10: 0 | V10: 6500 | W10: 500 | X10: 5600 | Y10: 0 | Z10: 2500 | AA10: 0 | AB10: 89.451613 | AC10: 1000 | AD10: 1300 | AE10: 0 | AF10: 10000 | AG10: 2000 | AH10: 0 | AI10: 2999.8519 | AJ10: 0 | AK10: 2000 | AL10: 0 | AM10: 11000 | AN10: 2000 | AO10: 10000 | AP10: 5000 | AQ10: 8000 | AR10: 3500 | AS10: 0 | AT10: 0 | AU10: 700 | AV10: 3500 | AW10: 2000 | AX10: 369.61071 | AY10: 0 | AZ10: 2499.7026 | BA10: 2499.7026 | BB10: 0 | BC10: 13500
B11: Sub Total | D11: =SUM(D6:D10) -> 1045520.8 | E11: =SUM(E6:E10) -> 4998.7187 | F11: =SUM(F6:F10) -> 8000 | G11: =SUM(G6:G10) -> 6000 | H11: =SUM(H6:H10) -> 14199.516 | I11: =SUM(I6:I10) -> 3220.1032 | J11: =SUM(J6:J10) -> 0 | K11: =SUM(K6:K10) -> 600 | ... BC11: =SUM(BC6:BC10) -> 67500
A13: =WEEKNUM(B13) -> 28 | B13: =B10+1 -> 46209 | C13: =TEXT(B13,"ddd") -> Mon | D13: =SUM(E13:BC13) -> 216250.93 | E13: 1199.5729 | F13: 2000 | G13: 1200 | H13: 3300 | I13: 644.02065 | J13: 0 | K13: 150 | L13: 603.76323 | M13: 673.27548 | N13: 5500 | O13: 5000 | P13: 2500 | Q13: 16000 | R13: 10300 | S13: 35000 | T13: 5000 | U13: 7000 | V13: 6500 | W13: 500 | X13: 5600 | Y13: 1000 | Z13: 5500 | AA13: 0 | AB13: 89.451613 | AC13: 3500 | AD13: 1300 | AE13: 3000 | AF13: 10000 | AG13: 2000 | AH13: 800 | AI13: 7200 | AJ13: 3499.8768 | AK13: 2000 | AL13: 1000 | AM13: 11000 | AN13: 2000 | AO13: 7000 | AP13: 9000.0571 | AQ13: 8000 | AR13: 3500 | AS13: 0 | AT13: 0 | AU13: 700 | AV13: 3500 | AW13: 2000 | AX13: 369.61071 | AY13: 1121.9003 | AZ13: 2499.7026 | BA13: 2499.7026 | BB13: 0 | BC13: 13500
B14: =B13+1 -> 46210 | C14: =TEXT(B14,"ddd") -> Tue | D14: =SUM(E14:BC14) -> 216250.93 | E14: 1199.5729 | F14: 2000 | G14: 1200 | H14: 3300 | I14: 644.02065 | J14: 0 | K14: 150 | L14: 603.76323 | M14: 673.27548 | N14: 5500 | O14: 5000 | P14: 2500 | Q14: 16000 | R14: 10300 | S14: 35000 | T14: 5000 | U14: 7000 | V14: 6500 | W14: 500 | X14: 5600 | Y14: 1000 | Z14: 5500 | AA14: 0 | AB14: 89.451613 | AC14: 3500 | AD14: 1300 | AE14: 3000 | AF14: 10000 | AG14: 2000 | AH14: 800 | AI14: 7200 | AJ14: 3499.8768 | AK14: 2000 | AL14: 1000 | AM14: 11000 | AN14: 2000 | AO14: 7000 | AP14: 9000.0571 | AQ14: 8000 | AR14: 3500 | AS14: =SUM(AS7:AS13) -> 0 | AT14: =SUM(AT7:AT13) -> 0 | AU14: 700 | AV14: 3500 | AW14: 2000 | AX14: 369.61071 | AY14: 1121.9003 | AZ14: 2499.7026 | BA14: 2499.7026 | BB14: 0 | BC14: 13500
B15: =B14+1 -> 46211 | C15: =TEXT(B15,"ddd") -> Wed | D15: =SUM(E15:BC15) -> 216250.93 | E15: 1199.5729 | F15: 2000 | G15: 1200 | H15: 3300 | I15: 644.02065 | J15: 0 | K15: 150 | L15: 603.76323 | M15: 673.27548 | N15: 5500 | O15: 5000 | P15: 2500 | Q15: 16000 | R15: 10300 | S15: 35000 | T15: 5000 | U15: 7000 | V15: 6500 | W15: 500 | X15: 5600 | Y15: 1000 | Z15: 5500 | AA15: 0 | AB15: 89.451613 | AC15: 3500 | AD15: 1300 | AE15: 3000 | AF15: 10000 | AG15: 2000 | AH15: 800 | AI15: 7200 | AJ15: 3499.8768 | AK15: 2000 | AL15: 1000 | AM15: 11000 | AN15: 2000 | AO15: 7000 | AP15: 9000.0571 | AQ15: 8000 | AR15: 3500 | AU15: 700 | AV15: 3500 | AW15: 2000 | AX15: 369.61071 | AY15: 1121.9003 | AZ15: 2499.7026 | BA15: 2499.7026 | BB15: 0 | BC15: 13500
B16: =B15+1 -> 46212 | C16: =TEXT(B16,"ddd") -> Thu | D16: =SUM(E16:BC16) -> 216250.93 | E16: 1199.5729 | F16: 2000 | G16: 1200 | H16: 3300 | I16: 644.02065 | J16: 0 | K16: 150 | L16: 603.76323 | M16: 673.27548 | N16: 5500 | O16: 5000 | P16: 2500 | Q16: 16000 | R16: 10300 | S16: 35000 | T16: 5000 | U16: 7000 | V16: 6500 | W16: 500 | X16: 5600 | Y16: 1000 | Z16: 5500 | AA16: 0 | AB16: 89.451613 | AC16: 3500 | AD16: 1300 | AE16: 3000 | AF16: 10000 | AG16: 2000 | AH16: 800 | AI16: 7200 | AJ16: 3499.8768 | AK16: 2000 | AL16: 1000 | AM16: 11000 | AN16: 2000 | AO16: 7000 | AP16: 9000.0571 | AQ16: 8000 | AR16: 3500 | AS16: 0 | AT16: 0 | AU16: 700 | AV16: 3500 | AW16: 2000 | AX16: 369.61071 | AY16: 1121.9003 | AZ16: 2499.7026 | BA16: 2499.7026 | BB16: 0 | BC16: 13500
B17: =B16+1 -> 46213 | C17: =TEXT(B17,"ddd") -> Fri | D17: =SUM(E17:BC17) -> 216250.93 | E17: 1199.5729 | F17: 2000 | G17: 1200 | H17: 3300 | I17: 644.02065 | J17: 0 | K17: 150 | L17: 603.76323 | M17: 673.27548 | N17: 5500 | O17: 5000 | P17: 2500 | Q17: 16000 | R17: 10300 | S17: 35000 | T17: 5000 | U17: 7000 | V17: 6500 | W17: 500 | X17: 5600 | Y17: 1000 | Z17: 5500 | AA17: 0 | AB17: 89.451613 | AC17: 3500 | AD17: 1300 | AE17: 3000 | AF17: 10000 | AG17: 2000 | AH17: 800 | AI17: 7200 | AJ17: 3499.8768 | AK17: 2000 | AL17: 1000 | AM17: 11000 | AN17: 2000 | AO17: 7000 | AP17: 9000.0571 | AQ17: 8000 | AR17: 3500 | AS17: 0 | AT17: 0 | AU17: 700 | AV17: 3500 | AW17: 2000 | AX17: 369.61071 | AY17: 1121.9003 | AZ17: 2499.7026 | BA17: 2499.7026 | BB17: 0 | BC17: 13500
B18: =B17+1 -> 46214 | C18: =TEXT(B18,"ddd") -> Sat | D18: =SUM(E18:BC18) -> 210629.53 | E18: 700 | F18: 1000 | G18: 1200 | H18: 3300 | I18: 644.02065 | J18: 0 | K18: 150 | L18: 603.76323 | M18: 673.27548 | N18: 4500 | O18: 5000 | P18: 1000 | Q18: 16000 | R18: 10300 | S18: 48000 | T18: 5000 | U18: 0 | V18: 6500 | W18: 500 | X18: 5600 | Y18: 1000 | Z18: 5500 | AA18: 0 | AB18: 89.451613 | AC18: 3500 | AD18: 1300 | AE18: 0 | AF18: 10000 | AG18: 2000 | AH18: 800 | AI18: 7200 | AJ18: 0 | AK18: 2000 | AL18: 1000 | AM18: 11000 | AN18: 2000 | AO18: 10000 | AP18: 6000 | AQ18: 8000 | AR18: 3500 | AS18: 0 | AT18: 0 | AU18: 700 | AV18: 3500 | AW18: 2000 | AX18: 369.61071 | AY18: 0 | AZ18: 2499.7026 | BA18: 2499.7026 | BB18: 0 | BC18: 13500
B19: =B18+1 -> 46215 | C19: =TEXT(B19,"ddd") -> Sun | D19: =SUM(E19:BC19) -> 186138.45 | E19: 700 | F19: 1000 | G19: 1200 | H19: 999.51613 | I19: 644.02065 | J19: 0 | K19: 0 | L19: 603.76323 | M19: 673.27548 | N19: 0 | O19: 5000 | P19: 300 | Q19: 6659.5545 | R19: 10300 | S19: =48000+6000 -> 54000 | T19: 5000 | U19: 0 | V19: 6500 | W19: 500 | X19: 5600 | Y19: 0 | Z19: 2500 | AA19: 0 | AB19: 89.451613 | AC19: 1000 | AD19: 1300 | AE19: 0 | AF19: 10000 | AG19: 2000 | AH19: 0 | AI19: 2999.8519 | AJ19: 0 | AK19: 2000 | AL19: 0 | AM19: 11000 | AN19: 2000 | AO19: 10000 | AP19: 5000 | AQ19: 8000 | AR19: 3500 | AS19: 0 | AT19: 0 | AU19: 700 | AV19: 3500 | AW19: 2000 | AX19: 369.61071 | AY19: 0 | AZ19: 2499.7026 | BA19: 2499.7026 | BB19: 0 | BC19: 13500
B20: Sub Total | D20: =SUM(D13:D19) -> 1478022.6 | E20: =SUM(E13:E19) -> 7397.8645 | F20: =SUM(F13:F19) -> 12000 | G20: =SUM(G13:G19) -> 8400 | H20: =SUM(H13:H19) -> 20799.516 | I20: =SUM(I13:I19) -> 4508.1445 | J20: =SUM(J13:J19) -> 0 | K20: =SUM(K13:K19) -> 900 | ... Z20: =SUM(Z13:Z19) -> 35500 | AA20: 0 | AB20: 626.16129 | AC20: =SUM(AC13:AC19) -> 22000 | AD20: =SUM(AD13:AD19) -> 9100 | AE20: =SUM(AE13:AE19) -> 15000 | AF20: =SUM(AF13:AF19) -> 70000 | AG20: =SUM(AG13:AG19) -> 14000 | AH20: =SUM(AH13:AH19) -> 4800 | AI20: =SUM(AI13:AI19) -> 46199.852 | AJ20: =SUM(AJ13:AJ19) -> 17499.384 | ... AR20: =SUM(AR13:AR19) -> 24500 | AS20: 0 | AT20: 0 | AU20: =SUM(AU13:AU19) -> 4900 | AV20: =SUM(AV13:AV19) -> 24500 | AW20: =SUM(AW13:AW19) -> 14000 | AX20: =SUM(AX13:AX19) -> 2587.275 | AY20: =SUM(AY13:AY19) -> 5609.5016 | AZ20: =SUM(AZ13:AZ19) -> 17497.918 | BA20: =SUM(BA13:BA19) -> 17497.918 | BB20: =SUM(BB13:BB19) -> 0 | BC20: =SUM(BC13:BC19) -> 94500
A22: =WEEKNUM(B22) -> 29 | B22: =B19+1 -> 46216 | C22: =TEXT(B22,"ddd") -> Mon | D22: =SUM(E22:BC22) -> 213250.93 | E22: 1199.5729 | F22: 2000 | G22: 1200 | H22: 3300 | I22: 644.02065 | J22: 0 | K22: 150 | L22: 603.76323 | M22: 673.27548 | N22: 5500 | O22: 5000 | P22: 2500 | Q22: 16000 | R22: 10300 | S22: 35000 | T22: 5000 | U22: 7000 | V22: 6500 | W22: 500 | X22: 5600 | Y22: 1000 | Z22: 5500 | AA22: 0 | AB22: 89.451613 | AC22: 3500 | AD22: 1300 | AE22: 3000 | AF22: 10000 | AG22: 2000 | AH22: 800 | AI22: 7200 | AJ22: 3499.8768 | AK22: 2000 | AL22: 1000 | AM22: 11000 | AN22: 2000 | AO22: 4000 | AP22: 9000.0571 | AQ22: 8000 | AR22: 3500 | AS22: 0 | AT22: 0 | AU22: 700 | AV22: 3500 | AW22: 2000 | AX22: 369.61071 | AY22: 1121.9003 | AZ22: 2499.7026 | BA22: 2499.7026 | BB22: 0 | BC22: 13500
B23: =B22+1 -> 46217 | C23: =TEXT(B23,"ddd") -> Tue | D23: =SUM(E23:BC23) -> 213250.93 | E23: 1199.5729 | F23: 2000 | G23: 1200 | H23: 3300 | I23: 644.02065 | J23: 0 | K23: 150 | L23: 603.76323 | M23: 673.27548 | N23: 5500 | O23: 5000 | P23: 2500 | Q23: 16000 | R23: 10300 | S23: 35000 | T23: 5000 | U23: 7000 | V23: 6500 | W23: 500 | X23: 5600 | Y23: 1000 | Z23: 5500 | AA23: 0 | AB23: 89.451613 | AC23: 3500 | AD23: 1300 | AE23: 3000 | AF23: 10000 | AG23: 2000 | AH23: 800 | AI23: 7200 | AJ23: 3499.8768 | AK23: 2000 | AL23: 1000 | AM23: 11000 | AN23: 2000 | AO23: 4000 | AP23: 9000.0571 | AQ23: 8000 | AR23: 3500 | AS23: =SUM(AS16:AS22) -> 0 | AT23: =SUM(AT16:AT22) -> 0 | AU23: 700 | AV23: 3500 | AW23: 2000 | AX23: 369.61071 | AY23: 1121.9003 | AZ23: 2499.7026 | BA23: 2499.7026 | BB23: 0 | BC23: 13500
B24: =B23+1 -> 46218 | C24: =TEXT(B24,"ddd") -> Wed | D24: =SUM(E24:BC24) -> 213250.93 | E24: 1199.5729 | F24: 2000 | G24: 1200 | H24: 3300 | I24: 644.02065 | J24: 0 | K24: 150 | L24: 603.76323 | M24: 673.27548 | N24: 5500 | O24: 5000 | P24: 2500 | Q24: 16000 | R24: 10300 | S24: 35000 | T24: 5000 | U24: 7000 | V24: 6500 | W24: 500 | X24: 5600 | Y24: 1000 | Z24: 5500 | AA24: 0 | AB24: 89.451613 | AC24: 3500 | AD24: 1300 | AE24: 3000 | AF24: 10000 | AG24: 2000 | AH24: 800 | AI24: 7200 | AJ24: 3499.8768 | AK24: 2000 | AL24: 1000 | AM24: 11000 | AN24: 2000 | AO24: 4000 | AP24: 9000.0571 | AQ24: 8000 | AR24: 3500 | AU24: 700 | AV24: 3500 | AW24: 2000 | AX24: 369.61071 | AY24: 1121.9003 | AZ24: 2499.7026 | BA24: 2499.7026 | BB24: 0 | BC24: 13500
B25: =B24+1 -> 46219 | C25: =TEXT(B25,"ddd") -> Thu | D25: =SUM(E25:BC25) -> 213250.93 | E25: 1199.5729 | F25: 2000 | G25: 1200 | H25: 3300 | I25: 644.02065 | J25: 0 | K25: 150 | L25: 603.76323 | M25: 673.27548 | N25: 5500 | O25: 5000 | P25: 2500 | Q25: 16000 | R25: 10300 | S25: 35000 | T25: 5000 | U25: 7000 | V25: 6500 | W25: 500 | X25: 5600 | Y25: 1000 | Z25: 5500 | AA25: 0 | AB25: 89.451613 | AC25: 3500 | AD25: 1300 | AE25: 3000 | AF25: 10000 | AG25: 2000 | AH25: 800 | AI25: 7200 | AJ25: 3499.8768 | AK25: 2000 | AL25: 1000 | AM25: 11000 | AN25: 2000 | AO25: 4000 | AP25: 9000.0571 | AQ25: 8000 | AR25: 3500 | AS25: 0 | AT25: 0 | AU25: 700 | AV25: 3500 | AW25: 2000 | AX25: 369.61071 | AY25: 1121.9003 | AZ25: 2499.7026 | BA25: 2499.7026 | BB25: 0 | BC25: 13500
B26: =B25+1 -> 46220 | C26: =TEXT(B26,"ddd") -> Fri | D26: =SUM(E26:BC26) -> 213250.93 | E26: 1199.5729 | F26: 2000 | G26: 1200 | H26: 3300 | I26: 644.02065 | J26: 0 | K26: 150 | L26: 603.76323 | M26: 673.27548 | N26: 5500 | O26: 5000 | P26: 2500 | Q26: 16000 | R26: 10300 | S26: 35000 | T26: 5000 | U26: 7000 | V26: 6500 | W26: 500 | X26: 5600 | Y26: 1000 | Z26: 5500 | AA26: 0 | AB26: 89.451613 | AC26: 3500 | AD26: 1300 | AE26: 3000 | AF26: 10000 | AG26: 2000 | AH26: 800 | AI26: 7200 | AJ26: 3499.8768 | AK26: 2000 | AL26: 1000 | AM26: 11000 | AN26: 2000 | AO26: 4000 | AP26: 9000.0571 | AQ26: 8000 | AR26: 3500 | AS26: 0 | AT26: 0 | AU26: 700 | AV26: 3500 | AW26: 2000 | AX26: 369.61071 | AY26: 1121.9003 | AZ26: 2499.7026 | BA26: 2499.7026 | BB26: 0 | BC26: 13500
B27: =B26+1 -> 46221 | C27: =TEXT(B27,"ddd") -> Sat | D27: =SUM(E27:BC27) -> 204629.53 | E27: 700 | F27: 1000 | G27: 1200 | H27: 3300 | I27: 644.02065 | J27: 0 | K27: 150 | L27: 603.76323 | M27: 673.27548 | N27: 4500 | O27: 5000 | P27: 1000 | Q27: 16000 | R27: 10300 | S27: 48000 | T27: 5000 | U27: 0 | V27: 6500 | W27: 500 | X27: 5600 | Y27: 1000 | Z27: 5500 | AA27: 0 | AB27: 89.451613 | AC27: 3500 | AD27: 1300 | AE27: 0 | AF27: 10000 | AG27: 2000 | AH27: 800 | AI27: 7200 | AJ27: 0 | AK27: 2000 | AL27: 1000 | AM27: 11000 | AN27: 2000 | AO27: 4000 | AP27: 6000 | AQ27: 8000 | AR27: 3500 | AS27: 0 | AT27: 0 | AU27: 700 | AV27: 3500 | AW27: 2000 | AX27: 369.61071 | AY27: 0 | AZ27: 2499.7026 | BA27: 2499.7026 | BB27: 0 | BC27: 13500
B28: =B27+1 -> 46222 | C28: =TEXT(B28,"ddd") -> Sun | D28: =SUM(E28:BC28) -> 180138.45 | E28: 700 | F28: 1000 | G28: 1200 | H28: 999.51613 | I28: 644.02065 | J28: 0 | K28: 0 | L28: 603.76323 | M28: 673.27548 | N28: 0 | O28: 5000 | P28: 300 | Q28: 6659.5545 | R28: 10300 | S28: =48000+6000 -> 54000 | T28: 5000 | U28: 0 | V28: 6500 | W28: 500 | X28: 5600 | Y28: 0 | Z28: 2500 | AA28: 0 | AB28: 89.451613 | AC28: 1000 | AD28: 1300 | AE28: 0 | AF28: 10000 | AG28: 2000 | AH28: 0 | AI28: 2999.8519 | AJ28: 0 | AK28: 2000 | AL28: 0 | AM28: 11000 | AN28: 2000 | AO28: 4000 | AP28: 5000 | AQ28: 8000 | AR28: 3500 | AS28: 0 | AT28: 0 | AU28: 700 | AV28: 3500 | AW28: 2000 | AX28: 369.61071 | AY28: 0 | AZ28: 2499.7026 | BA28: 2499.7026 | BB28: 0 | BC28: 13500
B29: Sub Total | D29: =SUM(D22:D28) -> 1451022.6 | E29: =SUM(E22:E28) -> 7397.8645 | F29: =SUM(F22:F28) -> 12000 | G29: =SUM(G22:G28) -> 8400 | H29: =SUM(H22:H28) -> 20799.516 | I29: =SUM(I22:I28) -> 4508.1445 | J29: =SUM(J22:J28) -> 0 | K29: =SUM(K22:K28) -> 900 | ... Z29: =SUM(Z22:Z28) -> 35500 | AA29: 0 | AB29: 626.16129 | AC29: =SUM(AC22:AC28) -> 22000 | AD29: =SUM(AD22:AD28) -> 9100 | AE29: =SUM(AE22:AE28) -> 15000 | AF29: =SUM(AF22:AF28) -> 70000 | AG29: =SUM(AG22:AG28) -> 14000 | AH29: =SUM(AH22:AH28) -> 4800 | AI29: =SUM(AI22:AI28) -> 46199.852 | AJ29: =SUM(AJ22:AJ28) -> 17499.384 | ... AR29: =SUM(AR22:AR28) -> 24500 | AS29: 0 | AT29: 0 | AU29: =SUM(AU22:AU28) -> 4900 | AV29: =SUM(AV22:AV28) -> 24500 | AW29: =SUM(AW22:AW28) -> 14000 | AX29: =SUM(AX22:AX28) -> 2587.275 | AY29: =SUM(AY22:AY28) -> 5609.5016 | AZ29: =SUM(AZ22:AZ28) -> 17497.918 | BA29: =SUM(BA22:BA28) -> 17497.918 | BB29: =SUM(BB22:BB28) -> 0 | BC29: =SUM(BC22:BC28) -> 94500
A31: =WEEKNUM(B31) -> 30 | B31: =B28+1 -> 46223 | C31: =TEXT(B31,"ddd") -> Mon | D31: =SUM(E31:BC31) -> 215751.06 | E31: 1199.5729 | F31: 2000 | G31: 1200 | H31: 3300 | I31: 644.02065 | J31: 0 | K31: 150 | L31: 603.76323 | M31: 673.27548 | N31: 5500 | O31: 5000 | P31: 2500 | Q31: 16000 | R31: 11000 | S31: 35000 | T31: 7000 | U31: 7000 | V31: 6500 | W31: 500 | X31: 5600 | Y31: 1000 | Z31: 5500 | AA31: 0 | AB31: 89.451613 | AC31: 3500 | AD31: 1300 | AE31: 3000 | AF31: 10000 | AG31: 2000 | AH31: 800 | AI31: 8000 | AJ31: 2000 | AK31: 2000 | AL31: 1000 | AM31: 11000 | AN31: 2000 | AO31: 4000 | AP31: 9000.0571 | AQ31: 8000 | AR31: 3500 | AS31: 0 | AT31: 0 | AU31: 700 | AV31: 4000 | AW31: 2000 | AX31: 369.61071 | AY31: 1121.9003 | AZ31: 2499.7026 | BA31: 2499.7026 | BB31: 0 | BC31: 13500
B32: =B31+1 -> 46224 | C32: =TEXT(B32,"ddd") -> Tue | D32: =SUM(E32:BC32) -> 215751.06 | E32: 1199.5729 | F32: 2000 | G32: 1200 | H32: 3300 | I32: 644.02065 | J32: 0 | K32: 150 | L32: 603.76323 | M32: 673.27548 | N32: 5500 | O32: 5000 | P32: 2500 | Q32: 16000 | R32: 11000 | S32: 35000 | T32: 7000 | U32: 7000 | V32: 6500 | W32: 500 | X32: 5600 | Y32: 1000 | Z32: 5500 | AA32: 0 | AB32: 89.451613 | AC32: 3500 | AD32: 1300 | AE32: 3000 | AF32: 10000 | AG32: 2000 | AH32: 800 | AI32: 8000 | AJ32: 2000 | AK32: 2000 | AL32: 1000 | AM32: 11000 | AN32: 2000 | AO32: 4000 | AP32: 9000.0571 | AQ32: 8000 | AR32: 3500 | AS32: =SUM(AS25:AS31) -> 0 | AT32: =SUM(AT25:AT31) -> 0 | AU32: 700 | AV32: 4000 | AW32: 2000 | AX32: 369.61071 | AY32: 1121.9003 | AZ32: 2499.7026 | BA32: 2499.7026 | BB32: 0 | BC32: 13500
B33: =B32+1 -> 46225 | C33: =TEXT(B33,"ddd") -> Wed | D33: =SUM(E33:BC33) -> 215751.06 | E33: 1199.5729 | F33: 2000 | G33: 1200 | H33: 3300 | I33: 644.02065 | J33: 0 | K33: 150 | L33: 603.76323 | M33: 673.27548 | N33: 5500 | O33: 5000 | P33: 2500 | Q33: 16000 | R33: 11000 | S33: 35000 | T33: 7000 | U33: 7000 | V33: 6500 | W33: 500 | X33: 5600 | Y33: 1000 | Z33: 5500 | AA33: 0 | AB33: 89.451613 | AC33: 3500 | AD33: 1300 | AE33: 3000 | AF33: 10000 | AG33: 2000 | AH33: 800 | AI33: 8000 | AJ33: 2000 | AK33: 2000 | AL33: 1000 | AM33: 11000 | AN33: 2000 | AO33: 4000 | AP33: 9000.0571 | AQ33: 8000 | AR33: 3500 | AU33: 700 | AV33: 4000 | AW33: 2000 | AX33: 369.61071 | AY33: 1121.9003 | AZ33: 2499.7026 | BA33: 2499.7026 | BB33: 0 | BC33: 13500
B34: =B33+1 -> 46226 | C34: =TEXT(B34,"ddd") -> Thu | D34: =SUM(E34:BC34) -> 215751.06 | E34: 1199.5729 | F34: 2000 | G34: 1200 | H34: 3300 | I34: 644.02065 | J34: 0 | K34: 150 | L34: 603.76323 | M34: 673.27548 | N34: 5500 | O34: 5000 | P34: 2500 | Q34: 16000 | R34: 11000 | S34: 35000 | T34: 7000 | U34: 7000 | V34: 6500 | W34: 500 | X34: 5600 | Y34: 1000 | Z34: 5500 | AA34: 0 | AB34: 89.451613 | AC34: 3500 | AD34: 1300 | AE34: 3000 | AF34: 10000 | AG34: 2000 | AH34: 800 | AI34: 8000 | AJ34: 2000 | AK34: 2000 | AL34: 1000 | AM34: 11000 | AN34: 2000 | AO34: 4000 | AP34: 9000.0571 | AQ34: 8000 | AR34: 3500 | AS34: 0 | AT34: 0 | AU34: 700 | AV34: 4000 | AW34: 2000 | AX34: 369.61071 | AY34: 1121.9003 | AZ34: 2499.7026 | BA34: 2499.7026 | BB34: 0 | BC34: 13500
B35: =B34+1 -> 46227 | C35: =TEXT(B35,"ddd") -> Fri | D35: =SUM(E35:BC35) -> 215751.06 | E35: 1199.5729 | F35: 2000 | G35: 1200 | H35: 3300 | I35: 644.02065 | J35: 0 | K35: 150 | L35: 603.76323 | M35: 673.27548 | N35: 5500 | O35: 5000 | P35: 2500 | Q35: 16000 | R35: 11000 | S35: 35000 | T35: 7000 | U35: 7000 | V35: 6500 | W35: 500 | X35: 5600 | Y35: 1000 | Z35: 5500 | AA35: 0 | AB35: 89.451613 | AC35: 3500 | AD35: 1300 | AE35: 3000 | AF35: 10000 | AG35: 2000 | AH35: 800 | AI35: 8000 | AJ35: 2000 | AK35: 2000 | AL35: 1000 | AM35: 11000 | AN35: 2000 | AO35: 4000 | AP35: 9000.0571 | AQ35: 8000 | AR35: 3500 | AS35: 0 | AT35: 0 | AU35: 700 | AV35: 4000 | AW35: 2000 | AX35: 369.61071 | AY35: 1121.9003 | AZ35: 2499.7026 | BA35: 2499.7026 | BB35: 0 | BC35: 13500
B36: =B35+1 -> 46228 | C36: =TEXT(B36,"ddd") -> Sat | D36: =SUM(E36:BC36) -> 206129.53 | E36: 700 | F36: 1000 | G36: 1200 | H36: 3300 | I36: 644.02065 | J36: 0 | K36: 150 | L36: 603.76323 | M36: 673.27548 | N36: 4500 | O36: 5000 | P36: 1000 | Q36: 16000 | R36: 11000 | S36: 48000 | T36: 7000 | U36: 0 | V36: 6500 | W36: 500 | X36: 5600 | Y36: 1000 | Z36: 5500 | AA36: 0 | AB36: 89.451613 | AC36: 3500 | AD36: 1300 | AE36: 0 | AF36: 10000 | AG36: 2000 | AH36: 800 | AI36: 5500 | AJ36: 0 | AK36: 2000 | AL36: 1000 | AM36: 11000 | AN36: 2000 | AO36: 4000 | AP36: 6000 | AQ36: 8000 | AR36: 3500 | AS36: 0 | AT36: 0 | AU36: 700 | AV36: 4000 | AW36: 2000 | AX36: 369.61071 | AY36: 0 | AZ36: 2499.7026 | BA36: 2499.7026 | BB36: 0 | BC36: 13500
B37: =B36+1 -> 46229 | C37: =TEXT(B37,"ddd") -> Sun | D37: =SUM(E37:BC37) -> 183338.45 | E37: 700 | F37: 1000 | G37: 1200 | H37: 999.51613 | I37: 644.02065 | J37: 0 | K37: 0 | L37: 603.76323 | M37: 673.27548 | N37: 0 | O37: 5000 | P37: 300 | Q37: 6659.5545 | R37: 11000 | S37: =48000+6000 -> 54000 | T37: 7000 | U37: 0 | V37: 6500 | W37: 500 | X37: 5600 | Y37: 0 | Z37: 2500 | AA37: 0 | AB37: 89.451613 | AC37: 1000 | AD37: 1300 | AE37: 0 | AF37: 10000 | AG37: 2000 | AH37: 0 | AI37: 2999.8519 | AJ37: 0 | AK37: 2000 | AL37: 0 | AM37: 11000 | AN37: 2000 | AO37: 4000 | AP37: 5000 | AQ37: 8000 | AR37: 3500 | AS37: 0 | AT37: 0 | AU37: 700 | AV37: 4000 | AW37: 2000 | AX37: 369.61071 | AY37: 0 | AZ37: 2499.7026 | BA37: 2499.7026 | BB37: 0 | BC37: 13500
B38: Sub Total | D38: =SUM(D31:D37) -> 1468223.3 | E38: =SUM(E31:E37) -> 7397.8645 | F38: =SUM(F31:F37) -> 12000 | G38: =SUM(G31:G37) -> 8400 | H38: =SUM(H31:H37) -> 20799.516 | I38: =SUM(I31:I37) -> 4508.1445 | J38: =SUM(J31:J37) -> 0 | K38: =SUM(K31:K37) -> 900 | ... BC38: =SUM(BC31:BC37) -> 94500
A40: =WEEKNUM(B40) -> 31 | B40: =B37+1 -> 46230 | C40: =TEXT(B40,"ddd") -> Mon | D40: =SUM(E40:BC40) -> 215751.06 | E40: 1199.5729 | F40: 2000 | G40: 1200 | H40: 3300 | I40: 644.02065 | J40: 0 | K40: 150 | L40: 603.76323 | M40: 673.27548 | N40: 5500 | O40: 5000 | P40: 2500 | Q40: 16000 | R40: 11000 | S40: 35000 | T40: 7000 | U40: 7000 | V40: 6500 | W40: 500 | X40: 5600 | Y40: 1000 | Z40: 5500 | AA40: 0 | AB40: 89.451613 | AC40: 3500 | AD40: 1300 | AE40: 3000 | AF40: 10000 | AG40: 2000 | AH40: 800 | AI40: 8000 | AJ40: 2000 | AK40: 2000 | AL40: 1000 | AM40: 11000 | AN40: 2000 | AO40: 4000 | AP40: 9000.0571 | AQ40: 8000 | AR40: 3500 | AS40: 0 | AT40: 0 | AU40: 700 | AV40: 4000 | AW40: 2000 | AX40: 369.61071 | AY40: 1121.9003 | AZ40: 2499.7026 | BA40: 2499.7026 | BB40: 0 | BC40: 13500
B41: =B40+1 -> 46231 | C41: =TEXT(B41,"ddd") -> Tue | D41: =SUM(E41:BC41) -> 215751.06 | E41: 1199.5729 | F41: 2000 | G41: 1200 | H41: 3300 | I41: 644.02065 | J41: 0 | K41: 150 | L41: 603.76323 | M41: 673.27548 | N41: 5500 | O41: 5000 | P41: 2500 | Q41: 16000 | R41: 11000 | S41: 35000 | T41: 7000 | U41: 7000 | V41: 6500 | W41: 500 | X41: 5600 | Y41: 1000 | Z41: 5500 | AA41: 0 | AB41: 89.451613 | AC41: 3500 | AD41: 1300 | AE41: 3000 | AF41: 10000 | AG41: 2000 | AH41: 800 | AI41: 8000 | AJ41: 2000 | AK41: 2000 | AL41: 1000 | AM41: 11000 | AN41: 2000 | AO41: 4000 | AP41: 9000.0571 | AQ41: 8000 | AR41: 3500 | AS41: 0 | AT41: 0 | AU41: 700 | AV41: 4000 | AW41: 2000 | AX41: 369.61071 | AY41: 1121.9003 | AZ41: 2499.7026 | BA41: 2499.7026 | BB41: 0 | BC41: 13500
B42: =B41+1 -> 46232 | C42: =TEXT(B42,"ddd") -> Wed | D42: =SUM(E42:BC42) -> 215751.06 | E42: 1199.5729 | F42: 2000 | G42: 1200 | H42: 3300 | I42: 644.02065 | J42: 0 | K42: 150 | L42: 603.76323 | M42: 673.27548 | N42: 5500 | O42: 5000 | P42: 2500 | Q42: 16000 | R42: 11000 | S42: 35000 | T42: 7000 | U42: 7000 | V42: 6500 | W42: 500 | X42: 5600 | Y42: 1000 | Z42: 5500 | AA42: 0 | AB42: 89.451613 | AC42: 3500 | AD42: 1300 | AE42: 3000 | AF42: 10000 | AG42: 2000 | AH42: 800 | AI42: 8000 | AJ42: 2000 | AK42: 2000 | AL42: 1000 | AM42: 11000 | AN42: 2000 | AO42: 4000 | AP42: 9000.0571 | AQ42: 8000 | AR42: 3500 | AS42: 0 | AT42: 0 | AU42: 700 | AV42: 4000 | AW42: 2000 | AX42: 369.61071 | AY42: 1121.9003 | AZ42: 2499.7026 | BA42: 2499.7026 | BB42: 0 | BC42: 13500
B43: =B42+1 -> 46233 | C43: =TEXT(B43,"ddd") -> Thu | D43: =SUM(E43:BC43) -> 215751.06 | E43: 1199.5729 | F43: 2000 | G43: 1200 | H43: 3300 | I43: 644.02065 | J43: 0 | K43: 150 | L43: 603.76323 | M43: 673.27548 | N43: 5500 | O43: 5000 | P43: 2500 | Q43: 16000 | R43: 11000 | S43: 35000 | T43: 7000 | U43: 7000 | V43: 6500 | W43: 500 | X43: 5600 | Y43: 1000 | Z43: 5500 | AA43: 0 | AB43: 89.451613 | AC43: 3500 | AD43: 1300 | AE43: 3000 | AF43: 10000 | AG43: 2000 | AH43: 800 | AI43: 8000 | AJ43: 2000 | AK43: 2000 | AL43: 1000 | AM43: 11000 | AN43: 2000 | AO43: 4000 | AP43: 9000.0571 | AQ43: 8000 | AR43: 3500 | AS43: 0 | AT43: 0 | AU43: 700 | AV43: 4000 | AW43: 2000 | AX43: 369.61071 | AY43: 1121.9003 | AZ43: 2499.7026 | BA43: 2499.7026 | BB43: 0 | BC43: 13500
B44: =B43+1 -> 46234 | C44: =TEXT(B44,"ddd") -> Fri | D44: =SUM(E44:BC44) -> 215751.06 | E44: 1199.5729 | F44: 2000 | G44: 1200 | H44: 3300 | I44: 644.02065 | J44: 0 | K44: 150 | L44: 603.76323 | M44: 673.27548 | N44: 5500 | O44: 5000 | P44: 2500 | Q44: 16000 | R44: 11000 | S44: 35000 | T44: 7000 | U44: 7000 | V44: 6500 | W44: 500 | X44: 5600 | Y44: 1000 | Z44: 5500 | AA44: 0 | AB44: 89.451613 | AC44: 3500 | AD44: 1300 | AE44: 3000 | AF44: 10000 | AG44: 2000 | AH44: 800 | AI44: 8000 | AJ44: 2000 | AK44: 2000 | AL44: 1000 | AM44: 11000 | AN44: 2000 | AO44: 4000 | AP44: 9000.0571 | AQ44: 8000 | AR44: 3500 | AS44: 0 | AT44: 0 | AU44: 700 | AV44: 4000 | AW44: 2000 | AX44: 369.61071 | AY44: 1121.9003 | AZ44: 2499.7026 | BA44: 2499.7026 | BB44: 0 | BC44: 13500
B45: Sub Total | D45: =SUM(D40:D44) -> 1078755.3 | E45: =SUM(E40:E44) -> 5997.8645 | F45: =SUM(F40:F44) -> 10000 | G45: =SUM(G40:G44) -> 6000 | H45: =SUM(H40:H44) -> 16500 | I45: =SUM(I40:I44) -> 3220.1032 | J45: =SUM(J40:J44) -> 0 | K45: =SUM(K40:K44) -> 750 | ... BC45: =SUM(BC40:BC44) -> 67500
B47: Sub Total | D47: =SUM(D45,D38,D29,D20,D11) -> 6521544.6 | E47: =SUM(E45,E38,E29,E20,E11) -> 33190.177 | F47: =SUM(F45,F38,F29,F20,F11) -> 54000 | G47: =SUM(G45,G38,G29,G20,G11) -> 37200 | H47: =SUM(H45,H38,H29,H20,H11) -> 93098.065 | I47: =SUM(I45,I38,I29,I20,I11) -> 19964.64 | J47: =SUM(J45,J38,J29,J20,J11) -> 0 | K47: =SUM(K45,K38,K29,K20,K11) -> 4050 | ... BC47: =SUM(BC45,BC38,BC29,BC20,BC11) -> 418500
...

Sheet KEBUTUHAN GAS
A1: KEBUTUHAN GAS
A4: ='SO FOB Juli 2026'!A4 -> 46204 | E4: KEBUTUHAN GAS | I4: KUOTA GAS
A5: Week | B5: DATE | D5: SELISIH GAS | E5: JABAR | F5: JATENG | G5: JATIM | H5: TOTAL | I5: MS SETU | J5: MS KHT | K5: MS BLORA | L5: MS BITUNG | M5: MS ZEBRA | N5: MS TAMBAKLOROK | O5: MS SAG | P5: MS SADANG | Q5: TOTAL
A6: =WEEKNUM(B6) -> 27 | B6: =A4 -> 46204 | C6: =TEXT(B6,"ddd") -> Wed | D6: =Q6-H6 -> -67277.439 | E6: =SUM('SO Juli 2026 Rev 2'!E6:AR6)-'SO Juli 2026 Rev 2'!V6 -> 183560.02 | F6: =SUM('SO Juli 2026 Rev 2'!AU6:BA6)+'SO Juli 2026 Rev 2'!V6 -> 19190.916 | G6: =SUM('SO Juli 2026 Rev 2'!BB6:BC6) -> 13500 | H6: =SUM(E6:G6) -> 216250.93 | I6: ='SO MS'!E6 -> 60000 | J6: ='SO MS'!F6 -> 34560 | K6: ='SO MS'!G6 -> 10800 | L6: ='SO MS'!H6 -> 10000 | M6: ='SO MS'!I6 -> 13500 | N6: ='SO MS'!J6 -> 3500 | O6: ='SO MS'!K6 -> 16613.495 | P6: ='SO MS'!L6 -> 0 | Q6: =SUM(I6:P6) -> 148973.49
B7: =B6+1 -> 46205 | C7: =TEXT(B7,"ddd") -> Thu | D7: =Q7-H7 -> -75356.128 | E7: =SUM('SO Juli 2026 Rev 2'!E7:AR7)-'SO Juli 2026 Rev 2'!V7 -> 183560.02 | F7: =SUM('SO Juli 2026 Rev 2'!AU7:BA7)+'SO Juli 2026 Rev 2'!V7 -> 19190.916 | G7: =SUM('SO Juli 2026 Rev 2'!BB7:BC7) -> 13500 | H7: =SUM(E7:G7) -> 216250.93 | I7: ='SO MS'!E7 -> 60000 | J7: ='SO MS'!F7 -> 34560 | K7: ='SO MS'!G7 -> 10800 | L7: ='SO MS'!H7 -> 10000 | M7: ='SO MS'!I7 -> 13500 | N7: ='SO MS'!J7 -> 3500 | O7: ='SO MS'!K7 -> 8534.806 | P7: ='SO MS'!L7 -> 0 | Q7: =SUM(I7:P7) -> 140894.81
B8: =B7+1 -> 46206 | C8: =TEXT(B8,"ddd") -> Fri | D8: =Q8-H8 -> -67059.403 | E8: =SUM('SO Juli 2026 Rev 2'!E8:AR8)-'SO Juli 2026 Rev 2'!V8 -> 183560.02 | F8: =SUM('SO Juli 2026 Rev 2'!AU8:BA8)+'SO Juli 2026 Rev 2'!V8 -> 19190.916 | G8: =SUM('SO Juli 2026 Rev 2'!BB8:BC8) -> 13500 | H8: =SUM(E8:G8) -> 216250.93 | I8: ='SO MS'!E8 -> 60000 | J8: ='SO MS'!F8 -> 34560 | K8: ='SO MS'!G8 -> 10800 | L8: ='SO MS'!H8 -> 10000 | M8: ='SO MS'!I8 -> 13500 | N8: ='SO MS'!J8 -> 3500 | O8: ='SO MS'!K8 -> 16831.531 | P8: ='SO MS'!L8 -> 0 | Q8: =SUM(I8:P8) -> 149191.53
B9: =B8+1 -> 46207 | C9: =TEXT(B9,"ddd") -> Sat | D9: =Q9-H9 -> -65700.037 | E9: =SUM('SO Juli 2026 Rev 2'!E9:AR9)-'SO Juli 2026 Rev 2'!V9 -> 179060.51 | F9: =SUM('SO Juli 2026 Rev 2'!AU9:BA9)+'SO Juli 2026 Rev 2'!V9 -> 18069.016 | G9: =SUM('SO Juli 2026 Rev 2'!BB9:BC9) -> 13500 | H9: =SUM(E9:G9) -> 210629.53 | I9: ='SO MS'!E9 -> 60000 | J9: ='SO MS'!F9 -> 34560 | K9: ='SO MS'!G9 -> 10800 | L9: ='SO MS'!H9 -> 10000 | M9: ='SO MS'!I9 -> 13500 | N9: ='SO MS'!J9 -> 3500 | O9: ='SO MS'!K9 -> 12569.49 | P9: ='SO MS'!L9 -> 0 | Q9: =SUM(I9:P9) -> 144929.49
B10: =B9+1 -> 46208 | C10: =TEXT(B10,"ddd") -> Sun | D10: =Q10-H10 -> -49701.163 | E10: =SUM('SO Juli 2026 Rev 2'!E10:AR10)-'SO Juli 2026 Rev 2'!V10 -> 154569.43 | F10: =SUM('SO Juli 2026 Rev 2'!AU10:BA10)+'SO Juli 2026 Rev 2'!V10 -> 18069.016 | G10: =SUM('SO Juli 2026 Rev 2'!BB10:BC10) -> 13500 | H10: =SUM(E10:G10) -> 186138.45 | I10: ='SO MS'!E10 -> 60000 | J10: ='SO MS'!F10 -> 34560 | K10: ='SO MS'!G10 -> 10800 | L10: ='SO MS'!H10 -> 10000 | M10: ='SO MS'!I10 -> 13500 | N10: ='SO MS'!J10 -> 3500 | O10: ='SO MS'!K10 -> 4077.286 | P10: ='SO MS'!L10 -> 0 | Q10: =SUM(I10:P10) -> 136437.29
B11: Sub Total | D11: =SUM(D6:D10) -> -325094.17 | E11: =SUM(E6:E10) -> 884310 | F11: =SUM(F6:F10) -> 93710.78 | G11: =SUM(G6:G10) -> 67500 | H11: =SUM(H6:H10) -> 1045520.8 | I11: =SUM(I6:I10) -> 300000 | J11: =SUM(J6:J10) -> 172800 | K11: =SUM(K6:K10) -> 54000 | ... Q11: =SUM(Q6:Q10) -> 720426.61
A13: =WEEKNUM(B13) -> 28 | B13: =B10+1 -> 46209 | C13: =TEXT(B13,"ddd") -> Mon | D13: =Q13-H13 -> -71394.409 | E13: =SUM('SO Juli 2026 Rev 2'!E13:AR13) -> 190060.02 | F13: =SUM('SO Juli 2026 Rev 2'!AU13:BA13) -> 12690.916 | G13: =SUM('SO Juli 2026 Rev 2'!BB13:BC13) -> 13500 | H13: =SUM(E13:G13) -> 216250.93 | I13: ='SO MS'!E13 -> 60000 | J13: ='SO MS'!F13 -> 34560 | K13: ='SO MS'!G13 -> 10800 | L13: ='SO MS'!H13 -> 10000 | M13: ='SO MS'!I13 -> 13500 | N13: ='SO MS'!J13 -> 3500 | O13: ='SO MS'!K13 -> 12496.525 | P13: ='SO MS'!L13 -> 0 | Q13: =SUM(I13:P13) -> 144856.52
B14: =B13+1 -> 46210 | C14: =TEXT(B14,"ddd") -> Tue | D14: =Q14-H14 -> -67655.663 | E14: =SUM('SO Juli 2026 Rev 2'!E14:AR14)-'SO Juli 2026 Rev 2'!V14 -> 183560.02 | F14: =SUM('SO Juli 2026 Rev 2'!AU14:BA14)+'SO Juli 2026 Rev 2'!V14 -> 19190.916 | G14: =SUM('SO Juli 2026 Rev 2'!BB14:BC14) -> 13500 | H14: =SUM(E14:G14) -> 216250.93 | I14: ='SO MS'!E14 -> 60000 | J14: ='SO MS'!F14 -> 34560 | K14: ='SO MS'!G14 -> 10800 | L14: ='SO MS'!H14 -> 10000 | M14: ='SO MS'!I14 -> 13500 | N14: ='SO MS'!J14 -> 3500 | O14: ='SO MS'!K14 -> 16235.271 | P14: ='SO MS'!L14 -> 0 | Q14: =SUM(I14:P14) -> 148595.27
B15: =B14+1 -> 46211 | C15: =TEXT(B15,"ddd") -> Wed | D15: =Q15-H15 -> -71180.196 | E15: =SUM('SO Juli 2026 Rev 2'!E15:AR15)-'SO Juli 2026 Rev 2'!V15 -> 183560.02 | F15: =SUM('SO Juli 2026 Rev 2'!AU15:BA15)+'SO Juli 2026 Rev 2'!V15 -> 19190.916 | G15: =SUM('SO Juli 2026 Rev 2'!BB15:BC15) -> 13500 | H15: =SUM(E15:G15) -> 216250.93 | I15: ='SO MS'!E15 -> 60000 | J15: ='SO MS'!F15 -> 34560 | K15: ='SO MS'!G15 -> 10800 | L15: ='SO MS'!H15 -> 10000 | M15: ='SO MS'!I15 -> 13500 | N15: ='SO MS'!J15 -> 3500 | O15: ='SO MS'!K15 -> 12710.738 | P15: ='SO MS'!L15 -> 0 | Q15: =SUM(I15:P15) -> 145070.74
B16: =B15+1 -> 46212 | C16: =TEXT(B16,"ddd") -> Thu | D16: =Q16-H16 -> -63180.318 | E16: =SUM('SO Juli 2026 Rev 2'!E16:AR16)-'SO Juli 2026 Rev 2'!V16 -> 183560.02 | F16: =SUM('SO Juli 2026 Rev 2'!AU16:BA16)+'SO Juli 2026 Rev 2'!V16 -> 19190.916 | G16: =SUM('SO Juli 2026 Rev 2'!BB16:BC16) -> 13500 | H16: =SUM(E16:G16) -> 216250.93 | I16: ='SO MS'!E16 -> 60000 | J16: ='SO MS'!F16 -> 34560 | K16: ='SO MS'!G16 -> 10800 | L16: ='SO MS'!H16 -> 10000 | M16: ='SO MS'!I16 -> 13500 | N16: ='SO MS'!J16 -> 3500 | O16: ='SO MS'!K16 -> 20710.616 | P16: ='SO MS'!L16 -> 0 | Q16: =SUM(I16:P16) -> 153070.62
B17: =B16+1 -> 46213 | C17: =TEXT(B17,"ddd") -> Fri | D17: =Q17-H17 -> -71116.597 | E17: =SUM('SO Juli 2026 Rev 2'!E17:AR17)-'SO Juli 2026 Rev 2'!V17 -> 183560.02 | F17: =SUM('SO Juli 2026 Rev 2'!AU17:BA17)+'SO Juli 2026 Rev 2'!V17 -> 19190.916 | G17: =SUM('SO Juli 2026 Rev 2'!BB17:BC17) -> 13500 | H17: =SUM(E17:G17) -> 216250.93 | I17: ='SO MS'!E17 -> 60000 | J17: ='SO MS'!F17 -> 34560 | K17: ='SO MS'!G17 -> 10800 | L17: ='SO MS'!H17 -> 10000 | M17: ='SO MS'!I17 -> 13500 | N17: ='SO MS'!J17 -> 3500 | O17: ='SO MS'!K17 -> 12774.337 | P17: ='SO MS'!L17 -> 0 | Q17: =SUM(I17:P17) -> 145134.34
B18: =B17+1 -> 46214 | C18: =TEXT(B18,"ddd") -> Sat | D18: =Q18-H18 -> -60882.072 | E18: =SUM('SO Juli 2026 Rev 2'!E18:AR18)-'SO Juli 2026 Rev 2'!V18 -> 179060.51 | F18: =SUM('SO Juli 2026 Rev 2'!AU18:BA18)+'SO Juli 2026 Rev 2'!V18 -> 18069.016 | G18: =SUM('SO Juli 2026 Rev 2'!BB18:BC18) -> 13500 | H18: =SUM(E18:G18) -> 210629.53 | I18: ='SO MS'!E18 -> 60000 | J18: ='SO MS'!F18 -> 34560 | K18: ='SO MS'!G18 -> 10800 | L18: ='SO MS'!H18 -> 10000 | M18: ='SO MS'!I18 -> 13500 | N18: ='SO MS'!J18 -> 3500 | O18: ='SO MS'!K18 -> 17387.455 | P18: ='SO MS'!L18 -> 0 | Q18: =SUM(I18:P18) -> 149747.46
B19: =B18+1 -> 46215 | C19: =TEXT(B19,"ddd") -> Sun | D19: =Q19-H19 -> -37053.591 | E19: =SUM('SO Juli 2026 Rev 2'!E19:AR19)-'SO Juli 2026 Rev 2'!V19 -> 154569.43 | F19: =SUM('SO Juli 2026 Rev 2'!AU19:BA19)+'SO Juli 2026 Rev 2'!V19 -> 18069.016 | G19: =SUM('SO Juli 2026 Rev 2'!BB19:BC19) -> 13500 | H19: =SUM(E19:G19) -> 186138.45 | I19: ='SO MS'!E19 -> 60000 | J19: ='SO MS'!F19 -> 34560 | K19: ='SO MS'!G19 -> 10800 | L19: ='SO MS'!H19 -> 10000 | M19: ='SO MS'!I19 -> 13500 | N19: ='SO MS'!J19 -> 3500 | O19: ='SO MS'!K19 -> 16724.858 | P19: ='SO MS'!L19 -> 0 | Q19: =SUM(I19:P19) -> 149084.86
B20: Sub Total | D20: =SUM(D13:D19) -> -442462.85 | E20: =SUM(E13:E19) -> 1257930 | F20: =SUM(F13:F19) -> 125592.61 | G20: =SUM(G13:G19) -> 94500 | H20: =SUM(H13:H19) -> 1478022.6 | I20: =SUM(I13:I19) -> 420000 | J20: =SUM(J13:J19) -> 241920 | K20: =SUM(K13:K19) -> 75600 | ... Q20: =SUM(Q13:Q19) -> 1035559.8
A22: =WEEKNUM(B22) -> 29 | B22: =B19+1 -> 46216 | C22: =TEXT(B22,"ddd") -> Mon | D22: =Q22-H22 -> -68194.396 | E22: =SUM('SO Juli 2026 Rev 2'!E22:AR22) -> 187060.02 | F22: =SUM('SO Juli 2026 Rev 2'!AU22:BA22) -> 12690.916 | G22: =SUM('SO Juli 2026 Rev 2'!BB22:BC22) -> 13500 | H22: =SUM(E22:G22) -> 213250.93 | I22: ='SO MS'!E22 -> 60000 | J22: ='SO MS'!F22 -> 34560 | K22: ='SO MS'!G22 -> 10800 | L22: ='SO MS'!H22 -> 10000 | M22: ='SO MS'!I22 -> 13500 | N22: ='SO MS'!J22 -> 3500 | O22: ='SO MS'!K22 -> 12696.538 | P22: ='SO MS'!L22 -> 0 | Q22: =SUM(I22:P22) -> 145056.54
B23: =B22+1 -> 46217 | C23: =TEXT(B23,"ddd") -> Tue | D23: =Q23-H23 -> -68465.863 | E23: =SUM('SO Juli 2026 Rev 2'!E23:AR23)-'SO Juli 2026 Rev 2'!V23 -> 180560.02 | F23: =SUM('SO Juli 2026 Rev 2'!AU23:BA23)+'SO Juli 2026 Rev 2'!V23 -> 19190.916 | G23: =SUM('SO Juli 2026 Rev 2'!BB23:BC23) -> 13500 | H23: =SUM(E23:G23) -> 213250.93 | I23: ='SO MS'!E23 -> 60000 | J23: ='SO MS'!F23 -> 34560 | K23: ='SO MS'!G23 -> 10800 | L23: ='SO MS'!H23 -> 10000 | M23: ='SO MS'!I23 -> 13500 | N23: ='SO MS'!J23 -> 3500 | O23: ='SO MS'!K23 -> 12425.071 | P23: ='SO MS'!L23 -> 0 | Q23: =SUM(I23:P23) -> 144785.07
B24: =B23+1 -> 46218 | C24: =TEXT(B24,"ddd") -> Wed | D24: =Q24-H24 -> -68302.24 | E24: =SUM('SO Juli 2026 Rev 2'!E24:AR24)-'SO Juli 2026 Rev 2'!V24 -> 180560.02 | F24: =SUM('SO Juli 2026 Rev 2'!AU24:BA24)+'SO Juli 2026 Rev 2'!V24 -> 19190.916 | G24: =SUM('SO Juli 2026 Rev 2'!BB24:BC24) -> 13500 | H24: =SUM(E24:G24) -> 213250.93 | I24: ='SO MS'!E24 -> 60000 | J24: ='SO MS'!F24 -> 34560 | K24: ='SO MS'!G24 -> 10800 | L24: ='SO MS'!H24 -> 10000 | M24: ='SO MS'!I24 -> 13500 | N24: ='SO MS'!J24 -> 3500 | O24: ='SO MS'!K24 -> 12588.694 | P24: ='SO MS'!L24 -> 0 | Q24: =SUM(I24:P24) -> 144948.69
B25: =B24+1 -> 46219 | C25: =TEXT(B25,"ddd") -> Thu | D25: =Q25-H25 -> -68283.525 | E25: =SUM('SO Juli 2026 Rev 2'!E25:AR25)-'SO Juli 2026 Rev 2'!V25 -> 180560.02 | F25: =SUM('SO Juli 2026 Rev 2'!AU25:BA25)+'SO Juli 2026 Rev 2'!V25 -> 19190.916 | G25: =SUM('SO Juli 2026 Rev 2'!BB25:BC25) -> 13500 | H25: =SUM(E25:G25) -> 213250.93 | I25: ='SO MS'!E25 -> 60000 | J25: ='SO MS'!F25 -> 34560 | K25: ='SO MS'!G25 -> 10800 | L25: ='SO MS'!H25 -> 10000 | M25: ='SO MS'!I25 -> 13500 | N25: ='SO MS'!J25 -> 3500 | O25: ='SO MS'!K25 -> 12607.409 | P25: ='SO MS'!L25 -> 0 | Q25: =SUM(I25:P25) -> 144967.41
B26: =B25+1 -> 46220 | C26: =TEXT(B26,"ddd") -> Fri | D26: =Q26-H26 -> -68256.485 | E26: =SUM('SO Juli 2026 Rev 2'!E26:AR26)-'SO Juli 2026 Rev 2'!V26 -> 180560.02 | F26: =SUM('SO Juli 2026 Rev 2'!AU26:BA26)+'SO Juli 2026 Rev 2'!V26 -> 19190.916 | G26: =SUM('SO Juli 2026 Rev 2'!BB26:BC26) -> 13500 | H26: =SUM(E26:G26) -> 213250.93 | I26: ='SO MS'!E26 -> 60000 | J26: ='SO MS'!F26 -> 34560 | K26: ='SO MS'!G26 -> 10800 | L26: ='SO MS'!H26 -> 10000 | M26: ='SO MS'!I26 -> 13500 | N26: ='SO MS'!J26 -> 3500 | O26: ='SO MS'!K26 -> 12634.449 | P26: ='SO MS'!L26 -> 0 | Q26: =SUM(I26:P26) -> 144994.45
B27: =B26+1 -> 46221 | C27: =TEXT(B27,"ddd") -> Sat | D27: =Q27-H27 -> -64131.725 | E27: =SUM('SO Juli 2026 Rev 2'!E27:AR27)-'SO Juli 2026 Rev 2'!V27 -> 173060.51 | F27: =SUM('SO Juli 2026 Rev 2'!AU27:BA27)+'SO Juli 2026 Rev 2'!V27 -> 18069.016 | G27: =SUM('SO Juli 2026 Rev 2'!BB27:BC27) -> 13500 | H27: =SUM(E27:G27) -> 204629.53 | I27: ='SO MS'!E27 -> 60000 | J27: ='SO MS'!F27 -> 34560 | K27: ='SO MS'!G27 -> 10800 | L27: ='SO MS'!H27 -> 10000 | M27: ='SO MS'!I27 -> 13500 | N27: ='SO MS'!J27 -> 3500 | O27: ='SO MS'!K27 -> 8137.802 | P27: ='SO MS'!L27 -> 0 | Q27: =SUM(I27:P27) -> 140497.8
B28: =B27+1 -> 46222 | C28: =TEXT(B28,"ddd") -> Sun | D28: =Q28-H28 -> -26491.212 | E28: =SUM('SO Juli 2026 Rev 2'!E28:AR28)-'SO Juli 2026 Rev 2'!V28 -> 148569.43 | F28: =SUM('SO Juli 2026 Rev 2'!AU28:BA28)+'SO Juli 2026 Rev 2'!V28 -> 18069.016 | G28: =SUM('SO Juli 2026 Rev 2'!BB28:BC28) -> 13500 | H28: =SUM(E28:G28) -> 180138.45 | I28: ='SO MS'!E28 -> 60000 | J28: ='SO MS'!F28 -> 34560 | K28: ='SO MS'!G28 -> 10800 | L28: ='SO MS'!H28 -> 10000 | M28: ='SO MS'!I28 -> 13500 | N28: ='SO MS'!J28 -> 3500 | O28: ='SO MS'!K28 -> 21287.237 | P28: ='SO MS'!L28 -> 0 | Q28: =SUM(I28:P28) -> 153647.24
B29: Sub Total | D29: =SUM(D22:D28) -> -432125.45 | E29: =SUM(E22:E28) -> 1230930 | F29: =SUM(F22:F28) -> 125592.61 | G29: =SUM(G22:G28) -> 94500 | H29: =SUM(H22:H28) -> 1451022.6 | I29: =SUM(I22:I28) -> 420000 | J29: =SUM(J22:J28) -> 241920 | K29: =SUM(K22:K28) -> 75600 | ... Q29: =SUM(Q22:Q28) -> 1018897.2
A31: =WEEKNUM(B31) -> 30 | B31: =B28+1 -> 46223 | C31: =TEXT(B31,"ddd") -> Mon | D31: =Q31-H31 -> -79094.725 | E31: =SUM('SO Juli 2026 Rev 2'!E31:AR31) -> 189060.14 | F31: =SUM('SO Juli 2026 Rev 2'!AU31:BA31) -> 13190.916 | G31: =SUM('SO Juli 2026 Rev 2'!BB31:BC31) -> 13500 | H31: =SUM(E31:G31) -> 215751.06 | I31: ='SO MS'!E31 -> 60000 | J31: ='SO MS'!F31 -> 34560 | K31: ='SO MS'!G31 -> 10800 | L31: ='SO MS'!H31 -> 10000 | M31: ='SO MS'!I31 -> 13500 | N31: ='SO MS'!J31 -> 3500 | O31: ='SO MS'!K31 -> 4296.332 | P31: ='SO MS'!L31 -> 0 | Q31: =SUM(I31:P31) -> 136656.33
B32: =B31+1 -> 46224 | C32: =TEXT(B32,"ddd") -> Tue | D32: =Q32-H32 -> -74680.165 | E32: =SUM('SO Juli 2026 Rev 2'!E32:AR32)-'SO Juli 2026 Rev 2'!V32 -> 182560.14 | F32: =SUM('SO Juli 2026 Rev 2'!AU32:BA32)+'SO Juli 2026 Rev 2'!V32 -> 19690.916 | G32: =SUM('SO Juli 2026 Rev 2'!BB32:BC32) -> 13500 | H32: =SUM(E32:G32) -> 215751.06 | I32: ='SO MS'!E32 -> 60000 | J32: ='SO MS'!F32 -> 34560 | K32: ='SO MS'!G32 -> 10800 | L32: ='SO MS'!H32 -> 10000 | M32: ='SO MS'!I32 -> 13500 | N32: ='SO MS'!J32 -> 3500 | O32: ='SO MS'!K32 -> 8710.892 | P32: ='SO MS'!L32 -> 0 | Q32: =SUM(I32:P32) -> 141070.89
B33: =B32+1 -> 46225 | C33: =TEXT(B33,"ddd") -> Wed | D33: =Q33-H33 -> -78998.798 | E33: =SUM('SO Juli 2026 Rev 2'!E33:AR33)-'SO Juli 2026 Rev 2'!V33 -> 182560.14 | F33: =SUM('SO Juli 2026 Rev 2'!AU33:BA33)+'SO Juli 2026 Rev 2'!V33 -> 19690.916 | G33: =SUM('SO Juli 2026 Rev 2'!BB33:BC33) -> 13500 | H33: =SUM(E33:G33) -> 215751.06 | I33: ='SO MS'!E33 -> 60000 | J33: ='SO MS'!F33 -> 34560 | K33: ='SO MS'!G33 -> 10800 | L33: ='SO MS'!H33 -> 10000 | M33: ='SO MS'!I33 -> 13500 | N33: ='SO MS'!J33 -> 3500 | O33: ='SO MS'!K33 -> 4392.259 | P33: ='SO MS'!L33 -> 0 | Q33: =SUM(I33:P33) -> 136752.26
B34: =B33+1 -> 46226 | C34: =TEXT(B34,"ddd") -> Thu | D34: =Q34-H34 -> -74881.979 | E34: =SUM('SO Juli 2026 Rev 2'!E34:AR34)-'SO Juli 2026 Rev 2'!V34 -> 182560.14 | F34: =SUM('SO Juli 2026 Rev 2'!AU34:BA34)+'SO Juli 2026 Rev 2'!V34 -> 19690.916 | G34: =SUM('SO Juli 2026 Rev 2'!BB34:BC34) -> 13500 | H34: =SUM(E34:G34) -> 215751.06 | I34: ='SO MS'!E34 -> 60000 | J34: ='SO MS'!F34 -> 34560 | K34: ='SO MS'!G34 -> 10800 | L34: ='SO MS'!H34 -> 10000 | M34: ='SO MS'!I34 -> 13500 | N34: ='SO MS'!J34 -> 3500 | O34: ='SO MS'!K34 -> 8509.078 | P34: ='SO MS'!L34 -> 0 | Q34: =SUM(I34:P34) -> 140869.08
B35: =B34+1 -> 46227 | C35: =TEXT(B35,"ddd") -> Fri | D35: =Q35-H35 -> -83391.057 | E35: =SUM('SO Juli 2026 Rev 2'!E35:AR35)-'SO Juli 2026 Rev 2'!V35 -> 182560.14 | F35: =SUM('SO Juli 2026 Rev 2'!AU35:BA35)+'SO Juli 2026 Rev 2'!V35 -> 19690.916 | G35: =SUM('SO Juli 2026 Rev 2'!BB35:BC35) -> 13500 | H35: =SUM(E35:G35) -> 215751.06 | I35: ='SO MS'!E35 -> 60000 | J35: ='SO MS'!F35 -> 34560 | K35: ='SO MS'!G35 -> 10800 | L35: ='SO MS'!H35 -> 10000 | M35: ='SO MS'!I35 -> 13500 | N35: ='SO MS'!J35 -> 3500 | O35: ='SO MS'!K35 -> 0 | P35: ='SO MS'!L35 -> 0 | Q35: =SUM(I35:P35) -> 132360
B36: =B35+1 -> 46228 | C36: =TEXT(B36,"ddd") -> Sat | D36: =Q36-H36 -> 300809.9 | E36: =SUM('SO Juli 2026 Rev 2'!E36:AR36)-'SO Juli 2026 Rev 2'!V36 -> 174060.51 | F36: =SUM('SO Juli 2026 Rev 2'!AU36:BA36)+'SO Juli 2026 Rev 2'!V36 -> 18569.016 | G36: =SUM('SO Juli 2026 Rev 2'!BB36:BC36) -> 13500 | H36: =SUM(E36:G36) -> 206129.53 | I36: ='SO MS'!E36 -> 60000 | J36: ='SO MS'!F36 -> 34560 | K36: ='SO MS'!G36 -> 10800 | L36: ='SO MS'!H36 -> 10000 | M36: ='SO MS'!I36 -> 13500 | N36: ='SO MS'!J36 -> 3500 | O36: ='SO MS'!K36 -> 374579.43 | P36: ='SO MS'!L36 -> 0 | Q36: =SUM(I36:P36) -> 506939.43
B37: =B36+1 -> 46229 | C37: =TEXT(B37,"ddd") -> Sun | D37: =Q37-H37 -> -50978.449 | E37: =SUM('SO Juli 2026 Rev 2'!E37:AR37)-'SO Juli 2026 Rev 2'!V37 -> 151269.43 | F37: =SUM('SO Juli 2026 Rev 2'!AU37:BA37)+'SO Juli 2026 Rev 2'!V37 -> 18569.016 | G37: =SUM('SO Juli 2026 Rev 2'!BB37:BC37) -> 13500 | H37: =SUM(E37:G37) -> 183338.45 | I37: ='SO MS'!E37 -> 60000 | J37: ='SO MS'!F37 -> 34560 | K37: ='SO MS'!G37 -> 10800 | L37: ='SO MS'!H37 -> 10000 | M37: ='SO MS'!I37 -> 13500 | N37: ='SO MS'!J37 -> 3500 | O37: ='SO MS'!K37 -> 0 | P37: ='SO MS'!L37 -> 0 | Q37: =SUM(I37:P37) -> 132360
B38: Sub Total | D38: =SUM(D31:D37) -> -141215.27 | E38: =SUM(E31:E37) -> 1244630.6 | F38: =SUM(F31:F37) -> 129092.61 | G38: =SUM(G31:G37) -> 94500 | H38: =SUM(H31:H37) -> 1468223.3 | I38: =SUM(I31:I37) -> 420000 | J38: =SUM(J31:J37) -> 241920 | K38: =SUM(K31:K37) -> 75600 | ... Q38: =SUM(Q31:Q37) -> 1327008
A40: =WEEKNUM(B40) -> 31 | B40: =B37+1 -> 46230 | C40: =TEXT(B40,"ddd") -> Mon | D40: =Q40-H40 -> -83391.057 | E40: =SUM('SO Juli 2026 Rev 2'!E40:AR40)-'SO Juli 2026 Rev 2'!V40 -> 182560.14 | F40: =SUM('SO Juli 2026 Rev 2'!AU40:BA40)+'SO Juli 2026 Rev 2'!V40 -> 19690.916 | G40: =SUM('SO Juli 2026 Rev 2'!BB40:BC40) -> 13500 | H40: =SUM(E40:G40) -> 215751.06 | I40: ='SO MS'!E40 -> 60000 | J40: ='SO MS'!F40 -> 34560 | K40: ='SO MS'!G40 -> 10800 | L40: ='SO MS'!H40 -> 10000 | M40: ='SO MS'!I40 -> 13500 | N40: ='SO MS'!J40 -> 3500 | O40: ='SO MS'!K40 -> 0 | P40: ='SO MS'!L40 -> 0 | Q40: =SUM(I40:P40) -> 132360
B41: =B40+1 -> 46231 | C41: =TEXT(B41,"ddd") -> Tue | D41: =Q41-H41 -> -83391.057 | E41: =SUM('SO Juli 2026 Rev 2'!E41:AR41)-'SO Juli 2026 Rev 2'!V41 -> 182560.14 | F41: =SUM('SO Juli 2026 Rev 2'!AU41:BA41)+'SO Juli 2026 Rev 2'!V41 -> 19690.916 | G41: =SUM('SO Juli 2026 Rev 2'!BB41:BC41) -> 13500 | H41: =SUM(E41:G41) -> 215751.06 | I41: ='SO MS'!E41 -> 60000 | J41: ='SO MS'!F41 -> 34560 | K41: ='SO MS'!G41 -> 10800 | L41: ='SO MS'!H41 -> 10000 | M41: ='SO MS'!I41 -> 13500 | N41: ='SO MS'!J41 -> 3500 | O41: ='SO MS'!K41 -> 0 | P41: ='SO MS'!L41 -> 0 | Q41: =SUM(I41:P41) -> 132360
B42: =B41+1 -> 46232 | C42: =TEXT(B42,"ddd") -> Wed | D42: =Q42-H42 -> -83391.057 | E42: =SUM('SO Juli 2026 Rev 2'!E42:AR42)-'SO Juli 2026 Rev 2'!V42 -> 182560.14 | F42: =SUM('SO Juli 2026 Rev 2'!AU42:BA42)+'SO Juli 2026 Rev 2'!V42 -> 19690.916 | G42: =SUM('SO Juli 2026 Rev 2'!BB42:BC42) -> 13500 | H42: =SUM(E42:G42) -> 215751.06 | I42: ='SO MS'!E42 -> 60000 | J42: ='SO MS'!F42 -> 34560 | K42: ='SO MS'!G42 -> 10800 | L42: ='SO MS'!H42 -> 10000 | M42: ='SO MS'!I42 -> 13500 | N42: ='SO MS'!J42 -> 3500 | O42: ='SO MS'!K42 -> 0 | P42: ='SO MS'!L42 -> 0 | Q42: =SUM(I42:P42) -> 132360
B43: =B42+1 -> 46233 | C43: =TEXT(B43,"ddd") -> Thu | D43: =Q43-H43 -> -83391.057 | E43: =SUM('SO Juli 2026 Rev 2'!E43:AR43)-'SO Juli 2026 Rev 2'!V43 -> 182560.14 | F43: =SUM('SO Juli 2026 Rev 2'!AU43:BA43)+'SO Juli 2026 Rev 2'!V43 -> 19690.916 | G43: =SUM('SO Juli 2026 Rev 2'!BB43:BC43) -> 13500 | H43: =SUM(E43:G43) -> 215751.06 | I43: ='SO MS'!E43 -> 60000 | J43: ='SO MS'!F43 -> 34560 | K43: ='SO MS'!G43 -> 10800 | L43: ='SO MS'!H43 -> 10000 | M43: ='SO MS'!I43 -> 13500 | N43: ='SO MS'!J43 -> 3500 | O43: ='SO MS'!K43 -> 0 | P43: ='SO MS'!L43 -> 0 | Q43: =SUM(I43:P43) -> 132360
B44: =B43+1 -> 46234 | C44: =TEXT(B44,"ddd") -> Fri | D44: =Q44-H44 -> -83391.057 | E44: =SUM('SO Juli 2026 Rev 2'!E44:AR44)-'SO Juli 2026 Rev 2'!V44 -> 182560.14 | F44: =SUM('SO Juli 2026 Rev 2'!AU44:BA44)+'SO Juli 2026 Rev 2'!V44 -> 19690.916 | G44: =SUM('SO Juli 2026 Rev 2'!BB44:BC44) -> 13500 | H44: =SUM(E44:G44) -> 215751.06 | I44: ='SO MS'!E44 -> 60000 | J44: ='SO MS'!F44 -> 34560 | K44: ='SO MS'!G44 -> 10800 | L44: ='SO MS'!H44 -> 10000 | M44: ='SO MS'!I44 -> 13500 | N44: ='SO MS'!J44 -> 3500 | O44: ='SO MS'!K44 -> 0 | P44: ='SO MS'!L44 -> 0 | Q44: =SUM(I44:P44) -> 132360
B45: Sub Total | D45: =SUM(D40:D44) -> -416955.29 | E45: =SUM(E40:E44) -> 912800.7 | F45: =SUM(F40:F44) -> 98454.581 | G45: =SUM(G40:G44) -> 67500 | H45: =SUM(H40:H44) -> 1078755.3 | I45: =SUM(I40:I44) -> 300000 | J45: =SUM(J40:J44) -> 172800 | K45: =SUM(K40:K44) -> 54000 | ... Q45: =SUM(Q40:Q44) -> 661800
B47: Sub Total | D47: =SUM(D45,D38,D29,D20,D11) -> -1757853 | E47: =SUM(E42,E34,E25,E16,E7) -> 912800.34 | F47: =SUM(F42,F34,F25,F16,F7) -> 96954.581 | G47: =SUM(G42,G34,G25,G16,G7) -> 67500 | H47: =SUM(H42,H34,H25,H16,H7) -> 1077254.9 | I47: =SUM(I42,I34,I25,I16,I7) -> 300000 | J47: =SUM(J42,J34,J25,J16,J7) -> 172800 | K47: =SUM(K42,K34,K25,K16,K7) -> 54000 | L47: =SUM(L42,L34,L25,L16,L7) -> 50000 | ... Q47: =SUM(Q42,Q34,Q25,Q16,Q7) -> 712161.91
...

Sheet SO MS
A1: SALES ORDER GAS
A4: ='SO FOB Juli 2026'!A4 -> 46204
A5: Week | B5: DATE | D5: TOTAL | E5: MS SETU | F5: MS KHT | G5: MS BLORA | H5: MS BITUNG | I5: MS ZEBRA | J5: MS TAMBAKLOROK | K5: MS SAG | L5: MS SADANG
A6: =WEEKNUM(B6) -> 27 | B6: =A4 -> 46204 | C6: =TEXT(B6,"ddd") -> Wed | D6: =SUM(E6:O6) -> 148973.49 | E6: =2.5*24000 -> 60000 | F6: =1.44*24000 -> 34560 | G6: =0.45*24000 -> 10800 | H6: 10000 | I6: =SUM('SO Juli 2026 Rev 2'!BB6:BC6) -> 13500 | J6: ='SO Juli 2026 Rev 2'!AR6 -> 3500 | K6: ='Summary sales'!K8 -> 16613.495 | L6: ='Summary sales'!L8 -> 0
B7: =B6+1 -> 46205 | C7: =TEXT(B7,"ddd") -> Thu | D7: =SUM(E7:O7) -> 140894.81 | E7: =2.5*24000 -> 60000 | F7: =1.44*24000 -> 34560 | G7: =0.45*24000 -> 10800 | H7: 10000 | I7: =SUM('SO Juli 2026 Rev 2'!BB7:BC7) -> 13500 | J7: ='SO Juli 2026 Rev 2'!AR7 -> 3500 | K7: ='Summary sales'!K9 -> 8534.806 | L7: ='Summary sales'!L9 -> 0
B8: =B7+1 -> 46206 | C8: =TEXT(B8,"ddd") -> Fri | D8: =SUM(E8:O8) -> 149191.53 | E8: =2.5*24000 -> 60000 | F8: =1.44*24000 -> 34560 | G8: =0.45*24000 -> 10800 | H8: 10000 | I8: =SUM('SO Juli 2026 Rev 2'!BB8:BC8) -> 13500 | J8: ='SO Juli 2026 Rev 2'!AR8 -> 3500 | K8: ='Summary sales'!K10 -> 16831.531 | L8: ='Summary sales'!L10 -> 0
B9: =B8+1 -> 46207 | C9: =TEXT(B9,"ddd") -> Sat | D9: =SUM(E9:O9) -> 144929.49 | E9: =2.5*24000 -> 60000 | F9: =1.44*24000 -> 34560 | G9: =0.45*24000 -> 10800 | H9: 10000 | I9: =SUM('SO Juli 2026 Rev 2'!BB9:BC9) -> 13500 | J9: ='SO Juli 2026 Rev 2'!AR9 -> 3500 | K9: ='Summary sales'!K11 -> 12569.49 | L9: ='Summary sales'!L11 -> 0
